Workbook

Sheet shop
A1: #enum shopType: int {设备 = 1,角色 = 2,遗物掉落 = 3,遗物商人 = 4}
A2: id | B2: shop_type | E2: goods_count_rnd | F2: shop_goods_price | G2: discount | H2: goods_rnd_pool
A3: uint key | B3: shopType | E3: (int,int) | F3: (uint,int)[] | G3: (int,float,float) | H3: dict<uint,int>
A4: 商店 编号 | B4: 商店类型 | C4: 备注 世界 | D4: 备注 等级 | E4: 商店商品数量 item1: 数量下限 item2: 数量上限 | F4: 商品价格 item1: 局内货币系数 item2: 权重 | G4: 折扣信息 item1: 折扣物品数量上限 item2: 每个物品的折扣几率 item3：折后价（比例） | H4: 商品随机池 key: 商品id value: 权重
A5: 3000 | B5: 遗物掉落 | C5: 普通三选一 | E5: 3~3 | F5: 0~1 | H5: 300011=1;300012=1;300013=1;300021=1;300022=1;300023=1;300031=1;300032=1;300033=1;300041=1;300042=1;300043=1;300051=1;300052=1;300053=1;300061=1;300062=1;300063=1;300071=1;300072=1;300073=1;300081=1;300082=1;300083=1;300091=1;300092=1;300093=1;301011=1;301012=1;301013=1;301021=1;301022=1;301023=1;301031=1;301032=1;301033=1;301041=1;301042=1;301043=1;301051=1;301052=1;301053=1;301061=1;301062=1;301063=1;301211=1;301212=1;301213=1;301221=1;301222=1;301223=1;301231=1;301232=1;301233=1;302011=1;302012=1;302013=1;302021=1;302022=1;302023=1;302031=1;302032=1;302033=1;302041=1;302042=1;302043=1;302051=1;302052=1;302053=1;302061=1;302062=1;302063=1;302211=1;302212=1;302213=1;302231=1;302232=1;302233=1;302311=1;302312=1;302313=1;302321=1;302322=1;302323=1;310201=10;310202=10;310203=10;310204=10;310205=10;310206=10;310207=10;310208=10;310209=10;310210=10;310211=10;310212=10;310213=10;310217=10;310218=10;310219=10;310401=10;310402=10;310403=10;310404=10;310407=10;310408=10;310409=10
A6: 3001 | B6: 遗物掉落 | C6: 普通三选一 | E6: 3~3 | F6: 0~1 | H6: 300011=1;300012=1;300013=1;300021=1;300022=1;300023=1;300031=1;300032=1;300033=1;300041=1;300042=1;300043=1;300051=1;300052=1;300053=1;300061=1;300062=1;300063=1;300071=1;300072=1;300073=1;300081=1;300082=1;300083=1;300091=1;300092=1;300093=1;301011=1;301012=1;301013=1;301021=1;301022=1;301023=1;301031=1;301032=1;301033=1;301041=1;301042=1;301043=1;301051=1;301052=1;301053=1;301061=1;301062=1;301063=1;301211=1;301212=1;301213=1;301221=1;301222=1;301223=1;301231=1;301232=1;301233=1;302011=1;302012=1;302013=1;302021=1;302022=1;302023=1;302031=1;302032=1;302033=1;302041=1;302042=1;302043=1;302051=1;302052=1;302053=1;302061=1;302062=1;302063=1;302211=1;302212=1;302213=1;302231=1;302232=1;302233=1;302311=1;302312=1;302313=1;302321=1;302322=1;302323=1;310201=10;310202=10;310203=10;310204=10;310205=10;310206=10;310207=10;310208=10;310209=10;310210=10;310211=10;310212=10;310213=10;310217=10;310218=10;310219=10;310401=10;310402=10;310403=10;310404=10;310407=10;310408=10;310409=10
C9: Main
A11: 10101 | B11: =VLOOKUP(VALUE(LEFT(A11,2)),tb_shopType[[prefix]:[type]],2,0) -> 设备 | C11: =VLOOKUP(VALUE(MID(A11,LEN(A11)-2,1)),table_world[[id]:[name]],2,0) -> 地宫 | D11: 1 | E11: =_xlfn.LET(_xlpm._i,RIGHT(A11,2), --ISODD(_xlpm._i)+2&"~"&3) -> 3~3 | F11: 800~4079 | G11: 1~1~0.5 | H11: {=_xlfn.LET(_xlpm._tb,_xlfn.XLOOKUP($B11,tb_shopType[type],tb_shopType[shop_table_name]), _xlpm._col,MATCH($C11&"-"&TEXT(D11,"00"),INDIRECT(_xlpm._tb&"[#标题]"),0), _xlpm._arr_id,INDIRECT(_xlpm._tb&"[id]"), _xlpm._count,ROWS(_xlpm._arr_id), _xlpm._arr_weight,OFFSET(INDIRECT(_xlpm._tb),0,_xlpm._col-1,_xlpm._count,1), _xlpm._outcome_arr,_xlfn.MAP(_xlpm._arr_id,_xlpm._arr_weight,_xlfn.LAMBDA(_xlpm.a,_xlpm.b,IF(AND(_xlpm.a<>"",_xlpm.b<>0),_xlpm.a&"="&_xlpm.b,""))), _xlfn.TEXTJOIN(";",1,_xlpm._outcome_arr))} -> 1310102=100;13101050=100;13101051=10;13101061=10;13101070=100;13101071=10;1311101=100;1311801=50;1320101=100;13201021=25;13201030=100;13201031=25;1320108=25;13201120=100;13201121=25;13301060=12;13601010=40;13601011=8;13601030=40;13601031=8
A12: 10102 | B12: =VLOOKUP(VALUE(LEFT(A12,2)),tb_shopType[[prefix]:[type]],2,0) -> 设备 | C12: =VLOOKUP(VALUE(MID(A12,LEN(A12)-2,1)),table_world[[id]:[name]],2,0) -> 地宫 | D12: 2 | E12: =_xlfn.LET(_xlpm._i,RIGHT(A12,2), --ISODD(_xlpm._i)+2&"~"&3) -> 2~3 | F12: 800~87739;825~6491;850~85 | G12: 2~0.2~0.75 | H12: {=_xlfn.LET(_xlpm._tb,_xlfn.XLOOKUP($B12,tb_shopType[type],tb_shopType[shop_table_name]), _xlpm._col,MATCH($C12&"-"&TEXT(D12,"00"),INDIRECT(_xlpm._tb&"[#标题]"),0), _xlpm._arr_id,INDIRECT(_xlpm._tb&"[id]"), _xlpm._count,ROWS(_xlpm._arr_id), _xlpm._arr_weight,OFFSET(INDIRECT(_xlpm._tb),0,_xlpm._col-1,_xlpm._count,1), _xlpm._outcome_arr,_xlfn.MAP(_xlpm._arr_id,_xlpm._arr_weight,_xlfn.LAMBDA(_xlpm.a,_xlpm.b,IF(AND(_xlpm.a<>"",_xlpm.b<>0),_xlpm.a&"="&_xlpm.b,""))), _xlfn.TEXTJOIN(";",1,_xlpm._outcome_arr))} -> 1310102=100;13101050=100;13101051=10;13101061=10;13101070=100;13101071=10;1311101=100;1311801=50;1320101=100;13201021=25;13201030=100;13201031=25;1320108=25;13201120=100;13201121=25;13301060=30;13301061=12;13601010=40;13601011=8;13601030=40;13601031=8
A13: 10103 | B13: =VLOOKUP(VALUE(LEFT(A13,2)),tb_shopType[[prefix]:[type]],2,0) -> 设备 | C13: =VLOOKUP(VALUE(MID(A13,LEN(A13)-2,1)),table_world[[id]:[name]],2,0) -> 地宫 | D13: 3 | E13: =_xlfn.LET(_xlpm._i,RIGHT(A13,2), --ISODD(_xlpm._i)+2&"~"&3) -> 3~3 | F13: 800~131058;825~48106;850~7005;875~404;900~9 | G13: 2~0.2~0.75 | H13: {=_xlfn.LET(_xlpm._tb,_xlfn.XLOOKUP($B13,tb_shopType[type],tb_shopType[shop_table_name]), _xlpm._col,MATCH($C13&"-"&TEXT(D13,"00"),INDIRECT(_xlpm._tb&"[#标题]"),0), _xlpm._arr_id,INDIRECT(_xlpm._tb&"[id]"), _xlpm._count,ROWS(_xlpm._arr_id), _xlpm._arr_weight,OFFSET(INDIRECT(_xlpm._tb),0,_xlpm._col-1,_xlpm._count,1), _xlpm._outcome_arr,_xlfn.MAP(_xlpm._arr_id,_xlpm._arr_weight,_xlfn.LAMBDA(_xlpm.a,_xlpm.b,IF(AND(_xlpm.a<>"",_xlpm.b<>0),_xlpm.a&"="&_xlpm.b,""))), _xlfn.TEXTJOIN(";",1,_xlpm._outcome_arr))} -> 1310102=100;13101050=100;13101051=10;13101061=10;13101070=100;13101071=10;1311101=100;1311801=50;1320101=50;13201021=100;13201022=25;13201030=50;13201031=100;13201032=25;1320105=25;1320108=100;1320111=25;13201120=50;13201121=100;13201122=25;13301060=30;13301061=12;13601010=40;13601011=8;13601030=40;13601031=8
A14: 10104 | B14: =VLOOKUP(VALUE(LEFT(A14,2)),tb_shopType[[prefix]:[type]],2,0) -> 设备 | C14: =VLOOKUP(VALUE(MID(A14,LEN(A14)-2,1)),table_world[[id]:[name]],2,0) -> 地宫 | D14: 4 | E14: =_xlfn.LET(_xlpm._i,RIGHT(A14,2), --ISODD(_xlpm._i)+2&"~"&3) -> 2~3 | F14: 800~119962;825~81948;850~31534;875~6835;900~834;925~57;950~2 | G14: 2~0.2~0.75 | H14: {=_xlfn.LET(_xlpm._tb,_xlfn.XLOOKUP($B14,tb_shopType[type],tb_shopType[shop_table_name]), _xlpm._col,MATCH($C14&"-"&TEXT(D14,"00"),INDIRECT(_xlpm._tb&"[#标题]"),0), _xlpm._arr_id,INDIRECT(_xlpm._tb&"[id]"), _xlpm._count,ROWS(_xlpm._arr_id), _xlpm._arr_weight,OFFSET(INDIRECT(_xlpm._tb),0,_xlpm._col-1,_xlpm._count,1), _xlpm._outcome_arr,_xlfn.MAP(_xlpm._arr_id,_xlpm._arr_weight,_xlfn.LAMBDA(_xlpm.a,_xlpm.b,IF(AND(_xlpm.a<>"",_xlpm.b<>0),_xlpm.a&"="&_xlpm.b,""))), _xlfn.TEXTJOIN(";",1,_xlpm._outcome_arr))} -> 1310102=100;1310104=20;13101050=100;13101051=10;13101061=50;13101062=10;13101070=100;13101071=50;13101072=10;1311101=100;1311801=50;1311802=10;1320101=50;13201021=100;13201022=25;13201030=50;13201031=100;13201032=25;1320105=25;1320108=100;1320111=25;13201120=50;13201121=100;13201122=25;13301060=30;13301061=12;13601010=40;13601011=8;13601030=40;13601031=8
A15: 10105 | B15: =VLOOKUP(VALUE(LEFT(A15,2)),tb_shopType[[prefix]:[type]],2,0) -> 设备 | C15: =VLOOKUP(VALUE(MID(A15,LEN(A15)-2,1)),table_world[[id]:[name]],2,0) -> 地宫 | D15: 5 | E15: =_xlfn.LET(_xlpm._i,RIGHT(A15,2), --ISODD(_xlpm._i)+2&"~"&3) -> 3~3 | F15: 800~98467;825~89515;850~55062;875~22917;900~6454;925~1229;950~158;975~13 | G15: 2~0.2~0.75 | H15: {=_xlfn.LET(_xlpm._tb,_xlfn.XLOOKUP($B15,tb_shopType[type],tb_shopType[shop_table_name]), _xlpm._col,MATCH($C15&"-"&TEXT(D15,"00"),INDIRECT(_xlpm._tb&"[#标题]"),0), _xlpm._arr_id,INDIRECT(_xlpm._tb&"[id]"), _xlpm._count,ROWS(_xlpm._arr_id), _xlpm._arr_weight,OFFSET(INDIRECT(_xlpm._tb),0,_xlpm._col-1,_xlpm._count,1), _xlpm._outcome_arr,_xlfn.MAP(_xlpm._arr_id,_xlpm._arr_weight,_xlfn.LAMBDA(_xlpm.a,_xlpm.b,IF(AND(_xlpm.a<>"",_xlpm.b<>0),_xlpm.a&"="&_xlpm.b,""))), _xlfn.TEXTJOIN(";",1,_xlpm._outcome_arr))} -> 1310102=100;1310104=20;13101050=100;13101051=100;13101061=100;13101062=10;13101070=100;13101071=100;13101072=10;1311101=100;1311801=50;1311802=10;1320101=50;13201021=100;13201022=25;13201030=50;13201031=100;13201032=25;1320105=25;1320108=100;1320111=25;13201120=50;13201121=100;13201122=25;13301012=12;13301060=60;13301061=30;13301062=12;13601010=40;13601011=40;13601012=8;13601022=8;13601030=40;13601031=40
A16: 10106 | B16: =VLOOKUP(VALUE(LEFT(A16,2)),tb_shopType[[prefix]:[type]],2,0) -> 设备 | C16: =VLOOKUP(VALUE(MID(A16,LEN(A16)-2,1)),table_world[[id]:[name]],2,0) -> 地宫 | D16: 6 | E16: =_xlfn.LET(_xlpm._i,RIGHT(A16,2), --ISODD(_xlpm._i)+2&"~"&3) -> 2~3 | F16: 800~79567;825~83630;850~66238;875~39535;900~17782;925~6027;950~1539;975~296;1000~42;1025~4 | G16: 2~0.2~0.75 | H16: {=_xlfn.LET(_xlpm._tb,_xlfn.XLOOKUP($B16,tb_shopType[type],tb_shopType[shop_table_name]), _xlpm._col,MATCH($C16&"-"&TEXT(D16,"00"),INDIRECT(_xlpm._tb&"[#标题]"),0), _xlpm._arr_id,INDIRECT(_xlpm._tb&"[id]"), _xlpm._count,ROWS(_xlpm._arr_id), _xlpm._arr_weight,OFFSET(INDIRECT(_xlpm._tb),0,_xlpm._col-1,_xlpm._count,1), _xlpm._outcome_arr,_xlfn.MAP(_xlpm._arr_id,_xlpm._arr_weight,_xlfn.LAMBDA(_xlpm.a,_xlpm.b,IF(AND(_xlpm.a<>"",_xlpm.b<>0),_xlpm.a&"="&_xlpm.b,""))), _xlfn.TEXTJOIN(";",1,_xlpm._outcome_arr))} -> 1310102=100;1310104=20;13101050=50;13101051=100;13101061=100;13101062=10;13101070=50;13101071=100;13101072=10;1311101=100;1311801=50;1311802=10;1320101=10;13201021=50;13201022=100;13201023=25;13201030=10;13201031=50;13201032=100;13201033=25;13201043=25;1320105=100;1320108=50;1320111=100;13201120=10;13201121=50;13201122=100;1320113=25;1320114=25;1320115=25;13301012=12;13301060=60;13301061=30;13301062=12;13601010=40;13601011=40;13601012=8;13601022=8;13601030=40;13601031=40
A17: 10107 | B17: =VLOOKUP(VALUE(LEFT(A17,2)),tb_shopType[[prefix]:[type]],2,0) -> 设备 | C17: =VLOOKUP(VALUE(MID(A17,LEN(A17)-2,1)),table_world[[id]:[name]],2,0) -> 地宫 | D17: 7 | E17: =_xlfn.LET(_xlpm._i,RIGHT(A17,2), --ISODD(_xlpm._i)+2&"~"&3) -> 3~3 | F17: 800~64954;825~73805;850~67683;875~50094;900~29923;925~14426;950~5613;975~1762;1000~446;1025~91;1050~15;1075~2 | G17: 2~0.2~0.75 | H17: {=_xlfn.LET(_xlpm._tb,_xlfn.XLOOKUP($B17,tb_shopType[type],tb_shopType[shop_table_name]), _xlpm._col,MATCH($C17&"-"&TEXT(D17,"00"),INDIRECT(_xlpm._tb&"[#标题]"),0), _xlpm._arr_id,INDIRECT(_xlpm._tb&"[id]"), _xlpm._count,ROWS(_xlpm._arr_id), _xlpm._arr_weight,OFFSET(INDIRECT(_xlpm._tb),0,_xlpm._col-1,_xlpm._count,1), _xlpm._outcome_arr,_xlfn.MAP(_xlpm._arr_id,_xlpm._arr_weight,_xlfn.LAMBDA(_xlpm.a,_xlpm.b,IF(AND(_xlpm.a<>"",_xlpm.b<>0),_xlpm.a&"="&_xlpm.b,""))), _xlfn.TEXTJOIN(";",1,_xlpm._outcome_arr))} -> 1310102=100;1310104=20;13101050=50;13101051=100;13101061=100;13101062=50;13101063=10;13101070=50;13101071=100;13101072=50;13101073=10;1311101=100;1311801=50;1311802=10;1320101=10;13201021=50;13201022=100;13201023=25;13201030=10;13201031=50;13201032=100;13201033=25;13201043=25;1320105=100;1320108=50;1320111=100;13201120=10;13201121=50;13201122=100;1320113=25;1320114=25;1320115=25;13301012=12;13301060=60;13301061=30;13301062=12;13601010=40;13601011=40;13601012=8;13601022=8;13601030=40;13601031=40
A18: 10108 | B18: =VLOOKUP(VALUE(LEFT(A18,2)),tb_shopType[[prefix]:[type]],2,0) -> 设备 | C18: =VLOOKUP(VALUE(MID(A18,LEN(A18)-2,1)),table_world[[id]:[name]],2,0) -> 地宫 | D18: 8 | E18: =_xlfn.LET(_xlpm._i,RIGHT(A18,2), --ISODD(_xlpm._i)+2&"~"&3) -> 2~3 | F18: 800~53920;825~63954;850~64126;875~54357;900~38952;925~23597;950~12084;975~5232;1000~1914;1025~592;1050~154;1075~34;1100~6;1125~1 | G18: 2~0.2~0.75 | H18: {=_xlfn.LET(_xlpm._tb,_xlfn.XLOOKUP($B18,tb_shopType[type],tb_shopType[shop_table_name]), _xlpm._col,MATCH($C18&"-"&TEXT(D18,"00"),INDIRECT(_xlpm._tb&"[#标题]"),0), _xlpm._arr_id,INDIRECT(_xlpm._tb&"[id]"), _xlpm._count,ROWS(_xlpm._arr_id), _xlpm._arr_weight,OFFSET(INDIRECT(_xlpm._tb),0,_xlpm._col-1,_xlpm._count,1), _xlpm._outcome_arr,_xlfn.MAP(_xlpm._arr_id,_xlpm._arr_weight,_xlfn.LAMBDA(_xlpm.a,_xlpm.b,IF(AND(_xlpm.a<>"",_xlpm.b<>0),_xlpm.a&"="&_xlpm.b,""))), _xlfn.TEXTJOIN(";",1,_xlpm._outcome_arr))} -> 1310102=50;1310103=20;1310104=100;13101050=50;13101051=100;13101061=100;13101062=100;13101063=10;13101070=50;13101071=100;13101072=100;13101073=10;1311101=50;1311801=25;1311802=50;1320101=10;13201021=50;13201022=100;13201023=25;13201030=10;13201031=50;13201032=100;13201033=25;13201043=25;1320105=100;1320108=50;1320111=100;13201120=10;13201121=50;13201122=100;1320113=25;1320114=25;1320115=25;13301012=30;13301013=12;13301060=60;13301061=60;13301062=30;13301063=12;13601010=40;13601011=40;13601012=8;13601022=8;13601030=40;13601031=40
A19: 10109 | B19: =VLOOKUP(VALUE(LEFT(A19,2)),tb_shopType[[prefix]:[type]],2,0) -> 设备 | C19: =VLOOKUP(VALUE(MID(A19,LEN(A19)-2,1)),table_world[[id]:[name]],2,0) -> 地宫 | D19: 9 | E19: =_xlfn.LET(_xlpm._i,RIGHT(A19,2), --ISODD(_xlpm._i)+2&"~"&3) -> 3~3 | F19: 800~45539;825~55295;850~58651;875~54346;900~43991;925~31106;950~19215;975~10368;1000~4887;1025~2012;1050~724;1075~227;1100~62;1125~14;1150~3 | G19: 2~0.2~0.75 | H19: {=_xlfn.LET(_xlpm._tb,_xlfn.XLOOKUP($B19,tb_shopType[type],tb_shopType[shop_table_name]), _xlpm._col,MATCH($C19&"-"&TEXT(D19,"00"),INDIRECT(_xlpm._tb&"[#标题]"),0), _xlpm._arr_id,INDIRECT(_xlpm._tb&"[id]"), _xlpm._count,ROWS(_xlpm._arr_id), _xlpm._arr_weight,OFFSET(INDIRECT(_xlpm._tb),0,_xlpm._col-1,_xlpm._count,1), _xlpm._outcome_arr,_xlfn.MAP(_xlpm._arr_id,_xlpm._arr_weight,_xlfn.LAMBDA(_xlpm.a,_xlpm.b,IF(AND(_xlpm.a<>"",_xlpm.b<>0),_xlpm.a&"="&_xlpm.b,""))), _xlfn.TEXTJOIN(";",1,_xlpm._outcome_arr))} -> 1310102=50;1310103=20;1310104=100;13101050=50;13101051=100;13101061=100;13101062=100;13101063=10;13101070=50;13101071=100;13101072=100;13101073=10;1311101=50;1311801=25;1311802=50;1320101=10;13201021=50;13201022=100;13201023=25;13201030=10;13201031=50;13201032=100;13201033=25;13201043=25;1320105=100;1320108=50;1320111=100;13201120=10;13201121=50;13201122=100;1320113=25;1320114=25;1320115=25;13301012=30;13301013=12;1330102=12;13301060=50;13301061=60;13301062=30;13301063=12;13601010=19;13601011=40;13601012=40;13601022=40;13601023=8;13601030=19;13601031=40
A20: 10110 | B20: =VLOOKUP(VALUE(LEFT(A20,2)),tb_shopType[[prefix]:[type]],2,0) -> 设备 | C20: =VLOOKUP(VALUE(MID(A20,LEN(A20)-2,1)),table_world[[id]:[name]],2,0) -> 地宫 | D20: 10 | E20: =_xlfn.LET(_xlpm._i,RIGHT(A20,2), --ISODD(_xlpm._i)+2&"~"&3) -> 2~3 | F20: 800~39077;825~48026;850~52819;875~51980;900~45776;925~36072;950~25437;975~16050;1000~9063;1025~4579;1050~2070;1075~837;1100~303;1125~98;1150~28;1175~7;1200~1 | G20: 2~0.2~0.75 | H20: {=_xlfn.LET(_xlpm._tb,_xlfn.XLOOKUP($B20,tb_shopType[type],tb_shopType[shop_table_name]), _xlpm._col,MATCH($C20&"-"&TEXT(D20,"00"),INDIRECT(_xlpm._tb&"[#标题]"),0), _xlpm._arr_id,INDIRECT(_xlpm._tb&"[id]"), _xlpm._count,ROWS(_xlpm._arr_id), _xlpm._arr_weight,OFFSET(INDIRECT(_xlpm._tb),0,_xlpm._col-1,_xlpm._count,1), _xlpm._outcome_arr,_xlfn.MAP(_xlpm._arr_id,_xlpm._arr_weight,_xlfn.LAMBDA(_xlpm.a,_xlpm.b,IF(AND(_xlpm.a<>"",_xlpm.b<>0),_xlpm.a&"="&_xlpm.b,""))), _xlfn.TEXTJOIN(";",1,_xlpm._outcome_arr))} -> 1310102=50;1310103=20;1310104=100;13101050=50;13101051=50;13101061=50;13101062=100;13101063=50;13101064=10;13101070=50;13101071=50;13101072=100;13101073=50;1311101=50;1311801=25;1311802=50;1320101=10;13201021=50;13201022=100;13201023=25;13201030=10;13201031=50;13201032=100;13201033=25;13201043=25;1320105=100;1320108=50;1320111=100;13201120=10;13201121=50;13201122=100;1320113=25;1320114=25;1320115=25;13301012=30;13301013=12;1330102=12;13301060=50;13301061=60;13301062=30;13301063=12;13601010=19;13601011=40;13601012=40;13601022=40;13601023=8;13601030=19;13601031=40
A21: 10111 | B21: =VLOOKUP(VALUE(LEFT(A21,2)),tb_shopType[[prefix]:[type]],2,0) -> 设备 | C21: =VLOOKUP(VALUE(MID(A21,LEN(A21)-2,1)),table_world[[id]:[name]],2,0) -> 地宫 | D21: 11 | E21: =_xlfn.LET(_xlpm._i,RIGHT(A21,2), --ISODD(_xlpm._i)+2&"~"&3) -> 3~3 | F21: 800~34005;825~42017;850~47308;875~48538;900~45379;925~38660;950~30012;975~21230;1000~13685;1025~8039;1050~4303;1075~2098;1100~932;1125~377;1150~139;1175~46;1200~14;1225~4;1250~1 | G21: 2~0.2~0.75 | H21: {=_xlfn.LET(_xlpm._tb,_xlfn.XLOOKUP($B21,tb_shopType[type],tb_shopType[shop_table_name]), _xlpm._col,MATCH($C21&"-"&TEXT(D21,"00"),INDIRECT(_xlpm._tb&"[#标题]"),0), _xlpm._arr_id,INDIRECT(_xlpm._tb&"[id]"), _xlpm._count,ROWS(_xlpm._arr_id), _xlpm._arr_weight,OFFSET(INDIRECT(_xlpm._tb),0,_xlpm._col-1,_xlpm._count,1), _xlpm._outcome_arr,_xlfn.MAP(_xlpm._arr_id,_xlpm._arr_weight,_xlfn.LAMBDA(_xlpm.a,_xlpm.b,IF(AND(_xlpm.a<>"",_xlpm.b<>0),_xlpm.a&"="&_xlpm.b,""))), _xlfn.TEXTJOIN(";",1,_xlpm._outcome_arr))} -> 1310102=50;1310103=20;1310104=100;13101050=50;13101051=50;13101061=50;13101062=100;13101063=100;13101064=10;13101070=50;13101071=50;13101072=100;13101073=100;1311101=50;1311801=25;1311802=50;1320101=5;13201021=20;13201022=50;13201023=100;13201030=5;13201031=20;13201032=50;13201033=100;13201043=100;13201044=25;1320105=50;1320108=20;1320111=50;13201120=5;13201121=20;13201122=50;1320113=100;1320114=100;1320115=100;13301012=60;13301013=30;13301014=12;1330102=30;13301060=25;13301061=60;13301062=60;13301063=30;13301064=12;13601010=19;13601011=40;13601012=40;13601022=40;13601023=8;13601030=19;13601031=40
A22: 10112 | B22: =VLOOKUP(VALUE(LEFT(A22,2)),tb_shopType[[prefix]:[type]],2,0) -> 设备 | C22: =VLOOKUP(VALUE(MID(A22,LEN(A22)-2,1)),table_world[[id]:[name]],2,0) -> 地宫 | D22: 12 | E22: =_xlfn.LET(_xlpm._i,RIGHT(A22,2), --ISODD(_xlpm._i)+2&"~"&3) -> 2~3 | F22: 800~29957;825~37058;850~42365;875~44757;900~43696;925~39423;950~32870;975~25327;1000~18034;1025~11867;1050~7216;1075~4055;1100~2106;1125~1010;1150~448;1175~183;1200~69;1225~24;1250~7;1275~2 | G22: 2~0.2~0.75 | H22: {=_xlfn.LET(_xlpm._tb,_xlfn.XLOOKUP($B22,tb_shopType[type],tb_shopType[shop_table_name]), _xlpm._col,MATCH($C22&"-"&TEXT(D22,"00"),INDIRECT(_xlpm._tb&"[#标题]"),0), _xlpm._arr_id,INDIRECT(_xlpm._tb&"[id]"), _xlpm._count,ROWS(_xlpm._arr_id), _xlpm._arr_weight,OFFSET(INDIRECT(_xlpm._tb),0,_xlpm._col-1,_xlpm._count,1), _xlpm._outcome_arr,_xlfn.MAP(_xlpm._arr_id,_xlpm._arr_weight,_xlfn.LAMBDA(_xlpm.a,_xlpm.b,IF(AND(_xlpm.a<>"",_xlpm.b<>0),_xlpm.a&"="&_xlpm.b,""))), _xlfn.TEXTJOIN(";",1,_xlpm._outcome_arr))} -> 1310102=18;1310103=100;1310104=50;13101050=18;13101051=50;13101061=50;13101062=100;13101063=100;13101064=10;13101070=18;13101071=50;13101072=100;13101073=100;1311101=18;1311801=9;1311802=25;1320101=5;13201021=20;13201022=50;13201023=100;13201030=5;13201031=20;13201032=50;13201033=100;13201043=100;13201044=25;1320105=50;1320108=20;1320111=50;13201120=5;13201121=20;13201122=50;1320113=100;1320114=100;1320115=100;13301012=60;13301013=30;13301014=12;1330102=30;13301060=25;13301061=50;13301062=60;13301063=30;13301064=12;13601010=19;13601011=40;13601012=40;13601022=40;13601023=8;13601030=19;13601031=40
... A93: 10820 | B93: =VLOOKUP(VALUE(LEFT(A93,2)),tb_shopType[[prefix]:[type]],2,0) -> 设备 | C93: =VLOOKUP(VALUE(MID(A93,LEN(A93)-2,1)),table_world[[id]:[name]],2,0) -> 大湖 | D93: 20 | E93: =_xlfn.LET(_xlpm._i,RIGHT(A93,2), --ISODD(_xlpm._i)+2&"~"&3) -> 2~3 | F93: 800~14524;825~17389;850~20209;875~22799;900~24967;925~26540;950~27387;975~27432;1000~26673;1025~25175;1050~23066;1075~20514;1100~17710;1125~14842;1150~12073;1175~9534;1200~7308;1225~5438;1250~3927;1275~2753;1300~1874 | G93: 2~0.2~0.75 | H93: {=_xlfn.LET(_xlpm._tb,_xlfn.XLOOKUP($B93,tb_shopType[type],tb_shopType[shop_table_name]), _xlpm._col,MATCH($C93&"-"&TEXT(D93,"00"),INDIRECT(_xlpm._tb&"[#标题]"),0), _xlpm._arr_id,INDIRECT(_xlpm._tb&"[id]"), _xlpm._count,ROWS(_xlpm._arr_id), _xlpm._arr_weight,OFFSET(INDIRECT(_xlpm._tb),0,_xlpm._col-1,_xlpm._count,1), _xlpm._outcome_arr,_xlfn.MAP(_xlpm._arr_id,_xlpm._arr_weight,_xlfn.LAMBDA(_xlpm.a,_xlpm.b,IF(AND(_xlpm.a<>"",_xlpm.b<>0),_xlpm.a&"="&_xlpm.b,""))), _xlfn.TEXTJOIN(";",1,_xlpm._outcome_arr))} -> 12101011=38;12101012=31;12101013=17;13101050=18;13101051=38;13101061=38;13101062=31;13101063=17;13101064=10;13101070=18;13101071=38;13101072=31;13101073=17;13201021=38;13201022=31;13201023=17;13201030=18;13201031=38;13201032=31;13201033=17;13201043=17;13201044=10;13201120=18;13201121=38;13201122=31;13301012=31;13301013=17;13301014=10;13301060=18;13301061=38;13301062=31;13301063=17;13301064=10;13318012=31;13318013=17;13318014=10;13601010=18;13601011=38;13601012=31;13601022=31;13601023=17;13601030=18;13601031=38;13618011=38;13618012=31;13618013=17
A97: 20101 | B97: =VLOOKUP(VALUE(LEFT(A97,2)),tb_shopType[[prefix]:[type]],2,0) -> 角色 | C97: =VLOOKUP(VALUE(MID(A97,LEN(A97)-2,1)),table_world[[id]:[name]],2,0) -> 地宫 | D97: 1 | E97: =_xlfn.LET(_xlpm._i,RIGHT(A97,2), INT(_xlpm._i/14)+2&"~"&3) -> 2~3 | F97: 500~25158;750~3599;1000~32 | G97: 1~1~0 | H97: {=_xlfn.LET(_xlpm._tb,_xlfn.XLOOKUP($B97,tb_shopType[type],tb_shopType[shop_table_name]), _xlpm._col,MATCH($C97&"-"&TEXT(D97,"00"),INDIRECT(_xlpm._tb&"[#标题]"),0), _xlpm._arr_id,INDIRECT(_xlpm._tb&"[id]"), _xlpm._count,ROWS(_xlpm._arr_id), _xlpm._arr_weight,OFFSET(INDIRECT(_xlpm._tb),0,_xlpm._col-1,_xlpm._count,1), _xlpm._outcome_arr,_xlfn.MAP(_xlpm._arr_id,_xlpm._arr_weight,_xlfn.LAMBDA(_xlpm.a,_xlpm.b,IF(AND(_xlpm.a<>"",_xlpm.b<>0),_xlpm.a&"="&_xlpm.b,""))), _xlfn.TEXTJOIN(";",1,_xlpm._outcome_arr))} -> 15101=756;15102=756;15103=756;15104=756;15105=692;15106=692;15107=692;15108=588;15109=588;15110=588;15111=452;15112=452;15113=452;15114=301;15115=301;15116=164;15117=164;15118=164;15119=67;15120=67
A98: 20102 | B98: =VLOOKUP(VALUE(LEFT(A98,2)),tb_shopType[[prefix]:[type]],2,0) -> 角色 | C98: =VLOOKUP(VALUE(MID(A98,LEN(A98)-2,1)),table_world[[id]:[name]],2,0) -> 地宫 | D98: 2 | E98: =_xlfn.LET(_xlpm._i,RIGHT(A98,2), INT(_xlpm._i/14)+2&"~"&3) -> 2~3 | F98: 500~759;750~16131;1000~21296;1250~1748;1500~8 | G98: ="1~0.4~"&0.2+D98*0.02 -> 1~0.4~0.24 | H98: {=_xlfn.LET(_xlpm._tb,_xlfn.XLOOKUP($B98,tb_shopType[type],tb_shopType[shop_table_name]), _xlpm._col,MATCH($C98&"-"&TEXT(D98,"00"),INDIRECT(_xlpm._tb&"[#标题]"),0), _xlpm._arr_id,INDIRECT(_xlpm._tb&"[id]"), _xlpm._count,ROWS(_xlpm._arr_id), _xlpm._arr_weight,OFFSET(INDIRECT(_xlpm._tb),0,_xlpm._col-1,_xlpm._count,1), _xlpm._outcome_arr,_xlfn.MAP(_xlpm._arr_id,_xlpm._arr_weight,_xlfn.LAMBDA(_xlpm.a,_xlpm.b,IF(AND(_xlpm.a<>"",_xlpm.b<>0),_xlpm.a&"="&_xlpm.b,""))), _xlfn.TEXTJOIN(";",1,_xlpm._outcome_arr))} -> 15101=752;15102=752;15103=752;15104=752;15105=705;15106=705;15107=705;15108=617;15109=617;15110=617;15111=492;15112=492;15113=492;15114=344;15115=344;15116=200;15117=200;15118=200;15119=88;15120=88
A99: 20103 | B99: =VLOOKUP(VALUE(LEFT(A99,2)),tb_shopType[[prefix]:[type]],2,0) -> 角色 | C99: =VLOOKUP(VALUE(MID(A99,LEN(A99)-2,1)),table_world[[id]:[name]],2,0) -> 地宫 | D99: 3 | E99: =_xlfn.LET(_xlpm._i,RIGHT(A99,2), INT(_xlpm._i/14)+2&"~"&3) -> 2~3 | F99: 750~8;1000~1748;1250~21296;1500~16131;1750~759;2000~2 | G99: ="1~0.4~"&0.2+D99*0.02 -> 1~0.4~0.26 | H99: {=_xlfn.LET(_xlpm._tb,_xlfn.XLOOKUP($B99,tb_shopType[type],tb_shopType[shop_table_name]), _xlpm._col,MATCH($C99&"-"&TEXT(D99,"00"),INDIRECT(_xlpm._tb&"[#标题]"),0), _xlpm._arr_id,INDIRECT(_xlpm._tb&"[id]"), _xlpm._count,ROWS(_xlpm._arr_id), _xlpm._arr_weight,OFFSET(INDIRECT(_xlpm._tb),0,_xlpm._col-1,_xlpm._count,1), _xlpm._outcome_arr,_xlfn.MAP(_xlpm._arr_id,_xlpm._arr_weight,_xlfn.LAMBDA(_xlpm.a,_xlpm.b,IF(AND(_xlpm.a<>"",_xlpm.b<>0),_xlpm.a&"="&_xlpm.b,""))), _xlfn.TEXTJOIN(";",1,_xlpm._outcome_arr))} -> 15101=739;15102=739;15103=739;15104=739;15105=709;15106=709;15107=709;15108=639;15109=639;15110=639;15111=528;15112=528;15113=528;15114=386;15115=386;15116=237;15117=237;15118=237;15119=113;15120=113
A100: 20104 | B100: =VLOOKUP(VALUE(LEFT(A100,2)),tb_shopType[[prefix]:[type]],2,0) -> 角色 | C100: =VLOOKUP(VALUE(MID(A100,LEN(A100)-2,1)),table_world[[id]:[name]],2,0) -> 地宫 | D100: 4 | E100: =_xlfn.LET(_xlpm._i,RIGHT(A100,2), INT(_xlpm._i/14)+2&"~"&3) -> 2~3 | F100: 1250~32;1500~3599;1750~25158;2000~10934;2250~295 | G100: ="1~0.4~"&0.2+D100*0.02 -> 1~0.4~0.28 | H100: {=_xlfn.LET(_xlpm._tb,_xlfn.XLOOKUP($B100,tb_shopType[type],tb_shopType[shop_table_name]), _xlpm._col,MATCH($C100&"-"&TEXT(D100,"00"),INDIRECT(_xlpm._tb&"[#标题]"),0), _xlpm._arr_id,INDIRECT(_xlpm._tb&"[id]"), _xlpm._count,ROWS(_xlpm._arr_id), _xlpm._arr_weight,OFFSET(INDIRECT(_xlpm._tb),0,_xlpm._col-1,_xlpm._count,1), _xlpm._outcome_arr,_xlfn.MAP(_xlpm._arr_id,_xlpm._arr_weight,_xlfn.LAMBDA(_xlpm.a,_xlpm.b,IF(AND(_xlpm.a<>"",_xlpm.b<>0),_xlpm.a&"="&_xlpm.b,""))), _xlfn.TEXTJOIN(";",1,_xlpm._outcome_arr))} -> 15101=719;15102=719;15103=719;15104=719;15105=705;15106=705;15107=705;15108=653;15109=653;15110=653;15111=558;15112=558;15113=558;15114=426;15115=426;15116=277;15117=277;15118=277;15119=141;15120=141
A101: 20105 | B101: =VLOOKUP(VALUE(LEFT(A101,2)),tb_shopType[[prefix]:[type]],2,0) -> 角色 | C101: =VLOOKUP(VALUE(MID(A101,LEN(A101)-2,1)),table_world[[id]:[name]],2,0) -> 地宫 | D101: 5 | E101: =_xlfn.LET(_xlpm._i,RIGHT(A101,2), INT(_xlpm._i/14)+2&"~"&3) -> 2~3 | F101: 1750~102;2000~6631;2250~26596;2500~6631;2750~102 | G101: ="1~0.4~"&0.2+D101*0.02 -> 1~0.4~0.3 | H101: {=_xlfn.LET(_xlpm._tb,_xlfn.XLOOKUP($B101,tb_shopType[type],tb_shopType[shop_table_name]), _xlpm._col,MATCH($C101&"-"&TEXT(D101,"00"),INDIRECT(_xlpm._tb&"[#标题]"),0), _xlpm._arr_id,INDIRECT(_xlpm._tb&"[id]"), _xlpm._count,ROWS(_xlpm._arr_id), _xlpm._arr_weight,OFFSET(INDIRECT(_xlpm._tb),0,_xlpm._col-1,_xlpm._count,1), _xlpm._outcome_arr,_xlfn.MAP(_xlpm._arr_id,_xlpm._arr_weight,_xlfn.LAMBDA(_xlpm.a,_xlpm.b,IF(AND(_xlpm.a<>"",_xlpm.b<>0),_xlpm.a&"="&_xlpm.b,""))), _xlfn.TEXTJOIN(";",1,_xlpm._outcome_arr))} -> 15101=692;15102=692;15103=692;15104=692;15105=692;15106=692;15107=692;15108=657;15109=657;15110=657;15111=580;15112=580;15113=580;15114=461;15115=461;15116=316;15117=316;15118=316;15119=173;15120=173
A102: 20106 | B102: =VLOOKUP(VALUE(LEFT(A102,2)),tb_shopType[[prefix]:[type]],2,0) -> 角色 | C102: =VLOOKUP(VALUE(MID(A102,LEN(A102)-2,1)),table_world[[id]:[name]],2,0) -> 地宫 | D102: 6 | E102: =_xlfn.LET(_xlpm._i,RIGHT(A102,2), INT(_xlpm._i/14)+2&"~"&3) -> 2~3 | F102: 2250~295;2500~10934;2750~25158;3000~3599;3250~32 | G102: ="1~0.4~"&0.2+D102*0.02 -> 1~0.4~0.32 | H102: {=_xlfn.LET(_xlpm._tb,_xlfn.XLOOKUP($B102,tb_shopType[type],tb_shopType[shop_table_name]), _xlpm._col,MATCH($C102&"-"&TEXT(D102,"00"),INDIRECT(_xlpm._tb&"[#标题]"),0), _xlpm._arr_id,INDIRECT(_xlpm._tb&"[id]"), _xlpm._count,ROWS(_xlpm._arr_id), _xlpm._arr_weight,OFFSET(INDIRECT(_xlpm._tb),0,_xlpm._col-1,_xlpm._count,1), _xlpm._outcome_arr,_xlfn.MAP(_xlpm._arr_id,_xlpm._arr_weight,_xlfn.LAMBDA(_xlpm.a,_xlpm.b,IF(AND(_xlpm.a<>"",_xlpm.b<>0),_xlpm.a&"="&_xlpm.b,""))), _xlfn.TEXTJOIN(";",1,_xlpm._outcome_arr))} -> 15101=658;15102=658;15103=658;15104=658;15105=671;15106=671;15107=671;15108=653;15109=653;15110=653;15111=594;15112=594;15113=594;15114=491;15115=491;15116=353;15117=353;15118=353;15119=206;15120=206
A103: 20107 | B103: =VLOOKUP(VALUE(LEFT(A103,2)),tb_shopType[[prefix]:[type]],2,0) -> 角色 | C103: =VLOOKUP(VALUE(MID(A103,LEN(A103)-2,1)),table_world[[id]:[name]],2,0) -> 地宫 | D103: 7 | E103: =_xlfn.LET(_xlpm._i,RIGHT(A103,2), INT(_xlpm._i/14)+2&"~"&3) -> 2~3 | F103: 2500~2;2750~759;3000~16131;3250~21296;3500~1748;3750~8 | G103: ="1~0.4~"&0.2+D103*0.02 -> 1~0.4~0.34 | H103: {=_xlfn.LET(_xlpm._tb,_xlfn.XLOOKUP($B103,tb_shopType[type],tb_shopType[shop_table_name]), _xlpm._col,MATCH($C103&"-"&TEXT(D103,"00"),INDIRECT(_xlpm._tb&"[#标题]"),0), _xlpm._arr_id,INDIRECT(_xlpm._tb&"[id]"), _xlpm._count,ROWS(_xlpm._arr_id), _xlpm._arr_weight,OFFSET(INDIRECT(_xlpm._tb),0,_xlpm._col-1,_xlpm._count,1), _xlpm._outcome_arr,_xlfn.MAP(_xlpm._arr_id,_xlpm._arr_weight,_xlfn.LAMBDA(_xlpm.a,_xlpm.b,IF(AND(_xlpm.a<>"",_xlpm.b<>0),_xlpm.a&"="&_xlpm.b,""))), _xlfn.TEXTJOIN(";",1,_xlpm._outcome_arr))} -> 15101=619;15102=619;15103=619;15104=619;15105=643;15106=643;15107=643;15108=639;15109=639;15110=639;15111=598;15112=598;15113=598;15114=513;15115=513;15116=387;15117=387;15118=387;15119=241;15120=241
A104: 20108 | B104: =VLOOKUP(VALUE(LEFT(A104,2)),tb_shopType[[prefix]:[type]],2,0) -> 角色 | C104: =VLOOKUP(VALUE(MID(A104,LEN(A104)-2,1)),table_world[[id]:[name]],2,0) -> 地宫 | D104: 8 | E104: =_xlfn.LET(_xlpm._i,RIGHT(A104,2), INT(_xlpm._i/14)+2&"~"&3) -> 2~3 | F104: 3000~8;3250~1748;3500~21296;3750~16131;4000~759;4250~2 | G104: ="1~0.4~"&0.2+D104*0.02 -> 1~0.4~0.36 | H104: {=_xlfn.LET(_xlpm._tb,_xlfn.XLOOKUP($B104,tb_shopType[type],tb_shopType[shop_table_name]), _xlpm._col,MATCH($C104&"-"&TEXT(D104,"00"),INDIRECT(_xlpm._tb&"[#标题]"),0), _xlpm._arr_id,INDIRECT(_xlpm._tb&"[id]"), _xlpm._count,ROWS(_xlpm._arr_id), _xlpm._arr_weight,OFFSET(INDIRECT(_xlpm._tb),0,_xlpm._col-1,_xlpm._count,1), _xlpm._outcome_arr,_xlfn.MAP(_xlpm._arr_id,_xlpm._arr_weight,_xlfn.LAMBDA(_xlpm.a,_xlpm.b,IF(AND(_xlpm.a<>"",_xlpm.b<>0),_xlpm.a&"="&_xlpm.b,""))), _xlfn.TEXTJOIN(";",1,_xlpm._outcome_arr))} -> 15101=576;15102=576;15103=576;15104=576;15105=608;15106=608;15107=608;15108=617;15109=617;15110=617;15111=594;15112=594;15113=594;15114=527;15115=527;15116=416;15117=416;15118=416;15119=274;15120=274
A105: 20109 | B105: =VLOOKUP(VALUE(LEFT(A105,2)),tb_shopType[[prefix]:[type]],2,0) -> 角色 | C105: =VLOOKUP(VALUE(MID(A105,LEN(A105)-2,1)),table_world[[id]:[name]],2,0) -> 地宫 | D105: 9 | E105: =_xlfn.LET(_xlpm._i,RIGHT(A105,2), INT(_xlpm._i/14)+2&"~"&3) -> 2~3 | F105: 3500~32;3750~3599;4000~25158;4250~10934;4500~295 | G105: ="1~0.4~"&0.2+D105*0.02 -> 1~0.4~0.38 | H105: {=_xlfn.LET(_xlpm._tb,_xlfn.XLOOKUP($B105,tb_shopType[type],tb_shopType[shop_table_name]), _xlpm._col,MATCH($C105&"-"&TEXT(D105,"00"),INDIRECT(_xlpm._tb&"[#标题]"),0), _xlpm._arr_id,INDIRECT(_xlpm._tb&"[id]"), _xlpm._count,ROWS(_xlpm._arr_id), _xlpm._arr_weight,OFFSET(INDIRECT(_xlpm._tb),0,_xlpm._col-1,_xlpm._count,1), _xlpm._outcome_arr,_xlfn.MAP(_xlpm._arr_id,_xlpm._arr_weight,_xlfn.LAMBDA(_xlpm.a,_xlpm.b,IF(AND(_xlpm.a<>"",_xlpm.b<>0),_xlpm.a&"="&_xlpm.b,""))), _xlfn.TEXTJOIN(";",1,_xlpm._outcome_arr))} -> 15101=530;15102=530;15103=530;15104=530;15105=568;15106=568;15107=568;15108=588;15109=588;15110=588;15111=580;15112=580;15113=580;15114=532;15115=532;15116=438;15117=438;15118=438;15119=305;15120=305
A106: 20110 | B106: =VLOOKUP(VALUE(LEFT(A106,2)),tb_shopType[[prefix]:[type]],2,0) -> 角色 | C106: =VLOOKUP(VALUE(MID(A106,LEN(A106)-2,1)),table_world[[id]:[name]],2,0) -> 地宫 | D106: 10 | E106: =_xlfn.LET(_xlpm._i,RIGHT(A106,2), INT(_xlpm._i/14)+2&"~"&3) -> 2~3 | F106: 4000~102;4250~6631;4500~26596;4750~6631;5000~102 | G106: ="1~0.4~"&0.2+D106*0.02 -> 1~0.4~0.4 | H106: {=_xlfn.LET(_xlpm._tb,_xlfn.XLOOKUP($B106,tb_shopType[type],tb_shopType[shop_table_name]), _xlpm._col,MATCH($C106&"-"&TEXT(D106,"00"),INDIRECT(_xlpm._tb&"[#标题]"),0), _xlpm._arr_id,INDIRECT(_xlpm._tb&"[id]"), _xlpm._count,ROWS(_xlpm._arr_id), _xlpm._arr_weight,OFFSET(INDIRECT(_xlpm._tb),0,_xlpm._col-1,_xlpm._count,1), _xlpm._outcome_arr,_xlfn.MAP(_xlpm._arr_id,_xlpm._arr_weight,_xlfn.LAMBDA(_xlpm.a,_xlpm.b,IF(AND(_xlpm.a<>"",_xlpm.b<>0),_xlpm.a&"="&_xlpm.b,""))), _xlfn.TEXTJOIN(";",1,_xlpm._outcome_arr))} -> 15101=483;15102=483;15103=483;15104=483;15105=524;15106=524;15107=524;15108=553;15109=553;15110=553;15111=558;15112=558;15113=558;15114=527;15115=527;15116=451;15117=451;15118=451;15119=331;15120=331
A107: 20111 | B107: =VLOOKUP(VALUE(LEFT(A107,2)),tb_shopType[[prefix]:[type]],2,0) -> 角色 | C107: =VLOOKUP(VALUE(MID(A107,LEN(A107)-2,1)),table_world[[id]:[name]],2,0) -> 地宫 | D107: 11 | E107: =_xlfn.LET(_xlpm._i,RIGHT(A107,2), INT(_xlpm._i/14)+2&"~"&3) -> 2~3 | F107: 4500~295;4750~10934;5000~25158;5250~3599;5500~32 | G107: ="1~0.4~"&0.2+D107*0.02 -> 1~0.4~0.42 | H107: {=_xlfn.LET(_xlpm._tb,_xlfn.XLOOKUP($B107,tb_shopType[type],tb_shopType[shop_table_name]), _xlpm._col,MATCH($C107&"-"&TEXT(D107,"00"),INDIRECT(_xlpm._tb&"[#标题]"),0), _xlpm._arr_id,INDIRECT(_xlpm._tb&"[id]"), _xlpm._count,ROWS(_xlpm._arr_id), _xlpm._arr_weight,OFFSET(INDIRECT(_xlpm._tb),0,_xlpm._col-1,_xlpm._count,1), _xlpm._outcome_arr,_xlfn.MAP(_xlpm._arr_id,_xlpm._arr_weight,_xlfn.LAMBDA(_xlpm.a,_xlpm.b,IF(AND(_xlpm.a<>"",_xlpm.b<>0),_xlpm.a&"="&_xlpm.b,""))), _xlfn.TEXTJOIN(";",1,_xlpm._outcome_arr))} -> 15101=434;15102=434;15103=434;15104=434;15105=478;15106=478;15107=478;15108=512;15109=512;15110=512;15111=528;15112=528;15113=528;15114=513;15115=513;15116=456;15117=456;15118=456;15119=351;15120=351
A108: 20112 | B108: =VLOOKUP(VALUE(LEFT(A108,2)),tb_shopType[[prefix]:[type]],2,0) -> 角色 | C108: =VLOOKUP(VALUE(MID(A108,LEN(A108)-2,1)),table_world[[id]:[name]],2,0) -> 地宫 | D108: 12 | E108: =_xlfn.LET(_xlpm._i,RIGHT(A108,2), INT(_xlpm._i/14)+2&"~"&3) -> 2~3 | F108: 4750~2;5000~759;5250~16131;5500~21296;5750~1748;6000~8 | G108: ="1~0.4~"&0.2+D108*0.02 -> 1~0.4~0.44 | H108: {=_xlfn.LET(_xlpm._tb,_xlfn.XLOOKUP($B108,tb_shopType[type],tb_shopType[shop_table_name]), _xlpm._col,MATCH($C108&"-"&TEXT(D108,"00"),INDIRECT(_xlpm._tb&"[#标题]"),0), _xlpm._arr_id,INDIRECT(_xlpm._tb&"[id]"), _xlpm._count,ROWS(_xlpm._arr_id), _xlpm._arr_weight,OFFSET(INDIRECT(_xlpm._tb),0,_xlpm._col-1,_xlpm._count,1), _xlpm._outcome_arr,_xlfn.MAP(_xlpm._arr_id,_xlpm._arr_weight,_xlfn.LAMBDA(_xlpm.a,_xlpm.b,IF(AND(_xlpm.a<>"",_xlpm.b<>0),_xlpm.a&"="&_xlpm.b,""))), _xlfn.TEXTJOIN(";",1,_xlpm._outcome_arr))} -> 15101=387;15102=387;15103=387;15104=387;15105=430;15106=430;15107=430;15108=468;15109=468;15110=468;15111=492;15112=492;15113=492;15114=491;15115=491;15116=451;15117=451;15118=451;15119=364;15120=364
A109: 20113 | B109: =VLOOKUP(VALUE(LEFT(A109,2)),tb_shopType[[prefix]:[type]],2,0) -> 角色 | C109: =VLOOKUP(VALUE(MID(A109,LEN(A109)-2,1)),table_world[[id]:[name]],2,0) -> 地宫 | D109: 13 | E109: =_xlfn.LET(_xlpm._i,RIGHT(A109,2), INT(_xlpm._i/14)+2&"~"&3) -> 2~3 | F109: 5250~8;5500~1748;5750~21296;6000~16131;6250~759;6500~2 | G109: ="1~0.4~"&0.2+D109*0.02 -> 1~0.4~0.46 | H109: {=_xlfn.LET(_xlpm._tb,_xlfn.XLOOKUP($B109,tb_shopType[type],tb_shopType[shop_table_name]), _xlpm._col,MATCH($C109&"-"&TEXT(D109,"00"),INDIRECT(_xlpm._tb&"[#标题]"),0), _xlpm._arr_id,INDIRECT(_xlpm._tb&"[id]"), _xlpm._count,ROWS(_xlpm._arr_id), _xlpm._arr_weight,OFFSET(INDIRECT(_xlpm._tb),0,_xlpm._col-1,_xlpm._count,1), _xlpm._outcome_arr,_xlfn.MAP(_xlpm._arr_id,_xlpm._arr_weight,_xlfn.LAMBDA(_xlpm.a,_xlpm.b,IF(AND(_xlpm.a<>"",_xlpm.b<>0),_xlpm.a&"="&_xlpm.b,""))), _xlfn.TEXTJOIN(";",1,_xlpm._outcome_arr))} -> 15101=340;15102=340;15103=340;15104=340;15105=383;15106=383;15107=383;15108=422;15109=422;15110=422;15111=452;15112=452;15113=452;15114=461;15115=461;15116=438;15117=438;15118=438;15119=368;15120=368
... A116: 20120 | B116: =VLOOKUP(VALUE(LEFT(A116,2)),tb_shopType[[prefix]:[type]],2,0) -> 角色 | C116: =VLOOKUP(VALUE(MID(A116,LEN(A116)-2,1)),table_world[[id]:[name]],2,0) -> 地宫 | D116: 20 | E116: =_xlfn.LET(_xlpm._i,RIGHT(A116,2), INT(_xlpm._i/14)+2&"~"&3) -> 3~3 | F116: 8500~102 | G116: ="1~0.4~"&0.2+D116*0.02 -> 1~0.4~0.6 | H116: {=_xlfn.LET(_xlpm._tb,_xlfn.XLOOKUP($B116,tb_shopType[type],tb_shopType[shop_table_name]), _xlpm._col,MATCH($C116&"-"&TEXT(D116,"00"),INDIRECT(_xlpm._tb&"[#标题]"),0), _xlpm._arr_id,INDIRECT(_xlpm._tb&"[id]"), _xlpm._count,ROWS(_xlpm._arr_id), _xlpm._arr_weight,OFFSET(INDIRECT(_xlpm._tb),0,_xlpm._col-1,_xlpm._count,1), _xlpm._outcome_arr,_xlfn.MAP(_xlpm._arr_id,_xlpm._arr_weight,_xlfn.LAMBDA(_xlpm.a,_xlpm.b,IF(AND(_xlpm.a<>"",_xlpm.b<>0),_xlpm.a&"="&_xlpm.b,""))), _xlfn.TEXTJOIN(";",1,_xlpm._outcome_arr))} -> 15101=102;15102=102;15103=102;15104=102;15105=119;15106=119;15107=119;15108=138;15109=138;15110=138;15111=160;15112=160;15113=160;15114=181;15115=181;15116=200;15117=200;15118=200;15119=206;15120=206
A118: 20401 | B118: =VLOOKUP(VALUE(LEFT(A118,2)),tb_shopType[[prefix]:[type]],2,0) -> 角色 | C118: =VLOOKUP(VALUE(MID(A118,LEN(A118)-2,1)),table_world[[id]:[name]],2,0) -> 树梢 | D118: 1 | E118: =_xlfn.LET(_xlpm._i,RIGHT(A118,2), INT(_xlpm._i/14)+2&"~"&3) -> 2~3 | F118: 500~25158;750~3599;1000~32 | G118: 1~1~0 | H118: {=_xlfn.LET(_xlpm._tb,_xlfn.XLOOKUP($B118,tb_shopType[type],tb_shopType[shop_table_name]), _xlpm._col,MATCH($C118&"-"&TEXT(D118,"00"),INDIRECT(_xlpm._tb&"[#标题]"),0), _xlpm._arr_id,INDIRECT(_xlpm._tb&"[id]"), _xlpm._count,ROWS(_xlpm._arr_id), _xlpm._arr_weight,OFFSET(INDIRECT(_xlpm._tb),0,_xlpm._col-1,_xlpm._count,1), _xlpm._outcome_arr,_xlfn.MAP(_xlpm._arr_id,_xlpm._arr_weight,_xlfn.LAMBDA(_xlpm.a,_xlpm.b,IF(AND(_xlpm.a<>"",_xlpm.b<>0),_xlpm.a&"="&_xlpm.b,""))), _xlfn.TEXTJOIN(";",1,_xlpm._outcome_arr))} -> 15101=756;15102=756;15103=756;15104=756;15105=692;15106=692;15107=692;15108=588;15109=588;15110=588;15111=452;15112=452;15113=452;15114=301;15115=301;15116=164;15117=164;15118=164;15119=67;15120=67
A119: 20402 | B119: =VLOOKUP(VALUE(LEFT(A119,2)),tb_shopType[[prefix]:[type]],2,0) -> 角色 | C119: =VLOOKUP(VALUE(MID(A119,LEN(A119)-2,1)),table_world[[id]:[name]],2,0) -> 树梢 | D119: 2 | E119: =_xlfn.LET(_xlpm._i,RIGHT(A119,2), INT(_xlpm._i/14)+2&"~"&3) -> 2~3 | F119: 500~759;750~16131;1000~21296;1250~1748;1500~8 | G119: ="1~0.4~"&0.2+D119*0.02 -> 1~0.4~0.24 | H119: {=_xlfn.LET(_xlpm._tb,_xlfn.XLOOKUP($B119,tb_shopType[type],tb_shopType[shop_table_name]), _xlpm._col,MATCH($C119&"-"&TEXT(D119,"00"),INDIRECT(_xlpm._tb&"[#标题]"),0), _xlpm._arr_id,INDIRECT(_xlpm._tb&"[id]"), _xlpm._count,ROWS(_xlpm._arr_id), _xlpm._arr_weight,OFFSET(INDIRECT(_xlpm._tb),0,_xlpm._col-1,_xlpm._count,1), _xlpm._outcome_arr,_xlfn.MAP(_xlpm._arr_id,_xlpm._arr_weight,_xlfn.LAMBDA(_xlpm.a,_xlpm.b,IF(AND(_xlpm.a<>"",_xlpm.b<>0),_xlpm.a&"="&_xlpm.b,""))), _xlfn.TEXTJOIN(";",1,_xlpm._outcome_arr))} -> 15101=752;15102=752;15103=752;15104=752;15105=705;15106=705;15107=705;15108=617;15109=617;15110=617;15111=492;15112=492;15113=492;15114=344;15115=344;15116=200;15117=200;15118=200;15119=88;15120=88
A120: 20403 | B120: =VLOOKUP(VALUE(LEFT(A120,2)),tb_shopType[[prefix]:[type]],2,0) -> 角色 | C120: =VLOOKUP(VALUE(MID(A120,LEN(A120)-2,1)),table_world[[id]:[name]],2,0) -> 树梢 | D120: 3 | E120: =_xlfn.LET(_xlpm._i,RIGHT(A120,2), INT(_xlpm._i/14)+2&"~"&3) -> 2~3 | F120: 750~8;1000~1748;1250~21296;1500~16131;1750~759;2000~2 | G120: ="1~0.4~"&0.2+D120*0.02 -> 1~0.4~0.26 | H120: {=_xlfn.LET(_xlpm._tb,_xlfn.XLOOKUP($B120,tb_shopType[type],tb_shopType[shop_table_name]), _xlpm._col,MATCH($C120&"-"&TEXT(D120,"00"),INDIRECT(_xlpm._tb&"[#标题]"),0), _xlpm._arr_id,INDIRECT(_xlpm._tb&"[id]"), _xlpm._count,ROWS(_xlpm._arr_id), _xlpm._arr_weight,OFFSET(INDIRECT(_xlpm._tb),0,_xlpm._col-1,_xlpm._count,1), _xlpm._outcome_arr,_xlfn.MAP(_xlpm._arr_id,_xlpm._arr_weight,_xlfn.LAMBDA(_xlpm.a,_xlpm.b,IF(AND(_xlpm.a<>"",_xlpm.b<>0),_xlpm.a&"="&_xlpm.b,""))), _xlfn.TEXTJOIN(";",1,_xlpm._outcome_arr))} -> 15101=739;15102=739;15103=739;15104=739;15105=709;15106=709;15107=709;15108=639;15109=639;15110=639;15111=528;15112=528;15113=528;15114=386;15115=386;15116=237;15117=237;15118=237;15119=113;15120=113
A121: 20404 | B121: =VLOOKUP(VALUE(LEFT(A121,2)),tb_shopType[[prefix]:[type]],2,0) -> 角色 | C121: =VLOOKUP(VALUE(MID(A121,LEN(A121)-2,1)),table_world[[id]:[name]],2,0) -> 树梢 | D121: 4 | E121: =_xlfn.LET(_xlpm._i,RIGHT(A121,2), INT(_xlpm._i/14)+2&"~"&3) -> 2~3 | F121: 1250~32;1500~3599;1750~25158;2000~10934;2250~295 | G121: ="1~0.4~"&0.2+D121*0.02 -> 1~0.4~0.28 | H121: {=_xlfn.LET(_xlpm._tb,_xlfn.XLOOKUP($B121,tb_shopType[type],tb_shopType[shop_table_name]), _xlpm._col,MATCH($C121&"-"&TEXT(D121,"00"),INDIRECT(_xlpm._tb&"[#标题]"),0), _xlpm._arr_id,INDIRECT(_xlpm._tb&"[id]"), _xlpm._count,ROWS(_xlpm._arr_id), _xlpm._arr_weight,OFFSET(INDIRECT(_xlpm._tb),0,_xlpm._col-1,_xlpm._count,1), _xlpm._outcome_arr,_xlfn.MAP(_xlpm._arr_id,_xlpm._arr_weight,_xlfn.LAMBDA(_xlpm.a,_xlpm.b,IF(AND(_xlpm.a<>"",_xlpm.b<>0),_xlpm.a&"="&_xlpm.b,""))), _xlfn.TEXTJOIN(";",1,_xlpm._outcome_arr))} -> 15101=719;15102=719;15103=719;15104=719;15105=705;15106=705;15107=705;15108=653;15109=653;15110=653;15111=558;15112=558;15113=558;15114=426;15115=426;15116=277;15117=277;15118=277;15119=141;15120=141
A122: 20405 | B122: =VLOOKUP(VALUE(LEFT(A122,2)),tb_shopType[[prefix]:[type]],2,0) -> 角色 | C122: =VLOOKUP(VALUE(MID(A122,LEN(A122)-2,1)),table_world[[id]:[name]],2,0) -> 树梢 | D122: 5 | E122: =_xlfn.LET(_xlpm._i,RIGHT(A122,2), INT(_xlpm._i/14)+2&"~"&3) -> 2~3 | F122: 1750~102;2000~6631;2250~26596;2500~6631;2750~102 | G122: ="1~0.4~"&0.2+D122*0.02 -> 1~0.4~0.3 | H122: {=_xlfn.LET(_xlpm._tb,_xlfn.XLOOKUP($B122,tb_shopType[type],tb_shopType[shop_table_name]), _xlpm._col,MATCH($C122&"-"&TEXT(D122,"00"),INDIRECT(_xlpm._tb&"[#标题]"),0), _xlpm._arr_id,INDIRECT(_xlpm._tb&"[id]"), _xlpm._count,ROWS(_xlpm._arr_id), _xlpm._arr_weight,OFFSET(INDIRECT(_xlpm._tb),0,_xlpm._col-1,_xlpm._count,1), _xlpm._outcome_arr,_xlfn.MAP(_xlpm._arr_id,_xlpm._arr_weight,_xlfn.LAMBDA(_xlpm.a,_xlpm.b,IF(AND(_xlpm.a<>"",_xlpm.b<>0),_xlpm.a&"="&_xlpm.b,""))), _xlfn.TEXTJOIN(";",1,_xlpm._outcome_arr))} -> 15101=692;15102=692;15103=692;15104=692;15105=692;15106=692;15107=692;15108=657;15109=657;15110=657;15111=580;15112=580;15113=580;15114=461;15115=461;15116=316;15117=316;15118=316;15119=173;15120=173
A123: 20406 | B123: =VLOOKUP(VALUE(LEFT(A123,2)),tb_shopType[[prefix]:[type]],2,0) -> 角色 | C123: =VLOOKUP(VALUE(MID(A123,LEN(A123)-2,1)),table_world[[id]:[name]],2,0) -> 树梢 | D123: 6 | E123: =_xlfn.LET(_xlpm._i,RIGHT(A123,2), INT(_xlpm._i/14)+2&"~"&3) -> 2~3 | F123: 2250~295;2500~10934;2750~25158;3000~3599;3250~32 | G123: ="1~0.4~"&0.2+D123*0.02 -> 1~0.4~0.32 | H123: {=_xlfn.LET(_xlpm._tb,_xlfn.XLOOKUP($B123,tb_shopType[type],tb_shopType[shop_table_name]), _xlpm._col,MATCH($C123&"-"&TEXT(D123,"00"),INDIRECT(_xlpm._tb&"[#标题]"),0), _xlpm._arr_id,INDIRECT(_xlpm._tb&"[id]"), _xlpm._count,ROWS(_xlpm._arr_id), _xlpm._arr_weight,OFFSET(INDIRECT(_xlpm._tb),0,_xlpm._col-1,_xlpm._count,1), _xlpm._outcome_arr,_xlfn.MAP(_xlpm._arr_id,_xlpm._arr_weight,_xlfn.LAMBDA(_xlpm.a,_xlpm.b,IF(AND(_xlpm.a<>"",_xlpm.b<>0),_xlpm.a&"="&_xlpm.b,""))), _xlfn.TEXTJOIN(";",1,_xlpm._outcome_arr))} -> 15101=658;15102=658;15103=658;15104=658;15105=671;15106=671;15107=671;15108=653;15109=653;15110=653;15111=594;15112=594;15113=594;15114=491;15115=491;15116=353;15117=353;15118=353;15119=206;15120=206
...

Sheet shop_ui
A1: id | B1: name | E1: icon
A2: string key | B2: string | E2: string
A3: 商店 种类 | B3: 名称 用于选路界面 | D3: 辅助列 图集编号 | E3: 商店icon 用于选路界面 填写资源address
A4: repair | B4: ="safe_zone_"&D4 -> safe_zone_0 | C4: 修理匠 | D4: 0 | E4: ="icon_store[namecard-npc_"&D4&"]" -> icon_store[namecard-npc_0]
A5: relic | B5: ="safe_zone_"&D5 -> safe_zone_1 | C5: 饰品商店 | D5: 1 | E5: ="icon_store[namecard-npc_"&D5&"]" -> icon_store[namecard-npc_1]
A6: device | B6: ="safe_zone_"&D6 -> safe_zone_2 | C6: 设备商店 | D6: 2 | E6: ="icon_store[namecard-npc_"&D6&"]" -> icon_store[namecard-npc_2]
A7: role | B7: ="safe_zone_"&D7 -> safe_zone_3 | C7: 英雄营地 | D7: 3 | E7: ="icon_store[namecard-npc_"&D7&"]" -> icon_store[namecard-npc_3]
A8: elite_relic | B8: ="safe_zone_"&D8 -> safe_zone_5 | C8: 饰品奖励 | D8: 5 | E8: ="icon_store[namecard-npc_"&D8&"]" -> icon_store[namecard-npc_5]

Sheet -10.device
A1: id | B1: name | C1: type | D1: rank | E1: 地宫-01 | F1: 地宫-02 | G1: 地宫-03 | H1: 地宫-04 | I1: 地宫-05 | J1: 地宫-06 | K1: 地宫-07 | L1: 地宫-08 | M1: 地宫-09 | N1: 地宫-10 | O1: 地宫-11 | P1: 地宫-12 | Q1: 地宫-13 | R1: 地宫-14 | S1: 地宫-15 | T1: 地宫-16 | U1: 地宫-17 | V1: 地宫-18 | W1: 地宫-19 | X1: 地宫-20 | Y1: 树梢-01 | Z1: 树梢-02 | AA1: 树梢-03 | AB1: 树梢-04 | AC1: 树梢-05 | AD1: 树梢-06 | AE1: 树梢-07 | AF1: 树梢-08 | AG1: 树梢-09 | AH1: 树梢-10 | AI1: 树梢-11 | AJ1: 树梢-12 | AK1: 树梢-13 | AL1: 树梢-14 | AM1: 树梢-15 | AN1: 树梢-16 | AO1: 树梢-17 | AP1: 树梢-18 | AQ1: 树梢-19 | AR1: 树梢-20 | AS1: 荒漠-01 | AT1: 荒漠-02 | AU1: 荒漠-03 | AV1: 荒漠-04 | AW1: 荒漠-05 | AX1: 荒漠-06 | AY1: 荒漠-07 | AZ1: 荒漠-08 | BA1: 荒漠-09 | BB1: 荒漠-10 | BC1: 荒漠-11 | BD1: 荒漠-12 | BE1: 荒漠-13 | BF1: 荒漠-14 | BG1: 荒漠-15 | BH1: 荒漠-16 | BI1: 荒漠-17 | BJ1: 荒漠-18 | BK1: 荒漠-19 | BL1: 荒漠-20 | BM1: 大湖-01 | BN1: 大湖-02 | BO1: 大湖-03 | BP1: 大湖-04 | BQ1: 大湖-05 | BR1: 大湖-06 | BS1: 大湖-07 | BT1: 大湖-08 | BU1: 大湖-09 | BV1: 大湖-10 | BW1: 大湖-11 | BX1: 大湖-12 | BY1: 大湖-13 | BZ1: 大湖-14 | CA1: 大湖-15 | CB1: 大湖-16 | CC1: 大湖-17 | CD1: 大湖-18 | CE1: 大湖-19 | CF1: 大湖-20
A2: 1210101 | B2: 硬木车轮 | C2: 车轮 | D2: 模板 | E2: 0 | F2: 0 | G2: 0 | H2: 0 | I2: 0 | J2: 0 | K2: 0 | L2: 0 | M2: 0 | N2: 0 | O2: 0 | P2: 0 | Q2: 0 | R2: 0 | S2: 0 | T2: 0 | U2: 0 | V2: 0 | W2: 0 | X2: 0 | Y2: 0 | Z2: 0 | AA2: 0 | AB2: 0 | AC2: 0 | AD2: 0 | AE2: 0 | AF2: 0 | AG2: 0 | AH2: 0 | AI2: 0 | AJ2: 0 | AK2: 0 | AL2: 0 | AM2: 0 | AN2: 0 | AO2: 0 | AP2: 0 | AQ2: 0 | AR2: 0 | AS2: 0 | AT2: 0 | AU2: 0 | AV2: 0 | AW2: 0 | AX2: 0 | AY2: 0 | AZ2: 0 | BA2: 0 | BB2: 0 | BC2: 0 | BD2: 0 | BE2: 0 | BF2: 0 | BG2: 0 | BH2: 0 | BI2: 0 | BJ2: 0 | BK2: 0 | BL2: 0
A3: 12101011 | B3: 硬木车轮 Lv.1 | C3: 车轮 | D3: 1 | BM3: 99999 | BN3: {=INDEX(_xlfn.ANCHORARRAY(_xlfn.XLOOKUP($D3,'-ref_Distribution'!$B$117:$B$121,'-ref_Distribution'!$G$117:$G$121)),RIGHT(BN$1,2))} -> 72 | BO3: {=INDEX(_xlfn.ANCHORARRAY(_xlfn.XLOOKUP($D3,'-ref_Distribution'!$B$117:$B$121,'-ref_Distribution'!$G$117:$G$121)),RIGHT(BO$1,2))} -> 66 | BP3: {=INDEX(_xlfn.ANCHORARRAY(_xlfn.XLOOKUP($D3,'-ref_Distribution'!$B$117:$B$121,'-ref_Distribution'!$G$117:$G$121)),RIGHT(BP$1,2))} -> 61 | BQ3: {=INDEX(_xlfn.ANCHORARRAY(_xlfn.XLOOKUP($D3,'-ref_Distribution'!$B$117:$B$121,'-ref_Distribution'!$G$117:$G$121)),RIGHT(BQ$1,2))} -> 58 | BR3: {=INDEX(_xlfn.ANCHORARRAY(_xlfn.XLOOKUP($D3,'-ref_Distribution'!$B$117:$B$121,'-ref_Distribution'!$G$117:$G$121)),RIGHT(BR$1,2))} -> 55 | BS3: {=INDEX(_xlfn.ANCHORARRAY(_xlfn.XLOOKUP($D3,'-ref_Distribution'!$B$117:$B$121,'-ref_Distribution'!$G$117:$G$121)),RIGHT(BS$1,2))} -> 52 | BT3: {=INDEX(_xlfn.ANCHORARRAY(_xlfn.XLOOKUP($D3,'-ref_Distribution'!$B$117:$B$121,'-ref_Distribution'!$G$117:$G$121)),RIGHT(BT$1,2))} -> 50 | BU3: {=INDEX(_xlfn.ANCHORARRAY(_xlfn.XLOOKUP($D3,'-ref_Distribution'!$B$117:$B$121,'-ref_Distribution'!$G$117:$G$121)),RIGHT(BU$1,2))} -> 48 | ... CF3: {=INDEX(_xlfn.ANCHORARRAY(_xlfn.XLOOKUP($D3,'-ref_Distribution'!$B$117:$B$121,'-ref_Distribution'!$G$117:$G$121)),RIGHT(CF$1,2))} -> 38
A4: 12101012 | B4: 硬木车轮 Lv.2 | C4: 车轮 | D4: 2 | BM4: {=INDEX(_xlfn.ANCHORARRAY(_xlfn.XLOOKUP($D4,'-ref_Distribution'!$B$117:$B$121,'-ref_Distribution'!$G$117:$G$121)),RIGHT(BM$1,2))} -> 0 | BN4: {=INDEX(_xlfn.ANCHORARRAY(_xlfn.XLOOKUP($D4,'-ref_Distribution'!$B$117:$B$121,'-ref_Distribution'!$G$117:$G$121)),RIGHT(BN$1,2))} -> 5 | BO4: {=INDEX(_xlfn.ANCHORARRAY(_xlfn.XLOOKUP($D4,'-ref_Distribution'!$B$117:$B$121,'-ref_Distribution'!$G$117:$G$121)),RIGHT(BO$1,2))} -> 12 | BP4: {=INDEX(_xlfn.ANCHORARRAY(_xlfn.XLOOKUP($D4,'-ref_Distribution'!$B$117:$B$121,'-ref_Distribution'!$G$117:$G$121)),RIGHT(BP$1,2))} -> 16 | BQ4: {=INDEX(_xlfn.ANCHORARRAY(_xlfn.XLOOKUP($D4,'-ref_Distribution'!$B$117:$B$121,'-ref_Distribution'!$G$117:$G$121)),RIGHT(BQ$1,2))} -> 19 | BR4: {=INDEX(_xlfn.ANCHORARRAY(_xlfn.XLOOKUP($D4,'-ref_Distribution'!$B$117:$B$121,'-ref_Distribution'!$G$117:$G$121)),RIGHT(BR$1,2))} -> 22 | BS4: {=INDEX(_xlfn.ANCHORARRAY(_xlfn.XLOOKUP($D4,'-ref_Distribution'!$B$117:$B$121,'-ref_Distribution'!$G$117:$G$121)),RIGHT(BS$1,2))} -> 23 | BT4: {=INDEX(_xlfn.ANCHORARRAY(_xlfn.XLOOKUP($D4,'-ref_Distribution'!$B$117:$B$121,'-ref_Distribution'!$G$117:$G$121)),RIGHT(BT$1,2))} -> 25 | ... CF4: {=INDEX(_xlfn.ANCHORARRAY(_xlfn.XLOOKUP($D4,'-ref_Distribution'!$B$117:$B$121,'-ref_Distribution'!$G$117:$G$121)),RIGHT(CF$1,2))} -> 31
A5: 12101013 | B5: 硬木车轮 Lv.3 | C5: 车轮 | D5: 3 | BM5: {=INDEX(_xlfn.ANCHORARRAY(_xlfn.XLOOKUP($D5,'-ref_Distribution'!$B$117:$B$121,'-ref_Distribution'!$G$117:$G$121)),RIGHT(BM$1,2))} -> 0 | BN5: {=INDEX(_xlfn.ANCHORARRAY(_xlfn.XLOOKUP($D5,'-ref_Distribution'!$B$117:$B$121,'-ref_Distribution'!$G$117:$G$121)),RIGHT(BN$1,2))} -> 0 | BO5: {=INDEX(_xlfn.ANCHORARRAY(_xlfn.XLOOKUP($D5,'-ref_Distribution'!$B$117:$B$121,'-ref_Distribution'!$G$117:$G$121)),RIGHT(BO$1,2))} -> 1 | BP5: {=INDEX(_xlfn.ANCHORARRAY(_xlfn.XLOOKUP($D5,'-ref_Distribution'!$B$117:$B$121,'-ref_Distribution'!$G$117:$G$121)),RIGHT(BP$1,2))} -> 3 | BQ5: {=INDEX(_xlfn.ANCHORARRAY(_xlfn.XLOOKUP($D5,'-ref_Distribution'!$B$117:$B$121,'-ref_Distribution'!$G$117:$G$121)),RIGHT(BQ$1,2))} -> 6 | BR5: {=INDEX(_xlfn.ANCHORARRAY(_xlfn.XLOOKUP($D5,'-ref_Distribution'!$B$117:$B$121,'-ref_Distribution'!$G$117:$G$121)),RIGHT(BR$1,2))} -> 8 | BS5: {=INDEX(_xlfn.ANCHORARRAY(_xlfn.XLOOKUP($D5,'-ref_Distribution'!$B$117:$B$121,'-ref_Distribution'!$G$117:$G$121)),RIGHT(BS$1,2))} -> 9 | BT5: {=INDEX(_xlfn.ANCHORARRAY(_xlfn.XLOOKUP($D5,'-ref_Distribution'!$B$117:$B$121,'-ref_Distribution'!$G$117:$G$121)),RIGHT(BT$1,2))} -> 10 | ... CF5: {=INDEX(_xlfn.ANCHORARRAY(_xlfn.XLOOKUP($D5,'-ref_Distribution'!$B$117:$B$121,'-ref_Distribution'!$G$117:$G$121)),RIGHT(CF$1,2))} -> 17
A6: 1210102 | B6: 履带 | C6: 车轮 | E6: 0 | F6: 0 | G6: 0 | H6: 0 | I6: 0 | J6: 0 | K6: 0 | L6: 0 | M6: 0 | N6: 0 | O6: 0 | P6: 0 | Q6: 0 | R6: 0 | S6: 0 | T6: 0 | U6: 0 | V6: 0 | W6: 0 | X6: 0 | Y6: 0 | Z6: 0 | AA6: 0 | AB6: 0 | AC6: 0 | AD6: 0 | AE6: 0 | AF6: 0 | AG6: 0 | AH6: 0 | AI6: 0 | AJ6: 0 | AK6: 0 | AL6: 0 | AM6: 0 | AN6: 0 | AO6: 0 | AP6: 0 | AQ6: 0 | AR6: 0 | AS6: 0 | AT6: 0 | AU6: 0 | AV6: 0 | AW6: 0 | AX6: 0 | AY6: 0 | AZ6: 0 | BA6: 0 | BB6: 0 | BC6: 0 | BD6: 0 | BE6: 0 | BF6: 0 | BG6: 0 | BH6: 0 | BI6: 0 | BJ6: 0 | BK6: 0 | BL6: 0
A7: 1211801 | B7: 救生圈 | C7: 车轮 | E7: 0 | F7: 0 | G7: 0 | H7: 0 | I7: 0 | J7: 0 | K7: 0 | L7: 0 | M7: 0 | N7: 0 | O7: 0 | P7: 0 | Q7: 0 | R7: 0 | S7: 0 | T7: 0 | U7: 0 | V7: 0 | W7: 0 | X7: 0 | Y7: 0 | Z7: 0 | AA7: 0 | AB7: 0 | AC7: 0 | AD7: 0 | AE7: 0 | AF7: 0 | AG7: 0 | AH7: 0 | AI7: 0 | AJ7: 0 | AK7: 0 | AL7: 0 | AM7: 0 | AN7: 0 | AO7: 0 | AP7: 0 | AQ7: 0 | AR7: 0 | AS7: 0 | AT7: 0 | AU7: 0 | AV7: 0 | AW7: 0 | AX7: 0 | AY7: 0 | AZ7: 0 | BA7: 0 | BB7: 0 | BC7: 0 | BD7: 0 | BE7: 0 | BF7: 0 | BG7: 0 | BH7: 0 | BI7: 0 | BJ7: 0 | BK7: 0 | BL7: 0
A9: 1310101 | B9: 短匕 | C9: 近战 | E9: 0 | F9: 0 | G9: 0 | H9: 0 | I9: 0 | J9: 0 | K9: 0 | L9: 0 | M9: 0 | N9: 0 | O9: 0 | P9: 0 | Q9: 0 | R9: 0 | S9: 0 | T9: 0 | U9: 0 | V9: 0 | W9: 0 | X9: 0 | Y9: 0 | Z9: 0 | AA9: 0 | AB9: 0 | AC9: 0 | AD9: 0 | AE9: 0 | AF9: 0 | AG9: 0 | AH9: 0 | AI9: 0 | AJ9: 0 | AK9: 0 | AL9: 0 | AM9: 0 | AN9: 0 | AO9: 0 | AP9: 0 | AQ9: 0 | AR9: 0 | AS9: 0 | AT9: 0 | AU9: 0 | AV9: 0 | AW9: 0 | AX9: 0 | AY9: 0 | AZ9: 0 | BA9: 0 | BB9: 0 | BC9: 0 | BD9: 0 | BE9: 0 | BF9: 0 | BG9: 0 | BH9: 0 | BI9: 0 | BJ9: 0 | BK9: 0 | BL9: 0
A10: 1310102 | B10: 砍刀 | C10: 近战 | E10: 100 | F10: 100 | G10: 100 | H10: 100 | I10: 100 | J10: 100 | K10: 100 | L10: 50 | M10: 50 | N10: 50 | O10: 50 | P10: 18 | Q10: 18 | R10: 18 | S10: 18 | T10: 18 | U10: 18 | V10: 18 | W10: 18 | X10: 18 | Y10: 100 | Z10: 100 | AA10: 100 | AB10: 100 | AC10: 100 | AD10: 100 | AE10: 100 | AF10: 50 | AG10: 50 | AH10: 50 | AI10: 50 | AJ10: 18 | AK10: 18 | AL10: 18 | AM10: 18 | AN10: 18 | AO10: 18 | AP10: 18 | AQ10: 18 | AR10: 18 | AS10: 100 | AT10: 100 | AU10: 100 | AV10: 100 | AW10: 100 | AX10: 100 | AY10: 100 | AZ10: 50 | BA10: 50 | BB10: 50 | BC10: 50 | BD10: 18 | BE10: 18 | BF10: 18 | BG10: 18 | BH10: 18 | BI10: 18 | BJ10: 18 | BK10: 18 | BL10: 18
A11: 1310103 | B11: 大剑 | C11: 近战 | E11: 0 | F11: 0 | G11: 0 | H11: 0 | I11: 0 | J11: 0 | K11: 0 | L11: 20 | M11: 20 | N11: 20 | O11: 20 | P11: 100 | Q11: 100 | R11: 100 | S11: 100 | T11: 100 | U11: 100 | V11: 100 | W11: 100 | X11: 100 | Y11: 0 | Z11: 0 | AA11: 0 | AB11: 0 | AC11: 0 | AD11: 0 | AE11: 0 | AF11: 20 | AG11: 20 | AH11: 20 | AI11: 20 | AJ11: 100 | AK11: 100 | AL11: 100 | AM11: 100 | AN11: 100 | AO11: 100 | AP11: 100 | AQ11: 100 | AR11: 100 | AS11: 0 | AT11: 0 | AU11: 0 | AV11: 0 | AW11: 0 | AX11: 0 | AY11: 0 | AZ11: 20 | BA11: 20 | BB11: 20 | BC11: 20 | BD11: 100 | BE11: 100 | BF11: 100 | BG11: 100 | BH11: 100 | BI11: 100 | BJ11: 100 | BK11: 100 | BL11: 100
A12: 1310104 | B12: 长矛 | C12: 近战 | E12: 0 | F12: 0 | G12: 0 | H12: 20 | I12: 20 | J12: 20 | K12: 20 | L12: 100 | M12: 100 | N12: 100 | O12: 100 | P12: 50 | Q12: 50 | R12: 50 | S12: 50 | T12: 50 | U12: 50 | V12: 50 | W12: 50 | X12: 50 | Y12: 0 | Z12: 0 | AA12: 0 | AB12: 20 | AC12: 20 | AD12: 20 | AE12: 20 | AF12: 100 | AG12: 100 | AH12: 100 | AI12: 100 | AJ12: 50 | AK12: 50 | AL12: 50 | AM12: 50 | AN12: 50 | AO12: 50 | AP12: 50 | AQ12: 50 | AR12: 50 | AS12: 0 | AT12: 0 | AU12: 0 | AV12: 20 | AW12: 20 | AX12: 20 | AY12: 20 | AZ12: 100 | BA12: 100 | BB12: 100 | BC12: 100 | BD12: 50 | BE12: 50 | BF12: 50 | BG12: 50 | BH12: 50 | BI12: 50 | BJ12: 50 | BK12: 50 | BL12: 50
A13: 1310105 | B13: 充气球棒(模板) | C13: 近战 | D13: 模板
A14: 13101050 | B14: 充气球棒 Lv.0 | C14: 近战 | D14: 0 | E14: 100 | F14: 100 | G14: 100 | H14: 100 | I14: 100 | J14: 50 | K14: 50 | L14: 50 | M14: 50 | N14: 50 | O14: 50 | P14: 18 | Q14: 18 | R14: 18 | S14: 18 | T14: 18 | U14: 0 | V14: 0 | W14: 0 | X14: 0 | Y14: 100 | Z14: 100 | AA14: 100 | AB14: 100 | AC14: 100 | AD14: 50 | AE14: 50 | AF14: 50 | AG14: 50 | AH14: 50 | AI14: 50 | AJ14: 18 | AK14: 18 | AL14: 18 | AM14: 18 | AN14: 18 | AO14: 0 | AP14: 0 | AQ14: 0 | AR14: 0 | AS14: 100 | AT14: 100 | AU14: 100 | AV14: 100 | AW14: 100 | AX14: 50 | AY14: 50 | AZ14: 50 | BA14: 50 | BB14: 50 | BC14: 50 | BD14: 18 | BE14: 18 | BF14: 18 | BG14: 18 | BH14: 18 | BI14: 0 | BJ14: 0 | BK14: 0 | BL14: 0 | BM14: {=INDEX(_xlfn.ANCHORARRAY(_xlfn.XLOOKUP($D14,'-ref_Distribution'!$B$117:$B$121,'-ref_Distribution'!$G$117:$G$121)),RIGHT(BM$1,2))} -> 130 | BN14: {=INDEX(_xlfn.ANCHORARRAY(_xlfn.XLOOKUP($D14,'-ref_Distribution'!$B$117:$B$121,'-ref_Distribution'!$G$117:$G$121)),RIGHT(BN$1,2))} -> 84 | BO14: {=INDEX(_xlfn.ANCHORARRAY(_xlfn.XLOOKUP($D14,'-ref_Distribution'!$B$117:$B$121,'-ref_Distribution'!$G$117:$G$121)),RIGHT(BO$1,2))} -> 65 | BP14: {=INDEX(_xlfn.ANCHORARRAY(_xlfn.XLOOKUP($D14,'-ref_Distribution'!$B$117:$B$121,'-ref_Distribution'!$G$117:$G$121)),RIGHT(BP$1,2))} -> 54 | BQ14: {=INDEX(_xlfn.ANCHORARRAY(_xlfn.XLOOKUP($D14,'-ref_Distribution'!$B$117:$B$121,'-ref_Distribution'!$G$117:$G$121)),RIGHT(BQ$1,2))} -> 47 | BR14: {=INDEX(_xlfn.ANCHORARRAY(_xlfn.XLOOKUP($D14,'-ref_Distribution'!$B$117:$B$121,'-ref_Distribution'!$G$117:$G$121)),RIGHT(BR$1,2))} -> 41 | BS14: {=INDEX(_xlfn.ANCHORARRAY(_xlfn.XLOOKUP($D14,'-ref_Distribution'!$B$117:$B$121,'-ref_Distribution'!$G$117:$G$121)),RIGHT(BS$1,2))} -> 38 | BT14: {=INDEX(_xlfn.ANCHORARRAY(_xlfn.XLOOKUP($D14,'-ref_Distribution'!$B$117:$B$121,'-ref_Distribution'!$G$117:$G$121)),RIGHT(BT$1,2))} -> 34 | ... CF14: {=INDEX(_xlfn.ANCHORARRAY(_xlfn.XLOOKUP($D14,'-ref_Distribution'!$B$117:$B$121,'-ref_Distribution'!$G$117:$G$121)),RIGHT(CF$1,2))} -> 18
A15: 13101051 | B15: 充气球棒 Lv.1 | C15: 近战 | D15: 1 | E15: 10 | F15: 10 | G15: 10 | H15: 10 | I15: 100 | J15: 100 | K15: 100 | L15: 100 | M15: 100 | N15: 50 | O15: 50 | P15: 50 | Q15: 50 | R15: 50 | S15: 50 | T15: 18 | U15: 18 | V15: 18 | W15: 18 | X15: 18 | Y15: 10 | Z15: 10 | AA15: 10 | AB15: 10 | AC15: 100 | AD15: 100 | AE15: 100 | AF15: 100 | AG15: 100 | AH15: 50 | AI15: 50 | AJ15: 50 | AK15: 50 | AL15: 50 | AM15: 50 | AN15: 18 | AO15: 18 | AP15: 18 | AQ15: 18 | AR15: 18 | AS15: 10 | AT15: 10 | AU15: 10 | AV15: 10 | AW15: 100 | AX15: 100 | AY15: 100 | AZ15: 100 | BA15: 100 | BB15: 50 | BC15: 50 | BD15: 50 | BE15: 50 | BF15: 50 | BG15: 50 | BH15: 18 | BI15: 18 | BJ15: 18 | BK15: 18 | BL15: 18 | BM15: {=INDEX(_xlfn.ANCHORARRAY(_xlfn.XLOOKUP($D15,'-ref_Distribution'!$B$117:$B$121,'-ref_Distribution'!$G$117:$G$121)),RIGHT(BM$1,2))} -> 78 | BN15: {=INDEX(_xlfn.ANCHORARRAY(_xlfn.XLOOKUP($D15,'-ref_Distribution'!$B$117:$B$121,'-ref_Distribution'!$G$117:$G$121)),RIGHT(BN$1,2))} -> 72 | BO15: {=INDEX(_xlfn.ANCHORARRAY(_xlfn.XLOOKUP($D15,'-ref_Distribution'!$B$117:$B$121,'-ref_Distribution'!$G$117:$G$121)),RIGHT(BO$1,2))} -> 66 | BP15: {=INDEX(_xlfn.ANCHORARRAY(_xlfn.XLOOKUP($D15,'-ref_Distribution'!$B$117:$B$121,'-ref_Distribution'!$G$117:$G$121)),RIGHT(BP$1,2))} -> 61 | BQ15: {=INDEX(_xlfn.ANCHORARRAY(_xlfn.XLOOKUP($D15,'-ref_Distribution'!$B$117:$B$121,'-ref_Distribution'!$G$117:$G$121)),RIGHT(BQ$1,2))} -> 58 | BR15: {=INDEX(_xlfn.ANCHORARRAY(_xlfn.XLOOKUP($D15,'-ref_Distribution'!$B$117:$B$121,'-ref_Distribution'!$G$117:$G$121)),RIGHT(BR$1,2))} -> 55 | BS15: {=INDEX(_xlfn.ANCHORARRAY(_xlfn.XLOOKUP($D15,'-ref_Distribution'!$B$117:$B$121,'-ref_Distribution'!$G$117:$G$121)),RIGHT(BS$1,2))} -> 52 | BT15: {=INDEX(_xlfn.ANCHORARRAY(_xlfn.XLOOKUP($D15,'-ref_Distribution'!$B$117:$B$121,'-ref_Distribution'!$G$117:$G$121)),RIGHT(BT$1,2))} -> 50 | ... CF15: {=INDEX(_xlfn.ANCHORARRAY(_xlfn.XLOOKUP($D15,'-ref_Distribution'!$B$117:$B$121,'-ref_Distribution'!$G$117:$G$121)),RIGHT(CF$1,2))} -> 38
A16: 1310106 | B16: 圆锯 (模板) | C16: 近战 | D16: 模板
A17: 13101061 | B17: 圆锯 Lv.1 | C17: 近战 | D17: 1 | E17: 10 | F17: 10 | G17: 10 | H17: 50 | I17: 100 | J17: 100 | K17: 100 | L17: 100 | M17: 100 | N17: 50 | O17: 50 | P17: 50 | Q17: 50 | R17: 50 | S17: 50 | T17: 18 | U17: 18 | V17: 18 | W17: 18 | X17: 18 | Y17: 10 | Z17: 10 | AA17: 10 | AB17: 50 | AC17: 100 | AD17: 100 | AE17: 100 | AF17: 100 | AG17: 100 | AH17: 50 | AI17: 50 | AJ17: 50 | AK17: 50 | AL17: 50 | AM17: 50 | AN17: 18 | AO17: 18 | AP17: 18 | AQ17: 18 | AR17: 18 | AS17: 10 | AT17: 10 | AU17: 10 | AV17: 50 | AW17: 100 | AX17: 100 | AY17: 100 | AZ17: 100 | BA17: 100 | BB17: 50 | BC17: 50 | BD17: 50 | BE17: 50 | BF17: 50 | BG17: 50 | BH17: 18 | BI17: 18 | BJ17: 18 | BK17: 18 | BL17: 18 | BM17: {=INDEX(_xlfn.ANCHORARRAY(_xlfn.XLOOKUP($D17,'-ref_Distribution'!$B$117:$B$121,'-ref_Distribution'!$G$117:$G$121)),RIGHT(BM$1,2))} -> 78 | BN17: {=INDEX(_xlfn.ANCHORARRAY(_xlfn.XLOOKUP($D17,'-ref_Distribution'!$B$117:$B$121,'-ref_Distribution'!$G$117:$G$121)),RIGHT(BN$1,2))} -> 72 | BO17: {=INDEX(_xlfn.ANCHORARRAY(_xlfn.XLOOKUP($D17,'-ref_Distribution'!$B$117:$B$121,'-ref_Distribution'!$G$117:$G$121)),RIGHT(BO$1,2))} -> 66 | BP17: {=INDEX(_xlfn.ANCHORARRAY(_xlfn.XLOOKUP($D17,'-ref_Distribution'!$B$117:$B$121,'-ref_Distribution'!$G$117:$G$121)),RIGHT(BP$1,2))} -> 61 | BQ17: {=INDEX(_xlfn.ANCHORARRAY(_xlfn.XLOOKUP($D17,'-ref_Distribution'!$B$117:$B$121,'-ref_Distribution'!$G$117:$G$121)),RIGHT(BQ$1,2))} -> 58 | BR17: {=INDEX(_xlfn.ANCHORARRAY(_xlfn.XLOOKUP($D17,'-ref_Distribution'!$B$117:$B$121,'-ref_Distribution'!$G$117:$G$121)),RIGHT(BR$1,2))} -> 55 | BS17: {=INDEX(_xlfn.ANCHORARRAY(_xlfn.XLOOKUP($D17,'-ref_Distribution'!$B$117:$B$121,'-ref_Distribution'!$G$117:$G$121)),RIGHT(BS$1,2))} -> 52 | BT17: {=INDEX(_xlfn.ANCHORARRAY(_xlfn.XLOOKUP($D17,'-ref_Distribution'!$B$117:$B$121,'-ref_Distribution'!$G$117:$G$121)),RIGHT(BT$1,2))} -> 50 | ... CF17: {=INDEX(_xlfn.ANCHORARRAY(_xlfn.XLOOKUP($D17,'-ref_Distribution'!$B$117:$B$121,'-ref_Distribution'!$G$117:$G$121)),RIGHT(CF$1,2))} -> 38
