Workbook

Sheet role
A1: id | B1: name | E1: portrait_small | F1: illustration_big | G1: illustration_small | H1: UI_Shop_Illustration_viewed | J1: base_value | K1: coma_g | L1: properties | N1: properties_num | O1: properties_rnd | P1: lines_coma
A2: uint key | B2: string | E2: string | F2: string | G2: string | H2: string | J2: int | K2: float | L2: uint[] | N2: (int,int) | O2: uint[] | P2: string[]
A3: id | B3: 人物名称 localization表id | C3: 备注1 名称 | D3: Hero? | E3: 人物头像 小 配置资源包名称 出现在设备工位上 | F3: 人物立绘 大 | G3: 人物立绘 小 会出现在商店中 | H3: 英雄营帐-立绘-已解锁角色 会出现在商店中 | I3: 辅助列 图集 index | J3: 基础价格 | K3: 过载阈值 用于摇摆昏迷 | L3: 固有人物特性 基础特性 | N3: 随机特性 数量 [min, max] | O3: 随机特性 池 随机特性 | P3: 台词-眩晕时
A4: 15101 | B4: =_xlfn.TEXTJOIN("_",1,"role",A4) -> role_15101 | C4: 阿比盖尔 | D4: TRUE | E4: =_xlfn.LET(_xlpm._type,IF($D4,"hero","npc"), _xlfn.CONCAT("namecard_",_xlpm._type,"[namecard-",_xlpm._type,"_",VALUE(RIGHT($A4-1,2)),"]")) -> namecard_hero[namecard-hero_0] | F4: =_xlfn.LET(_xlpm._type,IF($D4,"hero","npc"), _xlfn.CONCAT("ill_big_",_xlpm._type,"[ill-big-",_xlpm._type,"_",VALUE(RIGHT($A4-1,2)),"]")) -> ill_big_hero[ill-big-hero_0] | G4: =_xlfn.LET(_xlpm._type,IF($D4,"hero","npc"), _xlfn.CONCAT("ill_small_",_xlpm._type,"[ill_small_",_xlpm._type,"_",VALUE(RIGHT($A4-1,2)),"]")) -> ill_small_hero[ill_small_hero_0] | H4: =_xlfn.LET(_xlpm._asset,"ui_npc_shop_ill_viewed", _xlfn.CONCAT(_xlpm._asset,"[",_xlpm._asset,"_",$I4,"]")) -> ui_npc_shop_ill_viewed[ui_npc_shop_ill_viewed_0] | I4: 0 | J4: =INT(8*1.033^(RIGHT(A4,2)-1)) -> 8 | K4: {=_xlfn.LAMBDA(_xlpm._GMin,_xlpm._GMax,_xlpm._RankMin,_xlpm._RankMax,_xlpm._GMin+(_xlpm._GMax-_xlpm._GMin)/(_xlpm._RankMax-_xlpm._RankMin)*(J4-_xlpm._RankMin))(300,560,8,18)} -> 300 | L4: 16412 | M4: {=_xlfn.TEXTJOIN("，",1,IFERROR(VLOOKUP(VALUE(_xlfn.TEXTSPLIT(L4,";")),properties!A:C,3,0),""))} -> 庄园主 | N4: ="0~0" -> 0~0 | P4: 卧槽;握草;我草;会不会开车
A5: 15102 | B5: =_xlfn.TEXTJOIN("_",1,"role",A5) -> role_15102 | C5: 阿飞 | D5: TRUE | E5: =_xlfn.LET(_xlpm._type,IF($D5,"hero","npc"), _xlfn.CONCAT("namecard_",_xlpm._type,"[namecard-",_xlpm._type,"_",VALUE(RIGHT($A5-1,2)),"]")) -> namecard_hero[namecard-hero_1] | F5: =_xlfn.LET(_xlpm._type,IF($D5,"hero","npc"), _xlfn.CONCAT("ill_big_",_xlpm._type,"[ill-big-",_xlpm._type,"_",VALUE(RIGHT($A5-1,2)),"]")) -> ill_big_hero[ill-big-hero_1] | G5: =_xlfn.LET(_xlpm._type,IF($D5,"hero","npc"), _xlfn.CONCAT("ill_small_",_xlpm._type,"[ill_small_",_xlpm._type,"_",VALUE(RIGHT($A5-1,2)),"]")) -> ill_small_hero[ill_small_hero_1] | H5: =_xlfn.LET(_xlpm._asset,"ui_npc_shop_ill_viewed", _xlfn.CONCAT(_xlpm._asset,"[",_xlpm._asset,"_",$I5,"]")) -> ui_npc_shop_ill_viewed[ui_npc_shop_ill_viewed_1] | I5: 1 | J5: =INT(8*1.033^(RIGHT(A5,2)-1)) -> 8 | K5: {=_xlfn.LAMBDA(_xlpm._GMin,_xlpm._GMax,_xlpm._RankMin,_xlpm._RankMax,_xlpm._GMin+(_xlpm._GMax-_xlpm._GMin)/(_xlpm._RankMax-_xlpm._RankMin)*(J5-_xlpm._RankMin))(300,560,8,18)} -> 300 | L5: 16308;16310;16401;16410 | M5: {=_xlfn.TEXTJOIN("，",1,IFERROR(VLOOKUP(VALUE(_xlfn.TEXTSPLIT(L5,";")),properties!A:C,3,0),""))} -> 专心搜刮，奇行种，小偷，天生战狂 | N5: ="0~0" -> 0~0 | P5: 我运行像地狱;
A6: 15103 | B6: =_xlfn.TEXTJOIN("_",1,"role",A6) -> role_15103 | C6: 雷锵锵 | D6: TRUE | E6: =_xlfn.LET(_xlpm._type,IF($D6,"hero","npc"), _xlfn.CONCAT("namecard_",_xlpm._type,"[namecard-",_xlpm._type,"_",VALUE(RIGHT($A6-1,2)),"]")) -> namecard_hero[namecard-hero_2] | F6: =_xlfn.LET(_xlpm._type,IF($D6,"hero","npc"), _xlfn.CONCAT("ill_big_",_xlpm._type,"[ill-big-",_xlpm._type,"_",VALUE(RIGHT($A6-1,2)),"]")) -> ill_big_hero[ill-big-hero_2] | G6: =_xlfn.LET(_xlpm._type,IF($D6,"hero","npc"), _xlfn.CONCAT("ill_small_",_xlpm._type,"[ill_small_",_xlpm._type,"_",VALUE(RIGHT($A6-1,2)),"]")) -> ill_small_hero[ill_small_hero_2] | H6: =_xlfn.LET(_xlpm._asset,"ui_npc_shop_ill_viewed", _xlfn.CONCAT(_xlpm._asset,"[",_xlpm._asset,"_",$I6,"]")) -> ui_npc_shop_ill_viewed[ui_npc_shop_ill_viewed_2] | I6: 2 | J6: =INT(8*1.033^(RIGHT(A6,2)-1)) -> 8 | K6: {=_xlfn.LAMBDA(_xlpm._GMin,_xlpm._GMax,_xlpm._RankMin,_xlpm._RankMax,_xlpm._GMin+(_xlpm._GMax-_xlpm._GMin)/(_xlpm._RankMax-_xlpm._RankMin)*(J6-_xlpm._RankMin))(300,560,8,18)} -> 300 | L6: 16311;16412 | M6: {=_xlfn.TEXTJOIN("，",1,IFERROR(VLOOKUP(VALUE(_xlfn.TEXTSPLIT(L6,";")),properties!A:C,3,0),""))} -> 心神不宁，庄园主 | N6: ="0~0" -> 0~0 | P6: 卧槽;握草;我草;会不会开车
A7: 15104 | B7: =_xlfn.TEXTJOIN("_",1,"role",A7) -> role_15104 | C7: 响当当 | D7: TRUE | E7: =_xlfn.LET(_xlpm._type,IF($D7,"hero","npc"), _xlfn.CONCAT("namecard_",_xlpm._type,"[namecard-",_xlpm._type,"_",VALUE(RIGHT($A7-1,2)),"]")) -> namecard_hero[namecard-hero_3] | F7: =_xlfn.LET(_xlpm._type,IF($D7,"hero","npc"), _xlfn.CONCAT("ill_big_",_xlpm._type,"[ill-big-",_xlpm._type,"_",VALUE(RIGHT($A7-1,2)),"]")) -> ill_big_hero[ill-big-hero_3] | G7: =_xlfn.LET(_xlpm._type,IF($D7,"hero","npc"), _xlfn.CONCAT("ill_small_",_xlpm._type,"[ill_small_",_xlpm._type,"_",VALUE(RIGHT($A7-1,2)),"]")) -> ill_small_hero[ill_small_hero_3] | H7: =_xlfn.LET(_xlpm._asset,"ui_npc_shop_ill_viewed", _xlfn.CONCAT(_xlpm._asset,"[",_xlpm._asset,"_",$I7,"]")) -> ui_npc_shop_ill_viewed[ui_npc_shop_ill_viewed_3] | I7: 3 | J7: =INT(8*1.033^(RIGHT(A7,2)-1)) -> 8 | K7: {=_xlfn.LAMBDA(_xlpm._GMin,_xlpm._GMax,_xlpm._RankMin,_xlpm._RankMax,_xlpm._GMin+(_xlpm._GMax-_xlpm._GMin)/(_xlpm._RankMax-_xlpm._RankMin)*(J7-_xlpm._RankMin))(300,560,8,18)} -> 300 | L7: 16311;16308;16401 | M7: {=_xlfn.TEXTJOIN("，",1,IFERROR(VLOOKUP(VALUE(_xlfn.TEXTSPLIT(L7,";")),properties!A:C,3,0),""))} -> 心神不宁，专心搜刮，小偷 | N7: ="0~0" -> 0~0 | P7: 头晕目眩;上吐下泻;翻江倒海;头昏脑胀;汗如雨下
A8: 15105 | B8: =_xlfn.TEXTJOIN("_",1,"role",A8) -> role_15105 | C8: 漆雕婵 | D8: TRUE | E8: =_xlfn.LET(_xlpm._type,IF($D8,"hero","npc"), _xlfn.CONCAT("namecard_",_xlpm._type,"[namecard-",_xlpm._type,"_",VALUE(RIGHT($A8-1,2)),"]")) -> namecard_hero[namecard-hero_4] | F8: =_xlfn.LET(_xlpm._type,IF($D8,"hero","npc"), _xlfn.CONCAT("ill_big_",_xlpm._type,"[ill-big-",_xlpm._type,"_",VALUE(RIGHT($A8-1,2)),"]")) -> ill_big_hero[ill-big-hero_4] | G8: =_xlfn.LET(_xlpm._type,IF($D8,"hero","npc"), _xlfn.CONCAT("ill_small_",_xlpm._type,"[ill_small_",_xlpm._type,"_",VALUE(RIGHT($A8-1,2)),"]")) -> ill_small_hero[ill_small_hero_4] | H8: =_xlfn.LET(_xlpm._asset,"ui_npc_shop_ill_viewed", _xlfn.CONCAT(_xlpm._asset,"[",_xlpm._asset,"_",$I8,"]")) -> ui_npc_shop_ill_viewed[ui_npc_shop_ill_viewed_4] | I8: 4 | J8: =INT(8*1.033^(RIGHT(A8,2)-1)) -> 9 | K8: {=_xlfn.LAMBDA(_xlpm._GMin,_xlpm._GMax,_xlpm._RankMin,_xlpm._RankMax,_xlpm._GMin+(_xlpm._GMax-_xlpm._GMin)/(_xlpm._RankMax-_xlpm._RankMin)*(J8-_xlpm._RankMin))(300,560,8,18)} -> 326 | L8: 16311;16402 | M8: {=_xlfn.TEXTJOIN("，",1,IFERROR(VLOOKUP(VALUE(_xlfn.TEXTSPLIT(L8,";")),properties!A:C,3,0),""))} -> 心神不宁，擅长收纳 | N8: ="0~0" -> 0~0 | P8: 头晕目眩;上吐下泻;翻江倒海;头昏脑胀;汗如雨下
A9: 15106 | B9: =_xlfn.TEXTJOIN("_",1,"role",A9) -> role_15106 | C9: 漆雕墩 | D9: TRUE | E9: =_xlfn.LET(_xlpm._type,IF($D9,"hero","npc"), _xlfn.CONCAT("namecard_",_xlpm._type,"[namecard-",_xlpm._type,"_",VALUE(RIGHT($A9-1,2)),"]")) -> namecard_hero[namecard-hero_5] | F9: =_xlfn.LET(_xlpm._type,IF($D9,"hero","npc"), _xlfn.CONCAT("ill_big_",_xlpm._type,"[ill-big-",_xlpm._type,"_",VALUE(RIGHT($A9-1,2)),"]")) -> ill_big_hero[ill-big-hero_5] | G9: =_xlfn.LET(_xlpm._type,IF($D9,"hero","npc"), _xlfn.CONCAT("ill_small_",_xlpm._type,"[ill_small_",_xlpm._type,"_",VALUE(RIGHT($A9-1,2)),"]")) -> ill_small_hero[ill_small_hero_5] | H9: =_xlfn.LET(_xlpm._asset,"ui_npc_shop_ill_viewed", _xlfn.CONCAT(_xlpm._asset,"[",_xlpm._asset,"_",$I9,"]")) -> ui_npc_shop_ill_viewed[ui_npc_shop_ill_viewed_5] | I9: 5 | J9: =INT(8*1.033^(RIGHT(A9,2)-1)) -> 9 | K9: {=_xlfn.LAMBDA(_xlpm._GMin,_xlpm._GMax,_xlpm._RankMin,_xlpm._RankMax,_xlpm._GMin+(_xlpm._GMax-_xlpm._GMin)/(_xlpm._RankMax-_xlpm._RankMin)*(J9-_xlpm._RankMin))(300,560,8,18)} -> 326 | L9: 16311;16411 | M9: {=_xlfn.TEXTJOIN("，",1,IFERROR(VLOOKUP(VALUE(_xlfn.TEXTSPLIT(L9,";")),properties!A:C,3,0),""))} -> 心神不宁，不死人 | N9: ="0~0" -> 0~0 | P9: 头晕目眩;上吐下泻;翻江倒海;头昏脑胀;汗如雨下
A10: 15107 | B10: =_xlfn.TEXTJOIN("_",1,"role",A10) -> role_15107 | C10: 工头 | D10: TRUE | E10: =_xlfn.LET(_xlpm._type,IF($D10,"hero","npc"), _xlfn.CONCAT("namecard_",_xlpm._type,"[namecard-",_xlpm._type,"_",VALUE(RIGHT($A10-1,2)),"]")) -> namecard_hero[namecard-hero_6] | F10: =_xlfn.LET(_xlpm._type,IF($D10,"hero","npc"), _xlfn.CONCAT("ill_big_",_xlpm._type,"[ill-big-",_xlpm._type,"_",VALUE(RIGHT($A10-1,2)),"]")) -> ill_big_hero[ill-big-hero_6] | G10: =_xlfn.LET(_xlpm._type,IF($D10,"hero","npc"), _xlfn.CONCAT("ill_small_",_xlpm._type,"[ill_small_",_xlpm._type,"_",VALUE(RIGHT($A10-1,2)),"]")) -> ill_small_hero[ill_small_hero_6] | H10: =_xlfn.LET(_xlpm._asset,"ui_npc_shop_ill_viewed", _xlfn.CONCAT(_xlpm._asset,"[",_xlpm._asset,"_",$I10,"]")) -> ui_npc_shop_ill_viewed[ui_npc_shop_ill_viewed_6] | I10: 6 | J10: =INT(8*1.033^(RIGHT(A10,2)-1)) -> 9 | K10: {=_xlfn.LAMBDA(_xlpm._GMin,_xlpm._GMax,_xlpm._RankMin,_xlpm._RankMax,_xlpm._GMin+(_xlpm._GMax-_xlpm._GMin)/(_xlpm._RankMax-_xlpm._RankMin)*(J10-_xlpm._RankMin))(300,560,8,18)} -> 326 | L10: 16304;16413 | M10: {=_xlfn.TEXTJOIN("，",1,IFERROR(VLOOKUP(VALUE(_xlfn.TEXTSPLIT(L10,";")),properties!A:C,3,0),""))} -> 无法工作，鞭策队友 | N10: ="0~0" -> 0~0 | P10: 卧槽;握草;我草;会不会开车
A11: 15108 | B11: =_xlfn.TEXTJOIN("_",1,"role",A11) -> role_15108 | C11: 小绿人 | D11: TRUE | E11: =_xlfn.LET(_xlpm._type,IF($D11,"hero","npc"), _xlfn.CONCAT("namecard_",_xlpm._type,"[namecard-",_xlpm._type,"_",VALUE(RIGHT($A11-1,2)),"]")) -> namecard_hero[namecard-hero_7] | F11: =_xlfn.LET(_xlpm._type,IF($D11,"hero","npc"), _xlfn.CONCAT("ill_big_",_xlpm._type,"[ill-big-",_xlpm._type,"_",VALUE(RIGHT($A11-1,2)),"]")) -> ill_big_hero[ill-big-hero_7] | G11: =_xlfn.LET(_xlpm._type,IF($D11,"hero","npc"), _xlfn.CONCAT("ill_small_",_xlpm._type,"[ill_small_",_xlpm._type,"_",VALUE(RIGHT($A11-1,2)),"]")) -> ill_small_hero[ill_small_hero_7] | H11: =_xlfn.LET(_xlpm._asset,"ui_npc_shop_ill_viewed", _xlfn.CONCAT(_xlpm._asset,"[",_xlpm._asset,"_",$I11,"]")) -> ui_npc_shop_ill_viewed[ui_npc_shop_ill_viewed_7] | I11: 7 | J11: =INT(8*1.033^(RIGHT(A11,2)-1)) -> 10 | K11: 99999 | L11: 16301;16302 | M11: {=_xlfn.TEXTJOIN("，",1,IFERROR(VLOOKUP(VALUE(_xlfn.TEXTSPLIT(L11,";")),properties!A:C,3,0),""))} -> 卑微贱民，宇航员 | N11: ="0~0" -> 0~0 | P11: 01101010;10101101;11111101;10101000
A12: 15109 | B12: =_xlfn.TEXTJOIN("_",1,"role",A12) -> role_15109 | C12: 搞事 | D12: TRUE | E12: =_xlfn.LET(_xlpm._type,IF($D12,"hero","npc"), _xlfn.CONCAT("namecard_",_xlpm._type,"[namecard-",_xlpm._type,"_",VALUE(RIGHT($A12-1,2)),"]")) -> namecard_hero[namecard-hero_8] | F12: =_xlfn.LET(_xlpm._type,IF($D12,"hero","npc"), _xlfn.CONCAT("ill_big_",_xlpm._type,"[ill-big-",_xlpm._type,"_",VALUE(RIGHT($A12-1,2)),"]")) -> ill_big_hero[ill-big-hero_8] | G12: =_xlfn.LET(_xlpm._type,IF($D12,"hero","npc"), _xlfn.CONCAT("ill_small_",_xlpm._type,"[ill_small_",_xlpm._type,"_",VALUE(RIGHT($A12-1,2)),"]")) -> ill_small_hero[ill_small_hero_8] | H12: =_xlfn.LET(_xlpm._asset,"ui_npc_shop_ill_viewed", _xlfn.CONCAT(_xlpm._asset,"[",_xlpm._asset,"_",$I12,"]")) -> ui_npc_shop_ill_viewed[ui_npc_shop_ill_viewed_8] | I12: 8 | J12: =INT(8*1.033^(RIGHT(A12,2)-1)) -> 10 | K12: {=_xlfn.LAMBDA(_xlpm._GMin,_xlpm._GMax,_xlpm._RankMin,_xlpm._RankMax,_xlpm._GMin+(_xlpm._GMax-_xlpm._GMin)/(_xlpm._RankMax-_xlpm._RankMin)*(J12-_xlpm._RankMin))(300,560,8,18)} -> 352 | L12: 16410 | M12: {=_xlfn.TEXTJOIN("，",1,IFERROR(VLOOKUP(VALUE(_xlfn.TEXTSPLIT(L12,";")),properties!A:C,3,0),""))} -> 天生战狂 | N12: ="0~0" -> 0~0 | P12: 卧槽;握草;我草;会不会开车
A13: 15110 | B13: =_xlfn.TEXTJOIN("_",1,"role",A13) -> role_15110 | C13: 小敏 | D13: TRUE | E13: =_xlfn.LET(_xlpm._type,IF($D13,"hero","npc"), _xlfn.CONCAT("namecard_",_xlpm._type,"[namecard-",_xlpm._type,"_",VALUE(RIGHT($A13-1,2)),"]")) -> namecard_hero[namecard-hero_9] | F13: =_xlfn.LET(_xlpm._type,IF($D13,"hero","npc"), _xlfn.CONCAT("ill_big_",_xlpm._type,"[ill-big-",_xlpm._type,"_",VALUE(RIGHT($A13-1,2)),"]")) -> ill_big_hero[ill-big-hero_9] | G13: =_xlfn.LET(_xlpm._type,IF($D13,"hero","npc"), _xlfn.CONCAT("ill_small_",_xlpm._type,"[ill_small_",_xlpm._type,"_",VALUE(RIGHT($A13-1,2)),"]")) -> ill_small_hero[ill_small_hero_9] | H13: =_xlfn.LET(_xlpm._asset,"ui_npc_shop_ill_viewed", _xlfn.CONCAT(_xlpm._asset,"[",_xlpm._asset,"_",$I13,"]")) -> ui_npc_shop_ill_viewed[ui_npc_shop_ill_viewed_9] | I13: 9 | J13: =INT(8*1.033^(RIGHT(A13,2)-1)) -> 10 | K13: {=_xlfn.LAMBDA(_xlpm._GMin,_xlpm._GMax,_xlpm._RankMin,_xlpm._RankMax,_xlpm._GMin+(_xlpm._GMax-_xlpm._GMin)/(_xlpm._RankMax-_xlpm._RankMin)*(J13-_xlpm._RankMin))(300,560,8,18)} -> 352 | L13: 16303;16403 | M13: {=_xlfn.TEXTJOIN("，",1,IFERROR(VLOOKUP(VALUE(_xlfn.TEXTSPLIT(L13,";")),properties!A:C,3,0),""))} -> 幽闭恐惧，喜爱雕塑 | N13: ="0~0" -> 0~0 | P13: 卧槽;握草;我草;会不会开车
A14: 15111 | B14: =_xlfn.TEXTJOIN("_",1,"role",A14) -> role_15111 | C14: 王亨利 | D14: TRUE | E14: =_xlfn.LET(_xlpm._type,IF($D14,"hero","npc"), _xlfn.CONCAT("namecard_",_xlpm._type,"[namecard-",_xlpm._type,"_",VALUE(RIGHT($A14-1,2)),"]")) -> namecard_hero[namecard-hero_10] | F14: =_xlfn.LET(_xlpm._type,IF($D14,"hero","npc"), _xlfn.CONCAT("ill_big_",_xlpm._type,"[ill-big-",_xlpm._type,"_",VALUE(RIGHT($A14-1,2)),"]")) -> ill_big_hero[ill-big-hero_10] | G14: =_xlfn.LET(_xlpm._type,IF($D14,"hero","npc"), _xlfn.CONCAT("ill_small_",_xlpm._type,"[ill_small_",_xlpm._type,"_",VALUE(RIGHT($A14-1,2)),"]")) -> ill_small_hero[ill_small_hero_10] | H14: =_xlfn.LET(_xlpm._asset,"ui_npc_shop_ill_viewed", _xlfn.CONCAT(_xlpm._asset,"[",_xlpm._asset,"_",$I14,"]")) -> ui_npc_shop_ill_viewed[ui_npc_shop_ill_viewed_10] | I14: 10 | J14: =INT(8*1.033^(RIGHT(A14,2)-1)) -> 11 | K14: {=_xlfn.LAMBDA(_xlpm._GMin,_xlpm._GMax,_xlpm._RankMin,_xlpm._RankMax,_xlpm._GMin+(_xlpm._GMax-_xlpm._GMin)/(_xlpm._RankMax-_xlpm._RankMin)*(J14-_xlpm._RankMin))(300,560,8,18)} -> 378 | L14: 16305;16308;16401;16414 | M14: {=_xlfn.TEXTJOIN("，",1,IFERROR(VLOOKUP(VALUE(_xlfn.TEXTSPLIT(L14,";")),properties!A:C,3,0),""))} -> 骑士大人，专心搜刮，小偷，老千 | N14: ="0~0" -> 0~0 | P14: OMG;Jesus;哦我的天哪;我的上帝呀;上帝保佑你;这该死的震荡
A15: 15112 | B15: =_xlfn.TEXTJOIN("_",1,"role",A15) -> role_15112 | C15: 凯文 | D15: TRUE | E15: =_xlfn.LET(_xlpm._type,IF($D15,"hero","npc"), _xlfn.CONCAT("namecard_",_xlpm._type,"[namecard-",_xlpm._type,"_",VALUE(RIGHT($A15-1,2)),"]")) -> namecard_hero[namecard-hero_11] | F15: =_xlfn.LET(_xlpm._type,IF($D15,"hero","npc"), _xlfn.CONCAT("ill_big_",_xlpm._type,"[ill-big-",_xlpm._type,"_",VALUE(RIGHT($A15-1,2)),"]")) -> ill_big_hero[ill-big-hero_11] | G15: =_xlfn.LET(_xlpm._type,IF($D15,"hero","npc"), _xlfn.CONCAT("ill_small_",_xlpm._type,"[ill_small_",_xlpm._type,"_",VALUE(RIGHT($A15-1,2)),"]")) -> ill_small_hero[ill_small_hero_11] | H15: =_xlfn.LET(_xlpm._asset,"ui_npc_shop_ill_viewed", _xlfn.CONCAT(_xlpm._asset,"[",_xlpm._asset,"_",$I15,"]")) -> ui_npc_shop_ill_viewed[ui_npc_shop_ill_viewed_11] | I15: 11 | J15: =INT(8*1.033^(RIGHT(A15,2)-1)) -> 11 | K15: {=_xlfn.LAMBDA(_xlpm._GMin,_xlpm._GMax,_xlpm._RankMin,_xlpm._RankMax,_xlpm._GMin+(_xlpm._GMax-_xlpm._GMin)/(_xlpm._RankMax-_xlpm._RankMin)*(J15-_xlpm._RankMin))(300,560,8,18)} -> 378 | L15: 16410 | M15: {=_xlfn.TEXTJOIN("，",1,IFERROR(VLOOKUP(VALUE(_xlfn.TEXTSPLIT(L15,";")),properties!A:C,3,0),""))} -> 天生战狂 | N15: ="0~0" -> 0~0 | P15: 卧槽;握草;我草;会不会开车
A16: 15113 | B16: =_xlfn.TEXTJOIN("_",1,"role",A16) -> role_15113 | C16: 村民 | D16: TRUE | E16: =_xlfn.LET(_xlpm._type,IF($D16,"hero","npc"), _xlfn.CONCAT("namecard_",_xlpm._type,"[namecard-",_xlpm._type,"_",VALUE(RIGHT($A16-1,2)),"]")) -> namecard_hero[namecard-hero_12] | F16: =_xlfn.LET(_xlpm._type,IF($D16,"hero","npc"), _xlfn.CONCAT("ill_big_",_xlpm._type,"[ill-big-",_xlpm._type,"_",VALUE(RIGHT($A16-1,2)),"]")) -> ill_big_hero[ill-big-hero_12] | G16: =_xlfn.LET(_xlpm._type,IF($D16,"hero","npc"), _xlfn.CONCAT("ill_small_",_xlpm._type,"[ill_small_",_xlpm._type,"_",VALUE(RIGHT($A16-1,2)),"]")) -> ill_small_hero[ill_small_hero_12] | H16: =_xlfn.LET(_xlpm._asset,"ui_npc_shop_ill_viewed", _xlfn.CONCAT(_xlpm._asset,"[",_xlpm._asset,"_",$I16,"]")) -> ui_npc_shop_ill_viewed[ui_npc_shop_ill_viewed_12] | I16: 12 | J16: =INT(8*1.033^(RIGHT(A16,2)-1)) -> 11 | K16: {=_xlfn.LAMBDA(_xlpm._GMin,_xlpm._GMax,_xlpm._RankMin,_xlpm._RankMax,_xlpm._GMin+(_xlpm._GMax-_xlpm._GMin)/(_xlpm._RankMax-_xlpm._RankMin)*(J16-_xlpm._RankMin))(300,560,8,18)} -> 378 | L16: 16301;16306 | M16: {=_xlfn.TEXTJOIN("，",1,IFERROR(VLOOKUP(VALUE(_xlfn.TEXTSPLIT(L16,";")),properties!A:C,3,0),""))} -> 卑微贱民，亚当夏娃 | N16: ="0~0" -> 0~0 | P16: 卧槽;握草;我草;会不会开车
A17: 15114 | B17: =_xlfn.TEXTJOIN("_",1,"role",A17) -> role_15114 | C17: 爽爽 | D17: TRUE | E17: =_xlfn.LET(_xlpm._type,IF($D17,"hero","npc"), _xlfn.CONCAT("namecard_",_xlpm._type,"[namecard-",_xlpm._type,"_",VALUE(RIGHT($A17-1,2)),"]")) -> namecard_hero[namecard-hero_13] | F17: =_xlfn.LET(_xlpm._type,IF($D17,"hero","npc"), _xlfn.CONCAT("ill_big_",_xlpm._type,"[ill-big-",_xlpm._type,"_",VALUE(RIGHT($A17-1,2)),"]")) -> ill_big_hero[ill-big-hero_13] | G17: =_xlfn.LET(_xlpm._type,IF($D17,"hero","npc"), _xlfn.CONCAT("ill_small_",_xlpm._type,"[ill_small_",_xlpm._type,"_",VALUE(RIGHT($A17-1,2)),"]")) -> ill_small_hero[ill_small_hero_13] | H17: =_xlfn.LET(_xlpm._asset,"ui_npc_shop_ill_viewed", _xlfn.CONCAT(_xlpm._asset,"[",_xlpm._asset,"_",$I17,"]")) -> ui_npc_shop_ill_viewed[ui_npc_shop_ill_viewed_13] | I17: 13 | J17: =INT(8*1.033^(RIGHT(A17,2)-1)) -> 12 | K17: {=_xlfn.LAMBDA(_xlpm._GMin,_xlpm._GMax,_xlpm._RankMin,_xlpm._RankMax,_xlpm._GMin+(_xlpm._GMax-_xlpm._GMin)/(_xlpm._RankMax-_xlpm._RankMin)*(J17-_xlpm._RankMin))(300,560,8,18)} -> 404 | M17: {=_xlfn.TEXTJOIN("，",1,IFERROR(VLOOKUP(VALUE(_xlfn.TEXTSPLIT(L17,";")),properties!A:C,3,0),""))} | N17: ="0~0" -> 0~0 | P17: 嗷;嗷嗷嗷;嗷嗷嗷嗷嗷
A18: 15115 | B18: =_xlfn.TEXTJOIN("_",1,"role",A18) -> role_15115 | C18: 古神 | D18: TRUE | E18: =_xlfn.LET(_xlpm._type,IF($D18,"hero","npc"), _xlfn.CONCAT("namecard_",_xlpm._type,"[namecard-",_xlpm._type,"_",VALUE(RIGHT($A18-1,2)),"]")) -> namecard_hero[namecard-hero_14] | F18: =_xlfn.LET(_xlpm._type,IF($D18,"hero","npc"), _xlfn.CONCAT("ill_big_",_xlpm._type,"[ill-big-",_xlpm._type,"_",VALUE(RIGHT($A18-1,2)),"]")) -> ill_big_hero[ill-big-hero_14] | G18: =_xlfn.LET(_xlpm._type,IF($D18,"hero","npc"), _xlfn.CONCAT("ill_small_",_xlpm._type,"[ill_small_",_xlpm._type,"_",VALUE(RIGHT($A18-1,2)),"]")) -> ill_small_hero[ill_small_hero_14] | H18: =_xlfn.LET(_xlpm._asset,"ui_npc_shop_ill_viewed", _xlfn.CONCAT(_xlpm._asset,"[",_xlpm._asset,"_",$I18,"]")) -> ui_npc_shop_ill_viewed[ui_npc_shop_ill_viewed_14] | I18: 14 | J18: =INT(8*1.033^(RIGHT(A18,2)-1)) -> 12 | K18: {=_xlfn.LAMBDA(_xlpm._GMin,_xlpm._GMax,_xlpm._RankMin,_xlpm._RankMax,_xlpm._GMin+(_xlpm._GMax-_xlpm._GMin)/(_xlpm._RankMax-_xlpm._RankMin)*(J18-_xlpm._RankMin))(300,560,8,18)} -> 404 | L18: 16309;16411 | M18: {=_xlfn.TEXTJOIN("，",1,IFERROR(VLOOKUP(VALUE(_xlfn.TEXTSPLIT(L18,";")),properties!A:C,3,0),""))} -> 面目可憎，不死人 | N18: ="0~0" -> 0~0 | P18: 卧槽;握草;我草;会不会开车
A19: 15116 | B19: =_xlfn.TEXTJOIN("_",1,"role",A19) -> role_15116 | C19: 鲁卡提耶 | D19: TRUE | E19: =_xlfn.LET(_xlpm._type,IF($D19,"hero","npc"), _xlfn.CONCAT("namecard_",_xlpm._type,"[namecard-",_xlpm._type,"_",VALUE(RIGHT($A19-1,2)),"]")) -> namecard_hero[namecard-hero_15] | F19: =_xlfn.LET(_xlpm._type,IF($D19,"hero","npc"), _xlfn.CONCAT("ill_big_",_xlpm._type,"[ill-big-",_xlpm._type,"_",VALUE(RIGHT($A19-1,2)),"]")) -> ill_big_hero[ill-big-hero_15] | G19: =_xlfn.LET(_xlpm._type,IF($D19,"hero","npc"), _xlfn.CONCAT("ill_small_",_xlpm._type,"[ill_small_",_xlpm._type,"_",VALUE(RIGHT($A19-1,2)),"]")) -> ill_small_hero[ill_small_hero_15] | H19: =_xlfn.LET(_xlpm._asset,"ui_npc_shop_ill_viewed", _xlfn.CONCAT(_xlpm._asset,"[",_xlpm._asset,"_",$I19,"]")) -> ui_npc_shop_ill_viewed[ui_npc_shop_ill_viewed_15] | I19: 15 | J19: =INT(8*1.033^(RIGHT(A19,2)-1)) -> 13 | K19: {=_xlfn.LAMBDA(_xlpm._GMin,_xlpm._GMax,_xlpm._RankMin,_xlpm._RankMax,_xlpm._GMin+(_xlpm._GMax-_xlpm._GMin)/(_xlpm._RankMax-_xlpm._RankMin)*(J19-_xlpm._RankMin))(300,560,8,18)} -> 430 | L19: 16305;16411 | M19: {=_xlfn.TEXTJOIN("，",1,IFERROR(VLOOKUP(VALUE(_xlfn.TEXTSPLIT(L19,";")),properties!A:C,3,0),""))} -> 骑士大人，不死人 | N19: ="0~0" -> 0~0 | P19: 卧槽;握草;我草;会不会开车
A20: 15117 | B20: =_xlfn.TEXTJOIN("_",1,"role",A20) -> role_15117 | C20: 帕奇 | D20: TRUE | E20: =_xlfn.LET(_xlpm._type,IF($D20,"hero","npc"), _xlfn.CONCAT("namecard_",_xlpm._type,"[namecard-",_xlpm._type,"_",VALUE(RIGHT($A20-1,2)),"]")) -> namecard_hero[namecard-hero_16] | F20: =_xlfn.LET(_xlpm._type,IF($D20,"hero","npc"), _xlfn.CONCAT("ill_big_",_xlpm._type,"[ill-big-",_xlpm._type,"_",VALUE(RIGHT($A20-1,2)),"]")) -> ill_big_hero[ill-big-hero_16] | G20: =_xlfn.LET(_xlpm._type,IF($D20,"hero","npc"), _xlfn.CONCAT("ill_small_",_xlpm._type,"[ill_small_",_xlpm._type,"_",VALUE(RIGHT($A20-1,2)),"]")) -> ill_small_hero[ill_small_hero_16] | H20: =_xlfn.LET(_xlpm._asset,"ui_npc_shop_ill_viewed", _xlfn.CONCAT(_xlpm._asset,"[",_xlpm._asset,"_",$I20,"]")) -> ui_npc_shop_ill_viewed[ui_npc_shop_ill_viewed_16] | I20: 16 | J20: =INT(8*1.033^(RIGHT(A20,2)-1)) -> 13 | K20: {=_xlfn.LAMBDA(_xlpm._GMin,_xlpm._GMax,_xlpm._RankMin,_xlpm._RankMax,_xlpm._GMin+(_xlpm._GMax-_xlpm._GMin)/(_xlpm._RankMax-_xlpm._RankMin)*(J20-_xlpm._RankMin))(300,560,8,18)} -> 430 | L20: 16308;16411 | M20: {=_xlfn.TEXTJOIN("，",1,IFERROR(VLOOKUP(VALUE(_xlfn.TEXTSPLIT(L20,";")),properties!A:C,3,0),""))} -> 专心搜刮，不死人 | N20: ="0~0" -> 0~0 | P20: 卧槽;握草;我草;会不会开车
A21: 15118 | B21: =_xlfn.TEXTJOIN("_",1,"role",A21) -> role_15118 | C21: 呆呆兽 | D21: TRUE | E21: =_xlfn.LET(_xlpm._type,IF($D21,"hero","npc"), _xlfn.CONCAT("namecard_",_xlpm._type,"[namecard-",_xlpm._type,"_",VALUE(RIGHT($A21-1,2)),"]")) -> namecard_hero[namecard-hero_17] | F21: =_xlfn.LET(_xlpm._type,IF($D21,"hero","npc"), _xlfn.CONCAT("ill_big_",_xlpm._type,"[ill-big-",_xlpm._type,"_",VALUE(RIGHT($A21-1,2)),"]")) -> ill_big_hero[ill-big-hero_17] | G21: =_xlfn.LET(_xlpm._type,IF($D21,"hero","npc"), _xlfn.CONCAT("ill_small_",_xlpm._type,"[ill_small_",_xlpm._type,"_",VALUE(RIGHT($A21-1,2)),"]")) -> ill_small_hero[ill_small_hero_17] | H21: =_xlfn.LET(_xlpm._asset,"ui_npc_shop_ill_viewed", _xlfn.CONCAT(_xlpm._asset,"[",_xlpm._asset,"_",$I21,"]")) -> ui_npc_shop_ill_viewed[ui_npc_shop_ill_viewed_17] | I21: 17 | J21: =INT(8*1.033^(RIGHT(A21,2)-1)) -> 13 | K21: {=_xlfn.LAMBDA(_xlpm._GMin,_xlpm._GMax,_xlpm._RankMin,_xlpm._RankMax,_xlpm._GMin+(_xlpm._GMax-_xlpm._GMin)/(_xlpm._RankMax-_xlpm._RankMin)*(J21-_xlpm._RankMin))(300,560,8,18)} -> 430 | M21: {=_xlfn.TEXTJOIN("，",1,IFERROR(VLOOKUP(VALUE(_xlfn.TEXTSPLIT(L21,";")),properties!A:C,3,0),""))} | N21: ="0~0" -> 0~0 | P21: 卧槽;握草;我草;会不会开车
A22: 15119 | B22: =_xlfn.TEXTJOIN("_",1,"role",A22) -> role_15119 | C22: 蟹bro拟人 | D22: TRUE | E22: =_xlfn.LET(_xlpm._type,IF($D22,"hero","npc"), _xlfn.CONCAT("namecard_",_xlpm._type,"[namecard-",_xlpm._type,"_",VALUE(RIGHT($A22-1,2)),"]")) -> namecard_hero[namecard-hero_18] | F22: =_xlfn.LET(_xlpm._type,IF($D22,"hero","npc"), _xlfn.CONCAT("ill_big_",_xlpm._type,"[ill-big-",_xlpm._type,"_",VALUE(RIGHT($A22-1,2)),"]")) -> ill_big_hero[ill-big-hero_18] | G22: =_xlfn.LET(_xlpm._type,IF($D22,"hero","npc"), _xlfn.CONCAT("ill_small_",_xlpm._type,"[ill_small_",_xlpm._type,"_",VALUE(RIGHT($A22-1,2)),"]")) -> ill_small_hero[ill_small_hero_18] | H22: =_xlfn.LET(_xlpm._asset,"ui_npc_shop_ill_viewed", _xlfn.CONCAT(_xlpm._asset,"[",_xlpm._asset,"_",$I22,"]")) -> ui_npc_shop_ill_viewed[ui_npc_shop_ill_viewed_18] | I22: 18 | J22: =INT(8*1.033^(RIGHT(A22,2)-1)) -> 14 | K22: {=_xlfn.LAMBDA(_xlpm._GMin,_xlpm._GMax,_xlpm._RankMin,_xlpm._RankMax,_xlpm._GMin+(_xlpm._GMax-_xlpm._GMin)/(_xlpm._RankMax-_xlpm._RankMin)*(J22-_xlpm._RankMin))(300,560,8,18)} -> 456 | M22: {=_xlfn.TEXTJOIN("，",1,IFERROR(VLOOKUP(VALUE(_xlfn.TEXTSPLIT(L22,";")),properties!A:C,3,0),""))} | N22: ="0~0" -> 0~0 | P22: 咕噜咕噜;咕噜咕噜咕噜;咕噜，咕噜咕噜
A23: 15120 | B23: =_xlfn.TEXTJOIN("_",1,"role",A23) -> role_15120 | C23: 艾米丽 | D23: TRUE | E23: =_xlfn.LET(_xlpm._type,IF($D23,"hero","npc"), _xlfn.CONCAT("namecard_",_xlpm._type,"[namecard-",_xlpm._type,"_",VALUE(RIGHT($A23-1,2)),"]")) -> namecard_hero[namecard-hero_19] | F23: =_xlfn.LET(_xlpm._type,IF($D23,"hero","npc"), _xlfn.CONCAT("ill_big_",_xlpm._type,"[ill-big-",_xlpm._type,"_",VALUE(RIGHT($A23-1,2)),"]")) -> ill_big_hero[ill-big-hero_19] | G23: =_xlfn.LET(_xlpm._type,IF($D23,"hero","npc"), _xlfn.CONCAT("ill_small_",_xlpm._type,"[ill_small_",_xlpm._type,"_",VALUE(RIGHT($A23-1,2)),"]")) -> ill_small_hero[ill_small_hero_19] | H23: =_xlfn.LET(_xlpm._asset,"ui_npc_shop_ill_viewed", _xlfn.CONCAT(_xlpm._asset,"[",_xlpm._asset,"_",$I23,"]")) -> ui_npc_shop_ill_viewed[ui_npc_shop_ill_viewed_19] | I23: 19 | J23: =INT(8*1.033^(RIGHT(A23,2)-1)) -> 14 | K23: {=_xlfn.LAMBDA(_xlpm._GMin,_xlpm._GMax,_xlpm._RankMin,_xlpm._RankMax,_xlpm._GMin+(_xlpm._GMax-_xlpm._GMin)/(_xlpm._RankMax-_xlpm._RankMin)*(J23-_xlpm._RankMin))(300,560,8,18)} -> 456 | L23: 16307;16412 | M23: {=_xlfn.TEXTJOIN("，",1,IFERROR(VLOOKUP(VALUE(_xlfn.TEXTSPLIT(L23,";")),properties!A:C,3,0),""))} -> 工坊工匠，庄园主 | N23: ="0~0" -> 0~0 | P23: 卧槽;握草;我草;会不会开车
A25: 15121 | B25: =_xlfn.TEXTJOIN("_",1,"role",A25) -> role_15121 | C25: 原创妹妹一 | D25: TRUE | E25: namecard_hero[namecard-hero_2] | F25: =_xlfn.LET(_xlpm._type,IF($D25,"hero","npc"), _xlfn.CONCAT("ill_big_",_xlpm._type,"[ill-big-",_xlpm._type,"_",VALUE(RIGHT($A25-1,2)),"]")) -> ill_big_hero[ill-big-hero_20] | G25: =_xlfn.LET(_xlpm._type,IF($D25,"hero","npc"), _xlfn.CONCAT("ill_small_",_xlpm._type,"[ill_small_",_xlpm._type,"_",VALUE(RIGHT($A25-1,2)),"]")) -> ill_small_hero[ill_small_hero_20] | J25: =INT(8*1.033^(RIGHT(A25,2)-1)) -> 15 | K25: {=_xlfn.LAMBDA(_xlpm._GMin,_xlpm._GMax,_xlpm._RankMin,_xlpm._RankMax,_xlpm._GMin+(_xlpm._GMax-_xlpm._GMin)/(_xlpm._RankMax-_xlpm._RankMin)*(J25-_xlpm._RankMin))(300,560,8,18)} -> 482 | N25: ="0~0" -> 0~0
A26: 15122 | B26: =_xlfn.TEXTJOIN("_",1,"role",A26) -> role_15122 | C26: 原创妹妹二 | D26: TRUE | E26: namecard_hero[namecard-hero_2] | F26: =_xlfn.LET(_xlpm._type,IF($D26,"hero","npc"), _xlfn.CONCAT("ill_big_",_xlpm._type,"[ill-big-",_xlpm._type,"_",VALUE(RIGHT($A26-1,2)),"]")) -> ill_big_hero[ill-big-hero_21] | G26: =_xlfn.LET(_xlpm._type,IF($D26,"hero","npc"), _xlfn.CONCAT("ill_small_",_xlpm._type,"[ill_small_",_xlpm._type,"_",VALUE(RIGHT($A26-1,2)),"]")) -> ill_small_hero[ill_small_hero_21] | J26: =INT(8*1.033^(RIGHT(A26,2)-1)) -> 15 | K26: {=_xlfn.LAMBDA(_xlpm._GMin,_xlpm._GMax,_xlpm._RankMin,_xlpm._RankMax,_xlpm._GMin+(_xlpm._GMax-_xlpm._GMin)/(_xlpm._RankMax-_xlpm._RankMin)*(J26-_xlpm._RankMin))(300,560,8,18)} -> 482 | N26: ="0~0" -> 0~0
A27: 15123 | B27: =_xlfn.TEXTJOIN("_",1,"role",A27) -> role_15123 | C27: 原创妹妹三 | D27: TRUE | E27: namecard_hero[namecard-hero_2] | F27: =_xlfn.LET(_xlpm._type,IF($D27,"hero","npc"), _xlfn.CONCAT("ill_big_",_xlpm._type,"[ill-big-",_xlpm._type,"_",VALUE(RIGHT($A27-1,2)),"]")) -> ill_big_hero[ill-big-hero_22] | G27: =_xlfn.LET(_xlpm._type,IF($D27,"hero","npc"), _xlfn.CONCAT("ill_small_",_xlpm._type,"[ill_small_",_xlpm._type,"_",VALUE(RIGHT($A27-1,2)),"]")) -> ill_small_hero[ill_small_hero_22] | J27: =INT(8*1.033^(RIGHT(A27,2)-1)) -> 16 | K27: {=_xlfn.LAMBDA(_xlpm._GMin,_xlpm._GMax,_xlpm._RankMin,_xlpm._RankMax,_xlpm._GMin+(_xlpm._GMax-_xlpm._GMin)/(_xlpm._RankMax-_xlpm._RankMin)*(J27-_xlpm._RankMin))(300,560,8,18)} -> 508 | N27: ="0~0" -> 0~0
A28: 15124 | B28: =_xlfn.TEXTJOIN("_",1,"role",A28) -> role_15124 | C28: 原创妹妹四 | D28: TRUE | E28: namecard_hero[namecard-hero_2] | F28: =_xlfn.LET(_xlpm._type,IF($D28,"hero","npc"), _xlfn.CONCAT("ill_big_",_xlpm._type,"[ill-big-",_xlpm._type,"_",VALUE(RIGHT($A28-1,2)),"]")) -> ill_big_hero[ill-big-hero_23] | G28: =_xlfn.LET(_xlpm._type,IF($D28,"hero","npc"), _xlfn.CONCAT("ill_small_",_xlpm._type,"[ill_small_",_xlpm._type,"_",VALUE(RIGHT($A28-1,2)),"]")) -> ill_small_hero[ill_small_hero_23] | J28: =INT(8*1.033^(RIGHT(A28,2)-1)) -> 16 | K28: {=_xlfn.LAMBDA(_xlpm._GMin,_xlpm._GMax,_xlpm._RankMin,_xlpm._RankMax,_xlpm._GMin+(_xlpm._GMax-_xlpm._GMin)/(_xlpm._RankMax-_xlpm._RankMin)*(J28-_xlpm._RankMin))(300,560,8,18)} -> 508 | N28: ="0~0" -> 0~0
A30: 15125 | B30: =_xlfn.TEXTJOIN("_",1,"role",A30) -> role_15125 | C30: 地宫特殊npc | D30: TRUE | E30: namecard_hero[namecard-hero_2] | J30: 12 | K30: {=_xlfn.LAMBDA(_xlpm._GMin,_xlpm._GMax,_xlpm._RankMin,_xlpm._RankMax,_xlpm._GMin+(_xlpm._GMax-_xlpm._GMin)/(_xlpm._RankMax-_xlpm._RankMin)*(J30-_xlpm._RankMin))(300,560,8,18)} -> 404 | N30: ="0~0" -> 0~0
A31: 15126 | B31: =_xlfn.TEXTJOIN("_",1,"role",A31) -> role_15126 | C31: 天空特殊npc | D31: TRUE | E31: namecard_hero[namecard-hero_2] | J31: 18 | K31: 99999 | N31: ="0~0" -> 0~0
A32: 15127 | B32: =_xlfn.TEXTJOIN("_",1,"role",A32) -> role_15127 | C32: 密林特殊npc | D32: TRUE | E32: namecard_hero[namecard-hero_2] | J32: 18 | K32: {=_xlfn.LAMBDA(_xlpm._GMin,_xlpm._GMax,_xlpm._RankMin,_xlpm._RankMax,_xlpm._GMin+(_xlpm._GMax-_xlpm._GMin)/(_xlpm._RankMax-_xlpm._RankMin)*(J32-_xlpm._RankMin))(300,560,8,18)} -> 560 | N32: ="0~0" -> 0~0
A33: 15128 | B33: =_xlfn.TEXTJOIN("_",1,"role",A33) -> role_15128 | C33: 树梢特殊npc | D33: TRUE | E33: namecard_hero[namecard-hero_2] | J33: 16 | K33: {=_xlfn.LAMBDA(_xlpm._GMin,_xlpm._GMax,_xlpm._RankMin,_xlpm._RankMax,_xlpm._GMin+(_xlpm._GMax-_xlpm._GMin)/(_xlpm._RankMax-_xlpm._RankMin)*(J33-_xlpm._RankMin))(300,560,8,18)} -> 508 | N33: ="0~0" -> 0~0
A34: 15129 | B34: =_xlfn.TEXTJOIN("_",1,"role",A34) -> role_15129 | C34: 田野特殊npc | D34: TRUE | E34: namecard_hero[namecard-hero_2] | J34: 18 | K34: {=_xlfn.LAMBDA(_xlpm._GMin,_xlpm._GMax,_xlpm._RankMin,_xlpm._RankMax,_xlpm._GMin+(_xlpm._GMax-_xlpm._GMin)/(_xlpm._RankMax-_xlpm._RankMin)*(J34-_xlpm._RankMin))(300,560,8,18)} -> 560 | N34: ="0~0" -> 0~0
A35: 15130 | B35: =_xlfn.TEXTJOIN("_",1,"role",A35) -> role_15130 | C35: 永夜特殊npc | D35: TRUE | E35: namecard_hero[namecard-hero_2] | J35: 18 | K35: {=_xlfn.LAMBDA(_xlpm._GMin,_xlpm._GMax,_xlpm._RankMin,_xlpm._RankMax,_xlpm._GMin+(_xlpm._GMax-_xlpm._GMin)/(_xlpm._RankMax-_xlpm._RankMin)*(J35-_xlpm._RankMin))(300,560,8,18)} -> 560 | N35: ="0~0" -> 0~0
A36: 15131 | B36: =_xlfn.TEXTJOIN("_",1,"role",A36) -> role_15131 | C36: 沙漠特殊npc | D36: TRUE | E36: namecard_hero[namecard-hero_2] | J36: 16 | K36: {=_xlfn.LAMBDA(_xlpm._GMin,_xlpm._GMax,_xlpm._RankMin,_xlpm._RankMax,_xlpm._GMin+(_xlpm._GMax-_xlpm._GMin)/(_xlpm._RankMax-_xlpm._RankMin)*(J36-_xlpm._RankMin))(300,560,8,18)} -> 508 | N36: ="0~0" -> 0~0
A37: 15132 | B37: =_xlfn.TEXTJOIN("_",1,"role",A37) -> role_15132 | C37: 大湖特殊npc | D37: TRUE | E37: namecard_hero[namecard-hero_2] | J37: 14 | K37: {=_xlfn.LAMBDA(_xlpm._GMin,_xlpm._GMax,_xlpm._RankMin,_xlpm._RankMax,_xlpm._GMin+(_xlpm._GMax-_xlpm._GMin)/(_xlpm._RankMax-_xlpm._RankMin)*(J37-_xlpm._RankMin))(300,560,8,18)} -> 456 | N37: ="0~0" -> 0~0

Sheet properties
A1: id | B1: name | D1: rank | E1: negative | F1: desc | H1: script | I1: int_parms | J1: float_parms
A2: uint key | B2: string | D2: int | E2: bool | F2: string | H2: string | I2: int[] | J2: float[]
A3: id | B3: 词条名称 localization表id | C3: 备注 词条名称 | D3: 词条等级 | E3: 负面特性 | F3: 词条描述 localization表id | G3: 备注2 | H3: 脚本 | I3: 参数列表 int | J3: 参数列表 float
A4: 1600101 | B4: =_xlfn.TEXTJOIN("_",1,"trait_name",$A4) -> trait_name_1600101 | C4: 职业杀手 | D4: 1 | F4: =_xlfn.TEXTJOIN("_",1,"trait_desc",$A4) -> trait_desc_1600101 | G4: {=_xlfn.LET(_xlpm.trait_name,$H4, _xlpm.parms1,$I4, _xlpm.parms2,$J4, _xlpm.expr,RIGHT(desc,LEN(desc)-FIND("=",desc)), _xlpm.suffix,_xlfn.SWITCH(_xlpm.trait_name, "CP_Device_Skilled",_xlfn.CONCAT("操作以下设备时，战斗效率",IF(_xlpm.parms2>=0,"+",""),_xlpm.parms2,": ",_xlfn.TEXTJOIN(", ",1,"<br>"&VLOOKUP(VALUE(_xlfn.TEXTSPLIT(_xlpm.parms1,";")),table_tag[#All],2,0))), "CP_Device_Disabled",_xlfn.CONCAT("无法操作以下设备：",_xlfn.TEXTJOIN(", ",1,"<br>"&VLOOKUP(VALUE(_xlfn.TEXTSPLIT(_xlpm.parms1,";")),table_tag[#All],2,0))), "CP_Big_Eater","每次进食消耗"&_xlpm.parms1&"份食物，但进食后心情+"&_xlpm.parms2, "CP_Food_Saver","每次进食有"&TEXT(_xlpm.parms1/1000,"0%")&"的概率不消耗食物" ), IFERROR(IF($A4<>"",_xlpm.suffix,""),"//特性描述待配置"))} -> 操作以下设备时，战斗效率+30: <br>手枪 | H4: CP_Device_Skilled | I4: 1420211 | J4: 30
A5: 1600102 | B5: =_xlfn.TEXTJOIN("_",1,"trait_name",$A5) -> trait_name_1600102 | C5: 猎人 | D5: 1 | F5: =_xlfn.TEXTJOIN("_",1,"trait_desc",$A5) -> trait_desc_1600102 | G5: {=_xlfn.LET(_xlpm.trait_name,$H5, _xlpm.parms1,$I5, _xlpm.parms2,$J5, _xlpm.expr,RIGHT(desc,LEN(desc)-FIND("=",desc)), _xlpm.suffix,_xlfn.SWITCH(_xlpm.trait_name, "CP_Device_Skilled",_xlfn.CONCAT("操作以下设备时，战斗效率",IF(_xlpm.parms2>=0,"+",""),_xlpm.parms2,": ",_xlfn.TEXTJOIN(", ",1,"<br>"&VLOOKUP(VALUE(_xlfn.TEXTSPLIT(_xlpm.parms1,";")),table_tag[#All],2,0))), "CP_Device_Disabled",_xlfn.CONCAT("无法操作以下设备：",_xlfn.TEXTJOIN(", ",1,"<br>"&VLOOKUP(VALUE(_xlfn.TEXTSPLIT(_xlpm.parms1,";")),table_tag[#All],2,0))), "CP_Big_Eater","每次进食消耗"&_xlpm.parms1&"份食物，但进食后心情+"&_xlpm.parms2, "CP_Food_Saver","每次进食有"&TEXT(_xlpm.parms1/1000,"0%")&"的概率不消耗食物" ), IFERROR(IF($A5<>"",_xlpm.suffix,""),"//特性描述待配置"))} -> 操作以下设备时，战斗效率+30: <br>长矛, <br>弓箭 | H5: CP_Device_Skilled | I5: 1420102;1420221 | J5: 30
A6: 1600103 | B6: =_xlfn.TEXTJOIN("_",1,"trait_name",$A6) -> trait_name_1600103 | C6: 防暴队员 | D6: 1 | F6: =_xlfn.TEXTJOIN("_",1,"trait_desc",$A6) -> trait_desc_1600103 | G6: {=_xlfn.LET(_xlpm.trait_name,$H6, _xlpm.parms1,$I6, _xlpm.parms2,$J6, _xlpm.expr,RIGHT(desc,LEN(desc)-FIND("=",desc)), _xlpm.suffix,_xlfn.SWITCH(_xlpm.trait_name, "CP_Device_Skilled",_xlfn.CONCAT("操作以下设备时，战斗效率",IF(_xlpm.parms2>=0,"+",""),_xlpm.parms2,": ",_xlfn.TEXTJOIN(", ",1,"<br>"&VLOOKUP(VALUE(_xlfn.TEXTSPLIT(_xlpm.parms1,";")),table_tag[#All],2,0))), "CP_Device_Disabled",_xlfn.CONCAT("无法操作以下设备：",_xlfn.TEXTJOIN(", ",1,"<br>"&VLOOKUP(VALUE(_xlfn.TEXTSPLIT(_xlpm.parms1,";")),table_tag[#All],2,0))), "CP_Big_Eater","每次进食消耗"&_xlpm.parms1&"份食物，但进食后心情+"&_xlpm.parms2, "CP_Food_Saver","每次进食有"&TEXT(_xlpm.parms1/1000,"0%")&"的概率不消耗食物" ), IFERROR(IF($A6<>"",_xlpm.suffix,""),"//特性描述待配置"))} -> 操作以下设备时，战斗效率+30: <br>霰弹枪, <br>盾牌 | H6: CP_Device_Skilled | I6: 1420212;1420400 | J6: 30
A7: 1600108 | B7: =_xlfn.TEXTJOIN("_",1,"trait_name",$A7) -> trait_name_1600108 | C7: 近战武器大师 | D7: 2 | F7: =_xlfn.TEXTJOIN("_",1,"trait_desc",$A7) -> trait_desc_1600108 | G7: {=_xlfn.LET(_xlpm.trait_name,$H7, _xlpm.parms1,$I7, _xlpm.parms2,$J7, _xlpm.expr,RIGHT(desc,LEN(desc)-FIND("=",desc)), _xlpm.suffix,_xlfn.SWITCH(_xlpm.trait_name, "CP_Device_Skilled",_xlfn.CONCAT("操作以下设备时，战斗效率",IF(_xlpm.parms2>=0,"+",""),_xlpm.parms2,": ",_xlfn.TEXTJOIN(", ",1,"<br>"&VLOOKUP(VALUE(_xlfn.TEXTSPLIT(_xlpm.parms1,";")),table_tag[#All],2,0))), "CP_Device_Disabled",_xlfn.CONCAT("无法操作以下设备：",_xlfn.TEXTJOIN(", ",1,"<br>"&VLOOKUP(VALUE(_xlfn.TEXTSPLIT(_xlpm.parms1,";")),table_tag[#All],2,0))), "CP_Big_Eater","每次进食消耗"&_xlpm.parms1&"份食物，但进食后心情+"&_xlpm.parms2, "CP_Food_Saver","每次进食有"&TEXT(_xlpm.parms1/1000,"0%")&"的概率不消耗食物" ), IFERROR(IF($A7<>"",_xlpm.suffix,""),"//特性描述待配置"))} -> 操作以下设备时，战斗效率+60: <br>近战武器 | H7: CP_Device_Skilled | I7: 1420100 | J7: 60
A8: 1600109 | B8: =_xlfn.TEXTJOIN("_",1,"trait_name",$A8) -> trait_name_1600109 | C8: 远程武器大师 | D8: 2 | F8: =_xlfn.TEXTJOIN("_",1,"trait_desc",$A8) -> trait_desc_1600109 | G8: {=_xlfn.LET(_xlpm.trait_name,$H8, _xlpm.parms1,$I8, _xlpm.parms2,$J8, _xlpm.expr,RIGHT(desc,LEN(desc)-FIND("=",desc)), _xlpm.suffix,_xlfn.SWITCH(_xlpm.trait_name, "CP_Device_Skilled",_xlfn.CONCAT("操作以下设备时，战斗效率",IF(_xlpm.parms2>=0,"+",""),_xlpm.parms2,": ",_xlfn.TEXTJOIN(", ",1,"<br>"&VLOOKUP(VALUE(_xlfn.TEXTSPLIT(_xlpm.parms1,";")),table_tag[#All],2,0))), "CP_Device_Disabled",_xlfn.CONCAT("无法操作以下设备：",_xlfn.TEXTJOIN(", ",1,"<br>"&VLOOKUP(VALUE(_xlfn.TEXTSPLIT(_xlpm.parms1,";")),table_tag[#All],2,0))), "CP_Big_Eater","每次进食消耗"&_xlpm.parms1&"份食物，但进食后心情+"&_xlpm.parms2, "CP_Food_Saver","每次进食有"&TEXT(_xlpm.parms1/1000,"0%")&"的概率不消耗食物" ), IFERROR(IF($A8<>"",_xlpm.suffix,""),"//特性描述待配置"))} -> 操作以下设备时，战斗效率+60: <br>远程武器 | H8: CP_Device_Skilled | I8: 1420200 | J8: 60
G9: {=_xlfn.LET(_xlpm.trait_name,$H9, _xlpm.parms1,$I9, _xlpm.parms2,$J9, _xlpm.expr,RIGHT(desc,LEN(desc)-FIND("=",desc)), _xlpm.suffix,_xlfn.SWITCH(_xlpm.trait_name, "CP_Device_Skilled",_xlfn.CONCAT("操作以下设备时，战斗效率",IF(_xlpm.parms2>=0,"+",""),_xlpm.parms2,": ",_xlfn.TEXTJOIN(", ",1,"<br>"&VLOOKUP(VALUE(_xlfn.TEXTSPLIT(_xlpm.parms1,";")),table_tag[#All],2,0))), "CP_Device_Disabled",_xlfn.CONCAT("无法操作以下设备：",_xlfn.TEXTJOIN(", ",1,"<br>"&VLOOKUP(VALUE(_xlfn.TEXTSPLIT(_xlpm.parms1,";")),table_tag[#All],2,0))), "CP_Big_Eater","每次进食消耗"&_xlpm.parms1&"份食物，但进食后心情+"&_xlpm.parms2, "CP_Food_Saver","每次进食有"&TEXT(_xlpm.parms1/1000,"0%")&"的概率不消耗食物" ), IFERROR(IF($A9<>"",_xlpm.suffix,""),"//特性描述待配置"))}
A10: 1600201 | B10: =_xlfn.TEXTJOIN("_",1,"trait_name",$A10) -> trait_name_1600201 | C10: 刀剑笨拙 | D10: -1 | E10: TRUE | F10: =_xlfn.TEXTJOIN("_",1,"trait_desc",$A10) -> trait_desc_1600201 | G10: {=_xlfn.LET(_xlpm.trait_name,$H10, _xlpm.parms1,$I10, _xlpm.parms2,$J10, _xlpm.expr,RIGHT(desc,LEN(desc)-FIND("=",desc)), _xlpm.suffix,_xlfn.SWITCH(_xlpm.trait_name, "CP_Device_Skilled",_xlfn.CONCAT("操作以下设备时，战斗效率",IF(_xlpm.parms2>=0,"+",""),_xlpm.parms2,": ",_xlfn.TEXTJOIN(", ",1,"<br>"&VLOOKUP(VALUE(_xlfn.TEXTSPLIT(_xlpm.parms1,";")),table_tag[#All],2,0))), "CP_Device_Disabled",_xlfn.CONCAT("无法操作以下设备：",_xlfn.TEXTJOIN(", ",1,"<br>"&VLOOKUP(VALUE(_xlfn.TEXTSPLIT(_xlpm.parms1,";")),table_tag[#All],2,0))), "CP_Big_Eater","每次进食消耗"&_xlpm.parms1&"份食物，但进食后心情+"&_xlpm.parms2, "CP_Food_Saver","每次进食有"&TEXT(_xlpm.parms1/1000,"0%")&"的概率不消耗食物" ), IFERROR(IF($A10<>"",_xlpm.suffix,""),"//特性描述待配置"))} -> 操作以下设备时，战斗效率-30: <br>刀剑 | H10: CP_Device_Skilled | I10: 1420101 | J10: -30
A11: 1600202 | B11: =_xlfn.TEXTJOIN("_",1,"trait_name",$A11) -> trait_name_1600202 | C11: 长矛笨拙 | D11: -1 | E11: TRUE | F11: =_xlfn.TEXTJOIN("_",1,"trait_desc",$A11) -> trait_desc_1600202 | G11: {=_xlfn.LET(_xlpm.trait_name,$H11, _xlpm.parms1,$I11, _xlpm.parms2,$J11, _xlpm.expr,RIGHT(desc,LEN(desc)-FIND("=",desc)), _xlpm.suffix,_xlfn.SWITCH(_xlpm.trait_name, "CP_Device_Skilled",_xlfn.CONCAT("操作以下设备时，战斗效率",IF(_xlpm.parms2>=0,"+",""),_xlpm.parms2,": ",_xlfn.TEXTJOIN(", ",1,"<br>"&VLOOKUP(VALUE(_xlfn.TEXTSPLIT(_xlpm.parms1,";")),table_tag[#All],2,0))), "CP_Device_Disabled",_xlfn.CONCAT("无法操作以下设备：",_xlfn.TEXTJOIN(", ",1,"<br>"&VLOOKUP(VALUE(_xlfn.TEXTSPLIT(_xlpm.parms1,";")),table_tag[#All],2,0))), "CP_Big_Eater","每次进食消耗"&_xlpm.parms1&"份食物，但进食后心情+"&_xlpm.parms2, "CP_Food_Saver","每次进食有"&TEXT(_xlpm.parms1/1000,"0%")&"的概率不消耗食物" ), IFERROR(IF($A11<>"",_xlpm.suffix,""),"//特性描述待配置"))} -> 操作以下设备时，战斗效率-30: <br>长矛 | H11: CP_Device_Skilled | I11: 1420102 | J11: -30
A12: 1600203 | B12: =_xlfn.TEXTJOIN("_",1,"trait_name",$A12) -> trait_name_1600203 | C12: 棍棒笨拙 | D12: -1 | E12: TRUE | F12: =_xlfn.TEXTJOIN("_",1,"trait_desc",$A12) -> trait_desc_1600203 | G12: {=_xlfn.LET(_xlpm.trait_name,$H12, _xlpm.parms1,$I12, _xlpm.parms2,$J12, _xlpm.expr,RIGHT(desc,LEN(desc)-FIND("=",desc)), _xlpm.suffix,_xlfn.SWITCH(_xlpm.trait_name, "CP_Device_Skilled",_xlfn.CONCAT("操作以下设备时，战斗效率",IF(_xlpm.parms2>=0,"+",""),_xlpm.parms2,": ",_xlfn.TEXTJOIN(", ",1,"<br>"&VLOOKUP(VALUE(_xlfn.TEXTSPLIT(_xlpm.parms1,";")),table_tag[#All],2,0))), "CP_Device_Disabled",_xlfn.CONCAT("无法操作以下设备：",_xlfn.TEXTJOIN(", ",1,"<br>"&VLOOKUP(VALUE(_xlfn.TEXTSPLIT(_xlpm.parms1,";")),table_tag[#All],2,0))), "CP_Big_Eater","每次进食消耗"&_xlpm.parms1&"份食物，但进食后心情+"&_xlpm.parms2, "CP_Food_Saver","每次进食有"&TEXT(_xlpm.parms1/1000,"0%")&"的概率不消耗食物" ), IFERROR(IF($A12<>"",_xlpm.suffix,""),"//特性描述待配置"))} -> 操作以下设备时，战斗效率-30: <br>棍棒 | H12: CP_Device_Skilled | I12: 1420103 | J12: -30
A13: 1600204 | B13: =_xlfn.TEXTJOIN("_",1,"trait_name",$A13) -> trait_name_1600204 | C13: 斧钺笨拙 | D13: -1 | E13: TRUE | F13: =_xlfn.TEXTJOIN("_",1,"trait_desc",$A13) -> trait_desc_1600204 | G13: {=_xlfn.LET(_xlpm.trait_name,$H13, _xlpm.parms1,$I13, _xlpm.parms2,$J13, _xlpm.expr,RIGHT(desc,LEN(desc)-FIND("=",desc)), _xlpm.suffix,_xlfn.SWITCH(_xlpm.trait_name, "CP_Device_Skilled",_xlfn.CONCAT("操作以下设备时，战斗效率",IF(_xlpm.parms2>=0,"+",""),_xlpm.parms2,": ",_xlfn.TEXTJOIN(", ",1,"<br>"&VLOOKUP(VALUE(_xlfn.TEXTSPLIT(_xlpm.parms1,";")),table_tag[#All],2,0))), "CP_Device_Disabled",_xlfn.CONCAT("无法操作以下设备：",_xlfn.TEXTJOIN(", ",1,"<br>"&VLOOKUP(VALUE(_xlfn.TEXTSPLIT(_xlpm.parms1,";")),table_tag[#All],2,0))), "CP_Big_Eater","每次进食消耗"&_xlpm.parms1&"份食物，但进食后心情+"&_xlpm.parms2, "CP_Food_Saver","每次进食有"&TEXT(_xlpm.parms1/1000,"0%")&"的概率不消耗食物" ), IFERROR(IF($A13<>"",_xlpm.suffix,""),"//特性描述待配置"))} -> 操作以下设备时，战斗效率-30: <br>斧钺 | H13: CP_Device_Skilled | I13: 1420104 | J13: -30
G14: {=_xlfn.LET(_xlpm.trait_name,$H14, _xlpm.parms1,$I14, _xlpm.parms2,$J14, _xlpm.expr,RIGHT(desc,LEN(desc)-FIND("=",desc)), _xlpm.suffix,_xlfn.SWITCH(_xlpm.trait_name, "CP_Device_Skilled",_xlfn.CONCAT("操作以下设备时，战斗效率",IF(_xlpm.parms2>=0,"+",""),_xlpm.parms2,": ",_xlfn.TEXTJOIN(", ",1,"<br>"&VLOOKUP(VALUE(_xlfn.TEXTSPLIT(_xlpm.parms1,";")),table_tag[#All],2,0))), "CP_Device_Disabled",_xlfn.CONCAT("无法操作以下设备：",_xlfn.TEXTJOIN(", ",1,"<br>"&VLOOKUP(VALUE(_xlfn.TEXTSPLIT(_xlpm.parms1,";")),table_tag[#All],2,0))), "CP_Big_Eater","每次进食消耗"&_xlpm.parms1&"份食物，但进食后心情+"&_xlpm.parms2, "CP_Food_Saver","每次进食有"&TEXT(_xlpm.parms1/1000,"0%")&"的概率不消耗食物" ), IFERROR(IF($A14<>"",_xlpm.suffix,""),"//特性描述待配置"))}
A15: 1600301 | B15: =_xlfn.TEXTJOIN("_",1,"trait_name",$A15) -> trait_name_1600301 | C15: 刀剑白痴 | D15: -2 | E15: TRUE | F15: =_xlfn.TEXTJOIN("_",1,"trait_desc",$A15) -> trait_desc_1600301 | G15: {=_xlfn.LET(_xlpm.trait_name,$H15, _xlpm.parms1,$I15, _xlpm.parms2,$J15, _xlpm.expr,RIGHT(desc,LEN(desc)-FIND("=",desc)), _xlpm.suffix,_xlfn.SWITCH(_xlpm.trait_name, "CP_Device_Skilled",_xlfn.CONCAT("操作以下设备时，战斗效率",IF(_xlpm.parms2>=0,"+",""),_xlpm.parms2,": ",_xlfn.TEXTJOIN(", ",1,"<br>"&VLOOKUP(VALUE(_xlfn.TEXTSPLIT(_xlpm.parms1,";")),table_tag[#All],2,0))), "CP_Device_Disabled",_xlfn.CONCAT("无法操作以下设备：",_xlfn.TEXTJOIN(", ",1,"<br>"&VLOOKUP(VALUE(_xlfn.TEXTSPLIT(_xlpm.parms1,";")),table_tag[#All],2,0))), "CP_Big_Eater","每次进食消耗"&_xlpm.parms1&"份食物，但进食后心情+"&_xlpm.parms2, "CP_Food_Saver","每次进食有"&TEXT(_xlpm.parms1/1000,"0%")&"的概率不消耗食物" ), IFERROR(IF($A15<>"",_xlpm.suffix,""),"//特性描述待配置"))} -> 无法操作以下设备：<br>刀剑 | H15: CP_Device_Disabled | I15: 1420101
A16: 1600302 | B16: =_xlfn.TEXTJOIN("_",1,"trait_name",$A16) -> trait_name_1600302 | C16: 长矛白痴 | D16: -2 | E16: TRUE | F16: =_xlfn.TEXTJOIN("_",1,"trait_desc",$A16) -> trait_desc_1600302 | G16: {=_xlfn.LET(_xlpm.trait_name,$H16, _xlpm.parms1,$I16, _xlpm.parms2,$J16, _xlpm.expr,RIGHT(desc,LEN(desc)-FIND("=",desc)), _xlpm.suffix,_xlfn.SWITCH(_xlpm.trait_name, "CP_Device_Skilled",_xlfn.CONCAT("操作以下设备时，战斗效率",IF(_xlpm.parms2>=0,"+",""),_xlpm.parms2,": ",_xlfn.TEXTJOIN(", ",1,"<br>"&VLOOKUP(VALUE(_xlfn.TEXTSPLIT(_xlpm.parms1,";")),table_tag[#All],2,0))), "CP_Device_Disabled",_xlfn.CONCAT("无法操作以下设备：",_xlfn.TEXTJOIN(", ",1,"<br>"&VLOOKUP(VALUE(_xlfn.TEXTSPLIT(_xlpm.parms1,";")),table_tag[#All],2,0))), "CP_Big_Eater","每次进食消耗"&_xlpm.parms1&"份食物，但进食后心情+"&_xlpm.parms2, "CP_Food_Saver","每次进食有"&TEXT(_xlpm.parms1/1000,"0%")&"的概率不消耗食物" ), IFERROR(IF($A16<>"",_xlpm.suffix,""),"//特性描述待配置"))} -> 无法操作以下设备：<br>长矛 | H16: CP_Device_Disabled | I16: 1420102
A17: 1600303 | B17: =_xlfn.TEXTJOIN("_",1,"trait_name",$A17) -> trait_name_1600303 | C17: 棍棒白痴 | D17: -2 | E17: TRUE | F17: =_xlfn.TEXTJOIN("_",1,"trait_desc",$A17) -> trait_desc_1600303 | G17: {=_xlfn.LET(_xlpm.trait_name,$H17, _xlpm.parms1,$I17, _xlpm.parms2,$J17, _xlpm.expr,RIGHT(desc,LEN(desc)-FIND("=",desc)), _xlpm.suffix,_xlfn.SWITCH(_xlpm.trait_name, "CP_Device_Skilled",_xlfn.CONCAT("操作以下设备时，战斗效率",IF(_xlpm.parms2>=0,"+",""),_xlpm.parms2,": ",_xlfn.TEXTJOIN(", ",1,"<br>"&VLOOKUP(VALUE(_xlfn.TEXTSPLIT(_xlpm.parms1,";")),table_tag[#All],2,0))), "CP_Device_Disabled",_xlfn.CONCAT("无法操作以下设备：",_xlfn.TEXTJOIN(", ",1,"<br>"&VLOOKUP(VALUE(_xlfn.TEXTSPLIT(_xlpm.parms1,";")),table_tag[#All],2,0))), "CP_Big_Eater","每次进食消耗"&_xlpm.parms1&"份食物，但进食后心情+"&_xlpm.parms2, "CP_Food_Saver","每次进食有"&TEXT(_xlpm.parms1/1000,"0%")&"的概率不消耗食物" ), IFERROR(IF($A17<>"",_xlpm.suffix,""),"//特性描述待配置"))} -> 无法操作以下设备：<br>棍棒 | H17: CP_Device_Disabled | I17: 1420103
G18: {=_xlfn.LET(_xlpm.trait_name,$H18, _xlpm.parms1,$I18, _xlpm.parms2,$J18, _xlpm.expr,RIGHT(desc,LEN(desc)-FIND("=",desc)), _xlpm.suffix,_xlfn.SWITCH(_xlpm.trait_name, "CP_Device_Skilled",_xlfn.CONCAT("操作以下设备时，战斗效率",IF(_xlpm.parms2>=0,"+",""),_xlpm.parms2,": ",_xlfn.TEXTJOIN(", ",1,"<br>"&VLOOKUP(VALUE(_xlfn.TEXTSPLIT(_xlpm.parms1,";")),table_tag[#All],2,0))), "CP_Device_Disabled",_xlfn.CONCAT("无法操作以下设备：",_xlfn.TEXTJOIN(", ",1,"<br>"&VLOOKUP(VALUE(_xlfn.TEXTSPLIT(_xlpm.parms1,";")),table_tag[#All],2,0))), "CP_Big_Eater","每次进食消耗"&_xlpm.parms1&"份食物，但进食后心情+"&_xlpm.parms2, "CP_Food_Saver","每次进食有"&TEXT(_xlpm.parms1/1000,"0%")&"的概率不消耗食物" ), IFERROR(IF($A18<>"",_xlpm.suffix,""),"//特性描述待配置"))}
A19: 1600401 | B19: =_xlfn.TEXTJOIN("_",1,"trait_name",$A19) -> trait_name_1600401 | C19: 和平主义者 | D19: -2 | E19: TRUE | F19: =_xlfn.TEXTJOIN("_",1,"trait_desc",$A19) -> trait_desc_1600401 | G19: {=_xlfn.LET(_xlpm.trait_name,$H19, _xlpm.parms1,$I19, _xlpm.parms2,$J19, _xlpm.expr,RIGHT(desc,LEN(desc)-FIND("=",desc)), _xlpm.suffix,_xlfn.SWITCH(_xlpm.trait_name, "CP_Device_Skilled",_xlfn.CONCAT("操作以下设备时，战斗效率",IF(_xlpm.parms2>=0,"+",""),_xlpm.parms2,": ",_xlfn.TEXTJOIN(", ",1,"<br>"&VLOOKUP(VALUE(_xlfn.TEXTSPLIT(_xlpm.parms1,";")),table_tag[#All],2,0))), "CP_Device_Disabled",_xlfn.CONCAT("无法操作以下设备：",_xlfn.TEXTJOIN(", ",1,"<br>"&VLOOKUP(VALUE(_xlfn.TEXTSPLIT(_xlpm.parms1,";")),table_tag[#All],2,0))), "CP_Big_Eater","每次进食消耗"&_xlpm.parms1&"份食物，但进食后心情+"&_xlpm.parms2, "CP_Food_Saver","每次进食有"&TEXT(_xlpm.parms1/1000,"0%")&"的概率不消耗食物" ), IFERROR(IF($A19<>"",_xlpm.suffix,""),"//特性描述待配置"))} -> //特性描述待配置 | H19: CP_Mood_After_Killing
A20: 1600402 | B20: =_xlfn.TEXTJOIN("_",1,"trait_name",$A20) -> trait_name_1600402 | C20: 暴力狂 | D20: 2 | F20: =_xlfn.TEXTJOIN("_",1,"trait_desc",$A20) -> trait_desc_1600402 | G20: {=_xlfn.LET(_xlpm.trait_name,$H20, _xlpm.parms1,$I20, _xlpm.parms2,$J20, _xlpm.expr,RIGHT(desc,LEN(desc)-FIND("=",desc)), _xlpm.suffix,_xlfn.SWITCH(_xlpm.trait_name, "CP_Device_Skilled",_xlfn.CONCAT("操作以下设备时，战斗效率",IF(_xlpm.parms2>=0,"+",""),_xlpm.parms2,": ",_xlfn.TEXTJOIN(", ",1,"<br>"&VLOOKUP(VALUE(_xlfn.TEXTSPLIT(_xlpm.parms1,";")),table_tag[#All],2,0))), "CP_Device_Disabled",_xlfn.CONCAT("无法操作以下设备：",_xlfn.TEXTJOIN(", ",1,"<br>"&VLOOKUP(VALUE(_xlfn.TEXTSPLIT(_xlpm.parms1,";")),table_tag[#All],2,0))), "CP_Big_Eater","每次进食消耗"&_xlpm.parms1&"份食物，但进食后心情+"&_xlpm.parms2, "CP_Food_Saver","每次进食有"&TEXT(_xlpm.parms1/1000,"0%")&"的概率不消耗食物" ), IFERROR(IF($A20<>"",_xlpm.suffix,""),"//特性描述待配置"))} -> //特性描述待配置 | H20: CP_Mood_After_Killing
G21: {=_xlfn.LET(_xlpm.trait_name,$H21, _xlpm.parms1,$I21, _xlpm.parms2,$J21, _xlpm.expr,RIGHT(desc,LEN(desc)-FIND("=",desc)), _xlpm.suffix,_xlfn.SWITCH(_xlpm.trait_name, "CP_Device_Skilled",_xlfn.CONCAT("操作以下设备时，战斗效率",IF(_xlpm.parms2>=0,"+",""),_xlpm.parms2,": ",_xlfn.TEXTJOIN(", ",1,"<br>"&VLOOKUP(VALUE(_xlfn.TEXTSPLIT(_xlpm.parms1,";")),table_tag[#All],2,0))), "CP_Device_Disabled",_xlfn.CONCAT("无法操作以下设备：",_xlfn.TEXTJOIN(", ",1,"<br>"&VLOOKUP(VALUE(_xlfn.TEXTSPLIT(_xlpm.parms1,";")),table_tag[#All],2,0))), "CP_Big_Eater","每次进食消耗"&_xlpm.parms1&"份食物，但进食后心情+"&_xlpm.parms2, "CP_Food_Saver","每次进食有"&TEXT(_xlpm.parms1/1000,"0%")&"的概率不消耗食物" ), IFERROR(IF($A21<>"",_xlpm.suffix,""),"//特性描述待配置"))}
A22: 1600501 | B22: =_xlfn.TEXTJOIN("_",1,"trait_name",$A22) -> trait_name_1600501 | C22: 怠惰 | F22: =_xlfn.TEXTJOIN("_",1,"trait_desc",$A22) -> trait_desc_1600501 | G22: {=_xlfn.LET(_xlpm.trait_name,$H22, _xlpm.parms1,$I22, _xlpm.parms2,$J22, _xlpm.expr,RIGHT(desc,LEN(desc)-FIND("=",desc)), _xlpm.suffix,_xlfn.SWITCH(_xlpm.trait_name, "CP_Device_Skilled",_xlfn.CONCAT("操作以下设备时，战斗效率",IF(_xlpm.parms2>=0,"+",""),_xlpm.parms2,": ",_xlfn.TEXTJOIN(", ",1,"<br>"&VLOOKUP(VALUE(_xlfn.TEXTSPLIT(_xlpm.parms1,";")),table_tag[#All],2,0))), "CP_Device_Disabled",_xlfn.CONCAT("无法操作以下设备：",_xlfn.TEXTJOIN(", ",1,"<br>"&VLOOKUP(VALUE(_xlfn.TEXTSPLIT(_xlpm.parms1,";")),table_tag[#All],2,0))), "CP_Big_Eater","每次进食消耗"&_xlpm.parms1&"份食物，但进食后心情+"&_xlpm.parms2, "CP_Food_Saver","每次进食有"&TEXT(_xlpm.parms1/1000,"0%")&"的概率不消耗食物" ), IFERROR(IF($A22<>"",_xlpm.suffix,""),"//特性描述待配置"))} -> //特性描述待配置 | H22: CP_Mood_After_Working
A23: 1600502 | B23: =_xlfn.TEXTJOIN("_",1,"trait_name",$A23) -> trait_name_1600502 | C23: 习惯工作 | F23: =_xlfn.TEXTJOIN("_",1,"trait_desc",$A23) -> trait_desc_1600502 | G23: {=_xlfn.LET(_xlpm.trait_name,$H23, _xlpm.parms1,$I23, _xlpm.parms2,$J23, _xlpm.expr,RIGHT(desc,LEN(desc)-FIND("=",desc)), _xlpm.suffix,_xlfn.SWITCH(_xlpm.trait_name, "CP_Device_Skilled",_xlfn.CONCAT("操作以下设备时，战斗效率",IF(_xlpm.parms2>=0,"+",""),_xlpm.parms2,": ",_xlfn.TEXTJOIN(", ",1,"<br>"&VLOOKUP(VALUE(_xlfn.TEXTSPLIT(_xlpm.parms1,";")),table_tag[#All],2,0))), "CP_Device_Disabled",_xlfn.CONCAT("无法操作以下设备：",_xlfn.TEXTJOIN(", ",1,"<br>"&VLOOKUP(VALUE(_xlfn.TEXTSPLIT(_xlpm.parms1,";")),table_tag[#All],2,0))), "CP_Big_Eater","每次进食消耗"&_xlpm.parms1&"份食物，但进食后心情+"&_xlpm.parms2, "CP_Food_Saver","每次进食有"&TEXT(_xlpm.parms1/1000,"0%")&"的概率不消耗食物" ), IFERROR(IF($A23<>"",_xlpm.suffix,""),"//特性描述待配置"))} -> //特性描述待配置 | H23: CP_Mood_After_Working
G24: {=_xlfn.LET(_xlpm.trait_name,$H24, _xlpm.parms1,$I24, _xlpm.parms2,$J24, _xlpm.expr,RIGHT(desc,LEN(desc)-FIND("=",desc)), _xlpm.suffix,_xlfn.SWITCH(_xlpm.trait_name, "CP_Device_Skilled",_xlfn.CONCAT("操作以下设备时，战斗效率",IF(_xlpm.parms2>=0,"+",""),_xlpm.parms2,": ",_xlfn.TEXTJOIN(", ",1,"<br>"&VLOOKUP(VALUE(_xlfn.TEXTSPLIT(_xlpm.parms1,";")),table_tag[#All],2,0))), "CP_Device_Disabled",_xlfn.CONCAT("无法操作以下设备：",_xlfn.TEXTJOIN(", ",1,"<br>"&VLOOKUP(VALUE(_xlfn.TEXTSPLIT(_xlpm.parms1,";")),table_tag[#All],2,0))), "CP_Big_Eater","每次进食消耗"&_xlpm.parms1&"份食物，但进食后心情+"&_xlpm.parms2, "CP_Food_Saver","每次进食有"&TEXT(_xlpm.parms1/1000,"0%")&"的概率不消耗食物" ), IFERROR(IF($A24<>"",_xlpm.suffix,""),"//特性描述待配置"))}
A25: 1600601 | B25: =_xlfn.TEXTJOIN("_",1,"trait_name",$A25) -> trait_name_1600601 | C25: 度假爱好者 | F25: =_xlfn.TEXTJOIN("_",1,"trait_desc",$A25) -> trait_desc_1600601 | G25: {=_xlfn.LET(_xlpm.trait_name,$H25, _xlpm.parms1,$I25, _xlpm.parms2,$J25, _xlpm.expr,RIGHT(desc,LEN(desc)-FIND("=",desc)), _xlpm.suffix,_xlfn.SWITCH(_xlpm.trait_name, "CP_Device_Skilled",_xlfn.CONCAT("操作以下设备时，战斗效率",IF(_xlpm.parms2>=0,"+",""),_xlpm.parms2,": ",_xlfn.TEXTJOIN(", ",1,"<br>"&VLOOKUP(VALUE(_xlfn.TEXTSPLIT(_xlpm.parms1,";")),table_tag[#All],2,0))), "CP_Device_Disabled",_xlfn.CONCAT("无法操作以下设备：",_xlfn.TEXTJOIN(", ",1,"<br>"&VLOOKUP(VALUE(_xlfn.TEXTSPLIT(_xlpm.parms1,";")),table_tag[#All],2,0))), "CP_Big_Eater","每次进食消耗"&_xlpm.parms1&"份食物，但进食后心情+"&_xlpm.parms2, "CP_Food_Saver","每次进食有"&TEXT(_xlpm.parms1/1000,"0%")&"的概率不消耗食物" ), IFERROR(IF($A25<>"",_xlpm.suffix,""),"//特性描述待配置"))} -> //特性描述待配置 | H25: CP_Mood_After_Resting
A26: 1600602 | B26: =_xlfn.TEXTJOIN("_",1,"trait_name",$A26) -> trait_name_1600602 | C26: 充满干劲 | F26: =_xlfn.TEXTJOIN("_",1,"trait_desc",$A26) -> trait_desc_1600602 | G26: {=_xlfn.LET(_xlpm.trait_name,$H26, _xlpm.parms1,$I26, _xlpm.parms2,$J26, _xlpm.expr,RIGHT(desc,LEN(desc)-FIND("=",desc)), _xlpm.suffix,_xlfn.SWITCH(_xlpm.trait_name, "CP_Device_Skilled",_xlfn.CONCAT("操作以下设备时，战斗效率",IF(_xlpm.parms2>=0,"+",""),_xlpm.parms2,": ",_xlfn.TEXTJOIN(", ",1,"<br>"&VLOOKUP(VALUE(_xlfn.TEXTSPLIT(_xlpm.parms1,";")),table_tag[#All],2,0))), "CP_Device_Disabled",_xlfn.CONCAT("无法操作以下设备：",_xlfn.TEXTJOIN(", ",1,"<br>"&VLOOKUP(VALUE(_xlfn.TEXTSPLIT(_xlpm.parms1,";")),table_tag[#All],2,0))), "CP_Big_Eater","每次进食消耗"&_xlpm.parms1&"份食物，但进食后心情+"&_xlpm.parms2, "CP_Food_Saver","每次进食有"&TEXT(_xlpm.parms1/1000,"0%")&"的概率不消耗食物" ), IFERROR(IF($A26<>"",_xlpm.suffix,""),"//特性描述待配置"))} -> //特性描述待配置 | H26: CP_Mood_After_Resting
G27: {=_xlfn.LET(_xlpm.trait_name,$H27, _xlpm.parms1,$I27, _xlpm.parms2,$J27, _xlpm.expr,RIGHT(desc,LEN(desc)-FIND("=",desc)), _xlpm.suffix,_xlfn.SWITCH(_xlpm.trait_name, "CP_Device_Skilled",_xlfn.CONCAT("操作以下设备时，战斗效率",IF(_xlpm.parms2>=0,"+",""),_xlpm.parms2,": ",_xlfn.TEXTJOIN(", ",1,"<br>"&VLOOKUP(VALUE(_xlfn.TEXTSPLIT(_xlpm.parms1,";")),table_tag[#All],2,0))), "CP_Device_Disabled",_xlfn.CONCAT("无法操作以下设备：",_xlfn.TEXTJOIN(", ",1,"<br>"&VLOOKUP(VALUE(_xlfn.TEXTSPLIT(_xlpm.parms1,";")),table_tag[#All],2,0))), "CP_Big_Eater","每次进食消耗"&_xlpm.parms1&"份食物，但进食后心情+"&_xlpm.parms2, "CP_Food_Saver","每次进食有"&TEXT(_xlpm.parms1/1000,"0%")&"的概率不消耗食物" ), IFERROR(IF($A27<>"",_xlpm.suffix,""),"//特性描述待配置"))}
A28: 1600703 | B28: =_xlfn.TEXTJOIN("_",1,"trait_name",$A28) -> trait_name_1600703 | C28: 饭桶 | F28: =_xlfn.TEXTJOIN("_",1,"trait_desc",$A28) -> trait_desc_1600703 | G28: {=_xlfn.LET(_xlpm.trait_name,$H28, _xlpm.parms1,$I28, _xlpm.parms2,$J28, _xlpm.expr,RIGHT(desc,LEN(desc)-FIND("=",desc)), _xlpm.suffix,_xlfn.SWITCH(_xlpm.trait_name, "CP_Device_Skilled",_xlfn.CONCAT("操作以下设备时，战斗效率",IF(_xlpm.parms2>=0,"+",""),_xlpm.parms2,": ",_xlfn.TEXTJOIN(", ",1,"<br>"&VLOOKUP(VALUE(_xlfn.TEXTSPLIT(_xlpm.parms1,";")),table_tag[#All],2,0))), "CP_Device_Disabled",_xlfn.CONCAT("无法操作以下设备：",_xlfn.TEXTJOIN(", ",1,"<br>"&VLOOKUP(VALUE(_xlfn.TEXTSPLIT(_xlpm.parms1,";")),table_tag[#All],2,0))), "CP_Big_Eater","每次进食消耗"&_xlpm.parms1&"份食物，但进食后心情+"&_xlpm.parms2, "CP_Food_Saver","每次进食有"&TEXT(_xlpm.parms1/1000,"0%")&"的概率不消耗食物" ), IFERROR(IF($A28<>"",_xlpm.suffix,""),"//特性描述待配置"))} -> 每次进食消耗3份食物，但进食后心情+20 | H28: CP_Big_Eater | I28: 3 | J28: 20
A29: 1600704 | B29: =_xlfn.TEXTJOIN("_",1,"trait_name",$A29) -> trait_name_1600704 | C29: 超级饭桶 | F29: =_xlfn.TEXTJOIN("_",1,"trait_desc",$A29) -> trait_desc_1600704 | G29: {=_xlfn.LET(_xlpm.trait_name,$H29, _xlpm.parms1,$I29, _xlpm.parms2,$J29, _xlpm.expr,RIGHT(desc,LEN(desc)-FIND("=",desc)), _xlpm.suffix,_xlfn.SWITCH(_xlpm.trait_name, "CP_Device_Skilled",_xlfn.CONCAT("操作以下设备时，战斗效率",IF(_xlpm.parms2>=0,"+",""),_xlpm.parms2,": ",_xlfn.TEXTJOIN(", ",1,"<br>"&VLOOKUP(VALUE(_xlfn.TEXTSPLIT(_xlpm.parms1,";")),table_tag[#All],2,0))), "CP_Device_Disabled",_xlfn.CONCAT("无法操作以下设备：",_xlfn.TEXTJOIN(", ",1,"<br>"&VLOOKUP(VALUE(_xlfn.TEXTSPLIT(_xlpm.parms1,";")),table_tag[#All],2,0))), "CP_Big_Eater","每次进食消耗"&_xlpm.parms1&"份食物，但进食后心情+"&_xlpm.parms2, "CP_Food_Saver","每次进食有"&TEXT(_xlpm.parms1/1000,"0%")&"的概率不消耗食物" ), IFERROR(IF($A29<>"",_xlpm.suffix,""),"//特性描述待配置"))} -> 每次进食消耗3份食物，但进食后心情+30 | H29: CP_Big_Eater | I29: 3 | J29: 30
G30: {=_xlfn.LET(_xlpm.trait_name,$H30, _xlpm.parms1,$I30, _xlpm.parms2,$J30, _xlpm.expr,RIGHT(desc,LEN(desc)-FIND("=",desc)), _xlpm.suffix,_xlfn.SWITCH(_xlpm.trait_name, "CP_Device_Skilled",_xlfn.CONCAT("操作以下设备时，战斗效率",IF(_xlpm.parms2>=0,"+",""),_xlpm.parms2,": ",_xlfn.TEXTJOIN(", ",1,"<br>"&VLOOKUP(VALUE(_xlfn.TEXTSPLIT(_xlpm.parms1,";")),table_tag[#All],2,0))), "CP_Device_Disabled",_xlfn.CONCAT("无法操作以下设备：",_xlfn.TEXTJOIN(", ",1,"<br>"&VLOOKUP(VALUE(_xlfn.TEXTSPLIT(_xlpm.parms1,";")),table_tag[#All],2,0))), "CP_Big_Eater","每次进食消耗"&_xlpm.parms1&"份食物，但进食后心情+"&_xlpm.parms2, "CP_Food_Saver","每次进食有"&TEXT(_xlpm.parms1/1000,"0%")&"的概率不消耗食物" ), IFERROR(IF($A30<>"",_xlpm.suffix,""),"//特性描述待配置"))}
A31: 1600801 | B31: =_xlfn.TEXTJOIN("_",1,"trait_name",$A31) -> trait_name_1600801 | C31: 节约食物 | F31: =_xlfn.TEXTJOIN("_",1,"trait_desc",$A31) -> trait_desc_1600801 | G31: {=_xlfn.LET(_xlpm.trait_name,$H31, _xlpm.parms1,$I31, _xlpm.parms2,$J31, _xlpm.expr,RIGHT(desc,LEN(desc)-FIND("=",desc)), _xlpm.suffix,_xlfn.SWITCH(_xlpm.trait_name, "CP_Device_Skilled",_xlfn.CONCAT("操作以下设备时，战斗效率",IF(_xlpm.parms2>=0,"+",""),_xlpm.parms2,": ",_xlfn.TEXTJOIN(", ",1,"<br>"&VLOOKUP(VALUE(_xlfn.TEXTSPLIT(_xlpm.parms1,";")),table_tag[#All],2,0))), "CP_Device_Disabled",_xlfn.CONCAT("无法操作以下设备：",_xlfn.TEXTJOIN(", ",1,"<br>"&VLOOKUP(VALUE(_xlfn.TEXTSPLIT(_xlpm.parms1,";")),table_tag[#All],2,0))), "CP_Big_Eater","每次进食消耗"&_xlpm.parms1&"份食物，但进食后心情+"&_xlpm.parms2, "CP_Food_Saver","每次进食有"&TEXT(_xlpm.parms1/1000,"0%")&"的概率不消耗食物" ), IFERROR(IF($A31<>"",_xlpm.suffix,""),"//特性描述待配置"))} -> 每次进食有25%的概率不消耗食物 | H31: CP_Food_Saver | I31: 250
A32: 1600802 | B32: =_xlfn.TEXTJOIN("_",1,"trait_name",$A32) -> trait_name_1600802 | C32: 节约食物 2 | F32: =_xlfn.TEXTJOIN("_",1,"trait_desc",$A32) -> trait_desc_1600802 | G32: {=_xlfn.LET(_xlpm.trait_name,$H32, _xlpm.parms1,$I32, _xlpm.parms2,$J32, _xlpm.expr,RIGHT(desc,LEN(desc)-FIND("=",desc)), _xlpm.suffix,_xlfn.SWITCH(_xlpm.trait_name, "CP_Device_Skilled",_xlfn.CONCAT("操作以下设备时，战斗效率",IF(_xlpm.parms2>=0,"+",""),_xlpm.parms2,": ",_xlfn.TEXTJOIN(", ",1,"<br>"&VLOOKUP(VALUE(_xlfn.TEXTSPLIT(_xlpm.parms1,";")),table_tag[#All],2,0))), "CP_Device_Disabled",_xlfn.CONCAT("无法操作以下设备：",_xlfn.TEXTJOIN(", ",1,"<br>"&VLOOKUP(VALUE(_xlfn.TEXTSPLIT(_xlpm.parms1,";")),table_tag[#All],2,0))), "CP_Big_Eater","每次进食消耗"&_xlpm.parms1&"份食物，但进食后心情+"&_xlpm.parms2, "CP_Food_Saver","每次进食有"&TEXT(_xlpm.parms1/1000,"0%")&"的概率不消耗食物" ), IFERROR(IF($A32<>"",_xlpm.suffix,""),"//特性描述待配置"))} -> 每次进食有50%的概率不消耗食物 | H32: CP_Food_Saver | I32: 500
A33: 1600803 | B33: =_xlfn.TEXTJOIN("_",1,"trait_name",$A33) -> trait_name_1600803 | C33: 节约食物 3 | F33: =_xlfn.TEXTJOIN("_",1,"trait_desc",$A33) -> trait_desc_1600803 | G33: {=_xlfn.LET(_xlpm.trait_name,$H33, _xlpm.parms1,$I33, _xlpm.parms2,$J33, _xlpm.expr,RIGHT(desc,LEN(desc)-FIND("=",desc)), _xlpm.suffix,_xlfn.SWITCH(_xlpm.trait_name, "CP_Device_Skilled",_xlfn.CONCAT("操作以下设备时，战斗效率",IF(_xlpm.parms2>=0,"+",""),_xlpm.parms2,": ",_xlfn.TEXTJOIN(", ",1,"<br>"&VLOOKUP(VALUE(_xlfn.TEXTSPLIT(_xlpm.parms1,";")),table_tag[#All],2,0))), "CP_Device_Disabled",_xlfn.CONCAT("无法操作以下设备：",_xlfn.TEXTJOIN(", ",1,"<br>"&VLOOKUP(VALUE(_xlfn.TEXTSPLIT(_xlpm.parms1,";")),table_tag[#All],2,0))), "CP_Big_Eater","每次进食消耗"&_xlpm.parms1&"份食物，但进食后心情+"&_xlpm.parms2, "CP_Food_Saver","每次进食有"&TEXT(_xlpm.parms1/1000,"0%")&"的概率不消耗食物" ), IFERROR(IF($A33<>"",_xlpm.suffix,""),"//特性描述待配置"))} -> 每次进食有75%的概率不消耗食物 | H33: CP_Food_Saver | I33: 750
G34: {=_xlfn.LET(_xlpm.trait_name,$H34, _xlpm.parms1,$I34, _xlpm.parms2,$J34, _xlpm.expr,RIGHT(desc,LEN(desc)-FIND("=",desc)), _xlpm.suffix,_xlfn.SWITCH(_xlpm.trait_name, "CP_Device_Skilled",_xlfn.CONCAT("操作以下设备时，战斗效率",IF(_xlpm.parms2>=0,"+",""),_xlpm.parms2,": ",_xlfn.TEXTJOIN(", ",1,"<br>"&VLOOKUP(VALUE(_xlfn.TEXTSPLIT(_xlpm.parms1,";")),table_tag[#All],2,0))), "CP_Device_Disabled",_xlfn.CONCAT("无法操作以下设备：",_xlfn.TEXTJOIN(", ",1,"<br>"&VLOOKUP(VALUE(_xlfn.TEXTSPLIT(_xlpm.parms1,";")),table_tag[#All],2,0))), "CP_Big_Eater","每次进食消耗"&_xlpm.parms1&"份食物，但进食后心情+"&_xlpm.parms2, "CP_Food_Saver","每次进食有"&TEXT(_xlpm.parms1/1000,"0%")&"的概率不消耗食物" ), IFERROR(IF($A34<>"",_xlpm.suffix,""),"//特性描述待配置"))}
A35: 1601001 | B35: =_xlfn.TEXTJOIN("_",1,"trait_name",$A35) -> trait_name_1601001 | C35: 高速代谢 | F35: =_xlfn.TEXTJOIN("_",1,"trait_desc",$A35) -> trait_desc_1601001 | G35: {=_xlfn.LET(_xlpm.trait_name,$H35, _xlpm.parms1,$I35, _xlpm.parms2,$J35, _xlpm.expr,RIGHT(desc,LEN(desc)-FIND("=",desc)), _xlpm.suffix,_xlfn.SWITCH(_xlpm.trait_name, "CP_Device_Skilled",_xlfn.CONCAT("操作以下设备时，战斗效率",IF(_xlpm.parms2>=0,"+",""),_xlpm.parms2,": ",_xlfn.TEXTJOIN(", ",1,"<br>"&VLOOKUP(VALUE(_xlfn.TEXTSPLIT(_xlpm.parms1,";")),table_tag[#All],2,0))), "CP_Device_Disabled",_xlfn.CONCAT("无法操作以下设备：",_xlfn.TEXTJOIN(", ",1,"<br>"&VLOOKUP(VALUE(_xlfn.TEXTSPLIT(_xlpm.parms1,";")),table_tag[#All],2,0))), "CP_Big_Eater","每次进食消耗"&_xlpm.parms1&"份食物，但进食后心情+"&_xlpm.parms2, "CP_Food_Saver","每次进食有"&TEXT(_xlpm.parms1/1000,"0%")&"的概率不消耗食物" ), IFERROR(IF($A35<>"",_xlpm.suffix,""),"//特性描述待配置"))} -> //特性描述待配置 | H35: CP_Metabolism_Fast | I35: 25
A36: 1601002 | B36: =_xlfn.TEXTJOIN("_",1,"trait_name",$A36) -> trait_name_1601002 | C36: 高速代谢 2 | F36: =_xlfn.TEXTJOIN("_",1,"trait_desc",$A36) -> trait_desc_1601002 | G36: {=_xlfn.LET(_xlpm.trait_name,$H36, _xlpm.parms1,$I36, _xlpm.parms2,$J36, _xlpm.expr,RIGHT(desc,LEN(desc)-FIND("=",desc)), _xlpm.suffix,_xlfn.SWITCH(_xlpm.trait_name, "CP_Device_Skilled",_xlfn.CONCAT("操作以下设备时，战斗效率",IF(_xlpm.parms2>=0,"+",""),_xlpm.parms2,": ",_xlfn.TEXTJOIN(", ",1,"<br>"&VLOOKUP(VALUE(_xlfn.TEXTSPLIT(_xlpm.parms1,";")),table_tag[#All],2,0))), "CP_Device_Disabled",_xlfn.CONCAT("无法操作以下设备：",_xlfn.TEXTJOIN(", ",1,"<br>"&VLOOKUP(VALUE(_xlfn.TEXTSPLIT(_xlpm.parms1,";")),table_tag[#All],2,0))), "CP_Big_Eater","每次进食消耗"&_xlpm.parms1&"份食物，但进食后心情+"&_xlpm.parms2, "CP_Food_Saver","每次进食有"&TEXT(_xlpm.parms1/1000,"0%")&"的概率不消耗食物" ), IFERROR(IF($A36<>"",_xlpm.suffix,""),"//特性描述待配置"))} -> //特性描述待配置 | H36: CP_Metabolism_Fast | I36: 50
