Workbook

Sheet battle_data
A1: id | E1: armor_piercing | F1: critical_chance | G1: critical_rate | K1: hp | L1: def | O1: k_hurt
A2: uint key | E2: int | F2: int | G2: int | K2: int | L2: int | O2: dict<string,int>
A3: 设备id | B3: 备注 设备名称 | C3: 备注 设备等级 | D3: 备注 设备宽度 | E3: 护甲穿透 千分比配置 1000=100% | F3: 暴击率 千分比配置 1000=100% | G3: 暴击伤害 千分比配置 1000=100% 配置值不应低于1000 | I3: 查询地址 (表名) | J3: 生存等级 | K3: 血量 | L3: 减伤 | M3: 等效血量 | N3: 设定 base血量 | O3: 伤害修正
A4: 1210101 | B4: 硬木车轮 | C4: =IF(A4>=10000000,MOD(A4,10),"模板") -> 模板 | D4: 模板 | G4: 1000 | K4: 2400 | L4: 2
A5: 12101011 | B5: 硬木车轮 Lv.1 | C5: =IF(A5>=10000000,MOD(A5,10),"模板") -> 1 | D5: 0 | G5: 1000 | K5: 2400 | L5: 2
A6: 12101012 | B6: 硬木车轮 Lv.2 | C6: =IF(A6>=10000000,MOD(A6,10),"模板") -> 2 | D6: 0 | G6: 1000 | K6: 2400 | L6: 2
A7: 12101013 | B7: 硬木车轮 Lv.3 | C7: =IF(A7>=10000000,MOD(A7,10),"模板") -> 3 | D7: 0 | G7: 1000 | K7: 2400 | L7: 2
A8: 12101019 | B8: 旧木车轮 | C8: 0 | D8: 0 | G8: 1000 | K8: 2400 | L8: 2
A9: 1210102 | B9: 履带 | C9: =IF(A9>=10000000,MOD(A9,10),"模板") -> 模板 | D9: 模板 | G9: 1000 | K9: 5100 | L9: 9
A10: 12101022 | B10: 履带 Lv.2 | C10: =IF(A10>=10000000,MOD(A10,10),"模板") -> 2 | D10: 0 | G10: 1000 | K10: 5100 | L10: 9
A11: 12101023 | B11: 履带 Lv.3 | C11: =IF(A11>=10000000,MOD(A11,10),"模板") -> 3 | D11: 0 | G11: 1000 | K11: 5100 | L11: 9
A12: 12101024 | B12: 履带 Lv.4 | C12: =IF(A12>=10000000,MOD(A12,10),"模板") -> 4 | D12: 0 | G12: 1000 | K12: 5100 | L12: 9
A13: 1211801 | B13: 救生圈 | G13: 1000 | K13: 1500 | L13: 0
A14: 120000002 | B14: 笨重石轮 | G14: 1000 | K14: 2400 | L14: 0
A15: 120000003 | B15: 坚固铁轮 | G15: 1000 | K15: 2400 | L15: 0
A16: 120000004 | B16: 凝胶车轮 | G16: 1000 | K16: 2400 | L16: 0
A17: 120000006 | B17: 废弃轮胎 | G17: 1000 | K17: 2400 | L17: 0
A18: 120000007 | B18: 推进车轮 | G18: 1000 | K18: 2400 | L18: 2
A19: 120000008 | B19: 喷火车轮 | G19: 1000 | K19: 2400 | L19: 2
A21: 1310101 | B21: 短匕 | E21: 250 | F21: 300 | G21: 2500 | K21: 3300 | L21: 2
A22: 1310102 | B22: 砍刀 | E22: 0 | F22: 150 | G22: 2000 | K22: 3900 | L22: 3
A23: 1310103 | B23: 大剑 | E23: 0 | F23: 100 | G23: 2000 | K23: 4500 | L23: 5
A24: 1310104 | B24: 长矛 | E24: 250 | F24: 200 | G24: 2000 | K24: 3900 | L24: 3
A25: 1310105 | B25: 充气球棒 | C25: =IF(A25>=10000000,MOD(A25,10),"模板") -> 模板 | D25: 模板 | E25: 0 | F25: 600 | G25: 1010 | Q25: 表名 | R25: 生存等级-列
A26: 13101050 | B26: 充气球棒 Lv.0 | C26: =IF(A26>=10000000,MOD(A26,10),"模板") -> 0 | D26: 1 | E26: 0 | F26: 600 | G26: 1000 | I26: melee_logic | J26: {=_xlfn.XLOOKUP(A26,INDIRECT($I26&"!C1",0),INDIRECT(_xlfn.CONCAT($I26,"!C",_xlfn.XLOOKUP(I26,tb_sheetField[表名],tb_sheetField[生存等级-列])),0))} -> -1.5 | K26: =MROUND(M26/(1+L26*0.01),10) -> 1210 | L26: -10 | M26: =$N26*1.5^$J26 -> 1088.6621 | N26: 2000 | Q26: melee_logic | R26: =COLUMN(melee_logic!$BG$3) -> 59
A27: 13101051 | B27: 充气球棒 Lv.1 | C27: =IF(A27>=10000000,MOD(A27,10),"模板") -> 1 | D27: 1 | E27: 0 | F27: 600 | G27: 1000 | I27: melee_logic | J27: {=_xlfn.XLOOKUP(A27,INDIRECT($I27&"!C1",0),INDIRECT(_xlfn.CONCAT($I27,"!C",_xlfn.XLOOKUP(I27,tb_sheetField[表名],tb_sheetField[生存等级-列])),0))} -> 0.9 | K27: =MROUND(M27/(1+L27*0.01),10) -> 3030 | L27: -5 | M27: =$N27*1.5^$J27 -> 2880.7935 | N27: 2000 | Q27: fire_logic | R27: =COLUMN(fire_logic!$BM$3) -> 65
A28: 1310106 | B28: 圆锯 | C28: =IF(A28>=10000000,MOD(A28,10),"模板") -> 模板 | D28: 模板 | E28: 200 | F28: 200 | G28: 1050 | Q28: other_logic | R28: =COLUMN(other_logic!$AU$3) -> 47
A29: 13101061 | B29: 圆锯 Lv.1 | C29: =IF(A29>=10000000,MOD(A29,10),"模板") -> 1 | D29: 1 | E29: 200 | F29: 200 | G29: 1050 | I29: other_logic | J29: {=_xlfn.XLOOKUP(A29,INDIRECT($I29&"!C1",0),INDIRECT(_xlfn.CONCAT($I29,"!C",_xlfn.XLOOKUP(I29,tb_sheetField[表名],tb_sheetField[生存等级-列])),0))} -> 1.23 | K29: =MROUND(M29/(1+L29*0.01),10) -> 1500 | L29: 120 | M29: =$N29*1.5^$J29 -> 3293.2314 | N29: 2000 | Q29: ram_logic | R29: =COLUMN(ram_logic!$AF$3) -> 32
A30: 13101062 | B30: 圆锯 Lv.2 | C30: =IF(A30>=10000000,MOD(A30,10),"模板") -> 2 | D30: 1 | E30: 200 | F30: 200 | G30: 1050 | I30: other_logic | J30: {=_xlfn.XLOOKUP(A30,INDIRECT($I30&"!C1",0),INDIRECT(_xlfn.CONCAT($I30,"!C",_xlfn.XLOOKUP(I30,tb_sheetField[表名],tb_sheetField[生存等级-列])),0))} -> 2.06 | K30: =MROUND(M30/(1+L30*0.01),10) -> 1770 | L30: 160 | M30: =$N30*1.5^$J30 -> 4610.8181 | N30: 2000
A31: 13101063 | B31: 圆锯 Lv.3 | C31: =IF(A31>=10000000,MOD(A31,10),"模板") -> 3 | D31: 1 | E31: 200 | F31: 200 | G31: 1050 | I31: other_logic | J31: {=_xlfn.XLOOKUP(A31,INDIRECT($I31&"!C1",0),INDIRECT(_xlfn.CONCAT($I31,"!C",_xlfn.XLOOKUP(I31,tb_sheetField[表名],tb_sheetField[生存等级-列])),0))} -> 2.9 | K31: =MROUND(M31/(1+L31*0.01),10) -> 2160 | L31: 200 | M31: =$N31*1.5^$J31 -> 6481.7854 | N31: 2000
A32: 13101064 | B32: 圆锯 Lv.4 | C32: =IF(A32>=10000000,MOD(A32,10),"模板") -> 4 | D32: 1 | E32: 200 | F32: 200 | G32: 1050 | I32: other_logic | J32: {=_xlfn.XLOOKUP(A32,INDIRECT($I32&"!C1",0),INDIRECT(_xlfn.CONCAT($I32,"!C",_xlfn.XLOOKUP(I32,tb_sheetField[表名],tb_sheetField[生存等级-列])),0))} -> 3.79 | K32: =MROUND(M32/(1+L32*0.01),10) -> 2730 | L32: 240 | M32: =$N32*1.5^$J32 -> 9298.5636 | N32: 2000
A33: 1310107 | B33: 双刃铡刀 | C33: =IF(A33>=10000000,MOD(A33,10),"模板") -> 模板 | D33: 模板 | E33: 0 | F33: 80 | G33: 1300
A34: 13101070 | B34: 双刃铡刀 Lv.0 | C34: =IF(A34>=10000000,MOD(A34,10),"模板") -> 0 | D34: 1 | E34: 0 | F34: 80 | G34: 1300 | I34: melee_logic | J34: {=_xlfn.XLOOKUP(A34,INDIRECT($I34&"!C1",0),INDIRECT(_xlfn.CONCAT($I34,"!C",_xlfn.XLOOKUP(I34,tb_sheetField[表名],tb_sheetField[生存等级-列])),0))} -> 0 | K34: =MROUND(M34/(1+L34*0.01),10) -> 1820 | L34: 10 | M34: =$N34*1.5^$J34 -> 2000 | N34: 2000
A35: 13101071 | B35: 双刃铡刀 Lv.1 | C35: =IF(A35>=10000000,MOD(A35,10),"模板") -> 1 | D35: 1 | E35: 0 | F35: 80 | G35: 1300 | I35: melee_logic | J35: {=_xlfn.XLOOKUP(A35,INDIRECT($I35&"!C1",0),INDIRECT(_xlfn.CONCAT($I35,"!C",_xlfn.XLOOKUP(I35,tb_sheetField[表名],tb_sheetField[生存等级-列])),0))} -> 0.67 | K35: =MROUND(M35/(1+L35*0.01),10) -> 2190 | L35: 20 | M35: =$N35*1.5^$J35 -> 2624.2859 | N35: 2000
A36: 13101072 | B36: 双刃铡刀 Lv.2 | C36: =IF(A36>=10000000,MOD(A36,10),"模板") -> 2 | D36: 1 | E36: 0 | F36: 80 | G36: 1300 | I36: melee_logic | J36: {=_xlfn.XLOOKUP(A36,INDIRECT($I36&"!C1",0),INDIRECT(_xlfn.CONCAT($I36,"!C",_xlfn.XLOOKUP(I36,tb_sheetField[表名],tb_sheetField[生存等级-列])),0))} -> 1.54 | K36: =MROUND(M36/(1+L36*0.01),10) -> 2670 | L36: 40 | M36: =$N36*1.5^$J36 -> 3734.3114 | N36: 2000
A37: 13101073 | B37: 双刃铡刀 Lv.3 | C37: =IF(A37>=10000000,MOD(A37,10),"模板") -> 3 | D37: 1 | E37: 0 | F37: 80 | G37: 1300 | I37: melee_logic | J37: {=_xlfn.XLOOKUP(A37,INDIRECT($I37&"!C1",0),INDIRECT(_xlfn.CONCAT($I37,"!C",_xlfn.XLOOKUP(I37,tb_sheetField[表名],tb_sheetField[生存等级-列])),0))} -> 2.58 | K37: =MROUND(M37/(1+L37*0.01),10) -> 3160 | L37: 80 | M37: =$N37*1.5^$J37 -> 5693.0558 | N37: 2000
A38: 1311101 | B38: 执刑钉棍 | E38: 600 | F38: 100 | G38: 2000 | K38: 3900 | L38: 3
A39: 1311102 | B39: 执刑斧钺 | E39: 550 | F39: 100 | G39: 2000 | K39: 4500 | L39: 5
A40: 1311801 | B40: 短柄渔叉 | E40: 500 | F40: 150 | G40: 3000 | K40: 3900 | L40: 3
A41: 1311802 | B41: 海妖触手 | E41: 350 | F41: 0 | G41: 1500 | K41: 3900 | L41: 3
...

Sheet melee_logic
A1: logic_id | D1: cd | F1: can_blaze | G1: sharpness_min | H1: sharpness_range | L1: sharpness_dmg_range | P1: sharpness_loss | Q1: sharpness_recover | S1: ui_atk_horizontal_anim | T1: ui_atk_vertical_anim | U1: SE_attack_begin | V1: SE_grinding | W1: atk_event_num | X1: hit_period | AB1: hit_period_2 | AF1: hit_box_offset | AG1: atk_part_speed | AH1: attack_charge_weight | AI1: attack_charge_speed | AJ1: ui_charge_trigger_ticks | AL1: job_speed | AO1: damage | BJ1: knockback_ft
A2: uint key | D2: int | F2: bool | G2: float | H2: float[] | L2: float[] | P2: float | Q2: float | S2: string[] | T2: string[] | U2: string | V2: string | W2: int | X2: (float,float) | AB2: (float,float)? | AF2: float | AG2: float | AH2: float | AI2: float | AJ2: int | AL2: float[] | AO2: dict<string,int> | BJ2: float
A3: 近战逻辑id | B3: 备注1 设备 | C3: 备注2 设备控制脚本 | D3: 攻击间隔 (帧) | E3: 备注 (秒) | F3: 能否连击 true:自动攻击 false:手动攻击 | G3: 锋利度 下限 | H3: 锋利度 区间 | I3: 辅助列 锋利度 区间 1 | J3: 辅助列 锋利度 区间 2 | K3: 辅助列 锋利度 区间 3 | L3: 伤害 区间 | M3: 辅助列 伤害 区间 1 | N3: 辅助列 伤害 区间 2 | O3: 辅助列 伤害 区间 3 | P3: 锋利度 击打损失 | Q3: 锋利度 每帧恢复 | R3: 辅助列 每秒恢复 | S3: devicePanel 水平挥舞 关联动画 | T3: devicePanel 竖直戳刺 关联动画 | U3: 音效 - 挥舞 | V3: 音效 - 磨刀 | W3: 攻击动画数量 | X3: 打击时间段1 默认碰撞盒 开启、关闭 的时间段 | Y3: 碰撞盒 开启帧 attack_1 | Z3: 碰撞盒 关闭帧 attack_1 | AA3: 总帧数 attack_1 | AB3: 打击时间段2 若attack2动画为戳刺而不是挥砍，则需要配置不同的碰撞盒开关时间 | AC3: 碰撞盒 开启帧 attack_2 | AD3: 碰撞盒 关闭帧 attack_2 | AE3: 总帧数 attack_2 | AF3: 碰撞盒偏移 碰撞盒到自身坐标的偏移距离，根据动画进行配置 | AG3: 攻击部件移速 | AH3: 蓄力权重 配置范围0~1 | AI3: 蓄力速率 | AJ3: 蓄力启动速率 时长辅助 （帧） | AK3: 备注 时长(秒) | AL3: NPC工作速度 工作1：攻击 工作2：维护 | AM3: 工作1 帧数 | AN3: 工作2 帧数 | AO3: 伤害 | AP3: sharp | AQ3: blunt | AR3: fire | AS3: acid | AT3: wrap | AU3: armor_piercing |护甲穿透 | AV3: critical_chance |暴击率 | AW3: critical_rate |暴击伤害 | AX3: 计算参考 暴击修正倍率期望 | AY3: 计算参考 攻击伤害 | AZ3: 手动交互 单轮总耗时 （秒） | BA3: 计算统计 DPS | BB3: 计算统计 输出等级 base=55 | BC3: 设定 等级 | BD3: 设定 宽度 | BE3: 战力 等级 base=2 | BF3: 其他属性补正 e.g.. 因手感差、射程近等因素，获得减分 | BG3: 适配 生存等级 | BH3: 计算参考 单轮DPS | BI3: 计算参考 平均DPS | BJ3: 击退力度 | BK3: 计算参考 等级 (弃用) | BL3: 计算参考 手动DPS 表显max： 050 | BM3: 计算参考 自动DPS 表显max： 050
A4: 1310101 | B4: 短匕 | C4: BasicMelee_Click | D4: 120 | E4: =TEXT(D4/120,"0.00")&" s" -> 1.00 s | F4: TRUE | G4: 0 | H4: =_xlfn.TEXTJOIN(";",1,$I4:$K4) -> 7;24;60 | I4: 7 | J4: 24 | K4: 60 | L4: =_xlfn.TEXTJOIN(";",1,$M4:$O4) -> 0.25;0.6;0.85 | M4: 0.25 | N4: 0.6 | O4: 0.85 | P4: 0.12 | Q4: =R4/120 -> 0.11111111 | R4: =40/3 -> 13.333333 | S4: attack_1 | T4: attack_2 | U4: se_ag_melee_wield | V4: se_ag_melee_grinding | W4: 2 | X4: {=_xlfn.TEXTJOIN("~",1,Y4:Z4/AA4)} -> 0.25~0.45 | Y4: 5 | Z4: 9 | AA4: 20 | AB4: {=_xlfn.TEXTJOIN("~",1,AC4:AD4/AE4)} -> 0.5~0.8 | AC4: 10 | AD4: 16 | AE4: 20 | AF4: 0.71887 | AG4: 12 | AL4: {=_xlfn.TEXTJOIN(";",1,IFERROR(1/AM4:AN4,""))} | AO4: {=_xlfn.TEXTJOIN(";",1,_xlfn.LAMBDA(_xlpm.x,IF(_xlpm.x<>"",OFFSET(_xlpm.x,3-ROW(),0)&"="&_xlpm.x,""))(AP4:AT4))} -> sharp=27 | AP4: 27 | AU4: {=TEXT(VLOOKUP($A4,battle_data!$A:$G,MATCH(INDEX(_xlfn.TEXTSPLIT(AU$3,"|"),1),battle_data!$A$1:$G$1),0)*0.001,"0%")} -> 25% | AV4: {=TEXT(VLOOKUP($A4,battle_data!$A:$G,MATCH(INDEX(_xlfn.TEXTSPLIT(AV$3,"|"),1),battle_data!$A$1:$G$1),0)*0.001,"0%")} -> 30% | AW4: {=TEXT(VLOOKUP($A4,battle_data!$A:$G,MATCH(INDEX(_xlfn.TEXTSPLIT(AW$3,"|"),1),battle_data!$A$1:$G$1),0)*0.001,"0%")} -> 250% | AX4: =_xlfn.LET(_xlpm.p,($AV4),_xlpm.p*$AW4+(1-_xlpm.p)) -> 1.45 | AY4: =SUM($AP4:$AT4)*AX4 -> 39.15 | AZ4: =AA4/30 -> 0.66666667 | BA4: =AY4/AZ4 -> 58.725 | BB4: {=_xlfn.LAMBDA(_xlpm._dps,_xlpm._info_cell,ROUND(IF(_xlpm._dps<=0,-10,LOG(_xlpm._dps/INDEX(_xlfn.TEXTSPLIT(_xlpm._info_cell,"="),2),1.5)),2))($BA4,BB$3)} -> 0.16 | BC4: 0 | BF4: 0.05 | BG4: =BC4*2-BB4-BF4 -> -0.21 | BH4: =$AY4*30/$AA4 -> 58.725 | BI4: =$AY4*120/($D4+4*$AA4) -> 23.49 | BJ4: 1 | BK4: 0 | BL4: =_xlfn.LET(_xlpm._level_power,2,IF($BK4<>"",BH4/_xlpm._level_power^$BK4,"")) -> 58.725 | BM4: =_xlfn.LET(_xlpm._level_power,2,IF($BK4<>"",BH4/_xlpm._level_power^$BK4,"")) -> 58.725
A5: 1310102 | B5: 砍刀 | C5: BasicMelee_Click | D5: 300 | E5: =TEXT(D5/120,"0.00")&" s" -> 2.50 s | F5: TRUE | G5: 0 | H5: =_xlfn.TEXTJOIN(";",1,$I5:$K5) -> 7;24;60 | I5: 7 | J5: 24 | K5: 60 | L5: =_xlfn.TEXTJOIN(";",1,$M5:$O5) -> 0.25;0.6;0.85 | M5: 0.25 | N5: 0.6 | O5: 0.85 | P5: 0.12 | Q5: =R5/120 -> 0.083333333 | R5: 10 | S5: attack_1;attack_2 | U5: se_ag_melee_wield | V5: se_ag_melee_grinding | W5: 2 | X5: {=_xlfn.TEXTJOIN("~",1,Y5:Z5/AA5)} -> 0.32~0.48 | Y5: 8 | Z5: 12 | AA5: 25 | AF5: 1.2643 | AG5: 8 | AL5: {=_xlfn.TEXTJOIN(";",1,IFERROR(1/AM5:AN5,""))} | AO5: {=_xlfn.TEXTJOIN(";",1,_xlfn.LAMBDA(_xlpm.x,IF(_xlpm.x<>"",OFFSET(_xlpm.x,3-ROW(),0)&"="&_xlpm.x,""))(AP5:AT5))} -> sharp=52 | AP5: 52 | AU5: {=TEXT(VLOOKUP($A5,battle_data!$A:$G,MATCH(INDEX(_xlfn.TEXTSPLIT(AU$3,"|"),1),battle_data!$A$1:$G$1),0)*0.001,"0%")} -> 0% | AV5: {=TEXT(VLOOKUP($A5,battle_data!$A:$G,MATCH(INDEX(_xlfn.TEXTSPLIT(AV$3,"|"),1),battle_data!$A$1:$G$1),0)*0.001,"0%")} -> 15% | AW5: {=TEXT(VLOOKUP($A5,battle_data!$A:$G,MATCH(INDEX(_xlfn.TEXTSPLIT(AW$3,"|"),1),battle_data!$A$1:$G$1),0)*0.001,"0%")} -> 200% | AX5: =_xlfn.LET(_xlpm.p,($AV5),_xlpm.p*$AW5+(1-_xlpm.p)) -> 1.15 | AY5: =SUM($AP5:$AT5)*AX5 -> 59.8 | AZ5: =AA5/30 -> 0.83333333 | BA5: =AY5/AZ5 -> 71.76 | BB5: {=_xlfn.LAMBDA(_xlpm._dps,_xlpm._info_cell,ROUND(IF(_xlpm._dps<=0,-10,LOG(_xlpm._dps/INDEX(_xlfn.TEXTSPLIT(_xlpm._info_cell,"="),2),1.5)),2))($BA5,BB$3)} -> 0.66 | BC5: 1 | BF5: 0 | BG5: =BC5*2-BB5-BF5 -> 1.34 | BH5: =$AY5*30/$AA5 -> 71.76 | BI5: =$AY5*120/($D5+4*$AA5) -> 17.94 | BJ5: 4 | BK5: 1 | BL5: =_xlfn.LET(_xlpm._level_power,2,IF($BK5<>"",BH5/_xlpm._level_power^$BK5,"")) -> 35.88 | BM5: =_xlfn.LET(_xlpm._level_power,2,IF($BK5<>"",BH5/_xlpm._level_power^$BK5,"")) -> 35.88
A6: 1310103 | B6: 大剑 | C6: BasicMelee_Click | D6: 600 | E6: =TEXT(D6/120,"0.00")&" s" -> 5.00 s | F6: FALSE | G6: 0 | H6: =_xlfn.TEXTJOIN(";",1,$I6:$K6) -> 7;24;60 | I6: 7 | J6: 24 | K6: 60 | L6: =_xlfn.TEXTJOIN(";",1,$M6:$O6) -> 0.25;0.6;0.85 | M6: 0.25 | N6: 0.6 | O6: 0.85 | P6: 0.1 | Q6: =R6/120 -> 0.055555556 | R6: =20/3 -> 6.6666667 | S6: attack_1;attack_2 | U6: se_ag_melee_wield | V6: se_ag_melee_grinding | W6: 2 | X6: {=_xlfn.TEXTJOIN("~",1,Y6:Z6/AA6)} -> 0.466666666666667~0.6 | Y6: 14 | Z6: 18 | AA6: 30 | AF6: 1.7058 | AG6: 5 | AL6: {=_xlfn.TEXTJOIN(";",1,IFERROR(1/AM6:AN6,""))} | AO6: {=_xlfn.TEXTJOIN(";",1,_xlfn.LAMBDA(_xlpm.x,IF(_xlpm.x<>"",OFFSET(_xlpm.x,3-ROW(),0)&"="&_xlpm.x,""))(AP6:AT6))} -> sharp=150 | AP6: 150 | AU6: {=TEXT(VLOOKUP($A6,battle_data!$A:$G,MATCH(INDEX(_xlfn.TEXTSPLIT(AU$3,"|"),1),battle_data!$A$1:$G$1),0)*0.001,"0%")} -> 0% | AV6: {=TEXT(VLOOKUP($A6,battle_data!$A:$G,MATCH(INDEX(_xlfn.TEXTSPLIT(AV$3,"|"),1),battle_data!$A$1:$G$1),0)*0.001,"0%")} -> 10% | AW6: {=TEXT(VLOOKUP($A6,battle_data!$A:$G,MATCH(INDEX(_xlfn.TEXTSPLIT(AW$3,"|"),1),battle_data!$A$1:$G$1),0)*0.001,"0%")} -> 200% | AX6: =_xlfn.LET(_xlpm.p,($AV6),_xlpm.p*$AW6+(1-_xlpm.p)) -> 1.1 | AY6: =SUM($AP6:$AT6)*AX6 -> 165 | AZ6: =AA6/30 -> 1 | BA6: =AY6/AZ6 -> 165 | BB6: {=_xlfn.LAMBDA(_xlpm._dps,_xlpm._info_cell,ROUND(IF(_xlpm._dps<=0,-10,LOG(_xlpm._dps/INDEX(_xlfn.TEXTSPLIT(_xlpm._info_cell,"="),2),1.5)),2))($BA6,BB$3)} -> 2.71 | BC6: 2 | BF6: -0.2 | BG6: =BC6*2-BB6-BF6 -> 1.49 | BH6: =$AY6*30/$AA6 -> 165 | BI6: =$AY6*120/($D6+4*$AA6) -> 27.5 | BJ6: 8 | BK6: 2 | BL6: =_xlfn.LET(_xlpm._level_power,2,IF($BK6<>"",BH6/_xlpm._level_power^$BK6,"")) -> 41.25 | BM6: =_xlfn.LET(_xlpm._level_power,2,IF($BK6<>"",BH6/_xlpm._level_power^$BK6,"")) -> 41.25
A7: 1310104 | B7: 长矛 | C7: BasicMelee_Click | D7: 450 | E7: =TEXT(D7/120,"0.00")&" s" -> 3.75 s | F7: FALSE | G7: 0 | H7: =_xlfn.TEXTJOIN(";",1,$I7:$K7) -> 7;24;60 | I7: 7 | J7: 24 | K7: 60 | L7: =_xlfn.TEXTJOIN(";",1,$M7:$O7) -> 0.25;0.6;0.85 | M7: 0.25 | N7: 0.6 | O7: 0.85 | P7: 0.09 | Q7: =R7/120 -> 0.027777778 | R7: =10/3 -> 3.3333333 | S7: attack_1 | T7: attack_2 | U7: se_ag_melee_wield | V7: se_ag_melee_grinding | W7: 2 | X7: {=_xlfn.TEXTJOIN("~",1,Y7:Z7/AA7)} -> 0.333333333333333~0.433333333333333 | Y7: 10 | Z7: 13 | AA7: 30 | AB7: {=_xlfn.TEXTJOIN("~",1,AC7:AD7/AE7)} -> 0.5~0.666666666666667 | AC7: 15 | AD7: 20 | AE7: 30 | AF7: 2.097 | AG7: 6 | AL7: {=_xlfn.TEXTJOIN(";",1,IFERROR(1/AM7:AN7,""))} | AO7: {=_xlfn.TEXTJOIN(";",1,_xlfn.LAMBDA(_xlpm.x,IF(_xlpm.x<>"",OFFSET(_xlpm.x,3-ROW(),0)&"="&_xlpm.x,""))(AP7:AT7))} -> sharp=64 | AP7: 64 | AU7: {=TEXT(VLOOKUP($A7,battle_data!$A:$G,MATCH(INDEX(_xlfn.TEXTSPLIT(AU$3,"|"),1),battle_data!$A$1:$G$1),0)*0.001,"0%")} -> 25% | AV7: {=TEXT(VLOOKUP($A7,battle_data!$A:$G,MATCH(INDEX(_xlfn.TEXTSPLIT(AV$3,"|"),1),battle_data!$A$1:$G$1),0)*0.001,"0%")} -> 20% | AW7: {=TEXT(VLOOKUP($A7,battle_data!$A:$G,MATCH(INDEX(_xlfn.TEXTSPLIT(AW$3,"|"),1),battle_data!$A$1:$G$1),0)*0.001,"0%")} -> 200% | AX7: =_xlfn.LET(_xlpm.p,($AV7),_xlpm.p*$AW7+(1-_xlpm.p)) -> 1.2 | AY7: =SUM($AP7:$AT7)*AX7 -> 76.8 | AZ7: =AA7/30 -> 1 | BA7: =AY7/AZ7 -> 76.8 | BB7: {=_xlfn.LAMBDA(_xlpm._dps,_xlpm._info_cell,ROUND(IF(_xlpm._dps<=0,-10,LOG(_xlpm._dps/INDEX(_xlfn.TEXTSPLIT(_xlpm._info_cell,"="),2),1.5)),2))($BA7,BB$3)} -> 0.82 | BC7: 1 | BF7: -0.05 | BG7: =BC7*2-BB7-BF7 -> 1.23 | BH7: =$AY7*30/$AA7 -> 76.8 | BI7: =$AY7*120/($D7+4*$AA7) -> 16.168421 | BJ7: 5 | BK7: 2 | BL7: =_xlfn.LET(_xlpm._level_power,2,IF($BK7<>"",BH7/_xlpm._level_power^$BK7,"")) -> 19.2 | BM7: =_xlfn.LET(_xlpm._level_power,2,IF($BK7<>"",BH7/_xlpm._level_power^$BK7,"")) -> 19.2
A8: 1310105 | B8: 充气球棒 | C8: DScript_Melee | D8: 0 | E8: =TEXT(D8/120,"0.00")&" s" -> 0.00 s | F8: TRUE | G8: 0 | H8: =_xlfn.TEXTJOIN(";",1,$I8:$K8) -> 0 | I8: 0 | L8: =_xlfn.TEXTJOIN(";",1,$M8:$O8) -> 1 | M8: 1 | S8: attack_1;attack_2 | U8: se_ag_melee_wield | W8: 2 | X8: {=_xlfn.TEXTJOIN("~",1,Y8:Z8/AA8)} -> 0.428571428571429~0.571428571428571 | Y8: 15 | Z8: 20 | AA8: 35 | AF8: 0 | AG8: 8 | AL8: {=_xlfn.TEXTJOIN(";",1,IFERROR(1/AM8:AN8,""))} -> 0.00416666666666667 | AM8: 240 | AO8: {=_xlfn.TEXTJOIN(";",1,_xlfn.LAMBDA(_xlpm.x,IF(_xlpm.x<>"",OFFSET(_xlpm.x,3-ROW(),0)&"="&_xlpm.x,""))(AP8:AT8))} -> blunt=0 | AQ8: 0 | AU8: {=TEXT(VLOOKUP($A8,battle_data!$A:$G,MATCH(INDEX(_xlfn.TEXTSPLIT(AU$3,"|"),1),battle_data!$A$1:$G$1),0)*0.001,"0%")} -> 0% | AV8: {=TEXT(VLOOKUP($A8,battle_data!$A:$G,MATCH(INDEX(_xlfn.TEXTSPLIT(AV$3,"|"),1),battle_data!$A$1:$G$1),0)*0.001,"0%")} -> 60% | AW8: {=TEXT(VLOOKUP($A8,battle_data!$A:$G,MATCH(INDEX(_xlfn.TEXTSPLIT(AW$3,"|"),1),battle_data!$A$1:$G$1),0)*0.001,"0%")} -> 101% | AX8: =_xlfn.LET(_xlpm.p,($AV8),_xlpm.p*$AW8+(1-_xlpm.p)) -> 1.006 | AY8: =SUM($AP8:$AT8)*AX8 -> 0 | BH8: =$AY8*30/$AA8 -> 0 | BI8: =$AY8*120/($D8+4*$AA8) -> 0 | BJ8: 20 | BK8: 1 | BL8: =_xlfn.LET(_xlpm._level_power,2,IF($BK8<>"",BH8/_xlpm._level_power^$BK8,"")) -> 0 | BM8: =_xlfn.LET(_xlpm._level_power,2,IF($BK8<>"",BH8/_xlpm._level_power^$BK8,"")) -> 0
A9: 13101050 | B9: 充气球棒 Lv0 | C9: DScript_Melee | D9: 0 | E9: =TEXT(D9/120,"0.00")&" s" -> 0.00 s | F9: TRUE | G9: 0 | H9: =_xlfn.TEXTJOIN(";",1,$I9:$K9) -> 0 | I9: 0 | L9: =_xlfn.TEXTJOIN(";",1,$M9:$O9) -> 1 | M9: 1 | S9: attack_1;attack_2 | U9: se_ag_melee_wield | W9: 2 | X9: {=_xlfn.TEXTJOIN("~",1,Y9:Z9/AA9)} -> 0.428571428571429~0.571428571428571 | Y9: 15 | Z9: 20 | AA9: 35 | AF9: 0 | AG9: 8 | AL9: {=_xlfn.TEXTJOIN(";",1,IFERROR(1/AM9:AN9,""))} -> 0.00416666666666667 | AM9: 240 | AO9: {=_xlfn.TEXTJOIN(";",1,_xlfn.LAMBDA(_xlpm.x,IF(_xlpm.x<>"",OFFSET(_xlpm.x,3-ROW(),0)&"="&_xlpm.x,""))(AP9:AT9))} -> blunt=0 | AQ9: 0 | AU9: {=TEXT(VLOOKUP($A9,battle_data!$A:$G,MATCH(INDEX(_xlfn.TEXTSPLIT(AU$3,"|"),1),battle_data!$A$1:$G$1),0)*0.001,"0%")} -> 0% | AV9: {=TEXT(VLOOKUP($A9,battle_data!$A:$G,MATCH(INDEX(_xlfn.TEXTSPLIT(AV$3,"|"),1),battle_data!$A$1:$G$1),0)*0.001,"0%")} -> 60% | AW9: {=TEXT(VLOOKUP($A9,battle_data!$A:$G,MATCH(INDEX(_xlfn.TEXTSPLIT(AW$3,"|"),1),battle_data!$A$1:$G$1),0)*0.001,"0%")} -> 100% | AX9: =_xlfn.LET(_xlpm.p,($AV9),_xlpm.p*$AW9+(1-_xlpm.p)) -> 1 | AY9: =SUM($AP9:$AT9)*AX9 -> 0 | AZ9: =AA9/30 -> 1.1666667 | BA9: =AY9/AZ9 -> 0 | BB9: {=_xlfn.LAMBDA(_xlpm._dps,_xlpm._info_cell,ROUND(IF(_xlpm._dps<=0,-10,LOG(_xlpm._dps/INDEX(_xlfn.TEXTSPLIT(_xlpm._info_cell,"="),2),1.5)),2))($BA9,BB$3)} -> -10 | BC9: 0 | BD9: 1 | BE9: {=_xlfn.LAMBDA(_xlpm._lv,_xlpm._rank,_xlpm._base,_xlpm._lv+INDEX(_xlfn.TEXTSPLIT(_xlpm._base,"="),2)^(_xlpm._rank-2)-1)(BC9,BD9,BE$3)} -> -0.5 | BF9: 10.5 | BG9: =BE9*2-BB9-BF9 -> -1.5 | BH9: =$AY9*30/$AA9 -> 0 | BI9: =$AY9*120/($D9+4*$AA9) -> 0 | BJ9: 20 | BK9: 2 | BL9: =_xlfn.LET(_xlpm._level_power,2,IF($BK9<>"",BH9/_xlpm._level_power^$BK9,"")) -> 0 | BM9: =_xlfn.LET(_xlpm._level_power,2,IF($BK9<>"",BH9/_xlpm._level_power^$BK9,"")) -> 0
A10: 13101051 | B10: 充气球棒 Lv1 | C10: DScript_Melee | D10: 0 | E10: =TEXT(D10/120,"0.00")&" s" -> 0.00 s | F10: TRUE | G10: 0 | H10: =_xlfn.TEXTJOIN(";",1,$I10:$K10) -> 0 | I10: 0 | L10: =_xlfn.TEXTJOIN(";",1,$M10:$O10) -> 1 | M10: 1 | S10: attack_1;attack_2 | U10: se_ag_melee_wield | W10: 2 | X10: {=_xlfn.TEXTJOIN("~",1,Y10:Z10/AA10)} -> 0.428571428571429~0.571428571428571 | Y10: 15 | Z10: 20 | AA10: 35 | AF10: 0 | AG10: 8 | AL10: {=_xlfn.TEXTJOIN(";",1,IFERROR(1/AM10:AN10,""))} -> 0.00416666666666667 | AM10: 240 | AO10: {=_xlfn.TEXTJOIN(";",1,_xlfn.LAMBDA(_xlpm.x,IF(_xlpm.x<>"",OFFSET(_xlpm.x,3-ROW(),0)&"="&_xlpm.x,""))(AP10:AT10))} -> blunt=2 | AQ10: 2 | AU10: {=TEXT(VLOOKUP($A10,battle_data!$A:$G,MATCH(INDEX(_xlfn.TEXTSPLIT(AU$3,"|"),1),battle_data!$A$1:$G$1),0)*0.001,"0%")} -> 0% | AV10: {=TEXT(VLOOKUP($A10,battle_data!$A:$G,MATCH(INDEX(_xlfn.TEXTSPLIT(AV$3,"|"),1),battle_data!$A$1:$G$1),0)*0.001,"0%")} -> 60% | AW10: {=TEXT(VLOOKUP($A10,battle_data!$A:$G,MATCH(INDEX(_xlfn.TEXTSPLIT(AW$3,"|"),1),battle_data!$A$1:$G$1),0)*0.001,"0%")} -> 100% | AX10: =_xlfn.LET(_xlpm.p,($AV10),_xlpm.p*$AW10+(1-_xlpm.p)) -> 1 | AY10: =SUM($AP10:$AT10)*AX10 -> 2 | AZ10: =AA10/30 -> 1.1666667 | BA10: =AY10/AZ10 -> 1.7142857 | BB10: {=_xlfn.LAMBDA(_xlpm._dps,_xlpm._info_cell,ROUND(IF(_xlpm._dps<=0,-10,LOG(_xlpm._dps/INDEX(_xlfn.TEXTSPLIT(_xlpm._info_cell,"="),2),1.5)),2))($BA10,BB$3)} -> -8.55 | BC10: 1 | BD10: 1 | BE10: {=_xlfn.LAMBDA(_xlpm._lv,_xlpm._rank,_xlpm._base,_xlpm._lv+INDEX(_xlfn.TEXTSPLIT(_xlpm._base,"="),2)^(_xlpm._rank-2)-1)(BC10,BD10,BE$3)} -> 0.5 | BF10: 8.65 | BG10: =BE10*2-BB10-BF10 -> 0.9 | BH10: =$AY10*30/$AA10 -> 1.7142857 | BI10: =$AY10*120/($D10+4*$AA10) -> 1.7142857 | BJ10: 26 | BK10: 1 | BL10: =_xlfn.LET(_xlpm._level_power,2,IF($BK10<>"",BH10/_xlpm._level_power^$BK10,"")) -> 0.85714286 | BM10: =_xlfn.LET(_xlpm._level_power,2,IF($BK10<>"",BH10/_xlpm._level_power^$BK10,"")) -> 0.85714286
A11: 1310107 | B11: 双刃铡刀 | C11: DScript_Melee_Blade | D11: 0 | E11: =TEXT(D11/120,"0.00")&" s" -> 0.00 s | F11: FALSE | G11: 0 | H11: =_xlfn.TEXTJOIN(";",1,$I11:$K11) -> 0 | I11: 0 | L11: =_xlfn.TEXTJOIN(";",1,$M11:$O11) -> 1 | M11: 1 | S11: attack_1;attack_2 | U11: se_ag_melee_wield | V11: se_ag_melee_grinding | W11: 2 | X11: {=_xlfn.TEXTJOIN("~",1,Y11:Z11/AA11)} -> 0.307692307692308~0.769230769230769 | Y11: 8 | Z11: 20 | AA11: 26 | AF11: 1.7058 | AG11: 5 | AL11: {=_xlfn.TEXTJOIN(";",1,IFERROR(1/AM11:AN11,""))} -> 0.00208333333333333 | AM11: 480 | AO11: {=_xlfn.TEXTJOIN(";",1,_xlfn.LAMBDA(_xlpm.x,IF(_xlpm.x<>"",OFFSET(_xlpm.x,3-ROW(),0)&"="&_xlpm.x,""))(AP11:AT11))} -> sharp=150 | AP11: 150 | AU11: {=TEXT(VLOOKUP($A11,battle_data!$A:$G,MATCH(INDEX(_xlfn.TEXTSPLIT(AU$3,"|"),1),battle_data!$A$1:$G$1),0)*0.001,"0%")} -> 0% | AV11: {=TEXT(VLOOKUP($A11,battle_data!$A:$G,MATCH(INDEX(_xlfn.TEXTSPLIT(AV$3,"|"),1),battle_data!$A$1:$G$1),0)*0.001,"0%")} -> 8% | AW11: {=TEXT(VLOOKUP($A11,battle_data!$A:$G,MATCH(INDEX(_xlfn.TEXTSPLIT(AW$3,"|"),1),battle_data!$A$1:$G$1),0)*0.001,"0%")} -> 130% | AX11: =_xlfn.LET(_xlpm.p,($AV11),_xlpm.p*$AW11+(1-_xlpm.p)) -> 1.024 | AY11: =SUM($AP11:$AT11)*AX11 -> 153.6 | BH11: =$AY11*30/$AA11 -> 177.23077 | BI11: =$AY11*120/($D11+4*$AA11) -> 177.23077 | BJ11: 8 | BK11: 2 | BL11: =_xlfn.LET(_xlpm._level_power,2,IF($BK11<>"",BH11/_xlpm._level_power^$BK11,"")) -> 44.307692 | BM11: =_xlfn.LET(_xlpm._level_power,2,IF($BK11<>"",BH11/_xlpm._level_power^$BK11,"")) -> 44.307692
A12: 13101070 | B12: 双刃铡刀 Lv.0 | C12: DScript_Melee_Blade | D12: 0 | E12: =TEXT(D12/120,"0.00")&" s" -> 0.00 s | F12: FALSE | G12: 0 | H12: =_xlfn.TEXTJOIN(";",1,$I12:$K12) -> 0 | I12: 0 | L12: =_xlfn.TEXTJOIN(";",1,$M12:$O12) -> 1 | M12: 1 | S12: attack_1;attack_2 | U12: se_ag_melee_wield | V12: se_ag_melee_grinding | W12: 2 | X12: {=_xlfn.TEXTJOIN("~",1,Y12:Z12/AA12)} -> 0.307692307692308~0.769230769230769 | Y12: 8 | Z12: 20 | AA12: 26 | AF12: 1.7058 | AG12: 5 | AL12: {=_xlfn.TEXTJOIN(";",1,IFERROR(1/AM12:AN12,""))} -> 0.00208333333333333 | AM12: 480 | AO12: {=_xlfn.TEXTJOIN(";",1,_xlfn.LAMBDA(_xlpm.x,IF(_xlpm.x<>"",OFFSET(_xlpm.x,3-ROW(),0)&"="&_xlpm.x,""))(AP12:AT12))} -> sharp=35 | AP12: 35 | AU12: {=TEXT(VLOOKUP($A12,battle_data!$A:$G,MATCH(INDEX(_xlfn.TEXTSPLIT(AU$3,"|"),1),battle_data!$A$1:$G$1),0)*0.001,"0%")} -> 0% | AV12: {=TEXT(VLOOKUP($A12,battle_data!$A:$G,MATCH(INDEX(_xlfn.TEXTSPLIT(AV$3,"|"),1),battle_data!$A$1:$G$1),0)*0.001,"0%")} -> 8% | AW12: {=TEXT(VLOOKUP($A12,battle_data!$A:$G,MATCH(INDEX(_xlfn.TEXTSPLIT(AW$3,"|"),1),battle_data!$A$1:$G$1),0)*0.001,"0%")} -> 130% | AX12: =_xlfn.LET(_xlpm.p,($AV12),_xlpm.p*$AW12+(1-_xlpm.p)) -> 1.024 | AY12: =SUM($AP12:$AT12)*AX12 -> 35.84 | AZ12: =AA12/30 -> 0.86666667 | BA12: =AY12/AZ12 -> 41.353846 | BB12: {=_xlfn.LAMBDA(_xlpm._dps,_xlpm._info_cell,ROUND(IF(_xlpm._dps<=0,-10,LOG(_xlpm._dps/INDEX(_xlfn.TEXTSPLIT(_xlpm._info_cell,"="),2),1.5)),2))($BA12,BB$3)} -> -0.7 | BC12: 0 | BD12: 1 | BE12: {=_xlfn.LAMBDA(_xlpm._lv,_xlpm._rank,_xlpm._base,_xlpm._lv+INDEX(_xlfn.TEXTSPLIT(_xlpm._base,"="),2)^(_xlpm._rank-2)-1)(BC12,BD12,BE$3)} -> -0.5 | BF12: -0.3 | BG12: =BE12*2-BB12-BF12 -> 0 | BH12: =$AY12*30/$AA12 -> 41.353846 | BI12: =$AY12*120/($D12+4*$AA12) -> 41.353846 | BJ12: 3 | BK12: 2 | BL12: =_xlfn.LET(_xlpm._level_power,2,IF($BK12<>"",BH12/_xlpm._level_power^$BK12,"")) -> 10.338462 | BM12: =_xlfn.LET(_xlpm._level_power,2,IF($BK12<>"",BH12/_xlpm._level_power^$BK12,"")) -> 10.338462
A13: 13101071 | B13: 双刃铡刀 Lv.1 | C13: DScript_Melee_Blade | D13: 0 | E13: =TEXT(D13/120,"0.00")&" s" -> 0.00 s | F13: FALSE | G13: 0 | H13: =_xlfn.TEXTJOIN(";",1,$I13:$K13) -> 0 | I13: 0 | L13: =_xlfn.TEXTJOIN(";",1,$M13:$O13) -> 1 | M13: 1 | S13: attack_1;attack_2 | U13: se_ag_melee_wield | V13: se_ag_melee_grinding | W13: 2 | X13: {=_xlfn.TEXTJOIN("~",1,Y13:Z13/AA13)} -> 0.307692307692308~0.769230769230769 | Y13: 8 | Z13: 20 | AA13: 26 | AF13: 1.7058 | AG13: 5 | AL13: {=_xlfn.TEXTJOIN(";",1,IFERROR(1/AM13:AN13,""))} -> 0.00208333333333333 | AM13: 480 | AO13: {=_xlfn.TEXTJOIN(";",1,_xlfn.LAMBDA(_xlpm.x,IF(_xlpm.x<>"",OFFSET(_xlpm.x,3-ROW(),0)&"="&_xlpm.x,""))(AP13:AT13))} -> sharp=60 | AP13: 60 | AU13: {=TEXT(VLOOKUP($A13,battle_data!$A:$G,MATCH(INDEX(_xlfn.TEXTSPLIT(AU$3,"|"),1),battle_data!$A$1:$G$1),0)*0.001,"0%")} -> 0% | AV13: {=TEXT(VLOOKUP($A13,battle_data!$A:$G,MATCH(INDEX(_xlfn.TEXTSPLIT(AV$3,"|"),1),battle_data!$A$1:$G$1),0)*0.001,"0%")} -> 8% | AW13: {=TEXT(VLOOKUP($A13,battle_data!$A:$G,MATCH(INDEX(_xlfn.TEXTSPLIT(AW$3,"|"),1),battle_data!$A$1:$G$1),0)*0.001,"0%")} -> 130% | AX13: =_xlfn.LET(_xlpm.p,($AV13),_xlpm.p*$AW13+(1-_xlpm.p)) -> 1.024 | AY13: =SUM($AP13:$AT13)*AX13 -> 61.44 | AZ13: =AA13/30 -> 0.86666667 | BA13: =AY13/AZ13 -> 70.892308 | BB13: {=_xlfn.LAMBDA(_xlpm._dps,_xlpm._info_cell,ROUND(IF(_xlpm._dps<=0,-10,LOG(_xlpm._dps/INDEX(_xlfn.TEXTSPLIT(_xlpm._info_cell,"="),2),1.5)),2))($BA13,BB$3)} -> 0.63 | BC13: 1 | BD13: 1 | BE13: {=_xlfn.LAMBDA(_xlpm._lv,_xlpm._rank,_xlpm._base,_xlpm._lv+INDEX(_xlfn.TEXTSPLIT(_xlpm._base,"="),2)^(_xlpm._rank-2)-1)(BC13,BD13,BE$3)} -> 0.5 | BF13: -0.3 | BG13: =BE13*2-BB13-BF13 -> 0.67 | BH13: =$AY13*30/$AA13 -> 70.892308 | BI13: =$AY13*120/($D13+4*$AA13) -> 70.892308 | BJ13: 4 | BK13: 2 | BL13: =_xlfn.LET(_xlpm._level_power,2,IF($BK13<>"",BH13/_xlpm._level_power^$BK13,"")) -> 17.723077 | BM13: =_xlfn.LET(_xlpm._level_power,2,IF($BK13<>"",BH13/_xlpm._level_power^$BK13,"")) -> 17.723077
A14: 13101072 | B14: 双刃铡刀 Lv.2 | C14: DScript_Melee_Blade | D14: 0 | E14: =TEXT(D14/120,"0.00")&" s" -> 0.00 s | F14: FALSE | G14: 0 | H14: =_xlfn.TEXTJOIN(";",1,$I14:$K14) -> 0 | I14: 0 | L14: =_xlfn.TEXTJOIN(";",1,$M14:$O14) -> 1 | M14: 1 | S14: attack_1;attack_2 | U14: se_ag_melee_wield | V14: se_ag_melee_grinding | W14: 2 | X14: {=_xlfn.TEXTJOIN("~",1,Y14:Z14/AA14)} -> 0.307692307692308~0.769230769230769 | Y14: 8 | Z14: 20 | AA14: 26 | AF14: 1.7058 | AG14: 5 | AL14: {=_xlfn.TEXTJOIN(";",1,IFERROR(1/AM14:AN14,""))} -> 0.00208333333333333 | AM14: 480 | AO14: {=_xlfn.TEXTJOIN(";",1,_xlfn.LAMBDA(_xlpm.x,IF(_xlpm.x<>"",OFFSET(_xlpm.x,3-ROW(),0)&"="&_xlpm.x,""))(AP14:AT14))} -> sharp=95 | AP14: 95 | AU14: {=TEXT(VLOOKUP($A14,battle_data!$A:$G,MATCH(INDEX(_xlfn.TEXTSPLIT(AU$3,"|"),1),battle_data!$A$1:$G$1),0)*0.001,"0%")} -> 0% | AV14: {=TEXT(VLOOKUP($A14,battle_data!$A:$G,MATCH(INDEX(_xlfn.TEXTSPLIT(AV$3,"|"),1),battle_data!$A$1:$G$1),0)*0.001,"0%")} -> 8% | AW14: {=TEXT(VLOOKUP($A14,battle_data!$A:$G,MATCH(INDEX(_xlfn.TEXTSPLIT(AW$3,"|"),1),battle_data!$A$1:$G$1),0)*0.001,"0%")} -> 130% | AX14: =_xlfn.LET(_xlpm.p,($AV14),_xlpm.p*$AW14+(1-_xlpm.p)) -> 1.024 | AY14: =SUM($AP14:$AT14)*AX14 -> 97.28 | AZ14: =AA14/30 -> 0.86666667 | BA14: =AY14/AZ14 -> 112.24615 | BB14: {=_xlfn.LAMBDA(_xlpm._dps,_xlpm._info_cell,ROUND(IF(_xlpm._dps<=0,-10,LOG(_xlpm._dps/INDEX(_xlfn.TEXTSPLIT(_xlpm._info_cell,"="),2),1.5)),2))($BA14,BB$3)} -> 1.76 | BC14: 2 | BD14: 1 | BE14: {=_xlfn.LAMBDA(_xlpm._lv,_xlpm._rank,_xlpm._base,_xlpm._lv+INDEX(_xlfn.TEXTSPLIT(_xlpm._base,"="),2)^(_xlpm._rank-2)-1)(BC14,BD14,BE$3)} -> 1.5 | BF14: -0.3 | BG14: =BE14*2-BB14-BF14 -> 1.54 | BH14: =$AY14*30/$AA14 -> 112.24615 | BI14: =$AY14*120/($D14+4*$AA14) -> 112.24615 | BJ14: 5.33 | BK14: 2 | BL14: =_xlfn.LET(_xlpm._level_power,2,IF($BK14<>"",BH14/_xlpm._level_power^$BK14,"")) -> 28.061538 | BM14: =_xlfn.LET(_xlpm._level_power,2,IF($BK14<>"",BH14/_xlpm._level_power^$BK14,"")) -> 28.061538
A15: 13101073 | B15: 双刃铡刀 Lv.3 | C15: DScript_Melee_Blade | D15: 0 | E15: =TEXT(D15/120,"0.00")&" s" -> 0.00 s | F15: FALSE | G15: 0 | H15: =_xlfn.TEXTJOIN(";",1,$I15:$K15) -> 0 | I15: 0 | L15: =_xlfn.TEXTJOIN(";",1,$M15:$O15) -> 1 | M15: 1 | S15: attack_1;attack_2 | U15: se_ag_melee_wield | V15: se_ag_melee_grinding | W15: 2 | X15: {=_xlfn.TEXTJOIN("~",1,Y15:Z15/AA15)} -> 0.307692307692308~0.769230769230769 | Y15: 8 | Z15: 20 | AA15: 26 | AF15: 1.7058 | AG15: 5 | AL15: {=_xlfn.TEXTJOIN(";",1,IFERROR(1/AM15:AN15,""))} -> 0.00208333333333333 | AM15: 480 | AO15: {=_xlfn.TEXTJOIN(";",1,_xlfn.LAMBDA(_xlpm.x,IF(_xlpm.x<>"",OFFSET(_xlpm.x,3-ROW(),0)&"="&_xlpm.x,""))(AP15:AT15))} -> sharp=140 | AP15: 140 | AU15: {=TEXT(VLOOKUP($A15,battle_data!$A:$G,MATCH(INDEX(_xlfn.TEXTSPLIT(AU$3,"|"),1),battle_data!$A$1:$G$1),0)*0.001,"0%")} -> 0% | AV15: {=TEXT(VLOOKUP($A15,battle_data!$A:$G,MATCH(INDEX(_xlfn.TEXTSPLIT(AV$3,"|"),1),battle_data!$A$1:$G$1),0)*0.001,"0%")} -> 8% | AW15: {=TEXT(VLOOKUP($A15,battle_data!$A:$G,MATCH(INDEX(_xlfn.TEXTSPLIT(AW$3,"|"),1),battle_data!$A$1:$G$1),0)*0.001,"0%")} -> 130% | AX15: =_xlfn.LET(_xlpm.p,($AV15),_xlpm.p*$AW15+(1-_xlpm.p)) -> 1.024 | AY15: =SUM($AP15:$AT15)*AX15 -> 143.36 | AZ15: =AA15/30 -> 0.86666667 | BA15: =AY15/AZ15 -> 165.41538 | BB15: {=_xlfn.LAMBDA(_xlpm._dps,_xlpm._info_cell,ROUND(IF(_xlpm._dps<=0,-10,LOG(_xlpm._dps/INDEX(_xlfn.TEXTSPLIT(_xlpm._info_cell,"="),2),1.5)),2))($BA15,BB$3)} -> 2.72 | BC15: 3 | BD15: 1 | BE15: {=_xlfn.LAMBDA(_xlpm._lv,_xlpm._rank,_xlpm._base,_xlpm._lv+INDEX(_xlfn.TEXTSPLIT(_xlpm._base,"="),2)^(_xlpm._rank-2)-1)(BC15,BD15,BE$3)} -> 2.5 | BF15: -0.3 | BG15: =BE15*2-BB15-BF15 -> 2.58 | BH15: =$AY15*30/$AA15 -> 165.41538 | BI15: =$AY15*120/($D15+4*$AA15) -> 165.41538 | BJ15: 7.1 | BK15: 2 | BL15: =_xlfn.LET(_xlpm._level_power,2,IF($BK15<>"",BH15/_xlpm._level_power^$BK15,"")) -> 41.353846 | BM15: =_xlfn.LET(_xlpm._level_power,2,IF($BK15<>"",BH15/_xlpm._level_power^$BK15,"")) -> 41.353846
A16: 1311101 | B16: 执刑木棍 | C16: BasicMelee_Click | D16: 360 | E16: =TEXT(D16/120,"0.00")&" s" -> 3.00 s | F16: TRUE | G16: 0 | H16: =_xlfn.TEXTJOIN(";",1,$I16:$K16) -> 0 | I16: 0 | L16: =_xlfn.TEXTJOIN(";",1,$M16:$O16) -> 1 | M16: 1 | S16: attack_1;attack_2 | U16: se_ag_melee_wield | W16: 2 | X16: {=_xlfn.TEXTJOIN("~",1,Y16:Z16/AA16)} -> 0.25~0.4 | Y16: 5 | Z16: 8 | AA16: 20 | AF16: 1.67 | AG16: 8 | AL16: {=_xlfn.TEXTJOIN(";",1,IFERROR(1/AM16:AN16,""))} | AO16: {=_xlfn.TEXTJOIN(";",1,_xlfn.LAMBDA(_xlpm.x,IF(_xlpm.x<>"",OFFSET(_xlpm.x,3-ROW(),0)&"="&_xlpm.x,""))(AP16:AT16))} -> sharp=10;blunt=30 | AP16: 10 | AQ16: 30 | AU16: {=TEXT(VLOOKUP($A16,battle_data!$A:$G,MATCH(INDEX(_xlfn.TEXTSPLIT(AU$3,"|"),1),battle_data!$A$1:$G$1),0)*0.001,"0%")} -> 60% | AV16: {=TEXT(VLOOKUP($A16,battle_data!$A:$G,MATCH(INDEX(_xlfn.TEXTSPLIT(AV$3,"|"),1),battle_data!$A$1:$G$1),0)*0.001,"0%")} -> 10% | AW16: {=TEXT(VLOOKUP($A16,battle_data!$A:$G,MATCH(INDEX(_xlfn.TEXTSPLIT(AW$3,"|"),1),battle_data!$A$1:$G$1),0)*0.001,"0%")} -> 200% | AX16: =_xlfn.LET(_xlpm.p,($AV16),_xlpm.p*$AW16+(1-_xlpm.p)) -> 1.1 | AY16: =SUM($AP16:$AT16)*AX16 -> 44 | BH16: =$AY16*30/$AA16 -> 66 | BI16: =$AY16*120/($D16+4*$AA16) -> 12 | BJ16: 12 | BK16: 1 | BL16: =_xlfn.LET(_xlpm._level_power,2,IF($BK16<>"",BH16/_xlpm._level_power^$BK16,"")) -> 33 | BM16: =_xlfn.LET(_xlpm._level_power,2,IF($BK16<>"",BH16/_xlpm._level_power^$BK16,"")) -> 33
A17: 1311102 | B17: 执刑斧钺 | C17: BasicMelee_Click | D17: 750 | E17: =TEXT(D17/120,"0.00")&" s" -> 6.25 s | F17: FALSE | G17: 0 | H17: =_xlfn.TEXTJOIN(";",1,$I17:$K17) -> 7;24;60 | I17: 7 | J17: 24 | K17: 60 | L17: =_xlfn.TEXTJOIN(";",1,$M17:$O17) -> 0.25;0.6;0.85 | M17: 0.25 | N17: 0.6 | O17: 0.85 | P17: 0.05 | Q17: =R17/120 -> 0.016666667 | R17: 2 | S17: attack_1;attack_2 | U17: se_ag_melee_wield | V17: se_ag_melee_grinding | W17: 2 | X17: {=_xlfn.TEXTJOIN("~",1,Y17:Z17/AA17)} -> 0.485714285714286~0.571428571428571 | Y17: 17 | Z17: 20 | AA17: 35 | AF17: 1.75 | AG17: 2.5 | AL17: {=_xlfn.TEXTJOIN(";",1,IFERROR(1/AM17:AN17,""))} | AO17: {=_xlfn.TEXTJOIN(";",1,_xlfn.LAMBDA(_xlpm.x,IF(_xlpm.x<>"",OFFSET(_xlpm.x,3-ROW(),0)&"="&_xlpm.x,""))(AP17:AT17))} -> sharp=144;blunt=28 | AP17: 144 | AQ17: 28 | AU17: {=TEXT(VLOOKUP($A17,battle_data!$A:$G,MATCH(INDEX(_xlfn.TEXTSPLIT(AU$3,"|"),1),battle_data!$A$1:$G$1),0)*0.001,"0%")} -> 55% | AV17: {=TEXT(VLOOKUP($A17,battle_data!$A:$G,MATCH(INDEX(_xlfn.TEXTSPLIT(AV$3,"|"),1),battle_data!$A$1:$G$1),0)*0.001,"0%")} -> 10% | AW17: {=TEXT(VLOOKUP($A17,battle_data!$A:$G,MATCH(INDEX(_xlfn.TEXTSPLIT(AW$3,"|"),1),battle_data!$A$1:$G$1),0)*0.001,"0%")} -> 200% | AX17: =_xlfn.LET(_xlpm.p,($AV17),_xlpm.p*$AW17+(1-_xlpm.p)) -> 1.1 | AY17: =SUM($AP17:$AT17)*AX17 -> 189.2 | BH17: =$AY17*30/$AA17 -> 162.17143 | BI17: =$AY17*120/($D17+4*$AA17) -> 25.510112 | BJ17: 15 | BK17: 2 | BL17: =_xlfn.LET(_xlpm._level_power,2,IF($BK17<>"",BH17/_xlpm._level_power^$BK17,"")) -> 40.542857 | BM17: =_xlfn.LET(_xlpm._level_power,2,IF($BK17<>"",BH17/_xlpm._level_power^$BK17,"")) -> 40.542857
A18: 1311801 | B18: 短柄鱼叉 | C18: BasicMelee_Click | D18: 240 | E18: =TEXT(D18/120,"0.00")&" s" -> 2.00 s | F18: FALSE | G18: 0 | H18: =_xlfn.TEXTJOIN(";",1,$I18:$K18) -> 7;24;60 | I18: 7 | J18: 24 | K18: 60 | L18: =_xlfn.TEXTJOIN(";",1,$M18:$O18) -> 0.25;0.6;0.85 | M18: 0.25 | N18: 0.6 | O18: 0.85 | P18: 0.03 | Q18: =R18/120 -> 0.027777778 | R18: =10/3 -> 3.3333333 | T18: attack_1 | U18: se_ag_melee_wield | V18: se_ag_melee_grinding | W18: 1 | X18: {=_xlfn.TEXTJOIN("~",1,Y18:Z18/AA18)} -> 0.4~0.6 | Y18: 10 | Z18: 15 | AA18: 25 | AF18: 1.0188 | AG18: 9 | AL18: {=_xlfn.TEXTJOIN(";",1,IFERROR(1/AM18:AN18,""))} | AO18: {=_xlfn.TEXTJOIN(";",1,_xlfn.LAMBDA(_xlpm.x,IF(_xlpm.x<>"",OFFSET(_xlpm.x,3-ROW(),0)&"="&_xlpm.x,""))(AP18:AT18))} -> sharp=72 | AP18: 72 | AU18: {=TEXT(VLOOKUP($A18,battle_data!$A:$G,MATCH(INDEX(_xlfn.TEXTSPLIT(AU$3,"|"),1),battle_data!$A$1:$G$1),0)*0.001,"0%")} -> 50% | AV18: {=TEXT(VLOOKUP($A18,battle_data!$A:$G,MATCH(INDEX(_xlfn.TEXTSPLIT(AV$3,"|"),1),battle_data!$A$1:$G$1),0)*0.001,"0%")} -> 15% | AW18: {=TEXT(VLOOKUP($A18,battle_data!$A:$G,MATCH(INDEX(_xlfn.TEXTSPLIT(AW$3,"|"),1),battle_data!$A$1:$G$1),0)*0.001,"0%")} -> 300% | AX18: =_xlfn.LET(_xlpm.p,($AV18),_xlpm.p*$AW18+(1-_xlpm.p)) -> 1.3 | AY18: =SUM($AP18:$AT18)*AX18 -> 93.6 | BH18: =$AY18*30/$AA18 -> 112.32 | BI18: =$AY18*120/($D18+4*$AA18) -> 33.035294 | BJ18: 3 | BK18: 1 | BL18: =_xlfn.LET(_xlpm._level_power,2,IF($BK18<>"",BH18/_xlpm._level_power^$BK18,"")) -> 56.16 | BM18: =_xlfn.LET(_xlpm._level_power,2,IF($BK18<>"",BH18/_xlpm._level_power^$BK18,"")) -> 56.16
A19: 1311802 | B19: 海妖触手 | C19: BasicMelee_Click | D19: 300 | E19: =TEXT(D19/120,"0.00")&" s" -> 2.50 s | F19: FALSE | G19: 0 | H19: =_xlfn.TEXTJOIN(";",1,$I19:$K19) -> 0 | I19: 0 | L19: =_xlfn.TEXTJOIN(";",1,$M19:$O19) -> 1 | M19: 1 | S19: attack_1 | U19: se_ag_melee_wield | W19: 1 | X19: {=_xlfn.TEXTJOIN("~",1,Y19:Z19/AA19)} -> 0.4~0.72 | Y19: 10 | Z19: 18 | AA19: 25 | AF19: 1.0188 | AG19: 9 | AL19: {=_xlfn.TEXTJOIN(";",1,IFERROR(1/AM19:AN19,""))} | AO19: {=_xlfn.TEXTJOIN(";",1,_xlfn.LAMBDA(_xlpm.x,IF(_xlpm.x<>"",OFFSET(_xlpm.x,3-ROW(),0)&"="&_xlpm.x,""))(AP19:AT19))} -> blunt=44;acid=22;wrap=11 | AQ19: 44 | AS19: 22 | AT19: 11 | AU19: {=TEXT(VLOOKUP($A19,battle_data!$A:$G,MATCH(INDEX(_xlfn.TEXTSPLIT(AU$3,"|"),1),battle_data!$A$1:$G$1),0)*0.001,"0%")} -> 35% | AV19: {=TEXT(VLOOKUP($A19,battle_data!$A:$G,MATCH(INDEX(_xlfn.TEXTSPLIT(AV$3,"|"),1),battle_data!$A$1:$G$1),0)*0.001,"0%")} -> 0% | AW19: {=TEXT(VLOOKUP($A19,battle_data!$A:$G,MATCH(INDEX(_xlfn.TEXTSPLIT(AW$3,"|"),1),battle_data!$A$1:$G$1),0)*0.001,"0%")} -> 150% | AX19: =_xlfn.LET(_xlpm.p,($AV19),_xlpm.p*$AW19+(1-_xlpm.p)) -> 1 | AY19: =SUM($AP19:$AT19)*AX19 -> 77 | BH19: =$AY19*30/$AA19 -> 92.4 | BI19: =$AY19*120/($D19+4*$AA19) -> 23.1 | BJ19: 6.5 | BK19: 2 | BL19: =_xlfn.LET(_xlpm._level_power,2,IF($BK19<>"",BH19/_xlpm._level_power^$BK19,"")) -> 23.1 | BM19: =_xlfn.LET(_xlpm._level_power,2,IF($BK19<>"",BH19/_xlpm._level_power^$BK19,"")) -> 23.1
A21: 1319001 | B21: AMY棍棒 | C21: DScript_Melee_Baton | D21: 0 | E21: =TEXT(D21/120,"0.00")&" s" -> 0.00 s | F21: TRUE | G21: 0 | H21: =_xlfn.TEXTJOIN(";",1,$I21:$K21) -> 0 | I21: 0 | L21: =_xlfn.TEXTJOIN(";",1,$M21:$O21) -> 1 | M21: 1 | S21: attack_1;attack_2 | U21: se_ag_melee_wield | W21: 2 | X21: {=_xlfn.TEXTJOIN("~",1,Y21:Z21/AA21)} -> 0.25~0.4 | Y21: 5 | Z21: 8 | AA21: 20 | AF21: 1.67 | AG21: 8 | AH21: 0 | AL21: {=_xlfn.TEXTJOIN(";",1,IFERROR(1/AM21:AN21,""))} -> 0.00416666666666667 | AM21: 240 | AO21: {=_xlfn.TEXTJOIN(";",1,_xlfn.LAMBDA(_xlpm.x,IF(_xlpm.x<>"",OFFSET(_xlpm.x,3-ROW(),0)&"="&_xlpm.x,""))(AP21:AT21))} -> sharp=10;blunt=30 | AP21: 10 | AQ21: 30 | AU21: {=TEXT(VLOOKUP($A21,battle_data!$A:$G,MATCH(INDEX(_xlfn.TEXTSPLIT(AU$3,"|"),1),battle_data!$A$1:$G$1),0)*0.001,"0%")} -> 60% | AV21: {=TEXT(VLOOKUP($A21,battle_data!$A:$G,MATCH(INDEX(_xlfn.TEXTSPLIT(AV$3,"|"),1),battle_data!$A$1:$G$1),0)*0.001,"0%")} -> 10% | AW21: {=TEXT(VLOOKUP($A21,battle_data!$A:$G,MATCH(INDEX(_xlfn.TEXTSPLIT(AW$3,"|"),1),battle_data!$A$1:$G$1),0)*0.001,"0%")} -> 200% | AX21: =_xlfn.LET(_xlpm.p,($AV21),_xlpm.p*$AW21+(1-_xlpm.p)) -> 1.1 | AY21: =SUM($AP21:$AT21)*AX21 -> 44 | AZ21: =AA21/30 -> 0.66666667 | BA21: =AY21/AZ21 -> 66 | BB21: {=_xlfn.LAMBDA(_xlpm._dps,_xlpm._info_cell,ROUND(IF(_xlpm._dps<=0,-10,LOG(_xlpm._dps/INDEX(_xlfn.TEXTSPLIT(_xlpm._info_cell,"="),2),1.5)),2))($BA21,BB$3)} -> 0.45 | BC21: 1 | BG21: =BC21*2-BB21-BF21 -> 1.55 | BH21: =$AY21*30/$AA21 -> 66 | BI21: =$AY21*120/($D21+4*$AA21) -> 66 | BJ21: 12 | BK21: 1 | BL21: =_xlfn.LET(_xlpm._level_power,2,IF($BK21<>"",BH21/_xlpm._level_power^$BK21,"")) -> 33 | BM21: =_xlfn.LET(_xlpm._level_power,2,IF($BK21<>"",BH21/_xlpm._level_power^$BK21,"")) -> 33
A22: 1319002 | B22: AMY大剑 | C22: DScript_Melee_Claymore | D22: 0 | E22: =TEXT(D22/120,"0.00")&" s" -> 0.00 s | F22: FALSE | G22: 0 | H22: =_xlfn.TEXTJOIN(";",1,$I22:$K22) -> 7;24;60 | I22: 7 | J22: 24 | K22: 60 | L22: =_xlfn.TEXTJOIN(";",1,$M22:$O22) -> 0.4;0.6;0.85 | M22: 0.4 | N22: 0.6 | O22: 0.85 | P22: 0.1 | Q22: 20 | S22: attack_1;attack_2 | U22: se_ag_melee_wield | V22: se_ag_melee_grinding | W22: 2 | X22: {=_xlfn.TEXTJOIN("~",1,Y22:Z22/AA22)} -> 0.466666666666667~0.6 | Y22: 14 | Z22: 18 | AA22: 30 | AF22: 1.7058 | AG22: 5 | AH22: 1 | AI22: =1/AJ22 -> 0.0083333333 | AJ22: 120 | AK22: =TEXT(AJ22/120,"0.00")&" s" -> 1.00 s | AL22: {=_xlfn.TEXTJOIN(";",1,IFERROR(1/AM22:AN22,""))} -> 0.00208333333333333;0.00833333333333333 | AM22: 480 | AN22: 120 | AO22: {=_xlfn.TEXTJOIN(";",1,_xlfn.LAMBDA(_xlpm.x,IF(_xlpm.x<>"",OFFSET(_xlpm.x,3-ROW(),0)&"="&_xlpm.x,""))(AP22:AT22))} -> sharp=150 | AP22: 150 | AU22: {=TEXT(VLOOKUP($A22,battle_data!$A:$G,MATCH(INDEX(_xlfn.TEXTSPLIT(AU$3,"|"),1),battle_data!$A$1:$G$1),0)*0.001,"0%")} -> 0% | AV22: {=TEXT(VLOOKUP($A22,battle_data!$A:$G,MATCH(INDEX(_xlfn.TEXTSPLIT(AV$3,"|"),1),battle_data!$A$1:$G$1),0)*0.001,"0%")} -> 10% | AW22: {=TEXT(VLOOKUP($A22,battle_data!$A:$G,MATCH(INDEX(_xlfn.TEXTSPLIT(AW$3,"|"),1),battle_data!$A$1:$G$1),0)*0.001,"0%")} -> 200% | AX22: =_xlfn.LET(_xlpm.p,($AV22),_xlpm.p*$AW22+(1-_xlpm.p)) -> 1.1 | AY22: =SUM($AP22:$AT22)*AX22 -> 165 | AZ22: =AA22/30 -> 1 | BA22: =AY22/AZ22 -> 165 | BB22: {=_xlfn.LAMBDA(_xlpm._dps,_xlpm._info_cell,ROUND(IF(_xlpm._dps<=0,-10,LOG(_xlpm._dps/INDEX(_xlfn.TEXTSPLIT(_xlpm._info_cell,"="),2),1.5)),2))($BA22,BB$3)} -> 2.71 | BC22: 2 | BG22: =BC22*2-BB22-BF22 -> 1.29 | BH22: =$AY22*30/$AA22 -> 165 | BI22: =$AY22*120/($D22+4*$AA22) -> 165 | BJ22: 8 | BK22: 2 | BL22: =_xlfn.LET(_xlpm._level_power,2,IF($BK22<>"",BH22/_xlpm._level_power^$BK22,"")) -> 41.25 | BM22: =_xlfn.LET(_xlpm._level_power,2,IF($BK22<>"",BH22/_xlpm._level_power^$BK22,"")) -> 41.25

Sheet fire_logic
A1: logic_id | E1: SE_fire | F1: SE_reloaded | G1: projectile_id | I1: speed | L1: projectile_life_ticks | P1: salvo | Q1: angle | S1: bone_name | T1: capacity | U1: need_loaded_in_barrel_before_shoot | V1: auto_load | W1: reload_num | X1: reload_trigger_speed | Y1: ui_reloading_trigger_ticks | AA1: reload_speed | AB1: ui_reloading_ticks | AE1: job_speed | AI1: tick_percent | AJ1: rapid_fire_tick_percent | AO1: cd | AQ1: damage
A2: uint key | E2: string | F2: string | G2: uint | I2: (float,float) | L2: (int,int) | P2: uint | Q2: float | S2: string | T2: uint | U2: bool | V2: bool | W2: int | X2: float | Y2: int | AA2: float | AB2: int | AE2: float[] | AI2: float | AJ2: float | AO2: int | AQ2: dict<string,int>
A3: 发射逻辑id | B3: 备注1 名称 | C3: 备注2 类型 | D3: 备注3 设备/怪物控制脚本 | E3: 音效-射击 怪物未实装 | F3: 音效-装填完毕 怪物未实装 | G3: 飞射物id | H3: 备注 | I3: 初速度 设备: 随机 怪物: t控制 | J3: 辅助列 初速度 min | K3: 辅助列 初速度 max | L3: 飞射物寿命 | M3: 辅助列 寿命 min | N3: 辅助列 寿命 max | P3: 齐发数 单次射击多个子弹 | Q3: 散布角度 | R3: 精准度 | S3: 飞射物 创建位置 所在骨骼 | T3: 备弹数 弹匣容量 仅设备使用 对怪物无效 | U3: 开火前 是否需上膛 对怪物无效 | V3: 可自动上膛 “开火前需要上膛”配置为true时，该项才有意义 对怪物无效 | W3: 装填数 n<=0: 一次性装填完毕 n>0: 逐发装填具体数量 对怪物无效 | X3: 装填启动速度 设备:进入reload的速率 对怪物无效 | Y3: 装填启动速率 时长辅助 （帧） | Z3: 备注 时长(秒) | AA3: 装填速度 设备:装填速率 reload状态下每两发子弹的装填间隔 对怪物无效 | AB3: 装填速率 时长辅助 （帧） | AC3: 备注1 时长(秒) | AD3: 特殊2 时长修正倍数 | AE3: NPC工作速度 工作1：装填 工作2：射击 对怪物无效 | AF3: 工作1 装填 帧数 | AG3: 工作2 射击 帧数 | AH3: 工作3 弹药搬运 帧数 | AI3: 开火帧（0~1） 在这一时刻创造飞射物 对怪物无效 | AJ3: 后摇帧（0~1） 这一时刻后 进入可被打断的后摇 对怪物无效 | AK3: 射击帧 | AL3: 打断帧 | AM3: 总帧数 | AN3: 最小 动画 攻击 间隔 | AO3: 射击 冷却帧 设备:基础cd 怪物:cd | AP3: 备注 (秒) | AQ3: 伤害 | AR3: sharp | AS3: blunt | AT3: fire | AU3: acid | AV3: wrap | AW3: flash | AX3: armor_piercing |护甲穿透 |对怪物无效 | AY3: critical_chance |暴击率 |对怪物无效 | AZ3: critical_rate |暴击伤害 |对怪物无效 | BA3: 计算参考 暴击修正倍率期望 | BB3: 特殊 单轮齐射总数 | BC3: 计算参考 单轮伤害 | BD3: 特殊 单轮射击耗时 （帧） | BE3: 特殊 单轮装填耗时 （帧） | BF3: 手动交互 单轮总耗时 （秒） | BG3: 计算统计 DPS | BH3: 计算统计 输出等级 base=32 | BI3: 设定 等级 | BJ3: 设定 宽度 | BK3: 战力 等级 base=2 | BL3: 其他属性补正 e.g.. 因手感差、射程近等因素，获得减分 | BM3: 适配 生存等级 | BN3: 计算参考 单轮耗时 (极限) （秒） | BO3: 计算参考 单轮耗时 （常规） （秒） | BP3: 计算参考 单轮DPS | BQ3: 计算参考 装填默认总时长 | BR3: 计算参考 手动DPS 表显max： 300 | BS3: 计算参考 自动DPS 表显max： 300 | BT3: 计算参考 等级 | BU3: 计算参考 手动DPS 表显max： 050 | BV3: 计算参考 自动DPS 表显max： 050
A4: 1320101 | B4: 弓箭 | C4: 设备 | D4: BasicShooter | E4: se_ag_bow_shoot | F4: se_ag_bow_reload | G4: 10001 | H4: =IF(G4<>"",IFERROR(VLOOKUP(G4,t_proj[#All],2,0),"--"),"") -> 箭矢 | I4: =_xlfn.TEXTJOIN("~",1,J4:K4) -> 25~0 | J4: 25 | K4: 0 | L4: =_xlfn.TEXTJOIN("~",1,M4:N4) -> 2400~0 | M4: 2400 | N4: 0 | P4: 1 | Q4: 3 | R4: =IF(Q4="","",1-Q4/20) -> 0.85 | S4: proj_muzzel | T4: 22 | U4: TRUE | V4: FALSE | W4: 1 | X4: =1/Y4 -> 0.0083333333 | Y4: 120 | Z4: =TEXT(Y4/120,"0.00")&" s" -> 1.00 s | AA4: =1/AB4 -> 0.0083333333 | AB4: 120 | AC4: =TEXT(AB4/120,"0.00")&" s" -> 1.00 s | AD4: 1 | AE4: {=_xlfn.TEXTJOIN(";",1,IFERROR(1/AF4:AH4,""))} -> 0.00833333333333333;0.00833333333333333 | AF4: 120 | AG4: 120 | AI4: =AK4/AM4 -> 0.88 | AJ4: =AL4/AM4 -> 0.98 | AK4: 22 | AL4: 24.5 | AM4: 25 | AN4: =($AL4-$AK4)*120/30 -> 10 | AO4: 360 | AP4: =TEXT(AO4/120,"0.00")&" s" -> 3.00 s | AQ4: {=_xlfn.TEXTJOIN(";",1,_xlfn.LAMBDA(_xlpm.x,IF(_xlpm.x<>"",OFFSET(_xlpm.x,3-ROW(),0)&"="&_xlpm.x,""))(AR4:AW4))} -> sharp=52 | AR4: 52 | AX4: {=TEXT(VLOOKUP($A4,battle_data!$A:$G,MATCH(INDEX(_xlfn.TEXTSPLIT(AX$3,"|"),1),battle_data!$A$1:$G$1),0)*0.001,"0%")} -> 20% | AY4: {=TEXT(VLOOKUP($A4,battle_data!$A:$G,MATCH(INDEX(_xlfn.TEXTSPLIT(AY$3,"|"),1),battle_data!$A$1:$G$1),0)*0.001,"0%")} -> 20% | AZ4: {=TEXT(VLOOKUP($A4,battle_data!$A:$G,MATCH(INDEX(_xlfn.TEXTSPLIT(AZ$3,"|"),1),battle_data!$A$1:$G$1),0)*0.001,"0%")} -> 300% | BA4: =_xlfn.LET(_xlpm.p,($AY4),_xlpm.p*$AZ4+(1-_xlpm.p)) -> 1.4 | BC4: =_xlfn.LET(_xlpm._custom_all_ammo,$BB4, _xlpm._all_ammo,IF(_xlpm._custom_all_ammo<>"",_xlpm._custom_all_ammo,$P4*$T4), IF(A4<>"",SUM($AR4:$AW4)*$BA4*_xlpm._all_ammo,"")) -> 1601.6 | BN4: =(($T4-1)*$AL4+$AM4)/30 -> 17.983333 | BO4: =(($T4-1)*($AL4+$AO4/4)+$AM4)/30 -> 80.983333 | BP4: =$BC4/$BO4 -> 19.776909 | BQ4: =$AB4*$AD4*IF($W4<=0,1,$T4)/120 -> 22 | BR4: =$BC4/($BQ4+$BN4) -> 40.05669 | BS4: =$BC4/($BQ4+$BO4) -> 15.552031 | BT4: 0 | BU4: =_xlfn.LET(_xlpm._level_power,2,IF($BT4<>"",BR4/_xlpm._level_power^$BT4,"")) -> 40.05669 | BV4: =_xlfn.LET(_xlpm._level_power,2,IF($BT4<>"",BR4/_xlpm._level_power^$BT4,"")) -> 40.05669
A5: 1320102 | B5: 防身手枪 | C5: 设备 | D5: DScript_Shooter | E5: se_ag_shoot_gun | F5: se_ag_gun_reloaded | G5: 10002 | H5: =IF(G5<>"",IFERROR(VLOOKUP(G5,t_proj[#All],2,0),"--"),"") -> 手枪子弹 | I5: =_xlfn.TEXTJOIN("~",1,J5:K5) -> 85~0 | J5: 85 | K5: 0 | L5: =_xlfn.TEXTJOIN("~",1,M5:N5) -> 360~0 | M5: 360 | N5: 0 | P5: 1 | Q5: 4 | R5: =IF(Q5="","",1-Q5/20) -> 0.8 | S5: proj_muzzel | T5: 17 | U5: FALSE | W5: 1 | X5: =1/Y5 -> 0.025 | Y5: 40 | Z5: =TEXT(Y5/120,"0.00")&" s" -> 0.33 s | AA5: =1/AB5 -> 0.025 | AB5: 40 | AC5: =TEXT(AB5/120,"0.00")&" s" -> 0.33 s | AD5: 1 | AE5: {=_xlfn.TEXTJOIN(";",1,IFERROR(1/AF5:AH5,""))} -> 0.025;0.025 | AF5: 40 | AG5: 40 | AI5: =AK5/AM5 -> 0.3 | AJ5: =AL5/AM5 -> 0.6 | AK5: 3 | AL5: 6 | AM5: 10 | AN5: =($AL5-$AK5)*120/30 -> 12 | AO5: 18 | AP5: =TEXT(AO5/120,"0.00")&" s" -> 0.15 s | AQ5: {=_xlfn.TEXTJOIN(";",1,_xlfn.LAMBDA(_xlpm.x,IF(_xlpm.x<>"",OFFSET(_xlpm.x,3-ROW(),0)&"="&_xlpm.x,""))(AR5:AW5))} -> sharp=21 | AR5: 21 | AX5: {=TEXT(VLOOKUP($A5,battle_data!$A:$G,MATCH(INDEX(_xlfn.TEXTSPLIT(AX$3,"|"),1),battle_data!$A$1:$G$1),0)*0.001,"0%")} -> 0% | AY5: {=TEXT(VLOOKUP($A5,battle_data!$A:$G,MATCH(INDEX(_xlfn.TEXTSPLIT(AY$3,"|"),1),battle_data!$A$1:$G$1),0)*0.001,"0%")} -> 3% | AZ5: {=TEXT(VLOOKUP($A5,battle_data!$A:$G,MATCH(INDEX(_xlfn.TEXTSPLIT(AZ$3,"|"),1),battle_data!$A$1:$G$1),0)*0.001,"0%")} -> 150% | BA5: =_xlfn.LET(_xlpm.p,($AY5),_xlpm.p*$AZ5+(1-_xlpm.p)) -> 1.015 | BC5: =_xlfn.LET(_xlpm._custom_all_ammo,$BB5, _xlpm._all_ammo,IF(_xlpm._custom_all_ammo<>"",_xlpm._custom_all_ammo,$P5*$T5), IF(A5<>"",SUM($AR5:$AW5)*$BA5*_xlpm._all_ammo,"")) -> 362.355 | BN5: =(($T5-1)*$AL5+$AM5)/30 -> 3.5333333 | BO5: =(($T5-1)*($AL5+$AO5/4)+$AM5)/30 -> 5.9333333 | BP5: =$BC5/$BO5 -> 61.071067 | BQ5: =$AB5*$AD5*IF($W5<=0,1,$T5)/120 -> 5.6666667 | BR5: =$BC5/($BQ5+$BN5) -> 39.386413 | BS5: =$BC5/($BQ5+$BO5) -> 31.2375 | BT5: 0 | BU5: =_xlfn.LET(_xlpm._level_power,2,IF(BT5<>"",BR5/_xlpm._level_power^BT5,"")) -> 39.386413 | BV5: =_xlfn.LET(_xlpm._level_power,2,IF($BT5<>"",BR5/_xlpm._level_power^$BT5,"")) -> 39.386413
A6: 13201021 | B6: 防身手枪 | C6: 设备 | D6: DScript_Shooter | E6: se_ag_shoot_gun | F6: se_ag_gun_reloaded | G6: 10002 | H6: =IF(G6<>"",IFERROR(VLOOKUP(G6,t_proj[#All],2,0),"--"),"") -> 手枪子弹 | I6: =_xlfn.TEXTJOIN("~",1,J6:K6) -> 85~0 | J6: 85 | K6: 0 | L6: =_xlfn.TEXTJOIN("~",1,M6:N6) -> 360~0 | M6: 360 | N6: 0 | P6: 1 | Q6: 4 | R6: =IF(Q6="","",1-Q6/20) -> 0.8 | S6: proj_muzzel | T6: 17 | U6: FALSE | W6: 1 | X6: =1/Y6 -> 0.0066666667 | Y6: 150 | Z6: =TEXT(Y6/120,"0.00")&" s" -> 1.25 s | AA6: =1/AB6 -> 0.033333333 | AB6: 30 | AC6: =TEXT(AB6/120,"0.00")&" s" -> 0.25 s | AD6: 1 | AE6: {=_xlfn.TEXTJOIN(";",1,IFERROR(1/AF6:AH6,""))} -> 0.00555555555555556;0.025 | AF6: 180 | AG6: 40 | AI6: =AK6/AM6 -> 0.3 | AJ6: =AL6/AM6 -> 0.6 | AK6: 3 | AL6: 6 | AM6: 10 | AN6: =($AL6-$AK6)*120/30 -> 12 | AO6: 18 | AP6: =TEXT(AO6/120,"0.00")&" s" -> 0.15 s | AQ6: {=_xlfn.TEXTJOIN(";",1,_xlfn.LAMBDA(_xlpm.x,IF(_xlpm.x<>"",OFFSET(_xlpm.x,3-ROW(),0)&"="&_xlpm.x,""))(AR6:AW6))} -> sharp=25 | AR6: 25 | AX6: {=TEXT(VLOOKUP($A6,battle_data!$A:$G,MATCH(INDEX(_xlfn.TEXTSPLIT(AX$3,"|"),1),battle_data!$A$1:$G$1),0)*0.001,"0%")} -> 0% | AY6: {=TEXT(VLOOKUP($A6,battle_data!$A:$G,MATCH(INDEX(_xlfn.TEXTSPLIT(AY$3,"|"),1),battle_data!$A$1:$G$1),0)*0.001,"0%")} -> 3% | AZ6: {=TEXT(VLOOKUP($A6,battle_data!$A:$G,MATCH(INDEX(_xlfn.TEXTSPLIT(AZ$3,"|"),1),battle_data!$A$1:$G$1),0)*0.001,"0%")} -> 150% | BA6: =_xlfn.LET(_xlpm.p,($AY6),_xlpm.p*$AZ6+(1-_xlpm.p)) -> 1.015 | BC6: =_xlfn.LET(_xlpm._custom_all_ammo,$BB6, _xlpm._all_ammo,IF(_xlpm._custom_all_ammo<>"",_xlpm._custom_all_ammo,$P6*$T6), IF(A6<>"",SUM($AR6:$AW6)*$BA6*_xlpm._all_ammo,"")) -> 431.375 | BF6: =_xlfn.LET(_xlpm._ammo,$T6, _xlpm._count_reload,IF($W6>0,_xlfn.CEILING.MATH(_xlpm._ammo/$W6),1), _xlpm._shoot_ticks,IF($BD6<>"",$BD6,($AL6*(_xlpm._ammo-1)+$AM6)*120/30), _xlpm._reload_ticks,IF($BE6<>"",$BE6,$Y6+$AB6*_xlpm._count_reload), (_xlpm._shoot_ticks+_xlpm._reload_ticks)/120 ) -> 9.0333333 | BG6: =BC6/BF6 -> 47.75369 | BH6: {=_xlfn.LAMBDA(_xlpm._dps,_xlpm._info_cell,ROUND(IF(_xlpm._dps<=0,-10,LOG(_xlpm._dps/INDEX(_xlfn.TEXTSPLIT(_xlpm._info_cell,"="),2),1.5)),2))($BG6,BH$3)} -> 0.99 | BI6: 1 | BJ6: 2 | BK6: {=_xlfn.LAMBDA(_xlpm._lv,_xlpm._rank,_xlpm._base,_xlpm._lv+INDEX(_xlfn.TEXTSPLIT(_xlpm._base,"="),2)^(_xlpm._rank-2)-1)(BI6,BJ6,BK$3)} -> 1 | BM6: =BK6*2-BH6-BL6 -> 1.01 | BN6: =(($T6-1)*$AL6+$AM6)/30 -> 3.5333333 | BO6: =(($T6-1)*($AL6+$AO6/4)+$AM6)/30 -> 5.9333333 | BP6: =$BC6/$BO6 -> 72.703652 | BQ6: =$AB6*$AD6*IF($W6<=0,1,$T6)/120 -> 4.25 | BR6: =BP6 -> 72.703652 | BS6: =$BC6/($BQ6+$BO6) -> 42.360884 | BT6: 1 | BU6: =_xlfn.LET(_xlpm._level_power,2,IF(BT6<>"",BR6/_xlpm._level_power^BT6,"")) -> 36.351826 | BV6: =_xlfn.LET(_xlpm._level_power,2,IF($BT6<>"",BR6/_xlpm._level_power^$BT6,"")) -> 36.351826
A7: 13201022 | B7: 前线手枪 | C7: 设备 | D7: DScript_Shooter | E7: se_ag_shoot_gun | F7: se_ag_gun_reloaded | G7: 10002 | H7: =IF(G7<>"",IFERROR(VLOOKUP(G7,t_proj[#All],2,0),"--"),"") -> 手枪子弹 | I7: =_xlfn.TEXTJOIN("~",1,J7:K7) -> 85~0 | J7: 85 | K7: 0 | L7: =_xlfn.TEXTJOIN("~",1,M7:N7) -> 360~0 | M7: 360 | N7: 0 | P7: 1 | Q7: 4 | R7: =IF(Q7="","",1-Q7/20) -> 0.8 | S7: proj_muzzel | T7: 17 | U7: FALSE | W7: 1 | X7: =1/Y7 -> 0.0066666667 | Y7: 150 | Z7: =TEXT(Y7/120,"0.00")&" s" -> 1.25 s | AA7: =1/AB7 -> 0.041666667 | AB7: 24 | AC7: =TEXT(AB7/120,"0.00")&" s" -> 0.20 s | AD7: 1 | AE7: {=_xlfn.TEXTJOIN(";",1,IFERROR(1/AF7:AH7,""))} -> 0.00555555555555556;0.03125 | AF7: 180 | AG7: 32 | AI7: =AK7/AM7 -> 0.3 | AJ7: =AL7/AM7 -> 0.6 | AK7: 3 | AL7: 6 | AM7: 10 | AN7: =($AL7-$AK7)*120/30 -> 12 | AO7: 18 | AP7: =TEXT(AO7/120,"0.00")&" s" -> 0.15 s | AQ7: {=_xlfn.TEXTJOIN(";",1,_xlfn.LAMBDA(_xlpm.x,IF(_xlpm.x<>"",OFFSET(_xlpm.x,3-ROW(),0)&"="&_xlpm.x,""))(AR7:AW7))} -> sharp=34 | AR7: 34 | AX7: {=TEXT(VLOOKUP($A7,battle_data!$A:$G,MATCH(INDEX(_xlfn.TEXTSPLIT(AX$3,"|"),1),battle_data!$A$1:$G$1),0)*0.001,"0%")} -> 0% | AY7: {=TEXT(VLOOKUP($A7,battle_data!$A:$G,MATCH(INDEX(_xlfn.TEXTSPLIT(AY$3,"|"),1),battle_data!$A$1:$G$1),0)*0.001,"0%")} -> 3% | AZ7: {=TEXT(VLOOKUP($A7,battle_data!$A:$G,MATCH(INDEX(_xlfn.TEXTSPLIT(AZ$3,"|"),1),battle_data!$A$1:$G$1),0)*0.001,"0%")} -> 150% | BA7: =_xlfn.LET(_xlpm.p,($AY7),_xlpm.p*$AZ7+(1-_xlpm.p)) -> 1.015 | BC7: =_xlfn.LET(_xlpm._custom_all_ammo,$BB7, _xlpm._all_ammo,IF(_xlpm._custom_all_ammo<>"",_xlpm._custom_all_ammo,$P7*$T7), IF(A7<>"",SUM($AR7:$AW7)*$BA7*_xlpm._all_ammo,"")) -> 586.67 | BF7: =_xlfn.LET(_xlpm._ammo,$T7, _xlpm._count_reload,IF($W7>0,_xlfn.CEILING.MATH(_xlpm._ammo/$W7),1), _xlpm._shoot_ticks,IF($BD7<>"",$BD7,($AL7*(_xlpm._ammo-1)+$AM7)*120/30), _xlpm._reload_ticks,IF($BE7<>"",$BE7,$Y7+$AB7*_xlpm._count_reload), (_xlpm._shoot_ticks+_xlpm._reload_ticks)/120 ) -> 8.1833333 | BG7: =BC7/BF7 -> 71.690835 | BH7: {=_xlfn.LAMBDA(_xlpm._dps,_xlpm._info_cell,ROUND(IF(_xlpm._dps<=0,-10,LOG(_xlpm._dps/INDEX(_xlfn.TEXTSPLIT(_xlpm._info_cell,"="),2),1.5)),2))($BG7,BH$3)} -> 1.99 | BI7: 2 | BJ7: 2 | BK7: {=_xlfn.LAMBDA(_xlpm._lv,_xlpm._rank,_xlpm._base,_xlpm._lv+INDEX(_xlfn.TEXTSPLIT(_xlpm._base,"="),2)^(_xlpm._rank-2)-1)(BI7,BJ7,BK$3)} -> 2 | BM7: =BK7*2-BH7-BL7 -> 2.01 | BN7: =(($T7-1)*$AL7+$AM7)/30 -> 3.5333333 | BO7: =(($T7-1)*($AL7+$AO7/4)+$AM7)/30 -> 5.9333333 | BP7: =$BC7/$BO7 -> 98.876966 | BQ7: =$AB7*$AD7*IF($W7<=0,1,$T7)/120 -> 3.4 | BR7: =BP7 -> 98.876966 | BS7: =$BC7/($BQ7+$BO7) -> 62.8575 | BT7: 1 | BU7: =_xlfn.LET(_xlpm._level_power,2,IF(BT7<>"",BR7/_xlpm._level_power^BT7,"")) -> 49.438483 | BV7: =_xlfn.LET(_xlpm._level_power,2,IF($BT7<>"",BR7/_xlpm._level_power^$BT7,"")) -> 49.438483
A8: 13201023 | B8: 军士长手枪 | C8: 设备 | D8: DScript_Shooter | E8: se_ag_shoot_gun | F8: se_ag_gun_reloaded | G8: 10002 | H8: =IF(G8<>"",IFERROR(VLOOKUP(G8,t_proj[#All],2,0),"--"),"") -> 手枪子弹 | I8: =_xlfn.TEXTJOIN("~",1,J8:K8) -> 85~0 | J8: 85 | K8: 0 | L8: =_xlfn.TEXTJOIN("~",1,M8:N8) -> 360~0 | M8: 360 | N8: 0 | P8: 1 | Q8: 4 | R8: =IF(Q8="","",1-Q8/20) -> 0.8 | S8: proj_muzzel | T8: 17 | U8: FALSE | W8: 1 | X8: =1/Y8 -> 0.0066666667 | Y8: 150 | Z8: =TEXT(Y8/120,"0.00")&" s" -> 1.25 s | AA8: =1/AB8 -> 0.055555556 | AB8: 18 | AC8: =TEXT(AB8/120,"0.00")&" s" -> 0.15 s | AD8: 1 | AE8: {=_xlfn.TEXTJOIN(";",1,IFERROR(1/AF8:AH8,""))} -> 0.00555555555555556;0.0416666666666667 | AF8: 180 | AG8: 24 | AI8: =AK8/AM8 -> 0.3 | AJ8: =AL8/AM8 -> 0.6 | AK8: 3 | AL8: 6 | AM8: 10 | AN8: =($AL8-$AK8)*120/30 -> 12 | AO8: 18 | AP8: =TEXT(AO8/120,"0.00")&" s" -> 0.15 s | AQ8: {=_xlfn.TEXTJOIN(";",1,_xlfn.LAMBDA(_xlpm.x,IF(_xlpm.x<>"",OFFSET(_xlpm.x,3-ROW(),0)&"="&_xlpm.x,""))(AR8:AW8))} -> sharp=45 | AR8: 45 | AX8: {=TEXT(VLOOKUP($A8,battle_data!$A:$G,MATCH(INDEX(_xlfn.TEXTSPLIT(AX$3,"|"),1),battle_data!$A$1:$G$1),0)*0.001,"0%")} -> 0% | AY8: {=TEXT(VLOOKUP($A8,battle_data!$A:$G,MATCH(INDEX(_xlfn.TEXTSPLIT(AY$3,"|"),1),battle_data!$A$1:$G$1),0)*0.001,"0%")} -> 3% | AZ8: {=TEXT(VLOOKUP($A8,battle_data!$A:$G,MATCH(INDEX(_xlfn.TEXTSPLIT(AZ$3,"|"),1),battle_data!$A$1:$G$1),0)*0.001,"0%")} -> 150% | BA8: =_xlfn.LET(_xlpm.p,($AY8),_xlpm.p*$AZ8+(1-_xlpm.p)) -> 1.015 | BC8: =_xlfn.LET(_xlpm._custom_all_ammo,$BB8, _xlpm._all_ammo,IF(_xlpm._custom_all_ammo<>"",_xlpm._custom_all_ammo,$P8*$T8), IF(A8<>"",SUM($AR8:$AW8)*$BA8*_xlpm._all_ammo,"")) -> 776.475 | BF8: =_xlfn.LET(_xlpm._ammo,$T8, _xlpm._count_reload,IF($W8>0,_xlfn.CEILING.MATH(_xlpm._ammo/$W8),1), _xlpm._shoot_ticks,IF($BD8<>"",$BD8,($AL8*(_xlpm._ammo-1)+$AM8)*120/30), _xlpm._reload_ticks,IF($BE8<>"",$BE8,$Y8+$AB8*_xlpm._count_reload), (_xlpm._shoot_ticks+_xlpm._reload_ticks)/120 ) -> 7.3333333 | BG8: =BC8/BF8 -> 105.88295 | BH8: {=_xlfn.LAMBDA(_xlpm._dps,_xlpm._info_cell,ROUND(IF(_xlpm._dps<=0,-10,LOG(_xlpm._dps/INDEX(_xlfn.TEXTSPLIT(_xlpm._info_cell,"="),2),1.5)),2))($BG8,BH$3)} -> 2.95 | BI8: 3 | BJ8: 2 | BK8: {=_xlfn.LAMBDA(_xlpm._lv,_xlpm._rank,_xlpm._base,_xlpm._lv+INDEX(_xlfn.TEXTSPLIT(_xlpm._base,"="),2)^(_xlpm._rank-2)-1)(BI8,BJ8,BK$3)} -> 3 | BM8: =BK8*2-BH8-BL8 -> 3.05 | BN8: =(($T8-1)*$AL8+$AM8)/30 -> 3.5333333 | BO8: =(($T8-1)*($AL8+$AO8/4)+$AM8)/30 -> 5.9333333 | BP8: =$BC8/$BO8 -> 130.86657 | BQ8: =$AB8*$AD8*IF($W8<=0,1,$T8)/120 -> 2.55 | BR8: =BP8 -> 130.86657 | BS8: =$BC8/($BQ8+$BO8) -> 91.52947 | BT8: 1 | BU8: =_xlfn.LET(_xlpm._level_power,2,IF(BT8<>"",BR8/_xlpm._level_power^BT8,"")) -> 65.433287 | BV8: =_xlfn.LET(_xlpm._level_power,2,IF($BT8<>"",BR8/_xlpm._level_power^$BT8,"")) -> 65.433287
A9: 13201029 | B9: 老舅的手枪 | C9: 设备 | D9: DScript_Shooter | E9: se_ag_shoot_gun | F9: se_ag_gun_reloaded | G9: 10002 | H9: =IF(G9<>"",IFERROR(VLOOKUP(G9,t_proj[#All],2,0),"--"),"") -> 手枪子弹 | I9: =_xlfn.TEXTJOIN("~",1,J9:K9) -> 65~85 | J9: 65 | K9: 85 | L9: =_xlfn.TEXTJOIN("~",1,M9:N9) -> 360~0 | M9: 360 | N9: 0 | P9: 1 | Q9: 8 | R9: =IF(Q9="","",1-Q9/20) -> 0.6 | S9: proj_muzzel | T9: 7 | U9: FALSE | W9: 1 | X9: =1/Y9 -> 0.0066666667 | Y9: 150 | Z9: =TEXT(Y9/120,"0.00")&" s" -> 1.25 s | AA9: =1/AB9 -> 0.033333333 | AB9: 30 | AC9: =TEXT(AB9/120,"0.00")&" s" -> 0.25 s | AD9: 1 | AE9: {=_xlfn.TEXTJOIN(";",1,IFERROR(1/AF9:AH9,""))} -> 0.00555555555555556;0.025 | AF9: 180 | AG9: 40 | AI9: =AK9/AM9 -> 0.3 | AJ9: =AL9/AM9 -> 0.6 | AK9: 3 | AL9: 6 | AM9: 10 | AN9: =($AL9-$AK9)*120/30 -> 12 | AO9: 24 | AP9: =TEXT(AO9/120,"0.00")&" s" -> 0.20 s | AQ9: {=_xlfn.TEXTJOIN(";",1,_xlfn.LAMBDA(_xlpm.x,IF(_xlpm.x<>"",OFFSET(_xlpm.x,3-ROW(),0)&"="&_xlpm.x,""))(AR9:AW9))} -> sharp=21 | AR9: 21 | AX9: {=TEXT(VLOOKUP($A9,battle_data!$A:$G,MATCH(INDEX(_xlfn.TEXTSPLIT(AX$3,"|"),1),battle_data!$A$1:$G$1),0)*0.001,"0%")} -> 0% | AY9: {=TEXT(VLOOKUP($A9,battle_data!$A:$G,MATCH(INDEX(_xlfn.TEXTSPLIT(AY$3,"|"),1),battle_data!$A$1:$G$1),0)*0.001,"0%")} -> 3% | AZ9: {=TEXT(VLOOKUP($A9,battle_data!$A:$G,MATCH(INDEX(_xlfn.TEXTSPLIT(AZ$3,"|"),1),battle_data!$A$1:$G$1),0)*0.001,"0%")} -> 150% | BA9: =_xlfn.LET(_xlpm.p,($AY9),_xlpm.p*$AZ9+(1-_xlpm.p)) -> 1.015 | BC9: =_xlfn.LET(_xlpm._custom_all_ammo,$BB9, _xlpm._all_ammo,IF(_xlpm._custom_all_ammo<>"",_xlpm._custom_all_ammo,$P9*$T9), IF(A9<>"",SUM($AR9:$AW9)*$BA9*_xlpm._all_ammo,"")) -> 149.205 | BF9: =_xlfn.LET(_xlpm._ammo,$T9, _xlpm._count_reload,IF($W9>0,_xlfn.CEILING.MATH(_xlpm._ammo/$W9),1), _xlpm._shoot_ticks,IF($BD9<>"",$BD9,($AL9*(_xlpm._ammo-1)+$AM9)*120/30), _xlpm._reload_ticks,IF($BE9<>"",$BE9,$Y9+$AB9*_xlpm._count_reload), (_xlpm._shoot_ticks+_xlpm._reload_ticks)/120 ) -> 4.5333333 | BG9: =BC9/BF9 -> 32.912868 | BH9: {=_xlfn.LAMBDA(_xlpm._dps,_xlpm._info_cell,ROUND(IF(_xlpm._dps<=0,-10,LOG(_xlpm._dps/INDEX(_xlfn.TEXTSPLIT(_xlpm._info_cell,"="),2),1.5)),2))($BG9,BH$3)} -> 0.07 | BI9: 0 | BJ9: 2 | BK9: {=_xlfn.LAMBDA(_xlpm._lv,_xlpm._rank,_xlpm._base,_xlpm._lv+INDEX(_xlfn.TEXTSPLIT(_xlpm._base,"="),2)^(_xlpm._rank-2)-1)(BI9,BJ9,BK$3)} -> 0 | BM9: =BK9*2-BH9-BL9 -> -0.07 | BN9: =(($T9-1)*$AL9+$AM9)/30 -> 1.5333333 | BO9: =(($T9-1)*($AL9+$AO9/4)+$AM9)/30 -> 2.7333333 | BP9: =$BC9/$BO9 -> 54.587195 | BQ9: =$AB9*$AD9*IF($W9<=0,1,$T9)/120 -> 1.75 | BR9: =BP9 -> 54.587195 | BS9: =$BC9/($BQ9+$BO9) -> 33.279926 | BT9: 1 | BU9: =_xlfn.LET(_xlpm._level_power,2,IF(BT9<>"",BR9/_xlpm._level_power^BT9,"")) -> 27.293598 | BV9: =_xlfn.LET(_xlpm._level_power,2,IF($BT9<>"",BR9/_xlpm._level_power^$BT9,"")) -> 27.293598
