Workbook
Name tuple_avg: _xlfn.LAMBDA(_xlpm.x,AVERAGE(VALUE(_xlfn.TEXTSPLIT(_xlpm.x,","))))

Sheet mg_weather
A1: id | B1: sub_id | I1: monster_id | L1: init_state | M1: pos | P1: pos_rnd_radius | Q1: count_max | R1: generate_count_area | U1: spawn_init | W1: spawn_threshold | Y1: k_time
A2: uint key | B2: uint key | I2: uint | L2: string | M2: Vector2 | P2: float | Q2: int | R2: Vector2? | U2: Vector2 | W2: Vector2 | Y2: float
A3: 怪物组id | B3: 组内子id | C3: 重复key校验列 | D3: 备注 世界 | E3: 备注 天气 | F3: 编号辅助 怪物# | G3: 编号辅助 怪物小组# | H3: 编号辅助 细分# | I3: 怪物id | J3: 备注 生成内容 | K3: 备注 生成位置 | L3: 初始状态 | M3: 出现位置 | N3: pos.x | O3: pos.y | P3: 位置 随机散布 | Q3: 最大数量 | R3: 每次生成数 min~max | S3: rnd min | T3: rnd max | U3: 初始进度 仅在进入场景时随机取值一次 | V3: 特殊值? | W3: 生成所需进度 进入场景时随机取值一次；每次生成怪物后重新随机取值。 | X3: 特殊值? | Y3: 生成速率 时间系数
A5: 460703 | B5: {=F5&_xlfn.TEXTJOIN("",1,TEXT(G5:H5,"00"))} -> 10100 | C5: =_xlfn.TEXTJOIN(",",1,A5:B5) -> 460703,10100 | D5: 荒漠 | E5: 流沙区 | F5: 1 | G5: 1 | H5: 0 | I5: 201702 | J5: =IFERROR(VLOOKUP(I5,monsters[#All],4,0),"") -> 沙漠蛇 | K5: {=_xlfn.LET(_xlpm.v6p,ABS(ATAN2(N5,O5))*6/PI(), _xlpm.output,_xlfn.IFS(_xlpm.v6p<1,"正前",_xlpm.v6p>5,"正后",AND(_xlpm.v6p<5,_xlpm.v6p>2,O5<-1),"脚底",_xlpm.v6p>4,"后上",_xlpm.v6p<2,"前上",TRUE,"顶部"), IFERROR(_xlpm.output,""))} -> 正前 | L5: Default | M5: =N5+0&","&O5+0 -> 12,-2 | N5: 12 | O5: -2 | P5: =IF(R5<>"",1,"") -> 1 | Q5: 10 | R5: =IF(S5<>"", S5+0&","&T5+0,"") -> 1,3 | S5: 1 | T5: 3 | U5: =IF($A5<>"",IF($V5<>"",$V5,"0,0"),"") -> 0,45 | V5: 0,45 | W5: =IF($A5<>"",IF($X5<>"",$X5,"80,120"),"") -> 50,150 | X5: 50,150 | Y5: 1
A6: 460703 | B6: {=F6&_xlfn.TEXTJOIN("",1,TEXT(G6:H6,"00"))} -> 10200 | C6: =_xlfn.TEXTJOIN(",",1,A6:B6) -> 460703,10200 | D6: 荒漠 | E6: 流沙区 | F6: 1 | G6: 2 | H6: 0 | I6: 201702 | J6: =IFERROR(VLOOKUP(I6,monsters[#All],4,0),"") -> 沙漠蛇 | K6: {=_xlfn.LET(_xlpm.v6p,ABS(ATAN2(N6,O6))*6/PI(), _xlpm.output,_xlfn.IFS(_xlpm.v6p<1,"正前",_xlpm.v6p>5,"正后",AND(_xlpm.v6p<5,_xlpm.v6p>2,O6<-1),"脚底",_xlpm.v6p>4,"后上",_xlpm.v6p<2,"前上",TRUE,"顶部"), IFERROR(_xlpm.output,""))} -> 正前 | L6: Default | M6: =N6+0&","&O6+0 -> 6,-2 | N6: 6 | O6: -2 | P6: =IF(R6<>"",1,"") -> 1 | Q6: 10 | R6: =IF(S6<>"", S6+0&","&T6+0,"") -> 1,3 | S6: 1 | T6: 3 | U6: =IF($A6<>"",IF($V6<>"",$V6,"0,0"),"") -> 0,45 | V6: 0,45 | W6: =IF($A6<>"",IF($X6<>"",$X6,"80,120"),"") -> 50,150 | X6: 50,150 | Y6: 0.85
A7: 460703 | B7: {=F7&_xlfn.TEXTJOIN("",1,TEXT(G7:H7,"00"))} -> 10300 | C7: =_xlfn.TEXTJOIN(",",1,A7:B7) -> 460703,10300 | D7: 荒漠 | E7: 流沙区 | F7: 1 | G7: 3 | H7: 0 | I7: 201702 | J7: =IFERROR(VLOOKUP(I7,monsters[#All],4,0),"") -> 沙漠蛇 | K7: {=_xlfn.LET(_xlpm.v6p,ABS(ATAN2(N7,O7))*6/PI(), _xlpm.output,_xlfn.IFS(_xlpm.v6p<1,"正前",_xlpm.v6p>5,"正后",AND(_xlpm.v6p<5,_xlpm.v6p>2,O7<-1),"脚底",_xlpm.v6p>4,"后上",_xlpm.v6p<2,"前上",TRUE,"顶部"), IFERROR(_xlpm.output,""))} -> 脚底 | L7: Default | M7: =N7+0&","&O7+0 -> 1,-2 | N7: 1 | O7: -2 | P7: =IF(R7<>"",1,"") -> 1 | Q7: 10 | R7: =IF(S7<>"", S7+0&","&T7+0,"") -> 1,3 | S7: 1 | T7: 3 | U7: =IF($A7<>"",IF($V7<>"",$V7,"0,0"),"") -> 60,75 | V7: 60,75 | W7: =IF($A7<>"",IF($X7<>"",$X7,"80,120"),"") -> 80,120 | Y7: 0.7
A8: 460703 | B8: {=F8&_xlfn.TEXTJOIN("",1,TEXT(G8:H8,"00"))} -> 10400 | C8: =_xlfn.TEXTJOIN(",",1,A8:B8) -> 460703,10400 | D8: 荒漠 | E8: 流沙区 | F8: 1 | G8: 4 | H8: 0 | I8: 201702 | J8: =IFERROR(VLOOKUP(I8,monsters[#All],4,0),"") -> 沙漠蛇 | K8: {=_xlfn.LET(_xlpm.v6p,ABS(ATAN2(N8,O8))*6/PI(), _xlpm.output,_xlfn.IFS(_xlpm.v6p<1,"正前",_xlpm.v6p>5,"正后",AND(_xlpm.v6p<5,_xlpm.v6p>2,O8<-1),"脚底",_xlpm.v6p>4,"后上",_xlpm.v6p<2,"前上",TRUE,"顶部"), IFERROR(_xlpm.output,""))} -> 脚底 | L8: Default | M8: =N8+0&","&O8+0 -> -3,-2 | N8: -3 | O8: -2 | P8: =IF(R8<>"",1,"") -> 1 | Q8: 10 | R8: =IF(S8<>"", S8+0&","&T8+0,"") -> 1,3 | S8: 1 | T8: 3 | U8: =IF($A8<>"",IF($V8<>"",$V8,"0,0"),"") -> 0,45 | V8: 0,45 | W8: =IF($A8<>"",IF($X8<>"",$X8,"80,120"),"") -> 50,150 | X8: 50,150 | Y8: 0.55
A9: 460703 | B9: {=F9&_xlfn.TEXTJOIN("",1,TEXT(G9:H9,"00"))} -> 10500 | C9: =_xlfn.TEXTJOIN(",",1,A9:B9) -> 460703,10500 | D9: 荒漠 | E9: 流沙区 | F9: 1 | G9: 5 | H9: 0 | I9: 201702 | J9: =IFERROR(VLOOKUP(I9,monsters[#All],4,0),"") -> 沙漠蛇 | K9: {=_xlfn.LET(_xlpm.v6p,ABS(ATAN2(N9,O9))*6/PI(), _xlpm.output,_xlfn.IFS(_xlpm.v6p<1,"正前",_xlpm.v6p>5,"正后",AND(_xlpm.v6p<5,_xlpm.v6p>2,O9<-1),"脚底",_xlpm.v6p>4,"后上",_xlpm.v6p<2,"前上",TRUE,"顶部"), IFERROR(_xlpm.output,""))} -> 正后 | L9: Default | M9: =N9+0&","&O9+0 -> -8,-2 | N9: -8 | O9: -2 | P9: =IF(R9<>"",1,"") -> 1 | Q9: 10 | R9: =IF(S9<>"", S9+0&","&T9+0,"") -> 1,3 | S9: 1 | T9: 3 | U9: =IF($A9<>"",IF($V9<>"",$V9,"0,0"),"") -> 0,45 | V9: 0,45 | W9: =IF($A9<>"",IF($X9<>"",$X9,"80,120"),"") -> 50,150 | X9: 50,150 | Y9: 0.4
A11: 460704 | B11: {=F11&_xlfn.TEXTJOIN("",1,TEXT(G11:H11,"00"))} -> 10100 | C11: =_xlfn.TEXTJOIN(",",1,A11:B11) -> 460704,10100 | D11: 荒漠 | E11: 流沙区+扬尘 | F11: 1 | G11: 1 | H11: 0 | I11: 201702 | J11: =IFERROR(VLOOKUP(I11,monsters[#All],4,0),"") -> 沙漠蛇 | K11: {=_xlfn.LET(_xlpm.v6p,ABS(ATAN2(N11,O11))*6/PI(), _xlpm.output,_xlfn.IFS(_xlpm.v6p<1,"正前",_xlpm.v6p>5,"正后",AND(_xlpm.v6p<5,_xlpm.v6p>2,O11<-1),"脚底",_xlpm.v6p>4,"后上",_xlpm.v6p<2,"前上",TRUE,"顶部"), IFERROR(_xlpm.output,""))} -> 正前 | L11: Default | M11: =N11+0&","&O11+0 -> 12,-2 | N11: 12 | O11: -2 | P11: =IF(R11<>"",1,"") -> 1 | Q11: 10 | R11: =IF(S11<>"", S11+0&","&T11+0,"") -> 1,3 | S11: 1 | T11: 3 | U11: =IF($A11<>"",IF($V11<>"",$V11,"0,0"),"") -> 0,45 | V11: 0,45 | W11: =IF($A11<>"",IF($X11<>"",$X11,"80,120"),"") -> 50,150 | X11: 50,150 | Y11: 1
A12: 460704 | B12: {=F12&_xlfn.TEXTJOIN("",1,TEXT(G12:H12,"00"))} -> 10200 | C12: =_xlfn.TEXTJOIN(",",1,A12:B12) -> 460704,10200 | D12: 荒漠 | E12: 流沙区+扬尘 | F12: 1 | G12: 2 | H12: 0 | I12: 201702 | J12: =IFERROR(VLOOKUP(I12,monsters[#All],4,0),"") -> 沙漠蛇 | K12: {=_xlfn.LET(_xlpm.v6p,ABS(ATAN2(N12,O12))*6/PI(), _xlpm.output,_xlfn.IFS(_xlpm.v6p<1,"正前",_xlpm.v6p>5,"正后",AND(_xlpm.v6p<5,_xlpm.v6p>2,O12<-1),"脚底",_xlpm.v6p>4,"后上",_xlpm.v6p<2,"前上",TRUE,"顶部"), IFERROR(_xlpm.output,""))} -> 正前 | L12: Default | M12: =N12+0&","&O12+0 -> 6,-2 | N12: 6 | O12: -2 | P12: =IF(R12<>"",1,"") -> 1 | Q12: 10 | R12: =IF(S12<>"", S12+0&","&T12+0,"") -> 1,3 | S12: 1 | T12: 3 | U12: =IF($A12<>"",IF($V12<>"",$V12,"0,0"),"") -> 0,45 | V12: 0,45 | W12: =IF($A12<>"",IF($X12<>"",$X12,"80,120"),"") -> 50,150 | X12: 50,150 | Y12: 0.85
A13: 460704 | B13: {=F13&_xlfn.TEXTJOIN("",1,TEXT(G13:H13,"00"))} -> 10300 | C13: =_xlfn.TEXTJOIN(",",1,A13:B13) -> 460704,10300 | D13: 荒漠 | E13: 流沙区+扬尘 | F13: 1 | G13: 3 | H13: 0 | I13: 201702 | J13: =IFERROR(VLOOKUP(I13,monsters[#All],4,0),"") -> 沙漠蛇 | K13: {=_xlfn.LET(_xlpm.v6p,ABS(ATAN2(N13,O13))*6/PI(), _xlpm.output,_xlfn.IFS(_xlpm.v6p<1,"正前",_xlpm.v6p>5,"正后",AND(_xlpm.v6p<5,_xlpm.v6p>2,O13<-1),"脚底",_xlpm.v6p>4,"后上",_xlpm.v6p<2,"前上",TRUE,"顶部"), IFERROR(_xlpm.output,""))} -> 脚底 | L13: Default | M13: =N13+0&","&O13+0 -> 1,-2 | N13: 1 | O13: -2 | P13: =IF(R13<>"",1,"") -> 1 | Q13: 10 | R13: =IF(S13<>"", S13+0&","&T13+0,"") -> 1,3 | S13: 1 | T13: 3 | U13: =IF($A13<>"",IF($V13<>"",$V13,"0,0"),"") -> 60,75 | V13: 60,75 | W13: =IF($A13<>"",IF($X13<>"",$X13,"80,120"),"") -> 80,120 | Y13: 0.7
A14: 460704 | B14: {=F14&_xlfn.TEXTJOIN("",1,TEXT(G14:H14,"00"))} -> 10400 | C14: =_xlfn.TEXTJOIN(",",1,A14:B14) -> 460704,10400 | D14: 荒漠 | E14: 流沙区+扬尘 | F14: 1 | G14: 4 | H14: 0 | I14: 201702 | J14: =IFERROR(VLOOKUP(I14,monsters[#All],4,0),"") -> 沙漠蛇 | K14: {=_xlfn.LET(_xlpm.v6p,ABS(ATAN2(N14,O14))*6/PI(), _xlpm.output,_xlfn.IFS(_xlpm.v6p<1,"正前",_xlpm.v6p>5,"正后",AND(_xlpm.v6p<5,_xlpm.v6p>2,O14<-1),"脚底",_xlpm.v6p>4,"后上",_xlpm.v6p<2,"前上",TRUE,"顶部"), IFERROR(_xlpm.output,""))} -> 脚底 | L14: Default | M14: =N14+0&","&O14+0 -> -3,-2 | N14: -3 | O14: -2 | P14: =IF(R14<>"",1,"") -> 1 | Q14: 10 | R14: =IF(S14<>"", S14+0&","&T14+0,"") -> 1,3 | S14: 1 | T14: 3 | U14: =IF($A14<>"",IF($V14<>"",$V14,"0,0"),"") -> 0,45 | V14: 0,45 | W14: =IF($A14<>"",IF($X14<>"",$X14,"80,120"),"") -> 50,150 | X14: 50,150 | Y14: 0.55
A15: 460704 | B15: {=F15&_xlfn.TEXTJOIN("",1,TEXT(G15:H15,"00"))} -> 10500 | C15: =_xlfn.TEXTJOIN(",",1,A15:B15) -> 460704,10500 | D15: 荒漠 | E15: 流沙区+扬尘 | F15: 1 | G15: 5 | H15: 0 | I15: 201702 | J15: =IFERROR(VLOOKUP(I15,monsters[#All],4,0),"") -> 沙漠蛇 | K15: {=_xlfn.LET(_xlpm.v6p,ABS(ATAN2(N15,O15))*6/PI(), _xlpm.output,_xlfn.IFS(_xlpm.v6p<1,"正前",_xlpm.v6p>5,"正后",AND(_xlpm.v6p<5,_xlpm.v6p>2,O15<-1),"脚底",_xlpm.v6p>4,"后上",_xlpm.v6p<2,"前上",TRUE,"顶部"), IFERROR(_xlpm.output,""))} -> 正后 | L15: Default | M15: =N15+0&","&O15+0 -> -8,-2 | N15: -8 | O15: -2 | P15: =IF(R15<>"",1,"") -> 1 | Q15: 10 | R15: =IF(S15<>"", S15+0&","&T15+0,"") -> 1,3 | S15: 1 | T15: 3 | U15: =IF($A15<>"",IF($V15<>"",$V15,"0,0"),"") -> 0,45 | V15: 0,45 | W15: =IF($A15<>"",IF($X15<>"",$X15,"80,120"),"") -> 50,150 | X15: 50,150 | Y15: 0.4
A17: 460705 | B17: {=F17&_xlfn.TEXTJOIN("",1,TEXT(G17:H17,"00"))} -> 10100 | C17: =_xlfn.TEXTJOIN(",",1,A17:B17) -> 460705,10100 | D17: 荒漠 | E17: 流沙区+沙暴 | F17: 1 | G17: 1 | H17: 0 | I17: 201702 | J17: =IFERROR(VLOOKUP(I17,monsters[#All],4,0),"") -> 沙漠蛇 | K17: {=_xlfn.LET(_xlpm.v6p,ABS(ATAN2(N17,O17))*6/PI(), _xlpm.output,_xlfn.IFS(_xlpm.v6p<1,"正前",_xlpm.v6p>5,"正后",AND(_xlpm.v6p<5,_xlpm.v6p>2,O17<-1),"脚底",_xlpm.v6p>4,"后上",_xlpm.v6p<2,"前上",TRUE,"顶部"), IFERROR(_xlpm.output,""))} -> 正前 | L17: Default | M17: =N17+0&","&O17+0 -> 12,-2 | N17: 12 | O17: -2 | P17: =IF(R17<>"",1,"") -> 1 | Q17: 10 | R17: =IF(S17<>"", S17+0&","&T17+0,"") -> 1,3 | S17: 1 | T17: 3 | U17: =IF($A17<>"",IF($V17<>"",$V17,"0,0"),"") -> 0,45 | V17: 0,45 | W17: =IF($A17<>"",IF($X17<>"",$X17,"80,120"),"") -> 50,150 | X17: 50,150 | Y17: 1
A18: 460705 | B18: {=F18&_xlfn.TEXTJOIN("",1,TEXT(G18:H18,"00"))} -> 10200 | C18: =_xlfn.TEXTJOIN(",",1,A18:B18) -> 460705,10200 | D18: 荒漠 | E18: 流沙区+沙暴 | F18: 1 | G18: 2 | H18: 0 | I18: 201702 | J18: =IFERROR(VLOOKUP(I18,monsters[#All],4,0),"") -> 沙漠蛇 | K18: {=_xlfn.LET(_xlpm.v6p,ABS(ATAN2(N18,O18))*6/PI(), _xlpm.output,_xlfn.IFS(_xlpm.v6p<1,"正前",_xlpm.v6p>5,"正后",AND(_xlpm.v6p<5,_xlpm.v6p>2,O18<-1),"脚底",_xlpm.v6p>4,"后上",_xlpm.v6p<2,"前上",TRUE,"顶部"), IFERROR(_xlpm.output,""))} -> 正前 | L18: Default | M18: =N18+0&","&O18+0 -> 6,-2 | N18: 6 | O18: -2 | P18: =IF(R18<>"",1,"") -> 1 | Q18: 10 | R18: =IF(S18<>"", S18+0&","&T18+0,"") -> 1,3 | S18: 1 | T18: 3 | U18: =IF($A18<>"",IF($V18<>"",$V18,"0,0"),"") -> 0,45 | V18: 0,45 | W18: =IF($A18<>"",IF($X18<>"",$X18,"80,120"),"") -> 50,150 | X18: 50,150 | Y18: 0.85
A19: 460705 | B19: {=F19&_xlfn.TEXTJOIN("",1,TEXT(G19:H19,"00"))} -> 10300 | C19: =_xlfn.TEXTJOIN(",",1,A19:B19) -> 460705,10300 | D19: 荒漠 | E19: 流沙区+沙暴 | F19: 1 | G19: 3 | H19: 0 | I19: 201702 | J19: =IFERROR(VLOOKUP(I19,monsters[#All],4,0),"") -> 沙漠蛇 | K19: {=_xlfn.LET(_xlpm.v6p,ABS(ATAN2(N19,O19))*6/PI(), _xlpm.output,_xlfn.IFS(_xlpm.v6p<1,"正前",_xlpm.v6p>5,"正后",AND(_xlpm.v6p<5,_xlpm.v6p>2,O19<-1),"脚底",_xlpm.v6p>4,"后上",_xlpm.v6p<2,"前上",TRUE,"顶部"), IFERROR(_xlpm.output,""))} -> 脚底 | L19: Default | M19: =N19+0&","&O19+0 -> 1,-2 | N19: 1 | O19: -2 | P19: =IF(R19<>"",1,"") -> 1 | Q19: 10 | R19: =IF(S19<>"", S19+0&","&T19+0,"") -> 1,3 | S19: 1 | T19: 3 | U19: =IF($A19<>"",IF($V19<>"",$V19,"0,0"),"") -> 60,75 | V19: 60,75 | W19: =IF($A19<>"",IF($X19<>"",$X19,"80,120"),"") -> 80,120 | Y19: 0.7
A20: 460705 | B20: {=F20&_xlfn.TEXTJOIN("",1,TEXT(G20:H20,"00"))} -> 10400 | C20: =_xlfn.TEXTJOIN(",",1,A20:B20) -> 460705,10400 | D20: 荒漠 | E20: 流沙区+沙暴 | F20: 1 | G20: 4 | H20: 0 | I20: 201702 | J20: =IFERROR(VLOOKUP(I20,monsters[#All],4,0),"") -> 沙漠蛇 | K20: {=_xlfn.LET(_xlpm.v6p,ABS(ATAN2(N20,O20))*6/PI(), _xlpm.output,_xlfn.IFS(_xlpm.v6p<1,"正前",_xlpm.v6p>5,"正后",AND(_xlpm.v6p<5,_xlpm.v6p>2,O20<-1),"脚底",_xlpm.v6p>4,"后上",_xlpm.v6p<2,"前上",TRUE,"顶部"), IFERROR(_xlpm.output,""))} -> 脚底 | L20: Default | M20: =N20+0&","&O20+0 -> -3,-2 | N20: -3 | O20: -2 | P20: =IF(R20<>"",1,"") -> 1 | Q20: 10 | R20: =IF(S20<>"", S20+0&","&T20+0,"") -> 1,3 | S20: 1 | T20: 3 | U20: =IF($A20<>"",IF($V20<>"",$V20,"0,0"),"") -> 0,45 | V20: 0,45 | W20: =IF($A20<>"",IF($X20<>"",$X20,"80,120"),"") -> 50,150 | X20: 50,150 | Y20: 0.55
A21: 460705 | B21: {=F21&_xlfn.TEXTJOIN("",1,TEXT(G21:H21,"00"))} -> 10500 | C21: =_xlfn.TEXTJOIN(",",1,A21:B21) -> 460705,10500 | D21: 荒漠 | E21: 流沙区+沙暴 | F21: 1 | G21: 5 | H21: 0 | I21: 201702 | J21: =IFERROR(VLOOKUP(I21,monsters[#All],4,0),"") -> 沙漠蛇 | K21: {=_xlfn.LET(_xlpm.v6p,ABS(ATAN2(N21,O21))*6/PI(), _xlpm.output,_xlfn.IFS(_xlpm.v6p<1,"正前",_xlpm.v6p>5,"正后",AND(_xlpm.v6p<5,_xlpm.v6p>2,O21<-1),"脚底",_xlpm.v6p>4,"后上",_xlpm.v6p<2,"前上",TRUE,"顶部"), IFERROR(_xlpm.output,""))} -> 正后 | L21: Default | M21: =N21+0&","&O21+0 -> -8,-2 | N21: -8 | O21: -2 | P21: =IF(R21<>"",1,"") -> 1 | Q21: 10 | R21: =IF(S21<>"", S21+0&","&T21+0,"") -> 1,3 | S21: 1 | T21: 3 | U21: =IF($A21<>"",IF($V21<>"",$V21,"0,0"),"") -> 0,45 | V21: 0,45 | W21: =IF($A21<>"",IF($X21<>"",$X21,"80,120"),"") -> 50,150 | X21: 50,150 | Y21: 0.4
A25: 460803 | B25: {=F25&_xlfn.TEXTJOIN("",1,TEXT(G25:H25,"00"))} -> 10100 | C25: =_xlfn.TEXTJOIN(",",1,A25:B25) -> 460803,10100 | D25: 大湖 | E25: 暴雨 | F25: 1 | G25: 1 | H25: 0 | I25: 201814 | J25: =IFERROR(VLOOKUP(I25,monsters[#All],4,0),"") -> 弱小螃蟹 | K25: {=_xlfn.LET(_xlpm.v6p,ABS(ATAN2(N25,O25))*6/PI(), _xlpm.output,_xlfn.IFS(_xlpm.v6p<1,"正前",_xlpm.v6p>5,"正后",AND(_xlpm.v6p<5,_xlpm.v6p>2,O25<-1),"脚底",_xlpm.v6p>4,"后上",_xlpm.v6p<2,"前上",TRUE,"顶部"), IFERROR(_xlpm.output,""))} -> 前上 | L25: Default | M25: =N25+0&","&O25+0 -> 12,15 | N25: 12 | O25: 15 | P25: =IF(R25<>"",1,"") -> 1 | Q25: 10 | R25: =IF(S25<>"", S25+0&","&T25+0,"") -> 1,3 | S25: 1 | T25: 3 | U25: =IF($A25<>"",IF($V25<>"",$V25,"0,0"),"") -> 0,45 | V25: 0,45 | W25: =IF($A25<>"",IF($X25<>"",$X25,"80,120"),"") -> 50,150 | X25: 50,150 | Y25: 1
A26: 460803 | B26: {=F26&_xlfn.TEXTJOIN("",1,TEXT(G26:H26,"00"))} -> 10200 | C26: =_xlfn.TEXTJOIN(",",1,A26:B26) -> 460803,10200 | D26: 大湖 | E26: 暴雨 | F26: 1 | G26: 2 | H26: 0 | I26: 201814 | J26: =IFERROR(VLOOKUP(I26,monsters[#All],4,0),"") -> 弱小螃蟹 | K26: {=_xlfn.LET(_xlpm.v6p,ABS(ATAN2(N26,O26))*6/PI(), _xlpm.output,_xlfn.IFS(_xlpm.v6p<1,"正前",_xlpm.v6p>5,"正后",AND(_xlpm.v6p<5,_xlpm.v6p>2,O26<-1),"脚底",_xlpm.v6p>4,"后上",_xlpm.v6p<2,"前上",TRUE,"顶部"), IFERROR(_xlpm.output,""))} -> 顶部 | L26: Default | M26: =N26+0&","&O26+0 -> 6,15 | N26: 6 | O26: 15 | P26: =IF(R26<>"",1,"") -> 1 | Q26: 10 | R26: =IF(S26<>"", S26+0&","&T26+0,"") -> 1,3 | S26: 1 | T26: 3 | U26: =IF($A26<>"",IF($V26<>"",$V26,"0,0"),"") -> 0,45 | V26: 0,45 | W26: =IF($A26<>"",IF($X26<>"",$X26,"80,120"),"") -> 50,150 | X26: 50,150 | Y26: 0.85
A27: 460803 | B27: {=F27&_xlfn.TEXTJOIN("",1,TEXT(G27:H27,"00"))} -> 10300 | C27: =_xlfn.TEXTJOIN(",",1,A27:B27) -> 460803,10300 | D27: 大湖 | E27: 暴雨 | F27: 1 | G27: 3 | H27: 0 | I27: 201814 | J27: =IFERROR(VLOOKUP(I27,monsters[#All],4,0),"") -> 弱小螃蟹 | K27: {=_xlfn.LET(_xlpm.v6p,ABS(ATAN2(N27,O27))*6/PI(), _xlpm.output,_xlfn.IFS(_xlpm.v6p<1,"正前",_xlpm.v6p>5,"正后",AND(_xlpm.v6p<5,_xlpm.v6p>2,O27<-1),"脚底",_xlpm.v6p>4,"后上",_xlpm.v6p<2,"前上",TRUE,"顶部"), IFERROR(_xlpm.output,""))} -> 顶部 | L27: Default | M27: =N27+0&","&O27+0 -> 1,15 | N27: 1 | O27: 15 | P27: =IF(R27<>"",1,"") -> 1 | Q27: 10 | R27: =IF(S27<>"", S27+0&","&T27+0,"") -> 1,3 | S27: 1 | T27: 3 | U27: =IF($A27<>"",IF($V27<>"",$V27,"0,0"),"") -> 60,75 | V27: 60,75 | W27: =IF($A27<>"",IF($X27<>"",$X27,"80,120"),"") -> 80,120 | Y27: 0.7
A28: 460803 | B28: {=F28&_xlfn.TEXTJOIN("",1,TEXT(G28:H28,"00"))} -> 10400 | C28: =_xlfn.TEXTJOIN(",",1,A28:B28) -> 460803,10400 | D28: 大湖 | E28: 暴雨 | F28: 1 | G28: 4 | H28: 0 | I28: 201814 | J28: =IFERROR(VLOOKUP(I28,monsters[#All],4,0),"") -> 弱小螃蟹 | K28: {=_xlfn.LET(_xlpm.v6p,ABS(ATAN2(N28,O28))*6/PI(), _xlpm.output,_xlfn.IFS(_xlpm.v6p<1,"正前",_xlpm.v6p>5,"正后",AND(_xlpm.v6p<5,_xlpm.v6p>2,O28<-1),"脚底",_xlpm.v6p>4,"后上",_xlpm.v6p<2,"前上",TRUE,"顶部"), IFERROR(_xlpm.output,""))} -> 顶部 | L28: Default | M28: =N28+0&","&O28+0 -> -3,15 | N28: -3 | O28: 15 | P28: =IF(R28<>"",1,"") -> 1 | Q28: 10 | R28: =IF(S28<>"", S28+0&","&T28+0,"") -> 1,3 | S28: 1 | T28: 3 | U28: =IF($A28<>"",IF($V28<>"",$V28,"0,0"),"") -> 0,45 | V28: 0,45 | W28: =IF($A28<>"",IF($X28<>"",$X28,"80,120"),"") -> 50,150 | X28: 50,150 | Y28: 0.55
A29: 460803 | B29: {=F29&_xlfn.TEXTJOIN("",1,TEXT(G29:H29,"00"))} -> 10500 | C29: =_xlfn.TEXTJOIN(",",1,A29:B29) -> 460803,10500 | D29: 大湖 | E29: 暴雨 | F29: 1 | G29: 5 | H29: 0 | I29: 201814 | J29: =IFERROR(VLOOKUP(I29,monsters[#All],4,0),"") -> 弱小螃蟹 | K29: {=_xlfn.LET(_xlpm.v6p,ABS(ATAN2(N29,O29))*6/PI(), _xlpm.output,_xlfn.IFS(_xlpm.v6p<1,"正前",_xlpm.v6p>5,"正后",AND(_xlpm.v6p<5,_xlpm.v6p>2,O29<-1),"脚底",_xlpm.v6p>4,"后上",_xlpm.v6p<2,"前上",TRUE,"顶部"), IFERROR(_xlpm.output,""))} -> 顶部 | L29: Default | M29: =N29+0&","&O29+0 -> -8,15 | N29: -8 | O29: 15 | P29: =IF(R29<>"",1,"") -> 1 | Q29: 10 | R29: =IF(S29<>"", S29+0&","&T29+0,"") -> 1,3 | S29: 1 | T29: 3 | U29: =IF($A29<>"",IF($V29<>"",$V29,"0,0"),"") -> 0,45 | V29: 0,45 | W29: =IF($A29<>"",IF($X29<>"",$X29,"80,120"),"") -> 50,150 | X29: 50,150 | Y29: 0.4
A31: 460804 | B31: {=F31&_xlfn.TEXTJOIN("",1,TEXT(G31:H31,"00"))} -> 10100 | C31: =_xlfn.TEXTJOIN(",",1,A31:B31) -> 460804,10100 | D31: 大湖 | E31: 雷暴 | F31: 1 | G31: 1 | H31: 0 | I31: 201814 | J31: =IFERROR(VLOOKUP(I31,monsters[#All],4,0),"") -> 弱小螃蟹 | K31: {=_xlfn.LET(_xlpm.v6p,ABS(ATAN2(N31,O31))*6/PI(), _xlpm.output,_xlfn.IFS(_xlpm.v6p<1,"正前",_xlpm.v6p>5,"正后",AND(_xlpm.v6p<5,_xlpm.v6p>2,O31<-1),"脚底",_xlpm.v6p>4,"后上",_xlpm.v6p<2,"前上",TRUE,"顶部"), IFERROR(_xlpm.output,""))} -> 前上 | L31: Default | M31: =N31+0&","&O31+0 -> 12,15 | N31: 12 | O31: 15 | P31: =IF(R31<>"",1,"") -> 1 | Q31: 10 | R31: =IF(S31<>"", S31+0&","&T31+0,"") -> 1,3 | S31: 1 | T31: 3 | U31: =IF($A31<>"",IF($V31<>"",$V31,"0,0"),"") -> 0,45 | V31: 0,45 | W31: =IF($A31<>"",IF($X31<>"",$X31,"80,120"),"") -> 50,150 | X31: 50,150 | Y31: 1.5
A32: 460804 | B32: {=F32&_xlfn.TEXTJOIN("",1,TEXT(G32:H32,"00"))} -> 10200 | C32: =_xlfn.TEXTJOIN(",",1,A32:B32) -> 460804,10200 | D32: 大湖 | E32: 雷暴 | F32: 1 | G32: 2 | H32: 0 | I32: 201814 | J32: =IFERROR(VLOOKUP(I32,monsters[#All],4,0),"") -> 弱小螃蟹 | K32: {=_xlfn.LET(_xlpm.v6p,ABS(ATAN2(N32,O32))*6/PI(), _xlpm.output,_xlfn.IFS(_xlpm.v6p<1,"正前",_xlpm.v6p>5,"正后",AND(_xlpm.v6p<5,_xlpm.v6p>2,O32<-1),"脚底",_xlpm.v6p>4,"后上",_xlpm.v6p<2,"前上",TRUE,"顶部"), IFERROR(_xlpm.output,""))} -> 顶部 | L32: Default | M32: =N32+0&","&O32+0 -> 6,15 | N32: 6 | O32: 15 | P32: =IF(R32<>"",1,"") -> 1 | Q32: 10 | R32: =IF(S32<>"", S32+0&","&T32+0,"") -> 1,3 | S32: 1 | T32: 3 | U32: =IF($A32<>"",IF($V32<>"",$V32,"0,0"),"") -> 0,45 | V32: 0,45 | W32: =IF($A32<>"",IF($X32<>"",$X32,"80,120"),"") -> 50,150 | X32: 50,150 | Y32: 1.25
A33: 460804 | B33: {=F33&_xlfn.TEXTJOIN("",1,TEXT(G33:H33,"00"))} -> 10300 | C33: =_xlfn.TEXTJOIN(",",1,A33:B33) -> 460804,10300 | D33: 大湖 | E33: 雷暴 | F33: 1 | G33: 3 | H33: 0 | I33: 201814 | J33: =IFERROR(VLOOKUP(I33,monsters[#All],4,0),"") -> 弱小螃蟹 | K33: {=_xlfn.LET(_xlpm.v6p,ABS(ATAN2(N33,O33))*6/PI(), _xlpm.output,_xlfn.IFS(_xlpm.v6p<1,"正前",_xlpm.v6p>5,"正后",AND(_xlpm.v6p<5,_xlpm.v6p>2,O33<-1),"脚底",_xlpm.v6p>4,"后上",_xlpm.v6p<2,"前上",TRUE,"顶部"), IFERROR(_xlpm.output,""))} -> 顶部 | L33: Default | M33: =N33+0&","&O33+0 -> 1,15 | N33: 1 | O33: 15 | P33: =IF(R33<>"",1,"") -> 1 | Q33: 10 | R33: =IF(S33<>"", S33+0&","&T33+0,"") -> 1,3 | S33: 1 | T33: 3 | U33: =IF($A33<>"",IF($V33<>"",$V33,"0,0"),"") -> 60,75 | V33: 60,75 | W33: =IF($A33<>"",IF($X33<>"",$X33,"80,120"),"") -> 80,120 | Y33: 1
A34: 460804 | B34: {=F34&_xlfn.TEXTJOIN("",1,TEXT(G34:H34,"00"))} -> 10400 | C34: =_xlfn.TEXTJOIN(",",1,A34:B34) -> 460804,10400 | D34: 大湖 | E34: 雷暴 | F34: 1 | G34: 4 | H34: 0 | I34: 201814 | J34: =IFERROR(VLOOKUP(I34,monsters[#All],4,0),"") -> 弱小螃蟹 | K34: {=_xlfn.LET(_xlpm.v6p,ABS(ATAN2(N34,O34))*6/PI(), _xlpm.output,_xlfn.IFS(_xlpm.v6p<1,"正前",_xlpm.v6p>5,"正后",AND(_xlpm.v6p<5,_xlpm.v6p>2,O34<-1),"脚底",_xlpm.v6p>4,"后上",_xlpm.v6p<2,"前上",TRUE,"顶部"), IFERROR(_xlpm.output,""))} -> 顶部 | L34: Default | M34: =N34+0&","&O34+0 -> -3,15 | N34: -3 | O34: 15 | P34: =IF(R34<>"",1,"") -> 1 | Q34: 10 | R34: =IF(S34<>"", S34+0&","&T34+0,"") -> 1,3 | S34: 1 | T34: 3 | U34: =IF($A34<>"",IF($V34<>"",$V34,"0,0"),"") -> 0,45 | V34: 0,45 | W34: =IF($A34<>"",IF($X34<>"",$X34,"80,120"),"") -> 50,150 | X34: 50,150 | Y34: 0.75
A35: 460804 | B35: {=F35&_xlfn.TEXTJOIN("",1,TEXT(G35:H35,"00"))} -> 10500 | C35: =_xlfn.TEXTJOIN(",",1,A35:B35) -> 460804,10500 | D35: 大湖 | E35: 雷暴 | F35: 1 | G35: 5 | H35: 0 | I35: 201814 | J35: =IFERROR(VLOOKUP(I35,monsters[#All],4,0),"") -> 弱小螃蟹 | K35: {=_xlfn.LET(_xlpm.v6p,ABS(ATAN2(N35,O35))*6/PI(), _xlpm.output,_xlfn.IFS(_xlpm.v6p<1,"正前",_xlpm.v6p>5,"正后",AND(_xlpm.v6p<5,_xlpm.v6p>2,O35<-1),"脚底",_xlpm.v6p>4,"后上",_xlpm.v6p<2,"前上",TRUE,"顶部"), IFERROR(_xlpm.output,""))} -> 顶部 | L35: Default | M35: =N35+0&","&O35+0 -> -8,15 | N35: -8 | O35: 15 | P35: =IF(R35<>"",1,"") -> 1 | Q35: 10 | R35: =IF(S35<>"", S35+0&","&T35+0,"") -> 1,3 | S35: 1 | T35: 3 | U35: =IF($A35<>"",IF($V35<>"",$V35,"0,0"),"") -> 0,45 | V35: 0,45 | W35: =IF($A35<>"",IF($X35<>"",$X35,"80,120"),"") -> 50,150 | X35: 50,150 | Y35: 0.5

Sheet mg_scene
A1: id | B1: sub_id | H1: monster_id | K1: is_elite | L1: init_state | M1: end_state | N1: pos | Q1: pos_rnd_radius | S1: count_max | T1: generate_count_area | W1: tension_min | X1: tension_max | Y1: spawn_init | AA1: spawn_threshold | AC1: k_distance | AD1: k_time | AE1: kill_pressure | AF1: tide_count_addtion | AG1: tide_time_addtion
A2: uint key | B2: uint key | H2: uint | K2: bool? | L2: string | M2: string | N2: Vector2 | Q2: float | S2: int | T2: Vector2? | W2: int | X2: int | Y2: Vector2 | AA2: Vector2 | AC2: float | AD2: float | AE2: float | AF2: int | AG2: float
A3: 怪物组id | B3: 组内子id | C3: 重复key校验列 | D3: 编号 辅助 种类 | E3: 编号 辅助 大组 | F3: 编号 辅助 紧张 | G3: 编号 辅助 小组 | H3: 怪物id | I3: 备注 生成内容 | J3: 备注 生成 位置 | K3: 精英 | L3: 初始状态 | M3: 撤离状态 | N3: 出现位置 | O3: pos.x | P3: pos.y | Q3: 位置 随机散布 | R3: 特殊值? | S3: 最大数量 | T3: 每次生成数 min~max | U3: rnd min | V3: rnd max | W3: 地区紧张度 min | X3: 地区紧张度 max | Y3: 初始进度 仅在进入场景时随机取值一次 | Z3: 特殊值? | AA3: 生成所需进度 进入场景时随机取值一次；每次生成怪物后重新随机取值。 | AB3: 特殊值? | AC3: 生成速率 距离系数 | AD3: 生成速率 时间系数 代码中被除以120，意味着这是秒增量而不是帧增量。 | AE3: 击杀压力 | AF3: 兽潮 强化 数量 | AG3: 兽潮 强化 k_time | AI3: 生成速率 | AJ3: 稳态 单位距离 生成数 (100unit) | AK3: 稳态 单位时间 生成数 (16.67s) | AL3: 稳态 单位距离 hp (100unit) | AM3: 稳态 单位时间 hp (16.67s) | AN3: 定量生成？ | AO3: 定量 100u 分布
A4: 1 | B4: {=D4&_xlfn.TEXTJOIN("",1,TEXT(E4:G4,"00"))} -> 1010000 | C4: =_xlfn.TEXTJOIN(",",1,A4:B4) -> 1,1010000 | D4: 1 | E4: 1 | F4: =W4 -> 0 | G4: 0 | H4: 201101 | I4: =IFERROR(VLOOKUP(H4,monsters[#All],4,0),"") -> 地宫蝙蝠 | J4: {=_xlfn.LET(_xlpm.v6p,ABS(ATAN2(O4,P4))*6/PI(), _xlpm.output,_xlfn.IFS(_xlpm.v6p<1,"正前",_xlpm.v6p>5,"正后",AND(_xlpm.v6p<5,_xlpm.v6p>2,P4<-1),"脚底",_xlpm.v6p>4,"后上",_xlpm.v6p<2,"前上",TRUE,"顶部"), IFERROR(_xlpm.output,""))} -> 前上 | L4: Default | N4: =O4+0&","&P4+0 -> 15,10 | O4: 15 | P4: 10 | Q4: =_xlfn.LET(_xlpm._default,1, _xlpm._custom,R4, IF($A4<>"",IF(_xlpm._custom<>"",_xlpm._custom,_xlpm._default),"")) -> 1 | S4: 8 | T4: =IF(U4<>"", U4+0&","&V4+0,"") -> 1,3 | U4: 1 | V4: 3 | W4: 0 | X4: 11 | Y4: =IF($A4<>"",IF($Z4<>"",$Z4,"0,0"),"") -> 65,70 | Z4: 65,70 | AA4: =IF($A4<>"",IF($AB4<>"",$AB4,"80,120"),"") -> 80,120 | AC4: 2 | AD4: 2.5 | AE4: 0.3 | AF4: 3 | AG4: 100
A5: 1 | B5: {=D5&_xlfn.TEXTJOIN("",1,TEXT(E5:G5,"00"))} -> 1010100 | C5: =_xlfn.TEXTJOIN(",",1,A5:B5) -> 1,1010100 | D5: 1 | E5: 1 | F5: =W5 -> 1 | G5: 0 | H5: 201101 | I5: =IFERROR(VLOOKUP(H5,monsters[#All],4,0),"") -> 地宫蝙蝠 | J5: {=_xlfn.LET(_xlpm.v6p,ABS(ATAN2(O5,P5))*6/PI(), _xlpm.output,_xlfn.IFS(_xlpm.v6p<1,"正前",_xlpm.v6p>5,"正后",AND(_xlpm.v6p<5,_xlpm.v6p>2,P5<-1),"脚底",_xlpm.v6p>4,"后上",_xlpm.v6p<2,"前上",TRUE,"顶部"), IFERROR(_xlpm.output,""))} -> 前上 | L5: Default | N5: =O5+0&","&P5+0 -> 15,10 | O5: 15 | P5: 10 | Q5: =_xlfn.LET(_xlpm._default,1, _xlpm._custom,R5, IF($A5<>"",IF(_xlpm._custom<>"",_xlpm._custom,_xlpm._default),"")) -> 1 | S5: 4 | T5: =IF(U5<>"", U5+0&","&V5+0,"") -> 1,3 | U5: 1 | V5: 3 | W5: 1 | X5: 11 | Y5: =IF($A5<>"",IF($Z5<>"",$Z5,"0,0"),"") -> 0,0 | AA5: =IF($A5<>"",IF($AB5<>"",$AB5,"80,120"),"") -> 80,120 | AC5: 2 | AD5: 0.5 | AE5: 0.3 | AF5: 2 | AG5: 20
A6: 1 | B6: {=D6&_xlfn.TEXTJOIN("",1,TEXT(E6:G6,"00"))} -> 1010200 | C6: =_xlfn.TEXTJOIN(",",1,A6:B6) -> 1,1010200 | D6: 1 | E6: 1 | F6: =W6 -> 2 | G6: 0 | H6: 201101 | I6: =IFERROR(VLOOKUP(H6,monsters[#All],4,0),"") -> 地宫蝙蝠 | J6: {=_xlfn.LET(_xlpm.v6p,ABS(ATAN2(O6,P6))*6/PI(), _xlpm.output,_xlfn.IFS(_xlpm.v6p<1,"正前",_xlpm.v6p>5,"正后",AND(_xlpm.v6p<5,_xlpm.v6p>2,P6<-1),"脚底",_xlpm.v6p>4,"后上",_xlpm.v6p<2,"前上",TRUE,"顶部"), IFERROR(_xlpm.output,""))} -> 前上 | L6: Default | N6: =O6+0&","&P6+0 -> 15,10 | O6: 15 | P6: 10 | Q6: =_xlfn.LET(_xlpm._default,1, _xlpm._custom,R6, IF($A6<>"",IF(_xlpm._custom<>"",_xlpm._custom,_xlpm._default),"")) -> 1 | S6: 4 | T6: =IF(U6<>"", U6+0&","&V6+0,"") -> 1,3 | U6: 1 | V6: 3 | W6: 2 | X6: 11 | Y6: =IF($A6<>"",IF($Z6<>"",$Z6,"0,0"),"") -> 0,0 | AA6: =IF($A6<>"",IF($AB6<>"",$AB6,"80,120"),"") -> 80,120 | AC6: 2 | AD6: 0.5 | AE6: 0.3 | AF6: 2 | AG6: 20
A7: 1 | B7: {=D7&_xlfn.TEXTJOIN("",1,TEXT(E7:G7,"00"))} -> 1010300 | C7: =_xlfn.TEXTJOIN(",",1,A7:B7) -> 1,1010300 | D7: 1 | E7: 1 | F7: =W7 -> 3 | G7: 0 | H7: 201101 | I7: =IFERROR(VLOOKUP(H7,monsters[#All],4,0),"") -> 地宫蝙蝠 | J7: {=_xlfn.LET(_xlpm.v6p,ABS(ATAN2(O7,P7))*6/PI(), _xlpm.output,_xlfn.IFS(_xlpm.v6p<1,"正前",_xlpm.v6p>5,"正后",AND(_xlpm.v6p<5,_xlpm.v6p>2,P7<-1),"脚底",_xlpm.v6p>4,"后上",_xlpm.v6p<2,"前上",TRUE,"顶部"), IFERROR(_xlpm.output,""))} -> 前上 | L7: Default | N7: =O7+0&","&P7+0 -> 15,10 | O7: 15 | P7: 10 | Q7: =_xlfn.LET(_xlpm._default,1, _xlpm._custom,R7, IF($A7<>"",IF(_xlpm._custom<>"",_xlpm._custom,_xlpm._default),"")) -> 1 | S7: 12 | T7: =IF(U7<>"", U7+0&","&V7+0,"") -> 1,3 | U7: 1 | V7: 3 | W7: 3 | X7: 11 | Y7: =IF($A7<>"",IF($Z7<>"",$Z7,"0,0"),"") -> 0,0 | AA7: =IF($A7<>"",IF($AB7<>"",$AB7,"80,120"),"") -> 80,120 | AC7: 12 | AD7: 8 | AE7: 0.3 | AF7: 6 | AG7: 200
C8: =_xlfn.TEXTJOIN(",",1,A8:B8) | I8: =IFERROR(VLOOKUP(H8,monsters[#All],4,0),"") | J8: {=_xlfn.LET(_xlpm.v6p,ABS(ATAN2(O8,P8))*6/PI(), _xlpm.output,_xlfn.IFS(_xlpm.v6p<1,"正前",_xlpm.v6p>5,"正后",AND(_xlpm.v6p<5,_xlpm.v6p>2,P8<-1),"脚底",_xlpm.v6p>4,"后上",_xlpm.v6p<2,"前上",TRUE,"顶部"), IFERROR(_xlpm.output,""))} | Q8: =_xlfn.LET(_xlpm._default,1, _xlpm._custom,R8, IF($A8<>"",IF(_xlpm._custom<>"",_xlpm._custom,_xlpm._default),"")) | T8: =IF(U8<>"", U8+0&","&V8+0,"") | Y8: =IF($A8<>"",IF($Z8<>"",$Z8,"0,0"),"") | AA8: =IF($A8<>"",IF($AB8<>"",$AB8,"80,120"),"")
A9: 1 | B9: {=D9&_xlfn.TEXTJOIN("",1,TEXT(E9:G9,"00"))} -> 1020000 | C9: =_xlfn.TEXTJOIN(",",1,A9:B9) -> 1,1020000 | D9: 1 | E9: 2 | F9: =W9 -> 0 | G9: 0 | H9: 201101 | I9: =IFERROR(VLOOKUP(H9,monsters[#All],4,0),"") -> 地宫蝙蝠 | J9: {=_xlfn.LET(_xlpm.v6p,ABS(ATAN2(O9,P9))*6/PI(), _xlpm.output,_xlfn.IFS(_xlpm.v6p<1,"正前",_xlpm.v6p>5,"正后",AND(_xlpm.v6p<5,_xlpm.v6p>2,P9<-1),"脚底",_xlpm.v6p>4,"后上",_xlpm.v6p<2,"前上",TRUE,"顶部"), IFERROR(_xlpm.output,""))} -> 后上 | L9: Default | N9: =O9+0&","&P9+0 -> -15,10 | O9: -15 | P9: 10 | Q9: =_xlfn.LET(_xlpm._default,1, _xlpm._custom,R9, IF($A9<>"",IF(_xlpm._custom<>"",_xlpm._custom,_xlpm._default),"")) -> 1 | S9: 12 | T9: =IF(U9<>"", U9+0&","&V9+0,"") -> 1,3 | U9: 1 | V9: 3 | W9: 0 | X9: 11 | Y9: =IF($A9<>"",IF($Z9<>"",$Z9,"0,0"),"") -> 35,40 | Z9: 35,40 | AA9: =IF($A9<>"",IF($AB9<>"",$AB9,"80,120"),"") -> 80,120 | AC9: 2 | AD9: 2 | AE9: 0.3 | AF9: 4 | AG9: 100
A10: 1 | B10: {=D10&_xlfn.TEXTJOIN("",1,TEXT(E10:G10,"00"))} -> 1020100 | C10: =_xlfn.TEXTJOIN(",",1,A10:B10) -> 1,1020100 | D10: 1 | E10: 2 | F10: =W10 -> 1 | G10: 0 | H10: 201101 | I10: =IFERROR(VLOOKUP(H10,monsters[#All],4,0),"") -> 地宫蝙蝠 | J10: {=_xlfn.LET(_xlpm.v6p,ABS(ATAN2(O10,P10))*6/PI(), _xlpm.output,_xlfn.IFS(_xlpm.v6p<1,"正前",_xlpm.v6p>5,"正后",AND(_xlpm.v6p<5,_xlpm.v6p>2,P10<-1),"脚底",_xlpm.v6p>4,"后上",_xlpm.v6p<2,"前上",TRUE,"顶部"), IFERROR(_xlpm.output,""))} -> 后上 | L10: Default | N10: =O10+0&","&P10+0 -> -15,10 | O10: -15 | P10: 10 | Q10: =_xlfn.LET(_xlpm._default,1, _xlpm._custom,R10, IF($A10<>"",IF(_xlpm._custom<>"",_xlpm._custom,_xlpm._default),"")) -> 1 | S10: 4 | T10: =IF(U10<>"", U10+0&","&V10+0,"") -> 1,3 | U10: 1 | V10: 3 | W10: 1 | X10: 11 | Y10: =IF($A10<>"",IF($Z10<>"",$Z10,"0,0"),"") -> 0,0 | AA10: =IF($A10<>"",IF($AB10<>"",$AB10,"80,120"),"") -> 80,120 | AC10: 2 | AD10: 0.5 | AE10: 0.3 | AF10: 2 | AG10: 20
A11: 1 | B11: {=D11&_xlfn.TEXTJOIN("",1,TEXT(E11:G11,"00"))} -> 1020200 | C11: =_xlfn.TEXTJOIN(",",1,A11:B11) -> 1,1020200 | D11: 1 | E11: 2 | F11: =W11 -> 2 | G11: 0 | H11: 201101 | I11: =IFERROR(VLOOKUP(H11,monsters[#All],4,0),"") -> 地宫蝙蝠 | J11: {=_xlfn.LET(_xlpm.v6p,ABS(ATAN2(O11,P11))*6/PI(), _xlpm.output,_xlfn.IFS(_xlpm.v6p<1,"正前",_xlpm.v6p>5,"正后",AND(_xlpm.v6p<5,_xlpm.v6p>2,P11<-1),"脚底",_xlpm.v6p>4,"后上",_xlpm.v6p<2,"前上",TRUE,"顶部"), IFERROR(_xlpm.output,""))} -> 后上 | L11: Default | N11: =O11+0&","&P11+0 -> -15,10 | O11: -15 | P11: 10 | Q11: =_xlfn.LET(_xlpm._default,1, _xlpm._custom,R11, IF($A11<>"",IF(_xlpm._custom<>"",_xlpm._custom,_xlpm._default),"")) -> 1 | S11: 20 | T11: =IF(U11<>"", U11+0&","&V11+0,"") -> 1,3 | U11: 1 | V11: 3 | W11: 2 | X11: 11 | Y11: =IF($A11<>"",IF($Z11<>"",$Z11,"0,0"),"") -> 0,0 | AA11: =IF($A11<>"",IF($AB11<>"",$AB11,"80,120"),"") -> 80,120 | AC11: 2 | AD11: 0.5 | AE11: 0.3 | AF11: 2 | AG11: 20
A12: 1 | B12: {=D12&_xlfn.TEXTJOIN("",1,TEXT(E12:G12,"00"))} -> 1020300 | C12: =_xlfn.TEXTJOIN(",",1,A12:B12) -> 1,1020300 | D12: 1 | E12: 2 | F12: =W12 -> 3 | G12: 0 | H12: 201101 | I12: =IFERROR(VLOOKUP(H12,monsters[#All],4,0),"") -> 地宫蝙蝠 | J12: {=_xlfn.LET(_xlpm.v6p,ABS(ATAN2(O12,P12))*6/PI(), _xlpm.output,_xlfn.IFS(_xlpm.v6p<1,"正前",_xlpm.v6p>5,"正后",AND(_xlpm.v6p<5,_xlpm.v6p>2,P12<-1),"脚底",_xlpm.v6p>4,"后上",_xlpm.v6p<2,"前上",TRUE,"顶部"), IFERROR(_xlpm.output,""))} -> 后上 | L12: Default | N12: =O12+0&","&P12+0 -> -15,10 | O12: -15 | P12: 10 | Q12: =_xlfn.LET(_xlpm._default,1, _xlpm._custom,R12, IF($A12<>"",IF(_xlpm._custom<>"",_xlpm._custom,_xlpm._default),"")) -> 1 | S12: 20 | T12: =IF(U12<>"", U12+0&","&V12+0,"") -> 1,3 | U12: 1 | V12: 3 | W12: 3 | X12: 11 | Y12: =IF($A12<>"",IF($Z12<>"",$Z12,"0,0"),"") -> 0,0 | AA12: =IF($A12<>"",IF($AB12<>"",$AB12,"80,120"),"") -> 80,120 | AC12: 40 | AD12: 6 | AE12: 0.3 | AF12: 6 | AG12: 200
C13: =_xlfn.TEXTJOIN(",",1,A13:B13) | I13: =IFERROR(VLOOKUP(H13,monsters[#All],4,0),"") | J13: {=_xlfn.LET(_xlpm.v6p,ABS(ATAN2(O13,P13))*6/PI(), _xlpm.output,_xlfn.IFS(_xlpm.v6p<1,"正前",_xlpm.v6p>5,"正后",AND(_xlpm.v6p<5,_xlpm.v6p>2,P13<-1),"脚底",_xlpm.v6p>4,"后上",_xlpm.v6p<2,"前上",TRUE,"顶部"), IFERROR(_xlpm.output,""))} | Q13: =_xlfn.LET(_xlpm._default,1, _xlpm._custom,R13, IF($A13<>"",IF(_xlpm._custom<>"",_xlpm._custom,_xlpm._default),"")) | T13: =IF(U13<>"", U13+0&","&V13+0,"") | Y13: =IF($A13<>"",IF($Z13<>"",$Z13,"0,0"),"") | AA13: =IF($A13<>"",IF($AB13<>"",$AB13,"80,120"),"")
A14: 1 | B14: {=D14&_xlfn.TEXTJOIN("",1,TEXT(E14:G14,"00"))} -> 2010000 | C14: =_xlfn.TEXTJOIN(",",1,A14:B14) -> 1,2010000 | D14: 2 | E14: 1 | F14: =W14 -> 0 | G14: 0 | H14: 201102 | I14: =IFERROR(VLOOKUP(H14,monsters[#All],4,0),"") -> 自爆甲虫 | J14: {=_xlfn.LET(_xlpm.v6p,ABS(ATAN2(O14,P14))*6/PI(), _xlpm.output,_xlfn.IFS(_xlpm.v6p<1,"正前",_xlpm.v6p>5,"正后",AND(_xlpm.v6p<5,_xlpm.v6p>2,P14<-1),"脚底",_xlpm.v6p>4,"后上",_xlpm.v6p<2,"前上",TRUE,"顶部"), IFERROR(_xlpm.output,""))} -> 正前 | L14: Default | N14: =O14+0&","&P14+0 -> 15,-1 | O14: 15 | P14: -1 | Q14: =_xlfn.LET(_xlpm._default,1, _xlpm._custom,R14, IF($A14<>"",IF(_xlpm._custom<>"",_xlpm._custom,_xlpm._default),"")) -> 1 | S14: 4 | T14: =IF(U14<>"", U14+0&","&V14+0,"") | W14: 0 | X14: 11 | Y14: =IF($A14<>"",IF($Z14<>"",$Z14,"0,0"),"") -> 0,0 | AA14: =IF($A14<>"",IF($AB14<>"",$AB14,"80,120"),"") -> 80,120 | AC14: 0.12 | AD14: 0 | AE14: 2 | AG14: 99
A15: 1 | B15: {=D15&_xlfn.TEXTJOIN("",1,TEXT(E15:G15,"00"))} -> 2010100 | C15: =_xlfn.TEXTJOIN(",",1,A15:B15) -> 1,2010100 | D15: 2 | E15: 1 | F15: =W15 -> 1 | G15: 0 | H15: 201102 | I15: =IFERROR(VLOOKUP(H15,monsters[#All],4,0),"") -> 自爆甲虫 | J15: {=_xlfn.LET(_xlpm.v6p,ABS(ATAN2(O15,P15))*6/PI(), _xlpm.output,_xlfn.IFS(_xlpm.v6p<1,"正前",_xlpm.v6p>5,"正后",AND(_xlpm.v6p<5,_xlpm.v6p>2,P15<-1),"脚底",_xlpm.v6p>4,"后上",_xlpm.v6p<2,"前上",TRUE,"顶部"), IFERROR(_xlpm.output,""))} -> 正前 | L15: Default | N15: =O15+0&","&P15+0 -> 15,-1 | O15: 15 | P15: -1 | Q15: =_xlfn.LET(_xlpm._default,1, _xlpm._custom,R15, IF($A15<>"",IF(_xlpm._custom<>"",_xlpm._custom,_xlpm._default),"")) -> 1 | S15: 2 | T15: =IF(U15<>"", U15+0&","&V15+0,"") | W15: 1 | X15: 11 | Y15: =IF($A15<>"",IF($Z15<>"",$Z15,"0,0"),"") -> 0,0 | AA15: =IF($A15<>"",IF($AB15<>"",$AB15,"80,120"),"") -> 80,120 | AC15: 0.04 | AD15: 0 | AE15: 2 | AG15: 99
A16: 1 | B16: {=D16&_xlfn.TEXTJOIN("",1,TEXT(E16:G16,"00"))} -> 2010300 | C16: =_xlfn.TEXTJOIN(",",1,A16:B16) -> 1,2010300 | D16: 2 | E16: 1 | F16: =W16 -> 3 | G16: 0 | H16: 201102 | I16: =IFERROR(VLOOKUP(H16,monsters[#All],4,0),"") -> 自爆甲虫 | J16: {=_xlfn.LET(_xlpm.v6p,ABS(ATAN2(O16,P16))*6/PI(), _xlpm.output,_xlfn.IFS(_xlpm.v6p<1,"正前",_xlpm.v6p>5,"正后",AND(_xlpm.v6p<5,_xlpm.v6p>2,P16<-1),"脚底",_xlpm.v6p>4,"后上",_xlpm.v6p<2,"前上",TRUE,"顶部"), IFERROR(_xlpm.output,""))} -> 正前 | L16: Default | N16: =O16+0&","&P16+0 -> 15,-1 | O16: 15 | P16: -1 | Q16: =_xlfn.LET(_xlpm._default,1, _xlpm._custom,R16, IF($A16<>"",IF(_xlpm._custom<>"",_xlpm._custom,_xlpm._default),"")) -> 1 | S16: 4 | T16: =IF(U16<>"", U16+0&","&V16+0,"") | W16: 3 | X16: 11 | Y16: =IF($A16<>"",IF($Z16<>"",$Z16,"0,0"),"") -> 0,0 | AA16: =IF($A16<>"",IF($AB16<>"",$AB16,"80,120"),"") -> 80,120 | AC16: 14 | AD16: 0 | AE16: 2 | AG16: 99
C17: =_xlfn.TEXTJOIN(",",1,A17:B17) | I17: =IFERROR(VLOOKUP(H17,monsters[#All],4,0),"") | J17: {=_xlfn.LET(_xlpm.v6p,ABS(ATAN2(O17,P17))*6/PI(), _xlpm.output,_xlfn.IFS(_xlpm.v6p<1,"正前",_xlpm.v6p>5,"正后",AND(_xlpm.v6p<5,_xlpm.v6p>2,P17<-1),"脚底",_xlpm.v6p>4,"后上",_xlpm.v6p<2,"前上",TRUE,"顶部"), IFERROR(_xlpm.output,""))} | Q17: =_xlfn.LET(_xlpm._default,1, _xlpm._custom,R17, IF($A17<>"",IF(_xlpm._custom<>"",_xlpm._custom,_xlpm._default),"")) | T17: =IF(U17<>"", U17+0&","&V17+0,"") | Y17: =IF($A17<>"",IF($Z17<>"",$Z17,"0,0"),"") | AA17: =IF($A17<>"",IF($AB17<>"",$AB17,"80,120"),"")
A18: 1 | B18: {=D18&_xlfn.TEXTJOIN("",1,TEXT(E18:G18,"00"))} -> 2020001 | C18: =_xlfn.TEXTJOIN(",",1,A18:B18) -> 1,2020001 | D18: 2 | E18: 2 | F18: =W18 -> 0 | G18: 1 | H18: 201102 | I18: =IFERROR(VLOOKUP(H18,monsters[#All],4,0),"") -> 自爆甲虫 | J18: {=_xlfn.LET(_xlpm.v6p,ABS(ATAN2(O18,P18))*6/PI(), _xlpm.output,_xlfn.IFS(_xlpm.v6p<1,"正前",_xlpm.v6p>5,"正后",AND(_xlpm.v6p<5,_xlpm.v6p>2,P18<-1),"脚底",_xlpm.v6p>4,"后上",_xlpm.v6p<2,"前上",TRUE,"顶部"), IFERROR(_xlpm.output,""))} -> 前上 | L18: Default_Awaken | N18: =O18+0&","&P18+0 -> 20,12 | O18: 20 | P18: 12 | Q18: =_xlfn.LET(_xlpm._default,1, _xlpm._custom,R18, IF($A18<>"",IF(_xlpm._custom<>"",_xlpm._custom,_xlpm._default),"")) -> 1 | T18: =IF(U18<>"", U18+0&","&V18+0,"") | W18: 0 | X18: 11 | Y18: =IF($A18<>"",IF($Z18<>"",$Z18,"0,0"),"") -> 0,0 | AA18: =IF($A18<>"",IF($AB18<>"",$AB18,"80,120"),"") -> 80,120 | AE18: 0 | AF18: 1 | AG18: 1.8
A19: 1 | B19: {=D19&_xlfn.TEXTJOIN("",1,TEXT(E19:G19,"00"))} -> 2020002 | C19: =_xlfn.TEXTJOIN(",",1,A19:B19) -> 1,2020002 | D19: 2 | E19: 2 | F19: =W19 -> 0 | G19: 2 | H19: 201102 | I19: =IFERROR(VLOOKUP(H19,monsters[#All],4,0),"") -> 自爆甲虫 | J19: {=_xlfn.LET(_xlpm.v6p,ABS(ATAN2(O19,P19))*6/PI(), _xlpm.output,_xlfn.IFS(_xlpm.v6p<1,"正前",_xlpm.v6p>5,"正后",AND(_xlpm.v6p<5,_xlpm.v6p>2,P19<-1),"脚底",_xlpm.v6p>4,"后上",_xlpm.v6p<2,"前上",TRUE,"顶部"), IFERROR(_xlpm.output,""))} -> 正前 | L19: Default_Awaken | N19: =O19+0&","&P19+0 -> 20,8 | O19: 20 | P19: 8 | Q19: =_xlfn.LET(_xlpm._default,1, _xlpm._custom,R19, IF($A19<>"",IF(_xlpm._custom<>"",_xlpm._custom,_xlpm._default),"")) -> 1 | T19: =IF(U19<>"", U19+0&","&V19+0,"") | W19: 0 | X19: 11 | Y19: =IF($A19<>"",IF($Z19<>"",$Z19,"0,0"),"") -> 0,0 | AA19: =IF($A19<>"",IF($AB19<>"",$AB19,"80,120"),"") -> 80,120 | AE19: 0 | AF19: 1 | AG19: 2.6
A20: 1 | B20: {=D20&_xlfn.TEXTJOIN("",1,TEXT(E20:G20,"00"))} -> 2020003 | C20: =_xlfn.TEXTJOIN(",",1,A20:B20) -> 1,2020003 | D20: 2 | E20: 2 | F20: =W20 -> 0 | G20: 3 | H20: 201102 | I20: =IFERROR(VLOOKUP(H20,monsters[#All],4,0),"") -> 自爆甲虫 | J20: {=_xlfn.LET(_xlpm.v6p,ABS(ATAN2(O20,P20))*6/PI(), _xlpm.output,_xlfn.IFS(_xlpm.v6p<1,"正前",_xlpm.v6p>5,"正后",AND(_xlpm.v6p<5,_xlpm.v6p>2,P20<-1),"脚底",_xlpm.v6p>4,"后上",_xlpm.v6p<2,"前上",TRUE,"顶部"), IFERROR(_xlpm.output,""))} -> 正前 | L20: Default_Awaken | N20: =O20+0&","&P20+0 -> 20,5 | O20: 20 | P20: 5 | Q20: =_xlfn.LET(_xlpm._default,1, _xlpm._custom,R20, IF($A20<>"",IF(_xlpm._custom<>"",_xlpm._custom,_xlpm._default),"")) -> 1 | T20: =IF(U20<>"", U20+0&","&V20+0,"") | W20: 0 | X20: 11 | Y20: =IF($A20<>"",IF($Z20<>"",$Z20,"0,0"),"") -> 0,0 | AA20: =IF($A20<>"",IF($AB20<>"",$AB20,"80,120"),"") -> 80,120 | AE20: 0 | AF20: 1 | AG20: 3.4
A21: 1 | B21: {=D21&_xlfn.TEXTJOIN("",1,TEXT(E21:G21,"00"))} -> 2020004 | C21: =_xlfn.TEXTJOIN(",",1,A21:B21) -> 1,2020004 | D21: 2 | E21: 2 | F21: =W21 -> 0 | G21: 4 | H21: 201102 | I21: =IFERROR(VLOOKUP(H21,monsters[#All],4,0),"") -> 自爆甲虫 | J21: {=_xlfn.LET(_xlpm.v6p,ABS(ATAN2(O21,P21))*6/PI(), _xlpm.output,_xlfn.IFS(_xlpm.v6p<1,"正前",_xlpm.v6p>5,"正后",AND(_xlpm.v6p<5,_xlpm.v6p>2,P21<-1),"脚底",_xlpm.v6p>4,"后上",_xlpm.v6p<2,"前上",TRUE,"顶部"), IFERROR(_xlpm.output,""))} -> 正前 | L21: Default_Awaken | N21: =O21+0&","&P21+0 -> 20,2 | O21: 20 | P21: 2 | Q21: =_xlfn.LET(_xlpm._default,1, _xlpm._custom,R21, IF($A21<>"",IF(_xlpm._custom<>"",_xlpm._custom,_xlpm._default),"")) -> 1 | T21: =IF(U21<>"", U21+0&","&V21+0,"") | W21: 0 | X21: 11 | Y21: =IF($A21<>"",IF($Z21<>"",$Z21,"0,0"),"") -> 0,0 | AA21: =IF($A21<>"",IF($AB21<>"",$AB21,"80,120"),"") -> 80,120 | AE21: 0 | AF21: 1 | AG21: 4.6
A22: 1 | B22: {=D22&_xlfn.TEXTJOIN("",1,TEXT(E22:G22,"00"))} -> 2020005 | C22: =_xlfn.TEXTJOIN(",",1,A22:B22) -> 1,2020005 | D22: 2 | E22: 2 | F22: =W22 -> 0 | G22: 5 | H22: 201102 | I22: =IFERROR(VLOOKUP(H22,monsters[#All],4,0),"") -> 自爆甲虫 | J22: {=_xlfn.LET(_xlpm.v6p,ABS(ATAN2(O22,P22))*6/PI(), _xlpm.output,_xlfn.IFS(_xlpm.v6p<1,"正前",_xlpm.v6p>5,"正后",AND(_xlpm.v6p<5,_xlpm.v6p>2,P22<-1),"脚底",_xlpm.v6p>4,"后上",_xlpm.v6p<2,"前上",TRUE,"顶部"), IFERROR(_xlpm.output,""))} -> 正后 | L22: Default_Awaken | N22: =O22+0&","&P22+0 -> -15,5 | O22: -15 | P22: 5 | Q22: =_xlfn.LET(_xlpm._default,1, _xlpm._custom,R22, IF($A22<>"",IF(_xlpm._custom<>"",_xlpm._custom,_xlpm._default),"")) -> 1 | T22: =IF(U22<>"", U22+0&","&V22+0,"") | W22: 0 | X22: 11 | Y22: =IF($A22<>"",IF($Z22<>"",$Z22,"0,0"),"") -> 0,0 | AA22: =IF($A22<>"",IF($AB22<>"",$AB22,"80,120"),"") -> 80,120 | AE22: 0 | AF22: 1 | AG22: 6.2
C23: =_xlfn.TEXTJOIN(",",1,A23:B23) | I23: =IFERROR(VLOOKUP(H23,monsters[#All],4,0),"") | J23: {=_xlfn.LET(_xlpm.v6p,ABS(ATAN2(O23,P23))*6/PI(), _xlpm.output,_xlfn.IFS(_xlpm.v6p<1,"正前",_xlpm.v6p>5,"正后",AND(_xlpm.v6p<5,_xlpm.v6p>2,P23<-1),"脚底",_xlpm.v6p>4,"后上",_xlpm.v6p<2,"前上",TRUE,"顶部"), IFERROR(_xlpm.output,""))} | Q23: =_xlfn.LET(_xlpm._default,1, _xlpm._custom,R23, IF($A23<>"",IF(_xlpm._custom<>"",_xlpm._custom,_xlpm._default),"")) | T23: =IF(U23<>"", U23+0&","&V23+0,"") | Y23: =IF($A23<>"",IF($Z23<>"",$Z23,"0,0"),"") | AA23: =IF($A23<>"",IF($AB23<>"",$AB23,"80,120"),"")
A24: 1 | B24: {=D24&_xlfn.TEXTJOIN("",1,TEXT(E24:G24,"00"))} -> 3010000 | C24: =_xlfn.TEXTJOIN(",",1,A24:B24) -> 1,3010000 | D24: 3 | E24: 1 | F24: 0 | G24: 0 | H24: 201103 | I24: =IFERROR(VLOOKUP(H24,monsters[#All],4,0),"") -> 跳虫 | J24: {=_xlfn.LET(_xlpm.v6p,ABS(ATAN2(O24,P24))*6/PI(), _xlpm.output,_xlfn.IFS(_xlpm.v6p<1,"正前",_xlpm.v6p>5,"正后",AND(_xlpm.v6p<5,_xlpm.v6p>2,P24<-1),"脚底",_xlpm.v6p>4,"后上",_xlpm.v6p<2,"前上",TRUE,"顶部"), IFERROR(_xlpm.output,""))} -> 正后 | L24: Default | N24: =O24+0&","&P24+0 -> -14,-1 | O24: -14 | P24: -1 | Q24: =_xlfn.LET(_xlpm._default,1, _xlpm._custom,R24, IF($A24<>"",IF(_xlpm._custom<>"",_xlpm._custom,_xlpm._default),"")) -> 1 | S24: 8 | W24: 0 | X24: 11 | Y24: =IF($A24<>"",IF($Z24<>"",$Z24,"0,0"),"") -> 0,0 | AA24: =IF($A24<>"",IF($AB24<>"",$AB24,"80,120"),"") -> 1,120 | AB24: ="1,120" -> 1,120 | AC24: 1.44 | AD24: 0.075 | AE24: 0.25 | AF24: 2 | AG24: 3
A25: 1 | B25: {=D25&_xlfn.TEXTJOIN("",1,TEXT(E25:G25,"00"))} -> 3020000 | C25: =_xlfn.TEXTJOIN(",",1,A25:B25) -> 1,3020000 | D25: 3 | E25: 2 | F25: 0 | G25: 0 | H25: 201103 | I25: =IFERROR(VLOOKUP(H25,monsters[#All],4,0),"") -> 跳虫 | J25: {=_xlfn.LET(_xlpm.v6p,ABS(ATAN2(O25,P25))*6/PI(), _xlpm.output,_xlfn.IFS(_xlpm.v6p<1,"正前",_xlpm.v6p>5,"正后",AND(_xlpm.v6p<5,_xlpm.v6p>2,P25<-1),"脚底",_xlpm.v6p>4,"后上",_xlpm.v6p<2,"前上",TRUE,"顶部"), IFERROR(_xlpm.output,""))} -> 正前 | L25: Default | N25: =O25+0&","&P25+0 -> 14,-1 | O25: 14 | P25: -1 | Q25: =_xlfn.LET(_xlpm._default,1, _xlpm._custom,R25, IF($A25<>"",IF(_xlpm._custom<>"",_xlpm._custom,_xlpm._default),"")) -> 1 | S25: 8 | W25: 0 | X25: 11 | Y25: =IF($A25<>"",IF($Z25<>"",$Z25,"0,0"),"") -> 0,0 | AA25: =IF($A25<>"",IF($AB25<>"",$AB25,"80,120"),"") -> 1,120 | AB25: ="1,120" -> 1,120 | AC25: 1.48 | AD25: 0.082 | AE25: 0.25 | AF25: 2 | AG25: 3
A26: 1 | B26: {=D26&_xlfn.TEXTJOIN("",1,TEXT(E26:G26,"00"))} -> 3030001 | C26: =_xlfn.TEXTJOIN(",",1,A26:B26) -> 1,3030001 | D26: 3 | E26: 3 | F26: 0 | G26: 1 | H26: 201103 | I26: =IFERROR(VLOOKUP(H26,monsters[#All],4,0),"") -> 跳虫 | J26: {=_xlfn.LET(_xlpm.v6p,ABS(ATAN2(O26,P26))*6/PI(), _xlpm.output,_xlfn.IFS(_xlpm.v6p<1,"正前",_xlpm.v6p>5,"正后",AND(_xlpm.v6p<5,_xlpm.v6p>2,P26<-1),"脚底",_xlpm.v6p>4,"后上",_xlpm.v6p<2,"前上",TRUE,"顶部"), IFERROR(_xlpm.output,""))} -> 顶部 | L26: Default | N26: =O26+0&","&P26+0 -> 3,12 | O26: 3 | P26: 12 | Q26: =_xlfn.LET(_xlpm._default,1, _xlpm._custom,R26, IF($A26<>"",IF(_xlpm._custom<>"",_xlpm._custom,_xlpm._default),"")) -> 1 | S26: 8 | W26: 0 | X26: 11 | Y26: =IF($A26<>"",IF($Z26<>"",$Z26,"0,0"),"") -> 0,0 | AA26: =IF($A26<>"",IF($AB26<>"",$AB26,"80,120"),"") -> 1,120 | AB26: ="1,120" -> 1,120 | AC26: 0.88 | AD26: 0.051 | AE26: 0.25 | AF26: 2 | AG26: 3
A27: 1 | B27: {=D27&_xlfn.TEXTJOIN("",1,TEXT(E27:G27,"00"))} -> 3030002 | C27: =_xlfn.TEXTJOIN(",",1,A27:B27) -> 1,3030002 | D27: 3 | E27: 3 | F27: 0 | G27: 2 | H27: 201103 | I27: =IFERROR(VLOOKUP(H27,monsters[#All],4,0),"") -> 跳虫 | J27: {=_xlfn.LET(_xlpm.v6p,ABS(ATAN2(O27,P27))*6/PI(), _xlpm.output,_xlfn.IFS(_xlpm.v6p<1,"正前",_xlpm.v6p>5,"正后",AND(_xlpm.v6p<5,_xlpm.v6p>2,P27<-1),"脚底",_xlpm.v6p>4,"后上",_xlpm.v6p<2,"前上",TRUE,"顶部"), IFERROR(_xlpm.output,""))} -> 顶部 | L27: Default | N27: =O27+0&","&P27+0 -> -3,12 | O27: -3 | P27: 12 | Q27: =_xlfn.LET(_xlpm._default,1, _xlpm._custom,R27, IF($A27<>"",IF(_xlpm._custom<>"",_xlpm._custom,_xlpm._default),"")) -> 1 | S27: 8 | W27: 0 | X27: 11 | Y27: =IF($A27<>"",IF($Z27<>"",$Z27,"0,0"),"") -> 0,0 | AA27: =IF($A27<>"",IF($AB27<>"",$AB27,"80,120"),"") -> 1,120 | AB27: ="1,120" -> 1,120 | AC27: 1 | AD27: 0.042 | AE27: 0.25 | AF27: 2 | AG27: 3
C28: =_xlfn.TEXTJOIN(",",1,A28:B28) | I28: =IFERROR(VLOOKUP(H28,monsters[#All],4,0),"") | J28: {=_xlfn.LET(_xlpm.v6p,ABS(ATAN2(O28,P28))*6/PI(), _xlpm.output,_xlfn.IFS(_xlpm.v6p<1,"正前",_xlpm.v6p>5,"正后",AND(_xlpm.v6p<5,_xlpm.v6p>2,P28<-1),"脚底",_xlpm.v6p>4,"后上",_xlpm.v6p<2,"前上",TRUE,"顶部"), IFERROR(_xlpm.output,""))} | Q28: =_xlfn.LET(_xlpm._default,1, _xlpm._custom,R28, IF($A28<>"",IF(_xlpm._custom<>"",_xlpm._custom,_xlpm._default),"")) | T28: =IF(U28<>"", U28+0&","&V28+0,"") | Y28: =IF($A28<>"",IF($Z28<>"",$Z28,"0,0"),"") | AA28: =IF($A28<>"",IF($AB28<>"",$AB28,"80,120"),"")
A29: 1 | B29: {=D29&_xlfn.TEXTJOIN("",1,TEXT(E29:G29,"00"))} -> 4010000 | C29: =_xlfn.TEXTJOIN(",",1,A29:B29) -> 1,4010000 | D29: 4 | E29: 1 | F29: 0 | G29: 0 | H29: 201107 | I29: =IFERROR(VLOOKUP(H29,monsters[#All],4,0),"") -> 流浪洞穴人 | J29: {=_xlfn.LET(_xlpm.v6p,ABS(ATAN2(O29,P29))*6/PI(), _xlpm.output,_xlfn.IFS(_xlpm.v6p<1,"正前",_xlpm.v6p>5,"正后",AND(_xlpm.v6p<5,_xlpm.v6p>2,P29<-1),"脚底",_xlpm.v6p>4,"后上",_xlpm.v6p<2,"前上",TRUE,"顶部"), IFERROR(_xlpm.output,""))} -> 正前 | L29: Default | N29: =O29+0&","&P29+0 -> 18,-1 | O29: 18 | P29: -1 | Q29: =_xlfn.LET(_xlpm._default,1, _xlpm._custom,R29, IF($A29<>"",IF(_xlpm._custom<>"",_xlpm._custom,_xlpm._default),"")) -> 1 | S29: 28 | T29: =IF(U29<>"", U29+0&","&V29+0,"") -> 2,3 | U29: 2 | V29: 3 | W29: 0 | X29: 11 | Y29: =IF($A29<>"",IF($Z29<>"",$Z29,"0,0"),"") -> 0,0 | AA29: =IF($A29<>"",IF($AB29<>"",$AB29,"80,120"),"") -> 80,120 | AC29: 0.8 | AD29: 1.5 | AE29: 0.6
A30: 1 | B30: {=D30&_xlfn.TEXTJOIN("",1,TEXT(E30:G30,"00"))} -> 4020001 | C30: =_xlfn.TEXTJOIN(",",1,A30:B30) -> 1,4020001 | D30: 4 | E30: 2 | F30: 0 | G30: 1 | H30: 201107 | I30: =IFERROR(VLOOKUP(H30,monsters[#All],4,0),"") -> 流浪洞穴人 | J30: {=_xlfn.LET(_xlpm.v6p,ABS(ATAN2(O30,P30))*6/PI(), _xlpm.output,_xlfn.IFS(_xlpm.v6p<1,"正前",_xlpm.v6p>5,"正后",AND(_xlpm.v6p<5,_xlpm.v6p>2,P30<-1),"脚底",_xlpm.v6p>4,"后上",_xlpm.v6p<2,"前上",TRUE,"顶部"), IFERROR(_xlpm.output,""))} -> 正前 | L30: Default | N30: =O30+0&","&P30+0 -> 18,-1 | O30: 18 | P30: -1 | Q30: =_xlfn.LET(_xlpm._default,1, _xlpm._custom,R30, IF($A30<>"",IF(_xlpm._custom<>"",_xlpm._custom,_xlpm._default),"")) -> 1 | T30: =IF(U30<>"", U30+0&","&V30+0,"") | W30: 0 | X30: 11 | Y30: =IF($A30<>"",IF($Z30<>"",$Z30,"0,0"),"") -> 0,0 | AA30: =IF($A30<>"",IF($AB30<>"",$AB30,"80,120"),"") -> 80,120 | AE30: 0.6 | AF30: 2 | AG30: 10.2
A31: 1 | B31: {=D31&_xlfn.TEXTJOIN("",1,TEXT(E31:G31,"00"))} -> 4020002 | C31: =_xlfn.TEXTJOIN(",",1,A31:B31) -> 1,4020002 | D31: 4 | E31: 2 | F31: 0 | G31: 2 | H31: 201107 | I31: =IFERROR(VLOOKUP(H31,monsters[#All],4,0),"") -> 流浪洞穴人 | J31: {=_xlfn.LET(_xlpm.v6p,ABS(ATAN2(O31,P31))*6/PI(), _xlpm.output,_xlfn.IFS(_xlpm.v6p<1,"正前",_xlpm.v6p>5,"正后",AND(_xlpm.v6p<5,_xlpm.v6p>2,P31<-1),"脚底",_xlpm.v6p>4,"后上",_xlpm.v6p<2,"前上",TRUE,"顶部"), IFERROR(_xlpm.output,""))} -> 正后 | L31: Default | N31: =O31+0&","&P31+0 -> -14,-1 | O31: -14 | P31: -1 | Q31: =_xlfn.LET(_xlpm._default,1, _xlpm._custom,R31, IF($A31<>"",IF(_xlpm._custom<>"",_xlpm._custom,_xlpm._default),"")) -> 1 | T31: =IF(U31<>"", U31+0&","&V31+0,"") | W31: 0 | X31: 11 | Y31: =IF($A31<>"",IF($Z31<>"",$Z31,"0,0"),"") -> 0,0 | AA31: =IF($A31<>"",IF($AB31<>"",$AB31,"80,120"),"") -> 80,120 | AE31: 0.6 | AF31: 2 | AG31: 6.8
C32: =_xlfn.TEXTJOIN(",",1,A32:B32) | I32: =IFERROR(VLOOKUP(H32,monsters[#All],4,0),"") | J32: {=_xlfn.LET(_xlpm.v6p,ABS(ATAN2(O32,P32))*6/PI(), _xlpm.output,_xlfn.IFS(_xlpm.v6p<1,"正前",_xlpm.v6p>5,"正后",AND(_xlpm.v6p<5,_xlpm.v6p>2,P32<-1),"脚底",_xlpm.v6p>4,"后上",_xlpm.v6p<2,"前上",TRUE,"顶部"), IFERROR(_xlpm.output,""))} | Q32: =_xlfn.LET(_xlpm._default,1, _xlpm._custom,R32, IF($A32<>"",IF(_xlpm._custom<>"",_xlpm._custom,_xlpm._default),"")) | T32: =IF(U32<>"", U32+0&","&V32+0,"") | Y32: =IF($A32<>"",IF($Z32<>"",$Z32,"0,0"),"") | AA32: =IF($A32<>"",IF($AB32<>"",$AB32,"80,120"),"")
A33: 1 | B33: {=D33&_xlfn.TEXTJOIN("",1,TEXT(E33:G33,"00"))} -> 5010001 | C33: =_xlfn.TEXTJOIN(",",1,A33:B33) -> 1,5010001 | D33: 5 | E33: 1 | F33: 0 | G33: 1 | H33: 201106 | I33: =IFERROR(VLOOKUP(H33,monsters[#All],4,0),"") -> 蝙蝠骑手 | J33: {=_xlfn.LET(_xlpm.v6p,ABS(ATAN2(O33,P33))*6/PI(), _xlpm.output,_xlfn.IFS(_xlpm.v6p<1,"正前",_xlpm.v6p>5,"正后",AND(_xlpm.v6p<5,_xlpm.v6p>2,P33<-1),"脚底",_xlpm.v6p>4,"后上",_xlpm.v6p<2,"前上",TRUE,"顶部"), IFERROR(_xlpm.output,""))} -> 前上 | L33: Default | N33: =O33+0&","&P33+0 -> 7,12 | O33: 7 | P33: 12 | Q33: =_xlfn.LET(_xlpm._default,1, _xlpm._custom,R33, IF($A33<>"",IF(_xlpm._custom<>"",_xlpm._custom,_xlpm._default),"")) -> 1 | S33: 4 | T33: =IF(U33<>"", U33+0&","&V33+0,"") -> 1,2 | U33: 1 | V33: 2 | W33: 0 | X33: 11 | Y33: =IF($A33<>"",IF($Z33<>"",$Z33,"0,0"),"") -> 0,0 | AA33: =IF($A33<>"",IF($AB33<>"",$AB33,"80,120"),"") -> 80,120 | AC33: 1.28 | AD33: 0.06 | AE33: 1.2 | AF33: 1 | AG33: 7.7
A34: 1 | B34: {=D34&_xlfn.TEXTJOIN("",1,TEXT(E34:G34,"00"))} -> 5010002 | C34: =_xlfn.TEXTJOIN(",",1,A34:B34) -> 1,5010002 | D34: 5 | E34: 1 | F34: 0 | G34: 2 | H34: 201106 | I34: =IFERROR(VLOOKUP(H34,monsters[#All],4,0),"") -> 蝙蝠骑手 | J34: {=_xlfn.LET(_xlpm.v6p,ABS(ATAN2(O34,P34))*6/PI(), _xlpm.output,_xlfn.IFS(_xlpm.v6p<1,"正前",_xlpm.v6p>5,"正后",AND(_xlpm.v6p<5,_xlpm.v6p>2,P34<-1),"脚底",_xlpm.v6p>4,"后上",_xlpm.v6p<2,"前上",TRUE,"顶部"), IFERROR(_xlpm.output,""))} -> 后上 | L34: Default | N34: =O34+0&","&P34+0 -> -7,12 | O34: -7 | P34: 12 | Q34: =_xlfn.LET(_xlpm._default,1, _xlpm._custom,R34, IF($A34<>"",IF(_xlpm._custom<>"",_xlpm._custom,_xlpm._default),"")) -> 1 | S34: 4 | T34: =IF(U34<>"", U34+0&","&V34+0,"") -> 1,2 | U34: 1 | V34: 2 | W34: 0 | X34: 11 | Y34: =IF($A34<>"",IF($Z34<>"",$Z34,"0,0"),"") -> 0,0 | AA34: =IF($A34<>"",IF($AB34<>"",$AB34,"80,120"),"") -> 80,120 | AC34: 1.24 | AD34: 0.06 | AE34: 1.2 | AF34: 1 | AG34: 5.5
C35: =_xlfn.TEXTJOIN(",",1,A35:B35) | I35: =IFERROR(VLOOKUP(H35,monsters[#All],4,0),"") | J35: {=_xlfn.LET(_xlpm.v6p,ABS(ATAN2(O35,P35))*6/PI(), _xlpm.output,_xlfn.IFS(_xlpm.v6p<1,"正前",_xlpm.v6p>5,"正后",AND(_xlpm.v6p<5,_xlpm.v6p>2,P35<-1),"脚底",_xlpm.v6p>4,"后上",_xlpm.v6p<2,"前上",TRUE,"顶部"), IFERROR(_xlpm.output,""))} | Q35: =_xlfn.LET(_xlpm._default,1, _xlpm._custom,R35, IF($A35<>"",IF(_xlpm._custom<>"",_xlpm._custom,_xlpm._default),"")) | T35: =IF(U35<>"", U35+0&","&V35+0,"") | Y35: =IF($A35<>"",IF($Z35<>"",$Z35,"0,0"),"") | AA35: =IF($A35<>"",IF($AB35<>"",$AB35,"80,120"),"")
A36: 1 | B36: {=D36&_xlfn.TEXTJOIN("",1,TEXT(E36:G36,"00"))} -> 6010001 | C36: =_xlfn.TEXTJOIN(",",1,A36:B36) -> 1,6010001 | D36: 6 | E36: 1 | F36: =W36 -> 0 | G36: 1 | H36: 201105 | I36: =IFERROR(VLOOKUP(H36,monsters[#All],4,0),"") -> 跳虫骑手 | J36: {=_xlfn.LET(_xlpm.v6p,ABS(ATAN2(O36,P36))*6/PI(), _xlpm.output,_xlfn.IFS(_xlpm.v6p<1,"正前",_xlpm.v6p>5,"正后",AND(_xlpm.v6p<5,_xlpm.v6p>2,P36<-1),"脚底",_xlpm.v6p>4,"后上",_xlpm.v6p<2,"前上",TRUE,"顶部"), IFERROR(_xlpm.output,""))} -> 正前 | L36: Default | N36: =O36+0&","&P36+0 -> 14,-1 | O36: 14 | P36: -1 | Q36: =_xlfn.LET(_xlpm._default,1, _xlpm._custom,R36, IF($A36<>"",IF(_xlpm._custom<>"",_xlpm._custom,_xlpm._default),"")) -> 1 | S36: 8 | T36: =IF(U36<>"", U36+0&","&V36+0,"") | W36: 0 | X36: 11 | Y36: =IF($A36<>"",IF($Z36<>"",$Z36,"0,0"),"") -> 0,0 | AA36: =IF($A36<>"",IF($AB36<>"",$AB36,"80,120"),"") -> 80,120 | AC36: 2.44 | AD36: 0.11 | AE36: 1.2
C37: =_xlfn.TEXTJOIN(",",1,A37:B37) | I37: =IFERROR(VLOOKUP(H37,monsters[#All],4,0),"") | J37: {=_xlfn.LET(_xlpm.v6p,ABS(ATAN2(O37,P37))*6/PI(), _xlpm.output,_xlfn.IFS(_xlpm.v6p<1,"正前",_xlpm.v6p>5,"正后",AND(_xlpm.v6p<5,_xlpm.v6p>2,P37<-1),"脚底",_xlpm.v6p>4,"后上",_xlpm.v6p<2,"前上",TRUE,"顶部"), IFERROR(_xlpm.output,""))} | Q37: =_xlfn.LET(_xlpm._default,1, _xlpm._custom,R37, IF($A37<>"",IF(_xlpm._custom<>"",_xlpm._custom,_xlpm._default),"")) | T37: =IF(U37<>"", U37+0&","&V37+0,"") | Y37: =IF($A37<>"",IF($Z37<>"",$Z37,"0,0"),"") | AA37: =IF($A37<>"",IF($AB37<>"",$AB37,"80,120"),"")
A38: 1 | B38: {=D38&_xlfn.TEXTJOIN("",1,TEXT(E38:G38,"00"))} -> 7010000 | C38: =_xlfn.TEXTJOIN(",",1,A38:B38) -> 1,7010000 | D38: 7 | E38: 1 | F38: 0 | G38: 0 | H38: 201104 | I38: =IFERROR(VLOOKUP(H38,monsters[#All],4,0),"") -> 地宫洞穴人 | J38: {=_xlfn.LET(_xlpm.v6p,ABS(ATAN2(O38,P38))*6/PI(), _xlpm.output,_xlfn.IFS(_xlpm.v6p<1,"正前",_xlpm.v6p>5,"正后",AND(_xlpm.v6p<5,_xlpm.v6p>2,P38<-1),"脚底",_xlpm.v6p>4,"后上",_xlpm.v6p<2,"前上",TRUE,"顶部"), IFERROR(_xlpm.output,""))} -> 正前 | L38: Default | N38: =O38+0&","&P38+0 -> 18,-1 | O38: 18 | P38: -1 | Q38: =_xlfn.LET(_xlpm._default,1, _xlpm._custom,R38, IF($A38<>"",IF(_xlpm._custom<>"",_xlpm._custom,_xlpm._default),"")) -> 1 | S38: 16 | T38: =IF(U38<>"", U38+0&","&V38+0,"") -> 2,3 | U38: 2 | V38: 3 | W38: 0 | X38: 11 | Y38: =IF($A38<>"",IF($Z38<>"",$Z38,"0,0"),"") -> 0,0 | AA38: =IF($A38<>"",IF($AB38<>"",$AB38,"80,120"),"") -> 80,120 | AC38: 0.4 | AD38: 0.4 | AE38: 1
A39: 1 | B39: {=D39&_xlfn.TEXTJOIN("",1,TEXT(E39:G39,"00"))} -> 7020001 | C39: =_xlfn.TEXTJOIN(",",1,A39:B39) -> 1,7020001 | D39: 7 | E39: 2 | F39: 0 | G39: 1 | H39: 201104 | I39: =IFERROR(VLOOKUP(H39,monsters[#All],4,0),"") -> 地宫洞穴人 | J39: {=_xlfn.LET(_xlpm.v6p,ABS(ATAN2(O39,P39))*6/PI(), _xlpm.output,_xlfn.IFS(_xlpm.v6p<1,"正前",_xlpm.v6p>5,"正后",AND(_xlpm.v6p<5,_xlpm.v6p>2,P39<-1),"脚底",_xlpm.v6p>4,"后上",_xlpm.v6p<2,"前上",TRUE,"顶部"), IFERROR(_xlpm.output,""))} -> 正前 | L39: Default | N39: =O39+0&","&P39+0 -> 18,-1 | O39: 18 | P39: -1 | Q39: =_xlfn.LET(_xlpm._default,1, _xlpm._custom,R39, IF($A39<>"",IF(_xlpm._custom<>"",_xlpm._custom,_xlpm._default),"")) -> 1 | T39: =IF(U39<>"", U39+0&","&V39+0,"") -> 2,3 | U39: 2 | V39: 3 | W39: 0 | X39: 11 | Y39: =IF($A39<>"",IF($Z39<>"",$Z39,"0,0"),"") -> 0,0 | AA39: =IF($A39<>"",IF($AB39<>"",$AB39,"80,120"),"") -> 80,120 | AF39: 1 | AG39: 10.2
A40: 1 | B40: {=D40&_xlfn.TEXTJOIN("",1,TEXT(E40:G40,"00"))} -> 7020002 | C40: =_xlfn.TEXTJOIN(",",1,A40:B40) -> 1,7020002 | D40: 7 | E40: 2 | F40: 0 | G40: 2 | H40: 201104 | I40: =IFERROR(VLOOKUP(H40,monsters[#All],4,0),"") -> 地宫洞穴人 | J40: {=_xlfn.LET(_xlpm.v6p,ABS(ATAN2(O40,P40))*6/PI(), _xlpm.output,_xlfn.IFS(_xlpm.v6p<1,"正前",_xlpm.v6p>5,"正后",AND(_xlpm.v6p<5,_xlpm.v6p>2,P40<-1),"脚底",_xlpm.v6p>4,"后上",_xlpm.v6p<2,"前上",TRUE,"顶部"), IFERROR(_xlpm.output,""))} -> 正后 | L40: Default | N40: =O40+0&","&P40+0 -> -14,-1 | O40: -14 | P40: -1 | Q40: =_xlfn.LET(_xlpm._default,1, _xlpm._custom,R40, IF($A40<>"",IF(_xlpm._custom<>"",_xlpm._custom,_xlpm._default),"")) -> 1 | T40: =IF(U40<>"", U40+0&","&V40+0,"") -> 2,3 | U40: 2 | V40: 3 | W40: 0 | X40: 11 | Y40: =IF($A40<>"",IF($Z40<>"",$Z40,"0,0"),"") -> 0,0 | AA40: =IF($A40<>"",IF($AB40<>"",$AB40,"80,120"),"") -> 80,120 | AF40: 1 | AG40: 6.8
...

Sheet -配置辅助
H5: Config
B6: 怪物id | C6: 怪物名称 | D6: 备注1 地区 | E6: 备注2 名称 | F6: HP | H6: key | I6: value | J6: 单位 | M6: 世界 | N6: 色号
B7: 201101 | C7: enemy_201101 | D7: 地宫 | E7: 地宫蝙蝠 | F7: 26 | H7: 基础关卡长度 | I7: 300 | J7: unity unit | M7: 地宫 | N7: #D0CECE
B8: 201102 | C8: enemy_201102 | D8: 地宫 | E8: 自爆甲虫 | F8: 2 | H8: 稳态.单位距离 | I8: 100 | J8: unity unit | M8: 树梢 | N8: #FFC9FF
B9: 201103 | C9: enemy_201103 | D9: 地宫 | E9: 跳虫 | F9: 44 | H9: 稳态.基础速度 | I9: 6 | J9: unit / sec | M9: 荒漠 | N9: #FFE699
B10: 201104 | C10: enemy_201104 | D10: 地宫 | E10: 地宫洞穴人 | F10: 66 | H10: 稳态.单位时间 | I10: =I8/I9 -> 16.666667 | J10: sec | M10: 大湖 | N10: #B4C6E7
B11: 201105 | C11: enemy_201105 | D11: 地宫 | E11: 跳虫骑手 | F11: 55
B12: 201106 | C12: enemy_201106 | D12: 地宫 | E12: 蝙蝠骑手 | F12: 33
B13: 201107 | C13: enemy_201107 | D13: 地宫 | E13: 流浪洞穴人 | F13: 44
B14: 201108 | C14: enemy_201108 | D14: 地宫 | E14: 纵火洞穴人 | F14: 52
B15: 201109 | C15: enemy_201109 | D15: 地宫 | E15: 暴徒洞穴人 | F15: 59 | H15: Purchasing Enemy
H16: 追兵等级 | I16: 临界速度 | J16: 最大值速度 | K16: 生成速率
B17: 201401 | C17: enemy_201401 | D17: 树梢 | E17: 古灯 | F17: -1 | H17: 1 | I17: 2.6 | J17: 0.5 | K17: 0.6
B18: 201402 | C18: enemy_201402 | D18: 树梢 | E18: 毒刺果实丛 | F18: -1 | H18: 2 | I18: 3.2 | J18: 1 | K18: 0.8
B19: 201403 | C19: enemy_201403 | D19: 树梢 | E19: 毒刺果实 | F19: -1 | H19: 3 | I19: 3.8 | J19: 1.5 | K19: 1
B20: 201404 | C20: enemy_201404 | D20: 树梢 | E20: 画中仙 | F20: -1 | H20: 4 | I20: 4.4 | J20: 2 | K20: 1.2
B21: 201405 | C21: enemy_201405 | D21: 树梢 | E21: 鱼妖 | F21: 10 | H21: 5 | I21: 5 | J21: 2.5 | K21: 1.4
B22: 201406 | C22: enemy_201406 | D22: 树梢 | E22: 鬼瓮 | F22: 1
B23: 201407 | C23: enemy_201407 | D23: 树梢 | E23: 鬼狰 | F23: 6
B24: 201408 | C24: enemy_201408 | D24: 树梢 | E24: 铁针鸟 | F24: -1
B25: 201409 | C25: enemy_201409 | D25: 树梢 | E25: 密林松鼠 | F25: -1
B26: 201410 | C26: enemy_201410 | D26: 树梢 | E26: 暴躁金尾猴 | F26: -1
B27: 201411 | C27: enemy_201411 | D27: 树梢 | E27: 祖蜂 | F27: -1
B28: 201412 | C28: enemy_201412 | D28: 树梢 | E28: 幼祖蜂 | F28: -1
B29: 201413 | C29: enemy_201413 | D29: 树梢 | E29: 春花雀（蓝） | F29: -1
B30: 201414 | C30: enemy_201414 | D30: 树梢 | E30: 春花雀（红） | F30: -1
B31: 201415 | C31: enemy_201415 | D31: 树梢 | E31: 春花雀（黄） | F31: -1
B32: 201416 | C32: enemy_201416 | D32: 树梢 | E32: 绿枝粟粟民 | F32: -1
B33: 201417 | C33: enemy_201417 | D33: 树梢 | E33: 悬铃粟粟民 | F33: -1
... B73: 211112 | C73: enemy_211112 | D73: 地宫 | E73: 地宫装甲车-远程 | F73: -1
F74: -1
B75: 219999 | C75: enemy_219999 | D75: 地宫 | E75: 测试敌人车 | F75: -1
F76: -1
B77: 209000 | C77: enemy_209000 | E77: 测试蝙蝠 | F77: -1
B78: 209001 | C78: enemy_209001 | E78: 测试蝙蝠_盘旋 | F78: -1

Sheet -id 配置说明
A1: 第1位 | B1: 第2位 | C1: 第3位 | D1: 第4位 | E1: 第5位 | F1: 第6位 | G1: 第7位 | H1: 第8位
A2: 42 = scene | C2: 01 = 地宫关卡 | E2: 00 = 初始场景固定怪与追兵 | G2: 00~99 难度细分编号
C3: 04 = 树梢关卡 | E3: 01-49 = 普通怪
C4: 07 = 荒漠关卡 | E4: 50-79 = 精英怪
C5: 08 = 大湖关卡 | E5: 80-99 = Boss
C8: 99 = Demo大湖关卡 | E8: 01 = 关卡场景1 怪物组
E9: 02 = 关卡场景2 怪物组
E10: 03 = 关卡场景3 怪物组
E11: 04 = 关卡场景4 怪物组 | G11: 01 = 段1 似目草前
G12: 02 = 段2 似目草100m
G13: 03 = 段1 似目草后
E14: 05 = 关卡场景5 怪物组 | G14: 01 = 段1 似目草前
G15: 02 = 段2 似目草200m
G16: 03 = 段1 似目草后
E17: 06 = 关卡场景6 怪物组
