Workbook
Name _richtext_i: _xlfn.LAMBDA(_xlpm.x,IF(_xlpm.x<>"","<i>"&_xlpm.x&"</i>",""))
Name locate: _xlfn.LAMBDA(_xlpm.col_relative,_xlpm.rows,"RC["&_xlpm.col_relative&"]:R["&_xlpm.rows-1&"]C["&_xlpm.col_relative&"]")

Sheet weather
A1: id | F1: name | G1: desc | M1: weather_icon_path | N1: view_prefab | O1: mask_prefab | P1: monsters | Q1: heal_tags | R1: monster_HOT | S1: buff_remove | T1: behaviour | U1: diy_prms
A2: uint key | F2: string | G2: string | M2: string | N2: string | O2: string | P2: uint | Q2: string[] | R2: (float,float,float) | S2: string[] | T2: string | U2: dict<string,string>
A3: 天气 id | B3: 备注 世界 | C3: 辅助 命名 | D3: 备注 天气 | E3: 辅助 命名 | F3: 天气名称 | G3: 天气描述 | H3: 天气描述 备注 | I3: 场景desc | J3: 效果desc1 | K3: 效果desc2 | L3: 效果desc3 | M3: 天气icon | N3: 表现用prefab | O3: 遮罩prefab | P3: 生成怪物 | Q3: 治愈标签 | R3: 对特定怪物 heal over time (对普通怪的治疗百分比，对精英怪的治疗百分比，间隔秒) | S3: 移除buff | T3: 天气脚本 | U3: 自定义变量
A4: 0 | B4: 通用 | C4: general | D4: 晴 | E4: sunny | F4: =_xlfn.LET(_xlpm._id,$A4,_xlpm._output,_xlfn.TEXTJOIN("_",1,"weather_name",_xlpm._id),IF(_xlpm._id<>"",_xlpm._output,"")) -> weather_name_0 | G4: =_xlfn.LET(_xlpm._id,$A4,_xlpm._output,_xlfn.TEXTJOIN("_",1,"weather_desc",_xlpm._id),IF(_xlpm._id<>"",_xlpm._output,"")) -> weather_desc_0 | H4: =_xlfn.TEXTJOIN("<br>",1,IF(I4<>"",I4&"<br>",""),_richtext_i(J4:L4)) -> 飞星不动，脱水脱水。<br><br><i>无特殊效果</i> | I4: 飞星不动，脱水脱水。 | J4: 无特殊效果 | M4: =_xlfn.LET(_xlpm._id,$A4,_xlpm._output,_xlfn.TEXTJOIN("_",1,"ui_icon_weather",_xlpm._id),IF(_xlpm._id<>"",_xlpm._output,"")) -> ui_icon_weather_0
F5: =_xlfn.LET(_xlpm._id,$A5,_xlpm._output,_xlfn.TEXTJOIN("_",1,"weather_name",_xlpm._id),IF(_xlpm._id<>"",_xlpm._output,"")) | G5: =_xlfn.LET(_xlpm._id,$A5,_xlpm._output,_xlfn.TEXTJOIN("_",1,"weather_desc",_xlpm._id),IF(_xlpm._id<>"",_xlpm._output,"")) | H5: =_xlfn.TEXTJOIN("<br>",1,IF(I5<>"",I5&"<br>",""),_richtext_i(J5:L5)) | M5: =_xlfn.LET(_xlpm._id,$A5,_xlpm._output,_xlfn.TEXTJOIN("_",1,"ui_icon_weather",_xlpm._id),IF(_xlpm._id<>"",_xlpm._output,""))
A6: 460100 | B6: 通用 | C6: dungeon | D6: 未知 | E6: unknown | F6: =_xlfn.LET(_xlpm._id,$A6,_xlpm._output,_xlfn.TEXTJOIN("_",1,"weather_name",_xlpm._id),IF(_xlpm._id<>"",_xlpm._output,"")) -> weather_name_460100 | G6: =_xlfn.LET(_xlpm._id,$A6,_xlpm._output,_xlfn.TEXTJOIN("_",1,"weather_desc",_xlpm._id),IF(_xlpm._id<>"",_xlpm._output,"")) -> weather_desc_460100 | H6: =_xlfn.TEXTJOIN("<br>",1,IF(I6<>"",I6&"<br>",""),_richtext_i(J6:L6)) -> 九幽之下，不见天日。<br><br><i>无特殊效果</i> | I6: 九幽之下，不见天日。 | J6: 无特殊效果 | M6: =_xlfn.LET(_xlpm._id,$A6,_xlpm._output,_xlfn.TEXTJOIN("_",1,"ui_icon_weather",_xlpm._id),IF(_xlpm._id<>"",_xlpm._output,"")) -> ui_icon_weather_460100
H7: =_xlfn.TEXTJOIN("<br>",1,IF(I7<>"",I7&"<br>",""),_richtext_i(J7:L7))
A8: 460400 | B8: 通用 | C8: treetop | D8: 晴空 | E8: sunny | F8: =_xlfn.LET(_xlpm._id,$A8,_xlpm._output,_xlfn.TEXTJOIN("_",1,"weather_name",_xlpm._id),IF(_xlpm._id<>"",_xlpm._output,"")) -> weather_name_460400 | G8: =_xlfn.LET(_xlpm._id,$A8,_xlpm._output,_xlfn.TEXTJOIN("_",1,"weather_desc",_xlpm._id),IF(_xlpm._id<>"",_xlpm._output,"")) -> weather_desc_460400 | H8: =_xlfn.TEXTJOIN("<br>",1,IF(I8<>"",I8&"<br>",""),_richtext_i(J8:L8)) -> 日照芳林，金光如霰。<br><br><i>无特殊效果</i> | I8: 日照芳林，金光如霰。 | J8: 无特殊效果 | M8: ui_icon_weather_0
A9: 460401 | B9: 树梢 | C9: treetop | D9: 薄雾 | E9: mist | F9: =_xlfn.LET(_xlpm._id,$A9,_xlpm._output,_xlfn.TEXTJOIN("_",1,"weather_name",_xlpm._id),IF(_xlpm._id<>"",_xlpm._output,"")) -> weather_name_460401 | G9: =_xlfn.LET(_xlpm._id,$A9,_xlpm._output,_xlfn.TEXTJOIN("_",1,"weather_desc",_xlpm._id),IF(_xlpm._id<>"",_xlpm._output,"")) -> weather_desc_460401 | H9: =_xlfn.TEXTJOIN("<br>",1,IF(I9<>"",I9&"<br>",""),_richtext_i(J9:L9)) -> 薄雾朦胧，如梦似幻。<br><br><i>限制视野范围（轻微）</i> | I9: 薄雾朦胧，如梦似幻。 | J9: 限制视野范围（轻微） | M9: =_xlfn.LET(_xlpm._id,$A9,_xlpm._output,_xlfn.TEXTJOIN("_",1,"ui_icon_weather",_xlpm._id),IF(_xlpm._id<>"",_xlpm._output,"")) -> ui_icon_weather_460401 | N9: =_xlfn.TEXTJOIN("_",1,"weather",$A9,$C9,$E9) -> weather_460401_treetop_mist
A10: 460402 | B10: 树梢 | C10: treetop | D10: 浓雾 | E10: fog | F10: =_xlfn.LET(_xlpm._id,$A10,_xlpm._output,_xlfn.TEXTJOIN("_",1,"weather_name",_xlpm._id),IF(_xlpm._id<>"",_xlpm._output,"")) -> weather_name_460402 | G10: =_xlfn.LET(_xlpm._id,$A10,_xlpm._output,_xlfn.TEXTJOIN("_",1,"weather_desc",_xlpm._id),IF(_xlpm._id<>"",_xlpm._output,"")) -> weather_desc_460402 | H10: =_xlfn.TEXTJOIN("<br>",1,IF(I10<>"",I10&"<br>",""),_richtext_i(J10:L10)) -> 林雾环绕，鸟兽隐现。<br><br><i>限制视野范围（中等）</i><br><i>浓雾中刷出各种丛林生物</i> | I10: 林雾环绕，鸟兽隐现。 | J10: 限制视野范围（中等） | K10: 浓雾中刷出各种丛林生物 | M10: =_xlfn.LET(_xlpm._id,$A10,_xlpm._output,_xlfn.TEXTJOIN("_",1,"ui_icon_weather",_xlpm._id),IF(_xlpm._id<>"",_xlpm._output,"")) -> ui_icon_weather_460402 | N10: =_xlfn.TEXTJOIN("_",1,"weather",$A10,$C10,$E10) -> weather_460402_treetop_fog | P10: =A10 -> 460402
A11: 460403 | B11: 树梢 | C11: treetop | D11: 黑色妖雾 | E11: black_fog | F11: =_xlfn.LET(_xlpm._id,$A11,_xlpm._output,_xlfn.TEXTJOIN("_",1,"weather_name",_xlpm._id),IF(_xlpm._id<>"",_xlpm._output,"")) -> weather_name_460403 | G11: =_xlfn.LET(_xlpm._id,$A11,_xlpm._output,_xlfn.TEXTJOIN("_",1,"weather_desc",_xlpm._id),IF(_xlpm._id<>"",_xlpm._output,"")) -> weather_desc_460403 | H11: =_xlfn.TEXTJOIN("<br>",1,IF(I11<>"",I11&"<br>",""),_richtext_i(J11:L11)) -> 妖雾乍起，妖邪初现。<br><br><i>限制视野范围（中等）</i><br><i>浓雾中刷出各种魔物</i> | I11: 妖雾乍起，妖邪初现。 | J11: 限制视野范围（中等） | K11: 浓雾中刷出各种魔物 | M11: =_xlfn.LET(_xlpm._id,$A11,_xlpm._output,_xlfn.TEXTJOIN("_",1,"ui_icon_weather",_xlpm._id),IF(_xlpm._id<>"",_xlpm._output,"")) -> ui_icon_weather_460403 | N11: =_xlfn.TEXTJOIN("_",1,"weather",$A11,$C11,$E11) -> weather_460403_treetop_black_fog | P11: =A11 -> 460403
A12: 460404 | B12: 树梢 | C12: treetop | D12: 浓厚妖雾 | E12: thick_black_fog | F12: =_xlfn.LET(_xlpm._id,$A12,_xlpm._output,_xlfn.TEXTJOIN("_",1,"weather_name",_xlpm._id),IF(_xlpm._id<>"",_xlpm._output,"")) -> weather_name_460404 | G12: =_xlfn.LET(_xlpm._id,$A12,_xlpm._output,_xlfn.TEXTJOIN("_",1,"weather_desc",_xlpm._id),IF(_xlpm._id<>"",_xlpm._output,"")) -> weather_desc_460404 | H12: =_xlfn.TEXTJOIN("<br>",1,IF(I12<>"",I12&"<br>",""),_richtext_i(J12:L12)) -> 浓雾弥漫，鬼魅丛生。<br><br><i>限制视野范围（中等）</i><br><i>浓雾中刷出各种魔物</i><br><i>所有魔物快速回血</i> | I12: 浓雾弥漫，鬼魅丛生。 | J12: 限制视野范围（中等） | K12: 浓雾中刷出各种魔物 | L12: 所有魔物快速回血 | M12: =_xlfn.LET(_xlpm._id,$A12,_xlpm._output,_xlfn.TEXTJOIN("_",1,"ui_icon_weather",_xlpm._id),IF(_xlpm._id<>"",_xlpm._output,"")) -> ui_icon_weather_460404 | N12: =_xlfn.TEXTJOIN("_",1,"weather",$A12,$C12,$E12) -> weather_460404_treetop_thick_black_fog | P12: =A12 -> 460404 | R12: 0.04~0.04~3
F13: =_xlfn.LET(_xlpm._id,$A13,_xlpm._output,_xlfn.TEXTJOIN("_",1,"weather_name",_xlpm._id),IF(_xlpm._id<>"",_xlpm._output,"")) | G13: =_xlfn.LET(_xlpm._id,$A13,_xlpm._output,_xlfn.TEXTJOIN("_",1,"weather_desc",_xlpm._id),IF(_xlpm._id<>"",_xlpm._output,"")) | H13: =_xlfn.TEXTJOIN("<br>",1,IF(I13<>"",I13&"<br>",""),_richtext_i(J13:L13)) | M13: =_xlfn.LET(_xlpm._id,$A13,_xlpm._output,_xlfn.TEXTJOIN("_",1,"ui_icon_weather",_xlpm._id),IF(_xlpm._id<>"",_xlpm._output,""))
A14: 460700 | B14: 荒漠 | C14: desert | D14: 曝晒 | E14: sunny | F14: =_xlfn.LET(_xlpm._id,$A14,_xlpm._output,_xlfn.TEXTJOIN("_",1,"weather_name",_xlpm._id),IF(_xlpm._id<>"",_xlpm._output,"")) -> weather_name_460700 | G14: =_xlfn.LET(_xlpm._id,$A14,_xlpm._output,_xlfn.TEXTJOIN("_",1,"weather_desc",_xlpm._id),IF(_xlpm._id<>"",_xlpm._output,"")) -> weather_desc_460700 | H14: =_xlfn.TEXTJOIN("<br>",1,IF(I14<>"",I14&"<br>",""),_richtext_i(J14:L14)) -> 烈日当空，赤地千里。<br><br><i>无特殊效果</i> | I14: 烈日当空，赤地千里。 | J14: 无特殊效果 | M14: ui_icon_weather_0
A15: 460701 | B15: 荒漠 | C15: desert | D15: 扬尘 | E15: fugitive_dust | F15: =_xlfn.LET(_xlpm._id,$A15,_xlpm._output,_xlfn.TEXTJOIN("_",1,"weather_name",_xlpm._id),IF(_xlpm._id<>"",_xlpm._output,"")) -> weather_name_460701 | G15: =_xlfn.LET(_xlpm._id,$A15,_xlpm._output,_xlfn.TEXTJOIN("_",1,"weather_desc",_xlpm._id),IF(_xlpm._id<>"",_xlpm._output,"")) -> weather_desc_460701 | H15: =_xlfn.TEXTJOIN("<br>",1,IF(I15<>"",I15&"<br>",""),_richtext_i(J15:L15)) -> 扬尘四起，八方迷离。<br><br><i>所有飞射物额外产生20%未命中几率。</i> | I15: 扬尘四起，八方迷离。 | J15: 所有飞射物额外产生20%未命中几率。 | M15: =_xlfn.LET(_xlpm._id,$A15,_xlpm._output,_xlfn.TEXTJOIN("_",1,"ui_icon_weather",_xlpm._id),IF(_xlpm._id<>"",_xlpm._output,"")) -> ui_icon_weather_460701 | N15: =_xlfn.TEXTJOIN("_",1,"weather",$A15,$C15,$E15) -> weather_460701_desert_fugitive_dust
A16: 460702 | B16: 荒漠 | C16: desert | D16: 沙暴 | E16: sand_storm | F16: =_xlfn.LET(_xlpm._id,$A16,_xlpm._output,_xlfn.TEXTJOIN("_",1,"weather_name",_xlpm._id),IF(_xlpm._id<>"",_xlpm._output,"")) -> weather_name_460702 | G16: =_xlfn.LET(_xlpm._id,$A16,_xlpm._output,_xlfn.TEXTJOIN("_",1,"weather_desc",_xlpm._id),IF(_xlpm._id<>"",_xlpm._output,"")) -> weather_desc_460702 | H16: =_xlfn.TEXTJOIN("<br>",1,IF(I16<>"",I16&"<br>",""),_richtext_i(J16:L16)) -> 沙暴肆虐，遮天蔽日。<br><br><i>所有飞射物额外产生80%未命中几率。</i> | I16: 沙暴肆虐，遮天蔽日。 | J16: 所有飞射物额外产生80%未命中几率。 | M16: =_xlfn.LET(_xlpm._id,$A16,_xlpm._output,_xlfn.TEXTJOIN("_",1,"ui_icon_weather",_xlpm._id),IF(_xlpm._id<>"",_xlpm._output,"")) -> ui_icon_weather_460702 | N16: =_xlfn.TEXTJOIN("_",1,"weather",$A16,$C16,$E16) -> weather_460702_desert_sand_storm
A17: 460703 | B17: 荒漠 | C17: desert | D17: 积沙 | E17: quicksand | F17: =_xlfn.LET(_xlpm._id,$A17,_xlpm._output,_xlfn.TEXTJOIN("_",1,"weather_name",_xlpm._id),IF(_xlpm._id<>"",_xlpm._output,"")) -> weather_name_460703 | G17: =_xlfn.LET(_xlpm._id,$A17,_xlpm._output,_xlfn.TEXTJOIN("_",1,"weather_desc",_xlpm._id),IF(_xlpm._id<>"",_xlpm._output,"")) -> weather_desc_460703 | H17: =_xlfn.TEXTJOIN("<br>",1,IF(I17<>"",I17&"<br>",""),_richtext_i(J17:L17)) -> 遍地积沙，长路难行。<br><br><i>减缓车辆移速。</i><br><i>周期性从流沙中生成沙漠蛇与毒蝎。</i> | I17: 遍地积沙，长路难行。 | J17: 减缓车辆移速。 | K17: 周期性从流沙中生成沙漠蛇与毒蝎。 | M17: =_xlfn.LET(_xlpm._id,$A17,_xlpm._output,_xlfn.TEXTJOIN("_",1,"ui_icon_weather",_xlpm._id),IF(_xlpm._id<>"",_xlpm._output,"")) -> ui_icon_weather_460703 | N17: =_xlfn.TEXTJOIN("_",1,"weather",$A17,$C17,$E17) -> weather_460703_desert_quicksand | P17: =A17 -> 460703
A18: 460704 | B18: 荒漠 | C18: desert | D18: 积沙，扬尘 | E18: qs_and_fd | F18: =_xlfn.LET(_xlpm._id,$A18,_xlpm._output,_xlfn.TEXTJOIN("_",1,"weather_name",_xlpm._id),IF(_xlpm._id<>"",_xlpm._output,"")) -> weather_name_460704 | G18: =_xlfn.LET(_xlpm._id,$A18,_xlpm._output,_xlfn.TEXTJOIN("_",1,"weather_desc",_xlpm._id),IF(_xlpm._id<>"",_xlpm._output,"")) -> weather_desc_460704 | H18: =_xlfn.TEXTJOIN("<br>",1,IF(I18<>"",I18&"<br>",""),_richtext_i(J18:L18)) -> 流沙在下，扬尘在前。<br><br><i>减缓车辆移速。</i><br><i>周期性从流沙中生成沙漠蛇与毒蝎。</i><br><i>所有飞射物额外产生30%未命中几率。</i> | I18: 流沙在下，扬尘在前。 | J18: 减缓车辆移速。 | K18: 周期性从流沙中生成沙漠蛇与毒蝎。 | L18: 所有飞射物额外产生30%未命中几率。 | M18: =_xlfn.LET(_xlpm._id,$A18,_xlpm._output,_xlfn.TEXTJOIN("_",1,"ui_icon_weather",_xlpm._id),IF(_xlpm._id<>"",_xlpm._output,"")) -> ui_icon_weather_460704 | N18: =_xlfn.TEXTJOIN("_",1,"weather",$A18,$C18,$E18) -> weather_460704_desert_qs_and_fd | P18: =A18 -> 460704
A19: 460705 | B19: 荒漠 | C19: desert | D19: 积沙，沙暴 | E19: qs_and_ss | F19: =_xlfn.LET(_xlpm._id,$A19,_xlpm._output,_xlfn.TEXTJOIN("_",1,"weather_name",_xlpm._id),IF(_xlpm._id<>"",_xlpm._output,"")) -> weather_name_460705 | G19: =_xlfn.LET(_xlpm._id,$A19,_xlpm._output,_xlfn.TEXTJOIN("_",1,"weather_desc",_xlpm._id),IF(_xlpm._id<>"",_xlpm._output,"")) -> weather_desc_460705 | H19: =_xlfn.TEXTJOIN("<br>",1,IF(I19<>"",I19&"<br>",""),_richtext_i(J19:L19)) -> 困于深沙，陷于尘暴。<br><br><i>减缓车辆移速。</i><br><i>周期性从流沙中生成沙漠蛇与毒蝎。</i><br><i>所有飞射物额外产生80%未命中几率。</i> | I19: 困于深沙，陷于尘暴。 | J19: 减缓车辆移速。 | K19: 周期性从流沙中生成沙漠蛇与毒蝎。 | L19: 所有飞射物额外产生80%未命中几率。 | M19: =_xlfn.LET(_xlpm._id,$A19,_xlpm._output,_xlfn.TEXTJOIN("_",1,"ui_icon_weather",_xlpm._id),IF(_xlpm._id<>"",_xlpm._output,"")) -> ui_icon_weather_460705 | N19: =_xlfn.TEXTJOIN("_",1,"weather",$A19,$C19,$E19) -> weather_460705_desert_qs_and_ss | P19: =A19 -> 460705
F20: =_xlfn.LET(_xlpm._id,$A20,_xlpm._output,_xlfn.TEXTJOIN("_",1,"weather_name",_xlpm._id),IF(_xlpm._id<>"",_xlpm._output,"")) | G20: =_xlfn.LET(_xlpm._id,$A20,_xlpm._output,_xlfn.TEXTJOIN("_",1,"weather_desc",_xlpm._id),IF(_xlpm._id<>"",_xlpm._output,"")) | H20: =_xlfn.TEXTJOIN("<br>",1,IF(I20<>"",I20&"<br>",""),_richtext_i(J20:L20)) | M20: =_xlfn.LET(_xlpm._id,$A20,_xlpm._output,_xlfn.TEXTJOIN("_",1,"ui_icon_weather",_xlpm._id),IF(_xlpm._id<>"",_xlpm._output,""))
A21: 460800 | B21: 大湖 | C21: lake | D21: 暖阳 | E21: sunny | F21: =_xlfn.LET(_xlpm._id,$A21,_xlpm._output,_xlfn.TEXTJOIN("_",1,"weather_name",_xlpm._id),IF(_xlpm._id<>"",_xlpm._output,"")) -> weather_name_460800 | G21: =_xlfn.LET(_xlpm._id,$A21,_xlpm._output,_xlfn.TEXTJOIN("_",1,"weather_desc",_xlpm._id),IF(_xlpm._id<>"",_xlpm._output,"")) -> weather_desc_460800 | H21: =_xlfn.TEXTJOIN("<br>",1,IF(I21<>"",I21&"<br>",""),_richtext_i(J21:L21)) -> 暖阳高照，正当其时。<br><br><i>无特殊效果</i> | I21: 暖阳高照，正当其时。 | J21: 无特殊效果 | M21: ui_icon_weather_0
A22: 460801 | B22: 大湖 | C22: lake | D22: 阴天 | E22: dark_clouds | F22: =_xlfn.LET(_xlpm._id,$A22,_xlpm._output,_xlfn.TEXTJOIN("_",1,"weather_name",_xlpm._id),IF(_xlpm._id<>"",_xlpm._output,"")) -> weather_name_460801 | G22: =_xlfn.LET(_xlpm._id,$A22,_xlpm._output,_xlfn.TEXTJOIN("_",1,"weather_desc",_xlpm._id),IF(_xlpm._id<>"",_xlpm._output,"")) -> weather_desc_460801 | H22: =_xlfn.TEXTJOIN("<br>",1,IF(I22<>"",I22&"<br>",""),_richtext_i(J22:L22)) -> 乌云密布，山雨欲来。<br><br><i>无特殊效果</i> | I22: 乌云密布，山雨欲来。 | J22: 无特殊效果 | M22: =_xlfn.LET(_xlpm._id,$A22,_xlpm._output,_xlfn.TEXTJOIN("_",1,"ui_icon_weather",_xlpm._id),IF(_xlpm._id<>"",_xlpm._output,"")) -> ui_icon_weather_460801 | N22: =_xlfn.TEXTJOIN("_",1,"weather",$A22,$C22,$E22) -> weather_460801_lake_dark_clouds
A23: 460802 | B23: 大湖 | C23: lake | D23: 下雨 | E23: rain | F23: =_xlfn.LET(_xlpm._id,$A23,_xlpm._output,_xlfn.TEXTJOIN("_",1,"weather_name",_xlpm._id),IF(_xlpm._id<>"",_xlpm._output,"")) -> weather_name_460802 | G23: =_xlfn.LET(_xlpm._id,$A23,_xlpm._output,_xlfn.TEXTJOIN("_",1,"weather_desc",_xlpm._id),IF(_xlpm._id<>"",_xlpm._output,"")) -> weather_desc_460802 | H23: =_xlfn.TEXTJOIN("<br>",1,IF(I23<>"",I23&"<br>",""),_richtext_i(J23:L23)) -> 细雨朦胧，润物无声。<br><br><i>所有水生生物周期性获得生命恢复。</i><br><i>持续移除场景中的燃烧与酸蚀效果。</i> | I23: 细雨朦胧，润物无声。 | J23: 所有水生生物周期性获得生命恢复。 | K23: 持续移除场景中的燃烧与酸蚀效果。 | M23: =_xlfn.LET(_xlpm._id,$A23,_xlpm._output,_xlfn.TEXTJOIN("_",1,"ui_icon_weather",_xlpm._id),IF(_xlpm._id<>"",_xlpm._output,"")) -> ui_icon_weather_460802 | N23: =_xlfn.TEXTJOIN("_",1,"weather",$A23,$C23,$E23) -> weather_460802_lake_rain | Q23: aquatic | R23: 0.045~0.003~1 | S23: fire;acid | T23: Rain
A24: 460803 | B24: 大湖 | C24: lake | D24: 暴雨 | E24: storm | F24: =_xlfn.LET(_xlpm._id,$A24,_xlpm._output,_xlfn.TEXTJOIN("_",1,"weather_name",_xlpm._id),IF(_xlpm._id<>"",_xlpm._output,"")) -> weather_name_460803 | G24: =_xlfn.LET(_xlpm._id,$A24,_xlpm._output,_xlfn.TEXTJOIN("_",1,"weather_desc",_xlpm._id),IF(_xlpm._id<>"",_xlpm._output,"")) -> weather_desc_460803 | H24: =_xlfn.TEXTJOIN("<br>",1,IF(I24<>"",I24&"<br>",""),_richtext_i(J24:L24)) -> 暴雨如注，倾盆如瀑。<br><br><i>所有水生生物周期性获得生命恢复。</i><br><i>持续移除场景中的燃烧与酸蚀效果。</i><br><i>不断有螃蟹从天空中掉下。</i> | I24: 暴雨如注，倾盆如瀑。 | J24: 所有水生生物周期性获得生命恢复。 | K24: 持续移除场景中的燃烧与酸蚀效果。 | L24: 不断有螃蟹从天空中掉下。 | M24: =_xlfn.LET(_xlpm._id,$A24,_xlpm._output,_xlfn.TEXTJOIN("_",1,"ui_icon_weather",_xlpm._id),IF(_xlpm._id<>"",_xlpm._output,"")) -> ui_icon_weather_460803 | N24: =_xlfn.TEXTJOIN("_",1,"weather",$A24,$C24,$E24) -> weather_460803_lake_storm | P24: =A24 -> 460803 | Q24: aquatic | R24: 0.06~0.004~0.75 | S24: fire;acid | T24: Rain
A25: 460804 | B25: 大湖 | C25: lake | D25: 雷暴 | E25: thunderstorm | F25: =_xlfn.LET(_xlpm._id,$A25,_xlpm._output,_xlfn.TEXTJOIN("_",1,"weather_name",_xlpm._id),IF(_xlpm._id<>"",_xlpm._output,"")) -> weather_name_460804 | G25: =_xlfn.LET(_xlpm._id,$A25,_xlpm._output,_xlfn.TEXTJOIN("_",1,"weather_desc",_xlpm._id),IF(_xlpm._id<>"",_xlpm._output,"")) -> weather_desc_460804 | H25: =_xlfn.TEXTJOIN("<br>",1,IF(I25<>"",I25&"<br>",""),_richtext_i(J25:L25)) -> 惊雷动地，霹雳破空。<br><br><i>所有水生生物周期性获得生命恢复。</i><br><i>持续移除场景中的燃烧与酸蚀效果。</i><br><i>不断有螃蟹从天空中掉下。</i> | I25: 惊雷动地，霹雳破空。 | J25: 所有水生生物周期性获得生命恢复。 | K25: 持续移除场景中的燃烧与酸蚀效果。 | L25: 不断有螃蟹从天空中掉下。 | M25: =_xlfn.LET(_xlpm._id,$A25,_xlpm._output,_xlfn.TEXTJOIN("_",1,"ui_icon_weather",_xlpm._id),IF(_xlpm._id<>"",_xlpm._output,"")) -> ui_icon_weather_460804 | N25: =_xlfn.TEXTJOIN("_",1,"weather",$A25,$C25,$E25) -> weather_460804_lake_thunderstorm | P25: =A25 -> 460804 | Q25: aquatic | R25: 0.06~0.004~0.75 | S25: fire;acid | T25: ThunderStorm | U25: dmg_stupor=10;distance_range=3,30;gap_range=0.5,3;delay=2.25

Sheet weather_group
A1: group_id | B1: sub_id | D1: weather | G1: length | J1: next
A2: uint key | B2: uint key | D2: uint | G2: (float,float) | J2: (uint,int)[]
A3: 天气组 group id key | B3: 天气组 sub id key | C3: duplicated check | D3: 天气 id | E3: 备注1 世界 | F3: 备注2 天气 名称 | G3: 随机长度 | H3: 辅助列 长度 min | I3: 辅助列 长度 max | J3: 转移至特定新天气 (子 id~概率) 圆桌概率，总值=1m | K3: 辅助列 sub id 1 | L3: 辅助列 sub id 2 | M3: 辅助列 sub id 3 | N3: 辅助列 sub id 4 | O3: 辅助列 sub id 5 | P3: 辅助列 sub id 6 | Q3: 辅助列 sub id 7 | R3: 辅助列 sub id 8 | S3: 辅助列 概率 1 | T3: 辅助列 概率 2 | U3: 辅助列 概率 3 | V3: 辅助列 概率 4 | W3: 辅助列 概率 5 | X3: 辅助列 概率 6 | Y3: 辅助列 概率 7 | Z3: 辅助列 概率 8 | AA3: 总概率 校验 | AB3: 方阵 校验
A4: 0 | B4: 0 | C4: =_xlfn.TEXTJOIN(";",1,A4,B4) -> 0;0 | D4: 0 | F4: =VLOOKUP(D4,weather!A:D,4,0) -> 晴 | G4: =H4&"~"&I4 -> 99999~99999 | H4: 99999 | I4: 99999 | J4: {=_xlfn.TEXTJOIN(";",1,_xlfn.MAP(K4:R4,S4:Z4,_xlfn.LAMBDA(_xlpm.a,_xlpm.b,IF(_xlpm.b=0,"",_xlpm.a&"~"&_xlpm.b))))} -> 0~1000000 | K4: {=_xlfn.LET(_xlpm._arr_len,COUNTIF($A:$A,$A4),_xlpm._group_row,MATCH($A4,$A:$A,0),_xlfn.MAKEARRAY(1,8,_xlfn.LAMBDA(_xlpm.x,_xlpm.y,IF(_xlpm.y>_xlpm._arr_len,"",INDEX(OFFSET($A4,_xlpm._group_row-ROW(),1,_xlpm._arr_len),_xlpm.y)))))} -> 0 | S4: 1000000 | AA4: =IF(A4<>"",IF(SUM(S4:Z4)>=1000000,"Correct","Error"),"") -> Correct | AB4: {=IF(A4<>"",IF(AND(IF(VALUE(RIGHT($S$3:$Z$3,1))>COUNTIF(A:A,A4),S4:Z4<>""=FALSE,TRUE)),"Correct","Error"),"")} -> Correct
C5: =_xlfn.TEXTJOIN(";",1,A5,B5)
A6: 420499 | B6: 1 | C6: =_xlfn.TEXTJOIN(";",1,A6,B6) -> 420499;1 | D6: 460401 | E6: 树梢 | F6: =VLOOKUP(D6,weather!A:D,4,0) -> 薄雾 | G6: =H6&"~"&I6 -> 150~235 | H6: 150 | I6: =H6*1.5+10 -> 235 | J6: {=_xlfn.TEXTJOIN(";",1,_xlfn.MAP(K6:R6,S6:Z6,_xlfn.LAMBDA(_xlpm.a,_xlpm.b,IF(_xlpm.b=0,"",_xlpm.a&"~"&_xlpm.b))))} -> 1~100000;2~700000;0~1000000 | K6: {=_xlfn.LET(_xlpm._arr_len,COUNTIF($A:$A,$A6),_xlpm._group_row,MATCH($A6,$A:$A,0),_xlfn.MAKEARRAY(1,8,_xlfn.LAMBDA(_xlpm.x,_xlpm.y,IF(_xlpm.y>_xlpm._arr_len,"",INDEX(OFFSET($A6,_xlpm._group_row-ROW(),1,_xlpm._arr_len),_xlpm.y)))))} -> 1 | L6: 2 | M6: 3 | N6: 4 | O6: 0 | S6: 100000 | T6: 700000 | W6: 1000000 | AA6: =IF(A6<>"",IF(SUM(S6:Z6)>=1000000,"Correct","Error"),"") -> Correct | AB6: {=IF(A6<>"",IF(AND(IF(VALUE(RIGHT($S$3:$Z$3,1))>COUNTIF(A:A,A6),S6:Z6<>""=FALSE,TRUE)),"Correct","Error"),"")} -> Correct
A7: 420499 | B7: 2 | C7: =_xlfn.TEXTJOIN(";",1,A7,B7) -> 420499;2 | D7: 460402 | E7: 树梢 | F7: =VLOOKUP(D7,weather!A:D,4,0) -> 浓雾 | G7: =H7&"~"&I7 -> 200~310 | H7: 200 | I7: =H7*1.5+10 -> 310 | J7: {=_xlfn.TEXTJOIN(";",1,_xlfn.MAP(K7:R7,S7:Z7,_xlfn.LAMBDA(_xlpm.a,_xlpm.b,IF(_xlpm.b=0,"",_xlpm.a&"~"&_xlpm.b))))} -> 2~100000;3~1000000 | K7: {=_xlfn.LET(_xlpm._arr_len,COUNTIF($A:$A,$A7),_xlpm._group_row,MATCH($A7,$A:$A,0),_xlfn.MAKEARRAY(1,8,_xlfn.LAMBDA(_xlpm.x,_xlpm.y,IF(_xlpm.y>_xlpm._arr_len,"",INDEX(OFFSET($A7,_xlpm._group_row-ROW(),1,_xlpm._arr_len),_xlpm.y)))))} -> 1 | L7: 2 | M7: 3 | N7: 4 | O7: 0 | T7: 100000 | U7: 1000000 | AA7: =IF(A7<>"",IF(SUM(S7:Z7)>=1000000,"Correct","Error"),"") -> Correct | AB7: {=IF(A7<>"",IF(AND(IF(VALUE(RIGHT($S$3:$Z$3,1))>COUNTIF(A:A,A7),S7:Z7<>""=FALSE,TRUE)),"Correct","Error"),"")} -> Correct
A8: 420499 | B8: 3 | C8: =_xlfn.TEXTJOIN(";",1,A8,B8) -> 420499;3 | D8: 460403 | E8: 树梢 | F8: =VLOOKUP(D8,weather!A:D,4,0) -> 黑色妖雾 | G8: =H8&"~"&I8 -> 200~310 | H8: 200 | I8: =H8*1.5+10 -> 310 | J8: {=_xlfn.TEXTJOIN(";",1,_xlfn.MAP(K8:R8,S8:Z8,_xlfn.LAMBDA(_xlpm.a,_xlpm.b,IF(_xlpm.b=0,"",_xlpm.a&"~"&_xlpm.b))))} -> 3~100000;4~1000000 | K8: {=_xlfn.LET(_xlpm._arr_len,COUNTIF($A:$A,$A8),_xlpm._group_row,MATCH($A8,$A:$A,0),_xlfn.MAKEARRAY(1,8,_xlfn.LAMBDA(_xlpm.x,_xlpm.y,IF(_xlpm.y>_xlpm._arr_len,"",INDEX(OFFSET($A8,_xlpm._group_row-ROW(),1,_xlpm._arr_len),_xlpm.y)))))} -> 1 | L8: 2 | M8: 3 | N8: 4 | O8: 0 | U8: 100000 | V8: 1000000 | AA8: =IF(A8<>"",IF(SUM(S8:Z8)>=1000000,"Correct","Error"),"") -> Correct | AB8: {=IF(A8<>"",IF(AND(IF(VALUE(RIGHT($S$3:$Z$3,1))>COUNTIF(A:A,A8),S8:Z8<>""=FALSE,TRUE)),"Correct","Error"),"")} -> Correct
A9: 420499 | B9: 4 | C9: =_xlfn.TEXTJOIN(";",1,A9,B9) -> 420499;4 | D9: 460404 | E9: 树梢 | F9: =VLOOKUP(D9,weather!A:D,4,0) -> 浓厚妖雾 | G9: =H9&"~"&I9 -> 150~235 | H9: 150 | I9: =H9*1.5+10 -> 235 | J9: {=_xlfn.TEXTJOIN(";",1,_xlfn.MAP(K9:R9,S9:Z9,_xlfn.LAMBDA(_xlpm.a,_xlpm.b,IF(_xlpm.b=0,"",_xlpm.a&"~"&_xlpm.b))))} -> 4~100000;0~1000000 | K9: {=_xlfn.LET(_xlpm._arr_len,COUNTIF($A:$A,$A9),_xlpm._group_row,MATCH($A9,$A:$A,0),_xlfn.MAKEARRAY(1,8,_xlfn.LAMBDA(_xlpm.x,_xlpm.y,IF(_xlpm.y>_xlpm._arr_len,"",INDEX(OFFSET($A9,_xlpm._group_row-ROW(),1,_xlpm._arr_len),_xlpm.y)))))} -> 1 | L9: 2 | M9: 3 | N9: 4 | O9: 0 | V9: 100000 | W9: 1000000 | AA9: =IF(A9<>"",IF(SUM(S9:Z9)>=1000000,"Correct","Error"),"") -> Correct | AB9: {=IF(A9<>"",IF(AND(IF(VALUE(RIGHT($S$3:$Z$3,1))>COUNTIF(A:A,A9),S9:Z9<>""=FALSE,TRUE)),"Correct","Error"),"")} -> Correct
A10: 420499 | B10: 0 | C10: =_xlfn.TEXTJOIN(";",1,A10,B10) -> 420499;0 | D10: 0 | E10: 树梢 | F10: =VLOOKUP(D10,weather!A:D,4,0) -> 晴 | G10: =H10&"~"&I10 -> 100~160 | H10: 100 | I10: =H10*1.5+10 -> 160 | J10: {=_xlfn.TEXTJOIN(";",1,_xlfn.MAP(K10:R10,S10:Z10,_xlfn.LAMBDA(_xlpm.a,_xlpm.b,IF(_xlpm.b=0,"",_xlpm.a&"~"&_xlpm.b))))} -> 1~700000;0~1000000 | K10: {=_xlfn.LET(_xlpm._arr_len,COUNTIF($A:$A,$A10),_xlpm._group_row,MATCH($A10,$A:$A,0),_xlfn.MAKEARRAY(1,8,_xlfn.LAMBDA(_xlpm.x,_xlpm.y,IF(_xlpm.y>_xlpm._arr_len,"",INDEX(OFFSET($A10,_xlpm._group_row-ROW(),1,_xlpm._arr_len),_xlpm.y)))))} -> 1 | L10: 2 | M10: 3 | N10: 4 | O10: 0 | S10: 700000 | W10: 1000000 | AA10: =IF(A10<>"",IF(SUM(S10:Y10)>=1000000,"Correct","Error"),"") -> Correct | AB10: {=IF(A10<>"",IF(AND(IF(VALUE(RIGHT($S$3:$Z$3,1))>COUNTIF(A:A,A10),S10:Z10<>""=FALSE,TRUE)),"Correct","Error"),"")} -> Correct
C11: =_xlfn.TEXTJOIN(";",1,A11,B11)
C13: =_xlfn.TEXTJOIN(";",1,A13,B13)
A14: 420100 | B14: 0 | C14: =_xlfn.TEXTJOIN(";",1,A14,B14) -> 420100;0 | D14: 460100 | F14: =VLOOKUP(D14,weather!A:D,4,0) -> 未知 | G14: =H14&"~"&I14 -> 99999~99999 | H14: 99999 | I14: 99999 | J14: {=_xlfn.TEXTJOIN(";",1,_xlfn.MAP(K14:R14,S14:Z14,_xlfn.LAMBDA(_xlpm.a,_xlpm.b,IF(_xlpm.b=0,"",_xlpm.a&"~"&_xlpm.b))))} -> 0~1000000 | K14: {=_xlfn.LET(_xlpm._arr_len,COUNTIF($A:$A,$A14),_xlpm._group_row,MATCH($A14,$A:$A,0),_xlfn.MAKEARRAY(1,8,_xlfn.LAMBDA(_xlpm.x,_xlpm.y,IF(_xlpm.y>_xlpm._arr_len,"",INDEX(OFFSET($A14,_xlpm._group_row-ROW(),1,_xlpm._arr_len),_xlpm.y)))))} -> 0 | S14: 1000000 | AA14: =IF(A14<>"",IF(SUM(S14:Z14)>=1000000,"Correct","Error"),"") -> Correct | AB14: {=IF(A14<>"",IF(AND(IF(VALUE(RIGHT($S$3:$Z$3,1))>COUNTIF(A:A,A14),S14:Z14<>""=FALSE,TRUE)),"Correct","Error"),"")} -> Correct
C15: =_xlfn.TEXTJOIN(";",1,A15,B15)
C17: =_xlfn.TEXTJOIN(";",1,A17,B17) | AA17: =IF(A17<>"",IF(SUM(S17:Z17)>=1000000,"Correct","Error"),"") | AB17: {=IF(A17<>"",IF(AND(IF(VALUE(RIGHT($S$3:$Z$3,1))>COUNTIF(A:A,A17),S17:Z17<>""=FALSE,TRUE)),"Correct","Error"),"")}
A18: 420401 | B18: 0 | C18: =_xlfn.TEXTJOIN(";",1,A18,B18) -> 420401;0 | D18: 460400 | E18: 大湖 | F18: =VLOOKUP(D18,weather!A:D,4,0) -> 晴空 | G18: =H18&"~"&I18 -> 8680~9994 | H18: 8680 | I18: =H18*1.15+12 -> 9994 | J18: {=_xlfn.TEXTJOIN(";",1,_xlfn.MAP(K18:R18,S18:Z18,_xlfn.LAMBDA(_xlpm.a,_xlpm.b,IF(_xlpm.b=0,"",_xlpm.a&"~"&_xlpm.b))))} -> 0~1000000 | K18: {=_xlfn.LET(_xlpm._arr_len,COUNTIF($A:$A,$A18),_xlpm._group_row,MATCH($A18,$A:$A,0),_xlfn.MAKEARRAY(1,8,_xlfn.LAMBDA(_xlpm.x,_xlpm.y,IF(_xlpm.y>_xlpm._arr_len,"",INDEX(OFFSET($A18,_xlpm._group_row-ROW(),1,_xlpm._arr_len),_xlpm.y)))))} -> 0 | S18: 1000000 | AA18: =IF(A18<>"",IF(SUM(S18:Z18)>=1000000,"Correct","Error"),"") -> Correct | AB18: {=IF(A18<>"",IF(AND(IF(VALUE(RIGHT($S$3:$Z$3,1))>COUNTIF(A:A,A18),S18:Z18<>""=FALSE,TRUE)),"Correct","Error"),"")} -> Correct
C19: =_xlfn.TEXTJOIN(";",1,A19,B19) | AA19: =IF(A19<>"",IF(SUM(S19:Z19)>=1000000,"Correct","Error"),"") | AB19: {=IF(A19<>"",IF(AND(IF(VALUE(RIGHT($S$3:$Z$3,1))>COUNTIF(A:A,A19),S19:Z19<>""=FALSE,TRUE)),"Correct","Error"),"")}
A20: 420402 | B20: 0 | C20: =_xlfn.TEXTJOIN(";",1,A20,B20) -> 420402;0 | D20: 460400 | E20: 大湖 | F20: =VLOOKUP(D20,weather!A:D,4,0) -> 晴空 | G20: =H20&"~"&I20 -> 150~184.5 | H20: 150 | I20: =H20*1.15+12 -> 184.5 | J20: {=_xlfn.TEXTJOIN(";",1,_xlfn.MAP(K20:R20,S20:Z20,_xlfn.LAMBDA(_xlpm.a,_xlpm.b,IF(_xlpm.b=0,"",_xlpm.a&"~"&_xlpm.b))))} -> 0~400000;10~600000 | K20: {=_xlfn.LET(_xlpm._arr_len,COUNTIF($A:$A,$A20),_xlpm._group_row,MATCH($A20,$A:$A,0),_xlfn.MAKEARRAY(1,8,_xlfn.LAMBDA(_xlpm.x,_xlpm.y,IF(_xlpm.y>_xlpm._arr_len,"",INDEX(OFFSET($A20,_xlpm._group_row-ROW(),1,_xlpm._arr_len),_xlpm.y)))))} -> 0 | L20: 10 | S20: 400000 | T20: 600000 | AA20: =IF(A20<>"",IF(SUM(S20:Z20)>=1000000,"Correct","Error"),"") -> Correct | AB20: {=IF(A20<>"",IF(AND(IF(VALUE(RIGHT($S$3:$Z$3,1))>COUNTIF(A:A,A20),S20:Z20<>""=FALSE,TRUE)),"Correct","Error"),"")} -> Correct
A21: 420402 | B21: 10 | C21: =_xlfn.TEXTJOIN(";",1,A21,B21) -> 420402;10 | D21: 460401 | E21: 大湖 | F21: =VLOOKUP(D21,weather!A:D,4,0) -> 薄雾 | G21: =H21&"~"&I21 -> 300~357 | H21: 300 | I21: =H21*1.15+12 -> 357 | J21: {=_xlfn.TEXTJOIN(";",1,_xlfn.MAP(K21:R21,S21:Z21,_xlfn.LAMBDA(_xlpm.a,_xlpm.b,IF(_xlpm.b=0,"",_xlpm.a&"~"&_xlpm.b))))} -> 0~100000;10~900000 | K21: {=_xlfn.LET(_xlpm._arr_len,COUNTIF($A:$A,$A21),_xlpm._group_row,MATCH($A21,$A:$A,0),_xlfn.MAKEARRAY(1,8,_xlfn.LAMBDA(_xlpm.x,_xlpm.y,IF(_xlpm.y>_xlpm._arr_len,"",INDEX(OFFSET($A21,_xlpm._group_row-ROW(),1,_xlpm._arr_len),_xlpm.y)))))} -> 0 | L21: 10 | S21: 100000 | T21: 900000 | AA21: =IF(A21<>"",IF(SUM(S21:Z21)>=1000000,"Correct","Error"),"") -> Correct | AB21: {=IF(A21<>"",IF(AND(IF(VALUE(RIGHT($S$3:$Z$3,1))>COUNTIF(A:A,A21),S21:Z21<>""=FALSE,TRUE)),"Correct","Error"),"")} -> Correct
C22: =_xlfn.TEXTJOIN(";",1,A22,B22) | AA22: =IF(A22<>"",IF(SUM(S22:Z22)>=1000000,"Correct","Error"),"") | AB22: {=IF(A22<>"",IF(AND(IF(VALUE(RIGHT($S$3:$Z$3,1))>COUNTIF(A:A,A22),S22:Z22<>""=FALSE,TRUE)),"Correct","Error"),"")}
A23: 420403 | B23: 0 | C23: =_xlfn.TEXTJOIN(";",1,A23,B23) -> 420403;0 | D23: 460400 | E23: 大湖 | F23: =VLOOKUP(D23,weather!A:D,4,0) -> 晴空 | G23: =H23&"~"&I23 -> 150~184.5 | H23: 150 | I23: =H23*1.15+12 -> 184.5 | J23: {=_xlfn.TEXTJOIN(";",1,_xlfn.MAP(K23:R23,S23:Z23,_xlfn.LAMBDA(_xlpm.a,_xlpm.b,IF(_xlpm.b=0,"",_xlpm.a&"~"&_xlpm.b))))} -> 0~300000;10~700000 | K23: {=_xlfn.LET(_xlpm._arr_len,COUNTIF($A:$A,$A23),_xlpm._group_row,MATCH($A23,$A:$A,0),_xlfn.MAKEARRAY(1,8,_xlfn.LAMBDA(_xlpm.x,_xlpm.y,IF(_xlpm.y>_xlpm._arr_len,"",INDEX(OFFSET($A23,_xlpm._group_row-ROW(),1,_xlpm._arr_len),_xlpm.y)))))} -> 0 | L23: 10 | M23: 11 | S23: 300000 | T23: 700000 | AA23: =IF(A23<>"",IF(SUM(S23:Z23)>=1000000,"Correct","Error"),"") -> Correct | AB23: {=IF(A23<>"",IF(AND(IF(VALUE(RIGHT($S$3:$Z$3,1))>COUNTIF(A:A,A23),S23:Z23<>""=FALSE,TRUE)),"Correct","Error"),"")} -> Correct
A24: 420403 | B24: 10 | C24: =_xlfn.TEXTJOIN(";",1,A24,B24) -> 420403;10 | D24: 460401 | E24: 大湖 | F24: =VLOOKUP(D24,weather!A:D,4,0) -> 薄雾 | G24: =H24&"~"&I24 -> 150~184.5 | H24: 150 | I24: =H24*1.15+12 -> 184.5 | J24: {=_xlfn.TEXTJOIN(";",1,_xlfn.MAP(K24:R24,S24:Z24,_xlfn.LAMBDA(_xlpm.a,_xlpm.b,IF(_xlpm.b=0,"",_xlpm.a&"~"&_xlpm.b))))} -> 0~200000;10~200000;11~600000 | K24: {=_xlfn.LET(_xlpm._arr_len,COUNTIF($A:$A,$A24),_xlpm._group_row,MATCH($A24,$A:$A,0),_xlfn.MAKEARRAY(1,8,_xlfn.LAMBDA(_xlpm.x,_xlpm.y,IF(_xlpm.y>_xlpm._arr_len,"",INDEX(OFFSET($A24,_xlpm._group_row-ROW(),1,_xlpm._arr_len),_xlpm.y)))))} -> 0 | L24: 10 | M24: 11 | S24: 200000 | T24: 200000 | U24: 600000 | AA24: =IF(A24<>"",IF(SUM(S24:Z24)>=1000000,"Correct","Error"),"") -> Correct | AB24: {=IF(A24<>"",IF(AND(IF(VALUE(RIGHT($S$3:$Z$3,1))>COUNTIF(A:A,A24),S24:Z24<>""=FALSE,TRUE)),"Correct","Error"),"")} -> Correct
A25: 420403 | B25: 11 | C25: =_xlfn.TEXTJOIN(";",1,A25,B25) -> 420403;11 | D25: 460402 | E25: 大湖 | F25: =VLOOKUP(D25,weather!A:D,4,0) -> 浓雾 | G25: =H25&"~"&I25 -> 300~357 | H25: 300 | I25: =H25*1.15+12 -> 357 | J25: {=_xlfn.TEXTJOIN(";",1,_xlfn.MAP(K25:R25,S25:Z25,_xlfn.LAMBDA(_xlpm.a,_xlpm.b,IF(_xlpm.b=0,"",_xlpm.a&"~"&_xlpm.b))))} -> 10~100000;11~900000 | K25: {=_xlfn.LET(_xlpm._arr_len,COUNTIF($A:$A,$A25),_xlpm._group_row,MATCH($A25,$A:$A,0),_xlfn.MAKEARRAY(1,8,_xlfn.LAMBDA(_xlpm.x,_xlpm.y,IF(_xlpm.y>_xlpm._arr_len,"",INDEX(OFFSET($A25,_xlpm._group_row-ROW(),1,_xlpm._arr_len),_xlpm.y)))))} -> 0 | L25: 10 | M25: 11 | T25: 100000 | U25: 900000 | AA25: =IF(A25<>"",IF(SUM(S25:Z25)>=1000000,"Correct","Error"),"") -> Correct | AB25: {=IF(A25<>"",IF(AND(IF(VALUE(RIGHT($S$3:$Z$3,1))>COUNTIF(A:A,A25),S25:Z25<>""=FALSE,TRUE)),"Correct","Error"),"")} -> Correct
C26: =_xlfn.TEXTJOIN(";",1,A26,B26) | AA26: =IF(A26<>"",IF(SUM(S26:Z26)>=1000000,"Correct","Error"),"") | AB26: {=IF(A26<>"",IF(AND(IF(VALUE(RIGHT($S$3:$Z$3,1))>COUNTIF(A:A,A26),S26:Z26<>""=FALSE,TRUE)),"Correct","Error"),"")}
A27: 420404 | B27: 0 | C27: =_xlfn.TEXTJOIN(";",1,A27,B27) -> 420404;0 | D27: 460400 | E27: 大湖 | F27: =VLOOKUP(D27,weather!A:D,4,0) -> 晴空 | G27: =H27&"~"&I27 -> 150~184.5 | H27: 150 | I27: =H27*1.15+12 -> 184.5 | J27: {=_xlfn.TEXTJOIN(";",1,_xlfn.MAP(K27:R27,S27:Z27,_xlfn.LAMBDA(_xlpm.a,_xlpm.b,IF(_xlpm.b=0,"",_xlpm.a&"~"&_xlpm.b))))} -> 0~200000;10~800000 | K27: {=_xlfn.LET(_xlpm._arr_len,COUNTIF($A:$A,$A27),_xlpm._group_row,MATCH($A27,$A:$A,0),_xlfn.MAKEARRAY(1,8,_xlfn.LAMBDA(_xlpm.x,_xlpm.y,IF(_xlpm.y>_xlpm._arr_len,"",INDEX(OFFSET($A27,_xlpm._group_row-ROW(),1,_xlpm._arr_len),_xlpm.y)))))} -> 0 | L27: 10 | M27: 11 | N27: 12 | S27: 200000 | T27: 800000 | AA27: =IF(A27<>"",IF(SUM(S27:Z27)>=1000000,"Correct","Error"),"") -> Correct | AB27: {=IF(A27<>"",IF(AND(IF(VALUE(RIGHT($S$3:$Z$3,1))>COUNTIF(A:A,A27),S27:Z27<>""=FALSE,TRUE)),"Correct","Error"),"")} -> Correct
A28: 420404 | B28: 10 | C28: =_xlfn.TEXTJOIN(";",1,A28,B28) -> 420404;10 | D28: 460401 | E28: 大湖 | F28: =VLOOKUP(D28,weather!A:D,4,0) -> 薄雾 | G28: =H28&"~"&I28 -> 150~184.5 | H28: 150 | I28: =H28*1.15+12 -> 184.5 | J28: {=_xlfn.TEXTJOIN(";",1,_xlfn.MAP(K28:R28,S28:Z28,_xlfn.LAMBDA(_xlpm.a,_xlpm.b,IF(_xlpm.b=0,"",_xlpm.a&"~"&_xlpm.b))))} -> 0~100000;10~200000;11~700000 | K28: {=_xlfn.LET(_xlpm._arr_len,COUNTIF($A:$A,$A28),_xlpm._group_row,MATCH($A28,$A:$A,0),_xlfn.MAKEARRAY(1,8,_xlfn.LAMBDA(_xlpm.x,_xlpm.y,IF(_xlpm.y>_xlpm._arr_len,"",INDEX(OFFSET($A28,_xlpm._group_row-ROW(),1,_xlpm._arr_len),_xlpm.y)))))} -> 0 | L28: 10 | M28: 11 | N28: 12 | S28: 100000 | T28: 200000 | U28: 700000 | AA28: =IF(A28<>"",IF(SUM(S28:Z28)>=1000000,"Correct","Error"),"") -> Correct | AB28: {=IF(A28<>"",IF(AND(IF(VALUE(RIGHT($S$3:$Z$3,1))>COUNTIF(A:A,A28),S28:Z28<>""=FALSE,TRUE)),"Correct","Error"),"")} -> Correct
A29: 420404 | B29: 11 | C29: =_xlfn.TEXTJOIN(";",1,A29,B29) -> 420404;11 | D29: 460402 | E29: 大湖 | F29: =VLOOKUP(D29,weather!A:D,4,0) -> 浓雾 | G29: =H29&"~"&I29 -> 150~184.5 | H29: 150 | I29: =H29*1.15+12 -> 184.5 | J29: {=_xlfn.TEXTJOIN(";",1,_xlfn.MAP(K29:R29,S29:Z29,_xlfn.LAMBDA(_xlpm.a,_xlpm.b,IF(_xlpm.b=0,"",_xlpm.a&"~"&_xlpm.b))))} -> 10~100000;11~300000;12~600000 | K29: {=_xlfn.LET(_xlpm._arr_len,COUNTIF($A:$A,$A29),_xlpm._group_row,MATCH($A29,$A:$A,0),_xlfn.MAKEARRAY(1,8,_xlfn.LAMBDA(_xlpm.x,_xlpm.y,IF(_xlpm.y>_xlpm._arr_len,"",INDEX(OFFSET($A29,_xlpm._group_row-ROW(),1,_xlpm._arr_len),_xlpm.y)))))} -> 0 | L29: 10 | M29: 11 | N29: 12 | T29: 100000 | U29: 300000 | V29: 600000 | AA29: =IF(A29<>"",IF(SUM(S29:Z29)>=1000000,"Correct","Error"),"") -> Correct | AB29: {=IF(A29<>"",IF(AND(IF(VALUE(RIGHT($S$3:$Z$3,1))>COUNTIF(A:A,A29),S29:Z29<>""=FALSE,TRUE)),"Correct","Error"),"")} -> Correct
A30: 420404 | B30: 12 | C30: =_xlfn.TEXTJOIN(";",1,A30,B30) -> 420404;12 | D30: 460403 | E30: 大湖 | F30: =VLOOKUP(D30,weather!A:D,4,0) -> 黑色妖雾 | G30: =H30&"~"&I30 -> 300~357 | H30: 300 | I30: =H30*1.15+12 -> 357 | J30: {=_xlfn.TEXTJOIN(";",1,_xlfn.MAP(K30:R30,S30:Z30,_xlfn.LAMBDA(_xlpm.a,_xlpm.b,IF(_xlpm.b=0,"",_xlpm.a&"~"&_xlpm.b))))} -> 11~100000;12~900000 | K30: {=_xlfn.LET(_xlpm._arr_len,COUNTIF($A:$A,$A30),_xlpm._group_row,MATCH($A30,$A:$A,0),_xlfn.MAKEARRAY(1,8,_xlfn.LAMBDA(_xlpm.x,_xlpm.y,IF(_xlpm.y>_xlpm._arr_len,"",INDEX(OFFSET($A30,_xlpm._group_row-ROW(),1,_xlpm._arr_len),_xlpm.y)))))} -> 0 | L30: 10 | M30: 11 | N30: 12 | U30: 100000 | V30: 900000 | AA30: =IF(A30<>"",IF(SUM(S30:Z30)>=1000000,"Correct","Error"),"") -> Correct | AB30: {=IF(A30<>"",IF(AND(IF(VALUE(RIGHT($S$3:$Z$3,1))>COUNTIF(A:A,A30),S30:Z30<>""=FALSE,TRUE)),"Correct","Error"),"")} -> Correct
C31: =_xlfn.TEXTJOIN(";",1,A31,B31) | AA31: =IF(A31<>"",IF(SUM(S31:Z31)>=1000000,"Correct","Error"),"") | AB31: {=IF(A31<>"",IF(AND(IF(VALUE(RIGHT($S$3:$Z$3,1))>COUNTIF(A:A,A31),S31:Z31<>""=FALSE,TRUE)),"Correct","Error"),"")}
A32: 420405 | B32: 0 | C32: =_xlfn.TEXTJOIN(";",1,A32,B32) -> 420405;0 | D32: 460400 | E32: 大湖 | F32: =VLOOKUP(D32,weather!A:D,4,0) -> 晴空 | G32: =H32&"~"&I32 -> 150~184.5 | H32: 150 | I32: =H32*1.15+12 -> 184.5 | J32: {=_xlfn.TEXTJOIN(";",1,_xlfn.MAP(K32:R32,S32:Z32,_xlfn.LAMBDA(_xlpm.a,_xlpm.b,IF(_xlpm.b=0,"",_xlpm.a&"~"&_xlpm.b))))} -> 0~100000;10~900000 | K32: {=_xlfn.LET(_xlpm._arr_len,COUNTIF($A:$A,$A32),_xlpm._group_row,MATCH($A32,$A:$A,0),_xlfn.MAKEARRAY(1,8,_xlfn.LAMBDA(_xlpm.x,_xlpm.y,IF(_xlpm.y>_xlpm._arr_len,"",INDEX(OFFSET($A32,_xlpm._group_row-ROW(),1,_xlpm._arr_len),_xlpm.y)))))} -> 0 | L32: 10 | M32: 11 | N32: 12 | O32: 13 | S32: 100000 | T32: 900000 | AA32: =IF(A32<>"",IF(SUM(S32:Z32)>=1000000,"Correct","Error"),"") -> Correct | AB32: {=IF(A32<>"",IF(AND(IF(VALUE(RIGHT($S$3:$Z$3,1))>COUNTIF(A:A,A32),S32:Z32<>""=FALSE,TRUE)),"Correct","Error"),"")} -> Correct
A33: 420405 | B33: 10 | C33: =_xlfn.TEXTJOIN(";",1,A33,B33) -> 420405;10 | D33: 460401 | E33: 大湖 | F33: =VLOOKUP(D33,weather!A:D,4,0) -> 薄雾 | G33: =H33&"~"&I33 -> 150~184.5 | H33: 150 | I33: =H33*1.15+12 -> 184.5 | J33: {=_xlfn.TEXTJOIN(";",1,_xlfn.MAP(K33:R33,S33:Z33,_xlfn.LAMBDA(_xlpm.a,_xlpm.b,IF(_xlpm.b=0,"",_xlpm.a&"~"&_xlpm.b))))} -> 0~50000;10~150000;11~800000 | K33: {=_xlfn.LET(_xlpm._arr_len,COUNTIF($A:$A,$A33),_xlpm._group_row,MATCH($A33,$A:$A,0),_xlfn.MAKEARRAY(1,8,_xlfn.LAMBDA(_xlpm.x,_xlpm.y,IF(_xlpm.y>_xlpm._arr_len,"",INDEX(OFFSET($A33,_xlpm._group_row-ROW(),1,_xlpm._arr_len),_xlpm.y)))))} -> 0 | L33: 10 | M33: 11 | N33: 12 | O33: 13 | S33: 50000 | T33: 150000 | U33: 800000 | AA33: =IF(A33<>"",IF(SUM(S33:Z33)>=1000000,"Correct","Error"),"") -> Correct | AB33: {=IF(A33<>"",IF(AND(IF(VALUE(RIGHT($S$3:$Z$3,1))>COUNTIF(A:A,A33),S33:Z33<>""=FALSE,TRUE)),"Correct","Error"),"")} -> Correct
A34: 420405 | B34: 11 | C34: =_xlfn.TEXTJOIN(";",1,A34,B34) -> 420405;11 | D34: 460402 | E34: 大湖 | F34: =VLOOKUP(D34,weather!A:D,4,0) -> 浓雾 | G34: =H34&"~"&I34 -> 150~184.5 | H34: 150 | I34: =H34*1.15+12 -> 184.5 | J34: {=_xlfn.TEXTJOIN(";",1,_xlfn.MAP(K34:R34,S34:Z34,_xlfn.LAMBDA(_xlpm.a,_xlpm.b,IF(_xlpm.b=0,"",_xlpm.a&"~"&_xlpm.b))))} -> 10~100000;11~200000;12~700000 | K34: {=_xlfn.LET(_xlpm._arr_len,COUNTIF($A:$A,$A34),_xlpm._group_row,MATCH($A34,$A:$A,0),_xlfn.MAKEARRAY(1,8,_xlfn.LAMBDA(_xlpm.x,_xlpm.y,IF(_xlpm.y>_xlpm._arr_len,"",INDEX(OFFSET($A34,_xlpm._group_row-ROW(),1,_xlpm._arr_len),_xlpm.y)))))} -> 0 | L34: 10 | M34: 11 | N34: 12 | O34: 13 | T34: 100000 | U34: 200000 | V34: 700000 | AA34: =IF(A34<>"",IF(SUM(S34:Z34)>=1000000,"Correct","Error"),"") -> Correct | AB34: {=IF(A34<>"",IF(AND(IF(VALUE(RIGHT($S$3:$Z$3,1))>COUNTIF(A:A,A34),S34:Z34<>""=FALSE,TRUE)),"Correct","Error"),"")} -> Correct
A35: 420405 | B35: 12 | C35: =_xlfn.TEXTJOIN(";",1,A35,B35) -> 420405;12 | D35: 460403 | E35: 大湖 | F35: =VLOOKUP(D35,weather!A:D,4,0) -> 黑色妖雾 | G35: =H35&"~"&I35 -> 150~184.5 | H35: 150 | I35: =H35*1.15+12 -> 184.5 | J35: {=_xlfn.TEXTJOIN(";",1,_xlfn.MAP(K35:R35,S35:Z35,_xlfn.LAMBDA(_xlpm.a,_xlpm.b,IF(_xlpm.b=0,"",_xlpm.a&"~"&_xlpm.b))))} -> 11~100000;12~300000;13~600000 | K35: {=_xlfn.LET(_xlpm._arr_len,COUNTIF($A:$A,$A35),_xlpm._group_row,MATCH($A35,$A:$A,0),_xlfn.MAKEARRAY(1,8,_xlfn.LAMBDA(_xlpm.x,_xlpm.y,IF(_xlpm.y>_xlpm._arr_len,"",INDEX(OFFSET($A35,_xlpm._group_row-ROW(),1,_xlpm._arr_len),_xlpm.y)))))} -> 0 | L35: 10 | M35: 11 | N35: 12 | O35: 13 | U35: 100000 | V35: 300000 | W35: 600000 | AA35: =IF(A35<>"",IF(SUM(S35:Z35)>=1000000,"Correct","Error"),"") -> Correct | AB35: {=IF(A35<>"",IF(AND(IF(VALUE(RIGHT($S$3:$Z$3,1))>COUNTIF(A:A,A35),S35:Z35<>""=FALSE,TRUE)),"Correct","Error"),"")} -> Correct
A36: 420405 | B36: 13 | C36: =_xlfn.TEXTJOIN(";",1,A36,B36) -> 420405;13 | D36: 460404 | E36: 大湖 | F36: =VLOOKUP(D36,weather!A:D,4,0) -> 浓厚妖雾 | G36: =H36&"~"&I36 -> 300~357 | H36: 300 | I36: =H36*1.15+12 -> 357 | J36: {=_xlfn.TEXTJOIN(";",1,_xlfn.MAP(K36:R36,S36:Z36,_xlfn.LAMBDA(_xlpm.a,_xlpm.b,IF(_xlpm.b=0,"",_xlpm.a&"~"&_xlpm.b))))} -> 12~100000;13~900000 | K36: {=_xlfn.LET(_xlpm._arr_len,COUNTIF($A:$A,$A36),_xlpm._group_row,MATCH($A36,$A:$A,0),_xlfn.MAKEARRAY(1,8,_xlfn.LAMBDA(_xlpm.x,_xlpm.y,IF(_xlpm.y>_xlpm._arr_len,"",INDEX(OFFSET($A36,_xlpm._group_row-ROW(),1,_xlpm._arr_len),_xlpm.y)))))} -> 0 | L36: 10 | M36: 11 | N36: 12 | O36: 13 | V36: 100000 | W36: 900000 | AA36: =IF(A36<>"",IF(SUM(S36:Z36)>=1000000,"Correct","Error"),"") -> Correct | AB36: {=IF(A36<>"",IF(AND(IF(VALUE(RIGHT($S$3:$Z$3,1))>COUNTIF(A:A,A36),S36:Z36<>""=FALSE,TRUE)),"Correct","Error"),"")} -> Correct
C37: =_xlfn.TEXTJOIN(";",1,A37,B37) | AA37: =IF(A37<>"",IF(SUM(S37:Z37)>=1000000,"Correct","Error"),"") | AB37: {=IF(A37<>"",IF(AND(IF(VALUE(RIGHT($S$3:$Z$3,1))>COUNTIF(A:A,A37),S37:Z37<>""=FALSE,TRUE)),"Correct","Error"),"")}
A38: 420406 | B38: 10 | C38: =_xlfn.TEXTJOIN(";",1,A38,B38) -> 420406;10 | D38: 460401 | E38: 大湖 | F38: =VLOOKUP(D38,weather!A:D,4,0) -> 薄雾 | G38: =H38&"~"&I38 -> 150~184.5 | H38: 150 | I38: =H38*1.15+12 -> 184.5 | J38: {=_xlfn.TEXTJOIN(";",1,_xlfn.MAP(K38:R38,S38:Z38,_xlfn.LAMBDA(_xlpm.a,_xlpm.b,IF(_xlpm.b=0,"",_xlpm.a&"~"&_xlpm.b))))} -> 10~200000;11~800000 | K38: {=_xlfn.LET(_xlpm._arr_len,COUNTIF($A:$A,$A38),_xlpm._group_row,MATCH($A38,$A:$A,0),_xlfn.MAKEARRAY(1,8,_xlfn.LAMBDA(_xlpm.x,_xlpm.y,IF(_xlpm.y>_xlpm._arr_len,"",INDEX(OFFSET($A38,_xlpm._group_row-ROW(),1,_xlpm._arr_len),_xlpm.y)))))} -> 10 | L38: 11 | M38: 12 | N38: 13 | S38: 200000 | T38: 800000 | AA38: =IF(A38<>"",IF(SUM(S38:Z38)>=1000000,"Correct","Error"),"") -> Correct | AB38: {=IF(A38<>"",IF(AND(IF(VALUE(RIGHT($S$3:$Z$3,1))>COUNTIF(A:A,A38),S38:Z38<>""=FALSE,TRUE)),"Correct","Error"),"")} -> Correct
A39: 420406 | B39: 11 | C39: =_xlfn.TEXTJOIN(";",1,A39,B39) -> 420406;11 | D39: 460402 | E39: 大湖 | F39: =VLOOKUP(D39,weather!A:D,4,0) -> 浓雾 | G39: =H39&"~"&I39 -> 150~184.5 | H39: 150 | I39: =H39*1.15+12 -> 184.5 | J39: {=_xlfn.TEXTJOIN(";",1,_xlfn.MAP(K39:R39,S39:Z39,_xlfn.LAMBDA(_xlpm.a,_xlpm.b,IF(_xlpm.b=0,"",_xlpm.a&"~"&_xlpm.b))))} -> 10~100000;11~200000;12~700000 | K39: {=_xlfn.LET(_xlpm._arr_len,COUNTIF($A:$A,$A39),_xlpm._group_row,MATCH($A39,$A:$A,0),_xlfn.MAKEARRAY(1,8,_xlfn.LAMBDA(_xlpm.x,_xlpm.y,IF(_xlpm.y>_xlpm._arr_len,"",INDEX(OFFSET($A39,_xlpm._group_row-ROW(),1,_xlpm._arr_len),_xlpm.y)))))} -> 10 | L39: 11 | M39: 12 | N39: 13 | S39: 100000 | T39: 200000 | U39: 700000 | AA39: =IF(A39<>"",IF(SUM(S39:Z39)>=1000000,"Correct","Error"),"") -> Correct | AB39: {=IF(A39<>"",IF(AND(IF(VALUE(RIGHT($S$3:$Z$3,1))>COUNTIF(A:A,A39),S39:Z39<>""=FALSE,TRUE)),"Correct","Error"),"")} -> Correct
A40: 420406 | B40: 12 | C40: =_xlfn.TEXTJOIN(";",1,A40,B40) -> 420406;12 | D40: 460403 | E40: 大湖 | F40: =VLOOKUP(D40,weather!A:D,4,0) -> 黑色妖雾 | G40: =H40&"~"&I40 -> 150~184.5 | H40: 150 | I40: =H40*1.15+12 -> 184.5 | J40: {=_xlfn.TEXTJOIN(";",1,_xlfn.MAP(K40:R40,S40:Z40,_xlfn.LAMBDA(_xlpm.a,_xlpm.b,IF(_xlpm.b=0,"",_xlpm.a&"~"&_xlpm.b))))} -> 11~100000;12~300000;13~600000 | K40: {=_xlfn.LET(_xlpm._arr_len,COUNTIF($A:$A,$A40),_xlpm._group_row,MATCH($A40,$A:$A,0),_xlfn.MAKEARRAY(1,8,_xlfn.LAMBDA(_xlpm.x,_xlpm.y,IF(_xlpm.y>_xlpm._arr_len,"",INDEX(OFFSET($A40,_xlpm._group_row-ROW(),1,_xlpm._arr_len),_xlpm.y)))))} -> 10 | L40: 11 | M40: 12 | N40: 13 | T40: 100000 | U40: 300000 | V40: 600000 | AA40: =IF(A40<>"",IF(SUM(S40:Z40)>=1000000,"Correct","Error"),"") -> Correct | AB40: {=IF(A40<>"",IF(AND(IF(VALUE(RIGHT($S$3:$Z$3,1))>COUNTIF(A:A,A40),S40:Z40<>""=FALSE,TRUE)),"Correct","Error"),"")} -> Correct
A41: 420406 | B41: 13 | C41: =_xlfn.TEXTJOIN(";",1,A41,B41) -> 420406;13 | D41: 460404 | E41: 大湖 | F41: =VLOOKUP(D41,weather!A:D,4,0) -> 浓厚妖雾 | G41: =H41&"~"&I41 -> 300~357 | H41: 300 | I41: =H41*1.15+12 -> 357 | J41: {=_xlfn.TEXTJOIN(";",1,_xlfn.MAP(K41:R41,S41:Z41,_xlfn.LAMBDA(_xlpm.a,_xlpm.b,IF(_xlpm.b=0,"",_xlpm.a&"~"&_xlpm.b))))} -> 12~100000;13~900000 | K41: {=_xlfn.LET(_xlpm._arr_len,COUNTIF($A:$A,$A41),_xlpm._group_row,MATCH($A41,$A:$A,0),_xlfn.MAKEARRAY(1,8,_xlfn.LAMBDA(_xlpm.x,_xlpm.y,IF(_xlpm.y>_xlpm._arr_len,"",INDEX(OFFSET($A41,_xlpm._group_row-ROW(),1,_xlpm._arr_len),_xlpm.y)))))} -> 10 | L41: 11 | M41: 12 | N41: 13 | U41: 100000 | V41: 900000 | AA41: =IF(A41<>"",IF(SUM(S41:Z41)>=1000000,"Correct","Error"),"") -> Correct | AB41: {=IF(A41<>"",IF(AND(IF(VALUE(RIGHT($S$3:$Z$3,1))>COUNTIF(A:A,A41),S41:Z41<>""=FALSE,TRUE)),"Correct","Error"),"")} -> Correct
C42: =_xlfn.TEXTJOIN(";",1,A42,B42) | AA42: =IF(A42<>"",IF(SUM(S42:Z42)>=1000000,"Correct","Error"),"") | AB42: {=IF(A42<>"",IF(AND(IF(VALUE(RIGHT($S$3:$Z$3,1))>COUNTIF(A:A,A42),S42:Z42<>""=FALSE,TRUE)),"Correct","Error"),"")}
...

Sheet -id 配置说明
A1: 第1位 | B1: 第2位 | C1: 第3位 | D1: 第4位 | E1: 第5位 | F1: 第6位
A2: 46 = weather | C2: 01 = 地宫 | E2: 00~99 编号
C3: 02 = 云间
C4: 08 = 大湖
