Workbook

Sheet relic
A1: id | B1: name | E1: portrait | G1: description | J1: behaviour_script | L1: parm_int | M1: parm_string | N1: max_num | P1: unlocked_init | Q1: lock_relic | R1: unlock_relic | S1: upgrade_from | T1: rank | U1: base_value
A2: uint key | B2: string | E2: string | G2: string | J2: string | L2: int[] | M2: string[] | N2: int | P2: bool | Q2: uint[] | R2: uint[] | S2: uint | T2: int | U2: int
A3: 编号 | B3: Relic名称 | C3: name l10n key 同组复用 | D3: 备注 Relic 名称 | E3: 图标 配置address | F3: 辅助列 图集 index | G3: Relic 效果描述 | H3: 效果备注 | I3: 替代备注 (选填) | J3: Relic脚本 | K3: 备注：参数生效方式 | L3: int类型参数 作用见备注 | M3: string类型参数 | N3: Relic 数量上限 | O3: 基础数量 | P3: 默认已解锁 true：新游戏已解锁 false：新游戏未解锁 | Q3: 锁定其他relic | R3: 解锁其他relic | S3: 升级自其他relic 获取时，移除目标relic | T3: 品质等级 | U3: 基础价格 | V3: 基础价格 | W3: 等级底数
A4: 4 | B4: zoommelee | E4: relic_icons[relic_layout_100] | G4: 近战武器放大20% | H4: 近战武器放大20% | J4: ZoomMeleeRelic
A5: 6 | B5: titan | E5: relic_icons[relic_layout_100] | G5: 见鬼，它们是吃了什么? | H5: 见鬼，它们是吃了什么? | J5: TitanEnemyRelic
A6: 7 | B6: difficult | E6: relic_icons[relic_layout_100] | G6: 钟声响了，是谁敲的! | H6: 钟声响了，是谁敲的! | J6: DifficultModeRelic
A7: 8 | B7: lucky | E7: relic_icons[relic_layout_100] | G7: 如果还能不掉落就应该是人的问题了 | H7: 如果还能不掉落就应该是人的问题了 | J7: LuckyDogRelic
A9: 91 | E9: relic_icons[relic_layout_100] | G9: 加速测试 | H9: 加速测试 | J9: AccelerateRelic | K9: parm_int[0] = v.x，在代码中1:1转为 float | L9: 50 | N9: 9999 | P9: TRUE
A10: 92 | E10: relic_icons[relic_layout_100] | G10: 加速测试 | H10: 加速测试 | J10: AccelerateRelic | K10: parm_int[0] = v.x，在代码中1:1转为 float | L10: 150 | N10: 9999 | P10: TRUE
A11: 93 | E11: relic_icons[relic_layout_100] | G11: 加速测试 | H11: 加速测试 | J11: AccelerateRelic | K11: parm_int[0] = v.x，在代码中1:1转为 float | L11: 500 | N11: 9999 | P11: TRUE
H12: {=IF($I12<>"",$I12, _xlfn.LET( _xlpm.idx,MATCH(relic!$M12,'-id 配置说明'!$A:$A,0), _xlpm.desc,INDEX('-id 配置说明'!$F:$F,_xlpm.idx), _xlpm.tp,INDEX('-id 配置说明'!$B:$B,_xlpm.idx), _xlpm.expr,RIGHT(_xlpm.desc,LEN(_xlpm.desc)-FIND("=",_xlpm.desc))&" + "&_xlfn.SWITCH(_xlpm.tp,"pts",TEXT($L12/1000,"0%"),"add",$L12), IFERROR(_xlpm.expr,"") ))}
A13: 300011 | B13: =IF(A13<>"","relic_name_"&IF(C13,LEFT($A13,LEN($A13)-1),$A13),"") -> relic_name_30001 | C13: TRUE | D13: {=_xlfn.LET( _xlpm.idx,MATCH(relic!$M13,'-id 配置说明'!$A:$A,0), _xlpm.desc_1,INDEX('-id 配置说明'!$J:$J,_xlpm.idx), _xlpm.desc_2,INDEX('-id 配置说明'!$K:$K,_xlpm.idx), _xlpm.desc_array,_xlfn.TEXTSPLIT(_xlpm.desc_2,"；"), _xlpm.array_len,COLUMNS(_xlpm.desc_array), IFERROR(INDEX(_xlpm.desc_array,MIN(RIGHT($A13,1),_xlpm.array_len)),"") )} -> 阿菊 | E13: =_xlfn.LET(_xlpm._asset,"relic_layout", _xlfn.CONCAT(_xlpm._asset,"[",_xlpm._asset,"_",$F13,"]")) -> relic_layout[relic_layout_0] | F13: 0 | G13: =IF($A13<>"","relic_desc_"&$A13,"") -> relic_desc_300011 | H13: {=_xlfn.LET(_xlpm._manual_info,$I13:$I16, IF(_xlpm._manual_info<>"",_xlpm._manual_info,_xlfn.LET( _xlpm._parm_key,$M13, _xlpm._parm_value,$L13:$L16, _xlpm._desc,_xlfn.XLOOKUP(_xlpm._parm_key,'-id 配置说明'!$A:$A,'-id 配置说明'!$F:$F), _xlpm._tp,_xlfn.XLOOKUP(_xlpm._parm_key,'-id 配置说明'!$A:$A,'-id 配置说明'!$B:$B), _xlpm._expr,INDEX(_xlfn.TEXTSPLIT(_xlpm._desc," = "),2)&" + "&_xlfn.SWITCH(_xlpm._tp,"pts",TEXT(_xlpm._parm_value/1000,"0%"),"add",_xlpm._parm_value), IFERROR(_xlpm._expr,"") )) )} -> 所有设备 伤害 + 15% | J13: Relic_Modify_Variable | L13: 150 | M13: global_atk_pts | N13: =ROUND(POWER(O13,(5-T13)/5),0) -> 9 | O13: 9 | P13: TRUE | T13: 0 | U13: =ROUND(V13*POWER(W13,T13),0) -> 7 | V13: 7 | W13: 2.32
A14: 300012 | B14: =IF(A14<>"","relic_name_"&IF(C14,LEFT($A14,LEN($A14)-1),$A14),"") -> relic_name_30001 | C14: TRUE | D14: {=_xlfn.LET( _xlpm.idx,MATCH(relic!$M14,'-id 配置说明'!$A:$A,0), _xlpm.desc_1,INDEX('-id 配置说明'!$J:$J,_xlpm.idx), _xlpm.desc_2,INDEX('-id 配置说明'!$K:$K,_xlpm.idx), _xlpm.desc_array,_xlfn.TEXTSPLIT(_xlpm.desc_2,"；"), _xlpm.array_len,COLUMNS(_xlpm.desc_array), IFERROR(INDEX(_xlpm.desc_array,MIN(RIGHT($A14,1),_xlpm.array_len)),"") )} -> 阿菊 | E14: =_xlfn.LET(_xlpm._asset,"relic_layout", _xlfn.CONCAT(_xlpm._asset,"[",_xlpm._asset,"_",$F14,"]")) -> relic_layout[relic_layout_1] | F14: 1 | G14: =IF($A14<>"","relic_desc_"&$A14,"") -> relic_desc_300012 | H14: 所有设备 伤害 + 30% | J14: Relic_Modify_Variable | L14: 300 | M14: global_atk_pts | N14: =ROUND(POWER(O14,(5-T14)/5),0) -> 6 | O14: 9 | P14: TRUE | T14: 1 | U14: =ROUND(V14*POWER(W14,T14),0) -> 16 | V14: 7 | W14: 2.32
A15: 300013 | B15: =IF(A15<>"","relic_name_"&IF(C15,LEFT($A15,LEN($A15)-1),$A15),"") -> relic_name_30001 | C15: TRUE | D15: {=_xlfn.LET( _xlpm.idx,MATCH(relic!$M15,'-id 配置说明'!$A:$A,0), _xlpm.desc_1,INDEX('-id 配置说明'!$J:$J,_xlpm.idx), _xlpm.desc_2,INDEX('-id 配置说明'!$K:$K,_xlpm.idx), _xlpm.desc_array,_xlfn.TEXTSPLIT(_xlpm.desc_2,"；"), _xlpm.array_len,COLUMNS(_xlpm.desc_array), IFERROR(INDEX(_xlpm.desc_array,MIN(RIGHT($A15,1),_xlpm.array_len)),"") )} -> 阿菊 | E15: =_xlfn.LET(_xlpm._asset,"relic_layout", _xlfn.CONCAT(_xlpm._asset,"[",_xlpm._asset,"_",$F15,"]")) -> relic_layout[relic_layout_1] | F15: 1 | G15: =IF($A15<>"","relic_desc_"&$A15,"") -> relic_desc_300013 | H15: 所有设备 伤害 + 60% | J15: Relic_Modify_Variable | L15: 600 | M15: global_atk_pts | N15: =ROUND(POWER(O15,(5-T15)/5),0) -> 4 | O15: 9 | P15: TRUE | T15: 2 | U15: =ROUND(V15*POWER(W15,T15),0) -> 38 | V15: 7 | W15: 2.32
A16: 300014 | B16: =IF(A16<>"","relic_name_"&IF(C16,LEFT($A16,LEN($A16)-1),$A16),"") -> relic_name_30001 | C16: TRUE | D16: {=_xlfn.LET( _xlpm.idx,MATCH(relic!$M16,'-id 配置说明'!$A:$A,0), _xlpm.desc_1,INDEX('-id 配置说明'!$J:$J,_xlpm.idx), _xlpm.desc_2,INDEX('-id 配置说明'!$K:$K,_xlpm.idx), _xlpm.desc_array,_xlfn.TEXTSPLIT(_xlpm.desc_2,"；"), _xlpm.array_len,COLUMNS(_xlpm.desc_array), IFERROR(INDEX(_xlpm.desc_array,MIN(RIGHT($A16,1),_xlpm.array_len)),"") )} -> 阿菊 | E16: =_xlfn.LET(_xlpm._asset,"relic_layout", _xlfn.CONCAT(_xlpm._asset,"[",_xlpm._asset,"_",$F16,"]")) -> relic_layout[relic_layout_2] | F16: 2 | G16: =IF($A16<>"","relic_desc_"&$A16,"") -> relic_desc_300014 | H16: 所有设备 伤害 + 120% | J16: Relic_Modify_Variable | L16: 1200 | M16: global_atk_pts | N16: =ROUND(POWER(O16,(5-T16)/5),0) -> 2 | O16: 9 | P16: TRUE | T16: 3 | U16: =ROUND(V16*POWER(W16,T16),0) -> 87 | V16: 7 | W16: 2.32
D17: {=_xlfn.LET( _xlpm.idx,MATCH(relic!$M17,'-id 配置说明'!$A:$A,0), _xlpm.desc_1,INDEX('-id 配置说明'!$J:$J,_xlpm.idx), _xlpm.desc_2,INDEX('-id 配置说明'!$K:$K,_xlpm.idx), _xlpm.desc_array,_xlfn.TEXTSPLIT(_xlpm.desc_2,"；"), _xlpm.array_len,COLUMNS(_xlpm.desc_array), IFERROR(INDEX(_xlpm.desc_array,MIN(RIGHT($A17,1),_xlpm.array_len)),"") )} | G17: =IF($A17<>"","relic_desc_"&$A17,"")
A18: 300021 | B18: =IF(A18<>"","relic_name_"&IF(C18,LEFT($A18,LEN($A18)-1),$A18),"") -> relic_name_30002 | C18: TRUE | D18: {=_xlfn.LET( _xlpm.idx,MATCH(relic!$M18,'-id 配置说明'!$A:$A,0), _xlpm.desc_1,INDEX('-id 配置说明'!$J:$J,_xlpm.idx), _xlpm.desc_2,INDEX('-id 配置说明'!$K:$K,_xlpm.idx), _xlpm.desc_array,_xlfn.TEXTSPLIT(_xlpm.desc_2,"；"), _xlpm.array_len,COLUMNS(_xlpm.desc_array), IFERROR(INDEX(_xlpm.desc_array,MIN(RIGHT($A18,1),_xlpm.array_len)),"") )} -> 火星蝶 | E18: =_xlfn.LET(_xlpm._asset,"relic_layout", _xlfn.CONCAT(_xlpm._asset,"[",_xlpm._asset,"_",$F18,"]")) -> relic_layout[relic_layout_56] | F18: 56 | G18: =IF($A18<>"","relic_desc_"&$A18,"") -> relic_desc_300021 | H18: {=_xlfn.LET(_xlpm._manual_info,$I18:$I20, IF(_xlpm._manual_info<>"",_xlpm._manual_info,_xlfn.LET( _xlpm._parm_key,$M18, _xlpm._parm_value,$L18:$L20, _xlpm._desc,_xlfn.XLOOKUP(_xlpm._parm_key,'-id 配置说明'!$A:$A,'-id 配置说明'!$F:$F), _xlpm._tp,_xlfn.XLOOKUP(_xlpm._parm_key,'-id 配置说明'!$A:$A,'-id 配置说明'!$B:$B), _xlpm._expr,INDEX(_xlfn.TEXTSPLIT(_xlpm._desc," = "),2)&" + "&_xlfn.SWITCH(_xlpm._tp,"pts",TEXT(_xlpm._parm_value/1000,"0%"),"add",_xlpm._parm_value), IFERROR(_xlpm._expr,"") )) )} -> 所有设备 额外伤害 + 6 | J18: Relic_Modify_Variable | L18: 6 | M18: global_atk_add | N18: =ROUND(POWER(O18,(5-T18)/5),0) -> 4 | O18: 6 | P18: TRUE | T18: 1 | U18: =ROUND(V18*POWER(W18,T18),0) -> 19 | V18: 8 | W18: 2.32
A19: 300022 | B19: =IF(A19<>"","relic_name_"&IF(C19,LEFT($A19,LEN($A19)-1),$A19),"") -> relic_name_30002 | C19: TRUE | D19: {=_xlfn.LET( _xlpm.idx,MATCH(relic!$M19,'-id 配置说明'!$A:$A,0), _xlpm.desc_1,INDEX('-id 配置说明'!$J:$J,_xlpm.idx), _xlpm.desc_2,INDEX('-id 配置说明'!$K:$K,_xlpm.idx), _xlpm.desc_array,_xlfn.TEXTSPLIT(_xlpm.desc_2,"；"), _xlpm.array_len,COLUMNS(_xlpm.desc_array), IFERROR(INDEX(_xlpm.desc_array,MIN(RIGHT($A19,1),_xlpm.array_len)),"") )} -> 火星蝶 | E19: =_xlfn.LET(_xlpm._asset,"relic_layout", _xlfn.CONCAT(_xlpm._asset,"[",_xlpm._asset,"_",$F19,"]")) -> relic_layout[relic_layout_56] | F19: 56 | G19: =IF($A19<>"","relic_desc_"&$A19,"") -> relic_desc_300022 | H19: 所有设备 额外伤害 + 12 | J19: Relic_Modify_Variable | L19: 12 | M19: global_atk_add | N19: =ROUND(POWER(O19,(5-T19)/5),0) -> 3 | O19: 6 | P19: TRUE | T19: 2 | U19: =ROUND(V19*POWER(W19,T19),0) -> 43 | V19: 8 | W19: 2.32
A20: 300023 | B20: =IF(A20<>"","relic_name_"&IF(C20,LEFT($A20,LEN($A20)-1),$A20),"") -> relic_name_30002 | C20: TRUE | D20: {=_xlfn.LET( _xlpm.idx,MATCH(relic!$M20,'-id 配置说明'!$A:$A,0), _xlpm.desc_1,INDEX('-id 配置说明'!$J:$J,_xlpm.idx), _xlpm.desc_2,INDEX('-id 配置说明'!$K:$K,_xlpm.idx), _xlpm.desc_array,_xlfn.TEXTSPLIT(_xlpm.desc_2,"；"), _xlpm.array_len,COLUMNS(_xlpm.desc_array), IFERROR(INDEX(_xlpm.desc_array,MIN(RIGHT($A20,1),_xlpm.array_len)),"") )} -> 火星蝶 | E20: =_xlfn.LET(_xlpm._asset,"relic_layout", _xlfn.CONCAT(_xlpm._asset,"[",_xlpm._asset,"_",$F20,"]")) -> relic_layout[relic_layout_56] | F20: 56 | G20: =IF($A20<>"","relic_desc_"&$A20,"") -> relic_desc_300023 | H20: 所有设备 额外伤害 + 24 | J20: Relic_Modify_Variable | L20: 24 | M20: global_atk_add | N20: =ROUND(POWER(O20,(5-T20)/5),0) -> 2 | O20: 6 | P20: TRUE | T20: 3 | U20: =ROUND(V20*POWER(W20,T20),0) -> 100 | V20: 8 | W20: 2.32
D21: {=_xlfn.LET( _xlpm.idx,MATCH(relic!$M21,'-id 配置说明'!$A:$A,0), _xlpm.desc_1,INDEX('-id 配置说明'!$J:$J,_xlpm.idx), _xlpm.desc_2,INDEX('-id 配置说明'!$K:$K,_xlpm.idx), _xlpm.desc_array,_xlfn.TEXTSPLIT(_xlpm.desc_2,"；"), _xlpm.array_len,COLUMNS(_xlpm.desc_array), IFERROR(INDEX(_xlpm.desc_array,MIN(RIGHT($A21,1),_xlpm.array_len)),"") )} | G21: =IF($A21<>"","relic_desc_"&$A21,"")
A22: 300031 | B22: =IF(A22<>"","relic_name_"&IF(C22,LEFT($A22,LEN($A22)-1),$A22),"") -> relic_name_30003 | C22: TRUE | D22: {=_xlfn.LET( _xlpm.idx,MATCH(relic!$M22,'-id 配置说明'!$A:$A,0), _xlpm.desc_1,INDEX('-id 配置说明'!$J:$J,_xlpm.idx), _xlpm.desc_2,INDEX('-id 配置说明'!$K:$K,_xlpm.idx), _xlpm.desc_array,_xlfn.TEXTSPLIT(_xlpm.desc_2,"；"), _xlpm.array_len,COLUMNS(_xlpm.desc_array), IFERROR(INDEX(_xlpm.desc_array,MIN(RIGHT($A22,1),_xlpm.array_len)),"") )} -> 肌肉金轮草 | E22: =_xlfn.LET(_xlpm._asset,"relic_layout", _xlfn.CONCAT(_xlpm._asset,"[",_xlpm._asset,"_",$F22,"]")) -> relic_layout[relic_layout_57] | F22: 57 | G22: =IF($A22<>"","relic_desc_"&$A22,"") -> relic_desc_300031 | H22: {=_xlfn.LET(_xlpm._manual_info,$I22:$I25, IF(_xlpm._manual_info<>"",_xlpm._manual_info,_xlfn.LET( _xlpm._parm_key,$M22, _xlpm._parm_value,$L22:$L25, _xlpm._desc,_xlfn.XLOOKUP(_xlpm._parm_key,'-id 配置说明'!$A:$A,'-id 配置说明'!$F:$F), _xlpm._tp,_xlfn.XLOOKUP(_xlpm._parm_key,'-id 配置说明'!$A:$A,'-id 配置说明'!$B:$B), _xlpm._expr,INDEX(_xlfn.TEXTSPLIT(_xlpm._desc," = "),2)&" + "&_xlfn.SWITCH(_xlpm._tp,"pts",TEXT(_xlpm._parm_value/1000,"0%"),"add",_xlpm._parm_value), IFERROR(_xlpm._expr,"") )) )} -> 所有设备 暴击几率 + 4% | J22: Relic_Modify_Variable | K22: parm_int[0] = 暴击率增加值，千分比。 | L22: 40 | M22: global_critical_chance | N22: =ROUND(POWER(O22,(5-T22)/5),0) -> 2 | O22: 2 | P22: TRUE | T22: 0 | U22: =ROUND(V22*POWER(W22,T22),0) -> 9 | V22: 8.7 | W22: 2.32
A23: 300032 | B23: =IF(A23<>"","relic_name_"&IF(C23,LEFT($A23,LEN($A23)-1),$A23),"") -> relic_name_30003 | C23: TRUE | D23: {=_xlfn.LET( _xlpm.idx,MATCH(relic!$M23,'-id 配置说明'!$A:$A,0), _xlpm.desc_1,INDEX('-id 配置说明'!$J:$J,_xlpm.idx), _xlpm.desc_2,INDEX('-id 配置说明'!$K:$K,_xlpm.idx), _xlpm.desc_array,_xlfn.TEXTSPLIT(_xlpm.desc_2,"；"), _xlpm.array_len,COLUMNS(_xlpm.desc_array), IFERROR(INDEX(_xlpm.desc_array,MIN(RIGHT($A23,1),_xlpm.array_len)),"") )} -> 肌肉金轮草 | E23: =_xlfn.LET(_xlpm._asset,"relic_layout", _xlfn.CONCAT(_xlpm._asset,"[",_xlpm._asset,"_",$F23,"]")) -> relic_layout[relic_layout_57] | F23: 57 | G23: =IF($A23<>"","relic_desc_"&$A23,"") -> relic_desc_300032 | H23: 所有设备 暴击几率 + 6% | J23: Relic_Modify_Variable | K23: parm_int[0] = 暴击率增加值，千分比。 | L23: 60 | M23: global_critical_chance | N23: =ROUND(POWER(O23,(5-T23)/5),0) -> 2 | O23: 2 | P23: TRUE | T23: 1 | U23: =ROUND(V23*POWER(W23,T23),0) -> 20 | V23: 8.7 | W23: 2.32
A24: 300033 | B24: =IF(A24<>"","relic_name_"&IF(C24,LEFT($A24,LEN($A24)-1),$A24),"") -> relic_name_30003 | C24: TRUE | D24: {=_xlfn.LET( _xlpm.idx,MATCH(relic!$M24,'-id 配置说明'!$A:$A,0), _xlpm.desc_1,INDEX('-id 配置说明'!$J:$J,_xlpm.idx), _xlpm.desc_2,INDEX('-id 配置说明'!$K:$K,_xlpm.idx), _xlpm.desc_array,_xlfn.TEXTSPLIT(_xlpm.desc_2,"；"), _xlpm.array_len,COLUMNS(_xlpm.desc_array), IFERROR(INDEX(_xlpm.desc_array,MIN(RIGHT($A24,1),_xlpm.array_len)),"") )} -> 肌肉金轮草 | E24: =_xlfn.LET(_xlpm._asset,"relic_layout", _xlfn.CONCAT(_xlpm._asset,"[",_xlpm._asset,"_",$F24,"]")) -> relic_layout[relic_layout_57] | F24: 57 | G24: =IF($A24<>"","relic_desc_"&$A24,"") -> relic_desc_300033 | H24: 所有设备 暴击几率 + 9% | J24: Relic_Modify_Variable | K24: parm_int[0] = 暴击率增加值，千分比。 | L24: 90 | M24: global_critical_chance | N24: =ROUND(POWER(O24,(5-T24)/5),0) -> 2 | O24: 2 | P24: TRUE | T24: 2 | U24: =ROUND(V24*POWER(W24,T24),0) -> 47 | V24: 8.7 | W24: 2.32
A25: 300034 | B25: =IF(A25<>"","relic_name_"&IF(C25,LEFT($A25,LEN($A25)-1),$A25),"") -> relic_name_30003 | C25: TRUE | D25: {=_xlfn.LET( _xlpm.idx,MATCH(relic!$M25,'-id 配置说明'!$A:$A,0), _xlpm.desc_1,INDEX('-id 配置说明'!$J:$J,_xlpm.idx), _xlpm.desc_2,INDEX('-id 配置说明'!$K:$K,_xlpm.idx), _xlpm.desc_array,_xlfn.TEXTSPLIT(_xlpm.desc_2,"；"), _xlpm.array_len,COLUMNS(_xlpm.desc_array), IFERROR(INDEX(_xlpm.desc_array,MIN(RIGHT($A25,1),_xlpm.array_len)),"") )} -> 肌肉金轮草 | E25: =_xlfn.LET(_xlpm._asset,"relic_layout", _xlfn.CONCAT(_xlpm._asset,"[",_xlpm._asset,"_",$F25,"]")) -> relic_layout[relic_layout_57] | F25: 57 | G25: =IF($A25<>"","relic_desc_"&$A25,"") -> relic_desc_300034 | H25: 所有设备 暴击几率 + 13% | J25: Relic_Modify_Variable | K25: parm_int[0] = 暴击率增加值，千分比。 | L25: 130 | M25: global_critical_chance | N25: =ROUND(POWER(O25,(5-T25)/5),0) -> 1 | O25: 2 | P25: TRUE | T25: 3 | U25: =ROUND(V25*POWER(W25,T25),0) -> 109 | V25: 8.7 | W25: 2.32
D26: {=_xlfn.LET( _xlpm.idx,MATCH(relic!$M26,'-id 配置说明'!$A:$A,0), _xlpm.desc_1,INDEX('-id 配置说明'!$J:$J,_xlpm.idx), _xlpm.desc_2,INDEX('-id 配置说明'!$K:$K,_xlpm.idx), _xlpm.desc_array,_xlfn.TEXTSPLIT(_xlpm.desc_2,"；"), _xlpm.array_len,COLUMNS(_xlpm.desc_array), IFERROR(INDEX(_xlpm.desc_array,MIN(RIGHT($A26,1),_xlpm.array_len)),"") )} | G26: =IF($A26<>"","relic_desc_"&$A26,"")
A27: 300041 | B27: =IF(A27<>"","relic_name_"&IF(C27,LEFT($A27,LEN($A27)-1),$A27),"") -> relic_name_30004 | C27: TRUE | D27: {=_xlfn.LET( _xlpm.idx,MATCH(relic!$M27,'-id 配置说明'!$A:$A,0), _xlpm.desc_1,INDEX('-id 配置说明'!$J:$J,_xlpm.idx), _xlpm.desc_2,INDEX('-id 配置说明'!$K:$K,_xlpm.idx), _xlpm.desc_array,_xlfn.TEXTSPLIT(_xlpm.desc_2,"；"), _xlpm.array_len,COLUMNS(_xlpm.desc_array), IFERROR(INDEX(_xlpm.desc_array,MIN(RIGHT($A27,1),_xlpm.array_len)),"") )} -> 托利莲 | E27: =_xlfn.LET(_xlpm._asset,"relic_layout", _xlfn.CONCAT(_xlpm._asset,"[",_xlpm._asset,"_",$F27,"]")) -> relic_layout[relic_layout_58] | F27: 58 | G27: =IF($A27<>"","relic_desc_"&$A27,"") -> relic_desc_300041 | H27: {=_xlfn.LET(_xlpm._manual_info,$I27:$I30, IF(_xlpm._manual_info<>"",_xlpm._manual_info,_xlfn.LET( _xlpm._parm_key,$M27, _xlpm._parm_value,$L27:$L30, _xlpm._desc,_xlfn.XLOOKUP(_xlpm._parm_key,'-id 配置说明'!$A:$A,'-id 配置说明'!$F:$F), _xlpm._tp,_xlfn.XLOOKUP(_xlpm._parm_key,'-id 配置说明'!$A:$A,'-id 配置说明'!$B:$B), _xlpm._expr,INDEX(_xlfn.TEXTSPLIT(_xlpm._desc," = "),2)&" + "&_xlfn.SWITCH(_xlpm._tp,"pts",TEXT(_xlpm._parm_value/1000,"0%"),"add",_xlpm._parm_value), IFERROR(_xlpm._expr,"") )) )} -> 所有设备 暴击伤害 + 10% | J27: Relic_Modify_Variable | K27: parm_int[0] = 暴击伤害增加值，千分比。 | L27: 100 | M27: global_critical_dmg_rate | N27: =ROUND(POWER(O27,(5-T27)/5),0) -> 3 | O27: 3 | P27: TRUE | T27: 0 | U27: =ROUND(V27*POWER(W27,T27),0) -> 8 | V27: 8.3 | W27: 2.32
A28: 300042 | B28: =IF(A28<>"","relic_name_"&IF(C28,LEFT($A28,LEN($A28)-1),$A28),"") -> relic_name_30004 | C28: TRUE | D28: {=_xlfn.LET( _xlpm.idx,MATCH(relic!$M28,'-id 配置说明'!$A:$A,0), _xlpm.desc_1,INDEX('-id 配置说明'!$J:$J,_xlpm.idx), _xlpm.desc_2,INDEX('-id 配置说明'!$K:$K,_xlpm.idx), _xlpm.desc_array,_xlfn.TEXTSPLIT(_xlpm.desc_2,"；"), _xlpm.array_len,COLUMNS(_xlpm.desc_array), IFERROR(INDEX(_xlpm.desc_array,MIN(RIGHT($A28,1),_xlpm.array_len)),"") )} -> 托利莲 | E28: =_xlfn.LET(_xlpm._asset,"relic_layout", _xlfn.CONCAT(_xlpm._asset,"[",_xlpm._asset,"_",$F28,"]")) -> relic_layout[relic_layout_58] | F28: 58 | G28: =IF($A28<>"","relic_desc_"&$A28,"") -> relic_desc_300042 | H28: 所有设备 暴击伤害 + 20% | J28: Relic_Modify_Variable | K28: parm_int[0] = 暴击伤害增加值，千分比。 | L28: 200 | M28: global_critical_dmg_rate | N28: =ROUND(POWER(O28,(5-T28)/5),0) -> 2 | O28: 3 | P28: TRUE | T28: 1 | U28: =ROUND(V28*POWER(W28,T28),0) -> 19 | V28: 8.3 | W28: 2.32
A29: 300043 | B29: =IF(A29<>"","relic_name_"&IF(C29,LEFT($A29,LEN($A29)-1),$A29),"") -> relic_name_30004 | C29: TRUE | D29: {=_xlfn.LET( _xlpm.idx,MATCH(relic!$M29,'-id 配置说明'!$A:$A,0), _xlpm.desc_1,INDEX('-id 配置说明'!$J:$J,_xlpm.idx), _xlpm.desc_2,INDEX('-id 配置说明'!$K:$K,_xlpm.idx), _xlpm.desc_array,_xlfn.TEXTSPLIT(_xlpm.desc_2,"；"), _xlpm.array_len,COLUMNS(_xlpm.desc_array), IFERROR(INDEX(_xlpm.desc_array,MIN(RIGHT($A29,1),_xlpm.array_len)),"") )} -> 托利莲 | E29: =_xlfn.LET(_xlpm._asset,"relic_layout", _xlfn.CONCAT(_xlpm._asset,"[",_xlpm._asset,"_",$F29,"]")) -> relic_layout[relic_layout_58] | F29: 58 | G29: =IF($A29<>"","relic_desc_"&$A29,"") -> relic_desc_300043 | H29: 所有设备 暴击伤害 + 40% | J29: Relic_Modify_Variable | K29: parm_int[0] = 暴击伤害增加值，千分比。 | L29: 400 | M29: global_critical_dmg_rate | N29: =ROUND(POWER(O29,(5-T29)/5),0) -> 2 | O29: 3 | P29: TRUE | T29: 2 | U29: =ROUND(V29*POWER(W29,T29),0) -> 45 | V29: 8.3 | W29: 2.32
A30: 300044 | B30: =IF(A30<>"","relic_name_"&IF(C30,LEFT($A30,LEN($A30)-1),$A30),"") -> relic_name_30004 | C30: TRUE | D30: {=_xlfn.LET( _xlpm.idx,MATCH(relic!$M30,'-id 配置说明'!$A:$A,0), _xlpm.desc_1,INDEX('-id 配置说明'!$J:$J,_xlpm.idx), _xlpm.desc_2,INDEX('-id 配置说明'!$K:$K,_xlpm.idx), _xlpm.desc_array,_xlfn.TEXTSPLIT(_xlpm.desc_2,"；"), _xlpm.array_len,COLUMNS(_xlpm.desc_array), IFERROR(INDEX(_xlpm.desc_array,MIN(RIGHT($A30,1),_xlpm.array_len)),"") )} -> 托利莲 | E30: =_xlfn.LET(_xlpm._asset,"relic_layout", _xlfn.CONCAT(_xlpm._asset,"[",_xlpm._asset,"_",$F30,"]")) -> relic_layout[relic_layout_58] | F30: 58 | G30: =IF($A30<>"","relic_desc_"&$A30,"") -> relic_desc_300044 | H30: 所有设备 暴击伤害 + 80% | J30: Relic_Modify_Variable | K30: parm_int[0] = 暴击伤害增加值，千分比。 | L30: 800 | M30: global_critical_dmg_rate | N30: =ROUND(POWER(O30,(5-T30)/5),0) -> 2 | O30: 3 | P30: TRUE | T30: 3 | U30: =ROUND(V30*POWER(W30,T30),0) -> 104 | V30: 8.3 | W30: 2.32
B31: =IF(A31<>"","relic_name_"&$A31,"") | D31: {=_xlfn.LET( _xlpm.idx,MATCH(relic!$M31,'-id 配置说明'!$A:$A,0), _xlpm.desc_1,INDEX('-id 配置说明'!$J:$J,_xlpm.idx), _xlpm.desc_2,INDEX('-id 配置说明'!$K:$K,_xlpm.idx), _xlpm.desc_array,_xlfn.TEXTSPLIT(_xlpm.desc_2,"；"), _xlpm.array_len,COLUMNS(_xlpm.desc_array), IFERROR(INDEX(_xlpm.desc_array,MIN(RIGHT($A31,1),_xlpm.array_len)),"") )} | G31: =IF($A31<>"","relic_desc_"&$A31,"") | N31: =IF($A31>0,5,"") | P31: =IF($A31>0,TRUE,"") | U31: =IF(A31<>"",RIGHT(A31)*5,"")
A32: 300051 | B32: =IF(A32<>"","relic_name_"&$A32,"") -> relic_name_300051 | D32: {=_xlfn.LET( _xlpm.idx,MATCH(relic!$M32,'-id 配置说明'!$A:$A,0), _xlpm.desc_1,INDEX('-id 配置说明'!$J:$J,_xlpm.idx), _xlpm.desc_2,INDEX('-id 配置说明'!$K:$K,_xlpm.idx), _xlpm.desc_array,_xlfn.TEXTSPLIT(_xlpm.desc_2,"；"), _xlpm.array_len,COLUMNS(_xlpm.desc_array), IFERROR(INDEX(_xlpm.desc_array,MIN(RIGHT($A32,1),_xlpm.array_len)),"") )} -> 紫水晶 | E32: =IF($F32<>"",_xlfn.CONCAT("relic_icons[relic_layout_",$F32,"]"),"") -> relic_icons[relic_layout_12] | F32: 12 | G32: =IF($A32<>"","relic_desc_"&$A32,"") -> relic_desc_300051 | H32: {=_xlfn.LET(_xlpm._manual_info,$I32:$I34, IF(_xlpm._manual_info<>"",_xlpm._manual_info,_xlfn.LET( _xlpm._parm_key,$M32, _xlpm._parm_value,$L32:$L34, _xlpm._desc,_xlfn.XLOOKUP(_xlpm._parm_key,'-id 配置说明'!$A:$A,'-id 配置说明'!$F:$F), _xlpm._tp,_xlfn.XLOOKUP(_xlpm._parm_key,'-id 配置说明'!$A:$A,'-id 配置说明'!$B:$B), _xlpm._expr,INDEX(_xlfn.TEXTSPLIT(_xlpm._desc," = "),2)&" + "&_xlfn.SWITCH(_xlpm._tp,"pts",TEXT(_xlpm._parm_value/1000,"0%"),"add",_xlpm._parm_value), IFERROR(_xlpm._expr,"") )) )} -> 所有设备 击退 + 5% | J32: Relic_Modify_Variable | L32: 50 | M32: global_knockback | N32: =IF($A32>0,5,"") -> 5 | P32: =IF($A32>0,TRUE,"") -> TRUE | S32: =_xlfn.LET(_xlpm.end,IFERROR(VALUE(RIGHT($A32,1)),0), IF(_xlpm.end>1,$A31,"")) | T32: 0 | U32: =IF(A32<>"",RIGHT(A32)*5,"") -> 5
A33: 300052 | B33: =IF(A33<>"","relic_name_"&$A33,"") -> relic_name_300052 | D33: {=_xlfn.LET( _xlpm.idx,MATCH(relic!$M33,'-id 配置说明'!$A:$A,0), _xlpm.desc_1,INDEX('-id 配置说明'!$J:$J,_xlpm.idx), _xlpm.desc_2,INDEX('-id 配置说明'!$K:$K,_xlpm.idx), _xlpm.desc_array,_xlfn.TEXTSPLIT(_xlpm.desc_2,"；"), _xlpm.array_len,COLUMNS(_xlpm.desc_array), IFERROR(INDEX(_xlpm.desc_array,MIN(RIGHT($A33,1),_xlpm.array_len)),"") )} -> 粉水晶 | E33: =IF($F33<>"",_xlfn.CONCAT("relic_icons[relic_layout_",$F33,"]"),"") -> relic_icons[relic_layout_13] | F33: 13 | G33: =IF($A33<>"","relic_desc_"&$A33,"") -> relic_desc_300052 | H33: 所有设备 击退 + 10% | J33: Relic_Modify_Variable | L33: 100 | M33: global_knockback | N33: =IF($A33>0,5,"") -> 5 | P33: =IF($A33>0,TRUE,"") -> TRUE | S33: =_xlfn.LET(_xlpm.end,IFERROR(VALUE(RIGHT($A33,1)),0), IF(_xlpm.end>1,$A32,"")) -> 300051 | T33: 1 | U33: =IF(A33<>"",RIGHT(A33)*5,"") -> 10
A34: 300053 | B34: =IF(A34<>"","relic_name_"&$A34,"") -> relic_name_300053 | D34: {=_xlfn.LET( _xlpm.idx,MATCH(relic!$M34,'-id 配置说明'!$A:$A,0), _xlpm.desc_1,INDEX('-id 配置说明'!$J:$J,_xlpm.idx), _xlpm.desc_2,INDEX('-id 配置说明'!$K:$K,_xlpm.idx), _xlpm.desc_array,_xlfn.TEXTSPLIT(_xlpm.desc_2,"；"), _xlpm.array_len,COLUMNS(_xlpm.desc_array), IFERROR(INDEX(_xlpm.desc_array,MIN(RIGHT($A34,1),_xlpm.array_len)),"") )} -> 黄水晶 | E34: =IF($F34<>"",_xlfn.CONCAT("relic_icons[relic_layout_",$F34,"]"),"") -> relic_icons[relic_layout_14] | F34: 14 | G34: =IF($A34<>"","relic_desc_"&$A34,"") -> relic_desc_300053 | H34: 所有设备 击退 + 15% | J34: Relic_Modify_Variable | L34: 150 | M34: global_knockback | N34: =IF($A34>0,5,"") -> 5 | P34: =IF($A34>0,TRUE,"") -> TRUE | S34: =_xlfn.LET(_xlpm.end,IFERROR(VALUE(RIGHT($A34,1)),0), IF(_xlpm.end>1,$A33,"")) -> 300052 | T34: 2 | U34: =IF(A34<>"",RIGHT(A34)*5,"") -> 15
B35: =IF(A35<>"","relic_name_"&$A35,"") | D35: {=_xlfn.LET( _xlpm.idx,MATCH(relic!$M35,'-id 配置说明'!$A:$A,0), _xlpm.desc_1,INDEX('-id 配置说明'!$J:$J,_xlpm.idx), _xlpm.desc_2,INDEX('-id 配置说明'!$K:$K,_xlpm.idx), _xlpm.desc_array,_xlfn.TEXTSPLIT(_xlpm.desc_2,"；"), _xlpm.array_len,COLUMNS(_xlpm.desc_array), IFERROR(INDEX(_xlpm.desc_array,MIN(RIGHT($A35,1),_xlpm.array_len)),"") )} | G35: =IF($A35<>"","relic_desc_"&$A35,"") | N35: =IF($A35>0,5,"") | P35: =IF($A35>0,TRUE,"") | S35: =_xlfn.LET(_xlpm.end,IFERROR(VALUE(RIGHT($A35,1)),0), IF(_xlpm.end>1,$A34,"")) | U35: =IF(A35<>"",RIGHT(A35)*5,"")
A36: 300061 | B36: =IF(A36<>"","relic_name_"&$A36,"") -> relic_name_300061 | D36: {=_xlfn.LET( _xlpm.idx,MATCH(relic!$M36,'-id 配置说明'!$A:$A,0), _xlpm.desc_1,INDEX('-id 配置说明'!$J:$J,_xlpm.idx), _xlpm.desc_2,INDEX('-id 配置说明'!$K:$K,_xlpm.idx), _xlpm.desc_array,_xlfn.TEXTSPLIT(_xlpm.desc_2,"；"), _xlpm.array_len,COLUMNS(_xlpm.desc_array), IFERROR(INDEX(_xlpm.desc_array,MIN(RIGHT($A36,1),_xlpm.array_len)),"") )} -> 国王骰子 | E36: =IF($F36<>"",_xlfn.CONCAT("relic_icons[relic_layout_",$F36,"]"),"") -> relic_icons[relic_layout_15] | F36: 15 | G36: =IF($A36<>"","relic_desc_"&$A36,"") -> relic_desc_300061 | H36: {=_xlfn.LET(_xlpm._manual_info,$I36:$I38, IF(_xlpm._manual_info<>"",_xlpm._manual_info,_xlfn.LET( _xlpm._parm_key,$M36, _xlpm._parm_value,$L36:$L38, _xlpm._desc,_xlfn.XLOOKUP(_xlpm._parm_key,'-id 配置说明'!$A:$A,'-id 配置说明'!$F:$F), _xlpm._tp,_xlfn.XLOOKUP(_xlpm._parm_key,'-id 配置说明'!$A:$A,'-id 配置说明'!$B:$B), _xlpm._expr,INDEX(_xlfn.TEXTSPLIT(_xlpm._desc," = "),2)&" + "&_xlfn.SWITCH(_xlpm._tp,"pts",TEXT(_xlpm._parm_value/1000,"0%"),"add",_xlpm._parm_value), IFERROR(_xlpm._expr,"") )) )} -> 所有设备 破甲 + 10% | J36: Relic_Modify_Variable | K36: parm_int[0] = 破甲增加值，百分比的千分比。 | L36: 100 | M36: global_armor_piercing | N36: =IF($A36>0,5,"") -> 5 | P36: =IF($A36>0,TRUE,"") -> TRUE | S36: =_xlfn.LET(_xlpm.end,IFERROR(VALUE(RIGHT($A36,1)),0), IF(_xlpm.end>1,$A35,"")) | T36: 0 | U36: =IF(A36<>"",RIGHT(A36)*5,"") -> 5
A37: 300062 | B37: =IF(A37<>"","relic_name_"&$A37,"") -> relic_name_300062 | D37: {=_xlfn.LET( _xlpm.idx,MATCH(relic!$M37,'-id 配置说明'!$A:$A,0), _xlpm.desc_1,INDEX('-id 配置说明'!$J:$J,_xlpm.idx), _xlpm.desc_2,INDEX('-id 配置说明'!$K:$K,_xlpm.idx), _xlpm.desc_array,_xlfn.TEXTSPLIT(_xlpm.desc_2,"；"), _xlpm.array_len,COLUMNS(_xlpm.desc_array), IFERROR(INDEX(_xlpm.desc_array,MIN(RIGHT($A37,1),_xlpm.array_len)),"") )} -> 国王骰子 | E37: =IF($F37<>"",_xlfn.CONCAT("relic_icons[relic_layout_",$F37,"]"),"") -> relic_icons[relic_layout_16] | F37: 16 | G37: =IF($A37<>"","relic_desc_"&$A37,"") -> relic_desc_300062 | H37: 所有设备 破甲 + 20% | J37: Relic_Modify_Variable | K37: parm_int[0] = 破甲增加值，百分比的千分比。 | L37: 200 | M37: global_armor_piercing | N37: =IF($A37>0,5,"") -> 5 | P37: =IF($A37>0,TRUE,"") -> TRUE | S37: =_xlfn.LET(_xlpm.end,IFERROR(VALUE(RIGHT($A37,1)),0), IF(_xlpm.end>1,$A36,"")) -> 300061 | T37: 1 | U37: =IF(A37<>"",RIGHT(A37)*5,"") -> 10
A38: 300063 | B38: =IF(A38<>"","relic_name_"&$A38,"") -> relic_name_300063 | D38: {=_xlfn.LET( _xlpm.idx,MATCH(relic!$M38,'-id 配置说明'!$A:$A,0), _xlpm.desc_1,INDEX('-id 配置说明'!$J:$J,_xlpm.idx), _xlpm.desc_2,INDEX('-id 配置说明'!$K:$K,_xlpm.idx), _xlpm.desc_array,_xlfn.TEXTSPLIT(_xlpm.desc_2,"；"), _xlpm.array_len,COLUMNS(_xlpm.desc_array), IFERROR(INDEX(_xlpm.desc_array,MIN(RIGHT($A38,1),_xlpm.array_len)),"") )} -> 国王骰子 | E38: =IF($F38<>"",_xlfn.CONCAT("relic_icons[relic_layout_",$F38,"]"),"") -> relic_icons[relic_layout_17] | F38: 17 | G38: =IF($A38<>"","relic_desc_"&$A38,"") -> relic_desc_300063 | H38: 所有设备 破甲 + 30% | J38: Relic_Modify_Variable | K38: parm_int[0] = 破甲增加值，百分比的千分比。 | L38: 300 | M38: global_armor_piercing | N38: =IF($A38>0,5,"") -> 5 | P38: =IF($A38>0,TRUE,"") -> TRUE | S38: =_xlfn.LET(_xlpm.end,IFERROR(VALUE(RIGHT($A38,1)),0), IF(_xlpm.end>1,$A37,"")) -> 300062 | T38: 2 | U38: =IF(A38<>"",RIGHT(A38)*5,"") -> 15
B39: =IF(A39<>"","relic_name_"&$A39,"") | D39: {=_xlfn.LET( _xlpm.idx,MATCH(relic!$M39,'-id 配置说明'!$A:$A,0), _xlpm.desc_1,INDEX('-id 配置说明'!$J:$J,_xlpm.idx), _xlpm.desc_2,INDEX('-id 配置说明'!$K:$K,_xlpm.idx), _xlpm.desc_array,_xlfn.TEXTSPLIT(_xlpm.desc_2,"；"), _xlpm.array_len,COLUMNS(_xlpm.desc_array), IFERROR(INDEX(_xlpm.desc_array,MIN(RIGHT($A39,1),_xlpm.array_len)),"") )} | G39: =IF($A39<>"","relic_desc_"&$A39,"") | N39: =IF($A39>0,5,"") | P39: =IF($A39>0,TRUE,"") | S39: =_xlfn.LET(_xlpm.end,IFERROR(VALUE(RIGHT($A39,1)),0), IF(_xlpm.end>1,$A38,"")) | U39: =IF(A39<>"",RIGHT(A39)*5,"")
A40: 300071 | B40: =IF(A40<>"","relic_name_"&IF(C40,LEFT($A40,LEN($A40)-1),$A40),"") -> relic_name_30007 | C40: TRUE | D40: {=_xlfn.LET( _xlpm.idx,MATCH(relic!$M40,'-id 配置说明'!$A:$A,0), _xlpm.desc_1,INDEX('-id 配置说明'!$J:$J,_xlpm.idx), _xlpm.desc_2,INDEX('-id 配置说明'!$K:$K,_xlpm.idx), _xlpm.desc_array,_xlfn.TEXTSPLIT(_xlpm.desc_2,"；"), _xlpm.array_len,COLUMNS(_xlpm.desc_array), IFERROR(INDEX(_xlpm.desc_array,MIN(RIGHT($A40,1),_xlpm.array_len)),"") )} -> 守护符 | E40: =_xlfn.LET(_xlpm._asset,"relic_layout", _xlfn.CONCAT(_xlpm._asset,"[",_xlpm._asset,"_",$F40,"]")) -> relic_layout[relic_layout_9] | F40: 9 | G40: =IF($A40<>"","relic_desc_"&$A40,"") -> relic_desc_300071 | H40: {=_xlfn.LET(_xlpm._manual_info,$I40:$I43, IF(_xlpm._manual_info<>"",_xlpm._manual_info,_xlfn.LET( _xlpm._parm_key,$M40, _xlpm._parm_value,$L40:$L43, _xlpm._desc,_xlfn.XLOOKUP(_xlpm._parm_key,'-id 配置说明'!$A:$A,'-id 配置说明'!$F:$F), _xlpm._tp,_xlfn.XLOOKUP(_xlpm._parm_key,'-id 配置说明'!$A:$A,'-id 配置说明'!$B:$B), _xlpm._expr,INDEX(_xlfn.TEXTSPLIT(_xlpm._desc," = "),2)&" + "&_xlfn.SWITCH(_xlpm._tp,"pts",TEXT(_xlpm._parm_value/1000,"0%"),"add",_xlpm._parm_value), IFERROR(_xlpm._expr,"") )) )} -> 所有设备 护甲 + 10 | J40: Relic_Modify_Variable | K40: parm_int[0] = 护甲增加值。 | L40: 10 | M40: global_armor_add | N40: =ROUND(POWER(O40,(5-T40)/5),0) -> 5 | O40: 5 | P40: TRUE | T40: 0 | U40: =ROUND(V40*POWER(W40,T40),0) -> 7 | V40: 6.7 | W40: 2.25
A41: 300072 | B41: =IF(A41<>"","relic_name_"&IF(C41,LEFT($A41,LEN($A41)-1),$A41),"") -> relic_name_30007 | C41: TRUE | D41: {=_xlfn.LET( _xlpm.idx,MATCH(relic!$M41,'-id 配置说明'!$A:$A,0), _xlpm.desc_1,INDEX('-id 配置说明'!$J:$J,_xlpm.idx), _xlpm.desc_2,INDEX('-id 配置说明'!$K:$K,_xlpm.idx), _xlpm.desc_array,_xlfn.TEXTSPLIT(_xlpm.desc_2,"；"), _xlpm.array_len,COLUMNS(_xlpm.desc_array), IFERROR(INDEX(_xlpm.desc_array,MIN(RIGHT($A41,1),_xlpm.array_len)),"") )} -> 守护符 | E41: =_xlfn.LET(_xlpm._asset,"relic_layout", _xlfn.CONCAT(_xlpm._asset,"[",_xlpm._asset,"_",$F41,"]")) -> relic_layout[relic_layout_9] | F41: 9 | G41: =IF($A41<>"","relic_desc_"&$A41,"") -> relic_desc_300072 | H41: 所有设备 护甲 + 20 | J41: Relic_Modify_Variable | K41: parm_int[0] = 护甲增加值。 | L41: 20 | M41: global_armor_add | N41: =ROUND(POWER(O41,(5-T41)/5),0) -> 4 | O41: 5 | P41: TRUE | T41: 1 | U41: =ROUND(V41*POWER(W41,T41),0) -> 15 | V41: 6.7 | W41: 2.25
...

Sheet relic_pool
A1: pool_id | B1: parm_int | E1: weight
A2: uint key | B2: uint key | E2: int
A3: 池子编号 | B3: relic 编号 | C3: 备注 名称 | D3: 备注 效果 | E3: 随机权重
A4: 1 | B4: 300011 | C4: =_xlfn.XLOOKUP($B4,relic!A:A,relic!D:D,"") -> 阿菊 | D4: =VLOOKUP($B4,relic!A:H,7,0) -> relic_desc_300011 | E4: 1 | H4: =IF(E4,B4&"="&E4,"") -> 300011=1 | K4: =_xlfn.TEXTJOIN(";",1,H:H) -> 300011=1;300012=1;300013=1;300021=1;300022=1;300023=1;300031=1;300032=1;300033=1;300041=1;300042=1;300043=1;300051=1;300052=1;300053=1;300061=1;300062=1;300063=1;300071=1;300072=1;300073=1;300081=1;300082=1;300083=1;300091=1;300092=1;300093=1;301011=1;301012=1;301013=1;301021=1;301022=1;301023=1;301031=1;301032=1;301033=1;301041=1;301042=1;301043=1;301051=1;301052=1;301053=1;301061=1;301062=1;301063=1;301211=1;301212=1;301213=1;301221=1;301222=1;301223=1;301231=1;301232=1;301233=1;302011=1;302012=1;302013=1;302021=1;302022=1;302023=1;302031=1;302032=1;302033=1;302041=1;302042=1;302043=1;302051=1;302052=1;302053=1;302061=1;302062=1;302063=1;302211=1;302212=1;302213=1;302231=1;302232=1;302233=1;302311=1;302312=1;302313=1;302321=1;302322=1;302323=1;310201=10;310202=10;310203=10;310204=10;310205=10;310206=10;310207=10;310208=10;310209=10;310210=10;310211=10;310212=10;310213=10;310217=10;310218=10;310219=10;310401=10;310402=10;310403=10;310404=10;310407=10;310408=10;310409=10
A5: 1 | B5: 300012 | C5: =_xlfn.XLOOKUP($B5,relic!A:A,relic!D:D,"") -> 阿菊 | D5: =VLOOKUP($B5,relic!A:H,7,0) -> relic_desc_300012 | E5: 1 | H5: =IF(E5,B5&"="&E5,"") -> 300012=1
A6: 1 | B6: 300013 | C6: =_xlfn.XLOOKUP($B6,relic!A:A,relic!D:D,"") -> 阿菊 | D6: =VLOOKUP($B6,relic!A:H,7,0) -> relic_desc_300013 | E6: 1 | H6: =IF(E6,B6&"="&E6,"") -> 300013=1
A7: 1 | B7: 300021 | C7: =_xlfn.XLOOKUP($B7,relic!A:A,relic!D:D,"") -> 火星蝶 | D7: =VLOOKUP($B7,relic!A:H,7,0) -> relic_desc_300021 | E7: 1 | H7: =IF(E7,B7&"="&E7,"") -> 300021=1
A8: 1 | B8: 300022 | C8: =_xlfn.XLOOKUP($B8,relic!A:A,relic!D:D,"") -> 火星蝶 | D8: =VLOOKUP($B8,relic!A:H,7,0) -> relic_desc_300022 | E8: 1 | H8: =IF(E8,B8&"="&E8,"") -> 300022=1
A9: 1 | B9: 300023 | C9: =_xlfn.XLOOKUP($B9,relic!A:A,relic!D:D,"") -> 火星蝶 | D9: =VLOOKUP($B9,relic!A:H,7,0) -> relic_desc_300023 | E9: 1 | H9: =IF(E9,B9&"="&E9,"") -> 300023=1
A10: 1 | B10: 300031 | C10: =_xlfn.XLOOKUP($B10,relic!A:A,relic!D:D,"") -> 肌肉金轮草 | D10: =VLOOKUP($B10,relic!A:H,7,0) -> relic_desc_300031 | E10: 1 | H10: =IF(E10,B10&"="&E10,"") -> 300031=1
A11: 1 | B11: 300032 | C11: =_xlfn.XLOOKUP($B11,relic!A:A,relic!D:D,"") -> 肌肉金轮草 | D11: =VLOOKUP($B11,relic!A:H,7,0) -> relic_desc_300032 | E11: 1 | H11: =IF(E11,B11&"="&E11,"") -> 300032=1
A12: 1 | B12: 300033 | C12: =_xlfn.XLOOKUP($B12,relic!A:A,relic!D:D,"") -> 肌肉金轮草 | D12: =VLOOKUP($B12,relic!A:H,7,0) -> relic_desc_300033 | E12: 1 | H12: =IF(E12,B12&"="&E12,"") -> 300033=1
A13: 1 | B13: 300041 | C13: =_xlfn.XLOOKUP($B13,relic!A:A,relic!D:D,"") -> 托利莲 | D13: =VLOOKUP($B13,relic!A:H,7,0) -> relic_desc_300041 | E13: 1 | H13: =IF(E13,B13&"="&E13,"") -> 300041=1
A14: 1 | B14: 300042 | C14: =_xlfn.XLOOKUP($B14,relic!A:A,relic!D:D,"") -> 托利莲 | D14: =VLOOKUP($B14,relic!A:H,7,0) -> relic_desc_300042 | E14: 1 | H14: =IF(E14,B14&"="&E14,"") -> 300042=1
A15: 1 | B15: 300043 | C15: =_xlfn.XLOOKUP($B15,relic!A:A,relic!D:D,"") -> 托利莲 | D15: =VLOOKUP($B15,relic!A:H,7,0) -> relic_desc_300043 | E15: 1 | H15: =IF(E15,B15&"="&E15,"") -> 300043=1
A16: 1 | B16: 300051 | C16: =_xlfn.XLOOKUP($B16,relic!A:A,relic!D:D,"") -> 紫水晶 | D16: =VLOOKUP($B16,relic!A:H,7,0) -> relic_desc_300051 | E16: 1 | H16: =IF(E16,B16&"="&E16,"") -> 300051=1
... A133: 1 | B133: 310222 | C133: =_xlfn.XLOOKUP($B133,relic!A:A,relic!D:D,"") -> 子弹碰撞3 | D133: =VLOOKUP($B133,relic!A:H,7,0) -> relic_desc_310222 | E133: 0 | H133: =IF(E133,B133&"="&E133,"")
C134: =_xlfn.XLOOKUP($B134,relic!A:A,relic!D:D,"") -> 0 | H134: =IF(E134,B134&"="&E134,"")
A135: 1 | B135: 310401 | C135: =_xlfn.XLOOKUP($B135,relic!A:A,relic!D:D,"") -> 枪口风暴 | D135: =VLOOKUP($B135,relic!A:H,7,0) -> relic_desc_310401 | E135: 10 | H135: =IF(E135,B135&"="&E135,"") -> 310401=10
A136: 1 | B136: 310402 | C136: =_xlfn.XLOOKUP($B136,relic!A:A,relic!D:D,"") -> 枪焰冲击 | D136: =VLOOKUP($B136,relic!A:H,7,0) -> relic_desc_310402 | E136: 10 | H136: =IF(E136,B136&"="&E136,"") -> 310402=10
A137: 1 | B137: 310403 | C137: =_xlfn.XLOOKUP($B137,relic!A:A,relic!D:D,"") -> 枪焰燃烧 | D137: =VLOOKUP($B137,relic!A:H,7,0) -> relic_desc_310403 | E137: 10 | H137: =IF(E137,B137&"="&E137,"") -> 310403=10
A138: 1 | B138: 310404 | C138: =_xlfn.XLOOKUP($B138,relic!A:A,relic!D:D,"") -> 枪焰闪耀 | D138: =VLOOKUP($B138,relic!A:H,7,0) -> relic_desc_310404 | E138: 10 | H138: =IF(E138,B138&"="&E138,"") -> 310404=10
A139: 1 | B139: 310405 | C139: =_xlfn.XLOOKUP($B139,relic!A:A,relic!D:D,"") -> 枪托打击 | D139: =VLOOKUP($B139,relic!A:H,7,0) -> relic_desc_310405 | E139: 0 | H139: =IF(E139,B139&"="&E139,"")
A140: 1 | B140: 310406 | C140: =_xlfn.XLOOKUP($B140,relic!A:A,relic!D:D,"") -> 枪托重击 | D140: =VLOOKUP($B140,relic!A:H,7,0) -> relic_desc_310406 | E140: 0 | H140: =IF(E140,B140&"="&E140,"")
A141: 1 | B141: 310407 | C141: =_xlfn.XLOOKUP($B141,relic!A:A,relic!D:D,"") -> 作弊骰 Lv.1 | D141: =VLOOKUP($B141,relic!A:H,7,0) -> relic_desc_310407 | E141: 10 | H141: =IF(E141,B141&"="&E141,"") -> 310407=10
A142: 1 | B142: 310408 | C142: =_xlfn.XLOOKUP($B142,relic!A:A,relic!D:D,"") -> 作弊骰 Lv.2 | D142: =VLOOKUP($B142,relic!A:H,7,0) -> relic_desc_310408 | E142: 10 | H142: =IF(E142,B142&"="&E142,"") -> 310408=10
A143: 1 | B143: 310409 | C143: =_xlfn.XLOOKUP($B143,relic!A:A,relic!D:D,"") -> 作弊骰 Lv.3 | D143: =VLOOKUP($B143,relic!A:H,7,0) -> relic_desc_310409 | E143: 10 | H143: =IF(E143,B143&"="&E143,"") -> 310409=10

Sheet relic_rank
A1: id | C1: UI_shop_bg | D1: UI_bag_bg
A2: uint key | C2: string | D2: string
A3: 等级 | B3: 备注1 | C3: 商店资料图 背景板 | D3: 等级面板中的品质
A4: 0 | B4: 灰白 | C4: ui_relic_icon_bg_1 | D4: ui_relic_icon_board_level_1
A5: 1 | B5: 绿 | C5: ui_relic_icon_bg_2 | D5: ui_relic_icon_board_level_2
A6: 2 | B6: 蓝 | C6: ui_relic_icon_bg_3 | D6: ui_relic_icon_board_level_3
A7: 3 | B7: 紫 | C7: ui_relic_icon_bg_4 | D7: ui_relic_icon_board_level_4
A8: 4 | B8: 橙 | C8: ui_relic_icon_bg_5 | D8: ui_relic_icon_board_level_5

Sheet -投放筛选及l10n配置辅助
A1: relic id | B1: relic name key | C1: relic name | D1: rank | E1: relic desc key | F1: relic desc | G1: picked | I1: picked_name | L1: picked_desc
A2: 300011 | B2: =_xlfn.XLOOKUP(表2[[#This Row],[relic id]],relic!$A:$A,relic!B:B,"") -> relic_name_30001 | C2: =_xlfn.XLOOKUP(表2[[#This Row],[relic id]],relic!$A:$A,relic!D:D,"") -> 阿菊 | D2: =IF(表2[[#This Row],[relic id]]<>"",_xlfn.XLOOKUP(表2[[#This Row],[relic id]],relic!$A:$A,relic!$T:$T),"") -> 0 | E2: =_xlfn.XLOOKUP(表2[[#This Row],[relic id]],relic!$A:$A,relic!G:G,"") -> relic_desc_300011 | F2: =_xlfn.XLOOKUP(表2[[#This Row],[relic id]],relic!$A:$A,relic!H:H,"") -> 所有设备 伤害 + 15% | G2: TRUE | I2: {=_xlfn.UNIQUE(_xlfn._xlws.FILTER(表2[[relic name key]:[relic name]],表2[picked]))} -> relic_name_30001 | J2: 阿菊 | L2: {=_xlfn.UNIQUE(_xlfn._xlws.FILTER(表2[[relic desc key]:[relic desc]],表2[picked]))} -> relic_desc_300011 | M2: 所有设备 伤害 + 15%
A3: 300012 | B3: =_xlfn.XLOOKUP(表2[[#This Row],[relic id]],relic!$A:$A,relic!B:B,"") -> relic_name_30001 | C3: =_xlfn.XLOOKUP(表2[[#This Row],[relic id]],relic!$A:$A,relic!D:D,"") -> 阿菊 | D3: =IF(表2[[#This Row],[relic id]]<>"",_xlfn.XLOOKUP(表2[[#This Row],[relic id]],relic!$A:$A,relic!$T:$T),"") -> 1 | E3: =_xlfn.XLOOKUP(表2[[#This Row],[relic id]],relic!$A:$A,relic!G:G,"") -> relic_desc_300012 | F3: =_xlfn.XLOOKUP(表2[[#This Row],[relic id]],relic!$A:$A,relic!H:H,"") -> 所有设备 伤害 + 30% | G3: TRUE | I3: relic_name_30002 | J3: 火星蝶 | L3: relic_desc_300012 | M3: 所有设备 伤害 + 30%
A4: 300013 | B4: =_xlfn.XLOOKUP(表2[[#This Row],[relic id]],relic!$A:$A,relic!B:B,"") -> relic_name_30001 | C4: =_xlfn.XLOOKUP(表2[[#This Row],[relic id]],relic!$A:$A,relic!D:D,"") -> 阿菊 | D4: =IF(表2[[#This Row],[relic id]]<>"",_xlfn.XLOOKUP(表2[[#This Row],[relic id]],relic!$A:$A,relic!$T:$T),"") -> 2 | E4: =_xlfn.XLOOKUP(表2[[#This Row],[relic id]],relic!$A:$A,relic!G:G,"") -> relic_desc_300013 | F4: =_xlfn.XLOOKUP(表2[[#This Row],[relic id]],relic!$A:$A,relic!H:H,"") -> 所有设备 伤害 + 60% | G4: TRUE | I4: relic_name_30003 | J4: 肌肉金轮草 | L4: relic_desc_300013 | M4: 所有设备 伤害 + 60%
A5: 300014 | B5: =_xlfn.XLOOKUP(表2[[#This Row],[relic id]],relic!$A:$A,relic!B:B,"") -> relic_name_30001 | C5: =_xlfn.XLOOKUP(表2[[#This Row],[relic id]],relic!$A:$A,relic!D:D,"") -> 阿菊 | D5: =IF(表2[[#This Row],[relic id]]<>"",_xlfn.XLOOKUP(表2[[#This Row],[relic id]],relic!$A:$A,relic!$T:$T),"") -> 3 | E5: =_xlfn.XLOOKUP(表2[[#This Row],[relic id]],relic!$A:$A,relic!G:G,"") -> relic_desc_300014 | F5: =_xlfn.XLOOKUP(表2[[#This Row],[relic id]],relic!$A:$A,relic!H:H,"") -> 所有设备 伤害 + 120% | G5: TRUE | I5: relic_name_30004 | J5: 托利莲 | L5: relic_desc_300014 | M5: 所有设备 伤害 + 120%
B6: =_xlfn.XLOOKUP(表2[[#This Row],[relic id]],relic!$A:$A,relic!B:B,"") -> 0 | C6: =_xlfn.XLOOKUP(表2[[#This Row],[relic id]],relic!$A:$A,relic!D:D,"") -> 0 | D6: =IF(表2[[#This Row],[relic id]]<>"",_xlfn.XLOOKUP(表2[[#This Row],[relic id]],relic!$A:$A,relic!$T:$T),"") | E6: =_xlfn.XLOOKUP(表2[[#This Row],[relic id]],relic!$A:$A,relic!G:G,"") -> 0 | F6: =_xlfn.XLOOKUP(表2[[#This Row],[relic id]],relic!$A:$A,relic!H:H,"") -> 0 | I6: relic_name_30007 | J6: 守护符 | L6: relic_desc_300021 | M6: 所有设备 额外伤害 + 6
A7: 300021 | B7: =_xlfn.XLOOKUP(表2[[#This Row],[relic id]],relic!$A:$A,relic!B:B,"") -> relic_name_30002 | C7: =_xlfn.XLOOKUP(表2[[#This Row],[relic id]],relic!$A:$A,relic!D:D,"") -> 火星蝶 | D7: =IF(表2[[#This Row],[relic id]]<>"",_xlfn.XLOOKUP(表2[[#This Row],[relic id]],relic!$A:$A,relic!$T:$T),"") -> 1 | E7: =_xlfn.XLOOKUP(表2[[#This Row],[relic id]],relic!$A:$A,relic!G:G,"") -> relic_desc_300021 | F7: =_xlfn.XLOOKUP(表2[[#This Row],[relic id]],relic!$A:$A,relic!H:H,"") -> 所有设备 额外伤害 + 6 | G7: TRUE | I7: relic_name_30008 | J7: 文护符 | L7: relic_desc_300022 | M7: 所有设备 额外伤害 + 12
A8: 300022 | B8: =_xlfn.XLOOKUP(表2[[#This Row],[relic id]],relic!$A:$A,relic!B:B,"") -> relic_name_30002 | C8: =_xlfn.XLOOKUP(表2[[#This Row],[relic id]],relic!$A:$A,relic!D:D,"") -> 火星蝶 | D8: =IF(表2[[#This Row],[relic id]]<>"",_xlfn.XLOOKUP(表2[[#This Row],[relic id]],relic!$A:$A,relic!$T:$T),"") -> 2 | E8: =_xlfn.XLOOKUP(表2[[#This Row],[relic id]],relic!$A:$A,relic!G:G,"") -> relic_desc_300022 | F8: =_xlfn.XLOOKUP(表2[[#This Row],[relic id]],relic!$A:$A,relic!H:H,"") -> 所有设备 额外伤害 + 12 | G8: TRUE | I8: relic_name_30101 | J8: 镐子 | L8: relic_desc_300023 | M8: 所有设备 额外伤害 + 24
A9: 300023 | B9: =_xlfn.XLOOKUP(表2[[#This Row],[relic id]],relic!$A:$A,relic!B:B,"") -> relic_name_30002 | C9: =_xlfn.XLOOKUP(表2[[#This Row],[relic id]],relic!$A:$A,relic!D:D,"") -> 火星蝶 | D9: =IF(表2[[#This Row],[relic id]]<>"",_xlfn.XLOOKUP(表2[[#This Row],[relic id]],relic!$A:$A,relic!$T:$T),"") -> 3 | E9: =_xlfn.XLOOKUP(表2[[#This Row],[relic id]],relic!$A:$A,relic!G:G,"") -> relic_desc_300023 | F9: =_xlfn.XLOOKUP(表2[[#This Row],[relic id]],relic!$A:$A,relic!H:H,"") -> 所有设备 额外伤害 + 24 | G9: TRUE | I9: relic_name_30103 | J9: 斧头 | L9: relic_desc_300031 | M9: 所有设备 暴击几率 + 4%
B10: =_xlfn.XLOOKUP(表2[[#This Row],[relic id]],relic!$A:$A,relic!B:B,"") -> 0 | C10: =_xlfn.XLOOKUP(表2[[#This Row],[relic id]],relic!$A:$A,relic!D:D,"") -> 0 | D10: =IF(表2[[#This Row],[relic id]]<>"",_xlfn.XLOOKUP(表2[[#This Row],[relic id]],relic!$A:$A,relic!$T:$T),"") | E10: =_xlfn.XLOOKUP(表2[[#This Row],[relic id]],relic!$A:$A,relic!G:G,"") -> 0 | F10: =_xlfn.XLOOKUP(表2[[#This Row],[relic id]],relic!$A:$A,relic!H:H,"") -> 0 | I10: relic_name_30104 | J10: 扳手 | L10: relic_desc_300032 | M10: 所有设备 暴击几率 + 6%
A11: 300031 | B11: =_xlfn.XLOOKUP(表2[[#This Row],[relic id]],relic!$A:$A,relic!B:B,"") -> relic_name_30003 | C11: =_xlfn.XLOOKUP(表2[[#This Row],[relic id]],relic!$A:$A,relic!D:D,"") -> 肌肉金轮草 | D11: =IF(表2[[#This Row],[relic id]]<>"",_xlfn.XLOOKUP(表2[[#This Row],[relic id]],relic!$A:$A,relic!$T:$T),"") -> 0 | E11: =_xlfn.XLOOKUP(表2[[#This Row],[relic id]],relic!$A:$A,relic!G:G,"") -> relic_desc_300031 | F11: =_xlfn.XLOOKUP(表2[[#This Row],[relic id]],relic!$A:$A,relic!H:H,"") -> 所有设备 暴击几率 + 4% | G11: TRUE | I11: relic_name_30105 | J11: 起子 | L11: relic_desc_300033 | M11: 所有设备 暴击几率 + 9%
A12: 300032 | B12: =_xlfn.XLOOKUP(表2[[#This Row],[relic id]],relic!$A:$A,relic!B:B,"") -> relic_name_30003 | C12: =_xlfn.XLOOKUP(表2[[#This Row],[relic id]],relic!$A:$A,relic!D:D,"") -> 肌肉金轮草 | D12: =IF(表2[[#This Row],[relic id]]<>"",_xlfn.XLOOKUP(表2[[#This Row],[relic id]],relic!$A:$A,relic!$T:$T),"") -> 1 | E12: =_xlfn.XLOOKUP(表2[[#This Row],[relic id]],relic!$A:$A,relic!G:G,"") -> relic_desc_300032 | F12: =_xlfn.XLOOKUP(表2[[#This Row],[relic id]],relic!$A:$A,relic!H:H,"") -> 所有设备 暴击几率 + 6% | G12: TRUE | I12: relic_name_30201 | J12: 无黄蛋 | L12: relic_desc_300034 | M12: 所有设备 暴击几率 + 13%
A13: 300033 | B13: =_xlfn.XLOOKUP(表2[[#This Row],[relic id]],relic!$A:$A,relic!B:B,"") -> relic_name_30003 | C13: =_xlfn.XLOOKUP(表2[[#This Row],[relic id]],relic!$A:$A,relic!D:D,"") -> 肌肉金轮草 | D13: =IF(表2[[#This Row],[relic id]]<>"",_xlfn.XLOOKUP(表2[[#This Row],[relic id]],relic!$A:$A,relic!$T:$T),"") -> 2 | E13: =_xlfn.XLOOKUP(表2[[#This Row],[relic id]],relic!$A:$A,relic!G:G,"") -> relic_desc_300033 | F13: =_xlfn.XLOOKUP(表2[[#This Row],[relic id]],relic!$A:$A,relic!H:H,"") -> 所有设备 暴击几率 + 9% | G13: TRUE | I13: relic_name_30203 | J13: 天地一口香 | L13: relic_desc_300041 | M13: 所有设备 暴击伤害 + 10%
A14: 300034 | B14: =_xlfn.XLOOKUP(表2[[#This Row],[relic id]],relic!$A:$A,relic!B:B,"") -> relic_name_30003 | C14: =_xlfn.XLOOKUP(表2[[#This Row],[relic id]],relic!$A:$A,relic!D:D,"") -> 肌肉金轮草 | D14: =IF(表2[[#This Row],[relic id]]<>"",_xlfn.XLOOKUP(表2[[#This Row],[relic id]],relic!$A:$A,relic!$T:$T),"") -> 3 | E14: =_xlfn.XLOOKUP(表2[[#This Row],[relic id]],relic!$A:$A,relic!G:G,"") -> relic_desc_300034 | F14: =_xlfn.XLOOKUP(表2[[#This Row],[relic id]],relic!$A:$A,relic!H:H,"") -> 所有设备 暴击几率 + 13% | G14: TRUE | I14: relic_name_30204 | J14: 子母春茧 | L14: relic_desc_300042 | M14: 所有设备 暴击伤害 + 20%
B15: =_xlfn.XLOOKUP(表2[[#This Row],[relic id]],relic!$A:$A,relic!B:B,"") -> 0 | C15: =_xlfn.XLOOKUP(表2[[#This Row],[relic id]],relic!$A:$A,relic!D:D,"") -> 0 | D15: =IF(表2[[#This Row],[relic id]]<>"",_xlfn.XLOOKUP(表2[[#This Row],[relic id]],relic!$A:$A,relic!$T:$T),"") | E15: =_xlfn.XLOOKUP(表2[[#This Row],[relic id]],relic!$A:$A,relic!G:G,"") -> 0 | F15: =_xlfn.XLOOKUP(表2[[#This Row],[relic id]],relic!$A:$A,relic!H:H,"") -> 0 | I15: relic_name_30223 | J15: 太阳勋章 | L15: relic_desc_300043 | M15: 所有设备 暴击伤害 + 40%
A16: 300041 | B16: =_xlfn.XLOOKUP(表2[[#This Row],[relic id]],relic!$A:$A,relic!B:B,"") -> relic_name_30004 | C16: =_xlfn.XLOOKUP(表2[[#This Row],[relic id]],relic!$A:$A,relic!D:D,"") -> 托利莲 | D16: =IF(表2[[#This Row],[relic id]]<>"",_xlfn.XLOOKUP(表2[[#This Row],[relic id]],relic!$A:$A,relic!$T:$T),"") -> 0 | E16: =_xlfn.XLOOKUP(表2[[#This Row],[relic id]],relic!$A:$A,relic!G:G,"") -> relic_desc_300041 | F16: =_xlfn.XLOOKUP(表2[[#This Row],[relic id]],relic!$A:$A,relic!H:H,"") -> 所有设备 暴击伤害 + 10% | G16: TRUE | I16: relic_name_30232 | J16: 屋顶羊 | L16: relic_desc_300044 | M16: 所有设备 暴击伤害 + 80%
A17: 300042 | B17: =_xlfn.XLOOKUP(表2[[#This Row],[relic id]],relic!$A:$A,relic!B:B,"") -> relic_name_30004 | C17: =_xlfn.XLOOKUP(表2[[#This Row],[relic id]],relic!$A:$A,relic!D:D,"") -> 托利莲 | D17: =IF(表2[[#This Row],[relic id]]<>"",_xlfn.XLOOKUP(表2[[#This Row],[relic id]],relic!$A:$A,relic!$T:$T),"") -> 1 | E17: =_xlfn.XLOOKUP(表2[[#This Row],[relic id]],relic!$A:$A,relic!G:G,"") -> relic_desc_300042 | F17: =_xlfn.XLOOKUP(表2[[#This Row],[relic id]],relic!$A:$A,relic!H:H,"") -> 所有设备 暴击伤害 + 20% | G17: TRUE | I17: relic_name_310203 | J17: 花洒 Lv.1 | L17: relic_desc_300071 | M17: 所有设备 护甲 + 10
A18: 300043 | B18: =_xlfn.XLOOKUP(表2[[#This Row],[relic id]],relic!$A:$A,relic!B:B,"") -> relic_name_30004 | C18: =_xlfn.XLOOKUP(表2[[#This Row],[relic id]],relic!$A:$A,relic!D:D,"") -> 托利莲 | D18: =IF(表2[[#This Row],[relic id]]<>"",_xlfn.XLOOKUP(表2[[#This Row],[relic id]],relic!$A:$A,relic!$T:$T),"") -> 2 | E18: =_xlfn.XLOOKUP(表2[[#This Row],[relic id]],relic!$A:$A,relic!G:G,"") -> relic_desc_300043 | F18: =_xlfn.XLOOKUP(表2[[#This Row],[relic id]],relic!$A:$A,relic!H:H,"") -> 所有设备 暴击伤害 + 40% | G18: TRUE | I18: relic_name_310204 | J18: 花洒 Lv.2 | L18: relic_desc_300072 | M18: 所有设备 护甲 + 20
A19: 300044 | B19: =_xlfn.XLOOKUP(表2[[#This Row],[relic id]],relic!$A:$A,relic!B:B,"") -> relic_name_30004 | C19: =_xlfn.XLOOKUP(表2[[#This Row],[relic id]],relic!$A:$A,relic!D:D,"") -> 托利莲 | D19: =IF(表2[[#This Row],[relic id]]<>"",_xlfn.XLOOKUP(表2[[#This Row],[relic id]],relic!$A:$A,relic!$T:$T),"") -> 3 | E19: =_xlfn.XLOOKUP(表2[[#This Row],[relic id]],relic!$A:$A,relic!G:G,"") -> relic_desc_300044 | F19: =_xlfn.XLOOKUP(表2[[#This Row],[relic id]],relic!$A:$A,relic!H:H,"") -> 所有设备 暴击伤害 + 80% | G19: TRUE | I19: relic_name_310205 | J19: 花洒 Lv.3 | L19: relic_desc_300073 | M19: 所有设备 护甲 + 40
B20: =_xlfn.XLOOKUP(表2[[#This Row],[relic id]],relic!$A:$A,relic!B:B,"") -> 0 | C20: =_xlfn.XLOOKUP(表2[[#This Row],[relic id]],relic!$A:$A,relic!D:D,"") -> 0 | D20: =IF(表2[[#This Row],[relic id]]<>"",_xlfn.XLOOKUP(表2[[#This Row],[relic id]],relic!$A:$A,relic!$T:$T),"") | E20: =_xlfn.XLOOKUP(表2[[#This Row],[relic id]],relic!$A:$A,relic!G:G,"") -> 0 | F20: =_xlfn.XLOOKUP(表2[[#This Row],[relic id]],relic!$A:$A,relic!H:H,"") -> 0 | I20: relic_name_310206 | J20: 蟹钳 蒜蓉 | L20: relic_desc_300074 | M20: 所有设备 护甲 + 80
A21: 300051 | B21: =_xlfn.XLOOKUP(表2[[#This Row],[relic id]],relic!$A:$A,relic!B:B,"") -> relic_name_300051 | C21: =_xlfn.XLOOKUP(表2[[#This Row],[relic id]],relic!$A:$A,relic!D:D,"") -> 紫水晶 | D21: =IF(表2[[#This Row],[relic id]]<>"",_xlfn.XLOOKUP(表2[[#This Row],[relic id]],relic!$A:$A,relic!$T:$T),"") -> 0 | E21: =_xlfn.XLOOKUP(表2[[#This Row],[relic id]],relic!$A:$A,relic!G:G,"") -> relic_desc_300051 | F21: =_xlfn.XLOOKUP(表2[[#This Row],[relic id]],relic!$A:$A,relic!H:H,"") -> 所有设备 击退 + 5% | I21: relic_name_310207 | J21: 蟹钳 麻辣 | L21: relic_desc_300081 | M21: 所有设备 耐久 + 15%
A22: 300052 | B22: =_xlfn.XLOOKUP(表2[[#This Row],[relic id]],relic!$A:$A,relic!B:B,"") -> relic_name_300052 | C22: =_xlfn.XLOOKUP(表2[[#This Row],[relic id]],relic!$A:$A,relic!D:D,"") -> 粉水晶 | D22: =IF(表2[[#This Row],[relic id]]<>"",_xlfn.XLOOKUP(表2[[#This Row],[relic id]],relic!$A:$A,relic!$T:$T),"") -> 1 | E22: =_xlfn.XLOOKUP(表2[[#This Row],[relic id]],relic!$A:$A,relic!G:G,"") -> relic_desc_300052 | F22: =_xlfn.XLOOKUP(表2[[#This Row],[relic id]],relic!$A:$A,relic!H:H,"") -> 所有设备 击退 + 10% | I22: relic_name_310208 | J22: 蟹钳 十三香 | L22: relic_desc_300082 | M22: 所有设备 耐久 + 25%
A23: 300053 | B23: =_xlfn.XLOOKUP(表2[[#This Row],[relic id]],relic!$A:$A,relic!B:B,"") -> relic_name_300053 | C23: =_xlfn.XLOOKUP(表2[[#This Row],[relic id]],relic!$A:$A,relic!D:D,"") -> 黄水晶 | D23: =IF(表2[[#This Row],[relic id]]<>"",_xlfn.XLOOKUP(表2[[#This Row],[relic id]],relic!$A:$A,relic!$T:$T),"") -> 2 | E23: =_xlfn.XLOOKUP(表2[[#This Row],[relic id]],relic!$A:$A,relic!G:G,"") -> relic_desc_300053 | F23: =_xlfn.XLOOKUP(表2[[#This Row],[relic id]],relic!$A:$A,relic!H:H,"") -> 所有设备 击退 + 15% | I23: relic_name_310217 | J23: 牢门 | L23: relic_desc_300083 | M23: 所有设备 耐久 + 40%
B24: =_xlfn.XLOOKUP(表2[[#This Row],[relic id]],relic!$A:$A,relic!B:B,"") -> 0 | C24: =_xlfn.XLOOKUP(表2[[#This Row],[relic id]],relic!$A:$A,relic!D:D,"") -> 0 | D24: =IF(表2[[#This Row],[relic id]]<>"",_xlfn.XLOOKUP(表2[[#This Row],[relic id]],relic!$A:$A,relic!$T:$T),"") | E24: =_xlfn.XLOOKUP(表2[[#This Row],[relic id]],relic!$A:$A,relic!G:G,"") -> 0 | F24: =_xlfn.XLOOKUP(表2[[#This Row],[relic id]],relic!$A:$A,relic!H:H,"") -> 0 | I24: relic_name_310218 | J24: 警卫制服 | L24: relic_desc_300084 | M24: 所有设备 耐久 + 70%
A25: 300061 | B25: =_xlfn.XLOOKUP(表2[[#This Row],[relic id]],relic!$A:$A,relic!B:B,"") -> relic_name_300061 | C25: =_xlfn.XLOOKUP(表2[[#This Row],[relic id]],relic!$A:$A,relic!D:D,"") -> 国王骰子 | D25: =IF(表2[[#This Row],[relic id]]<>"",_xlfn.XLOOKUP(表2[[#This Row],[relic id]],relic!$A:$A,relic!$T:$T),"") -> 0 | E25: =_xlfn.XLOOKUP(表2[[#This Row],[relic id]],relic!$A:$A,relic!G:G,"") -> relic_desc_300061 | F25: =_xlfn.XLOOKUP(表2[[#This Row],[relic id]],relic!$A:$A,relic!H:H,"") -> 所有设备 破甲 + 10% | I25: relic_name_310219 | J25: 工头喇叭 | L25: relic_desc_301011 | M25: 近战武器 伤害 + 20%
A26: 300062 | B26: =_xlfn.XLOOKUP(表2[[#This Row],[relic id]],relic!$A:$A,relic!B:B,"") -> relic_name_300062 | C26: =_xlfn.XLOOKUP(表2[[#This Row],[relic id]],relic!$A:$A,relic!D:D,"") -> 国王骰子 | D26: =IF(表2[[#This Row],[relic id]]<>"",_xlfn.XLOOKUP(表2[[#This Row],[relic id]],relic!$A:$A,relic!$T:$T),"") -> 1 | E26: =_xlfn.XLOOKUP(表2[[#This Row],[relic id]],relic!$A:$A,relic!G:G,"") -> relic_desc_300062 | F26: =_xlfn.XLOOKUP(表2[[#This Row],[relic id]],relic!$A:$A,relic!H:H,"") -> 所有设备 破甲 + 20% | I26: relic_name_310223 | J26: 蛋糕 Lv.1 | L26: relic_desc_301012 | M26: 近战武器 伤害 + 40%
A27: 300063 | B27: =_xlfn.XLOOKUP(表2[[#This Row],[relic id]],relic!$A:$A,relic!B:B,"") -> relic_name_300063 | C27: =_xlfn.XLOOKUP(表2[[#This Row],[relic id]],relic!$A:$A,relic!D:D,"") -> 国王骰子 | D27: =IF(表2[[#This Row],[relic id]]<>"",_xlfn.XLOOKUP(表2[[#This Row],[relic id]],relic!$A:$A,relic!$T:$T),"") -> 2 | E27: =_xlfn.XLOOKUP(表2[[#This Row],[relic id]],relic!$A:$A,relic!G:G,"") -> relic_desc_300063 | F27: =_xlfn.XLOOKUP(表2[[#This Row],[relic id]],relic!$A:$A,relic!H:H,"") -> 所有设备 破甲 + 30% | I27: relic_name_310224 | J27: 蛋糕 Lv.2 | L27: relic_desc_301013 | M27: 近战武器 伤害 + 80%
B28: =_xlfn.XLOOKUP(表2[[#This Row],[relic id]],relic!$A:$A,relic!B:B,"") -> 0 | C28: =_xlfn.XLOOKUP(表2[[#This Row],[relic id]],relic!$A:$A,relic!D:D,"") -> 0 | D28: =IF(表2[[#This Row],[relic id]]<>"",_xlfn.XLOOKUP(表2[[#This Row],[relic id]],relic!$A:$A,relic!$T:$T),"") | E28: =_xlfn.XLOOKUP(表2[[#This Row],[relic id]],relic!$A:$A,relic!G:G,"") -> 0 | F28: =_xlfn.XLOOKUP(表2[[#This Row],[relic id]],relic!$A:$A,relic!H:H,"") -> 0 | I28: relic_name_310225 | J28: 蛋糕 Lv.3 | L28: relic_desc_301014 | M28: 近战武器 伤害 + 160%
A29: 300071 | B29: =_xlfn.XLOOKUP(表2[[#This Row],[relic id]],relic!$A:$A,relic!B:B,"") -> relic_name_30007 | C29: =_xlfn.XLOOKUP(表2[[#This Row],[relic id]],relic!$A:$A,relic!D:D,"") -> 守护符 | D29: =IF(表2[[#This Row],[relic id]]<>"",_xlfn.XLOOKUP(表2[[#This Row],[relic id]],relic!$A:$A,relic!$T:$T),"") -> 0 | E29: =_xlfn.XLOOKUP(表2[[#This Row],[relic id]],relic!$A:$A,relic!G:G,"") -> relic_desc_300071 | F29: =_xlfn.XLOOKUP(表2[[#This Row],[relic id]],relic!$A:$A,relic!H:H,"") -> 所有设备 护甲 + 10 | G29: TRUE | I29: relic_name_310407 | J29: 作弊骰 Lv.1 | L29: relic_desc_301031 | M29: 近战武器 暴击几率 + 5%
A30: 300072 | B30: =_xlfn.XLOOKUP(表2[[#This Row],[relic id]],relic!$A:$A,relic!B:B,"") -> relic_name_30007 | C30: =_xlfn.XLOOKUP(表2[[#This Row],[relic id]],relic!$A:$A,relic!D:D,"") -> 守护符 | D30: =IF(表2[[#This Row],[relic id]]<>"",_xlfn.XLOOKUP(表2[[#This Row],[relic id]],relic!$A:$A,relic!$T:$T),"") -> 1 | E30: =_xlfn.XLOOKUP(表2[[#This Row],[relic id]],relic!$A:$A,relic!G:G,"") -> relic_desc_300072 | F30: =_xlfn.XLOOKUP(表2[[#This Row],[relic id]],relic!$A:$A,relic!H:H,"") -> 所有设备 护甲 + 20 | G30: TRUE | I30: relic_name_310408 | J30: 作弊骰 Lv.2 | L30: relic_desc_301032 | M30: 近战武器 暴击几率 + 8%
A31: 300073 | B31: =_xlfn.XLOOKUP(表2[[#This Row],[relic id]],relic!$A:$A,relic!B:B,"") -> relic_name_30007 | C31: =_xlfn.XLOOKUP(表2[[#This Row],[relic id]],relic!$A:$A,relic!D:D,"") -> 守护符 | D31: =IF(表2[[#This Row],[relic id]]<>"",_xlfn.XLOOKUP(表2[[#This Row],[relic id]],relic!$A:$A,relic!$T:$T),"") -> 2 | E31: =_xlfn.XLOOKUP(表2[[#This Row],[relic id]],relic!$A:$A,relic!G:G,"") -> relic_desc_300073 | F31: =_xlfn.XLOOKUP(表2[[#This Row],[relic id]],relic!$A:$A,relic!H:H,"") -> 所有设备 护甲 + 40 | G31: TRUE | I31: relic_name_310409 | J31: 作弊骰 Lv.3 | L31: relic_desc_301033 | M31: 近战武器 暴击几率 + 12%
A32: 300074 | B32: =_xlfn.XLOOKUP(表2[[#This Row],[relic id]],relic!$A:$A,relic!B:B,"") -> relic_name_30007 | C32: =_xlfn.XLOOKUP(表2[[#This Row],[relic id]],relic!$A:$A,relic!D:D,"") -> 守护符 | D32: =IF(表2[[#This Row],[relic id]]<>"",_xlfn.XLOOKUP(表2[[#This Row],[relic id]],relic!$A:$A,relic!$T:$T),"") -> 3 | E32: =_xlfn.XLOOKUP(表2[[#This Row],[relic id]],relic!$A:$A,relic!G:G,"") -> relic_desc_300074 | F32: =_xlfn.XLOOKUP(表2[[#This Row],[relic id]],relic!$A:$A,relic!H:H,"") -> 所有设备 护甲 + 80 | G32: TRUE | I32: relic_name_310501 | J32: 箱子 Lv.1 | L32: relic_desc_301034 | M32: 近战武器 暴击几率 + 18%
B33: =_xlfn.XLOOKUP(表2[[#This Row],[relic id]],relic!$A:$A,relic!B:B,"") -> 0 | C33: =_xlfn.XLOOKUP(表2[[#This Row],[relic id]],relic!$A:$A,relic!D:D,"") -> 0 | D33: =IF(表2[[#This Row],[relic id]]<>"",_xlfn.XLOOKUP(表2[[#This Row],[relic id]],relic!$A:$A,relic!$T:$T),"") | E33: =_xlfn.XLOOKUP(表2[[#This Row],[relic id]],relic!$A:$A,relic!G:G,"") -> 0 | F33: =_xlfn.XLOOKUP(表2[[#This Row],[relic id]],relic!$A:$A,relic!H:H,"") -> 0 | I33: relic_name_310502 | J33: 箱子 Lv.2 | L33: relic_desc_301041 | M33: 近战武器 暴击伤害 + 15%
A34: 300081 | B34: =_xlfn.XLOOKUP(表2[[#This Row],[relic id]],relic!$A:$A,relic!B:B,"") -> relic_name_30008 | C34: =_xlfn.XLOOKUP(表2[[#This Row],[relic id]],relic!$A:$A,relic!D:D,"") -> 文护符 | D34: =IF(表2[[#This Row],[relic id]]<>"",_xlfn.XLOOKUP(表2[[#This Row],[relic id]],relic!$A:$A,relic!$T:$T),"") -> 0 | E34: =_xlfn.XLOOKUP(表2[[#This Row],[relic id]],relic!$A:$A,relic!G:G,"") -> relic_desc_300081 | F34: =_xlfn.XLOOKUP(表2[[#This Row],[relic id]],relic!$A:$A,relic!H:H,"") -> 所有设备 耐久 + 15% | G34: TRUE | I34: relic_name_310503 | J34: 箱子 Lv.3 | L34: relic_desc_301042 | M34: 近战武器 暴击伤害 + 30%
A35: 300082 | B35: =_xlfn.XLOOKUP(表2[[#This Row],[relic id]],relic!$A:$A,relic!B:B,"") -> relic_name_30008 | C35: =_xlfn.XLOOKUP(表2[[#This Row],[relic id]],relic!$A:$A,relic!D:D,"") -> 文护符 | D35: =IF(表2[[#This Row],[relic id]]<>"",_xlfn.XLOOKUP(表2[[#This Row],[relic id]],relic!$A:$A,relic!$T:$T),"") -> 1 | E35: =_xlfn.XLOOKUP(表2[[#This Row],[relic id]],relic!$A:$A,relic!G:G,"") -> relic_desc_300082 | F35: =_xlfn.XLOOKUP(表2[[#This Row],[relic id]],relic!$A:$A,relic!H:H,"") -> 所有设备 耐久 + 25% | G35: TRUE | I35: relic_name_310504 | J35: 符纸 Lv.1 | L35: relic_desc_301043 | M35: 近战武器 暴击伤害 + 60%
A36: 300083 | B36: =_xlfn.XLOOKUP(表2[[#This Row],[relic id]],relic!$A:$A,relic!B:B,"") -> relic_name_30008 | C36: =_xlfn.XLOOKUP(表2[[#This Row],[relic id]],relic!$A:$A,relic!D:D,"") -> 文护符 | D36: =IF(表2[[#This Row],[relic id]]<>"",_xlfn.XLOOKUP(表2[[#This Row],[relic id]],relic!$A:$A,relic!$T:$T),"") -> 2 | E36: =_xlfn.XLOOKUP(表2[[#This Row],[relic id]],relic!$A:$A,relic!G:G,"") -> relic_desc_300083 | F36: =_xlfn.XLOOKUP(表2[[#This Row],[relic id]],relic!$A:$A,relic!H:H,"") -> 所有设备 耐久 + 40% | G36: TRUE | I36: relic_name_310505 | J36: 符纸 Lv.2 | L36: relic_desc_301044 | M36: 近战武器 暴击伤害 + 120%
A37: 300084 | B37: =_xlfn.XLOOKUP(表2[[#This Row],[relic id]],relic!$A:$A,relic!B:B,"") -> relic_name_30008 | C37: =_xlfn.XLOOKUP(表2[[#This Row],[relic id]],relic!$A:$A,relic!D:D,"") -> 文护符 | D37: =IF(表2[[#This Row],[relic id]]<>"",_xlfn.XLOOKUP(表2[[#This Row],[relic id]],relic!$A:$A,relic!$T:$T),"") -> 3 | E37: =_xlfn.XLOOKUP(表2[[#This Row],[relic id]],relic!$A:$A,relic!G:G,"") -> relic_desc_300084 | F37: =_xlfn.XLOOKUP(表2[[#This Row],[relic id]],relic!$A:$A,relic!H:H,"") -> 所有设备 耐久 + 70% | G37: TRUE | I37: relic_name_310506 | J37: 符纸 Lv.3 | L37: relic_desc_301051 | M37: 近战武器 击退 + 10%
B38: =_xlfn.XLOOKUP(表2[[#This Row],[relic id]],relic!$A:$A,relic!B:B,"") -> 0 | C38: =_xlfn.XLOOKUP(表2[[#This Row],[relic id]],relic!$A:$A,relic!D:D,"") -> 0 | D38: =IF(表2[[#This Row],[relic id]]<>"",_xlfn.XLOOKUP(表2[[#This Row],[relic id]],relic!$A:$A,relic!$T:$T),"") | E38: =_xlfn.XLOOKUP(表2[[#This Row],[relic id]],relic!$A:$A,relic!G:G,"") -> 0 | F38: =_xlfn.XLOOKUP(表2[[#This Row],[relic id]],relic!$A:$A,relic!H:H,"") -> 0 | I38: relic_name_310507 | J38: 玩火艺人 | L38: relic_desc_301052 | M38: 近战武器 击退 + 20%
A39: 300091 | B39: =_xlfn.XLOOKUP(表2[[#This Row],[relic id]],relic!$A:$A,relic!B:B,"") -> relic_name_300091 | C39: =_xlfn.XLOOKUP(表2[[#This Row],[relic id]],relic!$A:$A,relic!D:D,"") -> 礼护符 | D39: =IF(表2[[#This Row],[relic id]]<>"",_xlfn.XLOOKUP(表2[[#This Row],[relic id]],relic!$A:$A,relic!$T:$T),"") -> 0 | E39: =_xlfn.XLOOKUP(表2[[#This Row],[relic id]],relic!$A:$A,relic!G:G,"") -> relic_desc_300091 | F39: =_xlfn.XLOOKUP(表2[[#This Row],[relic id]],relic!$A:$A,relic!H:H,"") -> 所有设备 耐久 + 300 | L39: relic_desc_301053 | M39: 近战武器 击退 + 40%
A40: 300092 | B40: =_xlfn.XLOOKUP(表2[[#This Row],[relic id]],relic!$A:$A,relic!B:B,"") -> relic_name_300092 | C40: =_xlfn.XLOOKUP(表2[[#This Row],[relic id]],relic!$A:$A,relic!D:D,"") -> 礼护符 | D40: =IF(表2[[#This Row],[relic id]]<>"",_xlfn.XLOOKUP(表2[[#This Row],[relic id]],relic!$A:$A,relic!$T:$T),"") -> 1 | E40: =_xlfn.XLOOKUP(表2[[#This Row],[relic id]],relic!$A:$A,relic!G:G,"") -> relic_desc_300092 | F40: =_xlfn.XLOOKUP(表2[[#This Row],[relic id]],relic!$A:$A,relic!H:H,"") -> 所有设备 耐久 + 600 | L40: relic_desc_301054 | M40: 近战武器 击退 + 80%
...

Sheet -id 配置说明
A1: Vlookup | B1: Type | C1: 第1位 | D1: 第2位 | E1: 第3位 | F1: 第4位 | G1: 第5位 | H1: 第6位 | J1: 命名参考1 | K1: 命名参考2 | L1: 备注 | M1: 投放说明
A2: global_atk_pts | B2: pts | C2: 30 = relic （数值类） | E2: 0 = 全局 | F2: 01 = 所有设备 伤害 | H2: 等级编号 | J2: 猛虎印记 | K2: 阿菊 | L2: 全局加成，效果数值应偏低，暂定*=40%
A3: global_atk_add | B3: add | F3: 02 = 所有设备 额外伤害 | J3: 猎豹印记 | K3: 火星蝶
A4: global_critical_chance | B4: pts | F4: 03 = 所有设备 暴击几率 | J4: 苍鹰印记 | K4: 肌肉金轮草
A5: global_critical_dmg_rate | B5: pts | F5: 04 = 所有设备 暴击伤害 | J5: 恶犬印记 | K5: 托利莲
A6: global_knockback | B6: pts | F6: 05 = 所有设备 击退 | J6: 灰熊印记 | K6: 紫水晶；粉水晶；黄水晶 | M6: 有限投放
A7: global_armor_piercing | B7: pts | F7: 06 = 所有设备 破甲 | J7: 郊狼印记 | K7: 国王骰子
A9: global_armor_add | B9: add | F9: 07 = 所有设备 护甲 | J9: 海龟印记 | K9: 守护符 | M9: 有限投放
A10: global_hp_pts | B10: pts | F10: 08 = 所有设备 耐久 | J10: 犀牛印记 | K10: 文护符
A11: global_hp_add | B11: add | F11: 09 = 所有设备 耐久 | J11: 大象印记 | K11: 礼护符
A13: melee_atk_pts | B13: pts | E13: 1 = 近战武器 | F13: 01 = 近战武器 伤害 | J13: 猛虎图腾 | K13: 镐子 | L13: 撞角同样受此加成 | M13: 拥有近战设备或撞角设备时解锁
A14: melee_atk_add | B14: add | F14: 02 = 近战武器 伤害 | J14: 猎豹图腾 | K14: 锄头 | L14: 撞角同样受此加成 | M14: 拥有近战设备或撞角设备时解锁
A15: melee_critical_chance | B15: pts | F15: 03 = 近战武器 暴击几率 | J15: 苍鹰图腾 | K15: 斧头 | L15: 撞角同样受此加成 | M15: 拥有近战设备或撞角设备时解锁
A16: melee_critical_dmg_rate | B16: pts | F16: 04 = 近战武器 暴击伤害 | J16: 恶犬图腾 | K16: 扳手 | L16: 撞角同样受此加成 | M16: 拥有近战设备或撞角设备时解锁
A17: melee_knockback | B17: pts | F17: 05 = 近战武器 击退 | J17: 灰熊图腾 | K17: 起子 | L17: 撞角同样受此加成 | M17: 拥有近战设备或撞角设备时解锁；有限投放
A18: melee_armor_piercing | B18: pts | F18: 06 = 近战武器 破甲附加值 | J18: 郊狼图腾 | K18: 钳子 | L18: 撞角同样受此加成 | M18: 拥有近战设备或撞角设备时解锁
A20: melee_sharpness_durability | B20: pts | F20: 21 = 近战武器 锋利度耐久 | J20: 天空图腾 | K20: 麻辣蟹钳；蒜蓉蟹钳；十三香蟹钳 | L20: 降低锋利度的损失速率 | M20: 拥有近战设备时解锁
A21: melee_sharpness_add | B21: pts | F21: 22 = 近战武器 锋利度上限 | J21: 峭壁图腾 | K21: 机械义肢 | L21: 锋利度超过100%时，可以增加武器伤害 | M21: 拥有近战设备时解锁
A22: melee_sharpness_recover | B22: pts | F22: 23 = 近战武器 磨刀速率 | J22: 海洋图腾 | K22: 开锁工具 | M22: 拥有近战设备时解锁
