Workbook

Sheet monster
A1: id | B1: name | E1: sub_table_name | F1: sub_table_key | G1: SE_attack | H1: hp | I1: def | J1: mass | K1: is_block_car | L1: is_elite | M1: diy_atk | T1: ts | U1: dodge | V1: base_speed | X1: max_force | Y1: is_follow | Z1: k_hurt | AA1: monster_view | AC1: monster_behaviour_tree | AD1: fire_logic | AE1: feedback | AF1: loot_list | AG1: death_vfx | AM1: enemy_tags | AN1: component | AO1: sub_monsters | AT1: diy_prms
A2: uint key | B2: string | E2: string | F2: string | G2: string | H2: int | I2: int | J2: float | K2: bool | L2: bool | M2: dict<string,int> | T2: int | U2: int | V2: float | X2: float | Y2: bool | Z2: dict<string,int> | AA2: string | AC2: string | AD2: int | AE2: float | AF2: dict<uint,float> | AG2: string[] | AM2: string[] | AN2: uint[] | AO2: dict<string,int> | AT2: dict<string,string>
A3: 怪物id | B3: 怪物名称 查localization表id | C3: 备注1 地区 | D3: 备注2 名称 | G3: 攻击音效 | H3: 血量 | I3: 减伤 | J3: 重量 | K3: 阻碍车辆 | M3: 伤害 近战用 | N3: sharp | O3: blunt | P3: fire | Q3: acid | R3: wrap | S3: flash | T3: 必中 0~100 | U3: 闪避 0~100 | V3: 基础速度 飞行用 灰色表示数据将由后方自定义参数控制 | W3: 辅助列 加速度 | X3: 推力最大值 飞行用 | Y3: 是否幽浮 飞行用 | Z3: 伤害修正 | AA3: 预制体 address | AB3: unity resource name | AC3: ai控制脚本 Scripts/World/Enemys/BT | AD3: 射击逻辑 | AE3: 阻力系数 | AF3: 掉落物列表 dict<loot表id, 概率> 概率配置值1 = 100% | AG3: 死亡特效 null = 不播放任何特效 | AH3: 辅助列1 | AI3: 辅助列2 | AJ3: 辅助列3 | AK3: 辅助列4 | AL3: 辅助列5 | AM3: 怪物标签 | AN3: 组合 | AO3: 组合 | AP3: 辅助列3 | AQ3: 辅助列3 | AR3: 辅助列3 | AS3: 辅助列3 | AT3: 自定义参数
A4: 201101 | B4: =_xlfn.TEXTJOIN("_",1,"enemy",$A4) -> enemy_201101 | C4: 地宫 | D4: 地宫蝙蝠 | G4: se_ag_bat_bite | H4: 26 | I4: 0 | J4: 2.4 | M4: {=_xlfn.TEXTJOIN(";",1,_xlfn.LAMBDA(_xlpm.x,IF(_xlpm.x<>"",OFFSET(_xlpm.x,3-ROW(),0)&"="&_xlpm.x,""))(N4:S4))} -> sharp=6 | N4: 6 | AA4: =_xlfn.TEXTJOIN("_",1,"monster",$A4,$AB4) -> monster_201101_dungeon_bat | AB4: dungeon_bat | AC4: =_xlfn.TEXTJOIN("_",1,"BT",$AB4) -> BT_dungeon_bat | AE4: 0.25 | AF4: =_xlfn.XLOOKUP(A4,'-loot_list辅助配置表'!A:A,'-loot_list辅助配置表'!V:V) -> 10000=0.0048;600109=0.0001 | AG4: =_xlfn.TEXTJOIN(";",1,AH4:AL4) -> vfx_monster_die_1;vfx_monster_die_2;vfx_monster_die_3;vfx_monster_die_4 | AH4: vfx_monster_die_1 | AI4: vfx_monster_die_2 | AJ4: vfx_monster_die_3 | AK4: vfx_monster_die_4 | AN4: 0 | AO4: {=_xlfn.TEXTJOIN(";",1,IF(AP4:AQ4<>"",AP4:AQ4&"="&AR4:AS4,""))}
A5: 201102 | B5: =_xlfn.TEXTJOIN("_",1,"enemy",$A5) -> enemy_201102 | C5: 地宫 | D5: 自爆甲虫 | H5: 2 | I5: -1 | J5: 0.8 | M5: {=_xlfn.TEXTJOIN(";",1,_xlfn.LAMBDA(_xlpm.x,IF(_xlpm.x<>"",OFFSET(_xlpm.x,3-ROW(),0)&"="&_xlpm.x,""))(N5:S5))} -> sharp=10 | N5: 10 | AA5: =_xlfn.TEXTJOIN("_",1,"monster",$A5,$AB5) -> monster_201102_dungeon_beatle | AB5: dungeon_beatle | AC5: =_xlfn.TEXTJOIN("_",1,"BT",$AB5) -> BT_dungeon_beatle | AE5: 0.1 | AF5: =_xlfn.XLOOKUP(A5,'-loot_list辅助配置表'!A:A,'-loot_list辅助配置表'!V:V) | AG5: =_xlfn.TEXTJOIN(";",1,AH5:AL5) -> vfx_monster_die_1;vfx_monster_die_2;vfx_monster_die_3;vfx_monster_die_4;vfx_monster_die_explosion | AH5: vfx_monster_die_1 | AI5: vfx_monster_die_2 | AJ5: vfx_monster_die_3 | AK5: vfx_monster_die_4 | AL5: vfx_monster_die_explosion | AN5: 0 | AO5: {=_xlfn.TEXTJOIN(";",1,IF(AP5:AQ5<>"",AP5:AQ5&"="&AR5:AS5,""))}
A6: 201103 | B6: =_xlfn.TEXTJOIN("_",1,"enemy",$A6) -> enemy_201103 | C6: 地宫 | D6: 跳虫 | H6: 44 | I6: 0 | J6: 7.5 | K6: TRUE | M6: {=_xlfn.TEXTJOIN(";",1,_xlfn.LAMBDA(_xlpm.x,IF(_xlpm.x<>"",OFFSET(_xlpm.x,3-ROW(),0)&"="&_xlpm.x,""))(N6:S6))} -> sharp=6 | N6: 6 | AA6: =_xlfn.TEXTJOIN("_",1,"monster",$A6,$AB6) -> monster_201103_dungeon_springtail | AB6: dungeon_springtail | AC6: =_xlfn.TEXTJOIN("_",1,"BT",$AB6) -> BT_dungeon_springtail | AE6: 0.12 | AF6: =_xlfn.XLOOKUP(A6,'-loot_list辅助配置表'!A:A,'-loot_list辅助配置表'!V:V) -> 10000=0.0048;600109=0.0001 | AG6: =_xlfn.TEXTJOIN(";",1,AH6:AL6) -> vfx_monster_die_1;vfx_monster_die_2;vfx_monster_die_3;vfx_monster_die_4 | AH6: vfx_monster_die_1 | AI6: vfx_monster_die_2 | AJ6: vfx_monster_die_3 | AK6: vfx_monster_die_4 | AN6: 0 | AO6: {=_xlfn.TEXTJOIN(";",1,IF(AP6:AQ6<>"",AP6:AQ6&"="&AR6:AS6,""))}
A7: 201104 | B7: =_xlfn.TEXTJOIN("_",1,"enemy",$A7) -> enemy_201104 | C7: 地宫 | D7: 地宫洞穴人 | H7: 66 | I7: 1 | J7: 20 | K7: TRUE | M7: {=_xlfn.TEXTJOIN(";",1,_xlfn.LAMBDA(_xlpm.x,IF(_xlpm.x<>"",OFFSET(_xlpm.x,3-ROW(),0)&"="&_xlpm.x,""))(N7:S7))} -> sharp=7 | N7: 7 | AA7: =_xlfn.TEXTJOIN("_",1,"monster",$A7,$AB7) -> monster_201104_dungeon_caveman | AB7: dungeon_caveman | AC7: =_xlfn.TEXTJOIN("_",1,"BT",$AB7) -> BT_dungeon_caveman | AD7: =A7 -> 201104 | AE7: 0.17 | AF7: =_xlfn.XLOOKUP(A7,'-loot_list辅助配置表'!A:A,'-loot_list辅助配置表'!V:V) -> 10000=0.0048;600109=0.0001 | AG7: =_xlfn.TEXTJOIN(";",1,AH7:AL7) -> vfx_monster_die_1;vfx_monster_die_2;vfx_monster_die_3;vfx_monster_die_4 | AH7: vfx_monster_die_1 | AI7: vfx_monster_die_2 | AJ7: vfx_monster_die_3 | AK7: vfx_monster_die_4 | AN7: 0 | AO7: {=_xlfn.TEXTJOIN(";",1,IF(AP7:AQ7<>"",AP7:AQ7&"="&AR7:AS7,""))}
A8: 201105 | B8: =_xlfn.TEXTJOIN("_",1,"enemy",$A8) -> enemy_201105 | C8: 地宫 | D8: 跳虫骑手 | H8: 55 | I8: 2 | J8: 27.5 | K8: TRUE | M8: {=_xlfn.TEXTJOIN(";",1,_xlfn.LAMBDA(_xlpm.x,IF(_xlpm.x<>"",OFFSET(_xlpm.x,3-ROW(),0)&"="&_xlpm.x,""))(N8:S8))} | AA8: =_xlfn.TEXTJOIN("_",1,"monster",$A8,$AB8) -> monster_201105_dungeon_springtail_rider | AB8: dungeon_springtail_rider | AC8: =_xlfn.TEXTJOIN("_",1,"BT",$AB8) -> BT_dungeon_springtail_rider | AD8: =A8 -> 201105 | AE8: 0.2 | AF8: =_xlfn.XLOOKUP(A8,'-loot_list辅助配置表'!A:A,'-loot_list辅助配置表'!V:V) | AG8: =_xlfn.TEXTJOIN(";",1,AH8:AL8) -> vfx_monster_die_1;vfx_monster_die_2;vfx_monster_die_3;vfx_monster_die_4;null | AH8: vfx_monster_die_1 | AI8: vfx_monster_die_2 | AJ8: vfx_monster_die_3 | AK8: vfx_monster_die_4 | AL8: null | AN8: 201103;201104 | AO8: {=_xlfn.TEXTJOIN(";",1,IF(AP8:AQ8<>"",AP8:AQ8&"="&AR8:AS8,""))} -> Mount=201103;Rider=201104 | AP8: Mount | AQ8: Rider | AR8: 201103 | AS8: 201104
A9: 201106 | B9: =_xlfn.TEXTJOIN("_",1,"enemy",$A9) -> enemy_201106 | C9: 地宫 | D9: 蝙蝠骑手 | H9: 33 | I9: 1 | J9: 22.4 | M9: {=_xlfn.TEXTJOIN(";",1,_xlfn.LAMBDA(_xlpm.x,IF(_xlpm.x<>"",OFFSET(_xlpm.x,3-ROW(),0)&"="&_xlpm.x,""))(N9:S9))} | AA9: =_xlfn.TEXTJOIN("_",1,"monster",$A9,$AB9) -> monster_201106_dungeon_bat_rider | AB9: dungeon_bat_rider | AC9: =_xlfn.TEXTJOIN("_",1,"BT",$AB9) -> BT_dungeon_bat_rider | AD9: =A9 -> 201106 | AE9: 0.2 | AF9: =_xlfn.XLOOKUP(A9,'-loot_list辅助配置表'!A:A,'-loot_list辅助配置表'!V:V) | AG9: =_xlfn.TEXTJOIN(";",1,AH9:AL9) -> vfx_monster_die_1;vfx_monster_die_2;vfx_monster_die_3;vfx_monster_die_4;null | AH9: vfx_monster_die_1 | AI9: vfx_monster_die_2 | AJ9: vfx_monster_die_3 | AK9: vfx_monster_die_4 | AL9: null | AN9: 201101;201104 | AO9: {=_xlfn.TEXTJOIN(";",1,IF(AP9:AQ9<>"",AP9:AQ9&"="&AR9:AS9,""))} -> Mount=201101;Rider=201104 | AP9: Mount | AQ9: Rider | AR9: 201101 | AS9: 201104
A10: 201107 | B10: =_xlfn.TEXTJOIN("_",1,"enemy",$A10) -> enemy_201107 | C10: 地宫 | D10: 流浪洞穴人 | H10: 44 | I10: 0 | J10: 20 | K10: TRUE | M10: {=_xlfn.TEXTJOIN(";",1,_xlfn.LAMBDA(_xlpm.x,IF(_xlpm.x<>"",OFFSET(_xlpm.x,3-ROW(),0)&"="&_xlpm.x,""))(N10:S10))} | AA10: =_xlfn.TEXTJOIN("_",1,"monster",$A10,$AB10) -> monster_201107_dungeon_caveman_wanderer | AB10: dungeon_caveman_wanderer | AC10: =_xlfn.TEXTJOIN("_",1,"BT",$AB10) -> BT_dungeon_caveman_wanderer | AD10: =A10 -> 201107 | AE10: 0.17 | AF10: =_xlfn.XLOOKUP(A10,'-loot_list辅助配置表'!A:A,'-loot_list辅助配置表'!V:V) -> 10000=0.0048;600109=0.0001 | AG10: =_xlfn.TEXTJOIN(";",1,AH10:AL10) -> vfx_monster_die_1;vfx_monster_die_2;vfx_monster_die_3;vfx_monster_die_4 | AH10: vfx_monster_die_1 | AI10: vfx_monster_die_2 | AJ10: vfx_monster_die_3 | AK10: vfx_monster_die_4 | AN10: 0 | AO10: {=_xlfn.TEXTJOIN(";",1,IF(AP10:AQ10<>"",AP10:AQ10&"="&AR10:AS10,""))}
A11: 201108 | B11: =_xlfn.TEXTJOIN("_",1,"enemy",$A11) -> enemy_201108 | C11: 地宫 | D11: 纵火洞穴人 | H11: 52 | I11: 0 | J11: 20 | K11: TRUE | M11: {=_xlfn.TEXTJOIN(";",1,_xlfn.LAMBDA(_xlpm.x,IF(_xlpm.x<>"",OFFSET(_xlpm.x,3-ROW(),0)&"="&_xlpm.x,""))(N11:S11))} | AA11: =_xlfn.TEXTJOIN("_",1,"monster",$A11,$AB11) -> monster_201108_dungeon_caveman_arsonist | AB11: dungeon_caveman_arsonist | AC11: BT_dungeon_caveman_wanderer | AD11: =A11 -> 201108 | AE11: 0.17 | AF11: =_xlfn.XLOOKUP(A11,'-loot_list辅助配置表'!A:A,'-loot_list辅助配置表'!V:V) -> 10000=0.0048;600109=0.0001 | AG11: =_xlfn.TEXTJOIN(";",1,AH11:AL11) -> vfx_monster_die_1;vfx_monster_die_2;vfx_monster_die_3;vfx_monster_die_4 | AH11: vfx_monster_die_1 | AI11: vfx_monster_die_2 | AJ11: vfx_monster_die_3 | AK11: vfx_monster_die_4 | AN11: 0 | AO11: {=_xlfn.TEXTJOIN(";",1,IF(AP11:AQ11<>"",AP11:AQ11&"="&AR11:AS11,""))}
A12: 201109 | B12: =_xlfn.TEXTJOIN("_",1,"enemy",$A12) -> enemy_201109 | C12: 地宫 | D12: 暴徒洞穴人 | H12: 59 | I12: 0 | J12: 20 | K12: TRUE | M12: {=_xlfn.TEXTJOIN(";",1,_xlfn.LAMBDA(_xlpm.x,IF(_xlpm.x<>"",OFFSET(_xlpm.x,3-ROW(),0)&"="&_xlpm.x,""))(N12:S12))} | AA12: =_xlfn.TEXTJOIN("_",1,"monster",$A12,$AB12) -> monster_201109_dungeon_caveman_mob | AB12: dungeon_caveman_mob | AC12: BT_dungeon_caveman_wanderer | AD12: =A12 -> 201109 | AE12: 0.17 | AF12: =_xlfn.XLOOKUP(A12,'-loot_list辅助配置表'!A:A,'-loot_list辅助配置表'!V:V) -> 10000=0.0048;600109=0.0001 | AG12: =_xlfn.TEXTJOIN(";",1,AH12:AL12) -> vfx_monster_die_1;vfx_monster_die_2;vfx_monster_die_3;vfx_monster_die_4 | AH12: vfx_monster_die_1 | AI12: vfx_monster_die_2 | AJ12: vfx_monster_die_3 | AK12: vfx_monster_die_4 | AN12: 0 | AO12: {=_xlfn.TEXTJOIN(";",1,IF(AP12:AQ12<>"",AP12:AQ12&"="&AR12:AS12,""))}
A14: 211101 | B14: =_xlfn.TEXTJOIN("_",1,"enemy",$A14) -> enemy_211101 | C14: 地宫 | D14: 地宫捕奴车-近战 | E14: sub_monster_car | F14: 1 | J14: 1200 | M14: {=_xlfn.TEXTJOIN(";",1,_xlfn.LAMBDA(_xlpm.x,IF(_xlpm.x<>"",OFFSET(_xlpm.x,3-ROW(),0)&"="&_xlpm.x,""))(N14:S14))} -> sharp=20 | N14: 20 | AF14: =_xlfn.XLOOKUP(A14,'-loot_list辅助配置表'!A:A,'-loot_list辅助配置表'!V:V) -> 10000=0.1 | AG14: =_xlfn.TEXTJOIN(";",1,AH14:AL14) -> vfx_monster_die_1;vfx_monster_die_2;vfx_monster_die_3;vfx_monster_die_4 | AH14: vfx_monster_die_1 | AI14: vfx_monster_die_2 | AJ14: vfx_monster_die_3 | AK14: vfx_monster_die_4
A15: 211102 | B15: =_xlfn.TEXTJOIN("_",1,"enemy",$A15) -> enemy_211102 | C15: 地宫 | D15: 地宫捕奴车-远程 | E15: sub_monster_car | F15: 2 | J15: 1200 | M15: {=_xlfn.TEXTJOIN(";",1,_xlfn.LAMBDA(_xlpm.x,IF(_xlpm.x<>"",OFFSET(_xlpm.x,3-ROW(),0)&"="&_xlpm.x,""))(N15:S15))} -> sharp=20 | N15: 20 | AF15: =_xlfn.XLOOKUP(A15,'-loot_list辅助配置表'!A:A,'-loot_list辅助配置表'!V:V) -> 10000=0.1 | AG15: =_xlfn.TEXTJOIN(";",1,AH15:AL15) -> vfx_monster_die_1;vfx_monster_die_2;vfx_monster_die_3;vfx_monster_die_4 | AH15: vfx_monster_die_1 | AI15: vfx_monster_die_2 | AJ15: vfx_monster_die_3 | AK15: vfx_monster_die_4
A16: 211111 | B16: =_xlfn.TEXTJOIN("_",1,"enemy",$A16) -> enemy_211111 | C16: 地宫 | D16: 地宫装甲车-近战 | E16: sub_monster_car | F16: =A16 -> 211111 | J16: 5000 | M16: {=_xlfn.TEXTJOIN(";",1,_xlfn.LAMBDA(_xlpm.x,IF(_xlpm.x<>"",OFFSET(_xlpm.x,3-ROW(),0)&"="&_xlpm.x,""))(N16:S16))} -> sharp=20 | N16: 20 | AF16: =_xlfn.XLOOKUP(A16,'-loot_list辅助配置表'!A:A,'-loot_list辅助配置表'!V:V) -> 10000=0.1 | AG16: =_xlfn.TEXTJOIN(";",1,AH16:AL16) -> vfx_monster_die_1;vfx_monster_die_2;vfx_monster_die_3;vfx_monster_die_4 | AH16: vfx_monster_die_1 | AI16: vfx_monster_die_2 | AJ16: vfx_monster_die_3 | AK16: vfx_monster_die_4
A17: 211112 | B17: =_xlfn.TEXTJOIN("_",1,"enemy",$A17) -> enemy_211112 | C17: 地宫 | D17: 地宫装甲车-远程 | E17: sub_monster_car | F17: =A17 -> 211112 | J17: 5000 | M17: {=_xlfn.TEXTJOIN(";",1,_xlfn.LAMBDA(_xlpm.x,IF(_xlpm.x<>"",OFFSET(_xlpm.x,3-ROW(),0)&"="&_xlpm.x,""))(N17:S17))} -> sharp=20 | N17: 20 | AF17: =_xlfn.XLOOKUP(A17,'-loot_list辅助配置表'!A:A,'-loot_list辅助配置表'!V:V) -> 10000=0.1 | AG17: =_xlfn.TEXTJOIN(";",1,AH17:AL17) -> vfx_monster_die_1;vfx_monster_die_2;vfx_monster_die_3;vfx_monster_die_4 | AH17: vfx_monster_die_1 | AI17: vfx_monster_die_2 | AJ17: vfx_monster_die_3 | AK17: vfx_monster_die_4
A19: 201401 | B19: =_xlfn.TEXTJOIN("_",1,"enemy",$A19) -> enemy_201401 | C19: 树梢 | D19: 古灯 | G19: se_ag_bat_bite | H19: 19 | I19: 0 | J19: 4 | M19: {=_xlfn.TEXTJOIN(";",1,_xlfn.LAMBDA(_xlpm.x,IF(_xlpm.x<>"",OFFSET(_xlpm.x,3-ROW(),0)&"="&_xlpm.x,""))(N19:S19))} -> sharp=5 | N19: 5 | V19: 10 | W19: 25 | X19: =$W19*$J19 -> 100 | AA19: =_xlfn.TEXTJOIN("_",1,"monster",$A19,$AB19) -> monster_201401_Treetop_Lamp | AB19: Treetop_Lamp | AC19: =_xlfn.TEXTJOIN("_",1,"BT",$AB19) -> BT_Treetop_Lamp | AE19: 0.15 | AF19: =_xlfn.XLOOKUP(A19,'-loot_list辅助配置表'!A:A,'-loot_list辅助配置表'!V:V) -> 10000=0.0048;600404=0.0001 | AG19: =_xlfn.TEXTJOIN(";",1,AH19:AL19) -> vfx_monster_die_1;vfx_monster_die_2;vfx_monster_die_3;vfx_monster_die_4 | AH19: vfx_monster_die_1 | AI19: vfx_monster_die_2 | AJ19: vfx_monster_die_3 | AK19: vfx_monster_die_4 | AN19: 0 | AO19: {=_xlfn.TEXTJOIN(";",1,IF(AP19:AQ19<>"",AP19:AQ19&"="&AR19:AS19,""))} | AT19: {=_xlfn.LET(_xlpm._tb,"tb_diy_0"&MID(A19,4,1),_xlfn.TEXTJOIN(";",1,_xlfn.MAP(INDIRECT(_xlpm._tb&"[id]"),INDIRECT(_xlpm._tb&"[parm_key]"),INDIRECT(_xlpm._tb&"[parm_value]"),_xlfn.LAMBDA(_xlpm._id,_xlpm._k,_xlpm._v,IF(_xlpm._id=A19,_xlpm._k&"="&_xlpm._v,"")))))}
A20: 201402 | B20: =_xlfn.TEXTJOIN("_",1,"enemy",$A20) -> enemy_201402 | C20: 树梢 | D20: 毒刺果实丛 | G20: se_ag_bat_bite | H20: 33 | I20: 0 | J20: 4 | M20: {=_xlfn.TEXTJOIN(";",1,_xlfn.LAMBDA(_xlpm.x,IF(_xlpm.x<>"",OFFSET(_xlpm.x,3-ROW(),0)&"="&_xlpm.x,""))(N20:S20))} | V20: 10 | W20: 25 | X20: =$W20*$J20 -> 100 | AA20: =_xlfn.TEXTJOIN("_",1,"monster",$A20,$AB20) -> monster_201402_Treetop_Berry_Bush | AB20: Treetop_Berry_Bush | AC20: =_xlfn.TEXTJOIN("_",1,"BT",$AB20) -> BT_Treetop_Berry_Bush | AE20: 0.15 | AF20: =_xlfn.XLOOKUP(A20,'-loot_list辅助配置表'!A:A,'-loot_list辅助配置表'!V:V) -> 10000=0.0048;600404=0.0001 | AG20: =_xlfn.TEXTJOIN(";",1,AH20:AL20) -> vfx_monster_die_1;vfx_monster_die_2;vfx_monster_die_3;vfx_monster_die_4 | AH20: vfx_monster_die_1 | AI20: vfx_monster_die_2 | AJ20: vfx_monster_die_3 | AK20: vfx_monster_die_4 | AN20: 0 | AO20: {=_xlfn.TEXTJOIN(";",1,IF(AP20:AQ20<>"",AP20:AQ20&"="&AR20:AS20,""))} | AT20: {=_xlfn.LET(_xlpm._tb,"tb_diy_0"&MID(A20,4,1),_xlfn.TEXTJOIN(";",1,_xlfn.MAP(INDIRECT(_xlpm._tb&"[id]"),INDIRECT(_xlpm._tb&"[parm_key]"),INDIRECT(_xlpm._tb&"[parm_value]"),_xlfn.LAMBDA(_xlpm._id,_xlpm._k,_xlpm._v,IF(_xlpm._id=A20,_xlpm._k&"="&_xlpm._v,"")))))} -> SUB_CELL_COUNT=4;SUB_CELL_POS_X_AREA=-0.5,0.5;SUB_CELL_POS_Y_AREA=-1.5,0
A21: 201403 | B21: =_xlfn.TEXTJOIN("_",1,"enemy",$A21) -> enemy_201403 | C21: 树梢 | D21: 毒刺果实 | G21: se_ag_bat_bite | H21: 18 | I21: 0 | J21: 4.5 | K21: TRUE | M21: {=_xlfn.TEXTJOIN(";",1,_xlfn.LAMBDA(_xlpm.x,IF(_xlpm.x<>"",OFFSET(_xlpm.x,3-ROW(),0)&"="&_xlpm.x,""))(N21:S21))} -> sharp=7 | N21: 7 | V21: 10 | W21: 25 | X21: =$W21*$J21 -> 112.5 | AA21: =_xlfn.TEXTJOIN("_",1,"monster",$A21,$AB21) -> monster_201403_Treetop_Berry | AB21: Treetop_Berry | AC21: =_xlfn.TEXTJOIN("_",1,"BT",$AB21) -> BT_Treetop_Berry | AE21: 0.15 | AF21: =_xlfn.XLOOKUP(A21,'-loot_list辅助配置表'!A:A,'-loot_list辅助配置表'!V:V) | AG21: =_xlfn.TEXTJOIN(";",1,AH21:AL21) -> vfx_monster_die_1;vfx_monster_die_2;vfx_monster_die_3;vfx_monster_die_4;vfx_monster_die_explode1 | AH21: vfx_monster_die_1 | AI21: vfx_monster_die_2 | AJ21: vfx_monster_die_3 | AK21: vfx_monster_die_4 | AL21: vfx_monster_die_explode1 | AN21: 0 | AO21: {=_xlfn.TEXTJOIN(";",1,IF(AP21:AQ21<>"",AP21:AQ21&"="&AR21:AS21,""))} | AT21: {=_xlfn.LET(_xlpm._tb,"tb_diy_0"&MID(A21,4,1),_xlfn.TEXTJOIN(";",1,_xlfn.MAP(INDIRECT(_xlpm._tb&"[id]"),INDIRECT(_xlpm._tb&"[parm_key]"),INDIRECT(_xlpm._tb&"[parm_value]"),_xlfn.LAMBDA(_xlpm._id,_xlpm._k,_xlpm._v,IF(_xlpm._id=A21,_xlpm._k&"="&_xlpm._v,"")))))}
A22: 201404 | B22: =_xlfn.TEXTJOIN("_",1,"enemy",$A22) -> enemy_201404 | C22: 树梢 | D22: 画中仙 | G22: se_ag_bat_bite | H22: 19 | I22: 0 | J22: 4 | M22: {=_xlfn.TEXTJOIN(";",1,_xlfn.LAMBDA(_xlpm.x,IF(_xlpm.x<>"",OFFSET(_xlpm.x,3-ROW(),0)&"="&_xlpm.x,""))(N22:S22))} -> sharp=5 | N22: 5 | V22: 10 | W22: 25 | X22: =$W22*$J22 -> 100 | AA22: =_xlfn.TEXTJOIN("_",1,"monster",$A22,$AB22) -> monster_201404_Treetop_Fairy | AB22: Treetop_Fairy | AC22: =_xlfn.TEXTJOIN("_",1,"BT",$AB22) -> BT_Treetop_Fairy | AE22: 0.15 | AF22: =_xlfn.XLOOKUP(A22,'-loot_list辅助配置表'!A:A,'-loot_list辅助配置表'!V:V) -> 10000=0.0048;600404=0.0001 | AG22: =_xlfn.TEXTJOIN(";",1,AH22:AL22) -> vfx_monster_die_1;vfx_monster_die_2;vfx_monster_die_3;vfx_monster_die_4 | AH22: vfx_monster_die_1 | AI22: vfx_monster_die_2 | AJ22: vfx_monster_die_3 | AK22: vfx_monster_die_4 | AN22: 0 | AO22: {=_xlfn.TEXTJOIN(";",1,IF(AP22:AQ22<>"",AP22:AQ22&"="&AR22:AS22,""))} | AT22: {=_xlfn.LET(_xlpm._tb,"tb_diy_0"&MID(A22,4,1),_xlfn.TEXTJOIN(";",1,_xlfn.MAP(INDIRECT(_xlpm._tb&"[id]"),INDIRECT(_xlpm._tb&"[parm_key]"),INDIRECT(_xlpm._tb&"[parm_value]"),_xlfn.LAMBDA(_xlpm._id,_xlpm._k,_xlpm._v,IF(_xlpm._id=A22,_xlpm._k&"="&_xlpm._v,"")))))} -> FLYAROUND_DEG=20,170;FLYAROUND_RADIUS=7,10;FLYAROUND_COUNT_MAX=6;FLYAROUND_COUNT_MIN=4;CREATE_CD_AREA=4,6;CREATE_INTERVAL_SEC=0.2;SUB_CELL_COUNT_SINGLE=3;SUB_CELL_SPEED_AREA=1,2
A23: 201405 | B23: =_xlfn.TEXTJOIN("_",1,"enemy",$A23) -> enemy_201405 | C23: 树梢 | D23: 鱼妖 | G23: se_ag_bat_bite | H23: 10 | I23: 0 | J23: 9.9 | M23: {=_xlfn.TEXTJOIN(";",1,_xlfn.LAMBDA(_xlpm.x,IF(_xlpm.x<>"",OFFSET(_xlpm.x,3-ROW(),0)&"="&_xlpm.x,""))(N23:S23))} -> sharp=5 | N23: 5 | V23: 10 | W23: 25 | X23: =$W23*$J23 -> 247.5 | AA23: =_xlfn.TEXTJOIN("_",1,"monster",$A23,$AB23) -> monster_201405_Treetop_Fish | AB23: Treetop_Fish | AC23: =_xlfn.TEXTJOIN("_",1,"BT",$AB23) -> BT_Treetop_Fish | AE23: 0.15 | AF23: =_xlfn.XLOOKUP(A23,'-loot_list辅助配置表'!A:A,'-loot_list辅助配置表'!V:V) | AG23: =_xlfn.TEXTJOIN(";",1,AH23:AL23) -> vfx_monster_die_1;vfx_monster_die_2;vfx_monster_die_3;vfx_monster_die_4 | AH23: vfx_monster_die_1 | AI23: vfx_monster_die_2 | AJ23: vfx_monster_die_3 | AK23: vfx_monster_die_4 | AN23: 0 | AO23: {=_xlfn.TEXTJOIN(";",1,IF(AP23:AQ23<>"",AP23:AQ23&"="&AR23:AS23,""))} | AT23: {=_xlfn.LET(_xlpm._tb,"tb_diy_0"&MID(A23,4,1),_xlfn.TEXTJOIN(";",1,_xlfn.MAP(INDIRECT(_xlpm._tb&"[id]"),INDIRECT(_xlpm._tb&"[parm_key]"),INDIRECT(_xlpm._tb&"[parm_value]"),_xlfn.LAMBDA(_xlpm._id,_xlpm._k,_xlpm._v,IF(_xlpm._id=A23,_xlpm._k&"="&_xlpm._v,"")))))} -> EXPLOSION_RADIUS=1.2;BEHIT_RADIUS=1
A24: 201406 | B24: =_xlfn.TEXTJOIN("_",1,"enemy",$A24) -> enemy_201406 | C24: 树梢 | D24: 鬼瓮 | G24: se_ag_bat_bite | H24: 1 | I24: 0 | J24: 10 | K24: TRUE | M24: {=_xlfn.TEXTJOIN(";",1,_xlfn.LAMBDA(_xlpm.x,IF(_xlpm.x<>"",OFFSET(_xlpm.x,3-ROW(),0)&"="&_xlpm.x,""))(N24:S24))} | V24: 10 | W24: 25 | X24: =$W24*$J24 -> 250 | AA24: =_xlfn.TEXTJOIN("_",1,"monster",$A24,$AB24) -> monster_201406_Treetop_Vase | AB24: Treetop_Vase | AC24: =_xlfn.TEXTJOIN("_",1,"BT",$AB24) -> BT_Treetop_Vase | AE24: 0.15 | AF24: =_xlfn.XLOOKUP(A24,'-loot_list辅助配置表'!A:A,'-loot_list辅助配置表'!V:V) -> 10000=0.0048;600404=0.0001 | AG24: =_xlfn.TEXTJOIN(";",1,AH24:AL24) -> vfx_monster_die_1;vfx_monster_die_2;vfx_monster_die_3;vfx_monster_die_4 | AH24: vfx_monster_die_1 | AI24: vfx_monster_die_2 | AJ24: vfx_monster_die_3 | AK24: vfx_monster_die_4 | AN24: 0 | AO24: {=_xlfn.TEXTJOIN(";",1,IF(AP24:AQ24<>"",AP24:AQ24&"="&AR24:AS24,""))} | AT24: {=_xlfn.LET(_xlpm._tb,"tb_diy_0"&MID(A24,4,1),_xlfn.TEXTJOIN(";",1,_xlfn.MAP(INDIRECT(_xlpm._tb&"[id]"),INDIRECT(_xlpm._tb&"[parm_key]"),INDIRECT(_xlpm._tb&"[parm_value]"),_xlfn.LAMBDA(_xlpm._id,_xlpm._k,_xlpm._v,IF(_xlpm._id=A24,_xlpm._k&"="&_xlpm._v,"")))))} -> CREATE_COUNT_AREA=0,3
A25: 201407 | B25: =_xlfn.TEXTJOIN("_",1,"enemy",$A25) -> enemy_201407 | C25: 树梢 | D25: 鬼狰 | G25: se_ag_bat_bite | H25: 6 | I25: 0 | J25: 9.9 | M25: {=_xlfn.TEXTJOIN(";",1,_xlfn.LAMBDA(_xlpm.x,IF(_xlpm.x<>"",OFFSET(_xlpm.x,3-ROW(),0)&"="&_xlpm.x,""))(N25:S25))} -> sharp=2 | N25: 2 | U25: 50 | V25: 2 | W25: 2 | X25: =$W25*$J25 -> 19.8 | AA25: =_xlfn.TEXTJOIN("_",1,"monster",$A25,$AB25) -> monster_201407_Treetop_Ghost | AB25: Treetop_Ghost | AC25: =_xlfn.TEXTJOIN("_",1,"BT",$AB25) -> BT_Treetop_Ghost | AE25: 0.15 | AF25: =_xlfn.XLOOKUP(A25,'-loot_list辅助配置表'!A:A,'-loot_list辅助配置表'!V:V) | AG25: =_xlfn.TEXTJOIN(";",1,AH25:AL25) -> vfx_monster_die_1;vfx_monster_die_2;vfx_monster_die_3;vfx_monster_die_4 | AH25: vfx_monster_die_1 | AI25: vfx_monster_die_2 | AJ25: vfx_monster_die_3 | AK25: vfx_monster_die_4 | AN25: 0 | AO25: {=_xlfn.TEXTJOIN(";",1,IF(AP25:AQ25<>"",AP25:AQ25&"="&AR25:AS25,""))} | AT25: {=_xlfn.LET(_xlpm._tb,"tb_diy_0"&MID(A25,4,1),_xlfn.TEXTJOIN(";",1,_xlfn.MAP(INDIRECT(_xlpm._tb&"[id]"),INDIRECT(_xlpm._tb&"[parm_key]"),INDIRECT(_xlpm._tb&"[parm_value]"),_xlfn.LAMBDA(_xlpm._id,_xlpm._k,_xlpm._v,IF(_xlpm._id=A25,_xlpm._k&"="&_xlpm._v,"")))))} -> FLYAROUND_DEG=20,170;FLYAROUND_RADIUS=1,5;ATTACK_CD_SEC=3.5
A26: 201408 | B26: =_xlfn.TEXTJOIN("_",1,"enemy",$A26) -> enemy_201408 | C26: 树梢 | D26: 铁针鸟 | G26: se_ag_bat_bite | H26: 19 | I26: 0 | J26: 4 | M26: {=_xlfn.TEXTJOIN(";",1,_xlfn.LAMBDA(_xlpm.x,IF(_xlpm.x<>"",OFFSET(_xlpm.x,3-ROW(),0)&"="&_xlpm.x,""))(N26:S26))} -> sharp=5 | N26: 5 | V26: 10 | W26: 25 | X26: =$W26*$J26 -> 100 | AA26: =_xlfn.TEXTJOIN("_",1,"monster",$A26,$AB26) -> monster_201408_Treetop_Spike_Bird | AB26: Treetop_Spike_Bird | AC26: =_xlfn.TEXTJOIN("_",1,"BT",$AB26) -> BT_Treetop_Spike_Bird | AE26: 0.15 | AF26: =_xlfn.XLOOKUP(A26,'-loot_list辅助配置表'!A:A,'-loot_list辅助配置表'!V:V) -> 10000=0.0048;600404=0.0001 | AG26: =_xlfn.TEXTJOIN(";",1,AH26:AL26) -> vfx_monster_die_1;vfx_monster_die_2;vfx_monster_die_3;vfx_monster_die_4 | AH26: vfx_monster_die_1 | AI26: vfx_monster_die_2 | AJ26: vfx_monster_die_3 | AK26: vfx_monster_die_4 | AN26: 0 | AO26: {=_xlfn.TEXTJOIN(";",1,IF(AP26:AQ26<>"",AP26:AQ26&"="&AR26:AS26,""))} | AT26: {=_xlfn.LET(_xlpm._tb,"tb_diy_0"&MID(A26,4,1),_xlfn.TEXTJOIN(";",1,_xlfn.MAP(INDIRECT(_xlpm._tb&"[id]"),INDIRECT(_xlpm._tb&"[parm_key]"),INDIRECT(_xlpm._tb&"[parm_value]"),_xlfn.LAMBDA(_xlpm._id,_xlpm._k,_xlpm._v,IF(_xlpm._id=A26,_xlpm._k&"="&_xlpm._v,"")))))}
A27: 201409 | B27: =_xlfn.TEXTJOIN("_",1,"enemy",$A27) -> enemy_201409 | C27: 树梢 | D27: 密林松鼠 | G27: se_ag_bat_bite | H27: 19 | I27: 0 | J27: 4 | M27: {=_xlfn.TEXTJOIN(";",1,_xlfn.LAMBDA(_xlpm.x,IF(_xlpm.x<>"",OFFSET(_xlpm.x,3-ROW(),0)&"="&_xlpm.x,""))(N27:S27))} -> sharp=5 | N27: 5 | V27: 10 | W27: 25 | X27: =$W27*$J27 -> 100 | AA27: =_xlfn.TEXTJOIN("_",1,"monster",$A27,$AB27) -> monster_201409_Treetop_Squirrel | AB27: Treetop_Squirrel | AC27: =_xlfn.TEXTJOIN("_",1,"BT",$AB27) -> BT_Treetop_Squirrel | AE27: 0.15 | AF27: =_xlfn.XLOOKUP(A27,'-loot_list辅助配置表'!A:A,'-loot_list辅助配置表'!V:V) -> 10000=0.0048;600404=0.0001 | AG27: =_xlfn.TEXTJOIN(";",1,AH27:AL27) -> vfx_monster_die_1;vfx_monster_die_2;vfx_monster_die_3;vfx_monster_die_4 | AH27: vfx_monster_die_1 | AI27: vfx_monster_die_2 | AJ27: vfx_monster_die_3 | AK27: vfx_monster_die_4 | AN27: 0 | AO27: {=_xlfn.TEXTJOIN(";",1,IF(AP27:AQ27<>"",AP27:AQ27&"="&AR27:AS27,""))} | AT27: {=_xlfn.LET(_xlpm._tb,"tb_diy_0"&MID(A27,4,1),_xlfn.TEXTJOIN(";",1,_xlfn.MAP(INDIRECT(_xlpm._tb&"[id]"),INDIRECT(_xlpm._tb&"[parm_key]"),INDIRECT(_xlpm._tb&"[parm_value]"),_xlfn.LAMBDA(_xlpm._id,_xlpm._k,_xlpm._v,IF(_xlpm._id=A27,_xlpm._k&"="&_xlpm._v,"")))))}
A28: 201410 | B28: =_xlfn.TEXTJOIN("_",1,"enemy",$A28) -> enemy_201410 | C28: 树梢 | D28: 暴躁金尾猴 | G28: se_ag_bat_bite | H28: 19 | I28: 0 | J28: 4 | M28: {=_xlfn.TEXTJOIN(";",1,_xlfn.LAMBDA(_xlpm.x,IF(_xlpm.x<>"",OFFSET(_xlpm.x,3-ROW(),0)&"="&_xlpm.x,""))(N28:S28))} -> sharp=5 | N28: 5 | V28: 10 | W28: 25 | X28: =$W28*$J28 -> 100 | AA28: =_xlfn.TEXTJOIN("_",1,"monster",$A28,$AB28) -> monster_201410_Treetop_Monkey | AB28: Treetop_Monkey | AC28: =_xlfn.TEXTJOIN("_",1,"BT",$AB28) -> BT_Treetop_Monkey | AE28: 0.15 | AF28: =_xlfn.XLOOKUP(A28,'-loot_list辅助配置表'!A:A,'-loot_list辅助配置表'!V:V) -> 10000=0.0048;600404=0.0001 | AG28: =_xlfn.TEXTJOIN(";",1,AH28:AL28) -> vfx_monster_die_1;vfx_monster_die_2;vfx_monster_die_3;vfx_monster_die_4 | AH28: vfx_monster_die_1 | AI28: vfx_monster_die_2 | AJ28: vfx_monster_die_3 | AK28: vfx_monster_die_4 | AN28: 0 | AO28: {=_xlfn.TEXTJOIN(";",1,IF(AP28:AQ28<>"",AP28:AQ28&"="&AR28:AS28,""))} | AT28: {=_xlfn.LET(_xlpm._tb,"tb_diy_0"&MID(A28,4,1),_xlfn.TEXTJOIN(";",1,_xlfn.MAP(INDIRECT(_xlpm._tb&"[id]"),INDIRECT(_xlpm._tb&"[parm_key]"),INDIRECT(_xlpm._tb&"[parm_value]"),_xlfn.LAMBDA(_xlpm._id,_xlpm._k,_xlpm._v,IF(_xlpm._id=A28,_xlpm._k&"="&_xlpm._v,"")))))}
A29: 201411 | B29: =_xlfn.TEXTJOIN("_",1,"enemy",$A29) -> enemy_201411 | C29: 树梢 | D29: 祖蜂 | G29: se_ag_bat_bite | H29: 19 | I29: 0 | J29: 4 | M29: {=_xlfn.TEXTJOIN(";",1,_xlfn.LAMBDA(_xlpm.x,IF(_xlpm.x<>"",OFFSET(_xlpm.x,3-ROW(),0)&"="&_xlpm.x,""))(N29:S29))} -> sharp=5 | N29: 5 | V29: 10 | W29: 25 | X29: =$W29*$J29 -> 100 | AA29: =_xlfn.TEXTJOIN("_",1,"monster",$A29,$AB29) -> monster_201411_Treetop_Bee | AB29: Treetop_Bee | AC29: =_xlfn.TEXTJOIN("_",1,"BT",$AB29) -> BT_Treetop_Bee | AE29: 0.15 | AF29: =_xlfn.XLOOKUP(A29,'-loot_list辅助配置表'!A:A,'-loot_list辅助配置表'!V:V) -> 10000=0.0048;600404=0.0001 | AG29: =_xlfn.TEXTJOIN(";",1,AH29:AL29) -> vfx_monster_die_1;vfx_monster_die_2;vfx_monster_die_3;vfx_monster_die_4 | AH29: vfx_monster_die_1 | AI29: vfx_monster_die_2 | AJ29: vfx_monster_die_3 | AK29: vfx_monster_die_4 | AN29: 0 | AO29: {=_xlfn.TEXTJOIN(";",1,IF(AP29:AQ29<>"",AP29:AQ29&"="&AR29:AS29,""))} | AT29: {=_xlfn.LET(_xlpm._tb,"tb_diy_0"&MID(A29,4,1),_xlfn.TEXTJOIN(";",1,_xlfn.MAP(INDIRECT(_xlpm._tb&"[id]"),INDIRECT(_xlpm._tb&"[parm_key]"),INDIRECT(_xlpm._tb&"[parm_value]"),_xlfn.LAMBDA(_xlpm._id,_xlpm._k,_xlpm._v,IF(_xlpm._id=A29,_xlpm._k&"="&_xlpm._v,"")))))}
A30: 201412 | B30: =_xlfn.TEXTJOIN("_",1,"enemy",$A30) -> enemy_201412 | C30: 树梢 | D30: 幼祖蜂 | G30: se_ag_bat_bite | H30: 19 | I30: 0 | J30: 4 | M30: {=_xlfn.TEXTJOIN(";",1,_xlfn.LAMBDA(_xlpm.x,IF(_xlpm.x<>"",OFFSET(_xlpm.x,3-ROW(),0)&"="&_xlpm.x,""))(N30:S30))} -> sharp=5 | N30: 5 | V30: 10 | W30: 25 | X30: =$W30*$J30 -> 100 | AA30: =_xlfn.TEXTJOIN("_",1,"monster",$A30,$AB30) -> monster_201412_Treetop_Young_Bee | AB30: Treetop_Young_Bee | AC30: =_xlfn.TEXTJOIN("_",1,"BT",$AB30) -> BT_Treetop_Young_Bee | AE30: 0.15 | AF30: =_xlfn.XLOOKUP(A30,'-loot_list辅助配置表'!A:A,'-loot_list辅助配置表'!V:V) | AG30: =_xlfn.TEXTJOIN(";",1,AH30:AL30) -> vfx_monster_die_1;vfx_monster_die_2;vfx_monster_die_3;vfx_monster_die_4 | AH30: vfx_monster_die_1 | AI30: vfx_monster_die_2 | AJ30: vfx_monster_die_3 | AK30: vfx_monster_die_4 | AN30: 0 | AO30: {=_xlfn.TEXTJOIN(";",1,IF(AP30:AQ30<>"",AP30:AQ30&"="&AR30:AS30,""))} | AT30: {=_xlfn.LET(_xlpm._tb,"tb_diy_0"&MID(A30,4,1),_xlfn.TEXTJOIN(";",1,_xlfn.MAP(INDIRECT(_xlpm._tb&"[id]"),INDIRECT(_xlpm._tb&"[parm_key]"),INDIRECT(_xlpm._tb&"[parm_value]"),_xlfn.LAMBDA(_xlpm._id,_xlpm._k,_xlpm._v,IF(_xlpm._id=A30,_xlpm._k&"="&_xlpm._v,"")))))}
A31: 201413 | B31: =_xlfn.TEXTJOIN("_",1,"enemy",$A31) -> enemy_201413 | C31: 树梢 | D31: 春花雀（蓝） | G31: se_ag_bat_bite | H31: 19 | I31: 0 | J31: 4 | M31: {=_xlfn.TEXTJOIN(";",1,_xlfn.LAMBDA(_xlpm.x,IF(_xlpm.x<>"",OFFSET(_xlpm.x,3-ROW(),0)&"="&_xlpm.x,""))(N31:S31))} -> sharp=5 | N31: 5 | V31: 10 | W31: 25 | X31: =$W31*$J31 -> 100 | AA31: =_xlfn.TEXTJOIN("_",1,"monster",$A31,$AB31) -> monster_201413_Treetop_Blue_Sparrow | AB31: Treetop_Blue_Sparrow | AC31: =_xlfn.TEXTJOIN("_",1,"BT",$AB31) -> BT_Treetop_Blue_Sparrow | AE31: 0.15 | AF31: =_xlfn.XLOOKUP(A31,'-loot_list辅助配置表'!A:A,'-loot_list辅助配置表'!V:V) -> 10000=0.0048;600404=0.0001 | AG31: =_xlfn.TEXTJOIN(";",1,AH31:AL31) -> vfx_monster_die_1;vfx_monster_die_2;vfx_monster_die_3;vfx_monster_die_4 | AH31: vfx_monster_die_1 | AI31: vfx_monster_die_2 | AJ31: vfx_monster_die_3 | AK31: vfx_monster_die_4 | AN31: 0 | AO31: {=_xlfn.TEXTJOIN(";",1,IF(AP31:AQ31<>"",AP31:AQ31&"="&AR31:AS31,""))} | AT31: {=_xlfn.LET(_xlpm._tb,"tb_diy_0"&MID(A31,4,1),_xlfn.TEXTJOIN(";",1,_xlfn.MAP(INDIRECT(_xlpm._tb&"[id]"),INDIRECT(_xlpm._tb&"[parm_key]"),INDIRECT(_xlpm._tb&"[parm_value]"),_xlfn.LAMBDA(_xlpm._id,_xlpm._k,_xlpm._v,IF(_xlpm._id=A31,_xlpm._k&"="&_xlpm._v,"")))))}
A32: 201414 | B32: =_xlfn.TEXTJOIN("_",1,"enemy",$A32) -> enemy_201414 | C32: 树梢 | D32: 春花雀（红） | G32: se_ag_bat_bite | H32: 19 | I32: 0 | J32: 4 | M32: {=_xlfn.TEXTJOIN(";",1,_xlfn.LAMBDA(_xlpm.x,IF(_xlpm.x<>"",OFFSET(_xlpm.x,3-ROW(),0)&"="&_xlpm.x,""))(N32:S32))} -> sharp=5 | N32: 5 | V32: 10 | W32: 25 | X32: =$W32*$J32 -> 100 | AA32: =_xlfn.TEXTJOIN("_",1,"monster",$A32,$AB32) -> monster_201414_Treetop_Red_Sparrow | AB32: Treetop_Red_Sparrow | AC32: =_xlfn.TEXTJOIN("_",1,"BT",$AB32) -> BT_Treetop_Red_Sparrow | AE32: 0.15 | AF32: =_xlfn.XLOOKUP(A32,'-loot_list辅助配置表'!A:A,'-loot_list辅助配置表'!V:V) -> 10000=0.0048;600404=0.0001 | AG32: =_xlfn.TEXTJOIN(";",1,AH32:AL32) -> vfx_monster_die_1;vfx_monster_die_2;vfx_monster_die_3;vfx_monster_die_4 | AH32: vfx_monster_die_1 | AI32: vfx_monster_die_2 | AJ32: vfx_monster_die_3 | AK32: vfx_monster_die_4 | AN32: 0 | AO32: {=_xlfn.TEXTJOIN(";",1,IF(AP32:AQ32<>"",AP32:AQ32&"="&AR32:AS32,""))} | AT32: {=_xlfn.LET(_xlpm._tb,"tb_diy_0"&MID(A32,4,1),_xlfn.TEXTJOIN(";",1,_xlfn.MAP(INDIRECT(_xlpm._tb&"[id]"),INDIRECT(_xlpm._tb&"[parm_key]"),INDIRECT(_xlpm._tb&"[parm_value]"),_xlfn.LAMBDA(_xlpm._id,_xlpm._k,_xlpm._v,IF(_xlpm._id=A32,_xlpm._k&"="&_xlpm._v,"")))))}
A33: 201415 | B33: =_xlfn.TEXTJOIN("_",1,"enemy",$A33) -> enemy_201415 | C33: 树梢 | D33: 春花雀（黄） | G33: se_ag_bat_bite | H33: 19 | I33: 0 | J33: 4 | M33: {=_xlfn.TEXTJOIN(";",1,_xlfn.LAMBDA(_xlpm.x,IF(_xlpm.x<>"",OFFSET(_xlpm.x,3-ROW(),0)&"="&_xlpm.x,""))(N33:S33))} -> sharp=5 | N33: 5 | V33: 10 | W33: 25 | X33: =$W33*$J33 -> 100 | AA33: =_xlfn.TEXTJOIN("_",1,"monster",$A33,$AB33) -> monster_201415_Treetop_Yellow_Sparrow | AB33: Treetop_Yellow_Sparrow | AC33: =_xlfn.TEXTJOIN("_",1,"BT",$AB33) -> BT_Treetop_Yellow_Sparrow | AE33: 0.15 | AF33: =_xlfn.XLOOKUP(A33,'-loot_list辅助配置表'!A:A,'-loot_list辅助配置表'!V:V) -> 10000=0.0048;600404=0.0001 | AG33: =_xlfn.TEXTJOIN(";",1,AH33:AL33) -> vfx_monster_die_1;vfx_monster_die_2;vfx_monster_die_3;vfx_monster_die_4 | AH33: vfx_monster_die_1 | AI33: vfx_monster_die_2 | AJ33: vfx_monster_die_3 | AK33: vfx_monster_die_4 | AN33: 0 | AO33: {=_xlfn.TEXTJOIN(";",1,IF(AP33:AQ33<>"",AP33:AQ33&"="&AR33:AS33,""))} | AT33: {=_xlfn.LET(_xlpm._tb,"tb_diy_0"&MID(A33,4,1),_xlfn.TEXTJOIN(";",1,_xlfn.MAP(INDIRECT(_xlpm._tb&"[id]"),INDIRECT(_xlpm._tb&"[parm_key]"),INDIRECT(_xlpm._tb&"[parm_value]"),_xlfn.LAMBDA(_xlpm._id,_xlpm._k,_xlpm._v,IF(_xlpm._id=A33,_xlpm._k&"="&_xlpm._v,"")))))}
A34: 201416 | B34: =_xlfn.TEXTJOIN("_",1,"enemy",$A34) -> enemy_201416 | C34: 树梢 | D34: 绿枝粟粟民 | G34: se_ag_bat_bite | H34: 19 | I34: 0 | J34: 4 | M34: {=_xlfn.TEXTJOIN(";",1,_xlfn.LAMBDA(_xlpm.x,IF(_xlpm.x<>"",OFFSET(_xlpm.x,3-ROW(),0)&"="&_xlpm.x,""))(N34:S34))} -> sharp=5 | N34: 5 | V34: 10 | W34: 25 | X34: =$W34*$J34 -> 100 | AA34: =_xlfn.TEXTJOIN("_",1,"monster",$A34,$AB34) -> monster_201416_Treetop_Branch_SuSu | AB34: Treetop_Branch_SuSu | AC34: =_xlfn.TEXTJOIN("_",1,"BT",$AB34) -> BT_Treetop_Branch_SuSu | AE34: 0.15 | AF34: =_xlfn.XLOOKUP(A34,'-loot_list辅助配置表'!A:A,'-loot_list辅助配置表'!V:V) -> 10000=0.0048;600404=0.0001 | AG34: =_xlfn.TEXTJOIN(";",1,AH34:AL34) -> vfx_monster_die_1;vfx_monster_die_2;vfx_monster_die_3;vfx_monster_die_4 | AH34: vfx_monster_die_1 | AI34: vfx_monster_die_2 | AJ34: vfx_monster_die_3 | AK34: vfx_monster_die_4 | AN34: 0 | AO34: {=_xlfn.TEXTJOIN(";",1,IF(AP34:AQ34<>"",AP34:AQ34&"="&AR34:AS34,""))} | AT34: {=_xlfn.LET(_xlpm._tb,"tb_diy_0"&MID(A34,4,1),_xlfn.TEXTJOIN(";",1,_xlfn.MAP(INDIRECT(_xlpm._tb&"[id]"),INDIRECT(_xlpm._tb&"[parm_key]"),INDIRECT(_xlpm._tb&"[parm_value]"),_xlfn.LAMBDA(_xlpm._id,_xlpm._k,_xlpm._v,IF(_xlpm._id=A34,_xlpm._k&"="&_xlpm._v,"")))))}
A35: 201417 | B35: =_xlfn.TEXTJOIN("_",1,"enemy",$A35) -> enemy_201417 | C35: 树梢 | D35: 悬铃粟粟民 | G35: se_ag_bat_bite | H35: 19 | I35: 0 | J35: 4 | M35: {=_xlfn.TEXTJOIN(";",1,_xlfn.LAMBDA(_xlpm.x,IF(_xlpm.x<>"",OFFSET(_xlpm.x,3-ROW(),0)&"="&_xlpm.x,""))(N35:S35))} -> sharp=5 | N35: 5 | V35: 10 | W35: 25 | X35: =$W35*$J35 -> 100 | AA35: =_xlfn.TEXTJOIN("_",1,"monster",$A35,$AB35) -> monster_201417_Treetop_Bell_SuSu | AB35: Treetop_Bell_SuSu | AC35: =_xlfn.TEXTJOIN("_",1,"BT",$AB35) -> BT_Treetop_Bell_SuSu | AE35: 0.15 | AF35: =_xlfn.XLOOKUP(A35,'-loot_list辅助配置表'!A:A,'-loot_list辅助配置表'!V:V) -> 10000=0.0048;600404=0.0001 | AG35: =_xlfn.TEXTJOIN(";",1,AH35:AL35) -> vfx_monster_die_1;vfx_monster_die_2;vfx_monster_die_3;vfx_monster_die_4 | AH35: vfx_monster_die_1 | AI35: vfx_monster_die_2 | AJ35: vfx_monster_die_3 | AK35: vfx_monster_die_4 | AN35: 0 | AO35: {=_xlfn.TEXTJOIN(";",1,IF(AP35:AQ35<>"",AP35:AQ35&"="&AR35:AS35,""))} | AT35: {=_xlfn.LET(_xlpm._tb,"tb_diy_0"&MID(A35,4,1),_xlfn.TEXTJOIN(";",1,_xlfn.MAP(INDIRECT(_xlpm._tb&"[id]"),INDIRECT(_xlpm._tb&"[parm_key]"),INDIRECT(_xlpm._tb&"[parm_value]"),_xlfn.LAMBDA(_xlpm._id,_xlpm._k,_xlpm._v,IF(_xlpm._id=A35,_xlpm._k&"="&_xlpm._v,"")))))}
A36: 201418 | B36: =_xlfn.TEXTJOIN("_",1,"enemy",$A36) -> enemy_201418 | C36: 树梢 | D36: 缓慢魔法飞弹 | G36: se_ag_bat_bite | H36: 19 | I36: 0 | J36: 4 | M36: {=_xlfn.TEXTJOIN(";",1,_xlfn.LAMBDA(_xlpm.x,IF(_xlpm.x<>"",OFFSET(_xlpm.x,3-ROW(),0)&"="&_xlpm.x,""))(N36:S36))} -> sharp=5 | N36: 5 | V36: 10 | W36: 25 | X36: =$W36*$J36 -> 100 | AA36: =_xlfn.TEXTJOIN("_",1,"monster",$A36,$AB36) -> monster_201418_Treetop_Slow_Magic_Missile | AB36: Treetop_Slow_Magic_Missile | AC36: =_xlfn.TEXTJOIN("_",1,"BT",$AB36) -> BT_Treetop_Slow_Magic_Missile | AE36: 0.15 | AF36: =_xlfn.XLOOKUP(A36,'-loot_list辅助配置表'!A:A,'-loot_list辅助配置表'!V:V) | AG36: =_xlfn.TEXTJOIN(";",1,AH36:AL36) -> vfx_monster_die_1;vfx_monster_die_2;vfx_monster_die_3;vfx_monster_die_4 | AH36: vfx_monster_die_1 | AI36: vfx_monster_die_2 | AJ36: vfx_monster_die_3 | AK36: vfx_monster_die_4 | AN36: 0 | AO36: {=_xlfn.TEXTJOIN(";",1,IF(AP36:AQ36<>"",AP36:AQ36&"="&AR36:AS36,""))} | AT36: {=_xlfn.LET(_xlpm._tb,"tb_diy_0"&MID(A36,4,1),_xlfn.TEXTJOIN(";",1,_xlfn.MAP(INDIRECT(_xlpm._tb&"[id]"),INDIRECT(_xlpm._tb&"[parm_key]"),INDIRECT(_xlpm._tb&"[parm_value]"),_xlfn.LAMBDA(_xlpm._id,_xlpm._k,_xlpm._v,IF(_xlpm._id=A36,_xlpm._k&"="&_xlpm._v,"")))))}
A37: 201419 | B37: =_xlfn.TEXTJOIN("_",1,"enemy",$A37) -> enemy_201419 | C37: 树梢 | D37: 空木粟粟民 | G37: se_ag_bat_bite | H37: 19 | I37: 0 | J37: 4 | M37: {=_xlfn.TEXTJOIN(";",1,_xlfn.LAMBDA(_xlpm.x,IF(_xlpm.x<>"",OFFSET(_xlpm.x,3-ROW(),0)&"="&_xlpm.x,""))(N37:S37))} -> sharp=5 | N37: 5 | V37: 10 | W37: 25 | X37: =$W37*$J37 -> 100 | AA37: =_xlfn.TEXTJOIN("_",1,"monster",$A37,$AB37) -> monster_201419_Treetop_Wood_SuSu | AB37: Treetop_Wood_SuSu | AC37: =_xlfn.TEXTJOIN("_",1,"BT",$AB37) -> BT_Treetop_Wood_SuSu | AE37: 0.15 | AF37: =_xlfn.XLOOKUP(A37,'-loot_list辅助配置表'!A:A,'-loot_list辅助配置表'!V:V) -> 10000=0.0048;600404=0.0001 | AG37: =_xlfn.TEXTJOIN(";",1,AH37:AL37) -> vfx_monster_die_1;vfx_monster_die_2;vfx_monster_die_3;vfx_monster_die_4 | AH37: vfx_monster_die_1 | AI37: vfx_monster_die_2 | AJ37: vfx_monster_die_3 | AK37: vfx_monster_die_4 | AN37: 0 | AO37: {=_xlfn.TEXTJOIN(";",1,IF(AP37:AQ37<>"",AP37:AQ37&"="&AR37:AS37,""))} | AT37: {=_xlfn.LET(_xlpm._tb,"tb_diy_0"&MID(A37,4,1),_xlfn.TEXTJOIN(";",1,_xlfn.MAP(INDIRECT(_xlpm._tb&"[id]"),INDIRECT(_xlpm._tb&"[parm_key]"),INDIRECT(_xlpm._tb&"[parm_value]"),_xlfn.LAMBDA(_xlpm._id,_xlpm._k,_xlpm._v,IF(_xlpm._id=A37,_xlpm._k&"="&_xlpm._v,"")))))}
A39: 201701 | B39: =_xlfn.TEXTJOIN("_",1,"enemy",$A39) -> enemy_201701 | C39: 荒漠 | D39: 涂涂鸟 | G39: se_ag_bat_bite | H39: 18 | I39: 0 | J39: 1.8 | M39: {=_xlfn.TEXTJOIN(";",1,_xlfn.LAMBDA(_xlpm.x,IF(_xlpm.x<>"",OFFSET(_xlpm.x,3-ROW(),0)&"="&_xlpm.x,""))(N39:S39))} -> sharp=4 | N39: 4 | V39: 5 | W39: 20 | X39: =$W39*$J39 -> 36 | AA39: =_xlfn.TEXTJOIN("_",1,"monster",$A39,$AB39) -> monster_201701_Desert_Bird | AB39: Desert_Bird | AC39: =_xlfn.TEXTJOIN("_",1,"BT",$AB39) -> BT_Desert_Bird | AE39: 0.2 | AF39: =_xlfn.XLOOKUP(A39,'-loot_list辅助配置表'!A:A,'-loot_list辅助配置表'!V:V) -> 10000=0.09;600701=0.0018 | AG39: =_xlfn.TEXTJOIN(";",1,AH39:AL39) -> vfx_monster_die_1;vfx_monster_die_2;vfx_monster_die_3;vfx_monster_die_4 | AH39: vfx_monster_die_1 | AI39: vfx_monster_die_2 | AJ39: vfx_monster_die_3 | AK39: vfx_monster_die_4 | AN39: 0 | AO39: {=_xlfn.TEXTJOIN(";",1,IF(AP39:AQ39<>"",AP39:AQ39&"="&AR39:AS39,""))} | AT39: {=_xlfn.LET(_xlpm._tb,"tb_diy_0"&MID(A39,4,1),_xlfn.TEXTJOIN(";",1,_xlfn.MAP(INDIRECT(_xlpm._tb&"[id]"),INDIRECT(_xlpm._tb&"[parm_key]"),INDIRECT(_xlpm._tb&"[parm_value]"),_xlfn.LAMBDA(_xlpm._id,_xlpm._k,_xlpm._v,IF(_xlpm._id=A39,_xlpm._k&"="&_xlpm._v,"")))))} -> CHARGE_SPEED=30;MAX_CHARGE_SEC=4;FLYAROUND_DEG=80,160;FLYAROUND_RADIUS=8,16;FLYAROUND_COUNT_MAX=6;FLYAROUND_COUNT_MIN=4
A40: 201702 | B40: =_xlfn.TEXTJOIN("_",1,"enemy",$A40) -> enemy_201702 | C40: 荒漠 | D40: 沙漠蛇 | G40: se_ag_bat_bite | H40: 32 | I40: 0 | J40: 6.5 | K40: TRUE | M40: {=_xlfn.TEXTJOIN(";",1,_xlfn.LAMBDA(_xlpm.x,IF(_xlpm.x<>"",OFFSET(_xlpm.x,3-ROW(),0)&"="&_xlpm.x,""))(N40:S40))} -> sharp=5 | N40: 5 | AA40: =_xlfn.TEXTJOIN("_",1,"monster",$A40,$AB40) -> monster_201702_Desert_Snake | AB40: Desert_Snake | AC40: =_xlfn.TEXTJOIN("_",1,"BT",$AB40) -> BT_Desert_Snake | AE40: 0.25 | AF40: =_xlfn.XLOOKUP(A40,'-loot_list辅助配置表'!A:A,'-loot_list辅助配置表'!V:V) -> 10000=0.16;600701=0.0032 | AG40: =_xlfn.TEXTJOIN(";",1,AH40:AL40) -> vfx_monster_die_1;vfx_monster_die_2;vfx_monster_die_3;vfx_monster_die_4 | AH40: vfx_monster_die_1 | AI40: vfx_monster_die_2 | AJ40: vfx_monster_die_3 | AK40: vfx_monster_die_4 | AN40: 0 | AO40: {=_xlfn.TEXTJOIN(";",1,IF(AP40:AQ40<>"",AP40:AQ40&"="&AR40:AS40,""))} | AT40: {=_xlfn.LET(_xlpm._tb,"tb_diy_0"&MID(A40,4,1),_xlfn.TEXTJOIN(";",1,_xlfn.MAP(INDIRECT(_xlpm._tb&"[id]"),INDIRECT(_xlpm._tb&"[parm_key]"),INDIRECT(_xlpm._tb&"[parm_value]"),_xlfn.LAMBDA(_xlpm._id,_xlpm._k,_xlpm._v,IF(_xlpm._id=A40,_xlpm._k&"="&_xlpm._v,"")))))} -> WALK_SPEED=4;BURROW_SEC=3;BURROW_VALID_DIS=6;BEFORE_ATTACK_SEC=0.2;AFTER_ATTACK_SEC=0.3;BEGIN_ATK_DIS=1;ATK_DIS=1.5;ATK_CD=2
A41: 201703 | B41: =_xlfn.TEXTJOIN("_",1,"enemy",$A41) -> enemy_201703 | C41: 荒漠 | D41: 巨牙蝎 | G41: se_ag_bat_bite | H41: 22 | I41: 0 | J41: 0.5 | K41: TRUE | M41: {=_xlfn.TEXTJOIN(";",1,_xlfn.LAMBDA(_xlpm.x,IF(_xlpm.x<>"",OFFSET(_xlpm.x,3-ROW(),0)&"="&_xlpm.x,""))(N41:S41))} -> sharp=5 | N41: 5 | AA41: =_xlfn.TEXTJOIN("_",1,"monster",$A41,$AB41) -> monster_201703_Desert_Scorpion | AB41: Desert_Scorpion | AC41: =_xlfn.TEXTJOIN("_",1,"BT",$AB41) -> BT_Desert_Scorpion | AE41: 0.25 | AF41: =_xlfn.XLOOKUP(A41,'-loot_list辅助配置表'!A:A,'-loot_list辅助配置表'!V:V) -> 10000=0.11;600701=0.0022 | AG41: =_xlfn.TEXTJOIN(";",1,AH41:AL41) -> vfx_monster_die_1;vfx_monster_die_2;vfx_monster_die_3;vfx_monster_die_4 | AH41: vfx_monster_die_1 | AI41: vfx_monster_die_2 | AJ41: vfx_monster_die_3 | AK41: vfx_monster_die_4 | AN41: 0 | AO41: {=_xlfn.TEXTJOIN(";",1,IF(AP41:AQ41<>"",AP41:AQ41&"="&AR41:AS41,""))} | AT41: {=_xlfn.LET(_xlpm._tb,"tb_diy_0"&MID(A41,4,1),_xlfn.TEXTJOIN(";",1,_xlfn.MAP(INDIRECT(_xlpm._tb&"[id]"),INDIRECT(_xlpm._tb&"[parm_key]"),INDIRECT(_xlpm._tb&"[parm_value]"),_xlfn.LAMBDA(_xlpm._id,_xlpm._k,_xlpm._v,IF(_xlpm._id=A41,_xlpm._k&"="&_xlpm._v,"")))))} -> WALK_SPEED=6;BEFORE_ATTACK_SEC=0.2;AFTER_ATTACK_SEC=0.3;BEGIN_ATK_DIS=4;ATK_DIS=1.5;ATK_CD=2;STAND_SEC=2
A42: 201704 | B42: =_xlfn.TEXTJOIN("_",1,"enemy",$A42) -> enemy_201704 | C42: 荒漠 | D42: 巨型石头人 | G42: se_ag_bat_bite | H42: 175 | I42: 0 | J42: 850 | M42: {=_xlfn.TEXTJOIN(";",1,_xlfn.LAMBDA(_xlpm.x,IF(_xlpm.x<>"",OFFSET(_xlpm.x,3-ROW(),0)&"="&_xlpm.x,""))(N42:S42))} -> sharp=13 | N42: 13 | AA42: =_xlfn.TEXTJOIN("_",1,"monster",$A42,$AB42) -> monster_201704_Desert_Giant_Rock | AB42: Desert_Giant_Rock | AC42: =_xlfn.TEXTJOIN("_",1,"BT",$AB42) -> BT_Desert_Giant_Rock | AE42: 0.7 | AF42: =_xlfn.XLOOKUP(A42,'-loot_list辅助配置表'!A:A,'-loot_list辅助配置表'!V:V) -> 10000=0.875;600701=0.0175 | AG42: =_xlfn.TEXTJOIN(";",1,AH42:AL42) -> vfx_monster_die_1;vfx_monster_die_2;vfx_monster_die_3;vfx_monster_die_4 | AH42: vfx_monster_die_1 | AI42: vfx_monster_die_2 | AJ42: vfx_monster_die_3 | AK42: vfx_monster_die_4 | AN42: 0 | AO42: {=_xlfn.TEXTJOIN(";",1,IF(AP42:AQ42<>"",AP42:AQ42&"="&AR42:AS42,""))} | AT42: {=_xlfn.LET(_xlpm._tb,"tb_diy_0"&MID(A42,4,1),_xlfn.TEXTJOIN(";",1,_xlfn.MAP(INDIRECT(_xlpm._tb&"[id]"),INDIRECT(_xlpm._tb&"[parm_key]"),INDIRECT(_xlpm._tb&"[parm_value]"),_xlfn.LAMBDA(_xlpm._id,_xlpm._k,_xlpm._v,IF(_xlpm._id=A42,_xlpm._k&"="&_xlpm._v,"")))))} -> JUMP_CD=1;ATK_DIS=2;LAND_SEC=2;JUMP_VELOCITY_X_MAX=50;JUMP_HEIGHT_AREA=1,2
A43: 201705 | B43: =_xlfn.TEXTJOIN("_",1,"enemy",$A43) -> enemy_201705 | C43: 荒漠 | D43: 小石头人 | G43: se_ag_bat_bite | H43: 55 | I43: 0 | J43: 95 | M43: {=_xlfn.TEXTJOIN(";",1,_xlfn.LAMBDA(_xlpm.x,IF(_xlpm.x<>"",OFFSET(_xlpm.x,3-ROW(),0)&"="&_xlpm.x,""))(N43:S43))} -> sharp=5 | N43: 5 | AA43: =_xlfn.TEXTJOIN("_",1,"monster",$A43,$AB43) -> monster_201705_Desert_Small_Rock | AB43: Desert_Small_Rock | AC43: BT_Desert_Scorpion | AE43: 0.4 | AF43: =_xlfn.XLOOKUP(A43,'-loot_list辅助配置表'!A:A,'-loot_list辅助配置表'!V:V) -> 10000=0.275;600701=0.0055 | AG43: =_xlfn.TEXTJOIN(";",1,AH43:AL43) -> vfx_monster_die_1;vfx_monster_die_2;vfx_monster_die_3;vfx_monster_die_4 | AH43: vfx_monster_die_1 | AI43: vfx_monster_die_2 | AJ43: vfx_monster_die_3 | AK43: vfx_monster_die_4 | AN43: 0 | AO43: {=_xlfn.TEXTJOIN(";",1,IF(AP43:AQ43<>"",AP43:AQ43&"="&AR43:AS43,""))} | AT43: {=_xlfn.LET(_xlpm._tb,"tb_diy_0"&MID(A43,4,1),_xlfn.TEXTJOIN(";",1,_xlfn.MAP(INDIRECT(_xlpm._tb&"[id]"),INDIRECT(_xlpm._tb&"[parm_key]"),INDIRECT(_xlpm._tb&"[parm_value]"),_xlfn.LAMBDA(_xlpm._id,_xlpm._k,_xlpm._v,IF(_xlpm._id=A43,_xlpm._k&"="&_xlpm._v,"")))))} -> WALK_SPEED=4;BEFORE_ATTACK_SEC=0.2;AFTER_ATTACK_SEC=0.3;BEGIN_ATK_DIS=1;ATK_DIS=1.5;ATK_CD=2;STAND_SEC=2
...

Sheet -diy_parm配置
A1: 地宫 | I1: 树梢 | Q1: 荒漠 | Y1: 大湖
A3: id | B3: name | C3: parm_key | D3: 参数说明 | E3: parm_value | F3: v1 | G3: v2 | I3: id | J3: name | K3: parm_key | L3: 参数说明 | M3: parm_value | N3: v1 | O3: v2 | Q3: id | R3: name | S3: parm_key | T3: 参数说明 | U3: parm_value | V3: v1 | W3: v2 | Y3: id | Z3: name | AA3: parm_key | AB3: 参数说明 | AC3: parm_value | AD3: v1 | AE3: v2
A4: 201101 | B4: =_xlfn.XLOOKUP(tb_diy_01[[#This Row],[id]],monster!A:A,monster!D:D,"",0) -> 地宫蝙蝠 | I4: 201402 | J4: =_xlfn.XLOOKUP(tb_diy_04[[#This Row],[id]],monster!A:A,monster!D:D,"",0) -> 毒刺果实丛 | K4: SUB_CELL_COUNT | L4: 果子数量 | M4: =_xlfn.TEXTJOIN(",",1,tb_diy_04[[#This Row],[v1]],tb_diy_04[[#This Row],[v2]]) -> 4 | N4: 4 | Q4: 201701 | R4: =_xlfn.XLOOKUP(tb_diy_07[[#This Row],[id]],monster!A:A,monster!D:D,"",0) -> 涂涂鸟 | S4: CHARGE_SPEED | U4: =_xlfn.TEXTJOIN(",",1,tb_diy_07[[#This Row],[v1]],tb_diy_07[[#This Row],[v2]]) -> 30 | V4: 30 | Y4: 201801 | Z4: =_xlfn.XLOOKUP(tb_diy_08[[#This Row],[id]],monster!A:A,monster!D:D,"",0) -> 金鱼 | AA4: FLYAROUND_DEG | AC4: =_xlfn.TEXTJOIN(",",1,tb_diy_08[[#This Row],[v1]],tb_diy_08[[#This Row],[v2]]) -> 20,170 | AD4: 20 | AE4: 170
A5: 201102 | B5: =_xlfn.XLOOKUP(tb_diy_01[[#This Row],[id]],monster!A:A,monster!D:D,"",0) -> 自爆甲虫 | I5: 201402 | J5: =_xlfn.XLOOKUP(tb_diy_04[[#This Row],[id]],monster!A:A,monster!D:D,"",0) -> 毒刺果实丛 | K5: SUB_CELL_POS_X_AREA | M5: =_xlfn.TEXTJOIN(",",1,tb_diy_04[[#This Row],[v1]],tb_diy_04[[#This Row],[v2]]) -> -0.5,0.5 | N5: -0.5 | O5: 0.5 | Q5: 201701 | R5: =_xlfn.XLOOKUP(tb_diy_07[[#This Row],[id]],monster!A:A,monster!D:D,"",0) -> 涂涂鸟 | S5: MAX_CHARGE_SEC | U5: =_xlfn.TEXTJOIN(",",1,tb_diy_07[[#This Row],[v1]],tb_diy_07[[#This Row],[v2]]) -> 4 | V5: 4 | Y5: 201801 | Z5: =_xlfn.XLOOKUP(tb_diy_08[[#This Row],[id]],monster!A:A,monster!D:D,"",0) -> 金鱼 | AA5: FLYAROUND_RADIUS | AB5: 跟随距离 | AC5: =_xlfn.TEXTJOIN(",",1,tb_diy_08[[#This Row],[v1]],tb_diy_08[[#This Row],[v2]]) -> 7.5,11.5 | AD5: 7.5 | AE5: 11.5
A6: 201103 | B6: =_xlfn.XLOOKUP(tb_diy_01[[#This Row],[id]],monster!A:A,monster!D:D,"",0) -> 跳虫 | I6: 201402 | J6: =_xlfn.XLOOKUP(tb_diy_04[[#This Row],[id]],monster!A:A,monster!D:D,"",0) -> 毒刺果实丛 | K6: SUB_CELL_POS_Y_AREA | M6: =_xlfn.TEXTJOIN(",",1,tb_diy_04[[#This Row],[v1]],tb_diy_04[[#This Row],[v2]]) -> -1.5,0 | N6: -1.5 | O6: 0 | Q6: 201701 | R6: =_xlfn.XLOOKUP(tb_diy_07[[#This Row],[id]],monster!A:A,monster!D:D,"",0) -> 涂涂鸟 | S6: FLYAROUND_DEG | U6: =_xlfn.TEXTJOIN(",",1,tb_diy_07[[#This Row],[v1]],tb_diy_07[[#This Row],[v2]]) -> 80,160 | V6: 80 | W6: 160 | Y6: 201801 | Z6: =_xlfn.XLOOKUP(tb_diy_08[[#This Row],[id]],monster!A:A,monster!D:D,"",0) -> 金鱼 | AA6: FLYAROUND_COUNT_MAX | AC6: =_xlfn.TEXTJOIN(",",1,tb_diy_08[[#This Row],[v1]],tb_diy_08[[#This Row],[v2]]) -> 6 | AD6: 6 | AF6: Tool 1 | AG6: Tool 2 | AH6: Tool 3 | AI6: Tool 4
A7: 201104 | B7: =_xlfn.XLOOKUP(tb_diy_01[[#This Row],[id]],monster!A:A,monster!D:D,"",0) -> 地宫洞穴人 | I7: 201404 | J7: =_xlfn.XLOOKUP(tb_diy_04[[#This Row],[id]],monster!A:A,monster!D:D,"",0) -> 画中仙 | K7: FLYAROUND_DEG | M7: =_xlfn.TEXTJOIN(",",1,tb_diy_04[[#This Row],[v1]],tb_diy_04[[#This Row],[v2]]) -> 20,170 | N7: 20 | O7: 170 | Q7: 201701 | R7: =_xlfn.XLOOKUP(tb_diy_07[[#This Row],[id]],monster!A:A,monster!D:D,"",0) -> 涂涂鸟 | S7: FLYAROUND_RADIUS | U7: =_xlfn.TEXTJOIN(",",1,tb_diy_07[[#This Row],[v1]],tb_diy_07[[#This Row],[v2]]) -> 8,16 | V7: 8 | W7: 16 | Y7: 201801 | Z7: =_xlfn.XLOOKUP(tb_diy_08[[#This Row],[id]],monster!A:A,monster!D:D,"",0) -> 金鱼 | AA7: FLYAROUND_COUNT_MIN | AC7: =_xlfn.TEXTJOIN(",",1,tb_diy_08[[#This Row],[v1]],tb_diy_08[[#This Row],[v2]]) -> 4 | AD7: 4 | AF7: 201401 | AH7: =IFERROR(COLUMNS(_xlfn.TEXTSPLIT(AG7,";")),0) -> 0 | AI7: {=_xlfn.MAKEARRAY(19,MAX(AH7:AH25),_xlfn.LAMBDA(_xlpm.x,_xlpm.y,IF(_xlpm.y<=INDEX(AH7:AH25,_xlpm.x),INDEX(AF7:AF25,_xlpm.x),"")))}
A8: 201105 | B8: =_xlfn.XLOOKUP(tb_diy_01[[#This Row],[id]],monster!A:A,monster!D:D,"",0) -> 跳虫骑手 | I8: 201404 | J8: =_xlfn.XLOOKUP(tb_diy_04[[#This Row],[id]],monster!A:A,monster!D:D,"",0) -> 画中仙 | K8: FLYAROUND_RADIUS | M8: =_xlfn.TEXTJOIN(",",1,tb_diy_04[[#This Row],[v1]],tb_diy_04[[#This Row],[v2]]) -> 7,10 | N8: 7 | O8: 10 | Q8: 201701 | R8: =_xlfn.XLOOKUP(tb_diy_07[[#This Row],[id]],monster!A:A,monster!D:D,"",0) -> 涂涂鸟 | S8: FLYAROUND_COUNT_MAX | U8: =_xlfn.TEXTJOIN(",",1,tb_diy_07[[#This Row],[v1]],tb_diy_07[[#This Row],[v2]]) -> 6 | V8: 6 | Y8: 201801 | Z8: =_xlfn.XLOOKUP(tb_diy_08[[#This Row],[id]],monster!A:A,monster!D:D,"",0) -> 金鱼 | AA8: FLYFOLLOW_DIS | AB8: 攻击距离 | AC8: =_xlfn.TEXTJOIN(",",1,tb_diy_08[[#This Row],[v1]],tb_diy_08[[#This Row],[v2]]) -> 6,10 | AD8: 6 | AE8: 10 | AF8: 201402 | AG8: SUB_CELL_COUNT=10;SUB_CELL_POS_X_AREA=-0.5,0.5;SUB_CELL_POS_Y_AREA=-1.5,0 | AH8: =IFERROR(COLUMNS(_xlfn.TEXTSPLIT(AG8,";")),0) -> 3 | AI8: 201402 | AJ8: 201402 | AK8: 201402
A9: 201106 | B9: =_xlfn.XLOOKUP(tb_diy_01[[#This Row],[id]],monster!A:A,monster!D:D,"",0) -> 蝙蝠骑手 | I9: 201404 | J9: =_xlfn.XLOOKUP(tb_diy_04[[#This Row],[id]],monster!A:A,monster!D:D,"",0) -> 画中仙 | K9: FLYAROUND_COUNT_MAX | M9: =_xlfn.TEXTJOIN(",",1,tb_diy_04[[#This Row],[v1]],tb_diy_04[[#This Row],[v2]]) -> 6 | N9: 6 | Q9: 201701 | R9: =_xlfn.XLOOKUP(tb_diy_07[[#This Row],[id]],monster!A:A,monster!D:D,"",0) -> 涂涂鸟 | S9: FLYAROUND_COUNT_MIN | U9: =_xlfn.TEXTJOIN(",",1,tb_diy_07[[#This Row],[v1]],tb_diy_07[[#This Row],[v2]]) -> 4 | V9: 4 | Y9: 201801 | Z9: =_xlfn.XLOOKUP(tb_diy_08[[#This Row],[id]],monster!A:A,monster!D:D,"",0) -> 金鱼 | AA9: BEFORE_ATTACK_SEC | AC9: =_xlfn.TEXTJOIN(",",1,tb_diy_08[[#This Row],[v1]],tb_diy_08[[#This Row],[v2]]) -> 0.2 | AD9: 0.2 | AF9: 201403 | AH9: =IFERROR(COLUMNS(_xlfn.TEXTSPLIT(AG9,";")),0) -> 0
A10: 201107 | B10: =_xlfn.XLOOKUP(tb_diy_01[[#This Row],[id]],monster!A:A,monster!D:D,"",0) -> 流浪洞穴人 | I10: 201404 | J10: =_xlfn.XLOOKUP(tb_diy_04[[#This Row],[id]],monster!A:A,monster!D:D,"",0) -> 画中仙 | K10: FLYAROUND_COUNT_MIN | M10: =_xlfn.TEXTJOIN(",",1,tb_diy_04[[#This Row],[v1]],tb_diy_04[[#This Row],[v2]]) -> 4 | N10: 4 | Q10: 201702 | R10: =_xlfn.XLOOKUP(tb_diy_07[[#This Row],[id]],monster!A:A,monster!D:D,"",0) -> 沙漠蛇 | S10: WALK_SPEED | U10: =_xlfn.TEXTJOIN(",",1,tb_diy_07[[#This Row],[v1]],tb_diy_07[[#This Row],[v2]]) -> 4 | V10: 4 | Y10: 201801 | Z10: =_xlfn.XLOOKUP(tb_diy_08[[#This Row],[id]],monster!A:A,monster!D:D,"",0) -> 金鱼 | AA10: AFTER_ATTACK_SEC | AC10: =_xlfn.TEXTJOIN(",",1,tb_diy_08[[#This Row],[v1]],tb_diy_08[[#This Row],[v2]]) -> 0.5 | AD10: 0.5 | AF10: 201404 | AG10: FLYAROUND_DEG=20,170;FLYAROUND_RADIUS=7,10;FLYAROUND_COUNT_MAX=6;FLYAROUND_COUNT_MIN=4;CREATE_CD_AREA=4,6;CREATE_INTERVAL_SEC=0.2;SUB_CELL_COUNT_SINGLE=3;SUB_CELL_SPEED_AREA=1,2 | AH10: =IFERROR(COLUMNS(_xlfn.TEXTSPLIT(AG10,";")),0) -> 8 | AI10: 201404 | AJ10: 201404 | AK10: 201404 | AL10: 201404 | AM10: 201404 | AN10: 201404 | AO10: 201404 | AP10: 201404
A11: 201108 | B11: =_xlfn.XLOOKUP(tb_diy_01[[#This Row],[id]],monster!A:A,monster!D:D,"",0) -> 纵火洞穴人 | I11: 201404 | J11: =_xlfn.XLOOKUP(tb_diy_04[[#This Row],[id]],monster!A:A,monster!D:D,"",0) -> 画中仙 | K11: CREATE_CD_AREA | M11: =_xlfn.TEXTJOIN(",",1,tb_diy_04[[#This Row],[v1]],tb_diy_04[[#This Row],[v2]]) -> 4,6 | N11: 4 | O11: 6 | Q11: 201702 | R11: =_xlfn.XLOOKUP(tb_diy_07[[#This Row],[id]],monster!A:A,monster!D:D,"",0) -> 沙漠蛇 | S11: BURROW_SEC | U11: =_xlfn.TEXTJOIN(",",1,tb_diy_07[[#This Row],[v1]],tb_diy_07[[#This Row],[v2]]) -> 3 | V11: 3 | Y11: 201801 | Z11: =_xlfn.XLOOKUP(tb_diy_08[[#This Row],[id]],monster!A:A,monster!D:D,"",0) -> 金鱼 | AA11: BUBBLE_COUNT | AB11: 泡泡吐出数 | AC11: =_xlfn.TEXTJOIN(",",1,tb_diy_08[[#This Row],[v1]],tb_diy_08[[#This Row],[v2]]) -> 1 | AD11: 1 | AF11: 201405 | AG11: EXPLOSION_RADIUS=1.2;BEHIT_RADIUS=1 | AH11: =IFERROR(COLUMNS(_xlfn.TEXTSPLIT(AG11,";")),0) -> 2 | AI11: 201405 | AJ11: 201405
A12: 201109 | B12: =_xlfn.XLOOKUP(tb_diy_01[[#This Row],[id]],monster!A:A,monster!D:D,"",0) -> 暴徒洞穴人 | I12: 201404 | J12: =_xlfn.XLOOKUP(tb_diy_04[[#This Row],[id]],monster!A:A,monster!D:D,"",0) -> 画中仙 | K12: CREATE_INTERVAL_SEC | M12: =_xlfn.TEXTJOIN(",",1,tb_diy_04[[#This Row],[v1]],tb_diy_04[[#This Row],[v2]]) -> 0.2 | N12: 0.2 | Q12: 201702 | R12: =_xlfn.XLOOKUP(tb_diy_07[[#This Row],[id]],monster!A:A,monster!D:D,"",0) -> 沙漠蛇 | S12: BURROW_VALID_DIS | U12: =_xlfn.TEXTJOIN(",",1,tb_diy_07[[#This Row],[v1]],tb_diy_07[[#This Row],[v2]]) -> 6 | V12: 6 | Y12: 201801 | Z12: =_xlfn.XLOOKUP(tb_diy_08[[#This Row],[id]],monster!A:A,monster!D:D,"",0) -> 金鱼 | AA12: BUBBLE_INTERVAL_SEC | AB12: 吐泡泡间隔 | AC12: =_xlfn.TEXTJOIN(",",1,tb_diy_08[[#This Row],[v1]],tb_diy_08[[#This Row],[v2]]) -> 0.3 | AD12: 0.3 | AF12: 201406 | AG12: CREATE_COUNT_AREA=1,3 | AH12: =IFERROR(COLUMNS(_xlfn.TEXTSPLIT(AG12,";")),0) -> 1 | AI12: 201406
I13: 201404 | J13: =_xlfn.XLOOKUP(tb_diy_04[[#This Row],[id]],monster!A:A,monster!D:D,"",0) -> 画中仙 | K13: SUB_CELL_COUNT_SINGLE | M13: =_xlfn.TEXTJOIN(",",1,tb_diy_04[[#This Row],[v1]],tb_diy_04[[#This Row],[v2]]) -> 3 | N13: 3 | Q13: 201702 | R13: =_xlfn.XLOOKUP(tb_diy_07[[#This Row],[id]],monster!A:A,monster!D:D,"",0) -> 沙漠蛇 | S13: BEFORE_ATTACK_SEC | U13: =_xlfn.TEXTJOIN(",",1,tb_diy_07[[#This Row],[v1]],tb_diy_07[[#This Row],[v2]]) -> 0.2 | V13: 0.2 | Y13: 201802 | Z13: =_xlfn.XLOOKUP(tb_diy_08[[#This Row],[id]],monster!A:A,monster!D:D,"",0) -> 金鱼泡泡 | AA13: EXPLOSION_RADIUS | AC13: =_xlfn.TEXTJOIN(",",1,tb_diy_08[[#This Row],[v1]],tb_diy_08[[#This Row],[v2]]) -> 1.2 | AD13: 1.2 | AF13: 201407 | AG13: FLYAROUND_DEG=20,170;FLYAROUND_RADIUS=1,5;ATTACK_CD_SEC=2 | AH13: =IFERROR(COLUMNS(_xlfn.TEXTSPLIT(AG13,";")),0) -> 3 | AI13: 201407 | AJ13: 201407 | AK13: 201407
I14: 201404 | J14: =_xlfn.XLOOKUP(tb_diy_04[[#This Row],[id]],monster!A:A,monster!D:D,"",0) -> 画中仙 | K14: SUB_CELL_SPEED_AREA | M14: =_xlfn.TEXTJOIN(",",1,tb_diy_04[[#This Row],[v1]],tb_diy_04[[#This Row],[v2]]) -> 1,2 | N14: 1 | O14: 2 | Q14: 201702 | R14: =_xlfn.XLOOKUP(tb_diy_07[[#This Row],[id]],monster!A:A,monster!D:D,"",0) -> 沙漠蛇 | S14: AFTER_ATTACK_SEC | U14: =_xlfn.TEXTJOIN(",",1,tb_diy_07[[#This Row],[v1]],tb_diy_07[[#This Row],[v2]]) -> 0.3 | V14: 0.3 | Y14: 201802 | Z14: =_xlfn.XLOOKUP(tb_diy_08[[#This Row],[id]],monster!A:A,monster!D:D,"",0) -> 金鱼泡泡 | AA14: BEHIT_RADIUS | AC14: =_xlfn.TEXTJOIN(",",1,tb_diy_08[[#This Row],[v1]],tb_diy_08[[#This Row],[v2]]) -> 1 | AD14: 1 | AF14: 201408 | AH14: =IFERROR(COLUMNS(_xlfn.TEXTSPLIT(AG14,";")),0) -> 0
I15: 201405 | J15: =_xlfn.XLOOKUP(tb_diy_04[[#This Row],[id]],monster!A:A,monster!D:D,"",0) -> 鱼妖 | K15: EXPLOSION_RADIUS | M15: =_xlfn.TEXTJOIN(",",1,tb_diy_04[[#This Row],[v1]],tb_diy_04[[#This Row],[v2]]) -> 1.2 | N15: 1.2 | Q15: 201702 | R15: =_xlfn.XLOOKUP(tb_diy_07[[#This Row],[id]],monster!A:A,monster!D:D,"",0) -> 沙漠蛇 | S15: BEGIN_ATK_DIS | U15: =_xlfn.TEXTJOIN(",",1,tb_diy_07[[#This Row],[v1]],tb_diy_07[[#This Row],[v2]]) -> 1 | V15: 1 | Y15: 201803 | Z15: =_xlfn.XLOOKUP(tb_diy_08[[#This Row],[id]],monster!A:A,monster!D:D,"",0) -> 海藻小妖 | AA15: FLYAROUND_DEG | AC15: =_xlfn.TEXTJOIN(",",1,tb_diy_08[[#This Row],[v1]],tb_diy_08[[#This Row],[v2]]) -> 35,145 | AD15: 35 | AE15: 145 | AF15: 201409 | AH15: =IFERROR(COLUMNS(_xlfn.TEXTSPLIT(AG15,";")),0) -> 0
I16: 201405 | J16: =_xlfn.XLOOKUP(tb_diy_04[[#This Row],[id]],monster!A:A,monster!D:D,"",0) -> 鱼妖 | K16: BEHIT_RADIUS | M16: =_xlfn.TEXTJOIN(",",1,tb_diy_04[[#This Row],[v1]],tb_diy_04[[#This Row],[v2]]) -> 1 | N16: 1 | Q16: 201702 | R16: =_xlfn.XLOOKUP(tb_diy_07[[#This Row],[id]],monster!A:A,monster!D:D,"",0) -> 沙漠蛇 | S16: ATK_DIS | U16: =_xlfn.TEXTJOIN(",",1,tb_diy_07[[#This Row],[v1]],tb_diy_07[[#This Row],[v2]]) -> 1.5 | V16: 1.5 | Y16: 201803 | Z16: =_xlfn.XLOOKUP(tb_diy_08[[#This Row],[id]],monster!A:A,monster!D:D,"",0) -> 海藻小妖 | AA16: FLYAROUND_RADIUS | AB16: 跟随距离 | AC16: =_xlfn.TEXTJOIN(",",1,tb_diy_08[[#This Row],[v1]],tb_diy_08[[#This Row],[v2]]) -> 6,9 | AD16: 6 | AE16: 9 | AF16: 201410 | AH16: =IFERROR(COLUMNS(_xlfn.TEXTSPLIT(AG16,";")),0) -> 0
I17: 201406 | J17: =_xlfn.XLOOKUP(tb_diy_04[[#This Row],[id]],monster!A:A,monster!D:D,"",0) -> 鬼瓮 | K17: CREATE_COUNT_AREA | L17: 鬼狰生成数 | M17: =_xlfn.TEXTJOIN(",",1,tb_diy_04[[#This Row],[v1]],tb_diy_04[[#This Row],[v2]]) -> 0,3 | N17: 0 | O17: 3 | Q17: 201702 | R17: =_xlfn.XLOOKUP(tb_diy_07[[#This Row],[id]],monster!A:A,monster!D:D,"",0) -> 沙漠蛇 | S17: ATK_CD | U17: =_xlfn.TEXTJOIN(",",1,tb_diy_07[[#This Row],[v1]],tb_diy_07[[#This Row],[v2]]) -> 2 | V17: 2 | Y17: 201803 | Z17: =_xlfn.XLOOKUP(tb_diy_08[[#This Row],[id]],monster!A:A,monster!D:D,"",0) -> 海藻小妖 | AA17: FLYAROUND_COUNT_MAX | AC17: =_xlfn.TEXTJOIN(",",1,tb_diy_08[[#This Row],[v1]],tb_diy_08[[#This Row],[v2]]) -> 3 | AD17: 3 | AF17: 201411 | AH17: =IFERROR(COLUMNS(_xlfn.TEXTSPLIT(AG17,";")),0) -> 0
I18: 201407 | J18: =_xlfn.XLOOKUP(tb_diy_04[[#This Row],[id]],monster!A:A,monster!D:D,"",0) -> 鬼狰 | K18: FLYAROUND_DEG | M18: =_xlfn.TEXTJOIN(",",1,tb_diy_04[[#This Row],[v1]],tb_diy_04[[#This Row],[v2]]) -> 20,170 | N18: 20 | O18: 170 | Q18: 201703 | R18: =_xlfn.XLOOKUP(tb_diy_07[[#This Row],[id]],monster!A:A,monster!D:D,"",0) -> 巨牙蝎 | S18: WALK_SPEED | U18: =_xlfn.TEXTJOIN(",",1,tb_diy_07[[#This Row],[v1]],tb_diy_07[[#This Row],[v2]]) -> 6 | V18: 6 | Y18: 201803 | Z18: =_xlfn.XLOOKUP(tb_diy_08[[#This Row],[id]],monster!A:A,monster!D:D,"",0) -> 海藻小妖 | AA18: FLYAROUND_COUNT_MIN | AC18: =_xlfn.TEXTJOIN(",",1,tb_diy_08[[#This Row],[v1]],tb_diy_08[[#This Row],[v2]]) -> 1 | AD18: 1 | AF18: 201412 | AH18: =IFERROR(COLUMNS(_xlfn.TEXTSPLIT(AG18,";")),0) -> 0
I19: 201407 | J19: =_xlfn.XLOOKUP(tb_diy_04[[#This Row],[id]],monster!A:A,monster!D:D,"",0) -> 鬼狰 | K19: FLYAROUND_RADIUS | M19: =_xlfn.TEXTJOIN(",",1,tb_diy_04[[#This Row],[v1]],tb_diy_04[[#This Row],[v2]]) -> 1,5 | N19: 1 | O19: 5 | Q19: 201703 | R19: =_xlfn.XLOOKUP(tb_diy_07[[#This Row],[id]],monster!A:A,monster!D:D,"",0) -> 巨牙蝎 | S19: BEFORE_ATTACK_SEC | U19: =_xlfn.TEXTJOIN(",",1,tb_diy_07[[#This Row],[v1]],tb_diy_07[[#This Row],[v2]]) -> 0.2 | V19: 0.2 | Y19: 201803 | Z19: =_xlfn.XLOOKUP(tb_diy_08[[#This Row],[id]],monster!A:A,monster!D:D,"",0) -> 海藻小妖 | AA19: FLYFOLLOW_DIS | AB19: 攻击距离 | AC19: =_xlfn.TEXTJOIN(",",1,tb_diy_08[[#This Row],[v1]],tb_diy_08[[#This Row],[v2]]) -> 1,2 | AD19: 1 | AE19: 2 | AF19: 201413 | AH19: =IFERROR(COLUMNS(_xlfn.TEXTSPLIT(AG19,";")),0) -> 0
I20: 201407 | J20: =_xlfn.XLOOKUP(tb_diy_04[[#This Row],[id]],monster!A:A,monster!D:D,"",0) -> 鬼狰 | K20: ATTACK_CD_SEC | M20: =_xlfn.TEXTJOIN(",",1,tb_diy_04[[#This Row],[v1]],tb_diy_04[[#This Row],[v2]]) -> 3.5 | N20: 3.5 | Q20: 201703 | R20: =_xlfn.XLOOKUP(tb_diy_07[[#This Row],[id]],monster!A:A,monster!D:D,"",0) -> 巨牙蝎 | S20: AFTER_ATTACK_SEC | U20: =_xlfn.TEXTJOIN(",",1,tb_diy_07[[#This Row],[v1]],tb_diy_07[[#This Row],[v2]]) -> 0.3 | V20: 0.3 | Y20: 201803 | Z20: =_xlfn.XLOOKUP(tb_diy_08[[#This Row],[id]],monster!A:A,monster!D:D,"",0) -> 海藻小妖 | AA20: BEFORE_ATTACK_SEC | AC20: =_xlfn.TEXTJOIN(",",1,tb_diy_08[[#This Row],[v1]],tb_diy_08[[#This Row],[v2]]) -> 0.2 | AD20: 0.2 | AF20: 201414 | AH20: =IFERROR(COLUMNS(_xlfn.TEXTSPLIT(AG20,";")),0) -> 0
Q21: 201703 | R21: =_xlfn.XLOOKUP(tb_diy_07[[#This Row],[id]],monster!A:A,monster!D:D,"",0) -> 巨牙蝎 | S21: BEGIN_ATK_DIS | T21: 钻出检测距离 | U21: =_xlfn.TEXTJOIN(",",1,tb_diy_07[[#This Row],[v1]],tb_diy_07[[#This Row],[v2]]) -> 4 | V21: 4 | Y21: 201803 | Z21: =_xlfn.XLOOKUP(tb_diy_08[[#This Row],[id]],monster!A:A,monster!D:D,"",0) -> 海藻小妖 | AA21: AFTER_ATTACK_SEC | AC21: =_xlfn.TEXTJOIN(",",1,tb_diy_08[[#This Row],[v1]],tb_diy_08[[#This Row],[v2]]) -> 0.5 | AD21: 0.5 | AF21: 201415 | AH21: =IFERROR(COLUMNS(_xlfn.TEXTSPLIT(AG21,";")),0) -> 0
Q22: 201703 | R22: =_xlfn.XLOOKUP(tb_diy_07[[#This Row],[id]],monster!A:A,monster!D:D,"",0) -> 巨牙蝎 | S22: ATK_DIS | U22: =_xlfn.TEXTJOIN(",",1,tb_diy_07[[#This Row],[v1]],tb_diy_07[[#This Row],[v2]]) -> 1.5 | V22: 1.5 | Y22: 201804 | Z22: =_xlfn.XLOOKUP(tb_diy_08[[#This Row],[id]],monster!A:A,monster!D:D,"",0) -> 鲶鱼 | AA22: FLYAROUND_DEG | AC22: =_xlfn.TEXTJOIN(",",1,tb_diy_08[[#This Row],[v1]],tb_diy_08[[#This Row],[v2]]) -> 20,160 | AD22: 20 | AE22: 160 | AF22: 201416 | AH22: =IFERROR(COLUMNS(_xlfn.TEXTSPLIT(AG22,";")),0) -> 0
Q23: 201703 | R23: =_xlfn.XLOOKUP(tb_diy_07[[#This Row],[id]],monster!A:A,monster!D:D,"",0) -> 巨牙蝎 | S23: ATK_CD | U23: =_xlfn.TEXTJOIN(",",1,tb_diy_07[[#This Row],[v1]],tb_diy_07[[#This Row],[v2]]) -> 2 | V23: 2 | Y23: 201804 | Z23: =_xlfn.XLOOKUP(tb_diy_08[[#This Row],[id]],monster!A:A,monster!D:D,"",0) -> 鲶鱼 | AA23: FLYAROUND_RADIUS | AC23: =_xlfn.TEXTJOIN(",",1,tb_diy_08[[#This Row],[v1]],tb_diy_08[[#This Row],[v2]]) -> 8,12 | AD23: 8 | AE23: 12 | AF23: 201417 | AH23: =IFERROR(COLUMNS(_xlfn.TEXTSPLIT(AG23,";")),0) -> 0
Q24: 201703 | R24: =_xlfn.XLOOKUP(tb_diy_07[[#This Row],[id]],monster!A:A,monster!D:D,"",0) -> 巨牙蝎 | S24: STAND_SEC | U24: =_xlfn.TEXTJOIN(",",1,tb_diy_07[[#This Row],[v1]],tb_diy_07[[#This Row],[v2]]) -> 2 | V24: 2 | Y24: 201804 | Z24: =_xlfn.XLOOKUP(tb_diy_08[[#This Row],[id]],monster!A:A,monster!D:D,"",0) -> 鲶鱼 | AA24: FLYAROUND_COUNT_MAX | AC24: =_xlfn.TEXTJOIN(",",1,tb_diy_08[[#This Row],[v1]],tb_diy_08[[#This Row],[v2]]) -> 3 | AD24: 3 | AF24: 201418 | AH24: =IFERROR(COLUMNS(_xlfn.TEXTSPLIT(AG24,";")),0) -> 0
Q25: 201704 | R25: =_xlfn.XLOOKUP(tb_diy_07[[#This Row],[id]],monster!A:A,monster!D:D,"",0) -> 巨型石头人 | S25: JUMP_CD | U25: =_xlfn.TEXTJOIN(",",1,tb_diy_07[[#This Row],[v1]],tb_diy_07[[#This Row],[v2]]) -> 1 | V25: 1 | Y25: 201804 | Z25: =_xlfn.XLOOKUP(tb_diy_08[[#This Row],[id]],monster!A:A,monster!D:D,"",0) -> 鲶鱼 | AA25: FLYAROUND_COUNT_MIN | AC25: =_xlfn.TEXTJOIN(",",1,tb_diy_08[[#This Row],[v1]],tb_diy_08[[#This Row],[v2]]) -> 1 | AD25: 1 | AF25: 201419 | AH25: =IFERROR(COLUMNS(_xlfn.TEXTSPLIT(AG25,";")),0) -> 0
Q26: 201704 | R26: =_xlfn.XLOOKUP(tb_diy_07[[#This Row],[id]],monster!A:A,monster!D:D,"",0) -> 巨型石头人 | S26: ATK_DIS | U26: =_xlfn.TEXTJOIN(",",1,tb_diy_07[[#This Row],[v1]],tb_diy_07[[#This Row],[v2]]) -> 2 | V26: 2 | Y26: 201804 | Z26: =_xlfn.XLOOKUP(tb_diy_08[[#This Row],[id]],monster!A:A,monster!D:D,"",0) -> 鲶鱼 | AA26: FLYFOLLOW_DIS | AC26: =_xlfn.TEXTJOIN(",",1,tb_diy_08[[#This Row],[v1]],tb_diy_08[[#This Row],[v2]]) -> 0.5,1 | AD26: 0.5 | AE26: 1
Q27: 201704 | R27: =_xlfn.XLOOKUP(tb_diy_07[[#This Row],[id]],monster!A:A,monster!D:D,"",0) -> 巨型石头人 | S27: LAND_SEC | U27: =_xlfn.TEXTJOIN(",",1,tb_diy_07[[#This Row],[v1]],tb_diy_07[[#This Row],[v2]]) -> 2 | V27: 2 | Y27: 201804 | Z27: =_xlfn.XLOOKUP(tb_diy_08[[#This Row],[id]],monster!A:A,monster!D:D,"",0) -> 鲶鱼 | AA27: BEFORE_ATTACK_SEC | AC27: =_xlfn.TEXTJOIN(",",1,tb_diy_08[[#This Row],[v1]],tb_diy_08[[#This Row],[v2]]) -> 0.2 | AD27: 0.2
