Workbook

Sheet device_all
A1: #enum slotType: int {车轮 = 0, 顶部 = 1,前 = 2,后 = 3 , 前上 = 4, 后上 = 5}
A2: #enum deviceType: int {Core = 1, Wheel = 2, Common = 3}
A3: id | B3: sub_id | F3: rank | H3: name | J3: alt_info | K3: icon_photo | M3: se_broken | N3: se_be_hit | O3: device_tag | Q3: device_type | Z3: prefeb | AA3: weight | AB3: size | AC3: base_value | AF3: target_counts | AG3: unlock_target_ticks | AH3: basic_range | AK3: init_angle_front | AL3: init_angle_front_top | AM3: init_angle_top | AN3: init_angle_back_top | AO3: init_angle_back | AP3: rotate_by_car | AQ3: behavior_script | AR3: basic_damage | AS3: melee_logic | AT3: fire_logic | AU3: shield_logic | AV3: hook_logic | AW3: ram_logic | AX3: other_logic | AY3: rotate_speed | BB3: device_upgrade | BC3: ui_prefab | BD3: cubicles
A4: uint key | B4: uint key | F4: int | H4: string | J4: string | K4: string | M4: string | N4: string | O4: uint[] | Q4: deviceType | Z4: string | AA4: int | AB4: int | AC4: int | AF4: int | AG4: int | AH4: (float,float) | AK4: float | AL4: float | AM4: float | AN4: float | AO4: float | AP4: bool | AQ4: string | AR4: int | AS4: int | AT4: int | AU4: int | AV4: int | AW4: int | AX4: int | AY4: (float,float) | BB4: uint | BC4: string | BD4: uint[]
A5: 设备种类 ID | B5: 设备变种 ID | C5: 备注 | D5: 版本 | E5: 名称 | F5: 设备等级 | G5: Spine 文件名称 | H5: 设备名称 | I5: 说明/备注 | J5: 设备alt信息 | K5: 设备形象图 会显示在商店信息面板中，与设备的spine形象保持一致 | L5: 配置辅助列 icon编号 | M5: 音效- 设备损坏 设备损坏时 播放的音效 | N5: 音效- 设备受击 设备受击时 播放的音效 | O5: 设备标签 | P5: 标签翻译 | Q5: 设备分类 | R5: 车轮 | S5: 顶部 | T5: 前 | U5: 后 | V5: 前上 | W5: 后上 | X5: prefix | Y5: suffix device main name | Z5: 预制体的 path （配置值是公式生成的，不要手填） dp_xxxxxxxxx_x | AA5: 重量 单位: kg | AB5: 设备 面板 宽度 | AC5: 设备原价 | AD5: 辅助列 价格 基准价格 | AE5: 辅助列 价格 等级梯度 | AF5: 最大 目标数 | AG5: 取消目标所需帧数 当目标超出攻击范围时开始计时 | AH5: 攻击范围 | AI5: 攻击范围 min | AJ5: 攻击范围 max | AK5: 初始 角度 前方 | AL5: 初始 角度 前上 | AM5: 初始 角度 正上 | AN5: 初始 角度 后上 | AO5: 初始 角度 后方 | AP5: 预制体会跟随车体进行旋转 | AQ5: 设备行为脚本 | AR5: 特殊设备伤害 其他设备伤害不放在这里是为了方便在配置表中计算dps | AS5: 近战逻辑 近战设备用。引用melee_logic表id | AT5: 开火逻辑 远程设备用。引用fire_logic表id | AU5: 护盾逻辑 盾牌设备用。引用shield_logic表id | AV5: 钩索逻辑 钩索设备用。引用hook_logic表id | AW5: 撞角逻辑 撞角设备用。引用ram_logic表id | AX5: 其他逻辑 其他设备用。引用other_logic表id | AY5: 旋转速度 单位 = deg/tick 近战: idle~atk 远程: idle~shoot 钩索: 索敌~Null | AZ5: 旋转 速度 1 | BA5: 旋转 速度 2 | BB5: 设备升级选项id | BC5: 设备UI面板的path | BD5: 设备工位 | BE5: 备注
A6: 1210101 | B6: 0 | C6: 硬木车轮 | D6: YH | F6: 99 | G6: wheel_wooden | H6: {=_xlfn.IFS($A6="","",OR($F6=99,$F6=""),_xlfn.TEXTJOIN("_",1,"device_name",$A6,$Y6),TRUE,OFFSET(H6,-1,0))} -> device_name_1210101_wheel_wooden | I6: 平平无奇的木质车轮。 | J6: =_xlfn.LET(_xlpm.get_device_type,VLOOKUP(VALUE(MID(A6,3,1)),tb_device_info_type[#All],3,0),_xlpm.check_if_wheel,IF(LEFT(A6,2)="12","wheel",_xlpm.get_device_type),_xlpm.raw_output,IF($A6<>"",_xlfn.TEXTJOIN("_",1,"device_alt",_xlpm.check_if_wheel),""),IFERROR(_xlpm.raw_output,"information missing")) -> device_alt_wheel | K6: {=_xlfn.IFS($A6="","",Q6="Wheel",_xlfn.CONCAT("dwt","[device_wheel_thumbnail_",IF($L6<>"",$L6,0),"]"),TRUE,_xlfn.CONCAT("dt","[device_thumbnail_",IF($L6<>"",$L6,0),"]"))} -> dwt[device_wheel_thumbnail_0] | L6: 0 | M6: se_ag_device_broken | N6: se_ag_device_be_hit | O6: 1410100 | P6: {=IFERROR(_xlfn.TEXTJOIN(";",1,_xlfn.MAP(_xlfn.TEXTSPLIT(O6,";"),_xlfn.LAMBDA(_xlpm.x,IFERROR(VLOOKUP(VALUE(_xlpm.x),device_tag!A:B,2,0),"error")))),"")} -> 车轮 | Q6: Wheel | R6: 0 | X6: device | Y6: wheel_wooden | Z6: {=_xlfn.IFS($A6="","",OR(F6=99,F6=""),_xlfn.TEXTJOIN("_",1,X6,$A6,Y6),TRUE,OFFSET($Z6,-1,0))} -> device_1210101_wheel_wooden | AA6: 25 | AC6: 9 | AP6: FALSE | AQ6: BasicWheel | BB6: =REPLACE($A6,1,1,6) -> 6210101 | BC6: 无需配置，车轮没有操作面板 | BE6: {=IF(BD6<>"",_xlfn.TEXTJOIN("; ",1,VLOOKUP(VALUE(_xlfn.TEXTSPLIT(BD6,";")),device_cubicles!A:B,2,0)),"")}
A7: 12101011 | B7: 0 | C7: 硬木车轮 Lv.1 | D7: YH | E7: ="Lv."&MOD(F7,100) -> Lv.1 | F7: 101 | G7: wheel_wooden | H7: {=_xlfn.IFS($A7="","",OR($F7=99,$F7=""),_xlfn.TEXTJOIN("_",1,"device_name",$A7,$Y7),TRUE,OFFSET(H7,-1,0))} -> device_name_1210101_wheel_wooden | I7: 平平无奇的木质车轮。 | J7: =_xlfn.LET(_xlpm.get_device_type,VLOOKUP(VALUE(MID(A7,3,1)),tb_device_info_type[#All],3,0),_xlpm.check_if_wheel,IF(LEFT(A7,2)="12","wheel",_xlpm.get_device_type),_xlpm.raw_output,IF($A7<>"",_xlfn.TEXTJOIN("_",1,"device_alt",_xlpm.check_if_wheel),""),IFERROR(_xlpm.raw_output,"information missing")) -> device_alt_wheel | K7: {=_xlfn.IFS($A7="","",Q7="Wheel",_xlfn.CONCAT("dwt","[device_wheel_thumbnail_",IF($L7<>"",$L7,0),"]"),TRUE,_xlfn.CONCAT("dt","[device_thumbnail_",IF($L7<>"",$L7,0),"]"))} -> dwt[device_wheel_thumbnail_0] | L7: 0 | M7: se_ag_device_broken | N7: se_ag_device_be_hit | O7: 1410100 | P7: {=IFERROR(_xlfn.TEXTJOIN(";",1,_xlfn.MAP(_xlfn.TEXTSPLIT(O7,";"),_xlfn.LAMBDA(_xlpm.x,IFERROR(VLOOKUP(VALUE(_xlpm.x),device_tag!A:B,2,0),"error")))),"")} -> 车轮 | Q7: Wheel | R7: 0 | X7: device | Y7: wheel_wooden | Z7: {=_xlfn.IFS($A7="","",OR(F7=99,F7=""),_xlfn.TEXTJOIN("_",1,X7,$A7,Y7),TRUE,OFFSET($Z7,-1,0))} -> device_1210101_wheel_wooden | AA7: 25 | AC7: =ROUND($AD7*$AE7^MOD($F7,100),0) -> 24 | AD7: =9*1.02^MOD(F7,100) -> 9.18 | AE7: =POWER(1.6,2) -> 2.56 | AP7: FALSE | AQ7: BasicWheel | BB7: 1 | BC7: 无需配置，车轮没有操作面板 | BE7: {=IF(BD7<>"",_xlfn.TEXTJOIN("; ",1,VLOOKUP(VALUE(_xlfn.TEXTSPLIT(BD7,";")),device_cubicles!A:B,2,0)),"")}
A8: 12101012 | B8: 0 | C8: 硬木车轮 Lv.2 | D8: YH | E8: ="Lv."&MOD(F8,100) -> Lv.2 | F8: 102 | G8: wheel_wooden | H8: {=_xlfn.IFS($A8="","",OR($F8=99,$F8=""),_xlfn.TEXTJOIN("_",1,"device_name",$A8,$Y8),TRUE,OFFSET(H8,-1,0))} -> device_name_1210101_wheel_wooden | I8: 平平无奇的木质车轮。 | J8: =_xlfn.LET(_xlpm.get_device_type,VLOOKUP(VALUE(MID(A8,3,1)),tb_device_info_type[#All],3,0),_xlpm.check_if_wheel,IF(LEFT(A8,2)="12","wheel",_xlpm.get_device_type),_xlpm.raw_output,IF($A8<>"",_xlfn.TEXTJOIN("_",1,"device_alt",_xlpm.check_if_wheel),""),IFERROR(_xlpm.raw_output,"information missing")) -> device_alt_wheel | K8: {=_xlfn.IFS($A8="","",Q8="Wheel",_xlfn.CONCAT("dwt","[device_wheel_thumbnail_",IF($L8<>"",$L8,0),"]"),TRUE,_xlfn.CONCAT("dt","[device_thumbnail_",IF($L8<>"",$L8,0),"]"))} -> dwt[device_wheel_thumbnail_0] | L8: 0 | M8: se_ag_device_broken | N8: se_ag_device_be_hit | O8: 1410100 | P8: {=IFERROR(_xlfn.TEXTJOIN(";",1,_xlfn.MAP(_xlfn.TEXTSPLIT(O8,";"),_xlfn.LAMBDA(_xlpm.x,IFERROR(VLOOKUP(VALUE(_xlpm.x),device_tag!A:B,2,0),"error")))),"")} -> 车轮 | Q8: Wheel | R8: 0 | X8: device | Y8: wheel_wooden | Z8: {=_xlfn.IFS($A8="","",OR(F8=99,F8=""),_xlfn.TEXTJOIN("_",1,X8,$A8,Y8),TRUE,OFFSET($Z8,-1,0))} -> device_1210101_wheel_wooden | AA8: 25 | AC8: =ROUND($AD8*$AE8^MOD($F8,100),0) -> 61 | AD8: =9*1.02^MOD(F8,100) -> 9.3636 | AE8: =POWER(1.6,2) -> 2.56 | AP8: FALSE | AQ8: BasicWheel | BB8: 1 | BC8: 无需配置，车轮没有操作面板 | BE8: {=IF(BD8<>"",_xlfn.TEXTJOIN("; ",1,VLOOKUP(VALUE(_xlfn.TEXTSPLIT(BD8,";")),device_cubicles!A:B,2,0)),"")}
A9: 12101013 | B9: 0 | C9: 硬木车轮 Lv.3 | D9: YH | E9: ="Lv."&MOD(F9,100) -> Lv.3 | F9: 103 | G9: wheel_wooden | H9: {=_xlfn.IFS($A9="","",OR($F9=99,$F9=""),_xlfn.TEXTJOIN("_",1,"device_name",$A9,$Y9),TRUE,OFFSET(H9,-1,0))} -> device_name_1210101_wheel_wooden | I9: 平平无奇的木质车轮。 | J9: =_xlfn.LET(_xlpm.get_device_type,VLOOKUP(VALUE(MID(A9,3,1)),tb_device_info_type[#All],3,0),_xlpm.check_if_wheel,IF(LEFT(A9,2)="12","wheel",_xlpm.get_device_type),_xlpm.raw_output,IF($A9<>"",_xlfn.TEXTJOIN("_",1,"device_alt",_xlpm.check_if_wheel),""),IFERROR(_xlpm.raw_output,"information missing")) -> device_alt_wheel | K9: {=_xlfn.IFS($A9="","",Q9="Wheel",_xlfn.CONCAT("dwt","[device_wheel_thumbnail_",IF($L9<>"",$L9,0),"]"),TRUE,_xlfn.CONCAT("dt","[device_thumbnail_",IF($L9<>"",$L9,0),"]"))} -> dwt[device_wheel_thumbnail_0] | L9: 0 | M9: se_ag_device_broken | N9: se_ag_device_be_hit | O9: 1410100 | P9: {=IFERROR(_xlfn.TEXTJOIN(";",1,_xlfn.MAP(_xlfn.TEXTSPLIT(O9,";"),_xlfn.LAMBDA(_xlpm.x,IFERROR(VLOOKUP(VALUE(_xlpm.x),device_tag!A:B,2,0),"error")))),"")} -> 车轮 | Q9: Wheel | R9: 0 | X9: device | Y9: wheel_wooden | Z9: {=_xlfn.IFS($A9="","",OR(F9=99,F9=""),_xlfn.TEXTJOIN("_",1,X9,$A9,Y9),TRUE,OFFSET($Z9,-1,0))} -> device_1210101_wheel_wooden | AA9: 25 | AC9: =ROUND($AD9*$AE9^MOD($F9,100),0) -> 160 | AD9: =9*1.02^MOD(F9,100) -> 9.550872 | AE9: =POWER(1.6,2) -> 2.56 | AP9: FALSE | AQ9: BasicWheel | BB9: 1 | BC9: 无需配置，车轮没有操作面板 | BE9: {=IF(BD9<>"",_xlfn.TEXTJOIN("; ",1,VLOOKUP(VALUE(_xlfn.TEXTSPLIT(BD9,";")),device_cubicles!A:B,2,0)),"")}
A10: 12101019 | B10: 0 | C10: 旧木轮 | D10: YH | E10: ="Lv."&MOD(F10,100) -> Lv.0 | F10: 100 | G10: wheel_wooden | H10: device_name_12101019_wheel_wooden | I10: 平平无奇的木质车轮。 | J10: =_xlfn.LET(_xlpm.get_device_type,VLOOKUP(VALUE(MID(A10,3,1)),tb_device_info_type[#All],3,0),_xlpm.check_if_wheel,IF(LEFT(A10,2)="12","wheel",_xlpm.get_device_type),_xlpm.raw_output,IF($A10<>"",_xlfn.TEXTJOIN("_",1,"device_alt",_xlpm.check_if_wheel),""),IFERROR(_xlpm.raw_output,"information missing")) -> device_alt_wheel | K10: {=_xlfn.IFS($A10="","",Q10="Wheel",_xlfn.CONCAT("dwt","[device_wheel_thumbnail_",IF($L10<>"",$L10,0),"]"),TRUE,_xlfn.CONCAT("dt","[device_thumbnail_",IF($L10<>"",$L10,0),"]"))} -> dwt[device_wheel_thumbnail_0] | L10: 0 | M10: se_ag_device_broken | N10: se_ag_device_be_hit | O10: 1410100 | P10: {=IFERROR(_xlfn.TEXTJOIN(";",1,_xlfn.MAP(_xlfn.TEXTSPLIT(O10,";"),_xlfn.LAMBDA(_xlpm.x,IFERROR(VLOOKUP(VALUE(_xlpm.x),device_tag!A:B,2,0),"error")))),"")} -> 车轮 | Q10: Wheel | R10: 0 | X10: device | Y10: wheel_wooden | Z10: {=_xlfn.IFS($A10="","",OR(F10=99,F10=""),_xlfn.TEXTJOIN("_",1,X10,$A10,Y10),TRUE,OFFSET($Z10,-1,0))} -> device_1210101_wheel_wooden | AA10: 25 | AC10: =ROUND($AD10*$AE10^MOD($F10,100),0) -> 5 | AD10: 5 | AE10: =POWER(1.6,2) -> 2.56 | AP10: FALSE | AQ10: BasicWheel | BB10: 1 | BC10: 无需配置，车轮没有操作面板 | BE10: {=IF(BD10<>"",_xlfn.TEXTJOIN("; ",1,VLOOKUP(VALUE(_xlfn.TEXTSPLIT(BD10,";")),device_cubicles!A:B,2,0)),"")}
A11: 1210102 | B11: 0 | C11: 履带 | D11: YH | F11: 99 | G11: wheel_track | H11: {=_xlfn.IFS($A11="","",OR($F11=99,$F11=""),_xlfn.TEXTJOIN("_",1,"device_name",$A11,$Y11),TRUE,OFFSET(H11,-1,0))} -> device_name_1210102_wheel_track | I11: 笨重，但通过性极佳。碾碎一切弱小的敌人。 | J11: =_xlfn.LET(_xlpm.get_device_type,VLOOKUP(VALUE(MID(A11,3,1)),tb_device_info_type[#All],3,0),_xlpm.check_if_wheel,IF(LEFT(A11,2)="12","wheel",_xlpm.get_device_type),_xlpm.raw_output,IF($A11<>"",_xlfn.TEXTJOIN("_",1,"device_alt",_xlpm.check_if_wheel),""),IFERROR(_xlpm.raw_output,"information missing")) -> device_alt_wheel | K11: {=_xlfn.IFS($A11="","",Q11="Wheel",_xlfn.CONCAT("dwt","[device_wheel_thumbnail_",IF($L11<>"",$L11,0),"]"),TRUE,_xlfn.CONCAT("dt","[device_thumbnail_",IF($L11<>"",$L11,0),"]"))} -> dwt[device_wheel_thumbnail_1] | L11: 1 | M11: se_ag_device_broken | N11: se_ag_device_be_hit | O11: 1410100 | P11: {=IFERROR(_xlfn.TEXTJOIN(";",1,_xlfn.MAP(_xlfn.TEXTSPLIT(O11,";"),_xlfn.LAMBDA(_xlpm.x,IFERROR(VLOOKUP(VALUE(_xlpm.x),device_tag!A:B,2,0),"error")))),"")} -> 车轮 | Q11: Wheel | R11: 0 | X11: device | Y11: wheel_track | Z11: {=_xlfn.IFS($A11="","",OR(F11=99,F11=""),_xlfn.TEXTJOIN("_",1,X11,$A11,Y11),TRUE,OFFSET($Z11,-1,0))} -> device_1210102_wheel_track | AA11: 735 | AC11: 14 | AP11: TRUE | AQ11: Wheel_Track | BB11: =REPLACE($A11,1,1,6) -> 6210102 | BC11: 无需配置，车轮没有操作面板 | BE11: {=IF(BD11<>"",_xlfn.TEXTJOIN("; ",1,VLOOKUP(VALUE(_xlfn.TEXTSPLIT(BD11,";")),device_cubicles!A:B,2,0)),"")}
A12: 12101022 | B12: 0 | C12: 履带 Lv.2 | D12: YH | E12: ="Lv."&MOD(F12,100) -> Lv.2 | F12: 102 | G12: wheel_track | H12: {=_xlfn.IFS($A12="","",OR($F12=99,$F12=""),_xlfn.TEXTJOIN("_",1,"device_name",$A12,$Y12),TRUE,OFFSET(H12,-1,0))} -> device_name_1210102_wheel_track | I12: 笨重，但通过性极佳。碾碎一切弱小的敌人。 | J12: =_xlfn.LET(_xlpm.get_device_type,VLOOKUP(VALUE(MID(A12,3,1)),tb_device_info_type[#All],3,0),_xlpm.check_if_wheel,IF(LEFT(A12,2)="12","wheel",_xlpm.get_device_type),_xlpm.raw_output,IF($A12<>"",_xlfn.TEXTJOIN("_",1,"device_alt",_xlpm.check_if_wheel),""),IFERROR(_xlpm.raw_output,"information missing")) -> device_alt_wheel | K12: {=_xlfn.IFS($A12="","",Q12="Wheel",_xlfn.CONCAT("dwt","[device_wheel_thumbnail_",IF($L12<>"",$L12,0),"]"),TRUE,_xlfn.CONCAT("dt","[device_thumbnail_",IF($L12<>"",$L12,0),"]"))} -> dwt[device_wheel_thumbnail_1] | L12: 1 | M12: se_ag_device_broken | N12: se_ag_device_be_hit | O12: 1410100 | P12: {=IFERROR(_xlfn.TEXTJOIN(";",1,_xlfn.MAP(_xlfn.TEXTSPLIT(O12,";"),_xlfn.LAMBDA(_xlpm.x,IFERROR(VLOOKUP(VALUE(_xlpm.x),device_tag!A:B,2,0),"error")))),"")} -> 车轮 | Q12: Wheel | R12: 0 | X12: device | Y12: wheel_track | Z12: {=_xlfn.IFS($A12="","",OR(F12=99,F12=""),_xlfn.TEXTJOIN("_",1,X12,$A12,Y12),TRUE,OFFSET($Z12,-1,0))} -> device_1210102_wheel_track | AA12: 735 | AC12: =ROUND($AD12*$AE12^MOD($F12,100),0) -> 75 | AD12: =12*0.975^MOD(F12,100) -> 11.4075 | AE12: =POWER(1.6,2) -> 2.56 | AP12: TRUE | AQ12: Wheel_Track | BB12: 1 | BC12: 无需配置，车轮没有操作面板 | BE12: {=IF(BD12<>"",_xlfn.TEXTJOIN("; ",1,VLOOKUP(VALUE(_xlfn.TEXTSPLIT(BD12,";")),device_cubicles!A:B,2,0)),"")}
A13: 12101023 | B13: 0 | C13: 履带 Lv.3 | D13: YH | E13: ="Lv."&MOD(F13,100) -> Lv.3 | F13: 103 | G13: wheel_track | H13: {=_xlfn.IFS($A13="","",OR($F13=99,$F13=""),_xlfn.TEXTJOIN("_",1,"device_name",$A13,$Y13),TRUE,OFFSET(H13,-1,0))} -> device_name_1210102_wheel_track | I13: 笨重，但通过性极佳。碾碎一切弱小的敌人。 | J13: =_xlfn.LET(_xlpm.get_device_type,VLOOKUP(VALUE(MID(A13,3,1)),tb_device_info_type[#All],3,0),_xlpm.check_if_wheel,IF(LEFT(A13,2)="12","wheel",_xlpm.get_device_type),_xlpm.raw_output,IF($A13<>"",_xlfn.TEXTJOIN("_",1,"device_alt",_xlpm.check_if_wheel),""),IFERROR(_xlpm.raw_output,"information missing")) -> device_alt_wheel | K13: {=_xlfn.IFS($A13="","",Q13="Wheel",_xlfn.CONCAT("dwt","[device_wheel_thumbnail_",IF($L13<>"",$L13,0),"]"),TRUE,_xlfn.CONCAT("dt","[device_thumbnail_",IF($L13<>"",$L13,0),"]"))} -> dwt[device_wheel_thumbnail_1] | L13: 1 | M13: se_ag_device_broken | N13: se_ag_device_be_hit | O13: 1410100 | P13: {=IFERROR(_xlfn.TEXTJOIN(";",1,_xlfn.MAP(_xlfn.TEXTSPLIT(O13,";"),_xlfn.LAMBDA(_xlpm.x,IFERROR(VLOOKUP(VALUE(_xlpm.x),device_tag!A:B,2,0),"error")))),"")} -> 车轮 | Q13: Wheel | R13: 0 | X13: device | Y13: wheel_track | Z13: {=_xlfn.IFS($A13="","",OR(F13=99,F13=""),_xlfn.TEXTJOIN("_",1,X13,$A13,Y13),TRUE,OFFSET($Z13,-1,0))} -> device_1210102_wheel_track | AA13: 735 | AC13: =ROUND($AD13*$AE13^MOD($F13,100),0) -> 187 | AD13: =12*0.975^MOD(F13,100) -> 11.122312 | AE13: =POWER(1.6,2) -> 2.56 | AP13: TRUE | AQ13: Wheel_Track | BB13: 1 | BC13: 无需配置，车轮没有操作面板 | BE13: {=IF(BD13<>"",_xlfn.TEXTJOIN("; ",1,VLOOKUP(VALUE(_xlfn.TEXTSPLIT(BD13,";")),device_cubicles!A:B,2,0)),"")}
A14: 12101024 | B14: 0 | C14: 履带 Lv.4 | D14: YH | E14: ="Lv."&MOD(F14,100) -> Lv.4 | F14: 104 | G14: wheel_track | H14: {=_xlfn.IFS($A14="","",OR($F14=99,$F14=""),_xlfn.TEXTJOIN("_",1,"device_name",$A14,$Y14),TRUE,OFFSET(H14,-1,0))} -> device_name_1210102_wheel_track | I14: 笨重，但通过性极佳。碾碎一切弱小的敌人。 | J14: =_xlfn.LET(_xlpm.get_device_type,VLOOKUP(VALUE(MID(A14,3,1)),tb_device_info_type[#All],3,0),_xlpm.check_if_wheel,IF(LEFT(A14,2)="12","wheel",_xlpm.get_device_type),_xlpm.raw_output,IF($A14<>"",_xlfn.TEXTJOIN("_",1,"device_alt",_xlpm.check_if_wheel),""),IFERROR(_xlpm.raw_output,"information missing")) -> device_alt_wheel | K14: {=_xlfn.IFS($A14="","",Q14="Wheel",_xlfn.CONCAT("dwt","[device_wheel_thumbnail_",IF($L14<>"",$L14,0),"]"),TRUE,_xlfn.CONCAT("dt","[device_thumbnail_",IF($L14<>"",$L14,0),"]"))} -> dwt[device_wheel_thumbnail_1] | L14: 1 | M14: se_ag_device_broken | N14: se_ag_device_be_hit | O14: 1410100 | P14: {=IFERROR(_xlfn.TEXTJOIN(";",1,_xlfn.MAP(_xlfn.TEXTSPLIT(O14,";"),_xlfn.LAMBDA(_xlpm.x,IFERROR(VLOOKUP(VALUE(_xlpm.x),device_tag!A:B,2,0),"error")))),"")} -> 车轮 | Q14: Wheel | R14: 0 | X14: device | Y14: wheel_track | Z14: {=_xlfn.IFS($A14="","",OR(F14=99,F14=""),_xlfn.TEXTJOIN("_",1,X14,$A14,Y14),TRUE,OFFSET($Z14,-1,0))} -> device_1210102_wheel_track | AA14: 735 | AC14: =ROUND($AD14*$AE14^MOD($F14,100),0) -> 466 | AD14: =12*0.975^MOD(F14,100) -> 10.844255 | AE14: =POWER(1.6,2) -> 2.56 | AP14: TRUE | AQ14: Wheel_Track | BB14: 1 | BC14: 无需配置，车轮没有操作面板 | BE14: {=IF(BD14<>"",_xlfn.TEXTJOIN("; ",1,VLOOKUP(VALUE(_xlfn.TEXTSPLIT(BD14,";")),device_cubicles!A:B,2,0)),"")}
A15: 1211801 | B15: 0 | C15: 救生圈 | D15: YH | F15: 99 | G15: wheel_lifebuoy | H15: {=_xlfn.IFS($A15="","",OR($F15=99,$F15=""),_xlfn.TEXTJOIN("_",1,"device_name",$A15,$Y15),TRUE,OFFSET(H15,-1,0))} -> device_name_1211801_wheel_lifebuoy | I15: 动力强劲又灵活，但总是会不受控地弹起… | J15: =_xlfn.LET(_xlpm.get_device_type,VLOOKUP(VALUE(MID(A15,3,1)),tb_device_info_type[#All],3,0),_xlpm.check_if_wheel,IF(LEFT(A15,2)="12","wheel",_xlpm.get_device_type),_xlpm.raw_output,IF($A15<>"",_xlfn.TEXTJOIN("_",1,"device_alt",_xlpm.check_if_wheel),""),IFERROR(_xlpm.raw_output,"information missing")) -> device_alt_wheel | K15: {=_xlfn.IFS($A15="","",Q15="Wheel",_xlfn.CONCAT("dwt","[device_wheel_thumbnail_",IF($L15<>"",$L15,0),"]"),TRUE,_xlfn.CONCAT("dt","[device_thumbnail_",IF($L15<>"",$L15,0),"]"))} -> dwt[device_wheel_thumbnail_3] | L15: 3 | M15: se_ag_device_broken | N15: se_ag_device_be_hit | O15: 1410100 | P15: {=IFERROR(_xlfn.TEXTJOIN(";",1,_xlfn.MAP(_xlfn.TEXTSPLIT(O15,";"),_xlfn.LAMBDA(_xlpm.x,IFERROR(VLOOKUP(VALUE(_xlpm.x),device_tag!A:B,2,0),"error")))),"")} -> 车轮 | Q15: Wheel | R15: 0 | X15: device | Y15: wheel_lifebuoy | Z15: {=_xlfn.IFS($A15="","",OR(F15=99,F15=""),_xlfn.TEXTJOIN("_",1,X15,$A15,Y15),TRUE,OFFSET($Z15,-1,0))} -> device_1211801_wheel_lifebuoy | AA15: 5 | AB15: 0 | AC15: 12 | AP15: FALSE | AQ15: BasicWheel | BB15: 1 | BC15: BasicWheel_Panel | BE15: {=IF(BD15<>"",_xlfn.TEXTJOIN("; ",1,VLOOKUP(VALUE(_xlfn.TEXTSPLIT(BD15,";")),device_cubicles!A:B,2,0)),"")}
A16: 120000002 | B16: 0 | C16: 笨重石轮 | H16: {=_xlfn.IFS($A16="","",OR($F16=99,$F16=""),_xlfn.TEXTJOIN("_",1,"device_name",$A16,$Y16),TRUE,OFFSET(H16,-1,0))} -> device_name_120000002_wheel_stone | J16: =_xlfn.LET(_xlpm.get_device_type,VLOOKUP(VALUE(MID(A16,3,1)),tb_device_info_type[#All],3,0),_xlpm.check_if_wheel,IF(LEFT(A16,2)="12","wheel",_xlpm.get_device_type),_xlpm.raw_output,IF($A16<>"",_xlfn.TEXTJOIN("_",1,"device_alt",_xlpm.check_if_wheel),""),IFERROR(_xlpm.raw_output,"information missing")) -> device_alt_wheel | K16: {=_xlfn.IFS($A16="","",Q16="Wheel",_xlfn.CONCAT("dwt","[device_wheel_thumbnail_",IF($L16<>"",$L16,0),"]"),TRUE,_xlfn.CONCAT("dt","[device_thumbnail_",IF($L16<>"",$L16,0),"]"))} -> dwt[device_wheel_thumbnail_3] | L16: 3 | M16: se_ag_device_broken | N16: se_ag_device_be_hit | P16: {=IFERROR(_xlfn.TEXTJOIN(";",1,_xlfn.MAP(_xlfn.TEXTSPLIT(O16,";"),_xlfn.LAMBDA(_xlpm.x,IFERROR(VLOOKUP(VALUE(_xlpm.x),device_tag!A:B,2,0),"error")))),"")} | Q16: Wheel | R16: 0 | X16: dp | Y16: wheel_stone | Z16: {=_xlfn.IFS($A16="","",OR(F16=99,F16=""),_xlfn.TEXTJOIN("_",1,X16,$A16,Y16),TRUE,OFFSET($Z16,-1,0))} -> dp_120000002_wheel_stone | AA16: 100 | AB16: 0 | BC16: Base_Device_Panel | BE16: {=IF(BD16<>"",_xlfn.TEXTJOIN("; ",1,VLOOKUP(VALUE(_xlfn.TEXTSPLIT(BD16,";")),device_cubicles!A:B,2,0)),"")}
A17: 120000003 | B17: 0 | C17: 坚固铁轮 | H17: {=_xlfn.IFS($A17="","",OR($F17=99,$F17=""),_xlfn.TEXTJOIN("_",1,"device_name",$A17,$Y17),TRUE,OFFSET(H17,-1,0))} -> device_name_120000003_wheel_iron | J17: =_xlfn.LET(_xlpm.get_device_type,VLOOKUP(VALUE(MID(A17,3,1)),tb_device_info_type[#All],3,0),_xlpm.check_if_wheel,IF(LEFT(A17,2)="12","wheel",_xlpm.get_device_type),_xlpm.raw_output,IF($A17<>"",_xlfn.TEXTJOIN("_",1,"device_alt",_xlpm.check_if_wheel),""),IFERROR(_xlpm.raw_output,"information missing")) -> device_alt_wheel | K17: {=_xlfn.IFS($A17="","",Q17="Wheel",_xlfn.CONCAT("dwt","[device_wheel_thumbnail_",IF($L17<>"",$L17,0),"]"),TRUE,_xlfn.CONCAT("dt","[device_thumbnail_",IF($L17<>"",$L17,0),"]"))} -> dwt[device_wheel_thumbnail_3] | L17: 3 | M17: se_ag_device_broken | N17: se_ag_device_be_hit | P17: {=IFERROR(_xlfn.TEXTJOIN(";",1,_xlfn.MAP(_xlfn.TEXTSPLIT(O17,";"),_xlfn.LAMBDA(_xlpm.x,IFERROR(VLOOKUP(VALUE(_xlpm.x),device_tag!A:B,2,0),"error")))),"")} | Q17: Wheel | R17: 0 | X17: dp | Y17: wheel_iron | Z17: {=_xlfn.IFS($A17="","",OR(F17=99,F17=""),_xlfn.TEXTJOIN("_",1,X17,$A17,Y17),TRUE,OFFSET($Z17,-1,0))} -> dp_120000003_wheel_iron | AA17: 250 | AB17: 0 | BC17: Base_Device_Panel | BE17: {=IF(BD17<>"",_xlfn.TEXTJOIN("; ",1,VLOOKUP(VALUE(_xlfn.TEXTSPLIT(BD17,";")),device_cubicles!A:B,2,0)),"")}
A18: 120000004 | B18: 0 | C18: 凝胶车轮 | H18: {=_xlfn.IFS($A18="","",OR($F18=99,$F18=""),_xlfn.TEXTJOIN("_",1,"device_name",$A18,$Y18),TRUE,OFFSET(H18,-1,0))} -> device_name_120000004_wheel_gem | J18: =_xlfn.LET(_xlpm.get_device_type,VLOOKUP(VALUE(MID(A18,3,1)),tb_device_info_type[#All],3,0),_xlpm.check_if_wheel,IF(LEFT(A18,2)="12","wheel",_xlpm.get_device_type),_xlpm.raw_output,IF($A18<>"",_xlfn.TEXTJOIN("_",1,"device_alt",_xlpm.check_if_wheel),""),IFERROR(_xlpm.raw_output,"information missing")) -> device_alt_wheel | K18: {=_xlfn.IFS($A18="","",Q18="Wheel",_xlfn.CONCAT("dwt","[device_wheel_thumbnail_",IF($L18<>"",$L18,0),"]"),TRUE,_xlfn.CONCAT("dt","[device_thumbnail_",IF($L18<>"",$L18,0),"]"))} -> dwt[device_wheel_thumbnail_3] | L18: 3 | M18: se_ag_device_broken | N18: se_ag_device_be_hit | P18: {=IFERROR(_xlfn.TEXTJOIN(";",1,_xlfn.MAP(_xlfn.TEXTSPLIT(O18,";"),_xlfn.LAMBDA(_xlpm.x,IFERROR(VLOOKUP(VALUE(_xlpm.x),device_tag!A:B,2,0),"error")))),"")} | Q18: Wheel | R18: 0 | X18: dp | Y18: wheel_gem | Z18: {=_xlfn.IFS($A18="","",OR(F18=99,F18=""),_xlfn.TEXTJOIN("_",1,X18,$A18,Y18),TRUE,OFFSET($Z18,-1,0))} -> dp_120000004_wheel_gem | AA18: 50 | AB18: 0 | BC18: Base_Device_Panel | BE18: {=IF(BD18<>"",_xlfn.TEXTJOIN("; ",1,VLOOKUP(VALUE(_xlfn.TEXTSPLIT(BD18,";")),device_cubicles!A:B,2,0)),"")}
A19: 120000006 | B19: 0 | C19: 废弃轮胎 | H19: {=_xlfn.IFS($A19="","",OR($F19=99,$F19=""),_xlfn.TEXTJOIN("_",1,"device_name",$A19,$Y19),TRUE,OFFSET(H19,-1,0))} -> device_name_120000006_wheel_tyre | J19: =_xlfn.LET(_xlpm.get_device_type,VLOOKUP(VALUE(MID(A19,3,1)),tb_device_info_type[#All],3,0),_xlpm.check_if_wheel,IF(LEFT(A19,2)="12","wheel",_xlpm.get_device_type),_xlpm.raw_output,IF($A19<>"",_xlfn.TEXTJOIN("_",1,"device_alt",_xlpm.check_if_wheel),""),IFERROR(_xlpm.raw_output,"information missing")) -> device_alt_wheel | K19: {=_xlfn.IFS($A19="","",Q19="Wheel",_xlfn.CONCAT("dwt","[device_wheel_thumbnail_",IF($L19<>"",$L19,0),"]"),TRUE,_xlfn.CONCAT("dt","[device_thumbnail_",IF($L19<>"",$L19,0),"]"))} -> dwt[device_wheel_thumbnail_3] | L19: 3 | M19: se_ag_device_broken | N19: se_ag_device_be_hit | P19: {=IFERROR(_xlfn.TEXTJOIN(";",1,_xlfn.MAP(_xlfn.TEXTSPLIT(O19,";"),_xlfn.LAMBDA(_xlpm.x,IFERROR(VLOOKUP(VALUE(_xlpm.x),device_tag!A:B,2,0),"error")))),"")} | Q19: Wheel | R19: 0 | X19: dp | Y19: wheel_tyre | Z19: {=_xlfn.IFS($A19="","",OR(F19=99,F19=""),_xlfn.TEXTJOIN("_",1,X19,$A19,Y19),TRUE,OFFSET($Z19,-1,0))} -> dp_120000006_wheel_tyre | AA19: 100 | AB19: 0 | BC19: Base_Device_Panel | BE19: {=IF(BD19<>"",_xlfn.TEXTJOIN("; ",1,VLOOKUP(VALUE(_xlfn.TEXTSPLIT(BD19,";")),device_cubicles!A:B,2,0)),"")}
A20: 120000007 | B20: 0 | C20: 推进车轮 | G20: wheel_wooden | H20: {=_xlfn.IFS($A20="","",OR($F20=99,$F20=""),_xlfn.TEXTJOIN("_",1,"device_name",$A20,$Y20),TRUE,OFFSET(H20,-1,0))} -> device_name_120000007_wheel_wooden | J20: =_xlfn.LET(_xlpm.get_device_type,VLOOKUP(VALUE(MID(A20,3,1)),tb_device_info_type[#All],3,0),_xlpm.check_if_wheel,IF(LEFT(A20,2)="12","wheel",_xlpm.get_device_type),_xlpm.raw_output,IF($A20<>"",_xlfn.TEXTJOIN("_",1,"device_alt",_xlpm.check_if_wheel),""),IFERROR(_xlpm.raw_output,"information missing")) -> device_alt_wheel | K20: {=_xlfn.IFS($A20="","",Q20="Wheel",_xlfn.CONCAT("dwt","[device_wheel_thumbnail_",IF($L20<>"",$L20,0),"]"),TRUE,_xlfn.CONCAT("dt","[device_thumbnail_",IF($L20<>"",$L20,0),"]"))} -> dwt[device_wheel_thumbnail_3] | L20: 3 | M20: se_ag_device_broken | N20: se_ag_device_be_hit | O20: 1410100 | P20: {=IFERROR(_xlfn.TEXTJOIN(";",1,_xlfn.MAP(_xlfn.TEXTSPLIT(O20,";"),_xlfn.LAMBDA(_xlpm.x,IFERROR(VLOOKUP(VALUE(_xlpm.x),device_tag!A:B,2,0),"error")))),"")} -> 车轮 | Q20: Wheel | R20: 0 | X20: device | Y20: wheel_wooden | Z20: {=_xlfn.IFS($A20="","",OR(F20=99,F20=""),_xlfn.TEXTJOIN("_",1,X20,$A20,Y20),TRUE,OFFSET($Z20,-1,0))} -> device_120000007_wheel_wooden | AA20: 25 | AB20: 0 | AP20: FALSE | AQ20: JetWheel | BB20: 1 | BC20: JetWheel_Panel | BE20: {=IF(BD20<>"",_xlfn.TEXTJOIN("; ",1,VLOOKUP(VALUE(_xlfn.TEXTSPLIT(BD20,";")),device_cubicles!A:B,2,0)),"")}
A21: 120000008 | B21: 0 | C21: 喷火车轮 | D21: YH | G21: fire_wheel | H21: {=_xlfn.IFS($A21="","",OR($F21=99,$F21=""),_xlfn.TEXTJOIN("_",1,"device_name",$A21,$Y21),TRUE,OFFSET(H21,-1,0))} -> device_name_120000008_fire_wheel | J21: =_xlfn.LET(_xlpm.get_device_type,VLOOKUP(VALUE(MID(A21,3,1)),tb_device_info_type[#All],3,0),_xlpm.check_if_wheel,IF(LEFT(A21,2)="12","wheel",_xlpm.get_device_type),_xlpm.raw_output,IF($A21<>"",_xlfn.TEXTJOIN("_",1,"device_alt",_xlpm.check_if_wheel),""),IFERROR(_xlpm.raw_output,"information missing")) -> device_alt_wheel | K21: {=_xlfn.IFS($A21="","",Q21="Wheel",_xlfn.CONCAT("dwt","[device_wheel_thumbnail_",IF($L21<>"",$L21,0),"]"),TRUE,_xlfn.CONCAT("dt","[device_thumbnail_",IF($L21<>"",$L21,0),"]"))} -> dwt[device_wheel_thumbnail_3] | L21: 3 | M21: se_ag_device_broken | N21: se_ag_device_be_hit | O21: 1410100 | P21: {=IFERROR(_xlfn.TEXTJOIN(";",1,_xlfn.MAP(_xlfn.TEXTSPLIT(O21,";"),_xlfn.LAMBDA(_xlpm.x,IFERROR(VLOOKUP(VALUE(_xlpm.x),device_tag!A:B,2,0),"error")))),"")} -> 车轮 | Q21: Wheel | R21: 0 | X21: device | Y21: fire_wheel | Z21: {=_xlfn.IFS($A21="","",OR(F21=99,F21=""),_xlfn.TEXTJOIN("_",1,X21,$A21,Y21),TRUE,OFFSET($Z21,-1,0))} -> device_120000008_fire_wheel | AA21: 25 | AB21: 0 | AP21: FALSE | AQ21: FireWheel | BB21: 1 | BC21: BasicWheel_Panel | BE21: {=IF(BD21<>"",_xlfn.TEXTJOIN("; ",1,VLOOKUP(VALUE(_xlfn.TEXTSPLIT(BD21,";")),device_cubicles!A:B,2,0)),"")}
J22: =_xlfn.LET(_xlpm.get_device_type,VLOOKUP(VALUE(MID(A22,3,1)),tb_device_info_type[#All],3,0),_xlpm.check_if_wheel,IF(LEFT(A22,2)="12","wheel",_xlpm.get_device_type),_xlpm.raw_output,IF($A22<>"",_xlfn.TEXTJOIN("_",1,"device_alt",_xlpm.check_if_wheel),""),IFERROR(_xlpm.raw_output,"information missing")) | K22: {=_xlfn.IFS($A22="","",ISTEXT($L22),_xlfn.CONCAT("dwt","[device_wheel_thumbnail_",RIGHT($A22,1)-1,"]"),TRUE,_xlfn.CONCAT("dt","[device_thumbnail_",IF($L22<>"",$L22,0),"]"))} | P22: {=IFERROR(_xlfn.TEXTJOIN(";",1,_xlfn.MAP(_xlfn.TEXTSPLIT(O22,";"),_xlfn.LAMBDA(_xlpm.x,IFERROR(VLOOKUP(VALUE(_xlpm.x),device_tag!A:B,2,0),"error")))),"")} | Z22: {=_xlfn.IFS($A22="","",OR(F22<0,F22=""),_xlfn.TEXTJOIN("_",1,X22,$A22,Y22),TRUE,OFFSET($Z22,-1,0))} | BE22: {=IF(BD22<>"",_xlfn.TEXTJOIN("; ",1,VLOOKUP(VALUE(_xlfn.TEXTSPLIT(BD22,";")),device_cubicles!A:B,2,0)),"")}
A23: 1310101 | B23: 0 | C23: 短匕 | D23: YH | G23: device_dagger | H23: {=_xlfn.IFS($A23="","",OR($F23=99,$F23=""),_xlfn.TEXTJOIN("_",1,"device_name",$A23,$Y23),TRUE,OFFSET(H23,-1,0))} -> device_name_1310101_dagger | J23: =_xlfn.LET(_xlpm.get_device_type,VLOOKUP(VALUE(MID(A23,3,1)),tb_device_info_type[#All],3,0),_xlpm.check_if_wheel,IF(LEFT(A23,2)="12","wheel",_xlpm.get_device_type),_xlpm.raw_output,IF($A23<>"",_xlfn.TEXTJOIN("_",1,"device_alt",_xlpm.check_if_wheel),""),IFERROR(_xlpm.raw_output,"information missing")) -> device_alt_melee | K23: {=_xlfn.IFS($A23="","",ISTEXT($L23),_xlfn.CONCAT("dwt","[device_wheel_thumbnail_",RIGHT($A23,1)-1,"]"),TRUE,_xlfn.CONCAT("dt","[device_thumbnail_",IF($L23<>"",$L23,0),"]"))} -> dt[device_thumbnail_8] | L23: 8 | M23: se_ag_device_broken | N23: se_ag_device_be_hit | O23: 1420100;1420101 | P23: {=IFERROR(_xlfn.TEXTJOIN(";",1,_xlfn.MAP(_xlfn.TEXTSPLIT(O23,";"),_xlfn.LAMBDA(_xlpm.x,IFERROR(VLOOKUP(VALUE(_xlpm.x),device_tag!A:B,2,0),"error")))),"")} -> 近战武器;刀剑 | Q23: Common | T23: 0 | U23: 1 | V23: 0 | W23: 1 | X23: device | Y23: dagger | Z23: {=_xlfn.IFS($A23="","",OR(F23=99,F23=""),_xlfn.TEXTJOIN("_",1,X23,$A23,Y23),TRUE,OFFSET($Z23,-1,0))} -> device_1310101_dagger | AA23: 2 | AB23: 1 | AC23: 9 | AF23: 1 | AG23: 0 | AH23: =_xlfn.TEXTJOIN("~",1,AI23:AJ23) -> 0~2.5 | AI23: 0 | AJ23: 2.5 | AK23: 0 | AL23: 0 | AM23: 0 | AN23: 0 | AO23: 0 | AP23: TRUE | AQ23: BasicMelee_Click | AS23: =$A23 -> 1310101 | AY23: =_xlfn.TEXTJOIN("~",1,AZ23:BA23) -> 10~2.5 | AZ23: 10 | BA23: 2.5 | BB23: =REPLACE($A23,1,1,6) -> 6310101 | BC23: DevicePanel_Click_Melee | BD23: 201;301 | BE23: {=IF(BD23<>"",_xlfn.TEXTJOIN("; ",1,VLOOKUP(VALUE(_xlfn.TEXTSPLIT(BD23,";")),device_cubicles!A:B,2,0)),"")} -> 近战攻击; 磨砺刀刃
A24: 1310102 | B24: 0 | C24: 砍刀 | D24: YH | G24: device_machete | H24: {=_xlfn.IFS($A24="","",OR($F24=99,$F24=""),_xlfn.TEXTJOIN("_",1,"device_name",$A24,$Y24),TRUE,OFFSET(H24,-1,0))} -> device_name_1310102_machete | J24: =_xlfn.LET(_xlpm.get_device_type,VLOOKUP(VALUE(MID(A24,3,1)),tb_device_info_type[#All],3,0),_xlpm.check_if_wheel,IF(LEFT(A24,2)="12","wheel",_xlpm.get_device_type),_xlpm.raw_output,IF($A24<>"",_xlfn.TEXTJOIN("_",1,"device_alt",_xlpm.check_if_wheel),""),IFERROR(_xlpm.raw_output,"information missing")) -> device_alt_melee | K24: {=_xlfn.IFS($A24="","",ISTEXT($L24),_xlfn.CONCAT("dwt","[device_wheel_thumbnail_",RIGHT($A24,1)-1,"]"),TRUE,_xlfn.CONCAT("dt","[device_thumbnail_",IF($L24<>"",$L24,0),"]"))} -> dt[device_thumbnail_15] | L24: 15 | M24: se_ag_device_broken | N24: se_ag_device_be_hit | O24: 1420100;1420101 | P24: {=IFERROR(_xlfn.TEXTJOIN(";",1,_xlfn.MAP(_xlfn.TEXTSPLIT(O24,";"),_xlfn.LAMBDA(_xlpm.x,IFERROR(VLOOKUP(VALUE(_xlpm.x),device_tag!A:B,2,0),"error")))),"")} -> 近战武器;刀剑 | Q24: Common | T24: 0 | U24: 1 | V24: 0 | W24: 1 | X24: device | Y24: machete | Z24: {=_xlfn.IFS($A24="","",OR(F24=99,F24=""),_xlfn.TEXTJOIN("_",1,X24,$A24,Y24),TRUE,OFFSET($Z24,-1,0))} -> device_1310102_machete | AA24: 5 | AB24: 1 | AC24: 11 | AF24: 1 | AG24: 0 | AH24: =_xlfn.TEXTJOIN("~",1,AI24:AJ24) -> 0~2.8 | AI24: 0 | AJ24: 2.8 | AK24: 0 | AL24: 0 | AM24: 0 | AN24: 0 | AO24: 0 | AP24: TRUE | AQ24: BasicMelee_Click | AS24: =$A24 -> 1310102 | AY24: =_xlfn.TEXTJOIN("~",1,AZ24:BA24) -> 7~0.2 | AZ24: 7 | BA24: 0.2 | BB24: =REPLACE($A24,1,1,6) -> 6310102 | BC24: DevicePanel_Click_Melee_Resharpenable_Machete | BD24: 201;301 | BE24: {=IF(BD24<>"",_xlfn.TEXTJOIN("; ",1,VLOOKUP(VALUE(_xlfn.TEXTSPLIT(BD24,";")),device_cubicles!A:B,2,0)),"")} -> 近战攻击; 磨砺刀刃
A25: 1310103 | B25: 0 | C25: 大剑 | D25: YH | G25: device_claymore | H25: {=_xlfn.IFS($A25="","",OR($F25=99,$F25=""),_xlfn.TEXTJOIN("_",1,"device_name",$A25,$Y25),TRUE,OFFSET(H25,-1,0))} -> device_name_1310103_claymore | J25: =_xlfn.LET(_xlpm.get_device_type,VLOOKUP(VALUE(MID(A25,3,1)),tb_device_info_type[#All],3,0),_xlpm.check_if_wheel,IF(LEFT(A25,2)="12","wheel",_xlpm.get_device_type),_xlpm.raw_output,IF($A25<>"",_xlfn.TEXTJOIN("_",1,"device_alt",_xlpm.check_if_wheel),""),IFERROR(_xlpm.raw_output,"information missing")) -> device_alt_melee | K25: {=_xlfn.IFS($A25="","",ISTEXT($L25),_xlfn.CONCAT("dwt","[device_wheel_thumbnail_",RIGHT($A25,1)-1,"]"),TRUE,_xlfn.CONCAT("dt","[device_thumbnail_",IF($L25<>"",$L25,0),"]"))} -> dt[device_thumbnail_7] | L25: 7 | M25: se_ag_device_broken | N25: se_ag_device_be_hit | O25: 1420100;1420101 | P25: {=IFERROR(_xlfn.TEXTJOIN(";",1,_xlfn.MAP(_xlfn.TEXTSPLIT(O25,";"),_xlfn.LAMBDA(_xlpm.x,IFERROR(VLOOKUP(VALUE(_xlpm.x),device_tag!A:B,2,0),"error")))),"")} -> 近战武器;刀剑 | Q25: Common | T25: 0 | U25: 1 | V25: 0 | W25: 1 | X25: device | Y25: claymore | Z25: {=_xlfn.IFS($A25="","",OR(F25=99,F25=""),_xlfn.TEXTJOIN("_",1,X25,$A25,Y25),TRUE,OFFSET($Z25,-1,0))} -> device_1310103_claymore | AA25: 7 | AB25: 1 | AC25: 13 | AF25: 1 | AG25: 0 | AH25: =_xlfn.TEXTJOIN("~",1,AI25:AJ25) -> 0~3 | AI25: 0 | AJ25: 3 | AK25: 0 | AL25: 0 | AM25: 0 | AN25: 0 | AO25: 0 | AP25: TRUE | AQ25: DScript_Melee_Blade | AS25: =$A25 -> 1310103 | AY25: =_xlfn.TEXTJOIN("~",1,AZ25:BA25) -> 2.5~0.1 | AZ25: 2.5 | BA25: 0.1 | BB25: =REPLACE($A25,1,1,6) -> 6310103 | BC25: DPanel_Melee_Blade | BD25: 201;301 | BE25: {=IF(BD25<>"",_xlfn.TEXTJOIN("; ",1,VLOOKUP(VALUE(_xlfn.TEXTSPLIT(BD25,";")),device_cubicles!A:B,2,0)),"")} -> 近战攻击; 磨砺刀刃
A26: 1310104 | B26: 0 | C26: 长矛 | D26: YH | G26: device_spear | H26: {=_xlfn.IFS($A26="","",OR($F26=99,$F26=""),_xlfn.TEXTJOIN("_",1,"device_name",$A26,$Y26),TRUE,OFFSET(H26,-1,0))} -> device_name_1310104_spear | J26: =_xlfn.LET(_xlpm.get_device_type,VLOOKUP(VALUE(MID(A26,3,1)),tb_device_info_type[#All],3,0),_xlpm.check_if_wheel,IF(LEFT(A26,2)="12","wheel",_xlpm.get_device_type),_xlpm.raw_output,IF($A26<>"",_xlfn.TEXTJOIN("_",1,"device_alt",_xlpm.check_if_wheel),""),IFERROR(_xlpm.raw_output,"information missing")) -> device_alt_melee | K26: {=_xlfn.IFS($A26="","",ISTEXT($L26),_xlfn.CONCAT("dwt","[device_wheel_thumbnail_",RIGHT($A26,1)-1,"]"),TRUE,_xlfn.CONCAT("dt","[device_thumbnail_",IF($L26<>"",$L26,0),"]"))} -> dt[device_thumbnail_28] | L26: 28 | M26: se_ag_device_broken | N26: se_ag_device_be_hit | O26: 1420100;1420102 | P26: {=IFERROR(_xlfn.TEXTJOIN(";",1,_xlfn.MAP(_xlfn.TEXTSPLIT(O26,";"),_xlfn.LAMBDA(_xlpm.x,IFERROR(VLOOKUP(VALUE(_xlpm.x),device_tag!A:B,2,0),"error")))),"")} -> 近战武器;长矛 | Q26: Common | T26: 0 | U26: 1 | V26: 0 | W26: 1 | X26: device | Y26: spear | Z26: {=_xlfn.IFS($A26="","",OR(F26=99,F26=""),_xlfn.TEXTJOIN("_",1,X26,$A26,Y26),TRUE,OFFSET($Z26,-1,0))} -> device_1310104_spear | AA26: 3 | AB26: 1 | AC26: 12 | AF26: 1 | AG26: 0 | AH26: =_xlfn.TEXTJOIN("~",1,AI26:AJ26) -> 0~4 | AI26: 0 | AJ26: 4 | AK26: 0 | AL26: 0 | AM26: 0 | AN26: 0 | AO26: 0 | AP26: TRUE | AQ26: BasicMelee_Click | AS26: =$A26 -> 1310104 | AY26: =_xlfn.TEXTJOIN("~",1,AZ26:BA26) -> 6~1.5 | AZ26: 6 | BA26: 1.5 | BB26: =REPLACE($A26,1,1,6) -> 6310104 | BC26: DevicePanel_Click_Melee_Resharpenable_Spear | BD26: 201;301 | BE26: {=IF(BD26<>"",_xlfn.TEXTJOIN("; ",1,VLOOKUP(VALUE(_xlfn.TEXTSPLIT(BD26,";")),device_cubicles!A:B,2,0)),"")} -> 近战攻击; 磨砺刀刃
A27: 1310105 | B27: 0 | C27: 充气球棍 | D27: XY | G27: Null | H27: {=_xlfn.IFS($A27="","",OR($F27=99,$F27=""),_xlfn.TEXTJOIN("_",1,"device_name",$A27,$Y27),TRUE,OFFSET(H27,-1,0))} -> device_name_1310105_inflatable_stick | J27: =_xlfn.LET(_xlpm.get_device_type,VLOOKUP(VALUE(MID(A27,3,1)),tb_device_info_type[#All],3,0),_xlpm.check_if_wheel,IF(LEFT(A27,2)="12","wheel",_xlpm.get_device_type),_xlpm.raw_output,IF($A27<>"",_xlfn.TEXTJOIN("_",1,"device_alt",_xlpm.check_if_wheel),""),IFERROR(_xlpm.raw_output,"information missing")) -> device_alt_melee | K27: {=_xlfn.IFS($A27="","",ISTEXT($L27),_xlfn.CONCAT("dwt","[device_wheel_thumbnail_",RIGHT($A27,1)-1,"]"),TRUE,_xlfn.CONCAT("dt","[device_thumbnail_",IF($L27<>"",$L27,0),"]"))} -> dt[device_thumbnail_39] | L27: 39 | M27: se_ag_device_broken | N27: se_ag_device_be_hit | O27: 1420100;1420103 | P27: {=IFERROR(_xlfn.TEXTJOIN(";",1,_xlfn.MAP(_xlfn.TEXTSPLIT(O27,";"),_xlfn.LAMBDA(_xlpm.x,IFERROR(VLOOKUP(VALUE(_xlpm.x),device_tag!A:B,2,0),"error")))),"")} -> 近战武器;棍棒 | Q27: Common | S27: 0 | T27: 0 | U27: 0 | V27: 0 | W27: 0 | X27: device | Y27: inflatable_stick | Z27: {=_xlfn.IFS($A27="","",OR(F27=99,F27=""),_xlfn.TEXTJOIN("_",1,X27,$A27,Y27),TRUE,OFFSET($Z27,-1,0))} -> device_1310105_inflatable_stick | AA27: 0.1 | AB27: =COLUMNS(_xlfn.TEXTSPLIT(BD27,";")) -> 1 | AC27: 10 | AF27: 1 | AG27: 0 | AH27: =_xlfn.TEXTJOIN("~",1,AI27:AJ27) -> 0~2.8 | AI27: 0 | AJ27: 2.8 | AK27: 0 | AL27: 0 | AM27: 0 | AN27: 0 | AO27: 0 | AP27: TRUE | AQ27: DScript_Melee | AS27: =$A27 -> 1310105 | AY27: =_xlfn.TEXTJOIN("~",1,AZ27:BA27) -> 5~0.8 | AZ27: 5 | BA27: 0.8 | BB27: 1 | BC27: (Base) | BD27: 201 | BE27: {=IF(BD27<>"",_xlfn.TEXTJOIN("; ",1,VLOOKUP(VALUE(_xlfn.TEXTSPLIT(BD27,";")),device_cubicles!A:B,2,0)),"")} -> 近战攻击
A28: 13101050 | B28: 0 | C28: 充气球棍 Lv.0 | D28: XY | F28: 0 | G28: Null | H28: {=_xlfn.IFS($A28="","",OR($F28=99,$F28=""),_xlfn.TEXTJOIN("_",1,"device_name",$A28,$Y28),TRUE,OFFSET(H28,-1,0))} -> device_name_1310105_inflatable_stick | J28: =_xlfn.LET(_xlpm.get_device_type,VLOOKUP(VALUE(MID(A28,3,1)),tb_device_info_type[#All],3,0),_xlpm.check_if_wheel,IF(LEFT(A28,2)="12","wheel",_xlpm.get_device_type),_xlpm.raw_output,IF($A28<>"",_xlfn.TEXTJOIN("_",1,"device_alt",_xlpm.check_if_wheel),""),IFERROR(_xlpm.raw_output,"information missing")) -> device_alt_melee | K28: {=_xlfn.IFS($A28="","",ISTEXT($L28),_xlfn.CONCAT("dwt","[device_wheel_thumbnail_",RIGHT($A28,1)-1,"]"),TRUE,_xlfn.CONCAT("dt","[device_thumbnail_",IF($L28<>"",$L28,0),"]"))} -> dt[device_thumbnail_39] | L28: 39 | M28: se_ag_device_broken | N28: se_ag_device_be_hit | O28: 1420100;1420103 | P28: {=IFERROR(_xlfn.TEXTJOIN(";",1,_xlfn.MAP(_xlfn.TEXTSPLIT(O28,";"),_xlfn.LAMBDA(_xlpm.x,IFERROR(VLOOKUP(VALUE(_xlpm.x),device_tag!A:B,2,0),"error")))),"")} -> 近战武器;棍棒 | Q28: Common | S28: 0 | T28: 0 | U28: 0 | V28: 0 | W28: 0 | X28: device | Y28: inflatable_stick | Z28: {=_xlfn.IFS($A28="","",OR(F28=99,F28=""),_xlfn.TEXTJOIN("_",1,X28,$A28,Y28),TRUE,OFFSET($Z28,-1,0))} -> device_1310105_inflatable_stick | AA28: 0.1 | AB28: =COLUMNS(_xlfn.TEXTSPLIT(BD28,";")) -> 1 | AC28: =ROUND($AD28*$AE28^$F28,0) -> 10 | AD28: 9.8 | AE28: =POWER(1.6,2) -> 2.56 | AF28: 1 | AG28: 0 | AH28: =_xlfn.TEXTJOIN("~",1,AI28:AJ28) -> 0~2.8 | AI28: 0 | AJ28: 2.8 | AK28: 0 | AL28: 0 | AM28: 0 | AN28: 0 | AO28: 0 | AP28: TRUE | AQ28: DScript_Melee | AS28: =$A28 -> 13101050 | AY28: =_xlfn.TEXTJOIN("~",1,AZ28:BA28) -> 5~0.8 | AZ28: 5 | BA28: 0.8 | BB28: 1 | BC28: DPanel_Melee_Inflatable_Stick_Lv0 | BD28: 201 | BE28: {=IF(BD28<>"",_xlfn.TEXTJOIN("; ",1,VLOOKUP(VALUE(_xlfn.TEXTSPLIT(BD28,";")),device_cubicles!A:B,2,0)),"")} -> 近战攻击
A29: 13101051 | B29: 0 | C29: 充气球棍 Lv.1 | D29: XY | F29: 1 | G29: Null | H29: {=_xlfn.IFS($A29="","",OR($F29=99,$F29=""),_xlfn.TEXTJOIN("_",1,"device_name",$A29,$Y29),TRUE,OFFSET(H29,-1,0))} -> device_name_1310105_inflatable_stick | J29: =_xlfn.LET(_xlpm.get_device_type,VLOOKUP(VALUE(MID(A29,3,1)),tb_device_info_type[#All],3,0),_xlpm.check_if_wheel,IF(LEFT(A29,2)="12","wheel",_xlpm.get_device_type),_xlpm.raw_output,IF($A29<>"",_xlfn.TEXTJOIN("_",1,"device_alt",_xlpm.check_if_wheel),""),IFERROR(_xlpm.raw_output,"information missing")) -> device_alt_melee | K29: {=_xlfn.IFS($A29="","",ISTEXT($L29),_xlfn.CONCAT("dwt","[device_wheel_thumbnail_",RIGHT($A29,1)-1,"]"),TRUE,_xlfn.CONCAT("dt","[device_thumbnail_",IF($L29<>"",$L29,0),"]"))} -> dt[device_thumbnail_39] | L29: 39 | M29: se_ag_device_broken | N29: se_ag_device_be_hit | O29: 1420100;1420103 | P29: {=IFERROR(_xlfn.TEXTJOIN(";",1,_xlfn.MAP(_xlfn.TEXTSPLIT(O29,";"),_xlfn.LAMBDA(_xlpm.x,IFERROR(VLOOKUP(VALUE(_xlpm.x),device_tag!A:B,2,0),"error")))),"")} -> 近战武器;棍棒 | Q29: Common | S29: 0 | T29: 0 | U29: 0 | V29: 0 | W29: 0 | X29: device | Y29: inflatable_stick | Z29: {=_xlfn.IFS($A29="","",OR(F29=99,F29=""),_xlfn.TEXTJOIN("_",1,X29,$A29,Y29),TRUE,OFFSET($Z29,-1,0))} -> device_1310105_inflatable_stick | AA29: 0.1 | AB29: =COLUMNS(_xlfn.TEXTSPLIT(BD29,";")) -> 1 | AC29: =ROUND($AD29*$AE29^$F29,0) -> 25 | AD29: 9.8 | AE29: =POWER(1.6,2) -> 2.56 | AF29: 1 | AG29: 0 | AH29: =_xlfn.TEXTJOIN("~",1,AI29:AJ29) -> 0~2.8 | AI29: 0 | AJ29: 2.8 | AK29: 0 | AL29: 0 | AM29: 0 | AN29: 0 | AO29: 0 | AP29: TRUE | AQ29: DScript_Melee | AS29: =$A29 -> 13101051 | AY29: =_xlfn.TEXTJOIN("~",1,AZ29:BA29) -> 5~0.8 | AZ29: 5 | BA29: 0.8 | BB29: 1 | BC29: DPanel_Melee_Inflatable_Stick_Lv1 | BD29: 201 | BE29: {=IF(BD29<>"",_xlfn.TEXTJOIN("; ",1,VLOOKUP(VALUE(_xlfn.TEXTSPLIT(BD29,";")),device_cubicles!A:B,2,0)),"")} -> 近战攻击
A30: 1310106 | B30: 0 | C30: 圆锯 | D30: XY | G30: Null | H30: {=_xlfn.IFS($A30="","",OR($F30=99,$F30=""),_xlfn.TEXTJOIN("_",1,"device_name",$A30,$Y30),TRUE,OFFSET(H30,-1,0))} -> device_name_1310106_circlesaw | J30: =_xlfn.LET(_xlpm.get_device_type,VLOOKUP(VALUE(MID(A30,3,1)),tb_device_info_type[#All],3,0),_xlpm.check_if_wheel,IF(LEFT(A30,2)="12","wheel",_xlpm.get_device_type),_xlpm.raw_output,IF($A30<>"",_xlfn.TEXTJOIN("_",1,"device_alt",_xlpm.check_if_wheel),""),IFERROR(_xlpm.raw_output,"information missing")) -> device_alt_melee | K30: {=_xlfn.IFS($A30="","",ISTEXT($L30),_xlfn.CONCAT("dwt","[device_wheel_thumbnail_",RIGHT($A30,1)-1,"]"),TRUE,_xlfn.CONCAT("dt","[device_thumbnail_",IF($L30<>"",$L30,0),"]"))} -> dt[device_thumbnail_36] | L30: 36 | M30: se_ag_device_broken | N30: se_ag_device_be_hit | O30: 1420100 | P30: {=IFERROR(_xlfn.TEXTJOIN(";",1,_xlfn.MAP(_xlfn.TEXTSPLIT(O30,";"),_xlfn.LAMBDA(_xlpm.x,IFERROR(VLOOKUP(VALUE(_xlpm.x),device_tag!A:B,2,0),"error")))),"")} -> 近战武器 | Q30: Common | X30: device | Y30: circlesaw | Z30: {=_xlfn.IFS($A30="","",OR(F30=99,F30=""),_xlfn.TEXTJOIN("_",1,X30,$A30,Y30),TRUE,OFFSET($Z30,-1,0))} -> device_1310106_circlesaw | AA30: 5 | AB30: =COLUMNS(_xlfn.TEXTSPLIT(BD30,";")) -> 1 | AC30: 11 | AF30: 1 | AG30: 0 | AH30: =_xlfn.TEXTJOIN("~",1,AI30:AJ30) -> 0~1.5 | AI30: 0 | AJ30: 1.5 | AK30: 0 | AL30: 0 | AM30: 0 | AN30: 0 | AO30: 0 | AP30: FALSE | AQ30: DScript_Melee_Charge_CircularSaw | AX30: =A30 -> 1310106 | AY30: =_xlfn.TEXTJOIN("~",1,AZ30:BA30) -> 6~3 | AZ30: 6 | BA30: 3 | BB30: 1 | BC30: (Base) | BD30: 201 | BE30: {=IF(BD30<>"",_xlfn.TEXTJOIN("; ",1,VLOOKUP(VALUE(_xlfn.TEXTSPLIT(BD30,";")),device_cubicles!A:B,2,0)),"")} -> 近战攻击
A31: 13101061 | B31: 0 | C31: 圆锯 Lv.1 | D31: XY | F31: 1 | G31: Null | H31: {=_xlfn.IFS($A31="","",OR($F31=99,$F31=""),_xlfn.TEXTJOIN("_",1,"device_name",$A31,$Y31),TRUE,OFFSET(H31,-1,0))} -> device_name_1310106_circlesaw | J31: =_xlfn.LET(_xlpm.get_device_type,VLOOKUP(VALUE(MID(A31,3,1)),tb_device_info_type[#All],3,0),_xlpm.check_if_wheel,IF(LEFT(A31,2)="12","wheel",_xlpm.get_device_type),_xlpm.raw_output,IF($A31<>"",_xlfn.TEXTJOIN("_",1,"device_alt",_xlpm.check_if_wheel),""),IFERROR(_xlpm.raw_output,"information missing")) -> device_alt_melee | K31: {=_xlfn.IFS($A31="","",ISTEXT($L31),_xlfn.CONCAT("dwt","[device_wheel_thumbnail_",RIGHT($A31,1)-1,"]"),TRUE,_xlfn.CONCAT("dt","[device_thumbnail_",IF($L31<>"",$L31,0),"]"))} -> dt[device_thumbnail_36] | L31: 36 | M31: se_ag_device_broken | N31: se_ag_device_be_hit | O31: 1420100 | P31: {=IFERROR(_xlfn.TEXTJOIN(";",1,_xlfn.MAP(_xlfn.TEXTSPLIT(O31,";"),_xlfn.LAMBDA(_xlpm.x,IFERROR(VLOOKUP(VALUE(_xlpm.x),device_tag!A:B,2,0),"error")))),"")} -> 近战武器 | Q31: Common | X31: device | Y31: circlesaw | Z31: {=_xlfn.IFS($A31="","",OR(F31=99,F31=""),_xlfn.TEXTJOIN("_",1,X31,$A31,Y31),TRUE,OFFSET($Z31,-1,0))} -> device_1310106_circlesaw | AA31: 5 | AB31: =COLUMNS(_xlfn.TEXTSPLIT(BD31,";")) -> 1 | AC31: =ROUND($AD31*$AE31^$F31,0) -> 28 | AD31: 10.75 | AE31: =POWER(1.6,2) -> 2.56 | AF31: 1 | AG31: 0 | AH31: =_xlfn.TEXTJOIN("~",1,AI31:AJ31) -> 0~1.5 | AI31: 0 | AJ31: 1.5 | AK31: 0 | AL31: 0 | AM31: 0 | AN31: 0 | AO31: 0 | AP31: FALSE | AQ31: DScript_Melee_Charge_CircularSaw | AX31: =A31 -> 13101061 | AY31: =_xlfn.TEXTJOIN("~",1,AZ31:BA31) -> 6~3 | AZ31: 6 | BA31: 3 | BB31: 1 | BC31: DPanel_Charge_CircularSaw | BD31: 201 | BE31: {=IF(BD31<>"",_xlfn.TEXTJOIN("; ",1,VLOOKUP(VALUE(_xlfn.TEXTSPLIT(BD31,";")),device_cubicles!A:B,2,0)),"")} -> 近战攻击
A32: 13101062 | B32: 0 | C32: 圆锯 Lv.2 | D32: XY | F32: 2 | G32: Null | H32: {=_xlfn.IFS($A32="","",OR($F32=99,$F32=""),_xlfn.TEXTJOIN("_",1,"device_name",$A32,$Y32),TRUE,OFFSET(H32,-1,0))} -> device_name_1310106_circlesaw | J32: =_xlfn.LET(_xlpm.get_device_type,VLOOKUP(VALUE(MID(A32,3,1)),tb_device_info_type[#All],3,0),_xlpm.check_if_wheel,IF(LEFT(A32,2)="12","wheel",_xlpm.get_device_type),_xlpm.raw_output,IF($A32<>"",_xlfn.TEXTJOIN("_",1,"device_alt",_xlpm.check_if_wheel),""),IFERROR(_xlpm.raw_output,"information missing")) -> device_alt_melee | K32: {=_xlfn.IFS($A32="","",ISTEXT($L32),_xlfn.CONCAT("dwt","[device_wheel_thumbnail_",RIGHT($A32,1)-1,"]"),TRUE,_xlfn.CONCAT("dt","[device_thumbnail_",IF($L32<>"",$L32,0),"]"))} -> dt[device_thumbnail_36] | L32: 36 | M32: se_ag_device_broken | N32: se_ag_device_be_hit | O32: 1420100 | P32: {=IFERROR(_xlfn.TEXTJOIN(";",1,_xlfn.MAP(_xlfn.TEXTSPLIT(O32,";"),_xlfn.LAMBDA(_xlpm.x,IFERROR(VLOOKUP(VALUE(_xlpm.x),device_tag!A:B,2,0),"error")))),"")} -> 近战武器 | Q32: Common | X32: device | Y32: circlesaw | Z32: {=_xlfn.IFS($A32="","",OR(F32=99,F32=""),_xlfn.TEXTJOIN("_",1,X32,$A32,Y32),TRUE,OFFSET($Z32,-1,0))} -> device_1310106_circlesaw | AA32: 5 | AB32: =COLUMNS(_xlfn.TEXTSPLIT(BD32,";")) -> 1 | AC32: =ROUND($AD32*$AE32^$F32,0) -> 70 | AD32: 10.75 | AE32: =POWER(1.6,2) -> 2.56 | AF32: 1 | AG32: 0 | AH32: =_xlfn.TEXTJOIN("~",1,AI32:AJ32) -> 0~1.5 | AI32: 0 | AJ32: 1.5 | AK32: 0 | AL32: 0 | AM32: 0 | AN32: 0 | AO32: 0 | AP32: FALSE | AQ32: DScript_Melee_Charge_CircularSaw | AX32: =A32 -> 13101062 | AY32: =_xlfn.TEXTJOIN("~",1,AZ32:BA32) -> 6~3 | AZ32: 6 | BA32: 3 | BB32: 1 | BC32: DPanel_Charge_CircularSaw | BD32: 201 | BE32: {=IF(BD32<>"",_xlfn.TEXTJOIN("; ",1,VLOOKUP(VALUE(_xlfn.TEXTSPLIT(BD32,";")),device_cubicles!A:B,2,0)),"")} -> 近战攻击
A33: 13101063 | B33: 0 | C33: 圆锯 Lv.3 | D33: XY | F33: 3 | G33: Null | H33: {=_xlfn.IFS($A33="","",OR($F33=99,$F33=""),_xlfn.TEXTJOIN("_",1,"device_name",$A33,$Y33),TRUE,OFFSET(H33,-1,0))} -> device_name_1310106_circlesaw | J33: =_xlfn.LET(_xlpm.get_device_type,VLOOKUP(VALUE(MID(A33,3,1)),tb_device_info_type[#All],3,0),_xlpm.check_if_wheel,IF(LEFT(A33,2)="12","wheel",_xlpm.get_device_type),_xlpm.raw_output,IF($A33<>"",_xlfn.TEXTJOIN("_",1,"device_alt",_xlpm.check_if_wheel),""),IFERROR(_xlpm.raw_output,"information missing")) -> device_alt_melee | K33: {=_xlfn.IFS($A33="","",ISTEXT($L33),_xlfn.CONCAT("dwt","[device_wheel_thumbnail_",RIGHT($A33,1)-1,"]"),TRUE,_xlfn.CONCAT("dt","[device_thumbnail_",IF($L33<>"",$L33,0),"]"))} -> dt[device_thumbnail_36] | L33: 36 | M33: se_ag_device_broken | N33: se_ag_device_be_hit | O33: 1420100 | P33: {=IFERROR(_xlfn.TEXTJOIN(";",1,_xlfn.MAP(_xlfn.TEXTSPLIT(O33,";"),_xlfn.LAMBDA(_xlpm.x,IFERROR(VLOOKUP(VALUE(_xlpm.x),device_tag!A:B,2,0),"error")))),"")} -> 近战武器 | Q33: Common | X33: device | Y33: circlesaw | Z33: {=_xlfn.IFS($A33="","",OR(F33=99,F33=""),_xlfn.TEXTJOIN("_",1,X33,$A33,Y33),TRUE,OFFSET($Z33,-1,0))} -> device_1310106_circlesaw | AA33: 5 | AB33: =COLUMNS(_xlfn.TEXTSPLIT(BD33,";")) -> 1 | AC33: =ROUND($AD33*$AE33^$F33,0) -> 180 | AD33: 10.75 | AE33: =POWER(1.6,2) -> 2.56 | AF33: 1 | AG33: 0 | AH33: =_xlfn.TEXTJOIN("~",1,AI33:AJ33) -> 0~1.5 | AI33: 0 | AJ33: 1.5 | AK33: 0 | AL33: 0 | AM33: 0 | AN33: 0 | AO33: 0 | AP33: FALSE | AQ33: DScript_Melee_Charge_CircularSaw | AX33: =A33 -> 13101063 | AY33: =_xlfn.TEXTJOIN("~",1,AZ33:BA33) -> 6~3 | AZ33: 6 | BA33: 3 | BB33: 1 | BC33: DPanel_Charge_CircularSaw | BD33: 201 | BE33: {=IF(BD33<>"",_xlfn.TEXTJOIN("; ",1,VLOOKUP(VALUE(_xlfn.TEXTSPLIT(BD33,";")),device_cubicles!A:B,2,0)),"")} -> 近战攻击
A34: 13101064 | B34: 0 | C34: 圆锯 Lv.4 | D34: XY | F34: 4 | G34: Null | H34: {=_xlfn.IFS($A34="","",OR($F34=99,$F34=""),_xlfn.TEXTJOIN("_",1,"device_name",$A34,$Y34),TRUE,OFFSET(H34,-1,0))} -> device_name_1310106_circlesaw | J34: =_xlfn.LET(_xlpm.get_device_type,VLOOKUP(VALUE(MID(A34,3,1)),tb_device_info_type[#All],3,0),_xlpm.check_if_wheel,IF(LEFT(A34,2)="12","wheel",_xlpm.get_device_type),_xlpm.raw_output,IF($A34<>"",_xlfn.TEXTJOIN("_",1,"device_alt",_xlpm.check_if_wheel),""),IFERROR(_xlpm.raw_output,"information missing")) -> device_alt_melee | K34: {=_xlfn.IFS($A34="","",ISTEXT($L34),_xlfn.CONCAT("dwt","[device_wheel_thumbnail_",RIGHT($A34,1)-1,"]"),TRUE,_xlfn.CONCAT("dt","[device_thumbnail_",IF($L34<>"",$L34,0),"]"))} -> dt[device_thumbnail_36] | L34: 36 | M34: se_ag_device_broken | N34: se_ag_device_be_hit | O34: 1420100 | P34: {=IFERROR(_xlfn.TEXTJOIN(";",1,_xlfn.MAP(_xlfn.TEXTSPLIT(O34,";"),_xlfn.LAMBDA(_xlpm.x,IFERROR(VLOOKUP(VALUE(_xlpm.x),device_tag!A:B,2,0),"error")))),"")} -> 近战武器 | Q34: Common | X34: device | Y34: circlesaw | Z34: {=_xlfn.IFS($A34="","",OR(F34=99,F34=""),_xlfn.TEXTJOIN("_",1,X34,$A34,Y34),TRUE,OFFSET($Z34,-1,0))} -> device_1310106_circlesaw | AA34: 5 | AB34: =COLUMNS(_xlfn.TEXTSPLIT(BD34,";")) -> 1 | AC34: =ROUND($AD34*$AE34^$F34,0) -> 462 | AD34: 10.75 | AE34: =POWER(1.6,2) -> 2.56 | AF34: 1 | AG34: 0 | AH34: =_xlfn.TEXTJOIN("~",1,AI34:AJ34) -> 0~1.5 | AI34: 0 | AJ34: 1.5 | AK34: 0 | AL34: 0 | AM34: 0 | AN34: 0 | AO34: 0 | AP34: FALSE | AQ34: DScript_Melee_Charge_CircularSaw | AX34: =A34 -> 13101064 | AY34: =_xlfn.TEXTJOIN("~",1,AZ34:BA34) -> 6~3 | AZ34: 6 | BA34: 3 | BB34: 1 | BC34: DPanel_Charge_CircularSaw | BD34: 201 | BE34: {=IF(BD34<>"",_xlfn.TEXTJOIN("; ",1,VLOOKUP(VALUE(_xlfn.TEXTSPLIT(BD34,";")),device_cubicles!A:B,2,0)),"")} -> 近战攻击
A35: 1310107 | B35: 0 | C35: 双刃铡刀 | D35: XY | G35: Null | H35: {=_xlfn.IFS($A35="","",OR($F35=99,$F35=""),_xlfn.TEXTJOIN("_",1,"device_name",$A35,$Y35),TRUE,OFFSET(H35,-1,0))} -> device_name_1310107_double_edged_cutter | J35: =_xlfn.LET(_xlpm.get_device_type,VLOOKUP(VALUE(MID(A35,3,1)),tb_device_info_type[#All],3,0),_xlpm.check_if_wheel,IF(LEFT(A35,2)="12","wheel",_xlpm.get_device_type),_xlpm.raw_output,IF($A35<>"",_xlfn.TEXTJOIN("_",1,"device_alt",_xlpm.check_if_wheel),""),IFERROR(_xlpm.raw_output,"information missing")) -> device_alt_melee | K35: {=_xlfn.IFS($A35="","",ISTEXT($L35),_xlfn.CONCAT("dwt","[device_wheel_thumbnail_",RIGHT($A35,1)-1,"]"),TRUE,_xlfn.CONCAT("dt","[device_thumbnail_",IF($L35<>"",$L35,0),"]"))} -> dt[device_thumbnail_38] | L35: 38 | M35: se_ag_device_broken | N35: se_ag_device_be_hit | O35: 1420100;1420101 | P35: {=IFERROR(_xlfn.TEXTJOIN(";",1,_xlfn.MAP(_xlfn.TEXTSPLIT(O35,";"),_xlfn.LAMBDA(_xlpm.x,IFERROR(VLOOKUP(VALUE(_xlpm.x),device_tag!A:B,2,0),"error")))),"")} -> 近战武器;刀剑 | Q35: Common | T35: 0 | U35: 1 | V35: 0 | W35: 1 | X35: device | Y35: double_edged_cutter | Z35: {=_xlfn.IFS($A35="","",OR(F35=99,F35=""),_xlfn.TEXTJOIN("_",1,X35,$A35,Y35),TRUE,OFFSET($Z35,-1,0))} -> device_1310107_double_edged_cutter | AA35: 7 | AB35: =COLUMNS(_xlfn.TEXTSPLIT(BD35,";")) -> 1 | AC35: 11.5 | AF35: 1 | AG35: 0 | AH35: =_xlfn.TEXTJOIN("~",1,AI35:AJ35) -> 0~3 | AI35: 0 | AJ35: 3 | AK35: 0 | AL35: 0 | AM35: 0 | AN35: 0 | AO35: 0 | AP35: TRUE | AQ35: DScript_Melee_Blade | AS35: =$A35 -> 1310107 | AY35: =_xlfn.TEXTJOIN("~",1,AZ35:BA35) -> 2.5~0.1 | AZ35: 2.5 | BA35: 0.1 | BB35: 1 | BC35: (Base) | BD35: 201 | BE35: {=IF(BD35<>"",_xlfn.TEXTJOIN("; ",1,VLOOKUP(VALUE(_xlfn.TEXTSPLIT(BD35,";")),device_cubicles!A:B,2,0)),"")} -> 近战攻击
A36: 13101070 | B36: 0 | C36: 双刃铡刀 Lv.0 | D36: XY | F36: 0 | G36: Null | H36: {=_xlfn.IFS($A36="","",OR($F36=99,$F36=""),_xlfn.TEXTJOIN("_",1,"device_name",$A36,$Y36),TRUE,OFFSET(H36,-1,0))} -> device_name_1310107_double_edged_cutter | J36: =_xlfn.LET(_xlpm.get_device_type,VLOOKUP(VALUE(MID(A36,3,1)),tb_device_info_type[#All],3,0),_xlpm.check_if_wheel,IF(LEFT(A36,2)="12","wheel",_xlpm.get_device_type),_xlpm.raw_output,IF($A36<>"",_xlfn.TEXTJOIN("_",1,"device_alt",_xlpm.check_if_wheel),""),IFERROR(_xlpm.raw_output,"information missing")) -> device_alt_melee | K36: {=_xlfn.IFS($A36="","",ISTEXT($L36),_xlfn.CONCAT("dwt","[device_wheel_thumbnail_",RIGHT($A36,1)-1,"]"),TRUE,_xlfn.CONCAT("dt","[device_thumbnail_",IF($L36<>"",$L36,0),"]"))} -> dt[device_thumbnail_38] | L36: 38 | M36: se_ag_device_broken | N36: se_ag_device_be_hit | O36: 1420100;1420101 | P36: {=IFERROR(_xlfn.TEXTJOIN(";",1,_xlfn.MAP(_xlfn.TEXTSPLIT(O36,";"),_xlfn.LAMBDA(_xlpm.x,IFERROR(VLOOKUP(VALUE(_xlpm.x),device_tag!A:B,2,0),"error")))),"")} -> 近战武器;刀剑 | Q36: Common | T36: 0 | U36: 1 | V36: 0 | W36: 1 | X36: device | Y36: double_edged_cutter | Z36: {=_xlfn.IFS($A36="","",OR(F36=99,F36=""),_xlfn.TEXTJOIN("_",1,X36,$A36,Y36),TRUE,OFFSET($Z36,-1,0))} -> device_1310107_double_edged_cutter | AA36: 7 | AB36: =COLUMNS(_xlfn.TEXTSPLIT(BD36,";")) -> 1 | AC36: =ROUND($AD36*$AE36^$F36,0) -> 10 | AD36: 10.11 | AE36: =POWER(1.6,2) -> 2.56 | AF36: 1 | AG36: 0 | AH36: =_xlfn.TEXTJOIN("~",1,AI36:AJ36) -> 0~3 | AI36: 0 | AJ36: 3 | AK36: 0 | AL36: 0 | AM36: 0 | AN36: 0 | AO36: 0 | AP36: TRUE | AQ36: DScript_Melee_Blade | AS36: =$A36 -> 13101070 | AY36: =_xlfn.TEXTJOIN("~",1,AZ36:BA36) -> 2.5~0.1 | AZ36: 2.5 | BA36: 0.1 | BB36: 1 | BC36: DPanel_Melee_Blade | BD36: 201 | BE36: {=IF(BD36<>"",_xlfn.TEXTJOIN("; ",1,VLOOKUP(VALUE(_xlfn.TEXTSPLIT(BD36,";")),device_cubicles!A:B,2,0)),"")} -> 近战攻击
A37: 13101071 | B37: 0 | C37: 双刃铡刀 Lv.1 | D37: XY | F37: 1 | G37: Null | H37: {=_xlfn.IFS($A37="","",OR($F37=99,$F37=""),_xlfn.TEXTJOIN("_",1,"device_name",$A37,$Y37),TRUE,OFFSET(H37,-1,0))} -> device_name_1310107_double_edged_cutter | J37: =_xlfn.LET(_xlpm.get_device_type,VLOOKUP(VALUE(MID(A37,3,1)),tb_device_info_type[#All],3,0),_xlpm.check_if_wheel,IF(LEFT(A37,2)="12","wheel",_xlpm.get_device_type),_xlpm.raw_output,IF($A37<>"",_xlfn.TEXTJOIN("_",1,"device_alt",_xlpm.check_if_wheel),""),IFERROR(_xlpm.raw_output,"information missing")) -> device_alt_melee | K37: {=_xlfn.IFS($A37="","",ISTEXT($L37),_xlfn.CONCAT("dwt","[device_wheel_thumbnail_",RIGHT($A37,1)-1,"]"),TRUE,_xlfn.CONCAT("dt","[device_thumbnail_",IF($L37<>"",$L37,0),"]"))} -> dt[device_thumbnail_38] | L37: 38 | M37: se_ag_device_broken | N37: se_ag_device_be_hit | O37: 1420100;1420101 | P37: {=IFERROR(_xlfn.TEXTJOIN(";",1,_xlfn.MAP(_xlfn.TEXTSPLIT(O37,";"),_xlfn.LAMBDA(_xlpm.x,IFERROR(VLOOKUP(VALUE(_xlpm.x),device_tag!A:B,2,0),"error")))),"")} -> 近战武器;刀剑 | Q37: Common | T37: 0 | U37: 1 | V37: 0 | W37: 1 | X37: device | Y37: double_edged_cutter | Z37: {=_xlfn.IFS($A37="","",OR(F37=99,F37=""),_xlfn.TEXTJOIN("_",1,X37,$A37,Y37),TRUE,OFFSET($Z37,-1,0))} -> device_1310107_double_edged_cutter | AA37: 7 | AB37: =COLUMNS(_xlfn.TEXTSPLIT(BD37,";")) -> 1 | AC37: =ROUND($AD37*$AE37^$F37,0) -> 26 | AD37: 10.11 | AE37: =POWER(1.6,2) -> 2.56 | AF37: 1 | AG37: 0 | AH37: =_xlfn.TEXTJOIN("~",1,AI37:AJ37) -> 0~3 | AI37: 0 | AJ37: 3 | AK37: 0 | AL37: 0 | AM37: 0 | AN37: 0 | AO37: 0 | AP37: TRUE | AQ37: DScript_Melee_Blade | AS37: =$A37 -> 13101071 | AY37: =_xlfn.TEXTJOIN("~",1,AZ37:BA37) -> 2.5~0.1 | AZ37: 2.5 | BA37: 0.1 | BB37: 1 | BC37: DPanel_Melee_Blade | BD37: 201 | BE37: {=IF(BD37<>"",_xlfn.TEXTJOIN("; ",1,VLOOKUP(VALUE(_xlfn.TEXTSPLIT(BD37,";")),device_cubicles!A:B,2,0)),"")} -> 近战攻击
A38: 13101072 | B38: 0 | C38: 双刃铡刀 Lv.2 | D38: XY | F38: 2 | G38: Null | H38: {=_xlfn.IFS($A38="","",OR($F38=99,$F38=""),_xlfn.TEXTJOIN("_",1,"device_name",$A38,$Y38),TRUE,OFFSET(H38,-1,0))} -> device_name_1310107_double_edged_cutter | J38: =_xlfn.LET(_xlpm.get_device_type,VLOOKUP(VALUE(MID(A38,3,1)),tb_device_info_type[#All],3,0),_xlpm.check_if_wheel,IF(LEFT(A38,2)="12","wheel",_xlpm.get_device_type),_xlpm.raw_output,IF($A38<>"",_xlfn.TEXTJOIN("_",1,"device_alt",_xlpm.check_if_wheel),""),IFERROR(_xlpm.raw_output,"information missing")) -> device_alt_melee | K38: {=_xlfn.IFS($A38="","",ISTEXT($L38),_xlfn.CONCAT("dwt","[device_wheel_thumbnail_",RIGHT($A38,1)-1,"]"),TRUE,_xlfn.CONCAT("dt","[device_thumbnail_",IF($L38<>"",$L38,0),"]"))} -> dt[device_thumbnail_38] | L38: 38 | M38: se_ag_device_broken | N38: se_ag_device_be_hit | O38: 1420100;1420101 | P38: {=IFERROR(_xlfn.TEXTJOIN(";",1,_xlfn.MAP(_xlfn.TEXTSPLIT(O38,";"),_xlfn.LAMBDA(_xlpm.x,IFERROR(VLOOKUP(VALUE(_xlpm.x),device_tag!A:B,2,0),"error")))),"")} -> 近战武器;刀剑 | Q38: Common | T38: 0 | U38: 1 | V38: 0 | W38: 1 | X38: device | Y38: double_edged_cutter | Z38: {=_xlfn.IFS($A38="","",OR(F38=99,F38=""),_xlfn.TEXTJOIN("_",1,X38,$A38,Y38),TRUE,OFFSET($Z38,-1,0))} -> device_1310107_double_edged_cutter | AA38: 7 | AB38: =COLUMNS(_xlfn.TEXTSPLIT(BD38,";")) -> 1 | AC38: =ROUND($AD38*$AE38^$F38,0) -> 66 | AD38: 10.11 | AE38: =POWER(1.6,2) -> 2.56 | AF38: 1 | AG38: 0 | AH38: =_xlfn.TEXTJOIN("~",1,AI38:AJ38) -> 0~3 | AI38: 0 | AJ38: 3 | AK38: 0 | AL38: 0 | AM38: 0 | AN38: 0 | AO38: 0 | AP38: TRUE | AQ38: DScript_Melee_Blade | AS38: =$A38 -> 13101072 | AY38: =_xlfn.TEXTJOIN("~",1,AZ38:BA38) -> 2.5~0.1 | AZ38: 2.5 | BA38: 0.1 | BB38: 1 | BC38: DPanel_Melee_Blade | BD38: 201 | BE38: {=IF(BD38<>"",_xlfn.TEXTJOIN("; ",1,VLOOKUP(VALUE(_xlfn.TEXTSPLIT(BD38,";")),device_cubicles!A:B,2,0)),"")} -> 近战攻击
A39: 13101073 | B39: 0 | C39: 双刃铡刀 Lv.3 | D39: XY | F39: 3 | G39: Null | H39: {=_xlfn.IFS($A39="","",OR($F39=99,$F39=""),_xlfn.TEXTJOIN("_",1,"device_name",$A39,$Y39),TRUE,OFFSET(H39,-1,0))} -> device_name_1310107_double_edged_cutter | J39: =_xlfn.LET(_xlpm.get_device_type,VLOOKUP(VALUE(MID(A39,3,1)),tb_device_info_type[#All],3,0),_xlpm.check_if_wheel,IF(LEFT(A39,2)="12","wheel",_xlpm.get_device_type),_xlpm.raw_output,IF($A39<>"",_xlfn.TEXTJOIN("_",1,"device_alt",_xlpm.check_if_wheel),""),IFERROR(_xlpm.raw_output,"information missing")) -> device_alt_melee | K39: {=_xlfn.IFS($A39="","",ISTEXT($L39),_xlfn.CONCAT("dwt","[device_wheel_thumbnail_",RIGHT($A39,1)-1,"]"),TRUE,_xlfn.CONCAT("dt","[device_thumbnail_",IF($L39<>"",$L39,0),"]"))} -> dt[device_thumbnail_38] | L39: 38 | M39: se_ag_device_broken | N39: se_ag_device_be_hit | O39: 1420100;1420101 | P39: {=IFERROR(_xlfn.TEXTJOIN(";",1,_xlfn.MAP(_xlfn.TEXTSPLIT(O39,";"),_xlfn.LAMBDA(_xlpm.x,IFERROR(VLOOKUP(VALUE(_xlpm.x),device_tag!A:B,2,0),"error")))),"")} -> 近战武器;刀剑 | Q39: Common | T39: 0 | U39: 1 | V39: 0 | W39: 1 | X39: device | Y39: double_edged_cutter | Z39: {=_xlfn.IFS($A39="","",OR(F39=99,F39=""),_xlfn.TEXTJOIN("_",1,X39,$A39,Y39),TRUE,OFFSET($Z39,-1,0))} -> device_1310107_double_edged_cutter | AA39: 7 | AB39: =COLUMNS(_xlfn.TEXTSPLIT(BD39,";")) -> 1 | AC39: =ROUND($AD39*$AE39^$F39,0) -> 170 | AD39: 10.11 | AE39: =POWER(1.6,2) -> 2.56 | AF39: 1 | AG39: 0 | AH39: =_xlfn.TEXTJOIN("~",1,AI39:AJ39) -> 0~3 | AI39: 0 | AJ39: 3 | AK39: 0 | AL39: 0 | AM39: 0 | AN39: 0 | AO39: 0 | AP39: TRUE | AQ39: DScript_Melee_Blade | AS39: =$A39 -> 13101073 | AY39: =_xlfn.TEXTJOIN("~",1,AZ39:BA39) -> 2.5~0.1 | AZ39: 2.5 | BA39: 0.1 | BB39: 1 | BC39: DPanel_Melee_Blade | BD39: 201 | BE39: {=IF(BD39<>"",_xlfn.TEXTJOIN("; ",1,VLOOKUP(VALUE(_xlfn.TEXTSPLIT(BD39,";")),device_cubicles!A:B,2,0)),"")} -> 近战攻击
A40: 1311101 | B40: 0 | C40: 执刑钉棍 | D40: DG | G40: device_executioner_baton | H40: {=_xlfn.IFS($A40="","",OR($F40=99,$F40=""),_xlfn.TEXTJOIN("_",1,"device_name",$A40,$Y40),TRUE,OFFSET(H40,-1,0))} -> device_name_1311101_executioner_baton | J40: =_xlfn.LET(_xlpm.get_device_type,VLOOKUP(VALUE(MID(A40,3,1)),tb_device_info_type[#All],3,0),_xlpm.check_if_wheel,IF(LEFT(A40,2)="12","wheel",_xlpm.get_device_type),_xlpm.raw_output,IF($A40<>"",_xlfn.TEXTJOIN("_",1,"device_alt",_xlpm.check_if_wheel),""),IFERROR(_xlpm.raw_output,"information missing")) -> device_alt_melee | K40: {=_xlfn.IFS($A40="","",ISTEXT($L40),_xlfn.CONCAT("dwt","[device_wheel_thumbnail_",RIGHT($A40,1)-1,"]"),TRUE,_xlfn.CONCAT("dt","[device_thumbnail_",IF($L40<>"",$L40,0),"]"))} -> dt[device_thumbnail_9] | L40: 9 | M40: se_ag_device_broken | N40: se_ag_device_be_hit | O40: 1420100;1420103 | P40: {=IFERROR(_xlfn.TEXTJOIN(";",1,_xlfn.MAP(_xlfn.TEXTSPLIT(O40,";"),_xlfn.LAMBDA(_xlpm.x,IFERROR(VLOOKUP(VALUE(_xlpm.x),device_tag!A:B,2,0),"error")))),"")} -> 近战武器;棍棒 | Q40: Common | S40: 0 | T40: 0 | U40: 0 | V40: 0 | W40: 0 | X40: device | Y40: executioner_baton | Z40: {=_xlfn.IFS($A40="","",OR(F40=99,F40=""),_xlfn.TEXTJOIN("_",1,X40,$A40,Y40),TRUE,OFFSET($Z40,-1,0))} -> device_1311101_executioner_baton | AA40: 3 | AB40: 1 | AC40: 14 | AF40: 1 | AG40: 0 | AH40: =_xlfn.TEXTJOIN("~",1,AI40:AJ40) -> 0~2.8 | AI40: 0 | AJ40: 2.8 | AK40: 0 | AL40: 0 | AM40: 0 | AN40: 0 | AO40: 0 | AP40: TRUE | AQ40: BasicMelee_Click | AS40: =$A40 -> 1311101 | AY40: =_xlfn.TEXTJOIN("~",1,AZ40:BA40) -> 5~0.8 | AZ40: 5 | BA40: 0.8 | BB40: =REPLACE($A40,1,1,6) -> 6311101 | BC40: DevicePanel_Click_Melee_Unresharpenable_Executioner_Baton | BD40: 201 | BE40: {=IF(BD40<>"",_xlfn.TEXTJOIN("; ",1,VLOOKUP(VALUE(_xlfn.TEXTSPLIT(BD40,";")),device_cubicles!A:B,2,0)),"")} -> 近战攻击
...

Sheet device_wheel
A1: id | B1: sub_id | F1: wheel_height | G1: wheel_radius_visual | H1: tractive_force_max | I1: feedback_0 | J1: feedback_1 | K1: blower_charge | M1: blower_decline | O1: bounce_loss | P1: bounce_coef | Q1: crush_radius | R1: crush_level | S1: crush_v_mod | T1: crush_jump_coef | U1: crush_atk | AA1: crush_ft | AB1: sprint_charge_speed | AD1: sprint_charge_speed_bonus | AE1: sprint_charge_point | AF1: sprint_lever_loss
A2: uint key | B2: uint key | F2: float? | G2: float | H2: int | I2: float | J2: float | K2: float | M2: float | O2: float | P2: float | Q2: float | R2: float | S2: float | T2: float | U2: dict<string,float> | AA2: float | AB2: float | AD2: float | AE2: int | AF2: float
