Workbook
Name locate: _xlfn.LAMBDA(_xlpm.col_relative,_xlpm.rows,"RC["&_xlpm.col_relative&"]:R["&_xlpm.rows-1&"]C["&_xlpm.col_relative&"]")

Sheet loot
A1: id | F1: name | G1: desc | K1: view | M1: camp_coin
A2: uint key | F2: string | G2: string | K2: string | M2: dict<int,int>
A3: id | B3: 备注1 | C3: 备注2 品质 | D3: 备注3 由...合成 | E3: 备注4 版本 | F3: 物品名称 查localization表id | G3: 物品描述 查localization表id | H3: 物品描述 | I3: 资源前缀 | J3: 资源命名 | K3: 外观address sprite address | L3: 图集编号 | M3: 营地货币折算 | N3: 备注 人话翻译器 | O3: 备注 价值统计
A4: 6000 | B4: 金币 | C4: —— | F4: =IF($A4<>"",_xlfn.TEXTJOIN("_",1,"loot_name",$A4),"") -> loot_name_6000 | G4: =IF($A4<>"",_xlfn.TEXTJOIN("_",1,"loot_desc",$A4),"") -> loot_desc_6000 | J4: coin | K4: =_xlfn.TEXTJOIN("_",1,"loot",A4,J4) -> loot_6000_coin
A5: 6001 | B5: 灵魂 | C5: —— | E5: Remove | F5: =IF($A5<>"",_xlfn.TEXTJOIN("_",1,"loot_name",$A5),"") -> loot_name_6001 | G5: =IF($A5<>"",_xlfn.TEXTJOIN("_",1,"loot_desc",$A5),"") -> loot_desc_6001 | J5: soul | K5: =_xlfn.TEXTJOIN("_",1,"loot",A5,J5) -> loot_6001_soul
A6: 6002 | B6: 食物 | C6: —— | E6: NEW | F6: =IF($A6<>"",_xlfn.TEXTJOIN("_",1,"loot_name",$A6),"") -> loot_name_6002 | G6: =IF($A6<>"",_xlfn.TEXTJOIN("_",1,"loot_desc",$A6),"") -> loot_desc_6002 | J6: meat | K6: =_xlfn.TEXTJOIN("_",1,"loot",A6,J6) -> loot_6002_meat
A7: 6003 | B7: 木材 | C7: —— | E7: NEW | F7: =IF($A7<>"",_xlfn.TEXTJOIN("_",1,"loot_name",$A7),"") -> loot_name_6003 | G7: =IF($A7<>"",_xlfn.TEXTJOIN("_",1,"loot_desc",$A7),"") -> loot_desc_6003 | J7: wood | K7: =_xlfn.TEXTJOIN("_",1,"loot",A7,J7) -> loot_6003_wood
A8: 6004 | B8: 金属 | C8: —— | E8: NEW | F8: =IF($A8<>"",_xlfn.TEXTJOIN("_",1,"loot_name",$A8),"") -> loot_name_6004 | G8: =IF($A8<>"",_xlfn.TEXTJOIN("_",1,"loot_desc",$A8),"") -> loot_desc_6004 | J8: metal | K8: =_xlfn.TEXTJOIN("_",1,"loot",A8,J8) -> loot_6004_metal
F10: =IF($A10<>"",_xlfn.TEXTJOIN("_",1,"loot_name",$A10),"") | G10: =IF($A10<>"",_xlfn.TEXTJOIN("_",1,"loot_desc",$A10),"")
A11: 6010 | B11: 生肉 | C11: 0 | E11: Remove | F11: =IF($A11<>"",_xlfn.TEXTJOIN("_",1,"loot_name",$A11),"") -> loot_name_6010 | G11: =IF($A11<>"",_xlfn.TEXTJOIN("_",1,"loot_desc",$A11),"") -> loot_desc_6010 | J11: meat | K11: =_xlfn.TEXTJOIN("_",1,"loot",A11,J11) -> loot_6010_meat
A12: 6011 | B12: 柔软皮毛 | C12: 0 | E12: Remove | F12: =IF($A12<>"",_xlfn.TEXTJOIN("_",1,"loot_name",$A12),"") -> loot_name_6011 | G12: =IF($A12<>"",_xlfn.TEXTJOIN("_",1,"loot_desc",$A12),"") -> loot_desc_6011 | J12: soft_fur | K12: =_xlfn.TEXTJOIN("_",1,"loot",A12,J12) -> loot_6011_soft_fur
A13: 6012 | B13: 植物果实 | C13: 0 | E13: Remove | F13: =IF($A13<>"",_xlfn.TEXTJOIN("_",1,"loot_name",$A13),"") -> loot_name_6012 | G13: =IF($A13<>"",_xlfn.TEXTJOIN("_",1,"loot_desc",$A13),"") -> loot_desc_6012 | J13: fruit | K13: =_xlfn.TEXTJOIN("_",1,"loot",A13,J13) -> loot_6012_fruit
A14: 6013 | B14: 纤维 | C14: 0 | E14: Remove | F14: =IF($A14<>"",_xlfn.TEXTJOIN("_",1,"loot_name",$A14),"") -> loot_name_6013 | G14: =IF($A14<>"",_xlfn.TEXTJOIN("_",1,"loot_desc",$A14),"") -> loot_desc_6013 | J14: fiber | K14: =_xlfn.TEXTJOIN("_",1,"loot",A14,J14) -> loot_6013_fiber
A15: 6014 | B15: 胶 | C15: 0 | E15: Remove | F15: =IF($A15<>"",_xlfn.TEXTJOIN("_",1,"loot_name",$A15),"") -> loot_name_6014 | G15: =IF($A15<>"",_xlfn.TEXTJOIN("_",1,"loot_desc",$A15),"") -> loot_desc_6014 | J15: glue | K15: =_xlfn.TEXTJOIN("_",1,"loot",A15,J15) -> loot_6014_glue
A16: 6020 | B16: 天然木材 | C16: 0 | E16: Remove | F16: =IF($A16<>"",_xlfn.TEXTJOIN("_",1,"loot_name",$A16),"") -> loot_name_6020 | G16: =IF($A16<>"",_xlfn.TEXTJOIN("_",1,"loot_desc",$A16),"") -> loot_desc_6020 | J16: wood | K16: =_xlfn.TEXTJOIN("_",1,"loot",A16,J16) -> loot_6020_wood
A17: 6021 | B17: 金属矿石 | C17: 0 | E17: Remove | F17: =IF($A17<>"",_xlfn.TEXTJOIN("_",1,"loot_name",$A17),"") -> loot_name_6021 | G17: =IF($A17<>"",_xlfn.TEXTJOIN("_",1,"loot_desc",$A17),"") -> loot_desc_6021 | J17: ore | K17: =_xlfn.TEXTJOIN("_",1,"loot",A17,J17) -> loot_6021_ore
A18: 6022 | B18: 天然石材 | C18: 0 | E18: Remove | F18: =IF($A18<>"",_xlfn.TEXTJOIN("_",1,"loot_name",$A18),"") -> loot_name_6022 | G18: =IF($A18<>"",_xlfn.TEXTJOIN("_",1,"loot_desc",$A18),"") -> loot_desc_6022 | J18: stone | K18: =_xlfn.TEXTJOIN("_",1,"loot",A18,J18) -> loot_6022_stone
A19: 6023 | B19: 易燃粉末 | C19: 0 | E19: Remove | F19: =IF($A19<>"",_xlfn.TEXTJOIN("_",1,"loot_name",$A19),"") -> loot_name_6023 | G19: =IF($A19<>"",_xlfn.TEXTJOIN("_",1,"loot_desc",$A19),"") -> loot_desc_6023 | J19: flammable_powder | K19: =_xlfn.TEXTJOIN("_",1,"loot",A19,J19) -> loot_6023_flammable_powder
A20: 6030 | B20: 废弃木材 | C20: 0 | E20: Remove | F20: =IF($A20<>"",_xlfn.TEXTJOIN("_",1,"loot_name",$A20),"") -> loot_name_6030 | G20: =IF($A20<>"",_xlfn.TEXTJOIN("_",1,"loot_desc",$A20),"") -> loot_desc_6030 | J20: timber_scrap | K20: =_xlfn.TEXTJOIN("_",1,"loot",A20,J20) -> loot_6030_timber_scrap
A21: 6031 | B21: 废弃金属 | C21: 0 | E21: Remove | F21: =IF($A21<>"",_xlfn.TEXTJOIN("_",1,"loot_name",$A21),"") -> loot_name_6031 | G21: =IF($A21<>"",_xlfn.TEXTJOIN("_",1,"loot_desc",$A21),"") -> loot_desc_6031 | J21: metal_scrap | K21: =_xlfn.TEXTJOIN("_",1,"loot",A21,J21) -> loot_6031_metal_scrap
A23: 6050 | B23: 食物 | C23: 1 | D23: 生肉; 植物果实 | E23: Remove | F23: =IF($A23<>"",_xlfn.TEXTJOIN("_",1,"loot_name",$A23),"") -> loot_name_6050 | G23: =IF($A23<>"",_xlfn.TEXTJOIN("_",1,"loot_desc",$A23),"") -> loot_desc_6050 | J23: meal | K23: =_xlfn.TEXTJOIN("_",1,"loot",A23,J23) -> loot_6050_meal
A24: 6051 | B24: 硬化兽皮 | C24: 1 | D24: 柔软皮毛 | E24: Remove | F24: =IF($A24<>"",_xlfn.TEXTJOIN("_",1,"loot_name",$A24),"") -> loot_name_6051 | G24: =IF($A24<>"",_xlfn.TEXTJOIN("_",1,"loot_desc",$A24),"") -> loot_desc_6051 | J24: harden_animal_skin | K24: =_xlfn.TEXTJOIN("_",1,"loot",A24,J24) -> loot_6051_harden_animal_skin
A25: 6052 | B25: 木制零件 | C25: 1 | D25: 天然木材; 废弃木材 | E25: Remove | F25: =IF($A25<>"",_xlfn.TEXTJOIN("_",1,"loot_name",$A25),"") -> loot_name_6052 | G25: =IF($A25<>"",_xlfn.TEXTJOIN("_",1,"loot_desc",$A25),"") -> loot_desc_6052 | J25: timber_part | K25: =_xlfn.TEXTJOIN("_",1,"loot",A25,J25) -> loot_6052_timber_part
A26: 6053 | B26: 金属零件 | C26: 1 | D26: 金属矿石; 废弃金属 | E26: Remove | F26: =IF($A26<>"",_xlfn.TEXTJOIN("_",1,"loot_name",$A26),"") -> loot_name_6053 | G26: =IF($A26<>"",_xlfn.TEXTJOIN("_",1,"loot_desc",$A26),"") -> loot_desc_6053 | J26: metal_parts | K26: =_xlfn.TEXTJOIN("_",1,"loot",A26,J26) -> loot_6053_metal_parts
A27: 6054 | B27: 磨刀石 | C27: 1 | D27: 天然石材 | E27: Remove | F27: =IF($A27<>"",_xlfn.TEXTJOIN("_",1,"loot_name",$A27),"") -> loot_name_6054 | G27: =IF($A27<>"",_xlfn.TEXTJOIN("_",1,"loot_desc",$A27),"") -> loot_desc_6054 | J27: grindstone | K27: =_xlfn.TEXTJOIN("_",1,"loot",A27,J27) -> loot_6054_grindstone
A28: 6055 | B28: 爆燃火药 | C28: 1 | D28: 易燃粉末 | E28: Remove | F28: =IF($A28<>"",_xlfn.TEXTJOIN("_",1,"loot_name",$A28),"") -> loot_name_6055 | G28: =IF($A28<>"",_xlfn.TEXTJOIN("_",1,"loot_desc",$A28),"") -> loot_desc_6055 | J28: fire_powder | K28: =_xlfn.TEXTJOIN("_",1,"loot",A28,J28) -> loot_6055_fire_powder
A29: 6056 | B29: 绑线 | C29: 1 | D29: 纤维 | E29: Remove | F29: =IF($A29<>"",_xlfn.TEXTJOIN("_",1,"loot_name",$A29),"") -> loot_name_6056 | G29: =IF($A29<>"",_xlfn.TEXTJOIN("_",1,"loot_desc",$A29),"") -> loot_desc_6056 | J29: string | K29: =_xlfn.TEXTJOIN("_",1,"loot",A29,J29) -> loot_6056_string
A31: 6070 | B31: 大餐 | C31: 2 | D31: 食物; 生肉; 果蔬 | E31: Remove | F31: =IF($A31<>"",_xlfn.TEXTJOIN("_",1,"loot_name",$A31),"") -> loot_name_6070 | G31: =IF($A31<>"",_xlfn.TEXTJOIN("_",1,"loot_desc",$A31),"") -> loot_desc_6070 | J31: feast | K31: =_xlfn.TEXTJOIN("_",1,"loot",A31,J31) -> loot_6070_feast
A32: 6071 | B32: 坚固皮革 | C32: 2 | D32: 硬化兽皮 | E32: Remove | F32: =IF($A32<>"",_xlfn.TEXTJOIN("_",1,"loot_name",$A32),"") -> loot_name_6071 | G32: =IF($A32<>"",_xlfn.TEXTJOIN("_",1,"loot_desc",$A32),"") -> loot_desc_6071 | J32: strong_leather | K32: =_xlfn.TEXTJOIN("_",1,"loot",A32,J32) -> loot_6071_strong_leather
A33: 6072 | B33: 武器部件 | C33: 2 | D33: 木制零件; 金属零件 | E33: Remove | F33: =IF($A33<>"",_xlfn.TEXTJOIN("_",1,"loot_name",$A33),"") -> loot_name_6072 | G33: =IF($A33<>"",_xlfn.TEXTJOIN("_",1,"loot_desc",$A33),"") -> loot_desc_6072 | J33: weapon_parts | K33: =_xlfn.TEXTJOIN("_",1,"loot",A33,J33) -> loot_6072_weapon_parts
A34: 6073 | B34: 优质磨刀石 | C34: 2 | D34: 磨刀石 | E34: Remove | F34: =IF($A34<>"",_xlfn.TEXTJOIN("_",1,"loot_name",$A34),"") -> loot_name_6073 | G34: =IF($A34<>"",_xlfn.TEXTJOIN("_",1,"loot_desc",$A34),"") -> loot_desc_6073 | J34: high_quality_grindstone | K34: =_xlfn.TEXTJOIN("_",1,"loot",A34,J34) -> loot_6073_high_quality_grindstone
A35: 6074 | B35: 烈性炸药 | C35: 2 | D35: 爆燃火药 | E35: Remove | F35: =IF($A35<>"",_xlfn.TEXTJOIN("_",1,"loot_name",$A35),"") -> loot_name_6074 | G35: =IF($A35<>"",_xlfn.TEXTJOIN("_",1,"loot_desc",$A35),"") -> loot_desc_6074 | J35: high_explosives | K35: =_xlfn.TEXTJOIN("_",1,"loot",A35,J35) -> loot_6074_high_explosives
A40: 10000 | B40: 铜币 | C40: —— | D40: —— | E40: —— | F40: =IF($A40<>"",_xlfn.TEXTJOIN("_",1,"loot_name",$A40),"") -> loot_name_10000 | G40: =IF($A40<>"",_xlfn.TEXTJOIN("_",1,"loot_desc",$A40),"") -> loot_desc_10000 | I40: coin | J40: coin | K40: loot_6000_coin
A42: 600101 | B42: 木武器柄 | C42: 地宫 | E42: 2025.Oct | F42: =IF($A42<>"",_xlfn.TEXTJOIN("_",1,"loot_name",$A42),"") -> loot_name_600101 | G42: =IF($A42<>"",_xlfn.TEXTJOIN("_",1,"loot_desc",$A42),"") -> loot_desc_600101 | I42: Dungeon | K42: =_xlfn.TEXTJOIN("_",1,"loot",A42,I42:J42) -> loot_600101_Dungeon | M42: 6112=4 | N42: {=IF(M42<>"", _xlfn.TEXTJOIN("; ",1, _xlfn.MAP(_xlfn.TEXTSPLIT(M42,";"), _xlfn.LAMBDA(_xlpm.x, _xlfn.LET(_xlpm.kv,_xlfn.TEXTSPLIT(_xlpm.x,"="), VLOOKUP(VALUE(INDEX(_xlpm.kv,1)),camp_coin!A:C,3,0)&" * "&INDEX(_xlpm.kv,2))))),"")} -> 木材 * 4
A43: 600102 | B43: 洞穴人碎金 | C43: 地宫 | E43: 2025.Oct | F43: =IF($A43<>"",_xlfn.TEXTJOIN("_",1,"loot_name",$A43),"") -> loot_name_600102 | G43: =IF($A43<>"",_xlfn.TEXTJOIN("_",1,"loot_desc",$A43),"") -> loot_desc_600102 | I43: Dungeon | K43: =_xlfn.TEXTJOIN("_",1,"loot",A43,I43:J43) -> loot_600102_Dungeon | M43: 6111=6 | N43: {=IF(M43<>"", _xlfn.TEXTJOIN("; ",1, _xlfn.MAP(_xlfn.TEXTSPLIT(M43,";"), _xlfn.LAMBDA(_xlpm.x, _xlfn.LET(_xlpm.kv,_xlfn.TEXTSPLIT(_xlpm.x,"="), VLOOKUP(VALUE(INDEX(_xlpm.kv,1)),camp_coin!A:C,3,0)&" * "&INDEX(_xlpm.kv,2))))),"")} -> 黄金 * 6
A44: 600103 | B44: 狗头金 | C44: 地宫 | E44: 2025.Oct | F44: =IF($A44<>"",_xlfn.TEXTJOIN("_",1,"loot_name",$A44),"") -> loot_name_600103 | G44: =IF($A44<>"",_xlfn.TEXTJOIN("_",1,"loot_desc",$A44),"") -> loot_desc_600103 | I44: Dungeon | K44: =_xlfn.TEXTJOIN("_",1,"loot",A44,I44:J44) -> loot_600103_Dungeon | M44: 6111=7 | N44: {=IF(M44<>"", _xlfn.TEXTJOIN("; ",1, _xlfn.MAP(_xlfn.TEXTSPLIT(M44,";"), _xlfn.LAMBDA(_xlpm.x, _xlfn.LET(_xlpm.kv,_xlfn.TEXTSPLIT(_xlpm.x,"="), VLOOKUP(VALUE(INDEX(_xlpm.kv,1)),camp_coin!A:C,3,0)&" * "&INDEX(_xlpm.kv,2))))),"")} -> 黄金 * 7
A45: 600104 | B45: 洞穴人金块 | C45: 地宫 | E45: 2025.Oct | F45: =IF($A45<>"",_xlfn.TEXTJOIN("_",1,"loot_name",$A45),"") -> loot_name_600104 | G45: =IF($A45<>"",_xlfn.TEXTJOIN("_",1,"loot_desc",$A45),"") -> loot_desc_600104 | I45: Dungeon | K45: =_xlfn.TEXTJOIN("_",1,"loot",A45,I45:J45) -> loot_600104_Dungeon | M45: 6111=12 | N45: {=IF(M45<>"", _xlfn.TEXTJOIN("; ",1, _xlfn.MAP(_xlfn.TEXTSPLIT(M45,";"), _xlfn.LAMBDA(_xlpm.x, _xlfn.LET(_xlpm.kv,_xlfn.TEXTSPLIT(_xlpm.x,"="), VLOOKUP(VALUE(INDEX(_xlpm.kv,1)),camp_coin!A:C,3,0)&" * "&INDEX(_xlpm.kv,2))))),"")} -> 黄金 * 12
A46: 600105 | B46: 古代地宫柱梁 | C46: 地宫 | E46: 2025.Oct | F46: =IF($A46<>"",_xlfn.TEXTJOIN("_",1,"loot_name",$A46),"") -> loot_name_600105 | G46: =IF($A46<>"",_xlfn.TEXTJOIN("_",1,"loot_desc",$A46),"") -> loot_desc_600105 | I46: Dungeon | K46: =_xlfn.TEXTJOIN("_",1,"loot",A46,I46:J46) -> loot_600105_Dungeon | M46: 6112=22 | N46: {=IF(M46<>"", _xlfn.TEXTJOIN("; ",1, _xlfn.MAP(_xlfn.TEXTSPLIT(M46,";"), _xlfn.LAMBDA(_xlpm.x, _xlfn.LET(_xlpm.kv,_xlfn.TEXTSPLIT(_xlpm.x,"="), VLOOKUP(VALUE(INDEX(_xlpm.kv,1)),camp_coin!A:C,3,0)&" * "&INDEX(_xlpm.kv,2))))),"")} -> 木材 * 22
A47: 600106 | B47: 古代地宫金砖 | C47: 地宫 | E47: 2025.Oct | F47: =IF($A47<>"",_xlfn.TEXTJOIN("_",1,"loot_name",$A47),"") -> loot_name_600106 | G47: =IF($A47<>"",_xlfn.TEXTJOIN("_",1,"loot_desc",$A47),"") -> loot_desc_600106 | I47: Dungeon | K47: =_xlfn.TEXTJOIN("_",1,"loot",A47,I47:J47) -> loot_600106_Dungeon | M47: 6111=20 | N47: {=IF(M47<>"", _xlfn.TEXTJOIN("; ",1, _xlfn.MAP(_xlfn.TEXTSPLIT(M47,";"), _xlfn.LAMBDA(_xlpm.x, _xlfn.LET(_xlpm.kv,_xlfn.TEXTSPLIT(_xlpm.x,"="), VLOOKUP(VALUE(INDEX(_xlpm.kv,1)),camp_coin!A:C,3,0)&" * "&INDEX(_xlpm.kv,2))))),"")} -> 黄金 * 20
A48: 600107 | B48: 古代地宫雕像 | C48: 地宫 | E48: 2025.Oct | F48: =IF($A48<>"",_xlfn.TEXTJOIN("_",1,"loot_name",$A48),"") -> loot_name_600107 | G48: =IF($A48<>"",_xlfn.TEXTJOIN("_",1,"loot_desc",$A48),"") -> loot_desc_600107 | I48: Dungeon | K48: =_xlfn.TEXTJOIN("_",1,"loot",A48,I48:J48) -> loot_600107_Dungeon | M48: 6111=18;6112=8 | N48: {=IF(M48<>"", _xlfn.TEXTJOIN("; ",1, _xlfn.MAP(_xlfn.TEXTSPLIT(M48,";"), _xlfn.LAMBDA(_xlpm.x, _xlfn.LET(_xlpm.kv,_xlfn.TEXTSPLIT(_xlpm.x,"="), VLOOKUP(VALUE(INDEX(_xlpm.kv,1)),camp_coin!A:C,3,0)&" * "&INDEX(_xlpm.kv,2))))),"")} -> 黄金 * 18; 木材 * 8
...

Sheet camp_coin
A1: id | B1: name | D1: icon
A2: uint key | B2: string | D2: string
A3: 编号 | B3: 名称 | C3: 备注 | D3: 图标 (asset address)
A4: 6111 | B4: ="camp_res_name_"&$A4 -> camp_res_name_6111 | C4: 黄金 | D4: ui_item_icon[ui_item_icon_0]
A5: 6112 | B5: ="camp_res_name_"&$A5 -> camp_res_name_6112 | C5: 木材 | D5: ui_item_icon[ui_item_icon_1]
A6: 6113 | B6: ="camp_res_name_"&$A6 -> camp_res_name_6113 | C6: 食物 | D6: ui_item_icon[ui_item_icon_2]
A7: 6114 | B7: ="camp_res_name_"&$A7 -> camp_res_name_6114 | C7: 金属 | D7: ui_item_icon[ui_item_icon_3]
A10: 6121 | B10: ="camp_res_name_"&$A10 -> camp_res_name_6121 | C10: 火硫磺 | D10: ="camp_res_icon_"&$A10 -> camp_res_icon_6121
A11: 6122 | B11: ="camp_res_name_"&$A11 -> camp_res_name_6122 | C11: 天空石 | D11: ="camp_res_icon_"&$A11 -> camp_res_icon_6122
A12: 6123 | B12: ="camp_res_name_"&$A12 -> camp_res_name_6123 | C12: 建木根须 | D12: ="camp_res_icon_"&$A12 -> camp_res_icon_6123
A13: 6124 | B13: ="camp_res_name_"&$A13 -> camp_res_name_6124 | C13: 建木果实 | D13: ="camp_res_icon_"&$A13 -> camp_res_icon_6124
A15: 6126 | B15: ="camp_res_name_"&$A15 -> camp_res_name_6126 | C15: 矮人矿石 | D15: ="camp_res_icon_"&$A15 -> camp_res_icon_6126
A16: 6127 | B16: ="camp_res_name_"&$A16 -> camp_res_name_6127 | C16: 沙漠水晶 | D16: ="camp_res_icon_"&$A16 -> camp_res_icon_6127
A17: 6128 | B17: ="camp_res_name_"&$A17 -> camp_res_name_6128 | C17: 珍珠 | D17: ="camp_res_icon_"&$A17 -> camp_res_icon_6128

Sheet -id 配置说明
A1: 第1位 | B1: 第2位 | C1: 第3位 | D1: 第4位 | E1: 第5位 | F1: 第6位
A2: 60 = loot | C2: 01 = 地宫 | E2: 00~99 编号
C3: 04 = 树梢
C4: 07 = 荒漠
C5: 08 = 大湖
A11: 第1位 | B11: 第2位 | C11: 第3位 | D11: 第4位
A12: 61 = camp_coin | C12: 1 = 基础 | D12: 1~9=编号
C13: 2 = 世界特殊 | D13: 1~8=世界编号
