Workbook

Sheet table_l10n
A1: id | D1: CN | E1: CHT | F1: EN | G1: ES | H1: JA | I1: RU | J1: KO
A2: string key | D2: string | E2: string | F2: string | G2: string | H2: string | I2: string | J2: string
A3: key | B3: 备注1 公式生成 | C3: 备注2 | D3: 简体中文 中文 | E3: 繁體中文 繁体中文 | F3: English 英语 | G3: Español 西班牙语 | H3: 日本語 日语 | I3: Русский 俄语 | J3: 한국어 韩语
A4: carbody_name_100101 | B4: {=_xlfn.TEXTJOIN(,1,IF(IFERROR(FIND(table_prefix[前缀],table_l10n!A4),FALSE),TEXT(table_prefix[说明],""),""))} -> 车体 - 名称 | C4: 简易篷车 | D4: 简易篷车 | E4: =_xlfn.TRANSLATE($D4,"zh-chs","zh-cht") -> 簡易篷車 | F4: =_xlfn.TRANSLATE($D4,"zh-chs","en") -> Improvised caravan | G4: =_xlfn.TRANSLATE($D4,"zh-chs","es") -> Caravana improvisada | H4: =_xlfn.TRANSLATE($D4,"zh-chs","ja") -> 即席キャラバン | I4: =_xlfn.TRANSLATE($D4,"zh-chs","ru") -> Импровизированный караван | J4: =_xlfn.TRANSLATE($D4,"zh-chs","ko") -> 즉석 캐러밴
B5: {=_xlfn.TEXTJOIN(,1,IF(IFERROR(FIND(table_prefix[前缀],table_l10n!A5),FALSE),TEXT(table_prefix[说明],""),""))} | E5: =_xlfn.TRANSLATE($D5,"zh-chs","zh-cht") | F5: =_xlfn.TRANSLATE($D5,"zh-chs","en") | G5: =_xlfn.TRANSLATE($D5,"zh-chs","es") | H5: =_xlfn.TRANSLATE($D5,"zh-chs","ja") | I5: =_xlfn.TRANSLATE($D5,"zh-chs","ru") | J5: =_xlfn.TRANSLATE($D5,"zh-chs","ko")
A6: carbody_name_101101 | B6: {=_xlfn.TEXTJOIN(,1,IF(IFERROR(FIND(table_prefix[前缀],table_l10n!A6),FALSE),TEXT(table_prefix[说明],""),""))} -> 车体 - 名称 | C6: 捕奴囚笼 | D6: 捕奴囚笼 | E6: 捕奴囚籠 | F6: Slave cages | G6: Jaulas de esclavos | H6: スレーブケージ | I6: Вольничьи клетки | J6: 슬레이브 케이지
A7: carbody_name_101102 | B7: {=_xlfn.TEXTJOIN(,1,IF(IFERROR(FIND(table_prefix[前缀],table_l10n!A7),FALSE),TEXT(table_prefix[说明],""),""))} -> 车体 - 名称 | C7: 镇暴装甲 | D7: 镇暴装甲 | E7: 鎮暴裝甲 | F7: Riot Suppression Armor | G7: Armadura de supresión de disturbios | H7: ライオット・サプレッション・アーマー | I7: Броня для подавления беспорядков | J7: 폭동 진압 갑옷
B8: {=_xlfn.TEXTJOIN(,1,IF(IFERROR(FIND(table_prefix[前缀],table_l10n!A8),FALSE),TEXT(table_prefix[说明],""),""))} | E8: =_xlfn.TRANSLATE($D8,"zh-chs","zh-cht") | F8: =_xlfn.TRANSLATE($D8,"zh-chs","en") | G8: =_xlfn.TRANSLATE($D8,"zh-chs","es") | H8: =_xlfn.TRANSLATE($D8,"zh-chs","ja") | I8: =_xlfn.TRANSLATE($D8,"zh-chs","ru") | J8: =_xlfn.TRANSLATE($D8,"zh-chs","ko")
B9: {=_xlfn.TEXTJOIN(,1,IF(IFERROR(FIND(table_prefix[前缀],table_l10n!A9),FALSE),TEXT(table_prefix[说明],""),""))} | E9: =_xlfn.TRANSLATE($D9,"zh-chs","zh-cht") | F9: =_xlfn.TRANSLATE($D9,"zh-chs","en") | G9: =_xlfn.TRANSLATE($D9,"zh-chs","es") | H9: =_xlfn.TRANSLATE($D9,"zh-chs","ja") | I9: =_xlfn.TRANSLATE($D9,"zh-chs","ru") | J9: =_xlfn.TRANSLATE($D9,"zh-chs","ko")
A10: device_name_1210101_wheel_wooden | B10: {=_xlfn.TEXTJOIN(,1,IF(IFERROR(FIND(table_prefix[前缀],table_l10n!A10),FALSE),TEXT(table_prefix[说明],""),""))} -> 设备 - 名称 | C10: 车轮 | D10: 硬木车轮 | E10: 硬木車輪 | F10: Hardwood wheels | G10: Ruedas de madera dura | H10: 広葉樹ホイール | I10: Колеса из твердой древесины | J10: 경재 바퀴
A11: device_name_12101019_wheel_wooden | B11: {=_xlfn.TEXTJOIN(,1,IF(IFERROR(FIND(table_prefix[前缀],table_l10n!A11),FALSE),TEXT(table_prefix[说明],""),""))} -> 设备 - 名称 | C11: 车轮 | D11: 旧木轮 | E11: 舊木輪 | F11: Old wooden wheels | G11: Ruedas antiguas de madera | H11: 古い木製車輪 | I11: Старые деревянные колёса | J11: 오래된 나무 바퀴
A12: device_name_1210102_wheel_track | B12: {=_xlfn.TEXTJOIN(,1,IF(IFERROR(FIND(table_prefix[前缀],table_l10n!A12),FALSE),TEXT(table_prefix[说明],""),""))} -> 设备 - 名称 | C12: 车轮 | D12: 履带 | E12: 履帶 | F12: track | G12: pista | H12: トラック | I12: дорожка | J12: 추적하다
A13: device_name_1211801_wheel_lifebuoy | B13: {=_xlfn.TEXTJOIN(,1,IF(IFERROR(FIND(table_prefix[前缀],table_l10n!A13),FALSE),TEXT(table_prefix[说明],""),""))} -> 设备 - 名称 | C13: 车轮 | D13: 救生圈 | E13: 救生圈 | F13: buoy | G13: boya | H13: ブイ | I13: буй | J13: 부표
A15: device_name_1310101_dagger | B15: {=_xlfn.TEXTJOIN(,1,IF(IFERROR(FIND(table_prefix[前缀],table_l10n!A15),FALSE),TEXT(table_prefix[说明],""),""))} -> 设备 - 名称 | C15: 近战 | D15: 短匕 | E15: 短匕 | F15: Short dagger | G15: Daga corta | H15: ショートダガー | I15: Короткий кинжал | J15: 짧은 단검
A16: device_name_1310102_machete | B16: {=_xlfn.TEXTJOIN(,1,IF(IFERROR(FIND(table_prefix[前缀],table_l10n!A16),FALSE),TEXT(table_prefix[说明],""),""))} -> 设备 - 名称 | C16: 近战 | D16: 砍刀 | E16: 砍刀 | F16: Machetes | G16: Machetes | H16: 山刀 | I16: Мачете | J16: 마체테
A17: device_name_1310103_claymore | B17: {=_xlfn.TEXTJOIN(,1,IF(IFERROR(FIND(table_prefix[前缀],table_l10n!A17),FALSE),TEXT(table_prefix[说明],""),""))} -> 设备 - 名称 | C17: 近战 | D17: 大剑 | E17: 大劍 | F17: Greatsword | G17: Espadón | H17: グレートソード | I17: Двуручный меч | J17: 대검
A18: device_name_1310104_spear | B18: {=_xlfn.TEXTJOIN(,1,IF(IFERROR(FIND(table_prefix[前缀],table_l10n!A18),FALSE),TEXT(table_prefix[说明],""),""))} -> 设备 - 名称 | C18: 近战 | D18: 长矛 | E18: 長矛 | F18: spear | G18: lanza | H18: 槍 | I18: копьё | J18: 창
A19: device_name_1310105_inflatable_stick | B19: {=_xlfn.TEXTJOIN(,1,IF(IFERROR(FIND(table_prefix[前缀],table_l10n!A19),FALSE),TEXT(table_prefix[说明],""),""))} -> 设备 - 名称 | C19: 近战 | D19: 充气球棒 | E19: 充氣球棒 | F19: Inflatable bats | G19: Bates inflables | H19: 膨らませるバット | I19: Надувные биты | J19: 팽창식 배트
A20: device_name_1310106_circlesaw | B20: {=_xlfn.TEXTJOIN(,1,IF(IFERROR(FIND(table_prefix[前缀],table_l10n!A20),FALSE),TEXT(table_prefix[说明],""),""))} -> 设备 - 名称 | C20: 近战 | D20: 圆锯 | E20: 圓鋸 | F20: circular saw | G20: Sierra circular | H20: 丸ノコ | I20: циркулярная пила | J20: 원형톱
A21: device_name_1310107_double_edged_cutter | B21: {=_xlfn.TEXTJOIN(,1,IF(IFERROR(FIND(table_prefix[前缀],table_l10n!A21),FALSE),TEXT(table_prefix[说明],""),""))} -> 设备 - 名称 | C21: 近战 | D21: 双刃铡刀 | E21: 雙刃鍘刀 | F21: Double-edged sword | G21: Espada de doble filo | H21: 両刃の剣 | I21: Палка о двух концах | J21: 양날의 검
A22: device_name_1311101_executioner_baton | B22: {=_xlfn.TEXTJOIN(,1,IF(IFERROR(FIND(table_prefix[前缀],table_l10n!A22),FALSE),TEXT(table_prefix[说明],""),""))} -> 设备 - 名称 | C22: 近战 | D22: 执刑木棍 | E22: 執刑木棍 | F22: Execution sticks | G22: Palos de ejecución | H22: 実行スティック | I22: Палочки для казни | J22: 실행 스틱
... A48: device_name_1330103_catching_flower | B48: {=_xlfn.TEXTJOIN(,1,IF(IFERROR(FIND(table_prefix[前缀],table_l10n!A48),FALSE),TEXT(table_prefix[说明],""),""))} -> 设备 - 名称 | C48: device_9999_hua | D48: 捕兽草 | E48: 捕獸草 | F48: Trapping grass | G48: Atrapar hierba | H48: 草の捕獲 | I48: Ловля травы | J48: 잔디 덫 놓기
A49: device_name_1330104_gyroscope | B49: {=_xlfn.TEXTJOIN(,1,IF(IFERROR(FIND(table_prefix[前缀],table_l10n!A49),FALSE),TEXT(table_prefix[说明],""),""))} -> 设备 - 名称 | D49: 飞针陀螺 | E49: 飛針陀螺 | F49: Flying needle spinner | G49: Girador de agujas voladoras | H49: フライングニードルスピナー | I49: Спиннер с летающей иглой | J49: 플라잉 니들 스피너
A50: device_name_1330106_car_bomb | B50: {=_xlfn.TEXTJOIN(,1,IF(IFERROR(FIND(table_prefix[前缀],table_l10n!A50),FALSE),TEXT(table_prefix[说明],""),""))} -> 设备 - 名称 | C50: 紧急炸药包 | D50: 采矿炸弹 | E50: 採礦炸彈 | F50: Mining bombs | G50: Bombas mineras | H50: 鉱山爆弾 | I50: Минные бомбы | J50: 광산 폭탄
A51: device_name_1330107 | B51: {=_xlfn.TEXTJOIN(,1,IF(IFERROR(FIND(table_prefix[前缀],table_l10n!A51),FALSE),TEXT(table_prefix[说明],""),""))} -> 设备 - 名称 | C51: 黑洞发射器 | D51: 黑洞发射器 | E51: 黑洞發射器 | F51: Black hole emitter | G51: Emisor de agujero negro | H51: ブラックホールエミッター | I51: Излучатель черных дыр | J51: 블랙홀 이미터
A52: device_name_1330108 | B52: {=_xlfn.TEXTJOIN(,1,IF(IFERROR(FIND(table_prefix[前缀],table_l10n!A52),FALSE),TEXT(table_prefix[说明],""),""))} -> 设备 - 名称 | C52: 磁铁 | D52: 磁铁 | E52: 磁鐵 | F52: magnet | G52: imán | H52: 磁石 | I52: магнит | J52: 자석
A53: device_name_1330109 | B53: {=_xlfn.TEXTJOIN(,1,IF(IFERROR(FIND(table_prefix[前缀],table_l10n!A53),FALSE),TEXT(table_prefix[说明],""),""))} -> 设备 - 名称 | C53: 回收者 | D53: 回收者 | E53: 回收者 | F53: Recyclers | G53: Recicladores | H53: リサイクル業者 | I53: Переработчики | J53: 재활용업체
A54: device_name_1330110 | B54: {=_xlfn.TEXTJOIN(,1,IF(IFERROR(FIND(table_prefix[前缀],table_l10n!A54),FALSE),TEXT(table_prefix[说明],""),""))} -> 设备 - 名称 | C54: 大百变怪 | D54: 大百变怪 | E54: 大百變怪 | F54: BigDitto | G54: Grande Cambiable | H54: 大きな異変 | I54: Большие перемены | J54: 큰 메타몽
A55: device_name_1330111 | B55: {=_xlfn.TEXTJOIN(,1,IF(IFERROR(FIND(table_prefix[前缀],table_l10n!A55),FALSE),TEXT(table_prefix[说明],""),""))} -> 设备 - 名称 | C55: 小百变怪 | D55: 小百变怪 | E55: 小百變怪 | F55: SmallDitto | G55: Pequeño Cambiable | H55: 小さな異変 | I55: Маленькие странники | J55: 작은 메타몽
A56: device_name_1330112 | B56: {=_xlfn.TEXTJOIN(,1,IF(IFERROR(FIND(table_prefix[前缀],table_l10n!A56),FALSE),TEXT(table_prefix[说明],""),""))} -> 设备 - 名称 | C56: 气球枪 | D56: 气球枪 | E56: 氣球槍 | F56: Balloon guns | G56: Pistolas de globos | H56: バルーンガン | I56: Аэростатные пушки | J56: 풍선 총
A57: device_name_1330113 | B57: {=_xlfn.TEXTJOIN(,1,IF(IFERROR(FIND(table_prefix[前缀],table_l10n!A57),FALSE),TEXT(table_prefix[说明],""),""))} -> 设备 - 名称 | C57: 铅球枪 | D57: 铅球枪 | E57: 鉛球槍 | F57: Shot gun | G57: Escopeta | H57: ショットガン | I57: Дробовик | J57: 샷 건
A58: device_name_1331801_tesla | B58: {=_xlfn.TEXTJOIN(,1,IF(IFERROR(FIND(table_prefix[前缀],table_l10n!A58),FALSE),TEXT(table_prefix[说明],""),""))} -> 设备 - 名称 | C58: 特斯拉电极 | D58: 特斯拉电极 | E58: 特斯拉電極 | F58: Tesla electrodes | G58: Electrodos de Tesla | H58: テスラ電極 | I58: Электроды Теслы | J58: 테슬라 전극
A60: device_name_1340101_buckler | B60: {=_xlfn.TEXTJOIN(,1,IF(IFERROR(FIND(table_prefix[前缀],table_l10n!A60),FALSE),TEXT(table_prefix[说明],""),""))} -> 设备 - 名称 | C60: 盾牌 | D60: 小圆盾 | E60: 小圓盾 | F60: buckler | G60: escudo | H60: 盾 | I60: небольшой круглый щит | J60: 작은 방패
A61: device_name_1340102_wooden_shield | B61: {=_xlfn.TEXTJOIN(,1,IF(IFERROR(FIND(table_prefix[前缀],table_l10n!A61),FALSE),TEXT(table_prefix[说明],""),""))} -> 设备 - 名称 | C61: 盾牌 | D61: 木盾 | E61: 木盾 | F61: Wooden shield | G61: Escudo de madera | H61: 木製の盾 | I61: Деревянный щит | J61: 나무 방패
A62: device_name_1340103_testudo | B62: {=_xlfn.TEXTJOIN(,1,IF(IFERROR(FIND(table_prefix[前缀],table_l10n!A62),FALSE),TEXT(table_prefix[说明],""),""))} -> 设备 - 名称 | C62: 盾牌 | D62: 长阔盾 | E62: 長闊盾 | F62: Long and broad shields | G62: Escudos largos y anchos | H62: 長くて広いシールド | I62: Длинные и широкие щиты | J62: 길고 넓은 방패
... A73: device_name_1351102_executioner_hookrope | B73: {=_xlfn.TEXTJOIN(,1,IF(IFERROR(FIND(table_prefix[前缀],table_l10n!A73),FALSE),TEXT(table_prefix[说明],""),""))} -> 设备 - 名称 | C73: 钩索 | D73: 执刑人挂钩 | E73: 執刑人掛鉤 | F73: Executioner hook | G73: Gancho de verdugo | H73: エクセキューショナーフック | I73: Крюк палача | J73: 처형자 갈고리
B74: {=_xlfn.TEXTJOIN(,1,IF(IFERROR(FIND(table_prefix[前缀],table_l10n!A74),FALSE),TEXT(table_prefix[说明],""),""))}
A75: device_name_1360101_spear_ram | B75: {=_xlfn.TEXTJOIN(,1,IF(IFERROR(FIND(table_prefix[前缀],table_l10n!A75),FALSE),TEXT(table_prefix[说明],""),""))} -> 设备 - 名称 | C75: 撞角 | D75: 刺矛撞角 | E75: 刺矛撞角 | F75: Spike spear ramming horns | G75: Lanza de púas que embisten cuernos | H75: 角に突き刺さるスパイクスピア | I75: Шиповое копье, таранное рога | J75: 스파이크 창 부딪히는 뿔
A76: device_name_1360102_metal_ram | B76: {=_xlfn.TEXTJOIN(,1,IF(IFERROR(FIND(table_prefix[前缀],table_l10n!A76),FALSE),TEXT(table_prefix[说明],""),""))} -> 设备 - 名称 | C76: 撞角 | D76: 金属铲斗 | E76: 金屬鏟鬥 | F76: Metal buckets | G76: Cubos metálicos | H76: 金属製バケツ | I76: Металлические ведра | J76: 금속 양동이
A77: device_name_1360103_bouncing_mushroom | B77: {=_xlfn.TEXTJOIN(,1,IF(IFERROR(FIND(table_prefix[前缀],table_l10n!A77),FALSE),TEXT(table_prefix[说明],""),""))} -> 设备 - 名称 | C77: 撞角 | D77: 菌菇挡板 | E77: 蘑菇擋板 | F77: Mushroom baffle | G77: Deflector de hongos | H77: マッシュルームバッフル | I77: Грибовидная перегородка | J77: 버섯 배플
...

Sheet -说明
A1: 前缀 | B1: 说明 | C1: id前缀
A2: carbody_name | B2: 车体 - 名称 | C2: 10
A3: device_name | B3: 设备 - 名称 | C3: 12;13
A4: device_alt | B4: 设备 - alt信息 | C4: —
A5: device_tag | B5: 设备标签 - 名称 | C5: 14
A6: role | B6: 角色 - 名称 | C6: 15
A7: trait_name | B7: 角色特性 - 名称 | C7: 16
A8: trait_desc | B8: 角色特性 - 描述 | C8: 16
A9: relic_name | B9: 遗物 - 名称 | C9: 30
A10: relic_desc | B10: 遗物 - 描述 | C10: 30
A11: world | B11: 世界 - 名称 | C11: 40
A12: scene | B12: 场景 - 名称 | C12: 42
A13: weather_name | B13: 天气 - 名称 | C13: 46
A14: weather_desc | B14: 天气 - 描述 | C14: 46
A15: loot_name | B15: 物品 - 名称 | C15: 60
A16: loot_desc | B16: 物品 - 描述 | C16: 60
A17: camp_res_name | B17: 营地资源 - 名称 | C17: 61
A18: dv_upgd_name | B18: 设备升级 - 名称 | C18: 62;63
A19: dv_upgd_desc | B19: 设备升级 - 描述 | C19: 62;63
A20: dv_upgd_story | B20: 设备升级 - 设定 | C20: 62;63
A21: safe_zone | B21: 安全区 | C21: —
A22: tech_name | B22: 科技 - 名称 | C22: 65
A23: tech_desc | B23: 科技 - 描述 | C23: 65
